,ts_recv,ts_event,rtype,publisher_id,instrument_id,action,side,depth,price,size,flags,ts_in_delta,sequence,bid_px_00,bid_sz_00,bid_ct_00,bid_px_01,bid_sz_01,bid_ct_01,bid_px_02,bid_sz_02,bid_ct_02,bid_px_03,bid_sz_03,bid_ct_03,bid_px_04,bid_sz_04,bid_ct_04,bid_px_05,bid_sz_05,bid_ct_05,bid_px_06,bid_sz_06,bid_ct_06,bid_px_07,bid_sz_07,bid_ct_07,bid_px_08,bid_sz_08,bid_ct_08,bid_px_09,bid_sz_09,bid_ct_09,ask_px_00,ask_sz_00,ask_ct_00,ask_px_01,ask_sz_01,ask_ct_01,ask_px_02,ask_sz_02,ask_ct_02,ask_px_03,ask_sz_03,ask_ct_03,ask_px_04,ask_sz_04,ask_ct_04,ask_px_05,ask_sz_05,ask_ct_05,ask_px_06,ask_sz_06,ask_ct_06,ask_px_07,ask_sz_07,ask_ct_07,ask_px_08,ask_sz_08,ask_ct_08,ask_px_09,ask_sz_09,ask_ct_09,symbol,order_id
1700,2025-07-17T16:18:45.978659056Z,2025-07-17T16:18:45.978493799Z,10,2,1108,A,A,3,14.08,100,130,165257,287547872,13.11,100,1,13.03,2,1,12.98,200,2,12.86,100,1,12.73,100,1,12.71,100,1,12.5,700,1,12.46,100,1,12.43,700,1,12.42,700,1,13.47,15,1,13.48,100,1,13.79,2,1,14.08,200,2,14.35,200,2,14.48,700,1,14.53,200,2,14.54,700,1,14.56,700,1,14.59,100,1,ARL,345889165
1701,2025-07-17T16:18:45.979453023Z,2025-07-17T16:18:45.979287575Z,10,2,1108,A,A,5,14.43,100,130,165448,287547885,13.11,100,1,13.03,2,1,12.98,200,2,12.86,100,1,12.73,100,1,12.71,100,1,12.5,700,1,12.46,100,1,12.43,700,1,12.42,700,1,13.47,15,1,13.48,100,1,13.79,2,1,14.08,200,2,14.35,200,2,14.43,100,1,14.48,700,1,14.53,200,2,14.54,700,1,14.56,700,1,ARL,345889189
1702,2025-07-17T16:18:45.980137835Z,2025-07-17T16:18:45.979972220Z,10,2,1108,A,A,5,14.43,100,130,165615,287547890,13.11,100,1,13.03,2,1,12.98,200,2,12.86,100,1,12.73,100,1,12.71,100,1,12.5,700,1,12.46,100,1,12.43,700,1,12.42,700,1,13.47,15,1,13.48,100,1,13.79,2,1,14.08,200,2,14.35,200,2,14.43,200,2,14.48,700,1,14.53,200,2,14.54,700,1,14.56,700,1,ARL,345889201
1703,2025-07-17T16:18:45.983098604Z,2025-07-17T16:18:45.982933040Z,10,2,1108,A,A,4,14.27,100,130,165564,287547921,13.11,100,1,13.03,2,1,12.98,200,2,12.86,100,1,12.73,100,1,12.71,100,1,12.5,700,1,12.46,100,1,12.43,700,1,12.42,700,1,13.47,15,1,13.48,100,1,13.79,2,1,14.08,200,2,14.27,100,1,14.35,200,2,14.43,200,2,14.48,700,1,14.53,200,2,14.54,700,1,ARL,345889277
1704,2025-07-17T16:18:45.994306597Z,2025-07-17T16:18:45.994141218Z,10,2,1108,C,A,3,14.08,100,130,165379,287548000,13.11,100,1,13.03,2,1,12.98,200,2,12.86,100,1,12.73,100,1,12.71,100,1,12.5,700,1,12.46,100,1,12.43,700,1,12.42,700,1,13.47,15,1,13.48,100,1,13.79,2,1,14.08,100,1,14.27,100,1,14.35,200,2,14.43,200,2,14.48,700,1,14.53,200,2,14.54,700,1,ARL,344989601
1705,2025-07-17T16:18:45.994356983Z,2025-07-17T16:18:45.994191684Z,10,2,1108,A,A,2,13.75,100,130,165299,287548002,13.11,100,1,13.03,2,1,12.98,200,2,12.86,100,1,12.73,100,1,12.71,100,1,12.5,700,1,12.46,100,1,12.43,700,1,12.42,700,1,13.47,15,1,13.48,100,1,13.75,100,1,13.79,2,1,14.08,100,1,14.27,100,1,14.35,200,2,14.43,200,2,14.48,700,1,14.53,200,2,ARL,345889457
1706,2025-07-17T16:18:46.583802176Z,2025-07-17T16:18:46.583636828Z,10,2,1108,A,A,6,14.28,100,130,165348,287559115,13.11,100,1,13.03,2,1,12.98,200,2,12.86,100,1,12.73,100,1,12.71,100,1,12.5,700,1,12.46,100,1,12.43,700,1,12.42,700,1,13.47,15,1,13.48,100,1,13.75,100,1,13.79,2,1,14.08,100,1,14.27,100,1,14.28,100,1,14.35,200,2,14.43,200,2,14.48,700,1,ARL,345903265
1707,2025-07-17T16:18:46.972855248Z,2025-07-17T16:18:46.972689989Z,10,2,1108,A,A,4,14.01,100,130,165259,287565225,13.11,100,1,13.03,2,1,12.98,200,2,12.86,100,1,12.73,100,1,12.71,100,1,12.5,700,1,12.46,100,1,12.43,700,1,12.42,700,1,13.47,15,1,13.48,100,1,13.75,100,1,13.79,2,1,14.01,100,1,14.08,100,1,14.27,100,1,14.28,100,1,14.35,200,2,14.43,200,2,ARL,345911213
1708,2025-07-17T16:18:47.836167832Z,2025-07-17T16:18:47.836002486Z,10,2,1108,A,A,0,13.45,15,130,165346,287577128,13.11,100,1,13.03,2,1,12.98,200,2,12.86,100,1,12.73,100,1,12.71,100,1,12.5,700,1,12.46,100,1,12.43,700,1,12.42,700,1,13.45,15,1,13.47,15,1,13.48,100,1,13.75,100,1,13.79,2,1,14.01,100,1,14.08,100,1,14.27,100,1,14.28,100,1,14.35,200,2,ARL,345924181
1709,2025-07-17T16:18:47.956236479Z,2025-07-17T16:18:47.956070064Z,10,2,1108,C,A,-1,13.48,100,0,166415,287579474,13.11,100,1,13.03,2,1,12.98,200,2,12.86,100,1,12.73,100,1,12.71,100,1,12.5,700,1,12.46,100,1,12.43,700,1,12.42,700,1,13.45,15,1,13.47,15,1,13.75,100,1,13.79,2,1,14.01,100,1,14.08,100,1,14.27,100,1,14.28,100,1,14.35,200,2,14.43,200,2,ARL,345889137
1710,2025-07-17T16:18:47.956236479Z,2025-07-17T16:18:47.956070064Z,10,2,1108,A,A,1,13.46,100,130,166415,287579474,13.11,100,1,13.03,2,1,12.98,200,2,12.86,100,1,12.73,100,1,12.71,100,1,12.5,700,1,12.46,100,1,12.43,700,1,12.42,700,1,13.45,15,1,13.46,100,1,13.47,15,1,13.75,100,1,13.79,2,1,14.01,100,1,14.08,100,1,14.27,100,1,14.28,100,1,14.35,200,2,ARL,345926413
1711,2025-07-17T16:18:51.228439638Z,2025-07-17T16:18:51.228274415Z,10,2,1108,A,A,7,14.18,700,130,165223,287639434,13.11,100,1,13.03,2,1,12.98,200,2,12.86,100,1,12.73,100,1,12.71,100,1,12.5,700,1,12.46,100,1,12.43,700,1,12.42,700,1,13.45,15,1,13.46,100,1,13.47,15,1,13.75,100,1,13.79,2,1,14.01,100,1,14.08,100,1,14.18,700,1,14.27,100,1,14.28,100,1,ARL,345998433
1712,2025-07-17T16:18:57.882365457Z,2025-07-17T16:18:57.882196648Z,10,2,1108,C,A,-1,13.47,15,128,168809,287807679,13.11,100,1,13.03,2,1,12.98,200,2,12.86,100,1,12.73,100,1,12.71,100,1,12.5,700,1,12.46,100,1,12.43,700,1,12.42,700,1,13.45,15,1,13.46,100,1,13.75,100,1,13.79,2,1,14.01,100,1,14.08,100,1,14.18,700,1,14.27,100,1,14.28,100,1,14.35,200,2,ARL,345869437
1713,2025-07-17T16:19:04.990890102Z,2025-07-17T16:19:04.990724544Z,10,2,1108,C,A,-1,13.79,2,0,165558,288025773,13.11,100,1,13.03,2,1,12.98,200,2,12.86,100,1,12.73,100,1,12.71,100,1,12.5,700,1,12.46,100,1,12.43,700,1,12.42,700,1,13.45,15,1,13.46,100,1,13.75,100,1,14.01,100,1,14.08,100,1,14.18,700,1,14.27,100,1,14.28,100,1,14.35,200,2,14.43,200,2,ARL,344765077
1714,2025-07-17T16:19:04.990890102Z,2025-07-17T16:19:04.990724544Z,10,2,1108,A,A,2,13.72,2,130,165558,288025773,13.11,100,1,13.03,2,1,12.98,200,2,12.86,100,1,12.73,100,1,12.71,100,1,12.5,700,1,12.46,100,1,12.43,700,1,12.42,700,1,13.45,15,1,13.46,100,1,13.72,2,1,13.75,100,1,14.01,100,1,14.08,100,1,14.18,700,1,14.27,100,1,14.28,100,1,14.35,200,2,ARL,346423105
1715,2025-07-17T16:19:08.837286193Z,2025-07-17T16:19:08.837120837Z,10,2,1108,A,A,0,13.43,15,130,165356,288088546,13.11,100,1,13.03,2,1,12.98,200,2,12.86,100,1,12.73,100,1,12.71,100,1,12.5,700,1,12.46,100,1,12.43,700,1,12.42,700,1,13.43,15,1,13.45,15,1,13.46,100,1,13.72,2,1,13.75,100,1,14.01,100,1,14.08,100,1,14.18,700,1,14.27,100,1,14.28,100,1,ARL,346492493
1716,2025-07-17T16:19:11.008353202Z,2025-07-17T16:19:11.008187551Z,10,2,1108,C,A,-1,13.46,100,0,165651,288143215,13.11,100,1,13.03,2,1,12.98,200,2,12.86,100,1,12.73,100,1,12.71,100,1,12.5,700,1,12.46,100,1,12.43,700,1,12.42,700,1,13.43,15,1,13.45,15,1,13.72,2,1,13.75,100,1,14.01,100,1,14.08,100,1,14.18,700,1,14.27,100,1,14.28,100,1,14.35,200,2,ARL,345926413
1717,2025-07-17T16:19:11.008353202Z,2025-07-17T16:19:11.008187551Z,10,2,1108,A,A,1,13.44,100,130,165651,288143215,13.11,100,1,13.03,2,1,12.98,200,2,12.86,100,1,12.73,100,1,12.71,100,1,12.5,700,1,12.46,100,1,12.43,700,1,12.42,700,1,13.43,15,1,13.44,100,1,13.45,15,1,13.72,2,1,13.75,100,1,14.01,100,1,14.08,100,1,14.18,700,1,14.27,100,1,14.28,100,1,ARL,346562289
1718,2025-07-17T16:19:20.837507906Z,2025-07-17T16:19:20.837342130Z,10,2,1108,C,A,-1,13.45,15,130,165776,288310746,13.11,100,1,13.03,2,1,12.98,200,2,12.86,100,1,12.73,100,1,12.71,100,1,12.5,700,1,12.46,100,1,12.43,700,1,12.42,700,1,13.43,15,1,13.44,100,1,13.72,2,1,13.75,100,1,14.01,100,1,14.08,100,1,14.18,700,1,14.27,100,1,14.28,100,1,14.35,200,2,ARL,345924181
1719,2025-07-17T16:19:26.654075072Z,2025-07-17T16:19:26.653909048Z,10,2,1108,A,A,0,13.41,15,128,166024,288411319,13.11,100,1,13.03,2,1,12.98,200,2,12.86,100,1,12.73,100,1,12.71,100,1,12.5,700,1,12.46,100,1,12.43,700,1,12.42,700,1,13.41,15,1,13.43,15,1,13.44,100,1,13.72,2,1,13.75,100,1,14.01,100,1,14.08,100,1,14.18,700,1,14.27,100,1,14.28,100,1,ARL,346891037
1720,2025-07-17T16:19:27.200595996Z,2025-07-17T16:19:27.200430092Z,10,2,1108,C,A,-1,13.44,100,0,165904,288424564,13.11,100,1,13.03,2,1,12.98,200,2,12.86,100,1,12.73,100,1,12.71,100,1,12.5,700,1,12.46,100,1,12.43,700,1,12.42,700,1,13.41,15,1,13.43,15,1,13.72,2,1,13.75,100,1,14.01,100,1,14.08,100,1,14.18,700,1,14.27,100,1,14.28,100,1,14.35,200,2,ARL,346562289
1721,2025-07-17T16:19:27.200595996Z,2025-07-17T16:19:27.200430092Z,10,2,1108,A,A,1,13.42,100,130,165904,288424564,13.11,100,1,13.03,2,1,12.98,200,2,12.86,100,1,12.73,100,1,12.71,100,1,12.5,700,1,12.46,100,1,12.43,700,1,12.42,700,1,13.41,15,1,13.42,100,1,13.43,15,1,13.72,2,1,13.75,100,1,14.01,100,1,14.08,100,1,14.18,700,1,14.27,100,1,14.28,100,1,ARL,346904153
1722,2025-07-17T16:19:27.201378249Z,2025-07-17T16:19:27.201212584Z,10,2,1108,A,A,8,14.19,700,130,165665,288424582,13.11,100,1,13.03,2,1,12.98,200,2,12.86,100,1,12.73,100,1,12.71,100,1,12.5,700,1,12.46,100,1,12.43,700,1,12.42,700,1,13.41,15,1,13.42,100,1,13.43,15,1,13.72,2,1,13.75,100,1,14.01,100,1,14.08,100,1,14.18,700,1,14.19,700,1,14.27,100,1,ARL,346904221
1723,2025-07-17T16:19:28.991308227Z,2025-07-17T16:19:28.991142567Z,10,2,1108,C,B,-1,13.03,2,0,165660,288452523,13.11,100,1,12.98,200,2,12.86,100,1,12.73,100,1,12.71,100,1,12.5,700,1,12.46,100,1,12.43,700,1,12.42,700,1,12.37,700,1,13.41,15,1,13.42,100,1,13.43,15,1,13.72,2,1,13.75,100,1,14.01,100,1,14.08,100,1,14.18,700,1,14.19,700,1,14.27,100,1,ARL,343084165
1724,2025-07-17T16:19:28.991308227Z,2025-07-17T16:19:28.991142567Z,10,2,1108,A,B,2,12.95,2,130,165660,288452523,13.11,100,1,12.98,200,2,12.95,2,1,12.86,100,1,12.73,100,1,12.71,100,1,12.5,700,1,12.46,100,1,12.43,700,1,12.42,700,1,13.41,15,1,13.42,100,1,13.43,15,1,13.72,2,1,13.75,100,1,14.01,100,1,14.08,100,1,14.18,700,1,14.19,700,1,14.27,100,1,ARL,346942181
1725,2025-07-17T16:19:30.834459284Z,2025-07-17T16:19:30.834293908Z,10,2,1108,C,A,-1,13.41,15,130,165376,288478995,13.11,100,1,12.98,200,2,12.95,2,1,12.86,100,1,12.73,100,1,12.71,100,1,12.5,700,1,12.46,100,1,12.43,700,1,12.42,700,1,13.42,100,1,13.43,15,1,13.72,2,1,13.75,100,1,14.01,100,1,14.08,100,1,14.18,700,1,14.19,700,1,14.27,100,1,14.28,100,1,ARL,346891037
1726,2025-07-17T16:19:30.835008022Z,2025-07-17T16:19:30.834842536Z,10,2,1108,C,A,-1,13.42,100,130,165486,288479015,13.11,100,1,12.98,200,2,12.95,2,1,12.86,100,1,12.73,100,1,12.71,100,1,12.5,700,1,12.46,100,1,12.43,700,1,12.42,700,1,13.43,15,1,13.72,2,1,13.75,100,1,14.01,100,1,14.08,100,1,14.18,700,1,14.19,700,1,14.27,100,1,14.28,100,1,14.35,200,2,ARL,346904153
1727,2025-07-17T16:19:30.835569072Z,2025-07-17T16:19:30.835403659Z,10,2,1108,C,A,-1,13.43,15,130,165413,288479032,13.11,100,1,12.98,200,2,12.95,2,1,12.86,100,1,12.73,100,1,12.71,100,1,12.5,700,1,12.46,100,1,12.43,700,1,12.42,700,1,13.72,2,1,13.75,100,1,14.01,100,1,14.08,100,1,14.18,700,1,14.19,700,1,14.27,100,1,14.28,100,1,14.35,200,2,14.43,200,2,ARL,346492493
1728,2025-07-17T16:19:32.547487183Z,2025-07-17T16:19:32.547320695Z,10,2,1108,C,A,-1,14.18,700,130,166488,288512762,13.11,100,1,12.98,200,2,12.95,2,1,12.86,100,1,12.73,100,1,12.71,100,1,12.5,700,1,12.46,100,1,12.43,700,1,12.42,700,1,13.72,2,1,13.75,100,1,14.01,100,1,14.08,100,1,14.19,700,1,14.27,100,1,14.28,100,1,14.35,200,2,14.43,200,2,14.48,800,2,ARL,345998433
1729,2025-07-17T16:19:32.547527626Z,2025-07-17T16:19:32.547362298Z,10,2,1108,A,A,9,14.44,700,130,165328,288512763,13.11,100,1,12.98,200,2,12.95,2,1,12.86,100,1,12.73,100,1,12.71,100,1,12.5,700,1,12.46,100,1,12.43,700,1,12.42,700,1,13.72,2,1,13.75,100,1,14.01,100,1,14.08,100,1,14.19,700,1,14.27,100,1,14.28,100,1,14.35,200,2,14.43,200,2,14.44,700,1,ARL,347022701
1730,2025-07-17T16:19:32.548069205Z,2025-07-17T16:19:32.547904024Z,10,2,1108,C,A,-1,14.08,100,130,165181,288512768,13.11,100,1,12.98,200,2,12.95,2,1,12.86,100,1,12.73,100,1,12.71,100,1,12.5,700,1,12.46,100,1,12.43,700,1,12.42,700,1,13.72,2,1,13.75,100,1,14.01,100,1,14.19,700,1,14.27,100,1,14.28,100,1,14.35,200,2,14.43,200,2,14.44,700,1,14.48,800,2,ARL,345889165
1731,2025-07-17T16:19:32.548096238Z,2025-07-17T16:19:32.547930966Z,10,2,1108,C,A,-1,14.19,700,130,165272,288512769,13.11,100,1,12.98,200,2,12.95,2,1,12.86,100,1,12.73,100,1,12.71,100,1,12.5,700,1,12.46,100,1,12.43,700,1,12.42,700,1,13.72,2,1,13.75,100,1,14.01,100,1,14.27,100,1,14.28,100,1,14.35,200,2,14.43,200,2,14.44,700,1,14.48,800,2,14.54,700,1,ARL,346904221
1732,2025-07-17T16:19:32.548113549Z,2025-07-17T16:19:32.547947865Z,10,2,1108,C,A,8,14.48,100,0,165684,288512770,13.11,100,1,12.98,200,2,12.95,2,1,12.86,100,1,12.73,100,1,12.71,100,1,12.5,700,1,12.46,100,1,12.43,700,1,12.42,700,1,13.72,2,1,13.75,100,1,14.01,100,1,14.27,100,1,14.28,100,1,14.35,200,2,14.43,200,2,14.44,700,1,14.48,700,1,14.54,700,1,ARL,346562329
1733,2025-07-17T16:19:32.548423905Z,2025-07-17T16:19:32.548258519Z,10,2,1108,A,A,6,14.36,100,130,165386,288512772,13.11,100,1,12.98,200,2,12.95,2,1,12.86,100,1,12.73,100,1,12.71,100,1,12.5,700,1,12.46,100,1,12.43,700,1,12.42,700,1,13.72,2,1,13.75,100,1,14.01,100,1,14.27,100,1,14.28,100,1,14.35,200,2,14.36,100,1,14.43,200,2,14.44,700,1,14.48,700,1,ARL,347022741
1734,2025-07-17T16:19:32.548503722Z,2025-07-17T16:19:32.548338068Z,10,2,1108,A,A,9,14.48,700,130,165654,288512773,13.11,100,1,12.98,200,2,12.95,2,1,12.86,100,1,12.73,100,1,12.71,100,1,12.5,700,1,12.46,100,1,12.43,700,1,12.42,700,1,13.72,2,1,13.75,100,1,14.01,100,1,14.27,100,1,14.28,100,1,14.35,200,2,14.36,100,1,14.43,200,2,14.44,700,1,14.48,1400,2,ARL,347022749
1735,2025-07-17T16:19:32.549166752Z,2025-07-17T16:19:32.549001387Z,10,2,1108,C,A,-1,14.27,100,0,165365,288512787,13.11,100,1,12.98,200,2,12.95,2,1,12.86,100,1,12.73,100,1,12.71,100,1,12.5,700,1,12.46,100,1,12.43,700,1,12.42,700,1,13.72,2,1,13.75,100,1,14.01,100,1,14.28,100,1,14.35,200,2,14.36,100,1,14.43,200,2,14.44,700,1,14.48,1400,2,14.54,700,1,ARL,345889277
1736,2025-07-17T16:19:32.549166752Z,2025-07-17T16:19:32.549001387Z,10,2,1108,A,A,9,14.54,100,130,165365,288512787,13.11,100,1,12.98,200,2,12.95,2,1,12.86,100,1,12.73,100,1,12.71,100,1,12.5,700,1,12.46,100,1,12.43,700,1,12.42,700,1,13.72,2,1,13.75,100,1,14.01,100,1,14.28,100,1,14.35,200,2,14.36,100,1,14.43,200,2,14.44,700,1,14.48,1400,2,14.54,800,2,ARL,347022789
1737,2025-07-17T16:19:32.549433234Z,2025-07-17T16:19:32.549267465Z,10,2,1108,C,A,6,14.43,100,0,165769,288512789,13.11,100,1,12.98,200,2,12.95,2,1,12.86,100,1,12.73,100,1,12.71,100,1,12.5,700,1,12.46,100,1,12.43,700,1,12.42,700,1,13.72,2,1,13.75,100,1,14.01,100,1,14.28,100,1,14.35,200,2,14.36,100,1,14.43,100,1,14.44,700,1,14.48,1400,2,14.54,800,2,ARL,345889201
1738,2025-07-17T16:19:32.554564549Z,2025-07-17T16:19:32.554398971Z,10,2,1108,C,A,-1,14.43,100,0,165578,288512857,13.11,100,1,12.98,200,2,12.95,2,1,12.86,100,1,12.73,100,1,12.71,100,1,12.5,700,1,12.46,100,1,12.43,700,1,12.42,700,1,13.72,2,1,13.75,100,1,14.01,100,1,14.28,100,1,14.35,200,2,14.36,100,1,14.44,700,1,14.48,1400,2,14.54,800,2,14.72,100,1,ARL,345889189
1739,2025-07-17T16:19:32.554564549Z,2025-07-17T16:19:32.554398971Z,10,2,1108,A,A,9,14.72,100,130,165578,288512857,13.11,100,1,12.98,200,2,12.95,2,1,12.86,100,1,12.73,100,1,12.71,100,1,12.5,700,1,12.46,100,1,12.43,700,1,12.42,700,1,13.72,2,1,13.75,100,1,14.01,100,1,14.28,100,1,14.35,200,2,14.36,100,1,14.44,700,1,14.48,1400,2,14.54,800,2,14.72,200,2,ARL,347022893
1740,2025-07-17T16:19:32.566140694Z,2025-07-17T16:19:32.565975313Z,10,2,1108,C,A,-1,13.75,100,130,165381,288512959,13.11,100,1,12.98,200,2,12.95,2,1,12.86,100,1,12.73,100,1,12.71,100,1,12.5,700,1,12.46,100,1,12.43,700,1,12.42,700,1,13.72,2,1,14.01,100,1,14.28,100,1,14.35,200,2,14.36,100,1,14.44,700,1,14.48,1400,2,14.54,800,2,14.72,200,2,14.82,100,1,ARL,345889457
1741,2025-07-17T16:19:32.566174380Z,2025-07-17T16:19:32.566009468Z,10,2,1108,C,A,-1,14.44,700,130,164912,288512961,13.11,100,1,12.98,200,2,12.95,2,1,12.86,100,1,12.73,100,1,12.71,100,1,12.5,700,1,12.46,100,1,12.43,700,1,12.42,700,1,13.72,2,1,14.01,100,1,14.28,100,1,14.35,200,2,14.36,100,1,14.48,1400,2,14.54,800,2,14.72,200,2,14.82,100,1,15.13,200,2,ARL,347022701
1742,2025-07-17T16:19:32.566193866Z,2025-07-17T16:19:32.566028302Z,10,2,1108,A,A,2,14.03,100,130,165564,288512962,13.11,100,1,12.98,200,2,12.95,2,1,12.86,100,1,12.73,100,1,12.71,100,1,12.5,700,1,12.46,100,1,12.43,700,1,12.42,700,1,13.72,2,1,14.01,100,1,14.03,100,1,14.28,100,1,14.35,200,2,14.36,100,1,14.48,1400,2,14.54,800,2,14.72,200,2,14.82,100,1,ARL,347023005
1743,2025-07-17T16:19:32.567048160Z,2025-07-17T16:19:32.566882768Z,10,2,1108,C,A,8,14.72,100,0,165392,288512963,13.11,100,1,12.98,200,2,12.95,2,1,12.86,100,1,12.73,100,1,12.71,100,1,12.5,700,1,12.46,100,1,12.43,700,1,12.42,700,1,13.72,2,1,14.01,100,1,14.03,100,1,14.28,100,1,14.35,200,2,14.36,100,1,14.48,1400,2,14.54,800,2,14.72,100,1,14.82,100,1,ARL,347022893
1744,2025-07-17T16:19:32.567981668Z,2025-07-17T16:19:32.567816385Z,10,2,1108,C,A,-1,14.72,100,0,165283,288512969,13.11,100,1,12.98,200,2,12.95,2,1,12.86,100,1,12.73,100,1,12.71,100,1,12.5,700,1,12.46,100,1,12.43,700,1,12.42,700,1,13.72,2,1,14.01,100,1,14.03,100,1,14.28,100,1,14.35,200,2,14.36,100,1,14.48,1400,2,14.54,800,2,14.82,100,1,14.95,100,1,ARL,347022797
1745,2025-07-17T16:19:32.568776675Z,2025-07-17T16:19:32.568611131Z,10,2,1108,C,A,-1,13.72,2,0,165544,288512974,13.11,100,1,12.98,200,2,12.95,2,1,12.86,100,1,12.73,100,1,12.71,100,1,12.5,700,1,12.46,100,1,12.43,700,1,12.42,700,1,14.01,100,1,14.03,100,1,14.28,100,1,14.35,200,2,14.36,100,1,14.48,1400,2,14.54,800,2,14.82,100,1,14.95,100,1,14.96,100,1,ARL,346423105
1746,2025-07-17T16:19:32.568776675Z,2025-07-17T16:19:32.568611131Z,10,2,1108,A,A,0,13.98,2,130,165544,288512974,13.11,100,1,12.98,200,2,12.95,2,1,12.86,100,1,12.73,100,1,12.71,100,1,12.5,700,1,12.46,100,1,12.43,700,1,12.42,700,1,13.98,2,1,14.01,100,1,14.03,100,1,14.28,100,1,14.35,200,2,14.36,100,1,14.48,1400,2,14.54,800,2,14.82,100,1,14.95,100,1,ARL,347023061
1747,2025-07-17T16:19:32.586782162Z,2025-07-17T16:19:32.586617069Z,10,2,1108,C,A,-1,14.03,100,130,165093,288513024,13.11,100,1,12.98,200,2,12.95,2,1,12.86,100,1,12.73,100,1,12.71,100,1,12.5,700,1,12.46,100,1,12.43,700,1,12.42,700,1,13.98,2,1,14.01,100,1,14.28,100,1,14.35,200,2,14.36,100,1,14.48,1400,2,14.54,800,2,14.82,100,1,14.95,100,1,14.96,100,1,ARL,347023005
1748,2025-07-17T16:19:32.586832073Z,2025-07-17T16:19:32.586666869Z,10,2,1108,A,A,2,14.25,100,130,165204,288513026,13.11,100,1,12.98,200,2,12.95,2,1,12.86,100,1,12.73,100,1,12.71,100,1,12.5,700,1,12.46,100,1,12.43,700,1,12.42,700,1,13.98,2,1,14.01,100,1,14.25,100,1,14.28,100,1,14.35,200,2,14.36,100,1,14.48,1400,2,14.54,800,2,14.82,100,1,14.95,100,1,ARL,347023197
1749,2025-07-17T16:19:32.597958839Z,2025-07-17T16:19:32.597793442Z,10,2,1108,C,A,-1,14.82,100,0,165397,288513278,13.11,100,1,12.98,200,2,12.95,2,1,12.86,100,1,12.73,100,1,12.71,100,1,12.5,700,1,12.46,100,1,12.43,700,1,12.42,700,1,13.98,2,1,14.01,100,1,14.25,100,1,14.28,100,1,14.35,200,2,14.36,100,1,14.48,1400,2,14.54,800,2,14.95,100,1,14.96,100,1,ARL,347022737
1750,2025-07-17T16:19:32.602447841Z,2025-07-17T16:19:32.602282571Z,10,2,1108,A,A,8,14.68,700,130,165270,288513328,13.11,100,1,12.98,200,2,12.95,2,1,12.86,100,1,12.73,100,1,12.71,100,1,12.5,700,1,12.46,100,1,12.43,700,1,12.42,700,1,13.98,2,1,14.01,100,1,14.25,100,1,14.28,100,1,14.35,200,2,14.36,100,1,14.48,1400,2,14.54,800,2,14.68,700,1,14.95,100,1,ARL,347023357
1751,2025-07-17T16:19:32.706223822Z,2025-07-17T16:19:32.706057444Z,10,2,1108,A,A,7,14.53,100,0,166378,288514904,13.11,100,1,12.98,200,2,12.95,2,1,12.86,100,1,12.73,100,1,12.71,100,1,12.5,700,1,12.46,100,1,12.43,700,1,12.42,700,1,13.98,2,1,14.01,100,1,14.25,100,1,14.28,100,1,14.35,200,2,14.36,100,1,14.48,1400,2,14.53,100,1,14.54,800,2,14.68,700,1,ARL,347025333
1752,2025-07-17T16:19:32.706223822Z,2025-07-17T16:19:32.706057831Z,10,2,1108,C,A,-1,14.01,100,130,165991,288514905,13.11,100,1,12.98,200,2,12.95,2,1,12.86,100,1,12.73,100,1,12.71,100,1,12.5,700,1,12.46,100,1,12.43,700,1,12.42,700,1,13.98,2,1,14.25,100,1,14.28,100,1,14.35,200,2,14.36,100,1,14.48,1400,2,14.53,100,1,14.54,800,2,14.68,700,1,14.95,100,1,ARL,345911213
1753,2025-07-17T16:19:32.857787299Z,2025-07-17T16:19:32.857621837Z,10,2,1108,A,A,9,14.81,100,130,165462,288516573,13.11,100,1,12.98,200,2,12.95,2,1,12.86,100,1,12.73,100,1,12.71,100,1,12.5,700,1,12.46,100,1,12.43,700,1,12.42,700,1,13.98,2,1,14.25,100,1,14.28,100,1,14.35,200,2,14.36,100,1,14.48,1400,2,14.53,100,1,14.54,800,2,14.68,700,1,14.81,100,1,ARL,347027121
1754,2025-07-17T16:19:32.857804235Z,2025-07-17T16:19:32.857638959Z,10,2,1108,C,A,-1,14.28,100,130,165276,288516574,13.11,100,1,12.98,200,2,12.95,2,1,12.86,100,1,12.73,100,1,12.71,100,1,12.5,700,1,12.46,100,1,12.43,700,1,12.42,700,1,13.98,2,1,14.25,100,1,14.35,200,2,14.36,100,1,14.48,1400,2,14.53,100,1,14.54,800,2,14.68,700,1,14.81,100,1,14.95,100,1,ARL,345903265
1755,2025-07-17T16:19:32.887058748Z,2025-07-17T16:19:32.886893433Z,10,2,1108,A,A,1,13.99,100,130,165315,288519618,13.11,100,1,12.98,200,2,12.95,2,1,12.86,100,1,12.73,100,1,12.71,100,1,12.5,700,1,12.46,100,1,12.43,700,1,12.42,700,1,13.98,2,1,13.99,100,1,14.25,100,1,14.35,200,2,14.36,100,1,14.48,1400,2,14.53,100,1,14.54,800,2,14.68,700,1,14.81,100,1,ARL,347030085
1756,2025-07-17T16:19:33.241360545Z,2025-07-17T16:19:33.241195095Z,10,2,1108,C,A,-1,14.36,100,130,165450,288533108,13.11,100,1,12.98,200,2,12.95,2,1,12.86,100,1,12.73,100,1,12.71,100,1,12.5,700,1,12.46,100,1,12.43,700,1,12.42,700,1,13.98,2,1,13.99,100,1,14.25,100,1,14.35,200,2,14.48,1400,2,14.53,100,1,14.54,800,2,14.68,700,1,14.81,100,1,14.95,100,1,ARL,347022741
1757,2025-07-17T16:19:33.241714286Z,2025-07-17T16:19:33.241548838Z,10,2,1108,A,A,7,14.6,100,130,165448,288533114,13.11,100,1,12.98,200,2,12.95,2,1,12.86,100,1,12.73,100,1,12.71,100,1,12.5,700,1,12.46,100,1,12.43,700,1,12.42,700,1,13.98,2,1,13.99,100,1,14.25,100,1,14.35,200,2,14.48,1400,2,14.53,100,1,14.54,800,2,14.6,100,1,14.68,700,1,14.81,100,1,ARL,347045237
1758,2025-07-17T16:19:33.550443222Z,2025-07-17T16:19:33.550277249Z,10,2,1108,C,A,6,14.54,100,130,165973,288537856,13.11,100,1,12.98,200,2,12.95,2,1,12.86,100,1,12.73,100,1,12.71,100,1,12.5,700,1,12.46,100,1,12.43,700,1,12.42,700,1,13.98,2,1,13.99,100,1,14.25,100,1,14.35,200,2,14.48,1400,2,14.53,100,1,14.54,700,1,14.6,100,1,14.68,700,1,14.81,100,1,ARL,347022789
1759,2025-07-17T16:19:33.550630659Z,2025-07-17T16:19:33.550465490Z,10,2,1108,A,A,9,14.77,100,130,165169,288537857,13.11,100,1,12.98,200,2,12.95,2,1,12.86,100,1,12.73,100,1,12.71,100,1,12.5,700,1,12.46,100,1,12.43,700,1,12.42,700,1,13.98,2,1,13.99,100,1,14.25,100,1,14.35,200,2,14.48,1400,2,14.53,100,1,14.54,700,1,14.6,100,1,14.68,700,1,14.77,100,1,ARL,347052337
1760,2025-07-17T16:19:42.789662492Z,2025-07-17T16:19:42.789496729Z,10,2,1108,C,B,-1,12.95,2,0,165763,288669878,13.11,100,1,12.98,200,2,12.86,100,1,12.73,100,1,12.71,100,1,12.5,700,1,12.46,100,1,12.43,700,1,12.42,700,1,12.37,700,1,13.98,2,1,13.99,100,1,14.25,100,1,14.35,200,2,14.48,1400,2,14.53,100,1,14.54,700,1,14.6,100,1,14.68,700,1,14.77,100,1,ARL,346942181
1761,2025-07-17T16:19:42.789662492Z,2025-07-17T16:19:42.789496729Z,10,2,1108,A,B,1,13.03,2,130,165763,288669878,13.11,100,1,13.03,2,1,12.98,200,2,12.86,100,1,12.73,100,1,12.71,100,1,12.5,700,1,12.46,100,1,12.43,700,1,12.42,700,1,13.98,2,1,13.99,100,1,14.25,100,1,14.35,200,2,14.48,1400,2,14.53,100,1,14.54,700,1,14.6,100,1,14.68,700,1,14.77,100,1,ARL,347220093
1762,2025-07-17T16:19:50.837886219Z,2025-07-17T16:19:50.837720648Z,10,2,1108,A,A,0,13.44,15,130,165571,288783555,13.11,100,1,13.03,2,1,12.98,200,2,12.86,100,1,12.73,100,1,12.71,100,1,12.5,700,1,12.46,100,1,12.43,700,1,12.42,700,1,13.44,15,1,13.98,2,1,13.99,100,1,14.25,100,1,14.35,200,2,14.48,1400,2,14.53,100,1,14.54,700,1,14.6,100,1,14.68,700,1,ARL,347377693
1763,2025-07-17T16:19:51.986999699Z,2025-07-17T16:19:51.986834012Z,10,2,1108,C,A,-1,13.99,100,0,165687,288797308,13.11,100,1,13.03,2,1,12.98,200,2,12.86,100,1,12.73,100,1,12.71,100,1,12.5,700,1,12.46,100,1,12.43,700,1,12.42,700,1,13.44,15,1,13.98,2,1,14.25,100,1,14.35,200,2,14.48,1400,2,14.53,100,1,14.54,700,1,14.6,100,1,14.68,700,1,14.77,100,1,ARL,347030085
1764,2025-07-17T16:19:51.986999699Z,2025-07-17T16:19:51.986834012Z,10,2,1108,A,A,1,13.45,100,130,165687,288797308,13.11,100,1,13.03,2,1,12.98,200,2,12.86,100,1,12.73,100,1,12.71,100,1,12.5,700,1,12.46,100,1,12.43,700,1,12.42,700,1,13.44,15,1,13.45,100,1,13.98,2,1,14.25,100,1,14.35,200,2,14.48,1400,2,14.53,100,1,14.54,700,1,14.6,100,1,14.68,700,1,ARL,347396033
1765,2025-07-17T16:19:51.987738024Z,2025-07-17T16:19:51.987571652Z,10,2,1108,C,A,-1,14.6,100,128,166372,288797316,13.11,100,1,13.03,2,1,12.98,200,2,12.86,100,1,12.73,100,1,12.71,100,1,12.5,700,1,12.46,100,1,12.43,700,1,12.42,700,1,13.44,15,1,13.45,100,1,13.98,2,1,14.25,100,1,14.35,200,2,14.48,1400,2,14.53,100,1,14.54,700,1,14.68,700,1,14.77,100,1,ARL,347045237
1766,2025-07-17T16:19:51.987743715Z,2025-07-17T16:19:51.987578278Z,10,2,1108,A,A,6,14.49,100,130,165437,288797318,13.11,100,1,13.03,2,1,12.98,200,2,12.86,100,1,12.73,100,1,12.71,100,1,12.5,700,1,12.46,100,1,12.43,700,1,12.42,700,1,13.44,15,1,13.45,100,1,13.98,2,1,14.25,100,1,14.35,200,2,14.48,1400,2,14.49,100,1,14.53,100,1,14.54,700,1,14.68,700,1,ARL,347396065
1767,2025-07-17T16:19:51.988088818Z,2025-07-17T16:19:51.987923621Z,10,2,1108,A,A,3,14.05,100,130,165197,288797336,13.11,100,1,13.03,2,1,12.98,200,2,12.86,100,1,12.73,100,1,12.71,100,1,12.5,700,1,12.46,100,1,12.43,700,1,12.42,700,1,13.44,15,1,13.45,100,1,13.98,2,1,14.05,100,1,14.25,100,1,14.35,200,2,14.48,1400,2,14.49,100,1,14.53,100,1,14.54,700,1,ARL,347396069
1768,2025-07-17T16:19:51.989180674Z,2025-07-17T16:19:51.989015100Z,10,2,1108,A,A,6,14.4,100,130,165574,288797340,13.11,100,1,13.03,2,1,12.98,200,2,12.86,100,1,12.73,100,1,12.71,100,1,12.5,700,1,12.46,100,1,12.43,700,1,12.42,700,1,13.44,15,1,13.45,100,1,13.98,2,1,14.05,100,1,14.25,100,1,14.35,200,2,14.4,100,1,14.48,1400,2,14.49,100,1,14.53,100,1,ARL,347396085
1769,2025-07-17T16:19:51.990825106Z,2025-07-17T16:19:51.990659712Z,10,2,1108,C,A,-1,13.98,2,0,165394,288797388,13.11,100,1,13.03,2,1,12.98,200,2,12.86,100,1,12.73,100,1,12.71,100,1,12.5,700,1,12.46,100,1,12.43,700,1,12.42,700,1,13.44,15,1,13.45,100,1,14.05,100,1,14.25,100,1,14.35,200,2,14.4,100,1,14.48,1400,2,14.49,100,1,14.53,100,1,14.54,700,1,ARL,347023061
1770,2025-07-17T16:19:51.990825106Z,2025-07-17T16:19:51.990659712Z,10,2,1108,A,A,2,13.86,2,130,165394,288797388,13.11,100,1,13.03,2,1,12.98,200,2,12.86,100,1,12.73,100,1,12.71,100,1,12.5,700,1,12.46,100,1,12.43,700,1,12.42,700,1,13.44,15,1,13.45,100,1,13.86,2,1,14.05,100,1,14.25,100,1,14.35,200,2,14.4,100,1,14.48,1400,2,14.49,100,1,14.53,100,1,ARL,347396177
1771,2025-07-17T16:19:52.000587632Z,2025-07-17T16:19:52.000421983Z,10,2,1108,C,A,-1,14.25,100,130,165649,288797576,13.11,100,1,13.03,2,1,12.98,200,2,12.86,100,1,12.73,100,1,12.71,100,1,12.5,700,1,12.46,100,1,12.43,700,1,12.42,700,1,13.44,15,1,13.45,100,1,13.86,2,1,14.05,100,1,14.35,200,2,14.4,100,1,14.48,1400,2,14.49,100,1,14.53,100,1,14.54,700,1,ARL,347023197
1772,2025-07-17T16:19:52.000639640Z,2025-07-17T16:19:52.000474403Z,10,2,1108,A,A,2,13.72,100,130,165237,288797577,13.11,100,1,13.03,2,1,12.98,200,2,12.86,100,1,12.73,100,1,12.71,100,1,12.5,700,1,12.46,100,1,12.43,700,1,12.42,700,1,13.44,15,1,13.45,100,1,13.72,100,1,13.86,2,1,14.05,100,1,14.35,200,2,14.4,100,1,14.48,1400,2,14.49,100,1,14.53,100,1,ARL,347396369
1773,2025-07-17T16:19:52.007405432Z,2025-07-17T16:19:52.007240010Z,10,2,1108,A,A,6,14.4,100,130,165422,288797725,13.11,100,1,13.03,2,1,12.98,200,2,12.86,100,1,12.73,100,1,12.71,100,1,12.5,700,1,12.46,100,1,12.43,700,1,12.42,700,1,13.44,15,1,13.45,100,1,13.72,100,1,13.86,2,1,14.05,100,1,14.35,200,2,14.4,200,2,14.48,1400,2,14.49,100,1,14.53,100,1,ARL,347396549
1774,2025-07-17T16:19:52.051786264Z,2025-07-17T16:19:52.051620731Z,10,2,1108,A,A,5,14.24,100,130,165533,288798183,13.11,100,1,13.03,2,1,12.98,200,2,12.86,100,1,12.73,100,1,12.71,100,1,12.5,700,1,12.46,100,1,12.43,700,1,12.42,700,1,13.44,15,1,13.45,100,1,13.72,100,1,13.86,2,1,14.05,100,1,14.24,100,1,14.35,200,2,14.4,200,2,14.48,1400,2,14.49,100,1,ARL,347397201
1775,2025-07-17T16:19:52.565796243Z,2025-07-17T16:19:52.565630623Z,10,2,1108,A,A,6,14.25,100,130,165620,288804470,13.11,100,1,13.03,2,1,12.98,200,2,12.86,100,1,12.73,100,1,12.71,100,1,12.5,700,1,12.46,100,1,12.43,700,1,12.42,700,1,13.44,15,1,13.45,100,1,13.72,100,1,13.86,2,1,14.05,100,1,14.24,100,1,14.25,100,1,14.35,200,2,14.4,200,2,14.48,1400,2,ARL,347404325
1776,2025-07-17T16:19:52.662889593Z,2025-07-17T16:19:52.662723196Z,10,2,1108,A,A,4,13.98,100,0,166397,288807539,13.11,100,1,13.03,2,1,12.98,200,2,12.86,100,1,12.73,100,1,12.71,100,1,12.5,700,1,12.46,100,1,12.43,700,1,12.42,700,1,13.44,15,1,13.45,100,1,13.72,100,1,13.86,2,1,13.98,100,1,14.05,100,1,14.24,100,1,14.25,100,1,14.35,200,2,14.4,200,2,ARL,347406169
1777,2025-07-17T16:19:53.670698618Z,2025-07-17T16:19:53.670533326Z,10,2,1108,C,A,-1,13.45,100,130,165292,288824717,13.11,100,1,13.03,2,1,12.98,200,2,12.86,100,1,12.73,100,1,12.71,100,1,12.5,700,1,12.46,100,1,12.43,700,1,12.42,700,1,13.44,15,1,13.72,100,1,13.86,2,1,13.98,100,1,14.05,100,1,14.24,100,1,14.25,100,1,14.35,200,2,14.4,200,2,14.48,1400,2,ARL,347396033
1778,2025-07-17T16:19:53.671446392Z,2025-07-17T16:19:53.671281229Z,10,2,1108,C,A,-1,14.05,100,130,165163,288824751,13.11,100,1,13.03,2,1,12.98,200,2,12.86,100,1,12.73,100,1,12.71,100,1,12.5,700,1,12.46,100,1,12.43,700,1,12.42,700,1,13.44,15,1,13.72,100,1,13.86,2,1,13.98,100,1,14.24,100,1,14.25,100,1,14.35,200,2,14.4,200,2,14.48,1400,2,14.54,700,1,ARL,347396069
1779,2025-07-17T16:19:53.671794970Z,2025-07-17T16:19:53.671629711Z,10,2,1108,A,A,6,14.33,100,130,165259,288824753,13.11,100,1,13.03,2,1,12.98,200,2,12.86,100,1,12.73,100,1,12.71,100,1,12.5,700,1,12.46,100,1,12.43,700,1,12.42,700,1,13.44,15,1,13.72,100,1,13.86,2,1,13.98,100,1,14.24,100,1,14.25,100,1,14.33,100,1,14.35,200,2,14.4,200,2,14.48,1400,2,ARL,347422225
1780,2025-07-17T16:19:53.673048826Z,2025-07-17T16:19:53.672883433Z,10,2,1108,C,A,8,14.4,100,0,165393,288824777,13.11,100,1,13.03,2,1,12.98,200,2,12.86,100,1,12.73,100,1,12.71,100,1,12.5,700,1,12.46,100,1,12.43,700,1,12.42,700,1,13.44,15,1,13.72,100,1,13.86,2,1,13.98,100,1,14.24,100,1,14.25,100,1,14.33,100,1,14.35,200,2,14.4,100,1,14.48,1400,2,ARL,347396085
1781,2025-07-17T16:19:53.673442999Z,2025-07-17T16:19:53.673277621Z,10,2,1108,C,A,-1,14.24,100,130,165378,288824780,13.11,100,1,13.03,2,1,12.98,200,2,12.86,100,1,12.73,100,1,12.71,100,1,12.5,700,1,12.46,100,1,12.43,700,1,12.42,700,1,13.44,15,1,13.72,100,1,13.86,2,1,13.98,100,1,14.25,100,1,14.33,100,1,14.35,200,2,14.4,100,1,14.48,1400,2,14.54,700,1,ARL,347397201
1782,2025-07-17T16:19:53.673563265Z,2025-07-17T16:19:53.673398019Z,10,2,1108,A,A,9,14.51,100,130,165246,288824781,13.11,100,1,13.03,2,1,12.98,200,2,12.86,100,1,12.73,100,1,12.71,100,1,12.5,700,1,12.46,100,1,12.43,700,1,12.42,700,1,13.44,15,1,13.72,100,1,13.86,2,1,13.98,100,1,14.25,100,1,14.33,100,1,14.35,200,2,14.4,100,1,14.48,1400,2,14.51,100,1,ARL,347422249
1783,2025-07-17T16:19:53.675414447Z,2025-07-17T16:19:53.675249213Z,10,2,1108,C,A,-1,13.72,100,130,165234,288824805,13.11,100,1,13.03,2,1,12.98,200,2,12.86,100,1,12.73,100,1,12.71,100,1,12.5,700,1,12.46,100,1,12.43,700,1,12.42,700,1,13.44,15,1,13.86,2,1,13.98,100,1,14.25,100,1,14.33,100,1,14.35,200,2,14.4,100,1,14.48,1400,2,14.51,100,1,14.54,700,1,ARL,347396369
1784,2025-07-17T16:19:53.675466833Z,2025-07-17T16:19:53.675301684Z,10,2,1108,A,A,3,13.99,100,130,165149,288824807,13.11,100,1,13.03,2,1,12.98,200,2,12.86,100,1,12.73,100,1,12.71,100,1,12.5,700,1,12.46,100,1,12.43,700,1,12.42,700,1,13.44,15,1,13.86,2,1,13.98,100,1,13.99,100,1,14.25,100,1,14.33,100,1,14.35,200,2,14.4,100,1,14.48,1400,2,14.51,100,1,ARL,347422265
1785,2025-07-17T16:19:53.679633024Z,2025-07-17T16:19:53.679468070Z,10,2,1108,C,A,-1,13.99,100,130,164954,288824919,13.11,100,1,13.03,2,1,12.98,200,2,12.86,100,1,12.73,100,1,12.71,100,1,12.5,700,1,12.46,100,1,12.43,700,1,12.42,700,1,13.44,15,1,13.86,2,1,13.98,100,1,14.25,100,1,14.33,100,1,14.35,200,2,14.4,100,1,14.48,1400,2,14.51,100,1,14.54,700,1,ARL,347422265
1786,2025-07-17T16:19:53.679682575Z,2025-07-17T16:19:53.679517110Z,10,2,1108,A,A,3,14.22,100,130,165465,288824921,13.11,100,1,13.03,2,1,12.98,200,2,12.86,100,1,12.73,100,1,12.71,100,1,12.5,700,1,12.46,100,1,12.43,700,1,12.42,700,1,13.44,15,1,13.86,2,1,13.98,100,1,14.22,100,1,14.25,100,1,14.33,100,1,14.35,200,2,14.4,100,1,14.48,1400,2,14.51,100,1,ARL,347422365
1787,2025-07-17T16:19:53.718084751Z,2025-07-17T16:19:53.717918994Z,10,2,1108,C,A,-1,14.4,100,0,165757,288827326,13.11,100,1,13.03,2,1,12.98,200,2,12.86,100,1,12.73,100,1,12.71,100,1,12.5,700,1,12.46,100,1,12.43,700,1,12.42,700,1,13.44,15,1,13.86,2,1,13.98,100,1,14.22,100,1,14.25,100,1,14.33,100,1,14.35,200,2,14.48,1400,2,14.51,100,1,14.54,700,1,ARL,347396549
1788,2025-07-17T16:19:54.211876077Z,2025-07-17T16:19:54.211710788Z,10,2,1108,C,A,-1,14.25,100,130,165289,288836876,13.11,100,1,13.03,2,1,12.98,200,2,12.86,100,1,12.73,100,1,12.71,100,1,12.5,700,1,12.46,100,1,12.43,700,1,12.42,700,1,13.44,15,1,13.86,2,1,13.98,100,1,14.22,100,1,14.33,100,1,14.35,200,2,14.48,1400,2,14.51,100,1,14.54,700,1,14.68,700,1,ARL,347404325
1789,2025-07-17T16:19:54.248985468Z,2025-07-17T16:19:54.248820201Z,10,2,1108,C,A,-1,14.33,100,130,165267,288837261,13.11,100,1,13.03,2,1,12.98,200,2,12.86,100,1,12.73,100,1,12.71,100,1,12.5,700,1,12.46,100,1,12.43,700,1,12.42,700,1,13.44,15,1,13.86,2,1,13.98,100,1,14.22,100,1,14.35,200,2,14.48,1400,2,14.51,100,1,14.54,700,1,14.68,700,1,14.81,100,1,ARL,347422225
1790,2025-07-17T16:19:54.249335716Z,2025-07-17T16:19:54.249170165Z,10,2,1108,A,A,8,14.6,100,130,165551,288837262,13.11,100,1,13.03,2,1,12.98,200,2,12.86,100,1,12.73,100,1,12.71,100,1,12.5,700,1,12.46,100,1,12.43,700,1,12.42,700,1,13.44,15,1,13.86,2,1,13.98,100,1,14.22,100,1,14.35,200,2,14.48,1400,2,14.51,100,1,14.54,700,1,14.6,100,1,14.68,700,1,ARL,347437857
1791,2025-07-17T16:19:54.601852935Z,2025-07-17T16:19:54.601687713Z,10,2,1108,C,A,-1,13.98,100,130,165222,288841783,13.11,100,1,13.03,2,1,12.98,200,2,12.86,100,1,12.73,100,1,12.71,100,1,12.5,700,1,12.46,100,1,12.43,700,1,12.42,700,1,13.44,15,1,13.86,2,1,14.22,100,1,14.35,200,2,14.48,1400,2,14.51,100,1,14.54,700,1,14.6,100,1,14.68,700,1,14.81,100,1,ARL,347406169
1792,2025-07-17T16:19:54.601853940Z,2025-07-17T16:19:54.601688695Z,10,2,1108,A,A,6,14.53,100,130,165245,288841784,13.11,100,1,13.03,2,1,12.98,200,2,12.86,100,1,12.73,100,1,12.71,100,1,12.5,700,1,12.46,100,1,12.43,700,1,12.42,700,1,13.44,15,1,13.86,2,1,14.22,100,1,14.35,200,2,14.48,1400,2,14.51,100,1,14.53,100,1,14.54,700,1,14.6,100,1,14.68,700,1,ARL,347443097
1793,2025-07-17T16:19:54.677250454Z,2025-07-17T16:19:54.677084975Z,10,2,1108,C,A,-1,14.51,100,0,165479,288842530,13.11,100,1,13.03,2,1,12.98,200,2,12.86,100,1,12.73,100,1,12.71,100,1,12.5,700,1,12.46,100,1,12.43,700,1,12.42,700,1,13.44,15,1,13.86,2,1,14.22,100,1,14.35,200,2,14.48,1400,2,14.53,100,1,14.54,700,1,14.6,100,1,14.68,700,1,14.81,100,1,ARL,347422249
1794,2025-07-17T16:19:54.677250454Z,2025-07-17T16:19:54.677084975Z,10,2,1108,A,A,9,14.77,100,130,165479,288842530,13.11,100,1,13.03,2,1,12.98,200,2,12.86,100,1,12.73,100,1,12.71,100,1,12.5,700,1,12.46,100,1,12.43,700,1,12.42,700,1,13.44,15,1,13.86,2,1,14.22,100,1,14.35,200,2,14.48,1400,2,14.53,100,1,14.54,700,1,14.6,100,1,14.68,700,1,14.77,100,1,ARL,347444385
1795,2025-07-17T16:19:54.919087937Z,2025-07-17T16:19:54.918922624Z,10,2,1108,A,A,2,13.87,100,130,165313,288846635,13.11,100,1,13.03,2,1,12.98,200,2,12.86,100,1,12.73,100,1,12.71,100,1,12.5,700,1,12.46,100,1,12.43,700,1,12.42,700,1,13.44,15,1,13.86,2,1,13.87,100,1,14.22,100,1,14.35,200,2,14.48,1400,2,14.53,100,1,14.54,700,1,14.6,100,1,14.68,700,1,ARL,347449521
1796,2025-07-17T16:19:54.942941458Z,2025-07-17T16:19:54.942776198Z,10,2,1108,C,A,-1,14.22,100,130,165260,288847105,13.11,100,1,13.03,2,1,12.98,200,2,12.86,100,1,12.73,100,1,12.71,100,1,12.5,700,1,12.46,100,1,12.43,700,1,12.42,700,1,13.44,15,1,13.86,2,1,13.87,100,1,14.35,200,2,14.48,1400,2,14.53,100,1,14.54,700,1,14.6,100,1,14.68,700,1,14.77,100,1,ARL,347422365
1797,2025-07-17T16:19:54.942998015Z,2025-07-17T16:19:54.942832705Z,10,2,1108,A,A,3,14.15,100,130,165310,288847115,13.11,100,1,13.03,2,1,12.98,200,2,12.86,100,1,12.73,100,1,12.71,100,1,12.5,700,1,12.46,100,1,12.43,700,1,12.42,700,1,13.44,15,1,13.86,2,1,13.87,100,1,14.15,100,1,14.35,200,2,14.48,1400,2,14.53,100,1,14.54,700,1,14.6,100,1,14.68,700,1,ARL,347449893
1798,2025-07-17T16:20:02.838461207Z,2025-07-17T16:20:02.838295810Z,10,2,1108,A,A,0,13.4,15,130,165397,288958120,13.11,100,1,13.03,2,1,12.98,200,2,12.86,100,1,12.73,100,1,12.71,100,1,12.5,700,1,12.46,100,1,12.43,700,1,12.42,700,1,13.4,15,1,13.44,15,1,13.86,2,1,13.87,100,1,14.15,100,1,14.35,200,2,14.48,1400,2,14.53,100,1,14.54,700,1,14.6,100,1,ARL,347592441
1799,2025-07-17T16:20:03.544957156Z,2025-07-17T16:20:03.544791773Z,10,2,1108,C,A,-1,13.87,100,0,165383,288969245,13.11,100,1,13.03,2,1,12.98,200,2,12.86,100,1,12.73,100,1,12.71,100,1,12.5,700,1,12.46,100,1,12.43,700,1,12.42,700,1,13.4,15,1,13.44,15,1,13.86,2,1,14.15,100,1,14.35,200,2,14.48,1400,2,14.53,100,1,14.54,700,1,14.6,100,1,14.68,700,1,ARL,347449521
1800,2025-07-17T16:20:03.544957156Z,2025-07-17T16:20:03.544791773Z,10,2,1108,A,A,2,13.45,100,130,165383,288969245,13.11,100,1,13.03,2,1,12.98,200,2,12.86,100,1,12.73,100,1,12.71,100,1,12.5,700,1,12.46,100,1,12.43,700,1,12.42,700,1,13.4,15,1,13.44,15,1,13.45,100,1,13.86,2,1,14.15,100,1,14.35,200,2,14.48,1400,2,14.53,100,1,14.54,700,1,14.6,100,1,ARL,347605041
1801,2025-07-17T16:20:03.545692221Z,2025-07-17T16:20:03.545526427Z,10,2,1108,A,A,7,14.49,100,130,165794,288969257,13.11,100,1,13.03,2,1,12.98,200,2,12.86,100,1,12.73,100,1,12.71,100,1,12.5,700,1,12.46,100,1,12.43,700,1,12.42,700,1,13.4,15,1,13.44,15,1,13.45,100,1,13.86,2,1,14.15,100,1,14.35,200,2,14.48,1400,2,14.49,100,1,14.53,100,1,14.54,700,1,ARL,347605073
1802,2025-07-17T16:20:03.546047231Z,2025-07-17T16:20:03.545881983Z,10,2,1108,A,A,4,14.05,100,130,165248,288969265,13.11,100,1,13.03,2,1,12.98,200,2,12.86,100,1,12.73,100,1,12.71,100,1,12.5,700,1,12.46,100,1,12.43,700,1,12.42,700,1,13.4,15,1,13.44,15,1,13.45,100,1,13.86,2,1,14.05,100,1,14.15,100,1,14.35,200,2,14.48,1400,2,14.49,100,1,14.53,100,1,ARL,347605081
1803,2025-07-17T16:20:03.547722218Z,2025-07-17T16:20:03.547556902Z,10,2,1108,A,A,7,14.4,100,130,165316,288969290,13.11,100,1,13.03,2,1,12.98,200,2,12.86,100,1,12.73,100,1,12.71,100,1,12.5,700,1,12.46,100,1,12.43,700,1,12.42,700,1,13.4,15,1,13.44,15,1,13.45,100,1,13.86,2,1,14.05,100,1,14.15,100,1,14.35,200,2,14.4,100,1,14.48,1400,2,14.49,100,1,ARL,347605109
1804,2025-07-17T16:20:03.558022065Z,2025-07-17T16:20:03.557856817Z,10,2,1108,C,A,-1,14.15,100,130,165248,288969562,13.11,100,1,13.03,2,1,12.98,200,2,12.86,100,1,12.73,100,1,12.71,100,1,12.5,700,1,12.46,100,1,12.43,700,1,12.42,700,1,13.4,15,1,13.44,15,1,13.45,100,1,13.86,2,1,14.05,100,1,14.35,200,2,14.4,100,1,14.48,1400,2,14.49,100,1,14.53,100,1,ARL,347449893
1805,2025-07-17T16:20:03.558074886Z,2025-07-17T16:20:03.557909645Z,10,2,1108,A,A,3,13.72,100,130,165241,288969565,13.11,100,1,13.03,2,1,12.98,200,2,12.86,100,1,12.73,100,1,12.71,100,1,12.5,700,1,12.46,100,1,12.43,700,1,12.42,700,1,13.4,15,1,13.44,15,1,13.45,100,1,13.72,100,1,13.86,2,1,14.05,100,1,14.35,200,2,14.4,100,1,14.48,1400,2,14.49,100,1,ARL,347605397
1806,2025-07-17T16:20:03.569904581Z,2025-07-17T16:20:03.569738711Z,10,2,1108,A,A,7,14.4,100,130,165870,288969738,13.11,100,1,13.03,2,1,12.98,200,2,12.86,100,1,12.73,100,1,12.71,100,1,12.5,700,1,12.46,100,1,12.43,700,1,12.42,700,1,13.4,15,1,13.44,15,1,13.45,100,1,13.72,100,1,13.86,2,1,14.05,100,1,14.35,200,2,14.4,200,2,14.48,1400,2,14.49,100,1,ARL,347605617
1807,2025-07-17T16:20:03.592903833Z,2025-07-17T16:20:03.592738507Z,10,2,1108,A,A,6,14.24,100,130,165326,288970211,13.11,100,1,13.03,2,1,12.98,200,2,12.86,100,1,12.73,100,1,12.71,100,1,12.5,700,1,12.46,100,1,12.43,700,1,12.42,700,1,13.4,15,1,13.44,15,1,13.45,100,1,13.72,100,1,13.86,2,1,14.05,100,1,14.24,100,1,14.35,200,2,14.4,200,2,14.48,1400,2,ARL,347605969
1808,2025-07-17T16:20:04.069661713Z,2025-07-17T16:20:04.069496437Z,10,2,1108,A,A,5,13.98,100,130,165276,288977269,13.11,100,1,13.03,2,1,12.98,200,2,12.86,100,1,12.73,100,1,12.71,100,1,12.5,700,1,12.46,100,1,12.43,700,1,12.42,700,1,13.4,15,1,13.44,15,1,13.45,100,1,13.72,100,1,13.86,2,1,13.98,100,1,14.05,100,1,14.24,100,1,14.35,200,2,14.4,200,2,ARL,347613877
1809,2025-07-17T16:20:04.111795639Z,2025-07-17T16:20:04.111630484Z,10,2,1108,A,A,8,14.25,100,130,165155,288978560,13.11,100,1,13.03,2,1,12.98,200,2,12.86,100,1,12.73,100,1,12.71,100,1,12.5,700,1,12.46,100,1,12.43,700,1,12.42,700,1,13.4,15,1,13.44,15,1,13.45,100,1,13.72,100,1,13.86,2,1,13.98,100,1,14.05,100,1,14.24,100,1,14.25,100,1,14.35,200,2,ARL,347615553
1810,2025-07-17T16:20:07.945427285Z,2025-07-17T16:20:07.945262120Z,10,2,1108,C,A,-1,13.44,15,130,165165,289031160,13.11,100,1,13.03,2,1,12.98,200,2,12.86,100,1,12.73,100,1,12.71,100,1,12.5,700,1,12.46,100,1,12.43,700,1,12.42,700,1,13.4,15,1,13.45,100,1,13.72,100,1,13.86,2,1,13.98,100,1,14.05,100,1,14.24,100,1,14.25,100,1,14.35,200,2,14.4,200,2,ARL,347377693
1811,2025-07-17T16:20:08.949407416Z,2025-07-17T16:20:08.949241997Z,10,2,1108,A,A,0,13.36,15,130,165419,289046760,13.11,100,1,13.03,2,1,12.98,200,2,12.86,100,1,12.73,100,1,12.71,100,1,12.5,700,1,12.46,100,1,12.43,700,1,12.42,700,1,13.36,15,1,13.4,15,1,13.45,100,1,13.72,100,1,13.86,2,1,13.98,100,1,14.05,100,1,14.24,100,1,14.25,100,1,14.35,200,2,ARL,347710393
1812,2025-07-17T16:20:09.428817232Z,2025-07-17T16:20:09.428650758Z,10,2,1108,A,A,7,14.17,700,130,166474,289052533,13.11,100,1,13.03,2,1,12.98,200,2,12.86,100,1,12.73,100,1,12.71,100,1,12.5,700,1,12.46,100,1,12.43,700,1,12.42,700,1,13.36,15,1,13.4,15,1,13.45,100,1,13.72,100,1,13.86,2,1,13.98,100,1,14.05,100,1,14.17,700,1,14.24,100,1,14.25,100,1,ARL,347717317
1813,2025-07-17T16:20:09.704859787Z,2025-07-17T16:20:09.704693450Z,10,2,1108,C,A,-1,13.86,2,0,166337,289057887,13.11,100,1,13.03,2,1,12.98,200,2,12.86,100,1,12.73,100,1,12.71,100,1,12.5,700,1,12.46,100,1,12.43,700,1,12.42,700,1,13.36,15,1,13.4,15,1,13.45,100,1,13.72,100,1,13.98,100,1,14.05,100,1,14.17,700,1,14.24,100,1,14.25,100,1,14.35,200,2,ARL,347396177
1814,2025-07-17T16:20:09.704859787Z,2025-07-17T16:20:09.704693450Z,10,2,1108,A,A,4,13.78,2,128,166337,289057887,13.11,100,1,13.03,2,1,12.98,200,2,12.86,100,1,12.73,100,1,12.71,100,1,12.5,700,1,12.46,100,1,12.43,700,1,12.42,700,1,13.36,15,1,13.4,15,1,13.45,100,1,13.72,100,1,13.78,2,1,13.98,100,1,14.05,100,1,14.17,700,1,14.24,100,1,14.25,100,1,ARL,347722857
1815,2025-07-17T16:20:11.608367693Z,2025-07-17T16:20:11.608202073Z,10,2,1108,A,A,8,14.24,100,130,165620,289085339,13.11,100,1,13.03,2,1,12.98,200,2,12.86,100,1,12.73,100,1,12.71,100,1,12.5,700,1,12.46,100,1,12.43,700,1,12.42,700,1,13.36,15,1,13.4,15,1,13.45,100,1,13.72,100,1,13.78,2,1,13.98,100,1,14.05,100,1,14.17,700,1,14.24,200,2,14.25,100,1,ARL,347760469
1816,2025-07-17T16:20:11.608472767Z,2025-07-17T16:20:11.608307409Z,10,2,1108,A,A,8,14.24,100,130,165358,289085342,13.11,100,1,13.03,2,1,12.98,200,2,12.86,100,1,12.73,100,1,12.71,100,1,12.5,700,1,12.46,100,1,12.43,700,1,12.42,700,1,13.36,15,1,13.4,15,1,13.45,100,1,13.72,100,1,13.78,2,1,13.98,100,1,14.05,100,1,14.17,700,1,14.24,300,3,14.25,100,1,ARL,347760485
1817,2025-07-17T16:20:20.588044932Z,2025-07-17T16:20:20.587879078Z,10,2,1108,C,A,-1,13.78,2,0,165854,289232518,13.11,100,1,13.03,2,1,12.98,200,2,12.86,100,1,12.73,100,1,12.71,100,1,12.5,700,1,12.46,100,1,12.43,700,1,12.42,700,1,13.36,15,1,13.4,15,1,13.45,100,1,13.72,100,1,13.98,100,1,14.05,100,1,14.17,700,1,14.24,300,3,14.25,100,1,14.4,200,2,ARL,347722857
1818,2025-07-17T16:20:20.588044932Z,2025-07-17T16:20:20.587879078Z,10,2,1108,A,A,3,13.71,2,130,165854,289232518,13.11,100,1,13.03,2,1,12.98,200,2,12.86,100,1,12.73,100,1,12.71,100,1,12.5,700,1,12.46,100,1,12.43,700,1,12.42,700,1,13.36,15,1,13.4,15,1,13.45,100,1,13.71,2,1,13.72,100,1,13.98,100,1,14.05,100,1,14.17,700,1,14.24,300,3,14.25,100,1,ARL,347935421
1819,2025-07-17T16:20:20.839245229Z,2025-07-17T16:20:20.839080003Z,10,2,1108,C,A,-1,13.4,15,130,165226,289235324,13.11,100,1,13.03,2,1,12.98,200,2,12.86,100,1,12.73,100,1,12.71,100,1,12.5,700,1,12.46,100,1,12.43,700,1,12.42,700,1,13.36,15,1,13.45,100,1,13.71,2,1,13.72,100,1,13.98,100,1,14.05,100,1,14.17,700,1,14.24,300,3,14.25,100,1,14.4,200,2,ARL,347592441
1820,2025-07-17T16:20:21.839565900Z,2025-07-17T16:20:21.839400050Z,10,2,1108,A,A,0,13.33,15,130,165850,289253047,13.11,100,1,13.03,2,1,12.98,200,2,12.86,100,1,12.73,100,1,12.71,100,1,12.5,700,1,12.46,100,1,12.43,700,1,12.42,700,1,13.33,15,1,13.36,15,1,13.45,100,1,13.71,2,1,13.72,100,1,13.98,100,1,14.05,100,1,14.17,700,1,14.24,300,3,14.25,100,1,ARL,347961173
1821,2025-07-17T16:20:27.448533855Z,2025-07-17T16:20:27.448368575Z,10,2,1108,C,A,-1,13.36,15,130,165280,289339972,13.11,100,1,13.03,2,1,12.98,200,2,12.86,100,1,12.73,100,1,12.71,100,1,12.5,700,1,12.46,100,1,12.43,700,1,12.42,700,1,13.33,15,1,13.45,100,1,13.71,2,1,13.72,100,1,13.98,100,1,14.05,100,1,14.17,700,1,14.24,300,3,14.25,100,1,14.4,200,2,ARL,347710393
1822,2025-07-17T16:20:28.452553412Z,2025-07-17T16:20:28.452388023Z,10,2,1108,A,A,0,13.31,15,130,165389,289367352,13.11,100,1,13.03,2,1,12.98,200,2,12.86,100,1,12.73,100,1,12.71,100,1,12.5,700,1,12.46,100,1,12.43,700,1,12.42,700,1,13.31,15,1,13.33,15,1,13.45,100,1,13.71,2,1,13.72,100,1,13.98,100,1,14.05,100,1,14.17,700,1,14.24,300,3,14.25,100,1,ARL,348099617
1823,2025-07-17T16:20:31.453437816Z,2025-07-17T16:20:31.453272244Z,10,2,1108,C,A,-1,13.33,15,130,165572,289452005,13.11,100,1,13.03,2,1,12.98,200,2,12.86,100,1,12.73,100,1,12.71,100,1,12.5,700,1,12.46,100,1,12.43,700,1,12.42,700,1,13.31,15,1,13.45,100,1,13.71,2,1,13.72,100,1,13.98,100,1,14.05,100,1,14.17,700,1,14.24,300,3,14.25,100,1,14.4,200,2,ARL,347961173
1824,2025-07-17T16:20:42.838073701Z,2025-07-17T16:20:42.837908349Z,10,2,1108,A,A,0,13.29,15,130,165352,289627630,13.11,100,1,13.03,2,1,12.98,200,2,12.86,100,1,12.73,100,1,12.71,100,1,12.5,700,1,12.46,100,1,12.43,700,1,12.42,700,1,13.29,15,1,13.31,15,1,13.45,100,1,13.71,2,1,13.72,100,1,13.98,100,1,14.05,100,1,14.17,700,1,14.24,300,3,14.25,100,1,ARL,348428649
1825,2025-07-17T16:20:56.875524789Z,2025-07-17T16:20:56.875359282Z,10,2,1108,C,B,-1,13.03,2,0,165507,289958017,13.11,100,1,12.98,200,2,12.86,100,1,12.73,100,1,12.71,100,1,12.5,700,1,12.46,100,1,12.43,700,1,12.42,700,1,12.37,700,1,13.29,15,1,13.31,15,1,13.45,100,1,13.71,2,1,13.72,100,1,13.98,100,1,14.05,100,1,14.17,700,1,14.24,300,3,14.25,100,1,ARL,347220093
1826,2025-07-17T16:20:56.875524789Z,2025-07-17T16:20:56.875359282Z,10,2,1108,A,B,2,12.96,2,130,165507,289958017,13.11,100,1,12.98,200,2,12.96,2,1,12.86,100,1,12.73,100,1,12.71,100,1,12.5,700,1,12.46,100,1,12.43,700,1,12.42,700,1,13.29,15,1,13.31,15,1,13.45,100,1,13.71,2,1,13.72,100,1,13.98,100,1,14.05,100,1,14.17,700,1,14.24,300,3,14.25,100,1,ARL,348838809
1827,2025-07-17T16:21:03.027643943Z,2025-07-17T16:21:03.027478065Z,10,2,1108,C,A,-1,13.31,15,130,165878,290149718,13.11,100,1,12.98,200,2,12.96,2,1,12.86,100,1,12.73,100,1,12.71,100,1,12.5,700,1,12.46,100,1,12.43,700,1,12.42,700,1,13.29,15,1,13.45,100,1,13.71,2,1,13.72,100,1,13.98,100,1,14.05,100,1,14.17,700,1,14.24,300,3,14.25,100,1,14.4,200,2,ARL,348099617
1828,2025-07-17T16:21:03.786334915Z,2025-07-17T16:21:03.786169333Z,10,2,1108,C,A,-1,13.71,2,0,165582,290172493,13.11,100,1,12.98,200,2,12.96,2,1,12.86,100,1,12.73,100,1,12.71,100,1,12.5,700,1,12.46,100,1,12.43,700,1,12.42,700,1,13.29,15,1,13.45,100,1,13.72,100,1,13.98,100,1,14.05,100,1,14.17,700,1,14.24,300,3,14.25,100,1,14.4,200,2,14.48,1400,2,ARL,347935421
1829,2025-07-17T16:21:03.786334915Z,2025-07-17T16:21:03.786169333Z,10,2,1108,A,A,2,13.65,2,130,165582,290172493,13.11,100,1,12.98,200,2,12.96,2,1,12.86,100,1,12.73,100,1,12.71,100,1,12.5,700,1,12.46,100,1,12.43,700,1,12.42,700,1,13.29,15,1,13.45,100,1,13.65,2,1,13.72,100,1,13.98,100,1,14.05,100,1,14.17,700,1,14.24,300,3,14.25,100,1,14.4,200,2,ARL,349094877
1830,2025-07-17T16:21:04.031563260Z,2025-07-17T16:21:04.031397539Z,10,2,1108,A,A,0,13.27,15,130,165721,290175495,13.11,100,1,12.98,200,2,12.96,2,1,12.86,100,1,12.73,100,1,12.71,100,1,12.5,700,1,12.46,100,1,12.43,700,1,12.42,700,1,13.27,15,1,13.29,15,1,13.45,100,1,13.65,2,1,13.72,100,1,13.98,100,1,14.05,100,1,14.17,700,1,14.24,300,3,14.25,100,1,ARL,349100269
1831,2025-07-17T16:21:04.035799229Z,2025-07-17T16:21:04.035632459Z,10,2,1108,C,A,-1,13.27,15,128,166770,290175561,13.11,100,1,12.98,200,2,12.96,2,1,12.86,100,1,12.73,100,1,12.71,100,1,12.5,700,1,12.46,100,1,12.43,700,1,12.42,700,1,13.29,15,1,13.45,100,1,13.65,2,1,13.72,100,1,13.98,100,1,14.05,100,1,14.17,700,1,14.24,300,3,14.25,100,1,14.4,200,2,ARL,349100269
1832,2025-07-17T16:21:04.035825836Z,2025-07-17T16:21:04.035660519Z,10,2,1108,A,B,0,13.14,11,130,165317,290175563,13.14,11,1,13.11,100,1,12.98,200,2,12.96,2,1,12.86,100,1,12.73,100,1,12.71,100,1,12.5,700,1,12.46,100,1,12.43,700,1,13.29,15,1,13.45,100,1,13.65,2,1,13.72,100,1,13.98,100,1,14.05,100,1,14.17,700,1,14.24,300,3,14.25,100,1,14.4,200,2,ARL,349100461
1833,2025-07-17T16:21:05.035171590Z,2025-07-17T16:21:05.035006249Z,10,2,1108,C,B,-1,13.14,11,130,165341,290207081,13.11,100,1,12.98,200,2,12.96,2,1,12.86,100,1,12.73,100,1,12.71,100,1,12.5,700,1,12.46,100,1,12.43,700,1,12.42,700,1,13.29,15,1,13.45,100,1,13.65,2,1,13.72,100,1,13.98,100,1,14.05,100,1,14.17,700,1,14.24,300,3,14.25,100,1,14.4,200,2,ARL,349100461
1834,2025-07-17T16:21:13.027776086Z,2025-07-17T16:21:13.027610071Z,10,2,1108,C,A,-1,13.29,15,130,166015,290382552,13.11,100,1,12.98,200,2,12.96,2,1,12.86,100,1,12.73,100,1,12.71,100,1,12.5,700,1,12.46,100,1,12.43,700,1,12.42,700,1,13.45,100,1,13.65,2,1,13.72,100,1,13.98,100,1,14.05,100,1,14.17,700,1,14.24,300,3,14.25,100,1,14.4,200,2,14.48,1400,2,ARL,348428649
1835,2025-07-17T16:21:13.028208678Z,2025-07-17T16:21:13.028039954Z,10,2,1108,C,A,-1,13.45,100,128,168724,290382699,13.11,100,1,12.98,200,2,12.96,2,1,12.86,100,1,12.73,100,1,12.71,100,1,12.5,700,1,12.46,100,1,12.43,700,1,12.42,700,1,13.65,2,1,13.72,100,1,13.98,100,1,14.05,100,1,14.17,700,1,14.24,300,3,14.25,100,1,14.4,200,2,14.48,1400,2,14.49,100,1,ARL,347605041
1836,2025-07-17T16:21:13.028929613Z,2025-07-17T16:21:13.028763898Z,10,2,1108,C,A,5,14.24,100,0,165715,290382878,13.11,100,1,12.98,200,2,12.96,2,1,12.86,100,1,12.73,100,1,12.71,100,1,12.5,700,1,12.46,100,1,12.43,700,1,12.42,700,1,13.65,2,1,13.72,100,1,13.98,100,1,14.05,100,1,14.17,700,1,14.24,200,2,14.25,100,1,14.4,200,2,14.48,1400,2,14.49,100,1,ARL,347760485
1837,2025-07-17T16:21:13.028960654Z,2025-07-17T16:21:13.028792918Z,10,2,1108,C,A,-1,14.05,100,128,167736,290382883,13.11,100,1,12.98,200,2,12.96,2,1,12.86,100,1,12.73,100,1,12.71,100,1,12.5,700,1,12.46,100,1,12.43,700,1,12.42,700,1,13.65,2,1,13.72,100,1,13.98,100,1,14.17,700,1,14.24,200,2,14.25,100,1,14.4,200,2,14.48,1400,2,14.49,100,1,14.54,700,1,ARL,347605081
1838,2025-07-17T16:21:13.029314299Z,2025-07-17T16:21:13.029148929Z,10,2,1108,A,A,6,14.33,100,130,165370,290382993,13.11,100,1,12.98,200,2,12.96,2,1,12.86,100,1,12.73,100,1,12.71,100,1,12.5,700,1,12.46,100,1,12.43,700,1,12.42,700,1,13.65,2,1,13.72,100,1,13.98,100,1,14.17,700,1,14.24,200,2,14.25,100,1,14.33,100,1,14.4,200,2,14.48,1400,2,14.49,100,1,ARL,349364205
1839,2025-07-17T16:21:13.029395561Z,2025-07-17T16:21:13.029229862Z,10,2,1108,C,A,-1,14.49,100,0,165699,290383014,13.11,100,1,12.98,200,2,12.96,2,1,12.86,100,1,12.73,100,1,12.71,100,1,12.5,700,1,12.46,100,1,12.43,700,1,12.42,700,1,13.65,2,1,13.72,100,1,13.98,100,1,14.17,700,1,14.24,200,2,14.25,100,1,14.33,100,1,14.4,200,2,14.48,1400,2,14.54,700,1,ARL,347605073
1840,2025-07-17T16:21:13.029433752Z,2025-07-17T16:21:13.029267150Z,10,2,1108,C,A,-1,14.17,700,130,166602,290383019,13.11,100,1,12.98,200,2,12.96,2,1,12.86,100,1,12.73,100,1,12.71,100,1,12.5,700,1,12.46,100,1,12.43,700,1,12.42,700,1,13.65,2,1,13.72,100,1,13.98,100,1,14.24,200,2,14.25,100,1,14.33,100,1,14.4,200,2,14.48,1400,2,14.54,700,1,14.63,100,1,ARL,347717317
1841,2025-07-17T16:21:13.029461868Z,2025-07-17T16:21:13.029296174Z,10,2,1108,C,A,3,14.24,100,0,165694,290383027,13.11,100,1,12.98,200,2,12.96,2,1,12.86,100,1,12.73,100,1,12.71,100,1,12.5,700,1,12.46,100,1,12.43,700,1,12.42,700,1,13.65,2,1,13.72,100,1,13.98,100,1,14.24,100,1,14.25,100,1,14.33,100,1,14.4,200,2,14.48,1400,2,14.54,700,1,14.63,100,1,ARL,347760469
1842,2025-07-17T16:21:13.029461868Z,2025-07-17T16:21:13.029296174Z,10,2,1108,A,A,9,14.63,100,130,165694,290383027,13.11,100,1,12.98,200,2,12.96,2,1,12.86,100,1,12.73,100,1,12.71,100,1,12.5,700,1,12.46,100,1,12.43,700,1,12.42,700,1,13.65,2,1,13.72,100,1,13.98,100,1,14.24,100,1,14.25,100,1,14.33,100,1,14.4,200,2,14.48,1400,2,14.54,700,1,14.63,200,2,ARL,349364233
1843,2025-07-17T16:21:13.029500611Z,2025-07-17T16:21:13.029335284Z,10,2,1108,A,A,7,14.41,700,130,165327,290383043,13.11,100,1,12.98,200,2,12.96,2,1,12.86,100,1,12.73,100,1,12.71,100,1,12.5,700,1,12.46,100,1,12.43,700,1,12.42,700,1,13.65,2,1,13.72,100,1,13.98,100,1,14.24,100,1,14.25,100,1,14.33,100,1,14.4,200,2,14.41,700,1,14.48,1400,2,14.54,700,1,ARL,349364241
1844,2025-07-17T16:21:13.033525905Z,2025-07-17T16:21:13.033360385Z,10,2,1108,C,A,-1,14.24,100,0,165520,290383910,13.11,100,1,12.98,200,2,12.96,2,1,12.86,100,1,12.73,100,1,12.71,100,1,12.5,700,1,12.46,100,1,12.43,700,1,12.42,700,1,13.65,2,1,13.72,100,1,13.98,100,1,14.25,100,1,14.33,100,1,14.4,200,2,14.41,700,1,14.48,1400,2,14.54,700,1,14.63,200,2,ARL,347605969
1845,2025-07-17T16:21:13.033525905Z,2025-07-17T16:21:13.033360385Z,10,2,1108,A,A,8,14.51,100,130,165520,290383910,13.11,100,1,12.98,200,2,12.96,2,1,12.86,100,1,12.73,100,1,12.71,100,1,12.5,700,1,12.46,100,1,12.43,700,1,12.42,700,1,13.65,2,1,13.72,100,1,13.98,100,1,14.25,100,1,14.33,100,1,14.4,200,2,14.41,700,1,14.48,1400,2,14.51,100,1,14.54,700,1,ARL,349364905
1846,2025-07-17T16:21:13.041339278Z,2025-07-17T16:21:13.041173935Z,10,2,1108,C,A,-1,13.72,100,130,165343,290385083,13.11,100,1,12.98,200,2,12.96,2,1,12.86,100,1,12.73,100,1,12.71,100,1,12.5,700,1,12.46,100,1,12.43,700,1,12.42,700,1,13.65,2,1,13.98,100,1,14.25,100,1,14.33,100,1,14.4,200,2,14.41,700,1,14.48,1400,2,14.51,100,1,14.54,700,1,14.63,200,2,ARL,347605397
1847,2025-07-17T16:21:13.041376591Z,2025-07-17T16:21:13.041211567Z,10,2,1108,C,A,-1,14.41,700,130,165024,290385085,13.11,100,1,12.98,200,2,12.96,2,1,12.86,100,1,12.73,100,1,12.71,100,1,12.5,700,1,12.46,100,1,12.43,700,1,12.42,700,1,13.65,2,1,13.98,100,1,14.25,100,1,14.33,100,1,14.4,200,2,14.48,1400,2,14.51,100,1,14.54,700,1,14.63,200,2,14.78,100,1,ARL,349364241
1848,2025-07-17T16:21:13.041396412Z,2025-07-17T16:21:13.041231123Z,10,2,1108,A,A,2,13.99,100,130,165289,290385086,13.11,100,1,12.98,200,2,12.96,2,1,12.86,100,1,12.73,100,1,12.71,100,1,12.5,700,1,12.46,100,1,12.43,700,1,12.42,700,1,13.65,2,1,13.98,100,1,13.99,100,1,14.25,100,1,14.33,100,1,14.4,200,2,14.48,1400,2,14.51,100,1,14.54,700,1,14.63,200,2,ARL,349365741
1849,2025-07-17T16:21:13.042377442Z,2025-07-17T16:21:13.042212059Z,10,2,1108,A,B,0,13.11,10,130,165383,290385162,13.11,110,2,12.98,200,2,12.96,2,1,12.86,100,1,12.73,100,1,12.71,100,1,12.5,700,1,12.46,100,1,12.43,700,1,12.42,700,1,13.65,2,1,13.98,100,1,13.99,100,1,14.25,100,1,14.33,100,1,14.4,200,2,14.48,1400,2,14.51,100,1,14.54,700,1,14.63,200,2,ARL,349365825
1850,2025-07-17T16:21:13.046293088Z,2025-07-17T16:21:13.046127777Z,10,2,1108,C,A,-1,13.99,100,130,165311,290385480,13.11,110,2,12.98,200,2,12.96,2,1,12.86,100,1,12.73,100,1,12.71,100,1,12.5,700,1,12.46,100,1,12.43,700,1,12.42,700,1,13.65,2,1,13.98,100,1,14.25,100,1,14.33,100,1,14.4,200,2,14.48,1400,2,14.51,100,1,14.54,700,1,14.63,200,2,14.78,100,1,ARL,349365741
1851,2025-07-17T16:21:13.046345105Z,2025-07-17T16:21:13.046179769Z,10,2,1108,A,A,2,14.22,100,130,165336,290385481,13.11,110,2,12.98,200,2,12.96,2,1,12.86,100,1,12.73,100,1,12.71,100,1,12.5,700,1,12.46,100,1,12.43,700,1,12.42,700,1,13.65,2,1,13.98,100,1,14.22,100,1,14.25,100,1,14.33,100,1,14.4,200,2,14.48,1400,2,14.51,100,1,14.54,700,1,14.63,200,2,ARL,349366121
1852,2025-07-17T16:21:13.051207283Z,2025-07-17T16:21:13.051041384Z,10,2,1108,C,A,-1,13.65,2,0,165899,290385730,13.11,110,2,12.98,200,2,12.96,2,1,12.86,100,1,12.73,100,1,12.71,100,1,12.5,700,1,12.46,100,1,12.43,700,1,12.42,700,1,13.98,100,1,14.22,100,1,14.25,100,1,14.33,100,1,14.4,200,2,14.48,1400,2,14.51,100,1,14.54,700,1,14.63,200,2,14.78,100,1,ARL,349094877
1853,2025-07-17T16:21:13.051207283Z,2025-07-17T16:21:13.051041384Z,10,2,1108,A,A,0,13.98,2,130,165899,290385730,13.11,110,2,12.98,200,2,12.96,2,1,12.86,100,1,12.73,100,1,12.71,100,1,12.5,700,1,12.46,100,1,12.43,700,1,12.42,700,1,13.98,102,2,14.22,100,1,14.25,100,1,14.33,100,1,14.4,200,2,14.48,1400,2,14.51,100,1,14.54,700,1,14.63,200,2,14.78,100,1,ARL,349366297
1854,2025-07-17T16:21:13.054107724Z,2025-07-17T16:21:13.053942197Z,10,2,1108,C,A,4,14.4,100,0,165527,290385849,13.11,110,2,12.98,200,2,12.96,2,1,12.86,100,1,12.73,100,1,12.71,100,1,12.5,700,1,12.46,100,1,12.43,700,1,12.42,700,1,13.98,102,2,14.22,100,1,14.25,100,1,14.33,100,1,14.4,100,1,14.48,1400,2,14.51,100,1,14.54,700,1,14.63,200,2,14.78,100,1,ARL,347605109
1855,2025-07-17T16:21:13.080134481Z,2025-07-17T16:21:13.079968994Z,10,2,1108,C,A,-1,14.78,100,0,165487,290387380,13.11,110,2,12.98,200,2,12.96,2,1,12.86,100,1,12.73,100,1,12.71,100,1,12.5,700,1,12.46,100,1,12.43,700,1,12.42,700,1,13.98,102,2,14.22,100,1,14.25,100,1,14.33,100,1,14.4,100,1,14.48,1400,2,14.51,100,1,14.54,700,1,14.63,200,2,14.8,100,1,ARL,349364213
1856,2025-07-17T16:21:13.155686293Z,2025-07-17T16:21:13.155520730Z,10,2,1108,C,A,-1,14.8,100,0,165563,290388741,13.11,110,2,12.98,200,2,12.96,2,1,12.86,100,1,12.73,100,1,12.71,100,1,12.5,700,1,12.46,100,1,12.43,700,1,12.42,700,1,13.98,102,2,14.22,100,1,14.25,100,1,14.33,100,1,14.4,100,1,14.48,1400,2,14.51,100,1,14.54,700,1,14.63,200,2,14.96,100,1,ARL,347605169
1857,2025-07-17T16:21:13.214483898Z,2025-07-17T16:21:13.214317987Z,10,2,1108,C,A,-1,14.4,100,0,165911,290389756,13.11,110,2,12.98,200,2,12.96,2,1,12.86,100,1,12.73,100,1,12.71,100,1,12.5,700,1,12.46,100,1,12.43,700,1,12.42,700,1,13.98,102,2,14.22,100,1,14.25,100,1,14.33,100,1,14.48,1400,2,14.51,100,1,14.54,700,1,14.63,200,2,14.96,100,1,15.06,100,1,ARL,347605617
1858,2025-07-17T16:21:13.214483898Z,2025-07-17T16:21:13.214317987Z,10,2,1108,A,A,8,14.96,100,130,165911,290389756,13.11,110,2,12.98,200,2,12.96,2,1,12.86,100,1,12.73,100,1,12.71,100,1,12.5,700,1,12.46,100,1,12.43,700,1,12.42,700,1,13.98,102,2,14.22,100,1,14.25,100,1,14.33,100,1,14.48,1400,2,14.51,100,1,14.54,700,1,14.63,200,2,14.96,200,2,15.06,100,1,ARL,349371829
1859,2025-07-17T16:21:13.236533203Z,2025-07-17T16:21:13.236367880Z,10,2,1108,A,A,8,14.68,700,130,165323,290390045,13.11,110,2,12.98,200,2,12.96,2,1,12.86,100,1,12.73,100,1,12.71,100,1,12.5,700,1,12.46,100,1,12.43,700,1,12.42,700,1,13.98,102,2,14.22,100,1,14.25,100,1,14.33,100,1,14.48,1400,2,14.51,100,1,14.54,700,1,14.63,200,2,14.68,700,1,14.96,200,2,ARL,349372241
1860,2025-07-17T16:21:13.533219934Z,2025-07-17T16:21:13.533054792Z,10,2,1108,C,A,-1,14.33,100,130,165142,290394645,13.11,110,2,12.98,200,2,12.96,2,1,12.86,100,1,12.73,100,1,12.71,100,1,12.5,700,1,12.46,100,1,12.43,700,1,12.42,700,1,13.98,102,2,14.22,100,1,14.25,100,1,14.48,1400,2,14.51,100,1,14.54,700,1,14.63,200,2,14.68,700,1,14.96,200,2,15.06,100,1,ARL,349364205
1861,2025-07-17T16:21:13.533568871Z,2025-07-17T16:21:13.533403508Z,10,2,1108,A,A,6,14.6,100,130,165363,290394647,13.11,110,2,12.98,200,2,12.96,2,1,12.86,100,1,12.73,100,1,12.71,100,1,12.5,700,1,12.46,100,1,12.43,700,1,12.42,700,1,13.98,102,2,14.22,100,1,14.25,100,1,14.48,1400,2,14.51,100,1,14.54,700,1,14.6,100,1,14.63,200,2,14.68,700,1,14.96,200,2,ARL,349378277
1862,2025-07-17T16:21:13.617836532Z,2025-07-17T16:21:13.617670801Z,10,2,1108,A,A,9,14.81,100,130,165731,290395763,13.11,110,2,12.98,200,2,12.96,2,1,12.86,100,1,12.73,100,1,12.71,100,1,12.5,700,1,12.46,100,1,12.43,700,1,12.42,700,1,13.98,102,2,14.22,100,1,14.25,100,1,14.48,1400,2,14.51,100,1,14.54,700,1,14.6,100,1,14.63,200,2,14.68,700,1,14.81,100,1,ARL,349380345
1863,2025-07-17T16:21:13.617850005Z,2025-07-17T16:21:13.617684550Z,10,2,1108,C,A,-1,14.25,100,130,165455,290395764,13.11,110,2,12.98,200,2,12.96,2,1,12.86,100,1,12.73,100,1,12.71,100,1,12.5,700,1,12.46,100,1,12.43,700,1,12.42,700,1,13.98,102,2,14.22,100,1,14.48,1400,2,14.51,100,1,14.54,700,1,14.6,100,1,14.63,200,2,14.68,700,1,14.81,100,1,14.96,200,2,ARL,347615553
1864,2025-07-17T16:21:13.652214194Z,2025-07-17T16:21:13.652048799Z,10,2,1108,A,A,1,13.99,100,130,165395,290396554,13.11,110,2,12.98,200,2,12.96,2,1,12.86,100,1,12.73,100,1,12.71,100,1,12.5,700,1,12.46,100,1,12.43,700,1,12.42,700,1,13.98,102,2,13.99,100,1,14.22,100,1,14.48,1400,2,14.51,100,1,14.54,700,1,14.6,100,1,14.63,200,2,14.68,700,1,14.81,100,1,ARL,349380925
1865,2025-07-17T16:21:13.742867781Z,2025-07-17T16:21:13.742700842Z,10,2,1108,A,A,5,14.53,100,0,166939,290397623,13.11,110,2,12.98,200,2,12.96,2,1,12.86,100,1,12.73,100,1,12.71,100,1,12.5,700,1,12.46,100,1,12.43,700,1,12.42,700,1,13.98,102,2,13.99,100,1,14.22,100,1,14.48,1400,2,14.51,100,1,14.53,100,1,14.54,700,1,14.6,100,1,14.63,200,2,14.68,700,1,ARL,349382189
1866,2025-07-17T16:21:13.742867781Z,2025-07-17T16:21:13.742701630Z,10,2,1108,C,A,0,13.98,100,130,166151,290397624,13.11,110,2,12.98,200,2,12.96,2,1,12.86,100,1,12.73,100,1,12.71,100,1,12.5,700,1,12.46,100,1,12.43,700,1,12.42,700,1,13.98,2,1,13.99,100,1,14.22,100,1,14.48,1400,2,14.51,100,1,14.53,100,1,14.54,700,1,14.6,100,1,14.63,200,2,14.68,700,1,ARL,347613877
1867,2025-07-17T16:21:14.030935993Z,2025-07-17T16:21:14.030770739Z,10,2,1108,C,A,-1,14.51,100,130,165254,290403111,13.11,110,2,12.98,200,2,12.96,2,1,12.86,100,1,12.73,100,1,12.71,100,1,12.5,700,1,12.46,100,1,12.43,700,1,12.42,700,1,13.98,2,1,13.99,100,1,14.22,100,1,14.48,1400,2,14.53,100,1,14.54,700,1,14.6,100,1,14.63,200,2,14.68,700,1,14.81,100,1,ARL,349364905
1868,2025-07-17T16:21:14.031072602Z,2025-07-17T16:21:14.030907193Z,10,2,1108,A,A,9,14.77,100,130,165409,290403117,13.11,110,2,12.98,200,2,12.96,2,1,12.86,100,1,12.73,100,1,12.71,100,1,12.5,700,1,12.46,100,1,12.43,700,1,12.42,700,1,13.98,2,1,13.99,100,1,14.22,100,1,14.48,1400,2,14.53,100,1,14.54,700,1,14.6,100,1,14.63,200,2,14.68,700,1,14.77,100,1,ARL,349388057
1869,2025-07-17T16:21:14.045944611Z,2025-07-17T16:21:14.045778918Z,10,2,1108,C,A,7,14.63,100,0,165693,290403302,13.11,110,2,12.98,200,2,12.96,2,1,12.86,100,1,12.73,100,1,12.71,100,1,12.5,700,1,12.46,100,1,12.43,700,1,12.42,700,1,13.98,2,1,13.99,100,1,14.22,100,1,14.48,1400,2,14.53,100,1,14.54,700,1,14.6,100,1,14.63,100,1,14.68,700,1,14.77,100,1,ARL,349364233
1870,2025-07-17T16:21:14.046189449Z,2025-07-17T16:21:14.046023656Z,10,2,1108,C,A,-1,14.63,100,0,165793,290403303,13.11,110,2,12.98,200,2,12.96,2,1,12.86,100,1,12.73,100,1,12.71,100,1,12.5,700,1,12.46,100,1,12.43,700,1,12.42,700,1,13.98,2,1,13.99,100,1,14.22,100,1,14.48,1400,2,14.53,100,1,14.54,700,1,14.6,100,1,14.68,700,1,14.77,100,1,14.81,100,1,ARL,349364085
1871,2025-07-17T16:21:18.838792785Z,2025-07-17T16:21:18.838627443Z,10,2,1108,C,B,0,13.11,10,130,165342,290472869,13.11,100,1,12.98,200,2,12.96,2,1,12.86,100,1,12.73,100,1,12.71,100,1,12.5,700,1,12.46,100,1,12.43,700,1,12.42,700,1,13.98,2,1,13.99,100,1,14.22,100,1,14.48,1400,2,14.53,100,1,14.54,700,1,14.6,100,1,14.68,700,1,14.77,100,1,14.81,100,1,ARL,349365825
1872,2025-07-17T16:21:19.432468330Z,2025-07-17T16:21:19.432302263Z,10,2,1108,A,A,3,14.32,100,130,166067,290480833,13.11,100,1,12.98,200,2,12.96,2,1,12.86,100,1,12.73,100,1,12.71,100,1,12.5,700,1,12.46,100,1,12.43,700,1,12.42,700,1,13.98,2,1,13.99,100,1,14.22,100,1,14.32,100,1,14.48,1400,2,14.53,100,1,14.54,700,1,14.6,100,1,14.68,700,1,14.77,100,1,ARL,349491773
1873,2025-07-17T16:21:19.432869322Z,2025-07-17T16:21:19.432703556Z,10,2,1108,A,A,3,14.32,100,130,165766,290480840,13.11,100,1,12.98,200,2,12.96,2,1,12.86,100,1,12.73,100,1,12.71,100,1,12.5,700,1,12.46,100,1,12.43,700,1,12.42,700,1,13.98,2,1,13.99,100,1,14.22,100,1,14.32,200,2,14.48,1400,2,14.53,100,1,14.54,700,1,14.6,100,1,14.68,700,1,14.77,100,1,ARL,349491781
1874,2025-07-17T16:21:21.559994951Z,2025-07-17T16:21:21.559829242Z,10,2,1108,C,A,3,14.32,100,0,165709,290520485,13.11,100,1,12.98,200,2,12.96,2,1,12.86,100,1,12.73,100,1,12.71,100,1,12.5,700,1,12.46,100,1,12.43,700,1,12.42,700,1,13.98,2,1,13.99,100,1,14.22,100,1,14.32,100,1,14.48,1400,2,14.53,100,1,14.54,700,1,14.6,100,1,14.68,700,1,14.77,100,1,ARL,349491781
1875,2025-07-17T16:21:21.560117656Z,2025-07-17T16:21:21.559952130Z,10,2,1108,C,A,-1,14.32,100,0,165526,290520492,13.11,100,1,12.98,200,2,12.96,2,1,12.86,100,1,12.73,100,1,12.71,100,1,12.5,700,1,12.46,100,1,12.43,700,1,12.42,700,1,13.98,2,1,13.99,100,1,14.22,100,1,14.48,1400,2,14.53,100,1,14.54,700,1,14.6,100,1,14.68,700,1,14.77,100,1,14.81,100,1,ARL,349491773
1876,2025-07-17T16:21:24.785963512Z,2025-07-17T16:21:24.785797985Z,10,2,1108,C,B,-1,12.96,2,0,165527,290591357,13.11,100,1,12.98,200,2,12.86,100,1,12.73,100,1,12.71,100,1,12.5,700,1,12.46,100,1,12.43,700,1,12.42,700,1,12.37,700,1,13.98,2,1,13.99,100,1,14.22,100,1,14.48,1400,2,14.53,100,1,14.54,700,1,14.6,100,1,14.68,700,1,14.77,100,1,14.81,100,1,ARL,348838809
1877,2025-07-17T16:21:24.785963512Z,2025-07-17T16:21:24.785797985Z,10,2,1108,A,B,1,13.04,2,130,165527,290591357,13.11,100,1,13.04,2,1,12.98,200,2,12.86,100,1,12.73,100,1,12.71,100,1,12.5,700,1,12.46,100,1,12.43,700,1,12.42,700,1,13.98,2,1,13.99,100,1,14.22,100,1,14.48,1400,2,14.53,100,1,14.54,700,1,14.6,100,1,14.68,700,1,14.77,100,1,14.81,100,1,ARL,349635277
1878,2025-07-17T16:21:30.041882933Z,2025-07-17T16:21:30.041717299Z,10,2,1108,A,A,3,14.33,100,130,165634,290665095,13.11,100,1,13.04,2,1,12.98,200,2,12.86,100,1,12.73,100,1,12.71,100,1,12.5,700,1,12.46,100,1,12.43,700,1,12.42,700,1,13.98,2,1,13.99,100,1,14.22,100,1,14.33,100,1,14.48,1400,2,14.53,100,1,14.54,700,1,14.6,100,1,14.68,700,1,14.77,100,1,ARL,349727893
1879,2025-07-17T16:21:30.042068124Z,2025-07-17T16:21:30.041902504Z,10,2,1108,A,A,3,14.33,100,130,165620,290665107,13.11,100,1,13.04,2,1,12.98,200,2,12.86,100,1,12.73,100,1,12.71,100,1,12.5,700,1,12.46,100,1,12.43,700,1,12.42,700,1,13.98,2,1,13.99,100,1,14.22,100,1,14.33,200,2,14.48,1400,2,14.53,100,1,14.54,700,1,14.6,100,1,14.68,700,1,14.77,100,1,ARL,349727897
1880,2025-07-17T16:21:32.891561821Z,2025-07-17T16:21:32.891396207Z,10,2,1108,C,A,3,14.33,100,0,165614,290706797,13.11,100,1,13.04,2,1,12.98,200,2,12.86,100,1,12.73,100,1,12.71,100,1,12.5,700,1,12.46,100,1,12.43,700,1,12.42,700,1,13.98,2,1,13.99,100,1,14.22,100,1,14.33,100,1,14.48,1400,2,14.53,100,1,14.54,700,1,14.6,100,1,14.68,700,1,14.77,100,1,ARL,349727893
1881,2025-07-17T16:21:32.920860700Z,2025-07-17T16:21:32.920695054Z,10,2,1108,C,A,-1,14.33,100,0,165646,290707080,13.11,100,1,13.04,2,1,12.98,200,2,12.86,100,1,12.73,100,1,12.71,100,1,12.5,700,1,12.46,100,1,12.43,700,1,12.42,700,1,13.98,2,1,13.99,100,1,14.22,100,1,14.48,1400,2,14.53,100,1,14.54,700,1,14.6,100,1,14.68,700,1,14.77,100,1,14.81,100,1,ARL,349727897
1882,2025-07-17T16:22:10.251959183Z,2025-07-17T16:22:10.251792275Z,10,2,1108,A,A,0,13.43,15,128,166908,291313152,13.11,100,1,13.04,2,1,12.98,200,2,12.86,100,1,12.73,100,1,12.71,100,1,12.5,700,1,12.46,100,1,12.43,700,1,12.42,700,1,13.43,15,1,13.98,2,1,13.99,100,1,14.22,100,1,14.48,1400,2,14.53,100,1,14.54,700,1,14.6,100,1,14.68,700,1,14.77,100,1,ARL,350555261
1883,2025-07-17T16:22:10.252448946Z,2025-07-17T16:22:10.252282744Z,10,2,1108,A,A,4,14.33,100,130,166202,291313277,13.11,100,1,13.04,2,1,12.98,200,2,12.86,100,1,12.73,100,1,12.71,100,1,12.5,700,1,12.46,100,1,12.43,700,1,12.42,700,1,13.43,15,1,13.98,2,1,13.99,100,1,14.22,100,1,14.33,100,1,14.48,1400,2,14.53,100,1,14.54,700,1,14.6,100,1,14.68,700,1,ARL,350555469
1884,2025-07-17T16:22:10.253186614Z,2025-07-17T16:22:10.253020717Z,10,2,1108,A,A,4,14.33,100,130,165897,291313433,13.11,100,1,13.04,2,1,12.98,200,2,12.86,100,1,12.73,100,1,12.71,100,1,12.5,700,1,12.46,100,1,12.43,700,1,12.42,700,1,13.43,15,1,13.98,2,1,13.99,100,1,14.22,100,1,14.33,200,2,14.48,1400,2,14.53,100,1,14.54,700,1,14.6,100,1,14.68,700,1,ARL,350555717
1885,2025-07-17T16:22:10.259208076Z,2025-07-17T16:22:10.259042453Z,10,2,1108,C,A,-1,13.99,100,0,165623,291313986,13.11,100,1,13.04,2,1,12.98,200,2,12.86,100,1,12.73,100,1,12.71,100,1,12.5,700,1,12.46,100,1,12.43,700,1,12.42,700,1,13.43,15,1,13.98,2,1,14.22,100,1,14.33,200,2,14.48,1400,2,14.53,100,1,14.54,700,1,14.6,100,1,14.68,700,1,14.77,100,1,ARL,349380925
1886,2025-07-17T16:22:10.259208076Z,2025-07-17T16:22:10.259042453Z,10,2,1108,A,A,1,13.96,100,130,165623,291313986,13.11,100,1,13.04,2,1,12.98,200,2,12.86,100,1,12.73,100,1,12.71,100,1,12.5,700,1,12.46,100,1,12.43,700,1,12.42,700,1,13.43,15,1,13.96,100,1,13.98,2,1,14.22,100,1,14.33,200,2,14.48,1400,2,14.53,100,1,14.54,700,1,14.6,100,1,14.68,700,1,ARL,350556253
1887,2025-07-17T16:22:10.651568698Z,2025-07-17T16:22:10.651403186Z,10,2,1108,C,A,-1,13.43,15,130,165512,291322198,13.11,100,1,13.04,2,1,12.98,200,2,12.86,100,1,12.73,100,1,12.71,100,1,12.5,700,1,12.46,100,1,12.43,700,1,12.42,700,1,13.96,100,1,13.98,2,1,14.22,100,1,14.33,200,2,14.48,1400,2,14.53,100,1,14.54,700,1,14.6,100,1,14.68,700,1,14.77,100,1,ARL,350555261
1888,2025-07-17T16:22:11.256335174Z,2025-07-17T16:22:11.256169948Z,10,2,1108,C,A,3,14.33,100,0,165226,291329858,13.11,100,1,13.04,2,1,12.98,200,2,12.86,100,1,12.73,100,1,12.71,100,1,12.5,700,1,12.46,100,1,12.43,700,1,12.42,700,1,13.96,100,1,13.98,2,1,14.22,100,1,14.33,100,1,14.48,1400,2,14.53,100,1,14.54,700,1,14.6,100,1,14.68,700,1,14.77,100,1,ARL,350555717
1889,2025-07-17T16:22:11.294105967Z,2025-07-17T16:22:11.293940494Z,10,2,1108,C,A,-1,14.33,100,0,165473,291330189,13.11,100,1,13.04,2,1,12.98,200,2,12.86,100,1,12.73,100,1,12.71,100,1,12.5,700,1,12.46,100,1,12.43,700,1,12.42,700,1,13.96,100,1,13.98,2,1,14.22,100,1,14.48,1400,2,14.53,100,1,14.54,700,1,14.6,100,1,14.68,700,1,14.77,100,1,14.81,100,1,ARL,350555469
1890,2025-07-17T16:23:50.726518986Z,2025-07-17T16:23:50.726353370Z,10,2,1108,A,A,3,14.33,100,130,165616,292930335,13.11,100,1,13.04,2,1,12.98,200,2,12.86,100,1,12.73,100,1,12.71,100,1,12.5,700,1,12.46,100,1,12.43,700,1,12.42,700,1,13.96,100,1,13.98,2,1,14.22,100,1,14.33,100,1,14.48,1400,2,14.53,100,1,14.54,700,1,14.6,100,1,14.68,700,1,14.77,100,1,ARL,352599713
1891,2025-07-17T16:23:50.751793627Z,2025-07-17T16:23:50.751628250Z,10,2,1108,A,A,3,14.33,100,130,165377,292931023,13.11,100,1,13.04,2,1,12.98,200,2,12.86,100,1,12.73,100,1,12.71,100,1,12.5,700,1,12.46,100,1,12.43,700,1,12.42,700,1,13.96,100,1,13.98,2,1,14.22,100,1,14.33,200,2,14.48,1400,2,14.53,100,1,14.54,700,1,14.6,100,1,14.68,700,1,14.77,100,1,ARL,352600973
1892,2025-07-17T16:23:55.522925458Z,2025-07-17T16:23:55.522760301Z,10,2,1108,A,A,0,13.42,15,130,165157,293010586,13.11,100,1,13.04,2,1,12.98,200,2,12.86,100,1,12.73,100,1,12.71,100,1,12.5,700,1,12.46,100,1,12.43,700,1,12.42,700,1,13.42,15,1,13.96,100,1,13.98,2,1,14.22,100,1,14.33,200,2,14.48,1400,2,14.53,100,1,14.54,700,1,14.6,100,1,14.68,700,1,ARL,352702077
1893,2025-07-17T16:23:56.914860179Z,2025-07-17T16:23:56.914694445Z,10,2,1108,C,A,-1,13.96,100,0,165734,293025765,13.11,100,1,13.04,2,1,12.98,200,2,12.86,100,1,12.73,100,1,12.71,100,1,12.5,700,1,12.46,100,1,12.43,700,1,12.42,700,1,13.42,15,1,13.98,2,1,14.22,100,1,14.33,200,2,14.48,1400,2,14.53,100,1,14.54,700,1,14.6,100,1,14.68,700,1,14.77,100,1,ARL,350556253
1894,2025-07-17T16:23:56.914860179Z,2025-07-17T16:23:56.914694445Z,10,2,1108,A,A,1,13.95,100,130,165734,293025765,13.11,100,1,13.04,2,1,12.98,200,2,12.86,100,1,12.73,100,1,12.71,100,1,12.5,700,1,12.46,100,1,12.43,700,1,12.42,700,1,13.42,15,1,13.95,100,1,13.98,2,1,14.22,100,1,14.33,200,2,14.48,1400,2,14.53,100,1,14.54,700,1,14.6,100,1,14.68,700,1,ARL,352722381
1895,2025-07-17T16:23:58.527884533Z,2025-07-17T16:23:58.527719150Z,10,2,1108,A,A,0,13.4,15,130,165383,293099007,13.11,100,1,13.04,2,1,12.98,200,2,12.86,100,1,12.73,100,1,12.71,100,1,12.5,700,1,12.46,100,1,12.43,700,1,12.42,700,1,13.4,15,1,13.42,15,1,13.95,100,1,13.98,2,1,14.22,100,1,14.33,200,2,14.48,1400,2,14.53,100,1,14.54,700,1,14.6,100,1,ARL,352791109
1896,2025-07-17T16:23:58.631872329Z,2025-07-17T16:23:58.631706924Z,10,2,1108,C,A,-1,13.95,100,0,165405,293104471,13.11,100,1,13.04,2,1,12.98,200,2,12.86,100,1,12.73,100,1,12.71,100,1,12.5,700,1,12.46,100,1,12.43,700,1,12.42,700,1,13.4,15,1,13.42,15,1,13.98,2,1,14.22,100,1,14.33,200,2,14.48,1400,2,14.53,100,1,14.54,700,1,14.6,100,1,14.68,700,1,ARL,352722381
1897,2025-07-17T16:23:58.631872329Z,2025-07-17T16:23:58.631706924Z,10,2,1108,A,A,2,13.93,100,130,165405,293104471,13.11,100,1,13.04,2,1,12.98,200,2,12.86,100,1,12.73,100,1,12.71,100,1,12.5,700,1,12.46,100,1,12.43,700,1,12.42,700,1,13.4,15,1,13.42,15,1,13.93,100,1,13.98,2,1,14.22,100,1,14.33,200,2,14.48,1400,2,14.53,100,1,14.54,700,1,14.6,100,1,ARL,352794377
1898,2025-07-17T16:24:02.427373552Z,2025-07-17T16:24:02.427208036Z,10,2,1108,C,A,-1,13.42,15,130,165516,293179655,13.11,100,1,13.04,2,1,12.98,200,2,12.86,100,1,12.73,100,1,12.71,100,1,12.5,700,1,12.46,100,1,12.43,700,1,12.42,700,1,13.4,15,1,13.93,100,1,13.98,2,1,14.22,100,1,14.33,200,2,14.48,1400,2,14.53,100,1,14.54,700,1,14.6,100,1,14.68,700,1,ARL,352702077
1899,2025-07-17T16:24:04.377837794Z,2025-07-17T16:24:04.377672438Z,10,2,1108,A,A,0,13.38,15,130,165356,293217696,13.11,100,1,13.04,2,1,12.98,200,2,12.86,100,1,12.73,100,1,12.71,100,1,12.5,700,1,12.46,100,1,12.43,700,1,12.42,700,1,13.38,15,1,13.4,15,1,13.93,100,1,13.98,2,1,14.22,100,1,14.33,200,2,14.48,1400,2,14.53,100,1,14.54,700,1,14.6,100,1,ARL,352939445
1900,2025-07-17T16:24:04.378891069Z,2025-07-17T16:24:04.378725117Z,10,2,1108,C,A,-1,13.93,100,0,165952,293217731,13.11,100,1,13.04,2,1,12.98,200,2,12.86,100,1,12.73,100,1,12.71,100,1,12.5,700,1,12.46,100,1,12.43,700,1,12.42,700,1,13.38,15,1,13.4,15,1,13.98,2,1,14.22,100,1,14.33,200,2,14.48,1400,2,14.53,100,1,14.54,700,1,14.6,100,1,14.68,700,1,ARL,352794377
1901,2025-07-17T16:24:04.378891069Z,2025-07-17T16:24:04.378725117Z,10,2,1108,A,A,2,13.91,100,130,165952,293217731,13.11,100,1,13.04,2,1,12.98,200,2,12.86,100,1,12.73,100,1,12.71,100,1,12.5,700,1,12.46,100,1,12.43,700,1,12.42,700,1,13.38,15,1,13.4,15,1,13.91,100,1,13.98,2,1,14.22,100,1,14.33,200,2,14.48,1400,2,14.53,100,1,14.54,700,1,14.6,100,1,ARL,352939465
1902,2025-07-17T16:25:06.191451123Z,2025-07-17T16:25:06.191285410Z,10,2,1108,C,B,-1,13.04,2,0,165713,294247609,13.11,100,1,12.98,200,2,12.86,100,1,12.73,100,1,12.71,100,1,12.5,700,1,12.46,100,1,12.43,700,1,12.42,700,1,12.37,700,1,13.38,15,1,13.4,15,1,13.91,100,1,13.98,2,1,14.22,100,1,14.33,200,2,14.48,1400,2,14.53,100,1,14.54,700,1,14.6,100,1,ARL,349635277
1903,2025-07-17T16:25:06.191451123Z,2025-07-17T16:25:06.191285410Z,10,2,1108,A,B,0,13.11,2,130,165713,294247609,13.11,102,2,12.98,200,2,12.86,100,1,12.73,100,1,12.71,100,1,12.5,700,1,12.46,100,1,12.43,700,1,12.42,700,1,12.37,700,1,13.38,15,1,13.4,15,1,13.91,100,1,13.98,2,1,14.22,100,1,14.33,200,2,14.48,1400,2,14.53,100,1,14.54,700,1,14.6,100,1,ARL,354187617
1904,2025-07-17T16:25:08.976415732Z,2025-07-17T16:25:08.976249966Z,10,2,1108,C,A,-1,13.98,2,0,165766,294349676,13.11,102,2,12.98,200,2,12.86,100,1,12.73,100,1,12.71,100,1,12.5,700,1,12.46,100,1,12.43,700,1,12.42,700,1,12.37,700,1,13.38,15,1,13.4,15,1,13.91,100,1,14.22,100,1,14.33,200,2,14.48,1400,2,14.53,100,1,14.54,700,1,14.6,100,1,14.68,700,1,ARL,349366297
1905,2025-07-17T16:25:08.976415732Z,2025-07-17T16:25:08.976249966Z,10,2,1108,A,A,2,13.91,2,130,165766,294349676,13.11,102,2,12.98,200,2,12.86,100,1,12.73,100,1,12.71,100,1,12.5,700,1,12.46,100,1,12.43,700,1,12.42,700,1,12.37,700,1,13.38,15,1,13.4,15,1,13.91,102,2,14.22,100,1,14.33,200,2,14.48,1400,2,14.53,100,1,14.54,700,1,14.6,100,1,14.68,700,1,ARL,354292533
1906,2025-07-17T16:25:35.129072184Z,2025-07-17T16:25:35.128903877Z,10,2,1108,C,A,-1,13.38,15,128,168307,294934217,13.11,102,2,12.98,200,2,12.86,100,1,12.73,100,1,12.71,100,1,12.5,700,1,12.46,100,1,12.43,700,1,12.42,700,1,12.37,700,1,13.4,15,1,13.91,102,2,14.22,100,1,14.33,200,2,14.48,1400,2,14.53,100,1,14.54,700,1,14.6,100,1,14.68,700,1,14.77,100,1,ARL,352939445
1907,2025-07-17T16:25:39.510507211Z,2025-07-17T16:25:39.510341866Z,10,2,1108,C,A,-1,13.4,15,130,165345,295034059,13.11,102,2,12.98,200,2,12.86,100,1,12.73,100,1,12.71,100,1,12.5,700,1,12.46,100,1,12.43,700,1,12.42,700,1,12.37,700,1,13.91,102,2,14.22,100,1,14.33,200,2,14.48,1400,2,14.53,100,1,14.54,700,1,14.6,100,1,14.68,700,1,14.77,100,1,14.81,100,1,ARL,352791109
1908,2025-07-17T16:25:39.511158862Z,2025-07-17T16:25:39.510992800Z,10,2,1108,C,A,2,14.33,100,0,166062,295034078,13.11,102,2,12.98,200,2,12.86,100,1,12.73,100,1,12.71,100,1,12.5,700,1,12.46,100,1,12.43,700,1,12.42,700,1,12.37,700,1,13.91,102,2,14.22,100,1,14.33,100,1,14.48,1400,2,14.53,100,1,14.54,700,1,14.6,100,1,14.68,700,1,14.77,100,1,14.81,100,1,ARL,352599713
1909,2025-07-17T16:25:39.511158862Z,2025-07-17T16:25:39.510992800Z,10,2,1108,A,A,9,14.8,100,130,166062,295034078,13.11,102,2,12.98,200,2,12.86,100,1,12.73,100,1,12.71,100,1,12.5,700,1,12.46,100,1,12.43,700,1,12.42,700,1,12.37,700,1,13.91,102,2,14.22,100,1,14.33,100,1,14.48,1400,2,14.53,100,1,14.54,700,1,14.6,100,1,14.68,700,1,14.77,100,1,14.8,100,1,ARL,355038285
1910,2025-07-17T16:25:39.511772004Z,2025-07-17T16:25:39.511606124Z,10,2,1108,C,A,-1,14.33,100,0,165880,295034094,13.11,102,2,12.98,200,2,12.86,100,1,12.73,100,1,12.71,100,1,12.5,700,1,12.46,100,1,12.43,700,1,12.42,700,1,12.37,700,1,13.91,102,2,14.22,100,1,14.48,1400,2,14.53,100,1,14.54,700,1,14.6,100,1,14.68,700,1,14.77,100,1,14.8,100,1,14.81,100,1,ARL,352600973
1911,2025-07-17T16:25:39.511772004Z,2025-07-17T16:25:39.511606124Z,10,2,1108,A,A,8,14.8,100,130,165880,295034094,13.11,102,2,12.98,200,2,12.86,100,1,12.73,100,1,12.71,100,1,12.5,700,1,12.46,100,1,12.43,700,1,12.42,700,1,12.37,700,1,13.91,102,2,14.22,100,1,14.48,1400,2,14.53,100,1,14.54,700,1,14.6,100,1,14.68,700,1,14.77,100,1,14.8,200,2,14.81,100,1,ARL,355038317
1912,2025-07-17T16:25:39.513587612Z,2025-07-17T16:25:39.513422230Z,10,2,1108,A,B,0,13.11,10,130,165382,295034123,13.11,112,3,12.98,200,2,12.86,100,1,12.73,100,1,12.71,100,1,12.5,700,1,12.46,100,1,12.43,700,1,12.42,700,1,12.37,700,1,13.91,102,2,14.22,100,1,14.48,1400,2,14.53,100,1,14.54,700,1,14.6,100,1,14.68,700,1,14.77,100,1,14.8,200,2,14.81,100,1,ARL,355038373
1913,2025-07-17T16:25:40.874979428Z,2025-07-17T16:25:40.874808027Z,10,2,1108,A,A,0,13.9,15,130,171401,295093819,13.11,112,3,12.98,200,2,12.86,100,1,12.73,100,1,12.71,100,1,12.5,700,1,12.46,100,1,12.43,700,1,12.42,700,1,12.37,700,1,13.9,15,1,13.91,102,2,14.22,100,1,14.48,1400,2,14.53,100,1,14.54,700,1,14.6,100,1,14.68,700,1,14.77,100,1,14.8,200,2,ARL,355097305
1914,2025-07-17T16:25:49.509607483Z,2025-07-17T16:25:49.509442229Z,10,2,1108,C,B,0,13.11,10,130,165254,295316849,13.11,102,2,12.98,200,2,12.86,100,1,12.73,100,1,12.71,100,1,12.5,700,1,12.46,100,1,12.43,700,1,12.42,700,1,12.37,700,1,13.9,15,1,13.91,102,2,14.22,100,1,14.48,1400,2,14.53,100,1,14.54,700,1,14.6,100,1,14.68,700,1,14.77,100,1,14.8,200,2,ARL,355038373
1915,2025-07-17T16:25:54.511931358Z,2025-07-17T16:25:54.511765715Z,10,2,1108,A,A,0,13.84,15,130,165643,295392773,13.11,102,2,12.98,200,2,12.86,100,1,12.73,100,1,12.71,100,1,12.5,700,1,12.46,100,1,12.43,700,1,12.42,700,1,12.37,700,1,13.84,15,1,13.9,15,1,13.91,102,2,14.22,100,1,14.48,1400,2,14.53,100,1,14.54,700,1,14.6,100,1,14.68,700,1,14.77,100,1,ARL,355455441
1916,2025-07-17T16:25:54.512201450Z,2025-07-17T16:25:54.512035936Z,10,2,1108,C,A,2,13.91,100,0,165514,295392775,13.11,102,2,12.98,200,2,12.86,100,1,12.73,100,1,12.71,100,1,12.5,700,1,12.46,100,1,12.43,700,1,12.42,700,1,12.37,700,1,13.84,15,1,13.9,15,1,13.91,2,1,14.22,100,1,14.48,1400,2,14.53,100,1,14.54,700,1,14.6,100,1,14.68,700,1,14.77,100,1,ARL,352939465
1917,2025-07-17T16:25:54.512201450Z,2025-07-17T16:25:54.512035936Z,10,2,1108,A,A,1,13.85,100,130,165514,295392775,13.11,102,2,12.98,200,2,12.86,100,1,12.73,100,1,12.71,100,1,12.5,700,1,12.46,100,1,12.43,700,1,12.42,700,1,12.37,700,1,13.84,15,1,13.85,100,1,13.9,15,1,13.91,2,1,14.22,100,1,14.48,1400,2,14.53,100,1,14.54,700,1,14.6,100,1,14.68,700,1,ARL,355455445
1918,2025-07-17T16:25:54.535083079Z,2025-07-17T16:25:54.534917732Z,10,2,1108,C,A,-1,14.22,100,130,165347,295392911,13.11,102,2,12.98,200,2,12.86,100,1,12.73,100,1,12.71,100,1,12.5,700,1,12.46,100,1,12.43,700,1,12.42,700,1,12.37,700,1,13.84,15,1,13.85,100,1,13.9,15,1,13.91,2,1,14.48,1400,2,14.53,100,1,14.54,700,1,14.6,100,1,14.68,700,1,14.77,100,1,ARL,349366121
1919,2025-07-17T16:25:54.535135667Z,2025-07-17T16:25:54.534970016Z,10,2,1108,A,A,4,14.13,100,130,165651,295392912,13.11,102,2,12.98,200,2,12.86,100,1,12.73,100,1,12.71,100,1,12.5,700,1,12.46,100,1,12.43,700,1,12.42,700,1,12.37,700,1,13.84,15,1,13.85,100,1,13.9,15,1,13.91,2,1,14.13,100,1,14.48,1400,2,14.53,100,1,14.54,700,1,14.6,100,1,14.68,700,1,ARL,355455809
1920,2025-07-17T16:26:01.563589927Z,2025-07-17T16:26:01.563424507Z,10,2,1108,C,A,-1,13.9,15,130,165420,295507323,13.11,102,2,12.98,200,2,12.86,100,1,12.73,100,1,12.71,100,1,12.5,700,1,12.46,100,1,12.43,700,1,12.42,700,1,12.37,700,1,13.84,15,1,13.85,100,1,13.91,2,1,14.13,100,1,14.48,1400,2,14.53,100,1,14.54,700,1,14.6,100,1,14.68,700,1,14.77,100,1,ARL,355097305
1921,2025-07-17T16:26:05.322538883Z,2025-07-17T16:26:05.322373598Z,10,2,1108,A,A,0,13.82,15,130,165285,295580795,13.11,102,2,12.98,200,2,12.86,100,1,12.73,100,1,12.71,100,1,12.5,700,1,12.46,100,1,12.43,700,1,12.42,700,1,12.37,700,1,13.82,15,1,13.84,15,1,13.85,100,1,13.91,2,1,14.13,100,1,14.48,1400,2,14.53,100,1,14.54,700,1,14.6,100,1,14.68,700,1,ARL,355692501
1922,2025-07-17T16:26:05.323669349Z,2025-07-17T16:26:05.323503152Z,10,2,1108,C,A,-1,13.85,100,0,166197,295580842,13.11,102,2,12.98,200,2,12.86,100,1,12.73,100,1,12.71,100,1,12.5,700,1,12.46,100,1,12.43,700,1,12.42,700,1,12.37,700,1,13.82,15,1,13.84,15,1,13.91,2,1,14.13,100,1,14.48,1400,2,14.53,100,1,14.54,700,1,14.6,100,1,14.68,700,1,14.77,100,1,ARL,355455445
1923,2025-07-17T16:26:05.323669349Z,2025-07-17T16:26:05.323503152Z,10,2,1108,A,A,1,13.83,100,130,166197,295580842,13.11,102,2,12.98,200,2,12.86,100,1,12.73,100,1,12.71,100,1,12.5,700,1,12.46,100,1,12.43,700,1,12.42,700,1,12.37,700,1,13.82,15,1,13.83,100,1,13.84,15,1,13.91,2,1,14.13,100,1,14.48,1400,2,14.53,100,1,14.54,700,1,14.6,100,1,14.68,700,1,ARL,355692553
1924,2025-07-17T16:26:05.328320637Z,2025-07-17T16:26:05.328155098Z,10,2,1108,A,A,9,14.62,100,130,165539,295581043,13.11,102,2,12.98,200,2,12.86,100,1,12.73,100,1,12.71,100,1,12.5,700,1,12.46,100,1,12.43,700,1,12.42,700,1,12.37,700,1,13.82,15,1,13.83,100,1,13.84,15,1,13.91,2,1,14.13,100,1,14.48,1400,2,14.53,100,1,14.54,700,1,14.6,100,1,14.62,100,1,ARL,355692649
1925,2025-07-17T16:26:10.885379151Z,2025-07-17T16:26:10.885204270Z,10,2,1108,C,A,-1,13.84,15,128,174881,295674513,13.11,102,2,12.98,200,2,12.86,100,1,12.73,100,1,12.71,100,1,12.5,700,1,12.46,100,1,12.43,700,1,12.42,700,1,12.37,700,1,13.82,15,1,13.83,100,1,13.91,2,1,14.13,100,1,14.48,1400,2,14.53,100,1,14.54,700,1,14.6,100,1,14.62,100,1,14.68,700,1,ARL,355455441
1926,2025-07-17T16:26:12.458773012Z,2025-07-17T16:26:12.458607766Z,10,2,1108,A,A,0,13.8,15,130,165246,295697152,13.11,102,2,12.98,200,2,12.86,100,1,12.73,100,1,12.71,100,1,12.5,700,1,12.46,100,1,12.43,700,1,12.42,700,1,12.37,700,1,13.8,15,1,13.82,15,1,13.83,100,1,13.91,2,1,14.13,100,1,14.48,1400,2,14.53,100,1,14.54,700,1,14.6,100,1,14.62,100,1,ARL,355834369
1927,2025-07-17T16:26:12.459039500Z,2025-07-17T16:26:12.458873979Z,10,2,1108,C,A,-1,13.83,100,0,165521,295697153,13.11,102,2,12.98,200,2,12.86,100,1,12.73,100,1,12.71,100,1,12.5,700,1,12.46,100,1,12.43,700,1,12.42,700,1,12.37,700,1,13.8,15,1,13.82,15,1,13.91,2,1,14.13,100,1,14.48,1400,2,14.53,100,1,14.54,700,1,14.6,100,1,14.62,100,1,14.68,700,1,ARL,355692553
1928,2025-07-17T16:26:12.459039500Z,2025-07-17T16:26:12.458873979Z,10,2,1108,A,A,1,13.81,100,130,165521,295697153,13.11,102,2,12.98,200,2,12.86,100,1,12.73,100,1,12.71,100,1,12.5,700,1,12.46,100,1,12.43,700,1,12.42,700,1,12.37,700,1,13.8,15,1,13.81,100,1,13.82,15,1,13.91,2,1,14.13,100,1,14.48,1400,2,14.53,100,1,14.54,700,1,14.6,100,1,14.62,100,1,ARL,355834377
1929,2025-07-17T16:26:21.188384358Z,2025-07-17T16:26:21.188218529Z,10,2,1108,C,B,0,13.11,2,0,165829,295810309,13.11,100,1,12.98,200,2,12.86,100,1,12.73,100,1,12.71,100,1,12.5,700,1,12.46,100,1,12.43,700,1,12.42,700,1,12.37,700,1,13.8,15,1,13.81,100,1,13.82,15,1,13.91,2,1,14.13,100,1,14.48,1400,2,14.53,100,1,14.54,700,1,14.6,100,1,14.62,100,1,ARL,354187617
1930,2025-07-17T16:26:21.188384358Z,2025-07-17T16:26:21.188218529Z,10,2,1108,A,B,1,13.01,2,130,165829,295810309,13.11,100,1,13.01,2,1,12.98,200,2,12.86,100,1,12.73,100,1,12.71,100,1,12.5,700,1,12.46,100,1,12.43,700,1,12.42,700,1,13.8,15,1,13.81,100,1,13.82,15,1,13.91,2,1,14.13,100,1,14.48,1400,2,14.53,100,1,14.54,700,1,14.6,100,1,14.62,100,1,ARL,355990209
1931,2025-07-17T16:26:22.849649042Z,2025-07-17T16:26:22.849483693Z,10,2,1108,C,A,-1,13.82,15,130,165349,295833352,13.11,100,1,13.01,2,1,12.98,200,2,12.86,100,1,12.73,100,1,12.71,100,1,12.5,700,1,12.46,100,1,12.43,700,1,12.42,700,1,13.8,15,1,13.81,100,1,13.91,2,1,14.13,100,1,14.48,1400,2,14.53,100,1,14.54,700,1,14.6,100,1,14.62,100,1,14.68,900,3,ARL,355692501
1932,2025-07-17T16:26:32.848769442Z,2025-07-17T16:26:32.848604005Z,10,2,1108,A,A,0,13.76,15,130,165437,295978389,13.11,100,1,13.01,2,1,12.98,200,2,12.86,100,1,12.73,100,1,12.71,100,1,12.5,700,1,12.46,100,1,12.43,700,1,12.42,700,1,13.76,15,1,13.8,15,1,13.81,100,1,13.91,2,1,14.13,100,1,14.48,1400,2,14.53,100,1,14.54,700,1,14.6,100,1,14.62,100,1,ARL,356212397
1933,2025-07-17T16:26:34.579093883Z,2025-07-17T16:26:34.578928535Z,10,2,1108,C,A,-1,13.81,100,0,165348,296006812,13.11,100,1,13.01,2,1,12.98,200,2,12.86,100,1,12.73,100,1,12.71,100,1,12.5,700,1,12.46,100,1,12.43,700,1,12.42,700,1,13.76,15,1,13.8,15,1,13.91,2,1,14.13,100,1,14.48,1400,2,14.53,100,1,14.54,700,1,14.6,100,1,14.62,100,1,14.68,900,3,ARL,355834377
1934,2025-07-17T16:26:34.579093883Z,2025-07-17T16:26:34.578928535Z,10,2,1108,A,A,1,13.77,100,130,165348,296006812,13.11,100,1,13.01,2,1,12.98,200,2,12.86,100,1,12.73,100,1,12.71,100,1,12.5,700,1,12.46,100,1,12.43,700,1,12.42,700,1,13.76,15,1,13.77,100,1,13.8,15,1,13.91,2,1,14.13,100,1,14.48,1400,2,14.53,100,1,14.54,700,1,14.6,100,1,14.62,100,1,ARL,356249197
1935,2025-07-17T16:26:34.579833477Z,2025-07-17T16:26:34.579668245Z,10,2,1108,C,A,-1,14.6,100,130,165232,296006823,13.11,100,1,13.01,2,1,12.98,200,2,12.86,100,1,12.73,100,1,12.71,100,1,12.5,700,1,12.46,100,1,12.43,700,1,12.42,700,1,13.76,15,1,13.77,100,1,13.8,15,1,13.91,2,1,14.13,100,1,14.48,1400,2,14.53,100,1,14.54,700,1,14.62,100,1,14.68,900,3,ARL,349378277
1936,2025-07-17T16:26:34.580190182Z,2025-07-17T16:26:34.580024867Z,10,2,1108,A,A,5,14.38,100,130,165315,296006828,13.11,100,1,13.01,2,1,12.98,200,2,12.86,100,1,12.73,100,1,12.71,100,1,12.5,700,1,12.46,100,1,12.43,700,1,12.42,700,1,13.76,15,1,13.77,100,1,13.8,15,1,13.91,2,1,14.13,100,1,14.38,100,1,14.48,1400,2,14.53,100,1,14.54,700,1,14.62,100,1,ARL,356249249
1937,2025-07-17T16:26:34.598179865Z,2025-07-17T16:26:34.598014487Z,10,2,1108,C,A,-1,14.13,100,130,165378,296007149,13.11,100,1,13.01,2,1,12.98,200,2,12.86,100,1,12.73,100,1,12.71,100,1,12.5,700,1,12.46,100,1,12.43,700,1,12.42,700,1,13.76,15,1,13.77,100,1,13.8,15,1,13.91,2,1,14.38,100,1,14.48,1400,2,14.53,100,1,14.54,700,1,14.62,100,1,14.68,900,3,ARL,355455809
1938,2025-07-17T16:26:34.598231978Z,2025-07-17T16:26:34.598066762Z,10,2,1108,A,A,4,14.05,100,130,165216,296007150,13.11,100,1,13.01,2,1,12.98,200,2,12.86,100,1,12.73,100,1,12.71,100,1,12.5,700,1,12.46,100,1,12.43,700,1,12.42,700,1,13.76,15,1,13.77,100,1,13.8,15,1,13.91,2,1,14.05,100,1,14.38,100,1,14.48,1400,2,14.53,100,1,14.54,700,1,14.62,100,1,ARL,356249781
1939,2025-07-17T16:26:40.082074080Z,2025-07-17T16:26:40.081907812Z,10,2,1108,C,A,-1,13.8,15,130,166268,296079992,13.11,100,1,13.01,2,1,12.98,200,2,12.86,100,1,12.73,100,1,12.71,100,1,12.5,700,1,12.46,100,1,12.43,700,1,12.42,700,1,13.76,15,1,13.77,100,1,13.91,2,1,14.05,100,1,14.38,100,1,14.48,1400,2,14.53,100,1,14.54,700,1,14.62,100,1,14.68,900,3,ARL,355834369
1940,2025-07-17T16:26:41.283116801Z,2025-07-17T16:26:41.282951271Z,10,2,1108,A,A,0,13.73,15,130,165530,296093549,13.11,100,1,13.01,2,1,12.98,200,2,12.86,100,1,12.73,100,1,12.71,100,1,12.5,700,1,12.46,100,1,12.43,700,1,12.42,700,1,13.73,15,1,13.76,15,1,13.77,100,1,13.91,2,1,14.05,100,1,14.38,100,1,14.48,1400,2,14.53,100,1,14.54,700,1,14.62,100,1,ARL,356366025
1941,2025-07-17T16:26:41.283384784Z,2025-07-17T16:26:41.283218820Z,10,2,1108,C,A,-1,13.77,100,0,165964,296093550,13.11,100,1,13.01,2,1,12.98,200,2,12.86,100,1,12.73,100,1,12.71,100,1,12.5,700,1,12.46,100,1,12.43,700,1,12.42,700,1,13.73,15,1,13.76,15,1,13.91,2,1,14.05,100,1,14.38,100,1,14.48,1400,2,14.53,100,1,14.54,700,1,14.62,100,1,14.68,900,3,ARL,356249197
1942,2025-07-17T16:26:41.283384784Z,2025-07-17T16:26:41.283218820Z,10,2,1108,A,A,1,13.74,100,130,165964,296093550,13.11,100,1,13.01,2,1,12.98,200,2,12.86,100,1,12.73,100,1,12.71,100,1,12.5,700,1,12.46,100,1,12.43,700,1,12.42,700,1,13.73,15,1,13.74,100,1,13.76,15,1,13.91,2,1,14.05,100,1,14.38,100,1,14.48,1400,2,14.53,100,1,14.54,700,1,14.62,100,1,ARL,356366029
1943,2025-07-17T16:26:52.849929707Z,2025-07-17T16:26:52.849764152Z,10,2,1108,C,A,-1,13.76,15,130,165555,296250544,13.11,100,1,13.01,2,1,12.98,200,2,12.86,100,1,12.73,100,1,12.71,100,1,12.5,700,1,12.46,100,1,12.43,700,1,12.42,700,1,13.73,15,1,13.74,100,1,13.91,2,1,14.05,100,1,14.38,100,1,14.48,1400,2,14.53,100,1,14.54,700,1,14.62,100,1,14.68,900,3,ARL,356212397
1944,2025-07-17T16:26:59.805421094Z,2025-07-17T16:26:59.805255232Z,10,2,1108,A,A,0,13.7,15,130,165862,296350781,13.11,100,1,13.01,2,1,12.98,200,2,12.86,100,1,12.73,100,1,12.71,100,1,12.5,700,1,12.46,100,1,12.43,700,1,12.42,700,1,13.7,15,1,13.73,15,1,13.74,100,1,13.91,2,1,14.05,100,1,14.38,100,1,14.48,1400,2,14.53,100,1,14.54,700,1,14.62,100,1,ARL,356686001
1945,2025-07-17T16:27:00.881244327Z,2025-07-17T16:27:00.881078814Z,10,2,1108,C,A,-1,13.74,100,0,165513,296372801,13.11,100,1,13.01,2,1,12.98,200,2,12.86,100,1,12.73,100,1,12.71,100,1,12.5,700,1,12.46,100,1,12.43,700,1,12.42,700,1,13.7,15,1,13.73,15,1,13.91,2,1,14.05,100,1,14.38,100,1,14.48,1400,2,14.53,100,1,14.54,700,1,14.62,100,1,14.68,900,3,ARL,356366029
1946,2025-07-17T16:27:00.881244327Z,2025-07-17T16:27:00.881078814Z,10,2,1108,A,A,1,13.71,100,130,165513,296372801,13.11,100,1,13.01,2,1,12.98,200,2,12.86,100,1,12.73,100,1,12.71,100,1,12.5,700,1,12.46,100,1,12.43,700,1,12.42,700,1,13.7,15,1,13.71,100,1,13.73,15,1,13.91,2,1,14.05,100,1,14.38,100,1,14.48,1400,2,14.53,100,1,14.54,700,1,14.62,100,1,ARL,356714633
1947,2025-07-17T16:27:00.888986182Z,2025-07-17T16:27:00.888818817Z,10,2,1108,C,A,-1,14.05,100,130,167365,296372958,13.11,100,1,13.01,2,1,12.98,200,2,12.86,100,1,12.73,100,1,12.71,100,1,12.5,700,1,12.46,100,1,12.43,700,1,12.42,700,1,13.7,15,1,13.71,100,1,13.73,15,1,13.91,2,1,14.38,100,1,14.48,1400,2,14.53,100,1,14.54,700,1,14.62,100,1,14.68,900,3,ARL,356249781
1948,2025-07-17T16:27:00.889034168Z,2025-07-17T16:27:00.888868946Z,10,2,1108,A,A,4,13.98,100,130,165222,296372964,13.11,100,1,13.01,2,1,12.98,200,2,12.86,100,1,12.73,100,1,12.71,100,1,12.5,700,1,12.46,100,1,12.43,700,1,12.42,700,1,13.7,15,1,13.71,100,1,13.73,15,1,13.91,2,1,13.98,100,1,14.38,100,1,14.48,1400,2,14.53,100,1,14.54,700,1,14.62,100,1,ARL,356714765
1949,2025-07-17T16:27:01.382794826Z,2025-07-17T16:27:01.382629641Z,10,2,1108,A,A,7,14.53,100,130,165185,296378810,13.11,100,1,13.01,2,1,12.98,200,2,12.86,100,1,12.73,100,1,12.71,100,1,12.5,700,1,12.46,100,1,12.43,700,1,12.42,700,1,13.7,15,1,13.71,100,1,13.73,15,1,13.91,2,1,13.98,100,1,14.38,100,1,14.48,1400,2,14.53,200,2,14.54,700,1,14.62,100,1,ARL,356722649
1950,2025-07-17T16:27:03.871788936Z,2025-07-17T16:27:03.871623478Z,10,2,1108,C,A,-1,13.73,15,130,165458,296454461,13.11,100,1,13.01,2,1,12.98,200,2,12.86,100,1,12.73,100,1,12.71,100,1,12.5,700,1,12.46,100,1,12.43,700,1,12.42,700,1,13.7,15,1,13.71,100,1,13.91,2,1,13.98,100,1,14.38,100,1,14.48,1400,2,14.53,200,2,14.54,700,1,14.62,100,1,14.68,900,3,ARL,356366025
1951,2025-07-17T16:27:06.196975879Z,2025-07-17T16:27:06.196810370Z,10,2,1108,A,A,0,13.67,15,130,165509,296495602,13.11,100,1,13.01,2,1,12.98,200,2,12.86,100,1,12.73,100,1,12.71,100,1,12.5,700,1,12.46,100,1,12.43,700,1,12.42,700,1,13.67,15,1,13.7,15,1,13.71,100,1,13.91,2,1,13.98,100,1,14.38,100,1,14.48,1400,2,14.53,200,2,14.54,700,1,14.62,100,1,ARL,356868209
1952,2025-07-17T16:27:06.197822714Z,2025-07-17T16:27:06.197657115Z,10,2,1108,A,A,9,14.57,100,130,165599,296495681,13.11,100,1,13.01,2,1,12.98,200,2,12.86,100,1,12.73,100,1,12.71,100,1,12.5,700,1,12.46,100,1,12.43,700,1,12.42,700,1,13.67,15,1,13.7,15,1,13.71,100,1,13.91,2,1,13.98,100,1,14.38,100,1,14.48,1400,2,14.53,200,2,14.54,700,1,14.57,100,1,ARL,356868353
1953,2025-07-17T16:27:06.198071760Z,2025-07-17T16:27:06.197902486Z,10,2,1108,A,A,9,14.57,100,128,169274,296495716,13.11,100,1,13.01,2,1,12.98,200,2,12.86,100,1,12.73,100,1,12.71,100,1,12.5,700,1,12.46,100,1,12.43,700,1,12.42,700,1,13.67,15,1,13.7,15,1,13.71,100,1,13.91,2,1,13.98,100,1,14.38,100,1,14.48,1400,2,14.53,200,2,14.54,700,1,14.57,200,2,ARL,356868473
1954,2025-07-17T16:27:06.203786192Z,2025-07-17T16:27:06.203607410Z,10,2,1108,C,A,-1,13.71,100,0,178782,296497538,13.11,100,1,13.01,2,1,12.98,200,2,12.86,100,1,12.73,100,1,12.71,100,1,12.5,700,1,12.46,100,1,12.43,700,1,12.42,700,1,13.67,15,1,13.7,15,1,13.91,2,1,13.98,100,1,14.38,100,1,14.48,1400,2,14.53,200,2,14.54,700,1,14.57,200,2,14.62,100,1,ARL,356714633
1955,2025-07-17T16:27:06.203786192Z,2025-07-17T16:27:06.203607410Z,10,2,1108,A,A,1,13.68,100,128,178782,296497538,13.11,100,1,13.01,2,1,12.98,200,2,12.86,100,1,12.73,100,1,12.71,100,1,12.5,700,1,12.46,100,1,12.43,700,1,12.42,700,1,13.67,15,1,13.68,100,1,13.7,15,1,13.91,2,1,13.98,100,1,14.38,100,1,14.48,1400,2,14.53,200,2,14.54,700,1,14.57,200,2,ARL,356870513
1956,2025-07-17T16:27:06.367859180Z,2025-07-17T16:27:06.367693589Z,10,2,1108,C,A,7,14.53,100,130,165591,296505003,13.11,100,1,13.01,2,1,12.98,200,2,12.86,100,1,12.73,100,1,12.71,100,1,12.5,700,1,12.46,100,1,12.43,700,1,12.42,700,1,13.67,15,1,13.68,100,1,13.7,15,1,13.91,2,1,13.98,100,1,14.38,100,1,14.48,1400,2,14.53,100,1,14.54,700,1,14.57,200,2,ARL,349382189
1957,2025-07-17T16:27:06.367860753Z,2025-07-17T16:27:06.367695483Z,10,2,1108,A,A,5,14.23,100,130,165270,296505004,13.11,100,1,13.01,2,1,12.98,200,2,12.86,100,1,12.73,100,1,12.71,100,1,12.5,700,1,12.46,100,1,12.43,700,1,12.42,700,1,13.67,15,1,13.68,100,1,13.7,15,1,13.91,2,1,13.98,100,1,14.23,100,1,14.38,100,1,14.48,1400,2,14.53,100,1,14.54,700,1,ARL,356878397
1958,2025-07-17T16:27:06.379540151Z,2025-07-17T16:27:06.379374401Z,10,2,1108,A,A,7,14.47,100,130,165750,296505373,13.11,100,1,13.01,2,1,12.98,200,2,12.86,100,1,12.73,100,1,12.71,100,1,12.5,700,1,12.46,100,1,12.43,700,1,12.42,700,1,13.67,15,1,13.68,100,1,13.7,15,1,13.91,2,1,13.98,100,1,14.23,100,1,14.38,100,1,14.47,100,1,14.48,1400,2,14.53,100,1,ARL,356878557
1959,2025-07-17T16:27:16.850332913Z,2025-07-17T16:27:16.850167737Z,10,2,1108,C,A,-1,13.7,15,130,165176,296665928,13.11,100,1,13.01,2,1,12.98,200,2,12.86,100,1,12.73,100,1,12.71,100,1,12.5,700,1,12.46,100,1,12.43,700,1,12.42,700,1,13.67,15,1,13.68,100,1,13.91,2,1,13.98,100,1,14.23,100,1,14.38,100,1,14.47,100,1,14.48,1400,2,14.53,100,1,14.54,700,1,ARL,356686001
1960,2025-07-17T16:27:26.589073481Z,2025-07-17T16:27:26.588907795Z,10,2,1108,C,B,-1,13.01,2,0,165686,296801845,13.11,100,1,12.98,200,2,12.86,100,1,12.73,100,1,12.71,100,1,12.5,700,1,12.46,100,1,12.43,700,1,12.42,700,1,12.37,700,1,13.67,15,1,13.68,100,1,13.91,2,1,13.98,100,1,14.23,100,1,14.38,100,1,14.47,100,1,14.48,1400,2,14.53,100,1,14.54,700,1,ARL,355990209
1961,2025-07-17T16:27:26.589073481Z,2025-07-17T16:27:26.588907795Z,10,2,1108,A,B,2,12.9,2,130,165686,296801845,13.11,100,1,12.98,200,2,12.9,2,1,12.86,100,1,12.73,100,1,12.71,100,1,12.5,700,1,12.46,100,1,12.43,700,1,12.42,700,1,13.67,15,1,13.68,100,1,13.91,2,1,13.98,100,1,14.23,100,1,14.38,100,1,14.47,100,1,14.48,1400,2,14.53,100,1,14.54,700,1,ARL,357261961
1962,2025-07-17T16:27:26.850588946Z,2025-07-17T16:27:26.850423539Z,10,2,1108,A,A,0,13.65,15,130,165407,296804447,13.11,100,1,12.98,200,2,12.9,2,1,12.86,100,1,12.73,100,1,12.71,100,1,12.5,700,1,12.46,100,1,12.43,700,1,12.42,700,1,13.65,15,1,13.67,15,1,13.68,100,1,13.91,2,1,13.98,100,1,14.23,100,1,14.38,100,1,14.47,100,1,14.48,1400,2,14.53,100,1,ARL,357266817
1963,2025-07-17T16:27:26.850854853Z,2025-07-17T16:27:26.850689196Z,10,2,1108,C,A,-1,13.68,100,0,165657,296804468,13.11,100,1,12.98,200,2,12.9,2,1,12.86,100,1,12.73,100,1,12.71,100,1,12.5,700,1,12.46,100,1,12.43,700,1,12.42,700,1,13.65,15,1,13.67,15,1,13.91,2,1,13.98,100,1,14.23,100,1,14.38,100,1,14.47,100,1,14.48,1400,2,14.53,100,1,14.54,700,1,ARL,356870513
1964,2025-07-17T16:27:26.850854853Z,2025-07-17T16:27:26.850689196Z,10,2,1108,A,A,1,13.66,100,130,165657,296804468,13.11,100,1,12.98,200,2,12.9,2,1,12.86,100,1,12.73,100,1,12.71,100,1,12.5,700,1,12.46,100,1,12.43,700,1,12.42,700,1,13.65,15,1,13.66,100,1,13.67,15,1,13.91,2,1,13.98,100,1,14.23,100,1,14.38,100,1,14.47,100,1,14.48,1400,2,14.53,100,1,ARL,357266825
1965,2025-07-17T16:27:44.755470864Z,2025-07-17T16:27:44.755305413Z,10,2,1108,C,A,-1,13.67,15,130,165451,297181709,13.11,100,1,12.98,200,2,12.9,2,1,12.86,100,1,12.73,100,1,12.71,100,1,12.5,700,1,12.46,100,1,12.43,700,1,12.42,700,1,13.65,15,1,13.66,100,1,13.91,2,1,13.98,100,1,14.23,100,1,14.38,100,1,14.47,100,1,14.48,1400,2,14.53,100,1,14.54,700,1,ARL,356868209
1966,2025-07-17T16:27:51.274193747Z,2025-07-17T16:27:51.274028105Z,10,2,1108,A,A,0,13.63,15,130,165642,297262308,13.11,100,1,12.98,200,2,12.9,2,1,12.86,100,1,12.73,100,1,12.71,100,1,12.5,700,1,12.46,100,1,12.43,700,1,12.42,700,1,13.63,15,1,13.65,15,1,13.66,100,1,13.91,2,1,13.98,100,1,14.23,100,1,14.38,100,1,14.47,100,1,14.48,1400,2,14.53,100,1,ARL,357831017
1967,2025-07-17T16:27:51.287994820Z,2025-07-17T16:27:51.287829323Z,10,2,1108,C,A,-1,13.66,100,0,165497,297264561,13.11,100,1,12.98,200,2,12.9,2,1,12.86,100,1,12.73,100,1,12.71,100,1,12.5,700,1,12.46,100,1,12.43,700,1,12.42,700,1,13.63,15,1,13.65,15,1,13.91,2,1,13.98,100,1,14.23,100,1,14.38,100,1,14.47,100,1,14.48,1400,2,14.53,100,1,14.54,700,1,ARL,357266825
1968,2025-07-17T16:27:51.287994820Z,2025-07-17T16:27:51.287829323Z,10,2,1108,A,A,1,13.64,100,130,165497,297264561,13.11,100,1,12.98,200,2,12.9,2,1,12.86,100,1,12.73,100,1,12.71,100,1,12.5,700,1,12.46,100,1,12.43,700,1,12.42,700,1,13.63,15,1,13.64,100,1,13.65,15,1,13.91,2,1,13.98,100,1,14.23,100,1,14.38,100,1,14.47,100,1,14.48,1400,2,14.53,100,1,ARL,357833401
1969,2025-07-17T16:27:51.309894790Z,2025-07-17T16:27:51.309729367Z,10,2,1108,C,A,-1,13.98,100,130,165423,297265448,13.11,100,1,12.98,200,2,12.9,2,1,12.86,100,1,12.73,100,1,12.71,100,1,12.5,700,1,12.46,100,1,12.43,700,1,12.42,700,1,13.63,15,1,13.64,100,1,13.65,15,1,13.91,2,1,14.23,100,1,14.38,100,1,14.47,100,1,14.48,1400,2,14.53,100,1,14.54,700,1,ARL,356714765
1970,2025-07-17T16:27:51.309945367Z,2025-07-17T16:27:51.309780024Z,10,2,1108,A,A,3,13.91,100,130,165343,297265452,13.11,100,1,12.98,200,2,12.9,2,1,12.86,100,1,12.73,100,1,12.71,100,1,12.5,700,1,12.46,100,1,12.43,700,1,12.42,700,1,13.63,15,1,13.64,100,1,13.65,15,1,13.91,102,2,14.23,100,1,14.38,100,1,14.47,100,1,14.48,1400,2,14.53,100,1,14.54,700,1,ARL,357834073
1971,2025-07-17T16:28:02.851437866Z,2025-07-17T16:28:02.851272527Z,10,2,1108,C,A,-1,13.65,15,130,165339,297397036,13.11,100,1,12.98,200,2,12.9,2,1,12.86,100,1,12.73,100,1,12.71,100,1,12.5,700,1,12.46,100,1,12.43,700,1,12.42,700,1,13.63,15,1,13.64,100,1,13.91,102,2,14.23,100,1,14.38,100,1,14.47,100,1,14.48,1400,2,14.53,100,1,14.54,700,1,14.57,200,2,ARL,357266817
1972,2025-07-17T16:28:09.315288028Z,2025-07-17T16:28:09.315122562Z,10,2,1108,A,A,0,13.61,15,130,165466,297494103,13.11,100,1,12.98,200,2,12.9,2,1,12.86,100,1,12.73,100,1,12.71,100,1,12.5,700,1,12.46,100,1,12.43,700,1,12.42,700,1,13.61,15,1,13.63,15,1,13.64,100,1,13.91,102,2,14.23,100,1,14.38,100,1,14.47,100,1,14.48,1400,2,14.53,100,1,14.54,700,1,ARL,358150085
1973,2025-07-17T16:28:09.320408712Z,2025-07-17T16:28:09.320239872Z,10,2,1108,C,A,-1,13.64,100,0,168840,297494317,13.11,100,1,12.98,200,2,12.9,2,1,12.86,100,1,12.73,100,1,12.71,100,1,12.5,700,1,12.46,100,1,12.43,700,1,12.42,700,1,13.61,15,1,13.63,15,1,13.91,102,2,14.23,100,1,14.38,100,1,14.47,100,1,14.48,1400,2,14.53,100,1,14.54,700,1,14.57,200,2,ARL,357833401
1974,2025-07-17T16:28:09.320408712Z,2025-07-17T16:28:09.320239872Z,10,2,1108,A,A,1,13.62,100,130,168840,297494317,13.11,100,1,12.98,200,2,12.9,2,1,12.86,100,1,12.73,100,1,12.71,100,1,12.5,700,1,12.46,100,1,12.43,700,1,12.42,700,1,13.61,15,1,13.62,100,1,13.63,15,1,13.91,102,2,14.23,100,1,14.38,100,1,14.47,100,1,14.48,1400,2,14.53,100,1,14.54,700,1,ARL,358150237
1975,2025-07-17T16:28:20.851638007Z,2025-07-17T16:28:20.851472409Z,10,2,1108,C,A,-1,13.63,15,130,165598,297651898,13.11,100,1,12.98,200,2,12.9,2,1,12.86,100,1,12.73,100,1,12.71,100,1,12.5,700,1,12.46,100,1,12.43,700,1,12.42,700,1,13.61,15,1,13.62,100,1,13.91,102,2,14.23,100,1,14.38,100,1,14.47,100,1,14.48,1400,2,14.53,100,1,14.54,700,1,14.57,200,2,ARL,357831017
1976,2025-07-17T16:28:24.674509358Z,2025-07-17T16:28:24.674343969Z,10,2,1108,A,A,0,13.59,15,130,165389,297733885,13.11,100,1,12.98,200,2,12.9,2,1,12.86,100,1,12.73,100,1,12.71,100,1,12.5,700,1,12.46,100,1,12.43,700,1,12.42,700,1,13.59,15,1,13.61,15,1,13.62,100,1,13.91,102,2,14.23,100,1,14.38,100,1,14.47,100,1,14.48,1400,2,14.53,100,1,14.54,700,1,ARL,358449973
1977,2025-07-17T16:28:25.348396135Z,2025-07-17T16:28:25.348230623Z,10,2,1108,C,A,-1,13.62,100,0,165512,297742434,13.11,100,1,12.98,200,2,12.9,2,1,12.86,100,1,12.73,100,1,12.71,100,1,12.5,700,1,12.46,100,1,12.43,700,1,12.42,700,1,13.59,15,1,13.61,15,1,13.91,102,2,14.23,100,1,14.38,100,1,14.47,100,1,14.48,1400,2,14.53,100,1,14.54,700,1,14.57,200,2,ARL,358150237
1978,2025-07-17T16:28:25.348396135Z,2025-07-17T16:28:25.348230623Z,10,2,1108,A,A,1,13.6,100,130,165512,297742434,13.11,100,1,12.98,200,2,12.9,2,1,12.86,100,1,12.73,100,1,12.71,100,1,12.5,700,1,12.46,100,1,12.43,700,1,12.42,700,1,13.59,15,1,13.6,100,1,13.61,15,1,13.91,102,2,14.23,100,1,14.38,100,1,14.47,100,1,14.48,1400,2,14.53,100,1,14.54,700,1,ARL,358463553
1979,2025-07-17T16:28:30.151777566Z,2025-07-17T16:28:30.151612118Z,10,2,1108,C,A,-1,13.61,15,130,165448,297801782,13.11,100,1,12.98,200,2,12.9,2,1,12.86,100,1,12.73,100,1,12.71,100,1,12.5,700,1,12.46,100,1,12.43,700,1,12.42,700,1,13.59,15,1,13.6,100,1,13.91,102,2,14.23,100,1,14.38,100,1,14.47,100,1,14.48,1400,2,14.53,100,1,14.54,700,1,14.57,200,2,ARL,358150085
1980,2025-07-17T16:28:31.156530154Z,2025-07-17T16:28:31.156364385Z,10,2,1108,A,A,0,13.57,15,130,165769,297818676,13.11,100,1,12.98,200,2,12.9,2,1,12.86,100,1,12.73,100,1,12.71,100,1,12.5,700,1,12.46,100,1,12.43,700,1,12.42,700,1,13.57,15,1,13.59,15,1,13.6,100,1,13.91,102,2,14.23,100,1,14.38,100,1,14.47,100,1,14.48,1400,2,14.53,100,1,14.54,700,1,ARL,358570565
1981,2025-07-17T16:28:31.749789697Z,2025-07-17T16:28:31.749624268Z,10,2,1108,C,A,-1,13.6,100,0,165429,297824579,13.11,100,1,12.98,200,2,12.9,2,1,12.86,100,1,12.73,100,1,12.71,100,1,12.5,700,1,12.46,100,1,12.43,700,1,12.42,700,1,13.57,15,1,13.59,15,1,13.91,102,2,14.23,100,1,14.38,100,1,14.47,100,1,14.48,1400,2,14.53,100,1,14.54,700,1,14.57,200,2,ARL,358463553
1982,2025-07-17T16:28:31.749789697Z,2025-07-17T16:28:31.749624268Z,10,2,1108,A,A,1,13.58,100,130,165429,297824579,13.11,100,1,12.98,200,2,12.9,2,1,12.86,100,1,12.73,100,1,12.71,100,1,12.5,700,1,12.46,100,1,12.43,700,1,12.42,700,1,13.57,15,1,13.58,100,1,13.59,15,1,13.91,102,2,14.23,100,1,14.38,100,1,14.47,100,1,14.48,1400,2,14.53,100,1,14.54,700,1,ARL,358578625
1983,2025-07-17T16:28:32.698672164Z,2025-07-17T16:28:32.698506029Z,10,2,1108,A,A,6,14.46,100,130,166135,297835499,13.11,100,1,12.98,200,2,12.9,2,1,12.86,100,1,12.73,100,1,12.71,100,1,12.5,700,1,12.46,100,1,12.43,700,1,12.42,700,1,13.57,15,1,13.58,100,1,13.59,15,1,13.91,102,2,14.23,100,1,14.38,100,1,14.46,100,1,14.47,100,1,14.48,1400,2,14.53,100,1,ARL,358596029
1984,2025-07-17T16:28:32.699117780Z,2025-07-17T16:28:32.698952035Z,10,2,1108,A,A,6,14.46,100,130,165745,297835506,13.11,100,1,12.98,200,2,12.9,2,1,12.86,100,1,12.73,100,1,12.71,100,1,12.5,700,1,12.46,100,1,12.43,700,1,12.42,700,1,13.57,15,1,13.58,100,1,13.59,15,1,13.91,102,2,14.23,100,1,14.38,100,1,14.46,200,2,14.47,100,1,14.48,1400,2,14.53,100,1,ARL,358596037
1985,2025-07-17T16:28:40.030676303Z,2025-07-17T16:28:40.030511022Z,10,2,1108,A,A,5,14.26,700,130,165281,297918373,13.11,100,1,12.98,200,2,12.9,2,1,12.86,100,1,12.73,100,1,12.71,100,1,12.5,700,1,12.46,100,1,12.43,700,1,12.42,700,1,13.57,15,1,13.58,100,1,13.59,15,1,13.91,102,2,14.23,100,1,14.26,700,1,14.38,100,1,14.46,200,2,14.47,100,1,14.48,1400,2,ARL,358712189
1986,2025-07-17T16:28:42.853463655Z,2025-07-17T16:28:42.853298390Z,10,2,1108,C,A,-1,13.59,15,130,165265,297952225,13.11,100,1,12.98,200,2,12.9,2,1,12.86,100,1,12.73,100,1,12.71,100,1,12.5,700,1,12.46,100,1,12.43,700,1,12.42,700,1,13.57,15,1,13.58,100,1,13.91,102,2,14.23,100,1,14.26,700,1,14.38,100,1,14.46,200,2,14.47,100,1,14.48,1400,2,14.53,100,1,ARL,358449973
1987,2025-07-17T16:28:52.853526381Z,2025-07-17T16:28:52.853361257Z,10,2,1108,A,A,0,13.55,15,130,165124,298071838,13.11,100,1,12.98,200,2,12.9,2,1,12.86,100,1,12.73,100,1,12.71,100,1,12.5,700,1,12.46,100,1,12.43,700,1,12.42,700,1,13.55,15,1,13.57,15,1,13.58,100,1,13.91,102,2,14.23,100,1,14.26,700,1,14.38,100,1,14.46,200,2,14.47,100,1,14.48,1400,2,ARL,358923309
1988,2025-07-17T16:28:52.853793896Z,2025-07-17T16:28:52.853628543Z,10,2,1108,C,A,-1,13.58,100,0,165353,298071841,13.11,100,1,12.98,200,2,12.9,2,1,12.86,100,1,12.73,100,1,12.71,100,1,12.5,700,1,12.46,100,1,12.43,700,1,12.42,700,1,13.55,15,1,13.57,15,1,13.91,102,2,14.23,100,1,14.26,700,1,14.38,100,1,14.46,200,2,14.47,100,1,14.48,1400,2,14.53,100,1,ARL,358578625
1989,2025-07-17T16:28:52.853793896Z,2025-07-17T16:28:52.853628543Z,10,2,1108,A,A,1,13.56,100,130,165353,298071841,13.11,100,1,12.98,200,2,12.9,2,1,12.86,100,1,12.73,100,1,12.71,100,1,12.5,700,1,12.46,100,1,12.43,700,1,12.42,700,1,13.55,15,1,13.56,100,1,13.57,15,1,13.91,102,2,14.23,100,1,14.26,700,1,14.38,100,1,14.46,200,2,14.47,100,1,14.48,1400,2,ARL,358923321
1990,2025-07-17T16:28:52.854531051Z,2025-07-17T16:28:52.854365748Z,10,2,1108,C,A,-1,14.38,100,130,165303,298071844,13.11,100,1,12.98,200,2,12.9,2,1,12.86,100,1,12.73,100,1,12.71,100,1,12.5,700,1,12.46,100,1,12.43,700,1,12.42,700,1,13.55,15,1,13.56,100,1,13.57,15,1,13.91,102,2,14.23,100,1,14.26,700,1,14.46,200,2,14.47,100,1,14.48,1400,2,14.53,100,1,ARL,356249249
1991,2025-07-17T16:28:52.854892733Z,2025-07-17T16:28:52.854727375Z,10,2,1108,A,A,4,14.17,100,130,165358,298071846,13.11,100,1,12.98,200,2,12.9,2,1,12.86,100,1,12.73,100,1,12.71,100,1,12.5,700,1,12.46,100,1,12.43,700,1,12.42,700,1,13.55,15,1,13.56,100,1,13.57,15,1,13.91,102,2,14.17,100,1,14.23,100,1,14.26,700,1,14.46,200,2,14.47,100,1,14.48,1400,2,ARL,358923345
1992,2025-07-17T16:28:52.874969164Z,2025-07-17T16:28:52.874803773Z,10,2,1108,C,A,3,13.91,100,130,165391,298071937,13.11,100,1,12.98,200,2,12.9,2,1,12.86,100,1,12.73,100,1,12.71,100,1,12.5,700,1,12.46,100,1,12.43,700,1,12.42,700,1,13.55,15,1,13.56,100,1,13.57,15,1,13.91,2,1,14.17,100,1,14.23,100,1,14.26,700,1,14.46,200,2,14.47,100,1,14.48,1400,2,ARL,357834073
1993,2025-07-17T16:28:52.875019400Z,2025-07-17T16:28:52.874854173Z,10,2,1108,A,A,3,13.83,100,130,165227,298071938,13.11,100,1,12.98,200,2,12.9,2,1,12.86,100,1,12.73,100,1,12.71,100,1,12.5,700,1,12.46,100,1,12.43,700,1,12.42,700,1,13.55,15,1,13.56,100,1,13.57,15,1,13.83,100,1,13.91,2,1,14.17,100,1,14.23,100,1,14.26,700,1,14.46,200,2,14.47,100,1,ARL,358923457
1994,2025-07-17T16:29:12.853224917Z,2025-07-17T16:29:12.853059452Z,10,2,1108,C,A,-1,13.57,15,130,165465,298434087,13.11,100,1,12.98,200,2,12.9,2,1,12.86,100,1,12.73,100,1,12.71,100,1,12.5,700,1,12.46,100,1,12.43,700,1,12.42,700,1,13.55,15,1,13.56,100,1,13.83,100,1,13.91,2,1,14.17,100,1,14.23,100,1,14.26,700,1,14.46,200,2,14.47,100,1,14.48,1400,2,ARL,358570565
1995,2025-07-17T16:29:15.051636723Z,2025-07-17T16:29:15.051471390Z,10,2,1108,A,A,0,13.53,15,130,165333,298465823,13.11,100,1,12.98,200,2,12.9,2,1,12.86,100,1,12.73,100,1,12.71,100,1,12.5,700,1,12.46,100,1,12.43,700,1,12.42,700,1,13.53,15,1,13.55,15,1,13.56,100,1,13.83,100,1,13.91,2,1,14.17,100,1,14.23,100,1,14.26,700,1,14.46,200,2,14.47,100,1,ARL,359402805
1996,2025-07-17T16:29:15.091786299Z,2025-07-17T16:29:15.091620748Z,10,2,1108,C,A,-1,13.56,100,0,165551,298467504,13.11,100,1,12.98,200,2,12.9,2,1,12.86,100,1,12.73,100,1,12.71,100,1,12.5,700,1,12.46,100,1,12.43,700,1,12.42,700,1,13.53,15,1,13.55,15,1,13.83,100,1,13.91,2,1,14.17,100,1,14.23,100,1,14.26,700,1,14.46,200,2,14.47,100,1,14.48,1400,2,ARL,358923321
1997,2025-07-17T16:29:15.091786299Z,2025-07-17T16:29:15.091620748Z,10,2,1108,A,A,1,13.54,100,130,165551,298467504,13.11,100,1,12.98,200,2,12.9,2,1,12.86,100,1,12.73,100,1,12.71,100,1,12.5,700,1,12.46,100,1,12.43,700,1,12.42,700,1,13.53,15,1,13.54,100,1,13.55,15,1,13.83,100,1,13.91,2,1,14.17,100,1,14.23,100,1,14.26,700,1,14.46,200,2,14.47,100,1,ARL,359403945
1998,2025-07-17T16:29:15.203931372Z,2025-07-17T16:29:15.203765956Z,10,2,1108,C,A,-1,14.47,100,0,165416,298471150,13.11,100,1,12.98,200,2,12.9,2,1,12.86,100,1,12.73,100,1,12.71,100,1,12.5,700,1,12.46,100,1,12.43,700,1,12.42,700,1,13.53,15,1,13.54,100,1,13.55,15,1,13.83,100,1,13.91,2,1,14.17,100,1,14.23,100,1,14.26,700,1,14.46,200,2,14.48,1400,2,ARL,356878557
1999,2025-07-17T16:29:15.203931372Z,2025-07-17T16:29:15.203765956Z,10,2,1108,A,A,8,14.33,100,130,165416,298471150,13.11,100,1,12.98,200,2,12.9,2,1,12.86,100,1,12.73,100,1,12.71,100,1,12.5,700,1,12.46,100,1,12.43,700,1,12.42,700,1,13.53,15,1,13.54,100,1,13.55,15,1,13.83,100,1,13.91,2,1,14.17,100,1,14.23,100,1,14.26,700,1,14.33,100,1,14.46,200,2,ARL,359406981
2000,2025-07-17T16:29:18.186126235Z,2025-07-17T16:29:18.185960448Z,10,2,1108,C,A,-1,13.91,2,0,165787,298518298,13.11,100,1,12.98,200,2,12.9,2,1,12.86,100,1,12.73,100,1,12.71,100,1,12.5,700,1,12.46,100,1,12.43,700,1,12.42,700,1,13.53,15,1,13.54,100,1,13.55,15,1,13.83,100,1,14.17,100,1,14.23,100,1,14.26,700,1,14.33,100,1,14.46,200,2,14.48,1400,2,ARL,354292533
2001,2025-07-17T16:29:18.186126235Z,2025-07-17T16:29:18.185960448Z,10,2,1108,A,A,3,13.82,2,130,165787,298518298,13.11,100,1,12.98,200,2,12.9,2,1,12.86,100,1,12.73,100,1,12.71,100,1,12.5,700,1,12.46,100,1,12.43,700,1,12.42,700,1,13.53,15,1,13.54,100,1,13.55,15,1,13.82,2,1,13.83,100,1,14.17,100,1,14.23,100,1,14.26,700,1,14.33,100,1,14.46,200,2,ARL,359459321
2002,2025-07-17T16:29:22.814624817Z,2025-07-17T16:29:22.814459272Z,10,2,1108,C,A,-1,13.55,15,130,165545,298597575,13.11,100,1,12.98,200,2,12.9,2,1,12.86,100,1,12.73,100,1,12.71,100,1,12.5,700,1,12.46,100,1,12.43,700,1,12.42,700,1,13.53,15,1,13.54,100,1,13.82,2,1,13.83,100,1,14.17,100,1,14.23,100,1,14.26,700,1,14.33,100,1,14.46,200,2,14.48,1400,2,ARL,358923309
2003,2025-07-17T16:29:34.353525366Z,2025-07-17T16:29:34.353360056Z,10,2,1108,A,A,0,13.51,15,130,165310,298768484,13.11,100,1,12.98,200,2,12.9,2,1,12.86,100,1,12.73,100,1,12.71,100,1,12.5,700,1,12.46,100,1,12.43,700,1,12.42,700,1,13.51,15,1,13.53,15,1,13.54,100,1,13.82,2,1,13.83,100,1,14.17,100,1,14.23,100,1,14.26,700,1,14.33,100,1,14.46,200,2,ARL,359747973
2004,2025-07-17T16:29:37.353817686Z,2025-07-17T16:29:37.353652254Z,10,2,1108,C,A,-1,13.53,15,130,165432,298809584,13.11,100,1,12.98,200,2,12.9,2,1,12.86,100,1,12.73,100,1,12.71,100,1,12.5,700,1,12.46,100,1,12.43,700,1,12.42,700,1,13.51,15,1,13.54,100,1,13.82,2,1,13.83,100,1,14.17,100,1,14.23,100,1,14.26,700,1,14.33,100,1,14.46,200,2,14.48,1400,2,ARL,359402805
2005,2025-07-17T16:29:38.016710092Z,2025-07-17T16:29:38.016544503Z,10,2,1108,C,A,-1,13.54,100,0,165589,298816720,13.11,100,1,12.98,200,2,12.9,2,1,12.86,100,1,12.73,100,1,12.71,100,1,12.5,700,1,12.46,100,1,12.43,700,1,12.42,700,1,13.51,15,1,13.82,2,1,13.83,100,1,14.17,100,1,14.23,100,1,14.26,700,1,14.33,100,1,14.46,200,2,14.48,1400,2,14.49,200,2,ARL,359403945
2006,2025-07-17T16:29:38.016710092Z,2025-07-17T16:29:38.016544503Z,10,2,1108,A,A,1,13.52,100,130,165589,298816720,13.11,100,1,12.98,200,2,12.9,2,1,12.86,100,1,12.73,100,1,12.71,100,1,12.5,700,1,12.46,100,1,12.43,700,1,12.42,700,1,13.51,15,1,13.52,100,1,13.82,2,1,13.83,100,1,14.17,100,1,14.23,100,1,14.26,700,1,14.33,100,1,14.46,200,2,14.48,1400,2,ARL,359803101
2007,2025-07-17T16:29:38.358698380Z,2025-07-17T16:29:38.358532978Z,10,2,1108,A,A,0,13.49,15,130,165402,298820897,13.11,100,1,12.98,200,2,12.9,2,1,12.86,100,1,12.73,100,1,12.71,100,1,12.5,700,1,12.46,100,1,12.43,700,1,12.42,700,1,13.49,15,1,13.51,15,1,13.52,100,1,13.82,2,1,13.83,100,1,14.17,100,1,14.23,100,1,14.26,700,1,14.33,100,1,14.46,200,2,ARL,359807057
2008,2025-07-17T16:29:39.396413450Z,2025-07-17T16:29:39.396248056Z,10,2,1108,C,A,-1,13.52,100,0,165394,298834883,13.11,100,1,12.98,200,2,12.9,2,1,12.86,100,1,12.73,100,1,12.71,100,1,12.5,700,1,12.46,100,1,12.43,700,1,12.42,700,1,13.49,15,1,13.51,15,1,13.82,2,1,13.83,100,1,14.17,100,1,14.23,100,1,14.26,700,1,14.33,100,1,14.46,200,2,14.48,1400,2,ARL,359803101
2009,2025-07-17T16:29:39.396413450Z,2025-07-17T16:29:39.396248056Z,10,2,1108,A,A,1,13.5,100,130,165394,298834883,13.11,100,1,12.98,200,2,12.9,2,1,12.86,100,1,12.73,100,1,12.71,100,1,12.5,700,1,12.46,100,1,12.43,700,1,12.42,700,1,13.49,15,1,13.5,100,1,13.51,15,1,13.82,2,1,13.83,100,1,14.17,100,1,14.23,100,1,14.26,700,1,14.33,100,1,14.46,200,2,ARL,359822513
2010,2025-07-17T16:29:44.669038478Z,2025-07-17T16:29:44.668873033Z,10,2,1108,C,A,-1,13.51,15,130,165445,298899512,13.11,100,1,12.98,200,2,12.9,2,1,12.86,100,1,12.73,100,1,12.71,100,1,12.5,700,1,12.46,100,1,12.43,700,1,12.42,700,1,13.49,15,1,13.5,100,1,13.82,2,1,13.83,100,1,14.17,100,1,14.23,100,1,14.26,700,1,14.33,100,1,14.46,200,2,14.48,1400,2,ARL,359747973
2011,2025-07-17T16:29:56.855566592Z,2025-07-17T16:29:56.855401137Z,10,2,1108,A,A,0,13.47,15,130,165455,299064196,13.11,100,1,12.98,200,2,12.9,2,1,12.86,100,1,12.73,100,1,12.71,100,1,12.5,700,1,12.46,100,1,12.43,700,1,12.42,700,1,13.47,15,1,13.49,15,1,13.5,100,1,13.82,2,1,13.83,100,1,14.17,100,1,14.23,100,1,14.26,700,1,14.33,100,1,14.46,200,2,ARL,360132781
2012,2025-07-17T16:29:57.332830897Z,2025-07-17T16:29:57.332665339Z,10,2,1108,C,A,-1,13.5,100,130,165558,299070813,13.11,100,1,12.98,200,2,12.9,2,1,12.86,100,1,12.73,100,1,12.71,100,1,12.5,700,1,12.46,100,1,12.43,700,1,12.42,700,1,13.47,15,1,13.49,15,1,13.82,2,1,13.83,100,1,14.17,100,1,14.23,100,1,14.26,700,1,14.33,100,1,14.46,200,2,14.48,1400,2,ARL,359822513
2013,2025-07-17T16:29:57.333105446Z,2025-07-17T16:29:57.332939872Z,10,2,1108,C,A,-1,14.26,700,130,165574,299070819,13.11,100,1,12.98,200,2,12.9,2,1,12.86,100,1,12.73,100,1,12.71,100,1,12.5,700,1,12.46,100,1,12.43,700,1,12.42,700,1,13.47,15,1,13.49,15,1,13.82,2,1,13.83,100,1,14.17,100,1,14.23,100,1,14.33,100,1,14.46,200,2,14.48,1400,2,14.49,200,2,ARL,358712189
2014,2025-07-17T16:29:57.333156116Z,2025-07-17T16:29:57.332990460Z,10,2,1108,A,A,7,14.46,700,130,165656,299070821,13.11,100,1,12.98,200,2,12.9,2,1,12.86,100,1,12.73,100,1,12.71,100,1,12.5,700,1,12.46,100,1,12.43,700,1,12.42,700,1,13.47,15,1,13.49,15,1,13.82,2,1,13.83,100,1,14.17,100,1,14.23,100,1,14.33,100,1,14.46,900,3,14.48,1400,2,14.49,200,2,ARL,360140477
2015,2025-07-17T16:29:57.333568888Z,2025-07-17T16:29:57.333403536Z,10,2,1108,C,A,-1,14.17,100,130,165352,299070833,13.11,100,1,12.98,200,2,12.9,2,1,12.86,100,1,12.73,100,1,12.71,100,1,12.5,700,1,12.46,100,1,12.43,700,1,12.42,700,1,13.47,15,1,13.49,15,1,13.82,2,1,13.83,100,1,14.23,100,1,14.33,100,1,14.46,900,3,14.48,1400,2,14.49,200,2,14.53,100,1,ARL,358923345
2016,2025-07-17T16:29:57.333925540Z,2025-07-17T16:29:57.333760331Z,10,2,1108,A,A,6,14.38,100,130,165209,299070841,13.11,100,1,12.98,200,2,12.9,2,1,12.86,100,1,12.73,100,1,12.71,100,1,12.5,700,1,12.46,100,1,12.43,700,1,12.42,700,1,13.47,15,1,13.49,15,1,13.82,2,1,13.83,100,1,14.23,100,1,14.33,100,1,14.38,100,1,14.46,900,3,14.48,1400,2,14.49,200,2,ARL,360140533
2017,2025-07-17T16:29:57.334822203Z,2025-07-17T16:29:57.334656229Z,10,2,1108,C,A,9,14.49,100,0,165974,299070877,13.11,100,1,12.98,200,2,12.9,2,1,12.86,100,1,12.73,100,1,12.71,100,1,12.5,700,1,12.46,100,1,12.43,700,1,12.42,700,1,13.47,15,1,13.49,15,1,13.82,2,1,13.83,100,1,14.23,100,1,14.33,100,1,14.38,100,1,14.46,900,3,14.48,1400,2,14.49,100,1,ARL,359403985
2018,2025-07-17T16:29:57.342525486Z,2025-07-17T16:29:57.342360168Z,10,2,1108,C,A,-1,14.33,100,130,165318,299071022,13.11,100,1,12.98,200,2,12.9,2,1,12.86,100,1,12.73,100,1,12.71,100,1,12.5,700,1,12.46,100,1,12.43,700,1,12.42,700,1,13.47,15,1,13.49,15,1,13.82,2,1,13.83,100,1,14.23,100,1,14.38,100,1,14.46,900,3,14.48,1400,2,14.49,100,1,14.53,100,1,ARL,359406981
2019,2025-07-17T16:29:57.346688326Z,2025-07-17T16:29:57.346522920Z,10,2,1108,C,A,-1,13.83,100,130,165406,299071131,13.11,100,1,12.98,200,2,12.9,2,1,12.86,100,1,12.73,100,1,12.71,100,1,12.5,700,1,12.46,100,1,12.43,700,1,12.42,700,1,13.47,15,1,13.49,15,1,13.82,2,1,14.23,100,1,14.38,100,1,14.46,900,3,14.48,1400,2,14.49,100,1,14.53,100,1,14.54,700,1,ARL,358923457
2020,2025-07-17T16:29:57.346720621Z,2025-07-17T16:29:57.346555573Z,10,2,1108,C,A,5,14.46,700,130,165048,299071132,13.11,100,1,12.98,200,2,12.9,2,1,12.86,100,1,12.73,100,1,12.71,100,1,12.5,700,1,12.46,100,1,12.43,700,1,12.42,700,1,13.47,15,1,13.49,15,1,13.82,2,1,14.23,100,1,14.38,100,1,14.46,200,2,14.48,1400,2,14.49,100,1,14.53,100,1,14.54,700,1,ARL,360140477
2021,2025-07-17T16:29:57.346741243Z,2025-07-17T16:29:57.346575752Z,10,2,1108,A,A,3,14.05,100,130,165491,299071133,13.11,100,1,12.98,200,2,12.9,2,1,12.86,100,1,12.73,100,1,12.71,100,1,12.5,700,1,12.46,100,1,12.43,700,1,12.42,700,1,13.47,15,1,13.49,15,1,13.82,2,1,14.05,100,1,14.23,100,1,14.38,100,1,14.46,200,2,14.48,1400,2,14.49,100,1,14.53,100,1,ARL,360140905
2022,2025-07-17T16:29:57.351343046Z,2025-07-17T16:29:57.351177695Z,10,2,1108,A,A,1,13.48,100,130,165351,299071172,13.11,100,1,12.98,200,2,12.9,2,1,12.86,100,1,12.73,100,1,12.71,100,1,12.5,700,1,12.46,100,1,12.43,700,1,12.42,700,1,13.47,15,1,13.48,100,1,13.49,15,1,13.82,2,1,14.05,100,1,14.23,100,1,14.38,100,1,14.46,200,2,14.48,1400,2,14.49,100,1,ARL,360140981
2023,2025-07-17T16:29:57.353067391Z,2025-07-17T16:29:57.352902068Z,10,2,1108,A,A,7,14.43,100,130,165323,299071184,13.11,100,1,12.98,200,2,12.9,2,1,12.86,100,1,12.73,100,1,12.71,100,1,12.5,700,1,12.46,100,1,12.43,700,1,12.42,700,1,13.47,15,1,13.48,100,1,13.49,15,1,13.82,2,1,14.05,100,1,14.23,100,1,14.38,100,1,14.43,100,1,14.46,200,2,14.48,1400,2,ARL,360141061
2024,2025-07-17T16:29:57.365451513Z,2025-07-17T16:29:57.365286456Z,10,2,1108,C,A,-1,14.05,100,130,165057,299071406,13.11,100,1,12.98,200,2,12.9,2,1,12.86,100,1,12.73,100,1,12.71,100,1,12.5,700,1,12.46,100,1,12.43,700,1,12.42,700,1,13.47,15,1,13.48,100,1,13.49,15,1,13.82,2,1,14.23,100,1,14.38,100,1,14.43,100,1,14.46,200,2,14.48,1400,2,14.49,100,1,ARL,360140905
2025,2025-07-17T16:29:57.365498767Z,2025-07-17T16:29:57.365333299Z,10,2,1108,A,A,5,14.26,100,130,165468,299071407,13.11,100,1,12.98,200,2,12.9,2,1,12.86,100,1,12.73,100,1,12.71,100,1,12.5,700,1,12.46,100,1,12.43,700,1,12.42,700,1,13.47,15,1,13.48,100,1,13.49,15,1,13.82,2,1,14.23,100,1,14.26,100,1,14.38,100,1,14.43,100,1,14.46,200,2,14.48,1400,2,ARL,360141269
2026,2025-07-17T16:29:57.366314396Z,2025-07-17T16:29:57.366149175Z,10,2,1108,C,A,-1,14.26,100,130,165221,299071411,13.11,100,1,12.98,200,2,12.9,2,1,12.86,100,1,12.73,100,1,12.71,100,1,12.5,700,1,12.46,100,1,12.43,700,1,12.42,700,1,13.47,15,1,13.48,100,1,13.49,15,1,13.82,2,1,14.23,100,1,14.38,100,1,14.43,100,1,14.46,200,2,14.48,1400,2,14.49,100,1,ARL,360141269
2027,2025-07-17T16:29:57.366362094Z,2025-07-17T16:29:57.366196404Z,10,2,1108,A,A,3,13.75,100,130,165690,299071412,13.11,100,1,12.98,200,2,12.9,2,1,12.86,100,1,12.73,100,1,12.71,100,1,12.5,700,1,12.46,100,1,12.43,700,1,12.42,700,1,13.47,15,1,13.48,100,1,13.49,15,1,13.75,100,1,13.82,2,1,14.23,100,1,14.38,100,1,14.43,100,1,14.46,200,2,14.48,1400,2,ARL,360141273
2028,2025-07-17T16:29:57.981902498Z,2025-07-17T16:29:57.981737315Z,10,2,1108,C,A,-1,14.38,100,130,165183,299079629,13.11,100,1,12.98,200,2,12.9,2,1,12.86,100,1,12.73,100,1,12.71,100,1,12.5,700,1,12.46,100,1,12.43,700,1,12.42,700,1,13.47,15,1,13.48,100,1,13.49,15,1,13.75,100,1,13.82,2,1,14.23,100,1,14.43,100,1,14.46,200,2,14.48,1400,2,14.49,100,1,ARL,360140533
2029,2025-07-17T16:29:57.982255734Z,2025-07-17T16:29:57.982089749Z,10,2,1108,A,A,5,14.08,100,130,165985,299079655,13.11,100,1,12.98,200,2,12.9,2,1,12.86,100,1,12.73,100,1,12.71,100,1,12.5,700,1,12.46,100,1,12.43,700,1,12.42,700,1,13.47,15,1,13.48,100,1,13.49,15,1,13.75,100,1,13.82,2,1,14.08,100,1,14.23,100,1,14.43,100,1,14.46,200,2,14.48,1400,2,ARL,360153053
2030,2025-07-17T16:29:58.344563086Z,2025-07-17T16:29:58.344397545Z,10,2,1108,A,A,7,14.27,100,130,165541,299094491,13.11,100,1,12.98,200,2,12.9,2,1,12.86,100,1,12.73,100,1,12.71,100,1,12.5,700,1,12.46,100,1,12.43,700,1,12.42,700,1,13.47,15,1,13.48,100,1,13.49,15,1,13.75,100,1,13.82,2,1,14.08,100,1,14.23,100,1,14.27,100,1,14.43,100,1,14.46,200,2,ARL,360169365
2031,2025-07-17T16:30:02.830939841Z,2025-07-17T16:30:02.830774434Z,10,2,1108,A,A,6,14.19,700,130,165407,299196935,13.11,100,1,12.98,200,2,12.9,2,1,12.86,100,1,12.73,100,1,12.71,100,1,12.5,700,1,12.46,100,1,12.43,700,1,12.42,700,1,13.47,15,1,13.48,100,1,13.49,15,1,13.75,100,1,13.82,2,1,14.08,100,1,14.19,700,1,14.23,100,1,14.27,100,1,14.43,100,1,ARL,360283881
2032,2025-07-17T16:30:05.499571762Z,2025-07-17T16:30:05.499406444Z,10,2,1108,C,A,-1,13.49,15,130,165318,299240923,13.11,100,1,12.98,200,2,12.9,2,1,12.86,100,1,12.73,100,1,12.71,100,1,12.5,700,1,12.46,100,1,12.43,700,1,12.42,700,1,13.47,15,1,13.48,100,1,13.75,100,1,13.82,2,1,14.08,100,1,14.19,700,1,14.23,100,1,14.27,100,1,14.43,100,1,14.46,200,2,ARL,359807057
2033,2025-07-17T16:30:10.414277885Z,2025-07-17T16:30:10.414112314Z,10,2,1108,C,A,-1,13.47,15,130,165571,299312853,13.11,100,1,12.98,200,2,12.9,2,1,12.86,100,1,12.73,100,1,12.71,100,1,12.5,700,1,12.46,100,1,12.43,700,1,12.42,700,1,13.48,100,1,13.75,100,1,13.82,2,1,14.08,100,1,14.19,700,1,14.23,100,1,14.27,100,1,14.43,100,1,14.46,200,2,14.48,1400,2,ARL,360132781
2034,2025-07-17T16:30:10.416282484Z,2025-07-17T16:30:10.416115247Z,10,2,1108,A,A,0,13.45,15,130,167237,299313346,13.11,100,1,12.98,200,2,12.9,2,1,12.86,100,1,12.73,100,1,12.71,100,1,12.5,700,1,12.46,100,1,12.43,700,1,12.42,700,1,13.45,15,1,13.48,100,1,13.75,100,1,13.82,2,1,14.08,100,1,14.19,700,1,14.23,100,1,14.27,100,1,14.43,100,1,14.46,200,2,ARL,360438585
2035,2025-07-17T16:30:10.418989003Z,2025-07-17T16:30:10.418822976Z,10,2,1108,C,A,9,14.46,100,0,166027,299313811,13.11,100,1,12.98,200,2,12.9,2,1,12.86,100,1,12.73,100,1,12.71,100,1,12.5,700,1,12.46,100,1,12.43,700,1,12.42,700,1,13.45,15,1,13.48,100,1,13.75,100,1,13.82,2,1,14.08,100,1,14.19,700,1,14.23,100,1,14.27,100,1,14.43,100,1,14.46,100,1,ARL,358596029
2036,2025-07-17T16:30:10.418989003Z,2025-07-17T16:30:10.418822976Z,10,2,1108,A,A,8,14.35,100,130,166027,299313811,13.11,100,1,12.98,200,2,12.9,2,1,12.86,100,1,12.73,100,1,12.71,100,1,12.5,700,1,12.46,100,1,12.43,700,1,12.42,700,1,13.45,15,1,13.48,100,1,13.75,100,1,13.82,2,1,14.08,100,1,14.19,700,1,14.23,100,1,14.27,100,1,14.35,100,1,14.43,100,1,ARL,360438973
2037,2025-07-17T16:30:10.422019848Z,2025-07-17T16:30:10.421853908Z,10,2,1108,A,A,8,14.35,100,130,165940,299314095,13.11,100,1,12.98,200,2,12.9,2,1,12.86,100,1,12.73,100,1,12.71,100,1,12.5,700,1,12.46,100,1,12.43,700,1,12.42,700,1,13.45,15,1,13.48,100,1,13.75,100,1,13.82,2,1,14.08,100,1,14.19,700,1,14.23,100,1,14.27,100,1,14.35,200,2,14.43,100,1,ARL,360439617
2038,2025-07-17T16:30:10.853783416Z,2025-07-17T16:30:10.853617251Z,10,2,1108,C,A,-1,13.45,15,128,166165,299339139,13.11,100,1,12.98,200,2,12.9,2,1,12.86,100,1,12.73,100,1,12.71,100,1,12.5,700,1,12.46,100,1,12.43,700,1,12.42,700,1,13.48,100,1,13.75,100,1,13.82,2,1,14.08,100,1,14.19,700,1,14.23,100,1,14.27,100,1,14.35,200,2,14.43,100,1,14.48,1400,2,ARL,360438585
2039,2025-07-17T16:30:17.586107006Z,2025-07-17T16:30:17.585941385Z,10,2,1108,C,A,-1,13.82,2,0,165621,299471791,13.11,100,1,12.98,200,2,12.9,2,1,12.86,100,1,12.73,100,1,12.71,100,1,12.5,700,1,12.46,100,1,12.43,700,1,12.42,700,1,13.48,100,1,13.75,100,1,14.08,100,1,14.19,700,1,14.23,100,1,14.27,100,1,14.35,200,2,14.43,100,1,14.48,1400,2,14.49,100,1,ARL,359459321
2040,2025-07-17T16:30:17.586107006Z,2025-07-17T16:30:17.585941385Z,10,2,1108,A,A,1,13.74,2,130,165621,299471791,13.11,100,1,12.98,200,2,12.9,2,1,12.86,100,1,12.73,100,1,12.71,100,1,12.5,700,1,12.46,100,1,12.43,700,1,12.42,700,1,13.48,100,1,13.74,2,1,13.75,100,1,14.08,100,1,14.19,700,1,14.23,100,1,14.27,100,1,14.35,200,2,14.43,100,1,14.48,1400,2,ARL,360630309
2041,2025-07-17T16:30:20.998286323Z,2025-07-17T16:30:20.998120507Z,10,2,1108,C,A,-1,13.48,100,130,165816,299514720,13.11,100,1,12.98,200,2,12.9,2,1,12.86,100,1,12.73,100,1,12.71,100,1,12.5,700,1,12.46,100,1,12.43,700,1,12.42,700,1,13.74,2,1,13.75,100,1,14.08,100,1,14.19,700,1,14.23,100,1,14.27,100,1,14.35,200,2,14.43,100,1,14.48,1400,2,14.49,100,1,ARL,360140981
2042,2025-07-17T16:30:22.627301648Z,2025-07-17T16:30:22.627136264Z,10,2,1108,A,A,2,13.76,100,130,165384,299534828,13.11,100,1,12.98,200,2,12.9,2,1,12.86,100,1,12.73,100,1,12.71,100,1,12.5,700,1,12.46,100,1,12.43,700,1,12.42,700,1,13.74,2,1,13.75,100,1,13.76,100,1,14.08,100,1,14.19,700,1,14.23,100,1,14.27,100,1,14.35,200,2,14.43,100,1,14.48,1400,2,ARL,360721497
2043,2025-07-17T16:30:22.654496103Z,2025-07-17T16:30:22.654329199Z,10,2,1108,A,A,0,13.47,15,128,166904,299538824,13.11,100,1,12.98,200,2,12.9,2,1,12.86,100,1,12.73,100,1,12.71,100,1,12.5,700,1,12.46,100,1,12.43,700,1,12.42,700,1,13.47,15,1,13.74,2,1,13.75,100,1,13.76,100,1,14.08,100,1,14.19,700,1,14.23,100,1,14.27,100,1,14.35,200,2,14.43,100,1,ARL,360725173
2044,2025-07-17T16:30:22.654651825Z,2025-07-17T16:30:22.654486255Z,10,2,1108,C,A,-1,13.76,100,0,165570,299538851,13.11,100,1,12.98,200,2,12.9,2,1,12.86,100,1,12.73,100,1,12.71,100,1,12.5,700,1,12.46,100,1,12.43,700,1,12.42,700,1,13.47,15,1,13.74,2,1,13.75,100,1,14.08,100,1,14.19,700,1,14.23,100,1,14.27,100,1,14.35,200,2,14.43,100,1,14.48,1400,2,ARL,360721497
2045,2025-07-17T16:30:22.654651825Z,2025-07-17T16:30:22.654486255Z,10,2,1108,A,A,1,13.48,100,130,165570,299538851,13.11,100,1,12.98,200,2,12.9,2,1,12.86,100,1,12.73,100,1,12.71,100,1,12.5,700,1,12.46,100,1,12.43,700,1,12.42,700,1,13.47,15,1,13.48,100,1,13.74,2,1,13.75,100,1,14.08,100,1,14.19,700,1,14.23,100,1,14.27,100,1,14.35,200,2,14.43,100,1,ARL,360725257
2046,2025-07-17T16:30:32.855757165Z,2025-07-17T16:30:32.855591892Z,10,2,1108,A,A,0,13.45,15,130,165273,299703863,13.11,100,1,12.98,200,2,12.9,2,1,12.86,100,1,12.73,100,1,12.71,100,1,12.5,700,1,12.46,100,1,12.43,700,1,12.42,700,1,13.45,15,1,13.47,15,1,13.48,100,1,13.74,2,1,13.75,100,1,14.08,100,1,14.19,700,1,14.23,100,1,14.27,100,1,14.35,200,2,ARL,360937965
2047,2025-07-17T16:30:37.085122421Z,2025-07-17T16:30:37.084955904Z,10,2,1108,C,A,-1,13.48,100,0,166517,299811310,13.11,100,1,12.98,200,2,12.9,2,1,12.86,100,1,12.73,100,1,12.71,100,1,12.5,700,1,12.46,100,1,12.43,700,1,12.42,700,1,13.45,15,1,13.47,15,1,13.74,2,1,13.75,100,1,14.08,100,1,14.19,700,1,14.23,100,1,14.27,100,1,14.35,200,2,14.43,100,1,ARL,360725257
2048,2025-07-17T16:30:37.085122421Z,2025-07-17T16:30:37.084955904Z,10,2,1108,A,A,1,13.46,100,128,166517,299811310,13.11,100,1,12.98,200,2,12.9,2,1,12.86,100,1,12.73,100,1,12.71,100,1,12.5,700,1,12.46,100,1,12.43,700,1,12.42,700,1,13.45,15,1,13.46,100,1,13.47,15,1,13.74,2,1,13.75,100,1,14.08,100,1,14.19,700,1,14.23,100,1,14.27,100,1,14.35,200,2,ARL,361057077
2049,2025-07-17T16:30:37.137757858Z,2025-07-17T16:30:37.137592621Z,10,2,1108,C,A,-1,13.47,15,130,165237,299813487,13.11,100,1,12.98,200,2,12.9,2,1,12.86,100,1,12.73,100,1,12.71,100,1,12.5,700,1,12.46,100,1,12.43,700,1,12.42,700,1,13.45,15,1,13.46,100,1,13.74,2,1,13.75,100,1,14.08,100,1,14.19,700,1,14.23,100,1,14.27,100,1,14.35,200,2,14.43,100,1,ARL,360725173
2050,2025-07-17T16:30:38.141405894Z,2025-07-17T16:30:38.141240528Z,10,2,1108,A,A,0,13.43,15,130,165366,299865395,13.11,100,1,12.98,200,2,12.9,2,1,12.86,100,1,12.73,100,1,12.71,100,1,12.5,700,1,12.46,100,1,12.43,700,1,12.42,700,1,13.43,15,1,13.45,15,1,13.46,100,1,13.74,2,1,13.75,100,1,14.08,100,1,14.19,700,1,14.23,100,1,14.27,100,1,14.35,200,2,ARL,361107853
2051,2025-07-17T16:30:47.573465649Z,2025-07-17T16:30:47.573300334Z,10,2,1108,C,A,-1,13.45,15,130,165315,300016920,13.11,100,1,12.98,200,2,12.9,2,1,12.86,100,1,12.73,100,1,12.71,100,1,12.5,700,1,12.46,100,1,12.43,700,1,12.42,700,1,13.43,15,1,13.46,100,1,13.74,2,1,13.75,100,1,14.08,100,1,14.19,700,1,14.23,100,1,14.27,100,1,14.35,200,2,14.43,100,1,ARL,360937965
2052,2025-07-17T16:30:48.578361111Z,2025-07-17T16:30:48.578195765Z,10,2,1108,A,A,0,13.41,15,130,165346,300031495,13.11,100,1,12.98,200,2,12.9,2,1,12.86,100,1,12.73,100,1,12.71,100,1,12.5,700,1,12.46,100,1,12.43,700,1,12.42,700,1,13.41,15,1,13.43,15,1,13.46,100,1,13.74,2,1,13.75,100,1,14.08,100,1,14.19,700,1,14.23,100,1,14.27,100,1,14.35,200,2,ARL,361297545
2053,2025-07-17T16:31:01.839958311Z,2025-07-17T16:31:01.839792805Z,10,2,1108,C,A,-1,13.43,15,130,165506,300264348,13.11,100,1,12.98,200,2,12.9,2,1,12.86,100,1,12.73,100,1,12.71,100,1,12.5,700,1,12.46,100,1,12.43,700,1,12.42,700,1,13.41,15,1,13.46,100,1,13.74,2,1,13.75,100,1,14.08,100,1,14.19,700,1,14.23,100,1,14.27,100,1,14.35,200,2,14.43,100,1,ARL,361107853
2054,2025-07-17T16:31:03.518517508Z,2025-07-17T16:31:03.518351610Z,10,2,1108,A,A,0,13.39,15,130,165898,300289961,13.11,100,1,12.98,200,2,12.9,2,1,12.86,100,1,12.73,100,1,12.71,100,1,12.5,700,1,12.46,100,1,12.43,700,1,12.42,700,1,13.39,15,1,13.41,15,1,13.46,100,1,13.74,2,1,13.75,100,1,14.08,100,1,14.19,700,1,14.23,100,1,14.27,100,1,14.35,200,2,ARL,361608869
2055,2025-07-17T16:31:54.027799461Z,2025-07-17T16:31:54.027625924Z,10,2,1108,C,A,-1,13.39,15,128,173537,301134389,13.11,100,1,12.98,200,2,12.9,2,1,12.86,100,1,12.73,100,1,12.71,100,1,12.5,700,1,12.46,100,1,12.43,700,1,12.42,700,1,13.41,15,1,13.46,100,1,13.74,2,1,13.75,100,1,14.08,100,1,14.19,700,1,14.23,100,1,14.27,100,1,14.35,200,2,14.43,100,1,ARL,361608869
2056,2025-07-17T16:31:54.028392397Z,2025-07-17T16:31:54.028224104Z,10,2,1108,C,A,-1,13.41,15,128,168293,301134777,13.11,100,1,12.98,200,2,12.9,2,1,12.86,100,1,12.73,100,1,12.71,100,1,12.5,700,1,12.46,100,1,12.43,700,1,12.42,700,1,13.46,100,1,13.74,2,1,13.75,100,1,14.08,100,1,14.19,700,1,14.23,100,1,14.27,100,1,14.35,200,2,14.43,100,1,14.48,1400,2,ARL,361297545
2057,2025-07-17T16:31:54.032841763Z,2025-07-17T16:31:54.032676481Z,10,2,1108,A,A,0,13.4,15,130,165282,301135720,13.11,100,1,12.98,200,2,12.9,2,1,12.86,100,1,12.73,100,1,12.71,100,1,12.5,700,1,12.46,100,1,12.43,700,1,12.42,700,1,13.4,15,1,13.46,100,1,13.74,2,1,13.75,100,1,14.08,100,1,14.19,700,1,14.23,100,1,14.27,100,1,14.35,200,2,14.43,100,1,ARL,362676381
2058,2025-07-17T16:31:54.397251889Z,2025-07-17T16:31:54.397082756Z,10,2,1108,C,A,-1,13.4,15,128,169133,301159766,13.11,100,1,12.98,200,2,12.9,2,1,12.86,100,1,12.73,100,1,12.71,100,1,12.5,700,1,12.46,100,1,12.43,700,1,12.42,700,1,13.46,100,1,13.74,2,1,13.75,100,1,14.08,100,1,14.19,700,1,14.23,100,1,14.27,100,1,14.35,200,2,14.43,100,1,14.48,1400,2,ARL,362676381
2059,2025-07-17T16:32:07.237674436Z,2025-07-17T16:32:07.237509237Z,10,2,1108,A,A,0,13.43,15,130,165199,301520854,13.11,100,1,12.98,200,2,12.9,2,1,12.86,100,1,12.73,100,1,12.71,100,1,12.5,700,1,12.46,100,1,12.43,700,1,12.42,700,1,13.43,15,1,13.46,100,1,13.74,2,1,13.75,100,1,14.08,100,1,14.19,700,1,14.23,100,1,14.27,100,1,14.35,200,2,14.43,100,1,ARL,363127401
2060,2025-07-17T16:32:11.247820316Z,2025-07-17T16:32:11.247654753Z,10,2,1108,A,A,0,13.41,15,130,165563,301601389,13.11,100,1,12.98,200,2,12.9,2,1,12.86,100,1,12.73,100,1,12.71,100,1,12.5,700,1,12.46,100,1,12.43,700,1,12.42,700,1,13.41,15,1,13.43,15,1,13.46,100,1,13.74,2,1,13.75,100,1,14.08,100,1,14.19,700,1,14.23,100,1,14.27,100,1,14.35,200,2,ARL,363219933
2061,2025-07-17T16:32:14.460342711Z,2025-07-17T16:32:14.460177384Z,10,2,1108,C,A,-1,13.43,15,130,165327,301668882,13.11,100,1,12.98,200,2,12.9,2,1,12.86,100,1,12.73,100,1,12.71,100,1,12.5,700,1,12.46,100,1,12.43,700,1,12.42,700,1,13.41,15,1,13.46,100,1,13.74,2,1,13.75,100,1,14.08,100,1,14.19,700,1,14.23,100,1,14.27,100,1,14.35,200,2,14.43,100,1,ARL,363127401
2062,2025-07-17T16:32:15.800152246Z,2025-07-17T16:32:15.799985302Z,10,2,1108,A,A,0,13.39,15,128,166944,301682529,13.11,100,1,12.98,200,2,12.9,2,1,12.86,100,1,12.73,100,1,12.71,100,1,12.5,700,1,12.46,100,1,12.43,700,1,12.42,700,1,13.39,15,1,13.41,15,1,13.46,100,1,13.74,2,1,13.75,100,1,14.08,100,1,14.19,700,1,14.23,100,1,14.27,100,1,14.35,200,2,ARL,363311909
2063,2025-07-17T16:32:24.791231377Z,2025-07-17T16:32:24.791064822Z,10,2,1108,C,A,-1,13.39,15,130,166555,301841660,13.11,100,1,12.98,200,2,12.9,2,1,12.86,100,1,12.73,100,1,12.71,100,1,12.5,700,1,12.46,100,1,12.43,700,1,12.42,700,1,13.41,15,1,13.46,100,1,13.74,2,1,13.75,100,1,14.08,100,1,14.19,700,1,14.23,100,1,14.27,100,1,14.35,200,2,14.43,100,1,ARL,363311909
2064,2025-07-17T16:32:24.791366155Z,2025-07-17T16:32:24.791200959Z,10,2,1108,C,A,-1,13.41,15,130,165196,301841671,13.11,100,1,12.98,200,2,12.9,2,1,12.86,100,1,12.73,100,1,12.71,100,1,12.5,700,1,12.46,100,1,12.43,700,1,12.42,700,1,13.46,100,1,13.74,2,1,13.75,100,1,14.08,100,1,14.19,700,1,14.23,100,1,14.27,100,1,14.35,200,2,14.43,100,1,14.48,1400,2,ARL,363219933
2065,2025-07-17T16:32:29.844824236Z,2025-07-17T16:32:29.844658946Z,10,2,1108,A,A,0,13.45,15,130,165290,301914964,13.11,100,1,12.98,200,2,12.9,2,1,12.86,100,1,12.73,100,1,12.71,100,1,12.5,700,1,12.46,100,1,12.43,700,1,12.42,700,1,13.45,15,1,13.46,100,1,13.74,2,1,13.75,100,1,14.08,100,1,14.19,700,1,14.23,100,1,14.27,100,1,14.35,200,2,14.43,100,1,ARL,363610537
2066,2025-07-17T16:32:29.844877268Z,2025-07-17T16:32:29.844711976Z,10,2,1108,C,A,-1,13.46,100,130,165292,301914968,13.11,100,1,12.98,200,2,12.9,2,1,12.86,100,1,12.73,100,1,12.71,100,1,12.5,700,1,12.46,100,1,12.43,700,1,12.42,700,1,13.45,15,1,13.74,2,1,13.75,100,1,14.08,100,1,14.19,700,1,14.23,100,1,14.27,100,1,14.35,200,2,14.43,100,1,14.48,1400,2,ARL,361057077
2067,2025-07-17T16:32:29.845608090Z,2025-07-17T16:32:29.845442602Z,10,2,1108,C,A,-1,14.19,700,130,165488,301914978,13.11,100,1,12.98,200,2,12.9,2,1,12.86,100,1,12.73,100,1,12.71,100,1,12.5,700,1,12.46,100,1,12.43,700,1,12.42,700,1,13.45,15,1,13.74,2,1,13.75,100,1,14.08,100,1,14.23,100,1,14.27,100,1,14.35,200,2,14.43,100,1,14.48,1400,2,14.49,100,1,ARL,360283881
2068,2025-07-17T16:32:29.845650966Z,2025-07-17T16:32:29.845485675Z,10,2,1108,A,A,8,14.44,700,130,165291,301914979,13.11,100,1,12.98,200,2,12.9,2,1,12.86,100,1,12.73,100,1,12.71,100,1,12.5,700,1,12.46,100,1,12.43,700,1,12.42,700,1,13.45,15,1,13.74,2,1,13.75,100,1,14.08,100,1,14.23,100,1,14.27,100,1,14.35,200,2,14.43,100,1,14.44,700,1,14.48,1400,2,ARL,363610557
2069,2025-07-17T16:32:29.846177627Z,2025-07-17T16:32:29.846012015Z,10,2,1108,C,A,-1,14.08,100,130,165612,301914986,13.11,100,1,12.98,200,2,12.9,2,1,12.86,100,1,12.73,100,1,12.71,100,1,12.5,700,1,12.46,100,1,12.43,700,1,12.42,700,1,13.45,15,1,13.74,2,1,13.75,100,1,14.23,100,1,14.27,100,1,14.35,200,2,14.43,100,1,14.44,700,1,14.48,1400,2,14.49,100,1,ARL,360153053
2070,2025-07-17T16:32:29.846533245Z,2025-07-17T16:32:29.846367579Z,10,2,1108,A,A,6,14.36,100,130,165666,301914994,13.11,100,1,12.98,200,2,12.9,2,1,12.86,100,1,12.73,100,1,12.71,100,1,12.5,700,1,12.46,100,1,12.43,700,1,12.42,700,1,13.45,15,1,13.74,2,1,13.75,100,1,14.23,100,1,14.27,100,1,14.35,200,2,14.36,100,1,14.43,100,1,14.44,700,1,14.48,1400,2,ARL,363610593
2071,2025-07-17T16:32:29.848251064Z,2025-07-17T16:32:29.848085539Z,10,2,1108,C,A,-1,14.43,100,0,165525,301915015,13.11,100,1,12.98,200,2,12.9,2,1,12.86,100,1,12.73,100,1,12.71,100,1,12.5,700,1,12.46,100,1,12.43,700,1,12.42,700,1,13.45,15,1,13.74,2,1,13.75,100,1,14.23,100,1,14.27,100,1,14.35,200,2,14.36,100,1,14.44,700,1,14.48,1400,2,14.49,100,1,ARL,360141061
2072,2025-07-17T16:32:29.852212038Z,2025-07-17T16:32:29.852046762Z,10,2,1108,C,A,-1,14.27,100,130,165276,301915065,13.11,100,1,12.98,200,2,12.9,2,1,12.86,100,1,12.73,100,1,12.71,100,1,12.5,700,1,12.46,100,1,12.43,700,1,12.42,700,1,13.45,15,1,13.74,2,1,13.75,100,1,14.23,100,1,14.35,200,2,14.36,100,1,14.44,700,1,14.48,1400,2,14.49,100,1,14.53,100,1,ARL,360169365
2073,2025-07-17T16:32:29.856094796Z,2025-07-17T16:32:29.855929386Z,10,2,1108,C,A,-1,13.75,100,130,165410,301915115,13.11,100,1,12.98,200,2,12.9,2,1,12.86,100,1,12.73,100,1,12.71,100,1,12.5,700,1,12.46,100,1,12.43,700,1,12.42,700,1,13.45,15,1,13.74,2,1,14.23,100,1,14.35,200,2,14.36,100,1,14.44,700,1,14.48,1400,2,14.49,100,1,14.53,100,1,14.54,800,2,ARL,360141273
2074,2025-07-17T16:32:29.856125341Z,2025-07-17T16:32:29.855960388Z,10,2,1108,C,A,-1,14.44,700,130,164953,301915116,13.11,100,1,12.98,200,2,12.9,2,1,12.86,100,1,12.73,100,1,12.71,100,1,12.5,700,1,12.46,100,1,12.43,700,1,12.42,700,1,13.45,15,1,13.74,2,1,14.23,100,1,14.35,200,2,14.36,100,1,14.48,1400,2,14.49,100,1,14.53,100,1,14.54,800,2,14.72,100,1,ARL,363610557
2075,2025-07-17T16:32:29.856146919Z,2025-07-17T16:32:29.855981505Z,10,2,1108,A,A,2,14.03,100,130,165414,301915117,13.11,100,1,12.98,200,2,12.9,2,1,12.86,100,1,12.73,100,1,12.71,100,1,12.5,700,1,12.46,100,1,12.43,700,1,12.42,700,1,13.45,15,1,13.74,2,1,14.03,100,1,14.23,100,1,14.35,200,2,14.36,100,1,14.48,1400,2,14.49,100,1,14.53,100,1,14.54,800,2,ARL,363610673
2076,2025-07-17T16:32:29.858881677Z,2025-07-17T16:32:29.858716093Z,10,2,1108,C,A,-1,13.74,2,0,165584,301915144,13.11,100,1,12.98,200,2,12.9,2,1,12.86,100,1,12.73,100,1,12.71,100,1,12.5,700,1,12.46,100,1,12.43,700,1,12.42,700,1,13.45,15,1,14.03,100,1,14.23,100,1,14.35,200,2,14.36,100,1,14.48,1400,2,14.49,100,1,14.53,100,1,14.54,800,2,14.81,100,1,ARL,360630309
2077,2025-07-17T16:32:29.858881677Z,2025-07-17T16:32:29.858716093Z,10,2,1108,A,A,1,13.98,2,130,165584,301915144,13.11,100,1,12.98,200,2,12.9,2,1,12.86,100,1,12.73,100,1,12.71,100,1,12.5,700,1,12.46,100,1,12.43,700,1,12.42,700,1,13.45,15,1,13.98,2,1,14.03,100,1,14.23,100,1,14.35,200,2,14.36,100,1,14.48,1400,2,14.49,100,1,14.53,100,1,14.54,800,2,ARL,363610729
2078,2025-07-17T16:32:29.876261150Z,2025-07-17T16:32:29.876096205Z,10,2,1108,C,A,-1,14.03,100,130,164945,301915267,13.11,100,1,12.98,200,2,12.9,2,1,12.86,100,1,12.73,100,1,12.71,100,1,12.5,700,1,12.46,100,1,12.43,700,1,12.42,700,1,13.45,15,1,13.98,2,1,14.23,100,1,14.35,200,2,14.36,100,1,14.48,1400,2,14.49,100,1,14.53,100,1,14.54,800,2,14.81,100,1,ARL,363610673
2079,2025-07-17T16:32:29.876312329Z,2025-07-17T16:32:29.876146665Z,10,2,1108,A,A,3,14.25,100,130,165664,301915268,13.11,100,1,12.98,200,2,12.9,2,1,12.86,100,1,12.73,100,1,12.71,100,1,12.5,700,1,12.46,100,1,12.43,700,1,12.42,700,1,13.45,15,1,13.98,2,1,14.23,100,1,14.25,100,1,14.35,200,2,14.36,100,1,14.48,1400,2,14.49,100,1,14.53,100,1,14.54,800,2,ARL,363610909
2080,2025-07-17T16:32:29.912427241Z,2025-07-17T16:32:29.912262068Z,10,2,1108,A,A,1,13.46,100,130,165173,301915922,13.11,100,1,12.98,200,2,12.9,2,1,12.86,100,1,12.73,100,1,12.71,100,1,12.5,700,1,12.46,100,1,12.43,700,1,12.42,700,1,13.45,15,1,13.46,100,1,13.98,2,1,14.23,100,1,14.25,100,1,14.35,200,2,14.36,100,1,14.48,1400,2,14.49,100,1,14.53,100,1,ARL,363611637
2081,2025-07-17T16:32:29.913247496Z,2025-07-17T16:32:29.913082173Z,10,2,1108,A,A,7,14.41,100,130,165323,301915949,13.11,100,1,12.98,200,2,12.9,2,1,12.86,100,1,12.73,100,1,12.71,100,1,12.5,700,1,12.46,100,1,12.43,700,1,12.42,700,1,13.45,15,1,13.46,100,1,13.98,2,1,14.23,100,1,14.25,100,1,14.35,200,2,14.36,100,1,14.41,100,1,14.48,1400,2,14.49,100,1,ARL,363611673
2082,2025-07-17T16:32:29.935991671Z,2025-07-17T16:32:29.935826022Z,10,2,1108,C,A,-1,14.25,100,130,165649,301916340,13.11,100,1,12.98,200,2,12.9,2,1,12.86,100,1,12.73,100,1,12.71,100,1,12.5,700,1,12.46,100,1,12.43,700,1,12.42,700,1,13.45,15,1,13.46,100,1,13.98,2,1,14.23,100,1,14.35,200,2,14.36,100,1,14.41,100,1,14.48,1400,2,14.49,100,1,14.53,100,1,ARL,363610909
2083,2025-07-17T16:32:29.936042528Z,2025-07-17T16:32:29.935877281Z,10,2,1108,A,A,2,13.73,100,130,165247,301916344,13.11,100,1,12.98,200,2,12.9,2,1,12.86,100,1,12.73,100,1,12.71,100,1,12.5,700,1,12.46,100,1,12.43,700,1,12.42,700,1,13.45,15,1,13.46,100,1,13.73,100,1,13.98,2,1,14.23,100,1,14.35,200,2,14.36,100,1,14.41,100,1,14.48,1400,2,14.49,100,1,ARL,363612541
2084,2025-07-17T16:32:30.189607246Z,2025-07-17T16:32:30.189441584Z,10,2,1108,C,A,-1,13.98,2,0,165662,301922126,13.11,100,1,12.98,200,2,12.9,2,1,12.86,100,1,12.73,100,1,12.71,100,1,12.5,700,1,12.46,100,1,12.43,700,1,12.42,700,1,13.45,15,1,13.46,100,1,13.73,100,1,14.23,100,1,14.35,200,2,14.36,100,1,14.41,100,1,14.48,1400,2,14.49,100,1,14.5,100,1,ARL,363610729
2085,2025-07-17T16:32:30.189607246Z,2025-07-17T16:32:30.189441584Z,10,2,1108,A,A,2,13.7,2,130,165662,301922126,13.11,100,1,12.98,200,2,12.9,2,1,12.86,100,1,12.73,100,1,12.71,100,1,12.5,700,1,12.46,100,1,12.43,700,1,12.42,700,1,13.45,15,1,13.46,100,1,13.7,2,1,13.73,100,1,14.23,100,1,14.35,200,2,14.36,100,1,14.41,100,1,14.48,1400,2,14.49,100,1,ARL,363619809
2086,2025-07-17T16:32:30.540993820Z,2025-07-17T16:32:30.540828846Z,10,2,1108,C,A,-1,14.36,100,130,164974,301928173,13.11,100,1,12.98,200,2,12.9,2,1,12.86,100,1,12.73,100,1,12.71,100,1,12.5,700,1,12.46,100,1,12.43,700,1,12.42,700,1,13.45,15,1,13.46,100,1,13.7,2,1,13.73,100,1,14.23,100,1,14.35,200,2,14.41,100,1,14.48,1400,2,14.49,100,1,14.5,100,1,ARL,363610593
2087,2025-07-17T16:32:30.541354303Z,2025-07-17T16:32:30.541188934Z,10,2,1108,A,A,4,14.06,100,130,165369,301928175,13.11,100,1,12.98,200,2,12.9,2,1,12.86,100,1,12.73,100,1,12.71,100,1,12.5,700,1,12.46,100,1,12.43,700,1,12.42,700,1,13.45,15,1,13.46,100,1,13.7,2,1,13.73,100,1,14.06,100,1,14.23,100,1,14.35,200,2,14.41,100,1,14.48,1400,2,14.49,100,1,ARL,363629061
2088,2025-07-17T16:32:30.850033052Z,2025-07-17T16:32:30.849867081Z,10,2,1108,A,A,6,14.25,100,130,165971,301933741,13.11,100,1,12.98,200,2,12.9,2,1,12.86,100,1,12.73,100,1,12.71,100,1,12.5,700,1,12.46,100,1,12.43,700,1,12.42,700,1,13.45,15,1,13.46,100,1,13.7,2,1,13.73,100,1,14.06,100,1,14.23,100,1,14.25,100,1,14.35,200,2,14.41,100,1,14.48,1400,2,ARL,363634009
2089,2025-07-17T16:32:34.631558459Z,2025-07-17T16:32:34.631393080Z,10,2,1108,A,A,5,14.18,700,130,165379,301979109,13.11,100,1,12.98,200,2,12.9,2,1,12.86,100,1,12.73,100,1,12.71,100,1,12.5,700,1,12.46,100,1,12.43,700,1,12.42,700,1,13.45,15,1,13.46,100,1,13.7,2,1,13.73,100,1,14.06,100,1,14.18,700,1,14.23,100,1,14.25,100,1,14.35,200,2,14.41,100,1,ARL,363687721
2090,2025-07-17T16:32:34.860112637Z,2025-07-17T16:32:34.859947247Z,10,2,1108,C,A,-1,13.45,15,130,165390,301982608,13.11,100,1,12.98,200,2,12.9,2,1,12.86,100,1,12.73,100,1,12.71,100,1,12.5,700,1,12.46,100,1,12.43,700,1,12.42,700,1,13.46,100,1,13.7,2,1,13.73,100,1,14.06,100,1,14.18,700,1,14.23,100,1,14.25,100,1,14.35,200,2,14.41,100,1,14.48,1400,2,ARL,363610537
2091,2025-07-17T16:33:30.089876358Z,2025-07-17T16:33:30.089711013Z,10,2,1108,C,A,-1,13.46,100,130,165345,302886447,13.11,100,1,12.98,200,2,12.9,2,1,12.86,100,1,12.73,100,1,12.71,100,1,12.5,700,1,12.46,100,1,12.43,700,1,12.42,700,1,13.7,2,1,13.73,100,1,14.06,100,1,14.18,700,1,14.23,100,1,14.25,100,1,14.35,200,2,14.41,100,1,14.48,1400,2,14.49,100,1,ARL,363611637
2092,2025-07-17T16:33:30.090411681Z,2025-07-17T16:33:30.090246420Z,10,2,1108,C,A,-1,14.18,700,130,165261,302886453,13.11,100,1,12.98,200,2,12.9,2,1,12.86,100,1,12.73,100,1,12.71,100,1,12.5,700,1,12.46,100,1,12.43,700,1,12.42,700,1,13.7,2,1,13.73,100,1,14.06,100,1,14.23,100,1,14.25,100,1,14.35,200,2,14.41,100,1,14.48,1400,2,14.49,100,1,14.5,100,1,ARL,363687721
2093,2025-07-17T16:33:30.090471806Z,2025-07-17T16:33:30.090305998Z,10,2,1108,A,A,7,14.42,700,130,165808,302886454,13.11,100,1,12.98,200,2,12.9,2,1,12.86,100,1,12.73,100,1,12.71,100,1,12.5,700,1,12.46,100,1,12.43,700,1,12.42,700,1,13.7,2,1,13.73,100,1,14.06,100,1,14.23,100,1,14.25,100,1,14.35,200,2,14.41,100,1,14.42,700,1,14.48,1400,2,14.49,100,1,ARL,364850805
2094,2025-07-17T16:33:30.090981115Z,2025-07-17T16:33:30.090815784Z,10,2,1108,C,A,-1,14.06,100,130,165331,302886458,13.11,100,1,12.98,200,2,12.9,2,1,12.86,100,1,12.73,100,1,12.71,100,1,12.5,700,1,12.46,100,1,12.43,700,1,12.42,700,1,13.7,2,1,13.73,100,1,14.23,100,1,14.25,100,1,14.35,200,2,14.41,100,1,14.42,700,1,14.48,1400,2,14.49,100,1,14.53,100,1,ARL,363629061
2095,2025-07-17T16:33:30.091339021Z,2025-07-17T16:33:30.091173730Z,10,2,1108,A,A,4,14.34,100,130,165291,302886460,13.11,100,1,12.98,200,2,12.9,2,1,12.86,100,1,12.73,100,1,12.71,100,1,12.5,700,1,12.46,100,1,12.43,700,1,12.42,700,1,13.7,2,1,13.73,100,1,14.23,100,1,14.25,100,1,14.34,100,1,14.35,200,2,14.41,100,1,14.42,700,1,14.48,1400,2,14.49,100,1,ARL,364850829
2096,2025-07-17T16:33:30.092954819Z,2025-07-17T16:33:30.092789154Z,10,2,1108,C,A,-1,14.41,100,0,165665,302886527,13.11,100,1,12.98,200,2,12.9,2,1,12.86,100,1,12.73,100,1,12.71,100,1,12.5,700,1,12.46,100,1,12.43,700,1,12.42,700,1,13.7,2,1,13.73,100,1,14.23,100,1,14.25,100,1,14.34,100,1,14.35,200,2,14.42,700,1,14.48,1400,2,14.49,100,1,14.53,100,1,ARL,363611673
2097,2025-07-17T16:33:30.096101526Z,2025-07-17T16:33:30.095936436Z,10,2,1108,C,A,-1,14.25,100,130,165090,302886538,13.11,100,1,12.98,200,2,12.9,2,1,12.86,100,1,12.73,100,1,12.71,100,1,12.5,700,1,12.46,100,1,12.43,700,1,12.42,700,1,13.7,2,1,13.73,100,1,14.23,100,1,14.34,100,1,14.35,200,2,14.42,700,1,14.48,1400,2,14.49,100,1,14.53,100,1,14.54,700,1,ARL,363634009
2098,2025-07-17T16:33:30.096245867Z,2025-07-17T16:33:30.096080731Z,10,2,1108,A,A,8,14.52,100,130,165136,302886541,13.11,100,1,12.98,200,2,12.9,2,1,12.86,100,1,12.73,100,1,12.71,100,1,12.5,700,1,12.46,100,1,12.43,700,1,12.42,700,1,13.7,2,1,13.73,100,1,14.23,100,1,14.34,100,1,14.35,200,2,14.42,700,1,14.48,1400,2,14.49,100,1,14.52,100,1,14.53,100,1,ARL,364850857
2099,2025-07-17T16:33:30.098419156Z,2025-07-17T16:33:30.098253924Z,10,2,1108,C,A,-1,13.73,100,130,165232,302886562,13.11,100,1,12.98,200,2,12.9,2,1,12.86,100,1,12.73,100,1,12.71,100,1,12.5,700,1,12.46,100,1,12.43,700,1,12.42,700,1,13.7,2,1,14.23,100,1,14.34,100,1,14.35,200,2,14.42,700,1,14.48,1400,2,14.49,100,1,14.52,100,1,14.53,100,1,14.54,700,1,ARL,363612541
2100,2025-07-17T16:33:30.098450406Z,2025-07-17T16:33:30.098285415Z,10,2,1108,C,A,-1,14.42,700,130,164991,302886563,13.11,100,1,12.98,200,2,12.9,2,1,12.86,100,1,12.73,100,1,12.71,100,1,12.5,700,1,12.46,100,1,12.43,700,1,12.42,700,1,13.7,2,1,14.23,100,1,14.34,100,1,14.35,200,2,14.48,1400,2,14.49,100,1,14.52,100,1,14.53,100,1,14.54,700,1,14.7,100,1,ARL,364850805
2101,2025-07-17T16:33:30.098470153Z,2025-07-17T16:33:30.098305102Z,10,2,1108,A,A,1,14,100,130,165051,302886564,13.11,100,1,12.98,200,2,12.9,2,1,12.86,100,1,12.73,100,1,12.71,100,1,12.5,700,1,12.46,100,1,12.43,700,1,12.42,700,1,13.7,2,1,14,100,1,14.23,100,1,14.34,100,1,14.35,200,2,14.48,1400,2,14.49,100,1,14.52,100,1,14.53,100,1,14.54,700,1,ARL,364850865
2102,2025-07-17T16:33:30.098761100Z,2025-07-17T16:33:30.098595621Z,10,2,1108,C,A,-1,13.7,2,0,165479,302886565,13.11,100,1,12.98,200,2,12.9,2,1,12.86,100,1,12.73,100,1,12.71,100,1,12.5,700,1,12.46,100,1,12.43,700,1,12.42,700,1,14,100,1,14.23,100,1,14.34,100,1,14.35,200,2,14.48,1400,2,14.49,100,1,14.52,100,1,14.53,100,1,14.54,700,1,14.7,100,1,ARL,363619809
2103,2025-07-17T16:33:30.098761100Z,2025-07-17T16:33:30.098595621Z,10,2,1108,A,A,0,13.95,2,130,165479,302886565,13.11,100,1,12.98,200,2,12.9,2,1,12.86,100,1,12.73,100,1,12.71,100,1,12.5,700,1,12.46,100,1,12.43,700,1,12.42,700,1,13.95,2,1,14,100,1,14.23,100,1,14.34,100,1,14.35,200,2,14.48,1400,2,14.49,100,1,14.52,100,1,14.53,100,1,14.54,700,1,ARL,364850881
2104,2025-07-17T16:33:30.108057014Z,2025-07-17T16:33:30.107892023Z,10,2,1108,C,A,-1,14,100,130,164991,302887072,13.11,100,1,12.98,200,2,12.9,2,1,12.86,100,1,12.73,100,1,12.71,100,1,12.5,700,1,12.46,100,1,12.43,700,1,12.42,700,1,13.95,2,1,14.23,100,1,14.34,100,1,14.35,200,2,14.48,1400,2,14.49,100,1,14.52,100,1,14.53,100,1,14.54,700,1,14.79,100,1,ARL,364850865
2105,2025-07-17T16:33:30.108104876Z,2025-07-17T16:33:30.107939741Z,10,2,1108,A,A,1,14.23,100,130,165135,302887073,13.11,100,1,12.98,200,2,12.9,2,1,12.86,100,1,12.73,100,1,12.71,100,1,12.5,700,1,12.46,100,1,12.43,700,1,12.42,700,1,13.95,2,1,14.23,200,2,14.34,100,1,14.35,200,2,14.48,1400,2,14.49,100,1,14.52,100,1,14.53,100,1,14.54,700,1,14.79,100,1,ARL,364851745
2106,2025-07-17T16:33:30.141192726Z,2025-07-17T16:33:30.141027528Z,10,2,1108,C,A,-1,14.79,100,0,165198,302887727,13.11,100,1,12.98,200,2,12.9,2,1,12.86,100,1,12.73,100,1,12.71,100,1,12.5,700,1,12.46,100,1,12.43,700,1,12.42,700,1,13.95,2,1,14.23,200,2,14.34,100,1,14.35,200,2,14.48,1400,2,14.49,100,1,14.52,100,1,14.53,100,1,14.54,700,1,14.81,100,1,ARL,364850825
2107,2025-07-17T16:33:30.231850974Z,2025-07-17T16:33:30.231685682Z,10,2,1108,A,A,9,14.68,700,130,165292,302888895,13.11,100,1,12.98,200,2,12.9,2,1,12.86,100,1,12.73,100,1,12.71,100,1,12.5,700,1,12.46,100,1,12.43,700,1,12.42,700,1,13.95,2,1,14.23,200,2,14.34,100,1,14.35,200,2,14.48,1400,2,14.49,100,1,14.52,100,1,14.53,100,1,14.54,700,1,14.68,700,1,ARL,364854641
2108,2025-07-17T16:33:30.550848293Z,2025-07-17T16:33:30.550682972Z,10,2,1108,C,A,-1,14.53,100,130,165321,302893144,13.11,100,1,12.98,200,2,12.9,2,1,12.86,100,1,12.73,100,1,12.71,100,1,12.5,700,1,12.46,100,1,12.43,700,1,12.42,700,1,13.95,2,1,14.23,200,2,14.34,100,1,14.35,200,2,14.48,1400,2,14.49,100,1,14.52,100,1,14.54,700,1,14.68,700,1,14.81,200,2,ARL,356722649
2109,2025-07-17T16:33:30.604637872Z,2025-07-17T16:33:30.604472710Z,10,2,1108,C,A,9,14.81,100,0,165162,302893497,13.11,100,1,12.98,200,2,12.9,2,1,12.86,100,1,12.73,100,1,12.71,100,1,12.5,700,1,12.46,100,1,12.43,700,1,12.42,700,1,13.95,2,1,14.23,200,2,14.34,100,1,14.35,200,2,14.48,1400,2,14.49,100,1,14.52,100,1,14.54,700,1,14.68,700,1,14.81,100,1,ARL,363613421
2110,2025-07-17T16:33:30.612521721Z,2025-07-17T16:33:30.612356156Z,10,2,1108,C,A,-1,14.49,100,0,165565,302893537,13.11,100,1,12.98,200,2,12.9,2,1,12.86,100,1,12.73,100,1,12.71,100,1,12.5,700,1,12.46,100,1,12.43,700,1,12.42,700,1,13.95,2,1,14.23,200,2,14.34,100,1,14.35,200,2,14.48,1400,2,14.52,100,1,14.54,700,1,14.68,700,1,14.81,100,1,14.96,100,1,ARL,359404829
2111,2025-07-17T16:33:30.612521721Z,2025-07-17T16:33:30.612356156Z,10,2,1108,A,A,9,14.96,100,130,165565,302893537,13.11,100,1,12.98,200,2,12.9,2,1,12.86,100,1,12.73,100,1,12.71,100,1,12.5,700,1,12.46,100,1,12.43,700,1,12.42,700,1,13.95,2,1,14.23,200,2,14.34,100,1,14.35,200,2,14.48,1400,2,14.52,100,1,14.54,700,1,14.68,700,1,14.81,100,1,14.96,200,2,ARL,364862829
2112,2025-07-17T16:33:30.817241936Z,2025-07-17T16:33:30.817076178Z,10,2,1108,C,A,-1,14.34,100,130,165758,302896626,13.11,100,1,12.98,200,2,12.9,2,1,12.86,100,1,12.73,100,1,12.71,100,1,12.5,700,1,12.46,100,1,12.43,700,1,12.42,700,1,13.95,2,1,14.23,200,2,14.35,200,2,14.48,1400,2,14.52,100,1,14.54,700,1,14.68,700,1,14.81,100,1,14.96,200,2,15.03,100,1,ARL,364850829
2113,2025-07-17T16:33:30.817590929Z,2025-07-17T16:33:30.817425307Z,10,2,1108,A,A,6,14.6,100,130,165622,302896627,13.11,100,1,12.98,200,2,12.9,2,1,12.86,100,1,12.73,100,1,12.71,100,1,12.5,700,1,12.46,100,1,12.43,700,1,12.42,700,1,13.95,2,1,14.23,200,2,14.35,200,2,14.48,1400,2,14.52,100,1,14.54,700,1,14.6,100,1,14.68,700,1,14.81,100,1,14.96,200,2,ARL,364866209
2114,2025-07-17T16:33:30.966227665Z,2025-07-17T16:33:30.966062395Z,10,2,1108,A,A,1,13.96,100,130,165270,302898973,13.11,100,1,12.98,200,2,12.9,2,1,12.86,100,1,12.73,100,1,12.71,100,1,12.5,700,1,12.46,100,1,12.43,700,1,12.42,700,1,13.95,2,1,13.96,100,1,14.23,200,2,14.35,200,2,14.48,1400,2,14.52,100,1,14.54,700,1,14.6,100,1,14.68,700,1,14.81,100,1,ARL,364868901
2115,2025-07-17T16:33:31.084776432Z,2025-07-17T16:33:31.084610021Z,10,2,1108,A,A,5,14.51,100,0,166411,302900128,13.11,100,1,12.98,200,2,12.9,2,1,12.86,100,1,12.73,100,1,12.71,100,1,12.5,700,1,12.46,100,1,12.43,700,1,12.42,700,1,13.95,2,1,13.96,100,1,14.23,200,2,14.35,200,2,14.48,1400,2,14.51,100,1,14.52,100,1,14.54,700,1,14.6,100,1,14.68,700,1,ARL,364870969
2116,2025-07-17T16:33:31.084776432Z,2025-07-17T16:33:31.084610406Z,10,2,1108,C,A,2,14.23,100,130,166026,302900129,13.11,100,1,12.98,200,2,12.9,2,1,12.86,100,1,12.73,100,1,12.71,100,1,12.5,700,1,12.46,100,1,12.43,700,1,12.42,700,1,13.95,2,1,13.96,100,1,14.23,100,1,14.35,200,2,14.48,1400,2,14.51,100,1,14.52,100,1,14.54,700,1,14.6,100,1,14.68,700,1,ARL,356878397
2117,2025-07-17T16:33:31.101033838Z,2025-07-17T16:33:31.100868523Z,10,2,1108,C,A,-1,14.52,100,0,165315,302900253,13.11,100,1,12.98,200,2,12.9,2,1,12.86,100,1,12.73,100,1,12.71,100,1,12.5,700,1,12.46,100,1,12.43,700,1,12.42,700,1,13.95,2,1,13.96,100,1,14.23,100,1,14.35,200,2,14.48,1400,2,14.51,100,1,14.54,700,1,14.6,100,1,14.68,700,1,14.81,100,1,ARL,364850857
2118,2025-07-17T16:33:31.101033838Z,2025-07-17T16:33:31.100868523Z,10,2,1108,A,A,9,14.75,100,130,165315,302900253,13.11,100,1,12.98,200,2,12.9,2,1,12.86,100,1,12.73,100,1,12.71,100,1,12.5,700,1,12.46,100,1,12.43,700,1,12.42,700,1,13.95,2,1,13.96,100,1,14.23,100,1,14.35,200,2,14.48,1400,2,14.51,100,1,14.54,700,1,14.6,100,1,14.68,700,1,14.75,100,1,ARL,364871373
2119,2025-07-17T16:33:44.518160840Z,2025-07-17T16:33:44.517994545Z,10,2,1108,A,A,0,13.43,15,130,166295,303072465,13.11,100,1,12.98,200,2,12.9,2,1,12.86,100,1,12.73,100,1,12.71,100,1,12.5,700,1,12.46,100,1,12.43,700,1,12.42,700,1,13.43,15,1,13.95,2,1,13.96,100,1,14.23,100,1,14.35,200,2,14.48,1400,2,14.51,100,1,14.54,700,1,14.6,100,1,14.68,700,1,ARL,365099977
2120,2025-07-17T16:33:44.586150696Z,2025-07-17T16:33:44.585985363Z,10,2,1108,C,B,-1,12.9,2,0,165333,303074172,13.11,100,1,12.98,200,2,12.86,100,1,12.73,100,1,12.71,100,1,12.5,700,1,12.46,100,1,12.43,700,1,12.42,700,1,12.37,700,1,13.43,15,1,13.95,2,1,13.96,100,1,14.23,100,1,14.35,200,2,14.48,1400,2,14.51,100,1,14.54,700,1,14.6,100,1,14.68,700,1,ARL,357261961
2121,2025-07-17T16:33:44.586150696Z,2025-07-17T16:33:44.585985363Z,10,2,1108,A,B,1,12.99,2,130,165333,303074172,13.11,100,1,12.99,2,1,12.98,200,2,12.86,100,1,12.73,100,1,12.71,100,1,12.5,700,1,12.46,100,1,12.43,700,1,12.42,700,1,13.43,15,1,13.95,2,1,13.96,100,1,14.23,100,1,14.35,200,2,14.48,1400,2,14.51,100,1,14.54,700,1,14.6,100,1,14.68,700,1,ARL,365101121
2122,2025-07-17T16:33:54.862730370Z,2025-07-17T16:33:54.862565014Z,10,2,1108,A,A,0,13.41,15,130,165356,303210030,13.11,100,1,12.99,2,1,12.98,200,2,12.86,100,1,12.73,100,1,12.71,100,1,12.5,700,1,12.46,100,1,12.43,700,1,12.42,700,1,13.41,15,1,13.43,15,1,13.95,2,1,13.96,100,1,14.23,100,1,14.35,200,2,14.48,1400,2,14.51,100,1,14.54,700,1,14.6,100,1,ARL,365283485
2123,2025-07-17T16:33:59.769411538Z,2025-07-17T16:33:59.769246037Z,10,2,1108,C,A,-1,13.96,100,0,165501,303268214,13.11,100,1,12.99,2,1,12.98,200,2,12.86,100,1,12.73,100,1,12.71,100,1,12.5,700,1,12.46,100,1,12.43,700,1,12.42,700,1,13.41,15,1,13.43,15,1,13.95,2,1,14.23,100,1,14.35,200,2,14.48,1400,2,14.51,100,1,14.54,700,1,14.6,100,1,14.68,700,1,ARL,364868901
2124,2025-07-17T16:33:59.769411538Z,2025-07-17T16:33:59.769246037Z,10,2,1108,A,A,2,13.94,100,130,165501,303268214,13.11,100,1,12.99,2,1,12.98,200,2,12.86,100,1,12.73,100,1,12.71,100,1,12.5,700,1,12.46,100,1,12.43,700,1,12.42,700,1,13.41,15,1,13.43,15,1,13.94,100,1,13.95,2,1,14.23,100,1,14.35,200,2,14.48,1400,2,14.51,100,1,14.54,700,1,14.6,100,1,ARL,365359953
2125,2025-07-17T16:33:59.769696813Z,2025-07-17T16:33:59.769531404Z,10,2,1108,C,A,-1,13.95,2,0,165409,303268221,13.11,100,1,12.99,2,1,12.98,200,2,12.86,100,1,12.73,100,1,12.71,100,1,12.5,700,1,12.46,100,1,12.43,700,1,12.42,700,1,13.41,15,1,13.43,15,1,13.94,100,1,14.23,100,1,14.35,200,2,14.48,1400,2,14.51,100,1,14.54,700,1,14.6,100,1,14.68,700,1,ARL,364850881
2126,2025-07-17T16:33:59.769696813Z,2025-07-17T16:33:59.769531404Z,10,2,1108,A,A,2,13.94,2,130,165409,303268221,13.11,100,1,12.99,2,1,12.98,200,2,12.86,100,1,12.73,100,1,12.71,100,1,12.5,700,1,12.46,100,1,12.43,700,1,12.42,700,1,13.41,15,1,13.43,15,1,13.94,102,2,14.23,100,1,14.35,200,2,14.48,1400,2,14.51,100,1,14.54,700,1,14.6,100,1,14.68,700,1,ARL,365359981
2127,2025-07-17T16:34:17.588352560Z,2025-07-17T16:34:17.588187064Z,10,2,1108,C,B,-1,12.99,2,0,165496,303567720,13.11,100,1,12.98,200,2,12.86,100,1,12.73,100,1,12.71,100,1,12.5,700,1,12.46,100,1,12.43,700,1,12.42,700,1,12.37,700,1,13.41,15,1,13.43,15,1,13.94,102,2,14.23,100,1,14.35,200,2,14.48,1400,2,14.51,100,1,14.54,700,1,14.6,100,1,14.68,700,1,ARL,365101121
2128,2025-07-17T16:34:17.588352560Z,2025-07-17T16:34:17.588187064Z,10,2,1108,A,B,1,13.07,2,130,165496,303567720,13.11,100,1,13.07,2,1,12.98,200,2,12.86,100,1,12.73,100,1,12.71,100,1,12.5,700,1,12.46,100,1,12.43,700,1,12.42,700,1,13.41,15,1,13.43,15,1,13.94,102,2,14.23,100,1,14.35,200,2,14.48,1400,2,14.51,100,1,14.54,700,1,14.6,100,1,14.68,700,1,ARL,365743281
2129,2025-07-17T16:34:22.930893268Z,2025-07-17T16:34:22.930728013Z,10,2,1108,C,A,-1,13.43,15,130,165255,303633305,13.11,100,1,13.07,2,1,12.98,200,2,12.86,100,1,12.73,100,1,12.71,100,1,12.5,700,1,12.46,100,1,12.43,700,1,12.42,700,1,13.41,15,1,13.94,102,2,14.23,100,1,14.35,200,2,14.48,1400,2,14.51,100,1,14.54,700,1,14.6,100,1,14.68,700,1,14.75,100,1,ARL,365099977
2130,2025-07-17T16:34:23.935665713Z,2025-07-17T16:34:23.935500330Z,10,2,1108,A,A,0,13.39,15,130,165383,303659749,13.11,100,1,13.07,2,1,12.98,200,2,12.86,100,1,12.73,100,1,12.71,100,1,12.5,700,1,12.46,100,1,12.43,700,1,12.42,700,1,13.39,15,1,13.41,15,1,13.94,102,2,14.23,100,1,14.35,200,2,14.48,1400,2,14.51,100,1,14.54,700,1,14.6,100,1,14.68,700,1,ARL,365868793
2131,2025-07-17T16:34:24.279536922Z,2025-07-17T16:34:24.279370835Z,10,2,1108,C,A,2,13.94,100,0,166087,303666139,13.11,100,1,13.07,2,1,12.98,200,2,12.86,100,1,12.73,100,1,12.71,100,1,12.5,700,1,12.46,100,1,12.43,700,1,12.42,700,1,13.39,15,1,13.41,15,1,13.94,2,1,14.23,100,1,14.35,200,2,14.48,1400,2,14.51,100,1,14.54,700,1,14.6,100,1,14.68,700,1,ARL,365359953
2132,2025-07-17T16:34:24.279536922Z,2025-07-17T16:34:24.279370835Z,10,2,1108,A,A,2,13.92,100,130,166087,303666139,13.11,100,1,13.07,2,1,12.98,200,2,12.86,100,1,12.73,100,1,12.71,100,1,12.5,700,1,12.46,100,1,12.43,700,1,12.42,700,1,13.39,15,1,13.41,15,1,13.92,100,1,13.94,2,1,14.23,100,1,14.35,200,2,14.48,1400,2,14.51,100,1,14.54,700,1,14.6,100,1,ARL,365876341
2133,2025-07-17T16:36:08.787698556Z,2025-07-17T16:36:08.787533217Z,10,2,1108,A,A,2,13.42,100,130,165339,305042754,13.11,100,1,13.07,2,1,12.98,200,2,12.86,100,1,12.73,100,1,12.71,100,1,12.5,700,1,12.46,100,1,12.43,700,1,12.42,700,1,13.39,15,1,13.41,15,1,13.42,100,1,13.92,100,1,13.94,2,1,14.23,100,1,14.35,200,2,14.48,1400,2,14.51,100,1,14.54,700,1,ARL,367721465
2134,2025-07-17T16:36:08.788471709Z,2025-07-17T16:36:08.788305174Z,10,2,1108,A,A,7,14.46,100,128,166535,305042788,13.11,100,1,13.07,2,1,12.98,200,2,12.86,100,1,12.73,100,1,12.71,100,1,12.5,700,1,12.46,100,1,12.43,700,1,12.42,700,1,13.39,15,1,13.41,15,1,13.42,100,1,13.92,100,1,13.94,2,1,14.23,100,1,14.35,200,2,14.46,100,1,14.48,1400,2,14.51,100,1,ARL,367721513
2135,2025-07-17T16:36:08.788838644Z,2025-07-17T16:36:08.788673150Z,10,2,1108,A,A,5,14.02,100,130,165494,305042798,13.11,100,1,13.07,2,1,12.98,200,2,12.86,100,1,12.73,100,1,12.71,100,1,12.5,700,1,12.46,100,1,12.43,700,1,12.42,700,1,13.39,15,1,13.41,15,1,13.42,100,1,13.92,100,1,13.94,2,1,14.02,100,1,14.23,100,1,14.35,200,2,14.46,100,1,14.48,1400,2,ARL,367721521
2136,2025-07-17T16:36:08.791164652Z,2025-07-17T16:36:08.790998871Z,10,2,1108,A,A,8,14.36,100,130,165781,305042843,13.11,100,1,13.07,2,1,12.98,200,2,12.86,100,1,12.73,100,1,12.71,100,1,12.5,700,1,12.46,100,1,12.43,700,1,12.42,700,1,13.39,15,1,13.41,15,1,13.42,100,1,13.92,100,1,13.94,2,1,14.02,100,1,14.23,100,1,14.35,200,2,14.36,100,1,14.46,100,1,ARL,367721617
2137,2025-07-17T16:36:08.813263755Z,2025-07-17T16:36:08.813098222Z,10,2,1108,C,A,-1,14.23,100,130,165533,305043109,13.11,100,1,13.07,2,1,12.98,200,2,12.86,100,1,12.73,100,1,12.71,100,1,12.5,700,1,12.46,100,1,12.43,700,1,12.42,700,1,13.39,15,1,13.41,15,1,13.42,100,1,13.92,100,1,13.94,2,1,14.02,100,1,14.35,200,2,14.36,100,1,14.46,100,1,14.48,1400,2,ARL,364851745
2138,2025-07-17T16:36:08.813315868Z,2025-07-17T16:36:08.813150617Z,10,2,1108,A,A,3,13.69,100,130,165251,305043110,13.11,100,1,13.07,2,1,12.98,200,2,12.86,100,1,12.73,100,1,12.71,100,1,12.5,700,1,12.46,100,1,12.43,700,1,12.42,700,1,13.39,15,1,13.41,15,1,13.42,100,1,13.69,100,1,13.92,100,1,13.94,2,1,14.02,100,1,14.35,200,2,14.36,100,1,14.46,100,1,ARL,367721969
2139,2025-07-17T16:36:08.861304636Z,2025-07-17T16:36:08.861139066Z,10,2,1108,A,A,8,14.36,100,130,165570,305043519,13.11,100,1,13.07,2,1,12.98,200,2,12.86,100,1,12.73,100,1,12.71,100,1,12.5,700,1,12.46,100,1,12.43,700,1,12.42,700,1,13.39,15,1,13.41,15,1,13.42,100,1,13.69,100,1,13.92,100,1,13.94,2,1,14.02,100,1,14.35,200,2,14.36,200,2,14.46,100,1,ARL,367722697
2140,2025-07-17T16:36:08.927786326Z,2025-07-17T16:36:08.927620800Z,10,2,1108,A,A,7,14.22,100,130,165526,305044162,13.11,100,1,13.07,2,1,12.98,200,2,12.86,100,1,12.73,100,1,12.71,100,1,12.5,700,1,12.46,100,1,12.43,700,1,12.42,700,1,13.39,15,1,13.41,15,1,13.42,100,1,13.69,100,1,13.92,100,1,13.94,2,1,14.02,100,1,14.22,100,1,14.35,200,2,14.36,200,2,ARL,367724041
2141,2025-07-17T16:36:08.966850725Z,2025-07-17T16:36:08.966685380Z,10,2,1108,A,A,6,13.95,100,130,165345,305045055,13.11,100,1,13.07,2,1,12.98,200,2,12.86,100,1,12.73,100,1,12.71,100,1,12.5,700,1,12.46,100,1,12.43,700,1,12.42,700,1,13.39,15,1,13.41,15,1,13.42,100,1,13.69,100,1,13.92,100,1,13.94,2,1,13.95,100,1,14.02,100,1,14.22,100,1,14.35,200,2,ARL,367724713
2142,2025-07-17T16:36:08.984778799Z,2025-07-17T16:36:08.984613329Z,10,2,1108,A,A,8,14.21,100,130,165470,305045290,13.11,100,1,13.07,2,1,12.98,200,2,12.86,100,1,12.73,100,1,12.71,100,1,12.5,700,1,12.46,100,1,12.43,700,1,12.42,700,1,13.39,15,1,13.41,15,1,13.42,100,1,13.69,100,1,13.92,100,1,13.94,2,1,13.95,100,1,14.02,100,1,14.21,100,1,14.22,100,1,ARL,367724841
2143,2025-07-17T16:36:09.002025490Z,2025-07-17T16:36:09.001859949Z,10,2,1108,C,A,-1,13.92,100,0,165541,305045747,13.11,100,1,13.07,2,1,12.98,200,2,12.86,100,1,12.73,100,1,12.71,100,1,12.5,700,1,12.46,100,1,12.43,700,1,12.42,700,1,13.39,15,1,13.41,15,1,13.42,100,1,13.69,100,1,13.94,2,1,13.95,100,1,14.02,100,1,14.21,100,1,14.22,100,1,14.35,200,2,ARL,365876341
2144,2025-07-17T16:36:09.002025490Z,2025-07-17T16:36:09.001859949Z,10,2,1108,A,A,3,13.43,100,130,165541,305045747,13.11,100,1,13.07,2,1,12.98,200,2,12.86,100,1,12.73,100,1,12.71,100,1,12.5,700,1,12.46,100,1,12.43,700,1,12.42,700,1,13.39,15,1,13.41,15,1,13.42,100,1,13.43,100,1,13.69,100,1,13.94,2,1,13.95,100,1,14.02,100,1,14.21,100,1,14.22,100,1,ARL,367725181
2145,2025-07-17T16:36:09.186314332Z,2025-07-17T16:36:09.186148784Z,10,2,1108,C,B,-1,13.07,2,0,165548,305049492,13.11,100,1,12.98,200,2,12.86,100,1,12.73,100,1,12.71,100,1,12.5,700,1,12.46,100,1,12.43,700,1,12.42,700,1,12.37,700,1,13.39,15,1,13.41,15,1,13.42,100,1,13.43,100,1,13.69,100,1,13.94,2,1,13.95,100,1,14.02,100,1,14.21,100,1,14.22,100,1,ARL,365743281
2146,2025-07-17T16:36:09.186314332Z,2025-07-17T16:36:09.186148784Z,10,2,1108,A,B,1,12.99,2,130,165548,305049492,13.11,100,1,12.99,2,1,12.98,200,2,12.86,100,1,12.73,100,1,12.71,100,1,12.5,700,1,12.46,100,1,12.43,700,1,12.42,700,1,13.39,15,1,13.41,15,1,13.42,100,1,13.43,100,1,13.69,100,1,13.94,2,1,13.95,100,1,14.02,100,1,14.21,100,1,14.22,100,1,ARL,367731761
2147,2025-07-17T16:36:15.432347217Z,2025-07-17T16:36:15.432181896Z,10,2,1108,A,A,8,14.16,700,130,165321,305159106,13.11,100,1,12.99,2,1,12.98,200,2,12.86,100,1,12.73,100,1,12.71,100,1,12.5,700,1,12.46,100,1,12.43,700,1,12.42,700,1,13.39,15,1,13.41,15,1,13.42,100,1,13.43,100,1,13.69,100,1,13.94,2,1,13.95,100,1,14.02,100,1,14.16,700,1,14.21,100,1,ARL,367862613
2148,2025-07-17T16:36:15.790152351Z,2025-07-17T16:36:15.789986725Z,10,2,1108,C,A,-1,13.94,2,0,165626,305163657,13.11,100,1,12.99,2,1,12.98,200,2,12.86,100,1,12.73,100,1,12.71,100,1,12.5,700,1,12.46,100,1,12.43,700,1,12.42,700,1,13.39,15,1,13.41,15,1,13.42,100,1,13.43,100,1,13.69,100,1,13.95,100,1,14.02,100,1,14.16,700,1,14.21,100,1,14.22,100,1,ARL,365359981
2149,2025-07-17T16:36:15.790152351Z,2025-07-17T16:36:15.789986725Z,10,2,1108,A,A,5,13.85,2,130,165626,305163657,13.11,100,1,12.99,2,1,12.98,200,2,12.86,100,1,12.73,100,1,12.71,100,1,12.5,700,1,12.46,100,1,12.43,700,1,12.42,700,1,13.39,15,1,13.41,15,1,13.42,100,1,13.43,100,1,13.69,100,1,13.85,2,1,13.95,100,1,14.02,100,1,14.16,700,1,14.21,100,1,ARL,367868161
2150,2025-07-17T16:36:25.985864517Z,2025-07-17T16:36:25.985698920Z,10,2,1108,C,A,-1,13.85,2,0,165597,305274495,13.11,100,1,12.99,2,1,12.98,200,2,12.86,100,1,12.73,100,1,12.71,100,1,12.5,700,1,12.46,100,1,12.43,700,1,12.42,700,1,13.39,15,1,13.41,15,1,13.42,100,1,13.43,100,1,13.69,100,1,13.95,100,1,14.02,100,1,14.16,700,1,14.21,100,1,14.22,100,1,ARL,367868161
2151,2025-07-17T16:36:25.985864517Z,2025-07-17T16:36:25.985698920Z,10,2,1108,A,A,5,13.77,2,130,165597,305274495,13.11,100,1,12.99,2,1,12.98,200,2,12.86,100,1,12.73,100,1,12.71,100,1,12.5,700,1,12.46,100,1,12.43,700,1,12.42,700,1,13.39,15,1,13.41,15,1,13.42,100,1,13.43,100,1,13.69,100,1,13.77,2,1,13.95,100,1,14.02,100,1,14.16,700,1,14.21,100,1,ARL,368018937
2152,2025-07-17T16:37:00.790007451Z,2025-07-17T16:37:00.789841841Z,10,2,1108,C,A,-1,13.77,2,0,165610,305798904,13.11,100,1,12.99,2,1,12.98,200,2,12.86,100,1,12.73,100,1,12.71,100,1,12.5,700,1,12.46,100,1,12.43,700,1,12.42,700,1,13.39,15,1,13.41,15,1,13.42,100,1,13.43,100,1,13.69,100,1,13.95,100,1,14.02,100,1,14.16,700,1,14.21,100,1,14.22,100,1,ARL,368018937
2153,2025-07-17T16:37:00.790007451Z,2025-07-17T16:37:00.789841841Z,10,2,1108,A,A,5,13.7,2,130,165610,305798904,13.11,100,1,12.99,2,1,12.98,200,2,12.86,100,1,12.73,100,1,12.71,100,1,12.5,700,1,12.46,100,1,12.43,700,1,12.42,700,1,13.39,15,1,13.41,15,1,13.42,100,1,13.43,100,1,13.69,100,1,13.7,2,1,13.95,100,1,14.02,100,1,14.16,700,1,14.21,100,1,ARL,368710393
2154,2025-07-17T16:37:37.386246890Z,2025-07-17T16:37:37.386081296Z,10,2,1108,C,B,-1,12.99,2,0,165594,306324624,13.11,100,1,12.98,200,2,12.86,100,1,12.73,100,1,12.71,100,1,12.5,700,1,12.46,100,1,12.43,700,1,12.42,700,1,12.37,700,1,13.39,15,1,13.41,15,1,13.42,100,1,13.43,100,1,13.69,100,1,13.7,2,1,13.95,100,1,14.02,100,1,14.16,700,1,14.21,100,1,ARL,367731761
2155,2025-07-17T16:37:37.386246890Z,2025-07-17T16:37:37.386081296Z,10,2,1108,A,B,2,12.91,2,130,165594,306324624,13.11,100,1,12.98,200,2,12.91,2,1,12.86,100,1,12.73,100,1,12.71,100,1,12.5,700,1,12.46,100,1,12.43,700,1,12.42,700,1,13.39,15,1,13.41,15,1,13.42,100,1,13.43,100,1,13.69,100,1,13.7,2,1,13.95,100,1,14.02,100,1,14.16,700,1,14.21,100,1,ARL,369392197
2156,2025-07-17T16:38:28.877605130Z,2025-07-17T16:38:28.877439870Z,10,2,1108,C,A,-1,13.42,100,130,165260,307157610,13.11,100,1,12.98,200,2,12.91,2,1,12.86,100,1,12.73,100,1,12.71,100,1,12.5,700,1,12.46,100,1,12.43,700,1,12.42,700,1,13.39,15,1,13.41,15,1,13.43,100,1,13.69,100,1,13.7,2,1,13.95,100,1,14.02,100,1,14.16,700,1,14.21,100,1,14.22,100,1,ARL,367721465
2157,2025-07-17T16:38:28.883758401Z,2025-07-17T16:38:28.883590127Z,10,2,1108,C,A,-1,13.39,15,130,168274,307158368,13.11,100,1,12.98,200,2,12.91,2,1,12.86,100,1,12.73,100,1,12.71,100,1,12.5,700,1,12.46,100,1,12.43,700,1,12.42,700,1,13.41,15,1,13.43,100,1,13.69,100,1,13.7,2,1,13.95,100,1,14.02,100,1,14.16,700,1,14.21,100,1,14.22,100,1,14.35,200,2,ARL,365868793
2158,2025-07-17T16:38:28.883887122Z,2025-07-17T16:38:28.883720539Z,10,2,1108,C,A,-1,13.41,15,130,166583,307158422,13.11,100,1,12.98,200,2,12.91,2,1,12.86,100,1,12.73,100,1,12.71,100,1,12.5,700,1,12.46,100,1,12.43,700,1,12.42,700,1,13.43,100,1,13.69,100,1,13.7,2,1,13.95,100,1,14.02,100,1,14.16,700,1,14.21,100,1,14.22,100,1,14.35,200,2,14.36,200,2,ARL,365283485
2159,2025-07-17T16:38:28.883934720Z,2025-07-17T16:38:28.883766503Z,10,2,1108,C,A,-1,13.43,100,128,168217,307158437,13.11,100,1,12.98,200,2,12.91,2,1,12.86,100,1,12.73,100,1,12.71,100,1,12.5,700,1,12.46,100,1,12.43,700,1,12.42,700,1,13.69,100,1,13.7,2,1,13.95,100,1,14.02,100,1,14.16,700,1,14.21,100,1,14.22,100,1,14.35,200,2,14.36,200,2,14.46,100,1,ARL,367725181
2160,2025-07-17T16:38:28.884686671Z,2025-07-17T16:38:28.884518373Z,10,2,1108,C,A,-1,14.02,100,128,168298,307158750,13.11,100,1,12.98,200,2,12.91,2,1,12.86,100,1,12.73,100,1,12.71,100,1,12.5,700,1,12.46,100,1,12.43,700,1,12.42,700,1,13.69,100,1,13.7,2,1,13.95,100,1,14.16,700,1,14.21,100,1,14.22,100,1,14.35,200,2,14.36,200,2,14.46,100,1,14.48,1400,2,ARL,367721521
2161,2025-07-17T16:38:28.884970150Z,2025-07-17T16:38:28.884800337Z,10,2,1108,C,A,-1,14.46,100,0,169813,307158964,13.11,100,1,12.98,200,2,12.91,2,1,12.86,100,1,12.73,100,1,12.71,100,1,12.5,700,1,12.46,100,1,12.43,700,1,12.42,700,1,13.69,100,1,13.7,2,1,13.95,100,1,14.16,700,1,14.21,100,1,14.22,100,1,14.35,200,2,14.36,200,2,14.48,1400,2,14.54,700,1,ARL,367721513
2162,2025-07-17T16:38:28.885052688Z,2025-07-17T16:38:28.884882340Z,10,2,1108,A,A,6,14.3,100,128,170348,307159022,13.11,100,1,12.98,200,2,12.91,2,1,12.86,100,1,12.73,100,1,12.71,100,1,12.5,700,1,12.46,100,1,12.43,700,1,12.42,700,1,13.69,100,1,13.7,2,1,13.95,100,1,14.16,700,1,14.21,100,1,14.22,100,1,14.3,100,1,14.35,200,2,14.36,200,2,14.48,1400,2,ARL,370437229
2163,2025-07-17T16:38:28.885228455Z,2025-07-17T16:38:28.885058824Z,10,2,1108,C,A,-1,14.16,700,128,169631,307159152,13.11,100,1,12.98,200,2,12.91,2,1,12.86,100,1,12.73,100,1,12.71,100,1,12.5,700,1,12.46,100,1,12.43,700,1,12.42,700,1,13.69,100,1,13.7,2,1,13.95,100,1,14.21,100,1,14.22,100,1,14.3,100,1,14.35,200,2,14.36,200,2,14.48,1400,2,14.54,700,1,ARL,367862613
2164,2025-07-17T16:38:28.885283551Z,2025-07-17T16:38:28.885115892Z,10,2,1108,A,A,8,14.38,700,128,167659,307159202,13.11,100,1,12.98,200,2,12.91,2,1,12.86,100,1,12.73,100,1,12.71,100,1,12.5,700,1,12.46,100,1,12.43,700,1,12.42,700,1,13.69,100,1,13.7,2,1,13.95,100,1,14.21,100,1,14.22,100,1,14.3,100,1,14.35,200,2,14.36,200,2,14.38,700,1,14.48,1400,2,ARL,370437313
2165,2025-07-17T16:38:28.887253724Z,2025-07-17T16:38:28.887087949Z,10,2,1108,C,A,-1,14.21,100,0,165775,307160536,13.11,100,1,12.98,200,2,12.91,2,1,12.86,100,1,12.73,100,1,12.71,100,1,12.5,700,1,12.46,100,1,12.43,700,1,12.42,700,1,13.69,100,1,13.7,2,1,13.95,100,1,14.22,100,1,14.3,100,1,14.35,200,2,14.36,200,2,14.38,700,1,14.48,1400,2,14.54,700,1,ARL,367724841
2166,2025-07-17T16:38:28.887253724Z,2025-07-17T16:38:28.887087949Z,10,2,1108,A,A,8,14.48,100,130,165775,307160536,13.11,100,1,12.98,200,2,12.91,2,1,12.86,100,1,12.73,100,1,12.71,100,1,12.5,700,1,12.46,100,1,12.43,700,1,12.42,700,1,13.69,100,1,13.7,2,1,13.95,100,1,14.22,100,1,14.3,100,1,14.35,200,2,14.36,200,2,14.38,700,1,14.48,1500,3,14.54,700,1,ARL,370438201
2167,2025-07-17T16:38:28.890349366Z,2025-07-17T16:38:28.890183678Z,10,2,1108,C,A,-1,13.69,100,130,165688,307160811,13.11,100,1,12.98,200,2,12.91,2,1,12.86,100,1,12.73,100,1,12.71,100,1,12.5,700,1,12.46,100,1,12.43,700,1,12.42,700,1,13.7,2,1,13.95,100,1,14.22,100,1,14.3,100,1,14.35,200,2,14.36,200,2,14.38,700,1,14.48,1500,3,14.54,700,1,14.75,100,1,ARL,367721969
2168,2025-07-17T16:38:28.890403384Z,2025-07-17T16:38:28.890238112Z,10,2,1108,A,A,2,13.96,100,130,165272,307160812,13.11,100,1,12.98,200,2,12.91,2,1,12.86,100,1,12.73,100,1,12.71,100,1,12.5,700,1,12.46,100,1,12.43,700,1,12.42,700,1,13.7,2,1,13.95,100,1,13.96,100,1,14.22,100,1,14.3,100,1,14.35,200,2,14.36,200,2,14.38,700,1,14.48,1500,3,14.54,700,1,ARL,370438445
2169,2025-07-17T16:38:28.890944566Z,2025-07-17T16:38:28.890779005Z,10,2,1108,C,A,6,14.36,100,0,165561,307160837,13.11,100,1,12.98,200,2,12.91,2,1,12.86,100,1,12.73,100,1,12.71,100,1,12.5,700,1,12.46,100,1,12.43,700,1,12.42,700,1,13.7,2,1,13.95,100,1,13.96,100,1,14.22,100,1,14.3,100,1,14.35,200,2,14.36,100,1,14.38,700,1,14.48,1500,3,14.54,700,1,ARL,367721617
2170,2025-07-17T16:38:28.891575770Z,2025-07-17T16:38:28.891410504Z,10,2,1108,C,A,-1,14.38,700,130,165266,307160861,13.11,100,1,12.98,200,2,12.91,2,1,12.86,100,1,12.73,100,1,12.71,100,1,12.5,700,1,12.46,100,1,12.43,700,1,12.42,700,1,13.7,2,1,13.95,100,1,13.96,100,1,14.22,100,1,14.3,100,1,14.35,200,2,14.36,100,1,14.48,1500,3,14.54,700,1,14.65,100,1,ARL,370437313
2171,2025-07-17T16:38:28.897123213Z,2025-07-17T16:38:28.896958047Z,10,2,1108,C,A,-1,14.65,100,0,165166,307161432,13.11,100,1,12.98,200,2,12.91,2,1,12.86,100,1,12.73,100,1,12.71,100,1,12.5,700,1,12.46,100,1,12.43,700,1,12.42,700,1,13.7,2,1,13.95,100,1,13.96,100,1,14.22,100,1,14.3,100,1,14.35,200,2,14.36,100,1,14.48,1500,3,14.54,700,1,14.75,100,1,ARL,370438481
2172,2025-07-17T16:38:28.897838481Z,2025-07-17T16:38:28.897673510Z,10,2,1108,C,A,-1,13.96,100,130,164971,307161526,13.11,100,1,12.98,200,2,12.91,2,1,12.86,100,1,12.73,100,1,12.71,100,1,12.5,700,1,12.46,100,1,12.43,700,1,12.42,700,1,13.7,2,1,13.95,100,1,14.22,100,1,14.3,100,1,14.35,200,2,14.36,100,1,14.48,1500,3,14.54,700,1,14.75,100,1,14.77,100,1,ARL,370438445
2173,2025-07-17T16:38:28.897891864Z,2025-07-17T16:38:28.897725631Z,10,2,1108,A,A,2,14.19,100,130,166233,307161541,13.11,100,1,12.98,200,2,12.91,2,1,12.86,100,1,12.73,100,1,12.71,100,1,12.5,700,1,12.46,100,1,12.43,700,1,12.42,700,1,13.7,2,1,13.95,100,1,14.19,100,1,14.22,100,1,14.3,100,1,14.35,200,2,14.36,100,1,14.48,1500,3,14.54,700,1,14.75,100,1,ARL,370439549
2174,2025-07-17T16:38:28.898754842Z,2025-07-17T16:38:28.898589292Z,10,2,1108,C,A,-1,13.7,2,0,165550,307161601,13.11,100,1,12.98,200,2,12.91,2,1,12.86,100,1,12.73,100,1,12.71,100,1,12.5,700,1,12.46,100,1,12.43,700,1,12.42,700,1,13.95,100,1,14.19,100,1,14.22,100,1,14.3,100,1,14.35,200,2,14.36,100,1,14.48,1500,3,14.54,700,1,14.75,100,1,14.77,100,1,ARL,368710393
2175,2025-07-17T16:38:28.898754842Z,2025-07-17T16:38:28.898589292Z,10,2,1108,A,A,0,13.95,2,130,165550,307161601,13.11,100,1,12.98,200,2,12.91,2,1,12.86,100,1,12.73,100,1,12.71,100,1,12.5,700,1,12.46,100,1,12.43,700,1,12.42,700,1,13.95,102,2,14.19,100,1,14.22,100,1,14.3,100,1,14.35,200,2,14.36,100,1,14.48,1500,3,14.54,700,1,14.75,100,1,14.77,100,1,ARL,370439617
2176,2025-07-17T16:38:28.918317468Z,2025-07-17T16:38:28.918152257Z,10,2,1108,A,A,1,13.96,100,130,165211,307162629,13.11,100,1,12.98,200,2,12.91,2,1,12.86,100,1,12.73,100,1,12.71,100,1,12.5,700,1,12.46,100,1,12.43,700,1,12.42,700,1,13.95,102,2,13.96,100,1,14.19,100,1,14.22,100,1,14.3,100,1,14.35,200,2,14.36,100,1,14.48,1500,3,14.54,700,1,14.75,100,1,ARL,370441181
2177,2025-07-17T16:38:28.936136896Z,2025-07-17T16:38:28.935971160Z,10,2,1108,C,A,-1,14.75,100,0,165736,307163278,13.11,100,1,12.98,200,2,12.91,2,1,12.86,100,1,12.73,100,1,12.71,100,1,12.5,700,1,12.46,100,1,12.43,700,1,12.42,700,1,13.95,102,2,13.96,100,1,14.19,100,1,14.22,100,1,14.3,100,1,14.35,200,2,14.36,100,1,14.48,1500,3,14.54,700,1,14.93,100,1,ARL,370437189
2178,2025-07-17T16:38:28.952681986Z,2025-07-17T16:38:28.952516142Z,10,2,1108,C,A,-1,14.36,100,0,165844,307163820,13.11,100,1,12.98,200,2,12.91,2,1,12.86,100,1,12.73,100,1,12.71,100,1,12.5,700,1,12.46,100,1,12.43,700,1,12.42,700,1,13.95,102,2,13.96,100,1,14.19,100,1,14.22,100,1,14.3,100,1,14.35,200,2,14.48,1500,3,14.54,700,1,14.93,100,1,15.03,100,1,ARL,367722697
2179,2025-07-17T16:38:28.952681986Z,2025-07-17T16:38:28.952516142Z,10,2,1108,A,A,8,14.93,100,130,165844,307163820,13.11,100,1,12.98,200,2,12.91,2,1,12.86,100,1,12.73,100,1,12.71,100,1,12.5,700,1,12.46,100,1,12.43,700,1,12.42,700,1,13.95,102,2,13.96,100,1,14.19,100,1,14.22,100,1,14.3,100,1,14.35,200,2,14.48,1500,3,14.54,700,1,14.93,200,2,15.03,100,1,ARL,370442725
2180,2025-07-17T16:38:29.032769021Z,2025-07-17T16:38:29.032603839Z,10,2,1108,A,A,8,14.65,700,130,165182,307165797,13.11,100,1,12.98,200,2,12.91,2,1,12.86,100,1,12.73,100,1,12.71,100,1,12.5,700,1,12.46,100,1,12.43,700,1,12.42,700,1,13.95,102,2,13.96,100,1,14.19,100,1,14.22,100,1,14.3,100,1,14.35,200,2,14.48,1500,3,14.54,700,1,14.65,700,1,14.93,200,2,ARL,370445145
2181,2025-07-17T16:38:29.148813737Z,2025-07-17T16:38:29.148648535Z,10,2,1108,A,A,9,14.78,100,130,165202,307167133,13.11,100,1,12.98,200,2,12.91,2,1,12.86,100,1,12.73,100,1,12.71,100,1,12.5,700,1,12.46,100,1,12.43,700,1,12.42,700,1,13.95,102,2,13.96,100,1,14.19,100,1,14.22,100,1,14.3,100,1,14.35,200,2,14.48,1500,3,14.54,700,1,14.65,700,1,14.78,100,1,ARL,370447077
2182,2025-07-17T16:38:29.148834353Z,2025-07-17T16:38:29.148668992Z,10,2,1108,C,A,-1,14.22,100,130,165361,307167134,13.11,100,1,12.98,200,2,12.91,2,1,12.86,100,1,12.73,100,1,12.71,100,1,12.5,700,1,12.46,100,1,12.43,700,1,12.42,700,1,13.95,102,2,13.96,100,1,14.19,100,1,14.3,100,1,14.35,200,2,14.48,1500,3,14.54,700,1,14.65,700,1,14.78,100,1,14.93,200,2,ARL,367724041
2183,2025-07-17T16:38:29.426836238Z,2025-07-17T16:38:29.426670903Z,10,2,1108,C,A,-1,14.3,100,130,165335,307173923,13.11,100,1,12.98,200,2,12.91,2,1,12.86,100,1,12.73,100,1,12.71,100,1,12.5,700,1,12.46,100,1,12.43,700,1,12.42,700,1,13.95,102,2,13.96,100,1,14.19,100,1,14.35,200,2,14.48,1500,3,14.54,700,1,14.65,700,1,14.78,100,1,14.93,200,2,15.03,100,1,ARL,370437229
2184,2025-07-17T16:38:29.427188198Z,2025-07-17T16:38:29.427022633Z,10,2,1108,A,A,6,14.57,100,130,165565,307173925,13.11,100,1,12.98,200,2,12.91,2,1,12.86,100,1,12.73,100,1,12.71,100,1,12.5,700,1,12.46,100,1,12.43,700,1,12.42,700,1,13.95,102,2,13.96,100,1,14.19,100,1,14.35,200,2,14.48,1500,3,14.54,700,1,14.57,100,1,14.65,700,1,14.78,100,1,14.93,200,2,ARL,370453877
2185,2025-07-17T16:38:29.676879357Z,2025-07-17T16:38:29.676713920Z,10,2,1108,C,A,0,13.95,100,130,165437,307176261,13.11,100,1,12.98,200,2,12.91,2,1,12.86,100,1,12.73,100,1,12.71,100,1,12.5,700,1,12.46,100,1,12.43,700,1,12.42,700,1,13.95,2,1,13.96,100,1,14.19,100,1,14.35,200,2,14.48,1500,3,14.54,700,1,14.57,100,1,14.65,700,1,14.78,100,1,14.93,200,2,ARL,367724713
2186,2025-07-17T16:38:29.676880707Z,2025-07-17T16:38:29.676715468Z,10,2,1108,A,A,5,14.5,100,130,165239,307176262,13.11,100,1,12.98,200,2,12.91,2,1,12.86,100,1,12.73,100,1,12.71,100,1,12.5,700,1,12.46,100,1,12.43,700,1,12.42,700,1,13.95,2,1,13.96,100,1,14.19,100,1,14.35,200,2,14.48,1500,3,14.5,100,1,14.54,700,1,14.57,100,1,14.65,700,1,14.78,100,1,ARL,370456865
2187,2025-07-17T16:38:29.885303008Z,2025-07-17T16:38:29.885137793Z,10,2,1108,A,A,0,13.45,15,130,165215,307178053,13.11,100,1,12.98,200,2,12.91,2,1,12.86,100,1,12.73,100,1,12.71,100,1,12.5,700,1,12.46,100,1,12.43,700,1,12.42,700,1,13.45,15,1,13.95,2,1,13.96,100,1,14.19,100,1,14.35,200,2,14.48,1500,3,14.5,100,1,14.54,700,1,14.57,100,1,14.65,700,1,ARL,370459453
2188,2025-07-17T16:38:29.888483332Z,2025-07-17T16:38:29.888318043Z,10,2,1108,C,A,5,14.48,100,130,165289,307178079,13.11,100,1,12.98,200,2,12.91,2,1,12.86,100,1,12.73,100,1,12.71,100,1,12.5,700,1,12.46,100,1,12.43,700,1,12.42,700,1,13.45,15,1,13.95,2,1,13.96,100,1,14.19,100,1,14.35,200,2,14.48,1400,2,14.5,100,1,14.54,700,1,14.57,100,1,14.65,700,1,ARL,370438201
2189,2025-07-17T16:38:29.941014789Z,2025-07-17T16:38:29.940849318Z,10,2,1108,C,A,-1,13.96,100,0,165471,307179401,13.11,100,1,12.98,200,2,12.91,2,1,12.86,100,1,12.73,100,1,12.71,100,1,12.5,700,1,12.46,100,1,12.43,700,1,12.42,700,1,13.45,15,1,13.95,2,1,14.19,100,1,14.35,200,2,14.48,1400,2,14.5,100,1,14.54,700,1,14.57,100,1,14.65,700,1,14.75,100,1,ARL,370441181
2190,2025-07-17T16:38:29.941014789Z,2025-07-17T16:38:29.940849318Z,10,2,1108,A,A,1,13.46,100,130,165471,307179401,13.11,100,1,12.98,200,2,12.91,2,1,12.86,100,1,12.73,100,1,12.71,100,1,12.5,700,1,12.46,100,1,12.43,700,1,12.42,700,1,13.45,15,1,13.46,100,1,13.95,2,1,14.19,100,1,14.35,200,2,14.48,1400,2,14.5,100,1,14.54,700,1,14.57,100,1,14.65,700,1,ARL,370461533
2191,2025-07-17T16:38:29.941750054Z,2025-07-17T16:38:29.941583872Z,10,2,1108,A,A,6,14.5,100,0,166182,307179436,13.11,100,1,12.98,200,2,12.91,2,1,12.86,100,1,12.73,100,1,12.71,100,1,12.5,700,1,12.46,100,1,12.43,700,1,12.42,700,1,13.45,15,1,13.46,100,1,13.95,2,1,14.19,100,1,14.35,200,2,14.48,1400,2,14.5,200,2,14.54,700,1,14.57,100,1,14.65,700,1,ARL,370461549
2192,2025-07-17T16:38:29.941750054Z,2025-07-17T16:38:29.941584913Z,10,2,1108,C,A,-1,14.57,100,130,165141,307179437,13.11,100,1,12.98,200,2,12.91,2,1,12.86,100,1,12.73,100,1,12.71,100,1,12.5,700,1,12.46,100,1,12.43,700,1,12.42,700,1,13.45,15,1,13.46,100,1,13.95,2,1,14.19,100,1,14.35,200,2,14.48,1400,2,14.5,200,2,14.54,700,1,14.65,700,1,14.75,100,1,ARL,370453877
2193,2025-07-17T16:38:29.942103994Z,2025-07-17T16:38:29.941938640Z,10,2,1108,A,A,3,14.06,100,130,165354,307179451,13.11,100,1,12.98,200,2,12.91,2,1,12.86,100,1,12.73,100,1,12.71,100,1,12.5,700,1,12.46,100,1,12.43,700,1,12.42,700,1,13.45,15,1,13.46,100,1,13.95,2,1,14.06,100,1,14.19,100,1,14.35,200,2,14.48,1400,2,14.5,200,2,14.54,700,1,14.65,700,1,ARL,370461553
2194,2025-07-17T16:38:29.942499783Z,2025-07-17T16:38:29.942334155Z,10,2,1108,A,A,6,14.41,100,130,165628,307179459,13.11,100,1,12.98,200,2,12.91,2,1,12.86,100,1,12.73,100,1,12.71,100,1,12.5,700,1,12.46,100,1,12.43,700,1,12.42,700,1,13.45,15,1,13.46,100,1,13.95,2,1,14.06,100,1,14.19,100,1,14.35,200,2,14.41,100,1,14.48,1400,2,14.5,200,2,14.54,700,1,ARL,370461565
2195,2025-07-17T16:38:29.947455917Z,2025-07-17T16:38:29.947290480Z,10,2,1108,C,A,-1,13.95,2,0,165437,307179507,13.11,100,1,12.98,200,2,12.91,2,1,12.86,100,1,12.73,100,1,12.71,100,1,12.5,700,1,12.46,100,1,12.43,700,1,12.42,700,1,13.45,15,1,13.46,100,1,14.06,100,1,14.19,100,1,14.35,200,2,14.41,100,1,14.48,1400,2,14.5,200,2,14.54,700,1,14.65,700,1,ARL,370439617
2196,2025-07-17T16:38:29.947455917Z,2025-07-17T16:38:29.947290480Z,10,2,1108,A,A,2,13.67,2,130,165437,307179507,13.11,100,1,12.98,200,2,12.91,2,1,12.86,100,1,12.73,100,1,12.71,100,1,12.5,700,1,12.46,100,1,12.43,700,1,12.42,700,1,13.45,15,1,13.46,100,1,13.67,2,1,14.06,100,1,14.19,100,1,14.35,200,2,14.41,100,1,14.48,1400,2,14.5,200,2,14.54,700,1,ARL,370461621
2197,2025-07-17T16:38:29.948127549Z,2025-07-17T16:38:29.947962321Z,10,2,1108,C,A,-1,14.19,100,130,165228,307179509,13.11,100,1,12.98,200,2,12.91,2,1,12.86,100,1,12.73,100,1,12.71,100,1,12.5,700,1,12.46,100,1,12.43,700,1,12.42,700,1,13.45,15,1,13.46,100,1,13.67,2,1,14.06,100,1,14.35,200,2,14.41,100,1,14.48,1400,2,14.5,200,2,14.54,700,1,14.65,700,1,ARL,370439549
2198,2025-07-17T16:38:29.948180463Z,2025-07-17T16:38:29.948015176Z,10,2,1108,A,A,3,13.73,100,130,165287,307179510,13.11,100,1,12.98,200,2,12.91,2,1,12.86,100,1,12.73,100,1,12.71,100,1,12.5,700,1,12.46,100,1,12.43,700,1,12.42,700,1,13.45,15,1,13.46,100,1,13.67,2,1,13.73,100,1,14.06,100,1,14.35,200,2,14.41,100,1,14.48,1400,2,14.5,200,2,14.54,700,1,ARL,370461625
2199,2025-07-17T16:38:29.970846281Z,2025-07-17T16:38:29.970680913Z,10,2,1108,A,A,6,14.41,100,130,165368,307179786,13.11,100,1,12.98,200,2,12.91,2,1,12.86,100,1,12.73,100,1,12.71,100,1,12.5,700,1,12.46,100,1,12.43,700,1,12.42,700,1,13.45,15,1,13.46,100,1,13.67,2,1,13.73,100,1,14.06,100,1,14.35,200,2,14.41,200,2,14.48,1400,2,14.5,200,2,14.54,700,1,ARL,370461885
2200,2025-07-17T16:38:30.253787558Z,2025-07-17T16:38:30.253622210Z,10,2,1108,A,A,5,14.26,100,130,165348,307185663,13.11,100,1,12.98,200,2,12.91,2,1,12.86,100,1,12.73,100,1,12.71,100,1,12.5,700,1,12.46,100,1,12.43,700,1,12.42,700,1,13.45,15,1,13.46,100,1,13.67,2,1,13.73,100,1,14.06,100,1,14.26,100,1,14.35,200,2,14.41,200,2,14.48,1400,2,14.5,200,2,ARL,370467237
2201,2025-07-17T16:38:30.904150735Z,2025-07-17T16:38:30.903985079Z,10,2,1108,A,A,5,14.25,100,130,165656,307190980,13.11,100,1,12.98,200,2,12.91,2,1,12.86,100,1,12.73,100,1,12.71,100,1,12.5,700,1,12.46,100,1,12.43,700,1,12.42,700,1,13.45,15,1,13.46,100,1,13.67,2,1,13.73,100,1,14.06,100,1,14.25,100,1,14.26,100,1,14.35,200,2,14.41,200,2,14.48,1400,2,ARL,370476497
2202,2025-07-17T16:38:31.559865365Z,2025-07-17T16:38:31.559700071Z,10,2,1108,A,A,4,13.99,100,130,165294,307199961,13.11,100,1,12.98,200,2,12.91,2,1,12.86,100,1,12.73,100,1,12.71,100,1,12.5,700,1,12.46,100,1,12.43,700,1,12.42,700,1,13.45,15,1,13.46,100,1,13.67,2,1,13.73,100,1,13.99,100,1,14.06,100,1,14.25,100,1,14.26,100,1,14.35,200,2,14.41,200,2,ARL,370489233
2203,2025-07-17T16:38:38.032884239Z,2025-07-17T16:38:38.032718859Z,10,2,1108,A,A,6,14.18,700,130,165380,307265517,13.11,100,1,12.98,200,2,12.91,2,1,12.86,100,1,12.73,100,1,12.71,100,1,12.5,700,1,12.46,100,1,12.43,700,1,12.42,700,1,13.45,15,1,13.46,100,1,13.67,2,1,13.73,100,1,13.99,100,1,14.06,100,1,14.18,700,1,14.25,100,1,14.26,100,1,14.35,200,2,ARL,370582469
2204,2025-07-17T16:38:40.071053065Z,2025-07-17T16:38:40.070887680Z,10,2,1108,C,A,-1,13.46,100,130,165385,307283804,13.11,100,1,12.98,200,2,12.91,2,1,12.86,100,1,12.73,100,1,12.71,100,1,12.5,700,1,12.46,100,1,12.43,700,1,12.42,700,1,13.45,15,1,13.67,2,1,13.73,100,1,13.99,100,1,14.06,100,1,14.18,700,1,14.25,100,1,14.26,100,1,14.35,200,2,14.41,200,2,ARL,370461533
2205,2025-07-17T16:38:40.071319071Z,2025-07-17T16:38:40.071154064Z,10,2,1108,C,A,-1,14.18,700,130,165007,307283810,13.11,100,1,12.98,200,2,12.91,2,1,12.86,100,1,12.73,100,1,12.71,100,1,12.5,700,1,12.46,100,1,12.43,700,1,12.42,700,1,13.45,15,1,13.67,2,1,13.73,100,1,13.99,100,1,14.06,100,1,14.25,100,1,14.26,100,1,14.35,200,2,14.41,200,2,14.48,1400,2,ARL,370582469
2206,2025-07-17T16:38:40.071364017Z,2025-07-17T16:38:40.071198819Z,10,2,1108,A,A,9,14.42,700,130,165198,307283812,13.11,100,1,12.98,200,2,12.91,2,1,12.86,100,1,12.73,100,1,12.71,100,1,12.5,700,1,12.46,100,1,12.43,700,1,12.42,700,1,13.45,15,1,13.67,2,1,13.73,100,1,13.99,100,1,14.06,100,1,14.25,100,1,14.26,100,1,14.35,200,2,14.41,200,2,14.42,700,1,ARL,370605993
2207,2025-07-17T16:38:40.071419817Z,2025-07-17T16:38:40.071254343Z,10,2,1108,A,A,0,13.43,15,130,165474,307283813,13.11,100,1,12.98,200,2,12.91,2,1,12.86,100,1,12.73,100,1,12.71,100,1,12.5,700,1,12.46,100,1,12.43,700,1,12.42,700,1,13.43,15,1,13.45,15,1,13.67,2,1,13.73,100,1,13.99,100,1,14.06,100,1,14.25,100,1,14.26,100,1,14.35,200,2,14.41,200,2,ARL,370606001
2208,2025-07-17T16:38:40.071794956Z,2025-07-17T16:38:40.071629854Z,10,2,1108,C,A,-1,14.06,100,130,165102,307283822,13.11,100,1,12.98,200,2,12.91,2,1,12.86,100,1,12.73,100,1,12.71,100,1,12.5,700,1,12.46,100,1,12.43,700,1,12.42,700,1,13.43,15,1,13.45,15,1,13.67,2,1,13.73,100,1,13.99,100,1,14.25,100,1,14.26,100,1,14.35,200,2,14.41,200,2,14.42,700,1,ARL,370461553
2209,2025-07-17T16:38:40.072139081Z,2025-07-17T16:38:40.071973553Z,10,2,1108,C,A,8,14.41,100,0,165528,307283824,13.11,100,1,12.98,200,2,12.91,2,1,12.86,100,1,12.73,100,1,12.71,100,1,12.5,700,1,12.46,100,1,12.43,700,1,12.42,700,1,13.43,15,1,13.45,15,1,13.67,2,1,13.73,100,1,13.99,100,1,14.25,100,1,14.26,100,1,14.35,200,2,14.41,100,1,14.42,700,1,ARL,370461565
2210,2025-07-17T16:38:40.072156795Z,2025-07-17T16:38:40.071991669Z,10,2,1108,A,A,7,14.34,100,130,165126,307283825,13.11,100,1,12.98,200,2,12.91,2,1,12.86,100,1,12.73,100,1,12.71,100,1,12.5,700,1,12.46,100,1,12.43,700,1,12.42,700,1,13.43,15,1,13.45,15,1,13.67,2,1,13.73,100,1,13.99,100,1,14.25,100,1,14.26,100,1,14.34,100,1,14.35,200,2,14.41,100,1,ARL,370606029
2211,2025-07-17T16:38:40.075044980Z,2025-07-17T16:38:40.074879393Z,10,2,1108,C,A,-1,14.25,100,130,165587,307283845,13.11,100,1,12.98,200,2,12.91,2,1,12.86,100,1,12.73,100,1,12.71,100,1,12.5,700,1,12.46,100,1,12.43,700,1,12.42,700,1,13.43,15,1,13.45,15,1,13.67,2,1,13.73,100,1,13.99,100,1,14.26,100,1,14.34,100,1,14.35,200,2,14.41,100,1,14.42,700,1,ARL,370476497
2212,2025-07-17T16:38:40.083988648Z,2025-07-17T16:38:40.083823366Z,10,2,1108,C,A,-1,13.73,100,130,165282,307283911,13.11,100,1,12.98,200,2,12.91,2,1,12.86,100,1,12.73,100,1,12.71,100,1,12.5,700,1,12.46,100,1,12.43,700,1,12.42,700,1,13.43,15,1,13.45,15,1,13.67,2,1,13.99,100,1,14.26,100,1,14.34,100,1,14.35,200,2,14.41,100,1,14.42,700,1,14.48,1400,2,ARL,370461625
2213,2025-07-17T16:38:40.084019246Z,2025-07-17T16:38:40.083854409Z,10,2,1108,C,A,-1,14.42,700,130,164837,307283912,13.11,100,1,12.98,200,2,12.91,2,1,12.86,100,1,12.73,100,1,12.71,100,1,12.5,700,1,12.46,100,1,12.43,700,1,12.42,700,1,13.43,15,1,13.45,15,1,13.67,2,1,13.99,100,1,14.26,100,1,14.34,100,1,14.35,200,2,14.41,100,1,14.48,1400,2,14.52,100,1,ARL,370605993
2214,2025-07-17T16:38:40.084042962Z,2025-07-17T16:38:40.083877729Z,10,2,1108,A,A,4,14,100,130,165233,307283913,13.11,100,1,12.98,200,2,12.91,2,1,12.86,100,1,12.73,100,1,12.71,100,1,12.5,700,1,12.46,100,1,12.43,700,1,12.42,700,1,13.43,15,1,13.45,15,1,13.67,2,1,13.99,100,1,14,100,1,14.26,100,1,14.34,100,1,14.35,200,2,14.41,100,1,14.48,1400,2,ARL,370606301
2215,2025-07-17T16:38:40.084983393Z,2025-07-17T16:38:40.084817954Z,10,2,1108,C,A,-1,13.67,2,0,165439,307283919,13.11,100,1,12.98,200,2,12.91,2,1,12.86,100,1,12.73,100,1,12.71,100,1,12.5,700,1,12.46,100,1,12.43,700,1,12.42,700,1,13.43,15,1,13.45,15,1,13.99,100,1,14,100,1,14.26,100,1,14.34,100,1,14.35,200,2,14.41,100,1,14.48,1400,2,14.52,100,1,ARL,370461621
2216,2025-07-17T16:38:40.084983393Z,2025-07-17T16:38:40.084817954Z,10,2,1108,A,A,2,13.95,2,130,165439,307283919,13.11,100,1,12.98,200,2,12.91,2,1,12.86,100,1,12.73,100,1,12.71,100,1,12.5,700,1,12.46,100,1,12.43,700,1,12.42,700,1,13.43,15,1,13.45,15,1,13.95,2,1,13.99,100,1,14,100,1,14.26,100,1,14.34,100,1,14.35,200,2,14.41,100,1,14.48,1400,2,ARL,370606329
2217,2025-07-17T16:38:40.091476523Z,2025-07-17T16:38:40.091311137Z,10,2,1108,C,A,-1,14.41,100,0,165386,307283939,13.11,100,1,12.98,200,2,12.91,2,1,12.86,100,1,12.73,100,1,12.71,100,1,12.5,700,1,12.46,100,1,12.43,700,1,12.42,700,1,13.43,15,1,13.45,15,1,13.95,2,1,13.99,100,1,14,100,1,14.26,100,1,14.34,100,1,14.35,200,2,14.48,1400,2,14.52,100,1,ARL,370461885
2218,2025-07-17T16:38:40.104056045Z,2025-07-17T16:38:40.103890619Z,10,2,1108,C,A,-1,14,100,130,165426,307283993,13.11,100,1,12.98,200,2,12.91,2,1,12.86,100,1,12.73,100,1,12.71,100,1,12.5,700,1,12.46,100,1,12.43,700,1,12.42,700,1,13.43,15,1,13.45,15,1,13.95,2,1,13.99,100,1,14.26,100,1,14.34,100,1,14.35,200,2,14.48,1400,2,14.52,100,1,14.54,700,1,ARL,370606301
2219,2025-07-17T16:38:40.104103420Z,2025-07-17T16:38:40.103938254Z,10,2,1108,A,A,4,14.23,100,130,165166,307283994,13.11,100,1,12.98,200,2,12.91,2,1,12.86,100,1,12.73,100,1,12.71,100,1,12.5,700,1,12.46,100,1,12.43,700,1,12.42,700,1,13.43,15,1,13.45,15,1,13.95,2,1,13.99,100,1,14.23,100,1,14.26,100,1,14.34,100,1,14.35,200,2,14.48,1400,2,14.52,100,1,ARL,370606485
2220,2025-07-17T16:38:40.619905273Z,2025-07-17T16:38:40.619739793Z,10,2,1108,C,A,-1,14.26,100,130,165480,307292058,13.11,100,1,12.98,200,2,12.91,2,1,12.86,100,1,12.73,100,1,12.71,100,1,12.5,700,1,12.46,100,1,12.43,700,1,12.42,700,1,13.43,15,1,13.45,15,1,13.95,2,1,13.99,100,1,14.23,100,1,14.34,100,1,14.35,200,2,14.48,1400,2,14.52,100,1,14.54,700,1,ARL,370467237
2221,2025-07-17T16:38:40.679615139Z,2025-07-17T16:38:40.679449976Z,10,2,1108,C,A,-1,14.34,100,130,165163,307292662,13.11,100,1,12.98,200,2,12.91,2,1,12.86,100,1,12.73,100,1,12.71,100,1,12.5,700,1,12.46,100,1,12.43,700,1,12.42,700,1,13.43,15,1,13.45,15,1,13.95,2,1,13.99,100,1,14.23,100,1,14.35,200,2,14.48,1400,2,14.52,100,1,14.54,700,1,14.68,700,1,ARL,370606029
2222,2025-07-17T16:38:40.679963059Z,2025-07-17T16:38:40.679797676Z,10,2,1108,A,A,9,14.6,100,130,165383,307292683,13.11,100,1,12.98,200,2,12.91,2,1,12.86,100,1,12.73,100,1,12.71,100,1,12.5,700,1,12.46,100,1,12.43,700,1,12.42,700,1,13.43,15,1,13.45,15,1,13.95,2,1,13.99,100,1,14.23,100,1,14.35,200,2,14.48,1400,2,14.52,100,1,14.54,700,1,14.6,100,1,ARL,370617053
2223,2025-07-17T16:38:40.980886187Z,2025-07-17T16:38:40.980719660Z,10,2,1108,A,A,8,14.53,100,0,166527,307295303,13.11,100,1,12.98,200,2,12.91,2,1,12.86,100,1,12.73,100,1,12.71,100,1,12.5,700,1,12.46,100,1,12.43,700,1,12.42,700,1,13.43,15,1,13.45,15,1,13.95,2,1,13.99,100,1,14.23,100,1,14.35,200,2,14.48,1400,2,14.52,100,1,14.53,100,1,14.54,700,1,ARL,370619813
2224,2025-07-17T16:38:40.980886187Z,2025-07-17T16:38:40.980720043Z,10,2,1108,C,A,-1,13.99,100,130,166144,307295304,13.11,100,1,12.98,200,2,12.91,2,1,12.86,100,1,12.73,100,1,12.71,100,1,12.5,700,1,12.46,100,1,12.43,700,1,12.42,700,1,13.43,15,1,13.45,15,1,13.95,2,1,14.23,100,1,14.35,200,2,14.48,1400,2,14.52,100,1,14.53,100,1,14.54,700,1,14.6,100,1,ARL,370489233
2225,2025-07-17T16:38:41.077087344Z,2025-07-17T16:38:41.076921744Z,10,2,1108,C,A,-1,14.52,100,0,165600,307296322,13.11,100,1,12.98,200,2,12.91,2,1,12.86,100,1,12.73,100,1,12.71,100,1,12.5,700,1,12.46,100,1,12.43,700,1,12.42,700,1,13.43,15,1,13.45,15,1,13.95,2,1,14.23,100,1,14.35,200,2,14.48,1400,2,14.53,100,1,14.54,700,1,14.6,100,1,14.68,700,1,ARL,370606097
2226,2025-07-17T16:38:42.071060459Z,2025-07-17T16:38:42.070895211Z,10,2,1108,A,A,1,13.44,100,130,165248,307311258,13.11,100,1,12.98,200,2,12.91,2,1,12.86,100,1,12.73,100,1,12.71,100,1,12.5,700,1,12.46,100,1,12.43,700,1,12.42,700,1,13.43,15,1,13.44,100,1,13.45,15,1,13.95,2,1,14.23,100,1,14.35,200,2,14.48,1400,2,14.53,100,1,14.54,700,1,14.6,100,1,ARL,370638733
2227,2025-07-17T16:38:42.071797100Z,2025-07-17T16:38:42.071631589Z,10,2,1108,C,A,-1,14.6,100,130,165511,307311262,13.11,100,1,12.98,200,2,12.91,2,1,12.86,100,1,12.73,100,1,12.71,100,1,12.5,700,1,12.46,100,1,12.43,700,1,12.42,700,1,13.43,15,1,13.44,100,1,13.45,15,1,13.95,2,1,14.23,100,1,14.35,200,2,14.48,1400,2,14.53,100,1,14.54,700,1,14.68,700,1,ARL,370617053
2228,2025-07-17T16:38:42.071798952Z,2025-07-17T16:38:42.071632569Z,10,2,1108,A,A,6,14.48,100,130,166383,307311263,13.11,100,1,12.98,200,2,12.91,2,1,12.86,100,1,12.73,100,1,12.71,100,1,12.5,700,1,12.46,100,1,12.43,700,1,12.42,700,1,13.43,15,1,13.44,100,1,13.45,15,1,13.95,2,1,14.23,100,1,14.35,200,2,14.48,1500,3,14.53,100,1,14.54,700,1,14.68,700,1,ARL,370638757
2229,2025-07-17T16:38:42.072149798Z,2025-07-17T16:38:42.071984594Z,10,2,1108,A,A,4,14.04,100,130,165204,307311265,13.11,100,1,12.98,200,2,12.91,2,1,12.86,100,1,12.73,100,1,12.71,100,1,12.5,700,1,12.46,100,1,12.43,700,1,12.42,700,1,13.43,15,1,13.44,100,1,13.45,15,1,13.95,2,1,14.04,100,1,14.23,100,1,14.35,200,2,14.48,1500,3,14.53,100,1,14.54,700,1,ARL,370638761
2230,2025-07-17T16:38:42.072229987Z,2025-07-17T16:38:42.072063883Z,10,2,1108,A,A,7,14.39,100,130,166104,307311266,13.11,100,1,12.98,200,2,12.91,2,1,12.86,100,1,12.73,100,1,12.71,100,1,12.5,700,1,12.46,100,1,12.43,700,1,12.42,700,1,13.43,15,1,13.44,100,1,13.45,15,1,13.95,2,1,14.04,100,1,14.23,100,1,14.35,200,2,14.39,100,1,14.48,1500,3,14.53,100,1,ARL,370638765
2231,2025-07-17T16:38:42.074211752Z,2025-07-17T16:38:42.074046298Z,10,2,1108,C,A,-1,13.95,2,0,165454,307311292,13.11,100,1,12.98,200,2,12.91,2,1,12.86,100,1,12.73,100,1,12.71,100,1,12.5,700,1,12.46,100,1,12.43,700,1,12.42,700,1,13.43,15,1,13.44,100,1,13.45,15,1,14.04,100,1,14.23,100,1,14.35,200,2,14.39,100,1,14.48,1500,3,14.53,100,1,14.54,700,1,ARL,370606329
2232,2025-07-17T16:38:42.074211752Z,2025-07-17T16:38:42.074046298Z,10,2,1108,A,A,3,13.71,2,130,165454,307311292,13.11,100,1,12.98,200,2,12.91,2,1,12.86,100,1,12.73,100,1,12.71,100,1,12.5,700,1,12.46,100,1,12.43,700,1,12.42,700,1,13.43,15,1,13.44,100,1,13.45,15,1,13.71,2,1,14.04,100,1,14.23,100,1,14.35,200,2,14.39,100,1,14.48,1500,3,14.53,100,1,ARL,370638805
2233,2025-07-17T16:38:42.078232224Z,2025-07-17T16:38:42.078067093Z,10,2,1108,C,A,-1,14.23,100,130,165131,307311344,13.11,100,1,12.98,200,2,12.91,2,1,12.86,100,1,12.73,100,1,12.71,100,1,12.5,700,1,12.46,100,1,12.43,700,1,12.42,700,1,13.43,15,1,13.44,100,1,13.45,15,1,13.71,2,1,14.04,100,1,14.35,200,2,14.39,100,1,14.48,1500,3,14.53,100,1,14.54,700,1,ARL,370606485
2234,2025-07-17T16:38:42.078281818Z,2025-07-17T16:38:42.078116589Z,10,2,1108,A,A,3,13.71,100,130,165229,307311345,13.11,100,1,12.98,200,2,12.91,2,1,12.86,100,1,12.73,100,1,12.71,100,1,12.5,700,1,12.46,100,1,12.43,700,1,12.42,700,1,13.43,15,1,13.44,100,1,13.45,15,1,13.71,102,2,14.04,100,1,14.35,200,2,14.39,100,1,14.48,1500,3,14.53,100,1,14.54,700,1,ARL,370638829
2235,2025-07-17T16:38:42.078565517Z,2025-07-17T16:38:42.078400348Z,10,2,1108,A,A,5,14.23,100,130,165169,307311347,13.11,100,1,12.98,200,2,12.91,2,1,12.86,100,1,12.73,100,1,12.71,100,1,12.5,700,1,12.46,100,1,12.43,700,1,12.42,700,1,13.43,15,1,13.44,100,1,13.45,15,1,13.71,102,2,14.04,100,1,14.23,100,1,14.35,200,2,14.39,100,1,14.48,1500,3,14.53,100,1,ARL,370638833
2236,2025-07-17T16:38:42.088647035Z,2025-07-17T16:38:42.088481675Z,10,2,1108,A,A,7,14.39,100,130,165360,307311591,13.11,100,1,12.98,200,2,12.91,2,1,12.86,100,1,12.73,100,1,12.71,100,1,12.5,700,1,12.46,100,1,12.43,700,1,12.42,700,1,13.43,15,1,13.44,100,1,13.45,15,1,13.71,102,2,14.04,100,1,14.23,100,1,14.35,200,2,14.39,200,2,14.48,1500,3,14.53,100,1,ARL,370638997
2237,2025-07-17T16:38:42.253796551Z,2025-07-17T16:38:42.253631195Z,10,2,1108,A,A,6,14.24,100,130,165356,307313171,13.11,100,1,12.98,200,2,12.91,2,1,12.86,100,1,12.73,100,1,12.71,100,1,12.5,700,1,12.46,100,1,12.43,700,1,12.42,700,1,13.43,15,1,13.44,100,1,13.45,15,1,13.71,102,2,14.04,100,1,14.23,100,1,14.24,100,1,14.35,200,2,14.39,200,2,14.48,1500,3,ARL,370641493
2238,2025-07-17T16:38:42.858867827Z,2025-07-17T16:38:42.858701545Z,10,2,1108,A,A,4,13.97,100,0,166282,307318631,13.11,100,1,12.98,200,2,12.91,2,1,12.86,100,1,12.73,100,1,12.71,100,1,12.5,700,1,12.46,100,1,12.43,700,1,12.42,700,1,13.43,15,1,13.44,100,1,13.45,15,1,13.71,102,2,13.97,100,1,14.04,100,1,14.23,100,1,14.24,100,1,14.35,200,2,14.39,200,2,ARL,370648729
2239,2025-07-17T16:38:47.232918544Z,2025-07-17T16:38:47.232753264Z,10,2,1108,A,A,6,14.17,700,130,165280,307383998,13.11,100,1,12.98,200,2,12.91,2,1,12.86,100,1,12.73,100,1,12.71,100,1,12.5,700,1,12.46,100,1,12.43,700,1,12.42,700,1,13.43,15,1,13.44,100,1,13.45,15,1,13.71,102,2,13.97,100,1,14.04,100,1,14.17,700,1,14.23,100,1,14.24,100,1,14.35,200,2,ARL,370738933
2240,2025-07-17T16:39:58.874293523Z,2025-07-17T16:39:58.874128495Z,10,2,1108,C,A,-1,13.43,15,130,165028,309108049,13.11,100,1,12.98,200,2,12.91,2,1,12.86,100,1,12.73,100,1,12.71,100,1,12.5,700,1,12.46,100,1,12.43,700,1,12.42,700,1,13.44,100,1,13.45,15,1,13.71,102,2,13.97,100,1,14.04,100,1,14.17,700,1,14.23,100,1,14.24,100,1,14.35,200,2,14.39,200,2,ARL,370606001
2241,2025-07-17T16:40:01.981585967Z,2025-07-17T16:40:01.981419959Z,10,2,1108,A,A,0,13.42,15,128,166008,309194219,13.11,100,1,12.98,200,2,12.91,2,1,12.86,100,1,12.73,100,1,12.71,100,1,12.5,700,1,12.46,100,1,12.43,700,1,12.42,700,1,13.42,15,1,13.44,100,1,13.45,15,1,13.71,102,2,13.97,100,1,14.04,100,1,14.17,700,1,14.23,100,1,14.24,100,1,14.35,200,2,ARL,372913209
2242,2025-07-17T16:40:02.086681947Z,2025-07-17T16:40:02.086515046Z,10,2,1108,C,A,-1,13.44,100,0,166901,309196660,13.11,100,1,12.98,200,2,12.91,2,1,12.86,100,1,12.73,100,1,12.71,100,1,12.5,700,1,12.46,100,1,12.43,700,1,12.42,700,1,13.42,15,1,13.45,15,1,13.71,102,2,13.97,100,1,14.04,100,1,14.17,700,1,14.23,100,1,14.24,100,1,14.35,200,2,14.39,200,2,ARL,370638733
2243,2025-07-17T16:40:02.086681947Z,2025-07-17T16:40:02.086515046Z,10,2,1108,A,A,1,13.43,100,130,166901,309196660,13.11,100,1,12.98,200,2,12.91,2,1,12.86,100,1,12.73,100,1,12.71,100,1,12.5,700,1,12.46,100,1,12.43,700,1,12.42,700,1,13.42,15,1,13.43,100,1,13.45,15,1,13.71,102,2,13.97,100,1,14.04,100,1,14.17,700,1,14.23,100,1,14.24,100,1,14.35,200,2,ARL,372916289
2244,2025-07-17T16:40:24.333916297Z,2025-07-17T16:40:24.333742996Z,10,2,1108,C,A,-1,13.42,15,128,173301,309657551,13.11,100,1,12.98,200,2,12.91,2,1,12.86,100,1,12.73,100,1,12.71,100,1,12.5,700,1,12.46,100,1,12.43,700,1,12.42,700,1,13.43,100,1,13.45,15,1,13.71,102,2,13.97,100,1,14.04,100,1,14.17,700,1,14.23,100,1,14.24,100,1,14.35,200,2,14.39,200,2,ARL,372913209
2245,2025-07-17T16:40:24.333925326Z,2025-07-17T16:40:24.333748583Z,10,2,1108,C,A,-1,13.45,15,128,176743,309657561,13.11,100,1,12.98,200,2,12.91,2,1,12.86,100,1,12.73,100,1,12.71,100,1,12.5,700,1,12.46,100,1,12.43,700,1,12.42,700,1,13.43,100,1,13.71,102,2,13.97,100,1,14.04,100,1,14.17,700,1,14.23,100,1,14.24,100,1,14.35,200,2,14.39,200,2,14.48,1500,3,ARL,370459453
2246,2025-07-17T16:40:27.510997872Z,2025-07-17T16:40:27.510832450Z,10,2,1108,A,A,0,13.43,15,130,165422,309727211,13.11,100,1,12.98,200,2,12.91,2,1,12.86,100,1,12.73,100,1,12.71,100,1,12.5,700,1,12.46,100,1,12.43,700,1,12.42,700,1,13.43,115,2,13.71,102,2,13.97,100,1,14.04,100,1,14.17,700,1,14.23,100,1,14.24,100,1,14.35,200,2,14.39,200,2,14.48,1500,3,ARL,373568805
2247,2025-07-17T16:40:30.874687699Z,2025-07-17T16:40:30.874522389Z,10,2,1108,C,A,0,13.43,15,130,165310,309772472,13.11,100,1,12.98,200,2,12.91,2,1,12.86,100,1,12.73,100,1,12.71,100,1,12.5,700,1,12.46,100,1,12.43,700,1,12.42,700,1,13.43,100,1,13.71,102,2,13.97,100,1,14.04,100,1,14.17,700,1,14.23,100,1,14.24,100,1,14.35,200,2,14.39,200,2,14.48,1500,3,ARL,373568805
2248,2025-07-17T16:41:16.989343671Z,2025-07-17T16:41:16.989178019Z,10,2,1108,C,A,1,13.71,2,0,165652,310649827,13.11,100,1,12.98,200,2,12.91,2,1,12.86,100,1,12.73,100,1,12.71,100,1,12.5,700,1,12.46,100,1,12.43,700,1,12.42,700,1,13.43,100,1,13.71,100,1,13.97,100,1,14.04,100,1,14.17,700,1,14.23,100,1,14.24,100,1,14.35,200,2,14.39,200,2,14.48,1500,3,ARL,370638805
2249,2025-07-17T16:41:16.989343671Z,2025-07-17T16:41:16.989178019Z,10,2,1108,A,A,1,13.64,2,130,165652,310649827,13.11,100,1,12.98,200,2,12.91,2,1,12.86,100,1,12.73,100,1,12.71,100,1,12.5,700,1,12.46,100,1,12.43,700,1,12.42,700,1,13.43,100,1,13.64,2,1,13.71,100,1,13.97,100,1,14.04,100,1,14.17,700,1,14.23,100,1,14.24,100,1,14.35,200,2,14.39,200,2,ARL,374709161
2250,2025-07-17T16:41:43.139096645Z,2025-07-17T16:41:43.138931223Z,10,2,1108,C,A,-1,13.43,100,130,165422,311182878,13.11,100,1,12.98,200,2,12.91,2,1,12.86,100,1,12.73,100,1,12.71,100,1,12.5,700,1,12.46,100,1,12.43,700,1,12.42,700,1,13.64,2,1,13.71,100,1,13.97,100,1,14.04,100,1,14.17,700,1,14.23,100,1,14.24,100,1,14.35,200,2,14.39,200,2,14.48,1500,3,ARL,372916289
2251,2025-07-17T16:41:43.139367855Z,2025-07-17T16:41:43.139202376Z,10,2,1108,C,A,-1,14.17,700,130,165479,311182881,13.11,100,1,12.98,200,2,12.91,2,1,12.86,100,1,12.73,100,1,12.71,100,1,12.5,700,1,12.46,100,1,12.43,700,1,12.42,700,1,13.64,2,1,13.71,100,1,13.97,100,1,14.04,100,1,14.23,100,1,14.24,100,1,14.35,200,2,14.39,200,2,14.48,1500,3,14.54,700,1,ARL,370738933
2252,2025-07-17T16:41:43.139410669Z,2025-07-17T16:41:43.139245098Z,10,2,1108,A,A,8,14.4,700,130,165571,311182882,13.11,100,1,12.98,200,2,12.91,2,1,12.86,100,1,12.73,100,1,12.71,100,1,12.5,700,1,12.46,100,1,12.43,700,1,12.42,700,1,13.64,2,1,13.71,100,1,13.97,100,1,14.04,100,1,14.23,100,1,14.24,100,1,14.35,200,2,14.39,200,2,14.4,700,1,14.48,1500,3,ARL,375327817
