,ts_recv,ts_event,rtype,publisher_id,instrument_id,action,side,depth,price,size,flags,ts_in_delta,sequence,bid_px_00,bid_sz_00,bid_ct_00,bid_px_01,bid_sz_01,bid_ct_01,bid_px_02,bid_sz_02,bid_ct_02,bid_px_03,bid_sz_03,bid_ct_03,bid_px_04,bid_sz_04,bid_ct_04,bid_px_05,bid_sz_05,bid_ct_05,bid_px_06,bid_sz_06,bid_ct_06,bid_px_07,bid_sz_07,bid_ct_07,bid_px_08,bid_sz_08,bid_ct_08,bid_px_09,bid_sz_09,bid_ct_09,ask_px_00,ask_sz_00,ask_ct_00,ask_px_01,ask_sz_01,ask_ct_01,ask_px_02,ask_sz_02,ask_ct_02,ask_px_03,ask_sz_03,ask_ct_03,ask_px_04,ask_sz_04,ask_ct_04,ask_px_05,ask_sz_05,ask_ct_05,ask_px_06,ask_sz_06,ask_ct_06,ask_px_07,ask_sz_07,ask_ct_07,ask_px_08,ask_sz_08,ask_ct_08,ask_px_09,ask_sz_09,ask_ct_09,symbol,order_id
1145,2025-07-17T16:03:27.454939600Z,2025-07-17T16:03:27.454773691Z,10,2,1108,A,B,3,12.86,100,130,165909,272788943,13.12,200,2,13.11,100,1,13,2,1,12.86,100,1,12.73,100,1,12.71,100,1,12.5,700,1,12.46,200,2,12.43,700,1,12.42,700,1,13.87,200,2,13.88,100,1,14.03,2,1,14.15,100,1,14.25,53,1,14.28,100,1,14.45,100,1,14.56,800,2,14.6,700,1,14.66,100,1,ARL,327112577
1146,2025-07-17T16:03:27.517751270Z,2025-07-17T16:03:27.517585374Z,10,2,1108,C,B,7,12.46,100,130,165896,272790695,13.12,200,2,13.11,100,1,13,2,1,12.86,100,1,12.73,100,1,12.71,100,1,12.5,700,1,12.46,100,1,12.43,700,1,12.42,700,1,13.87,200,2,13.88,100,1,14.03,2,1,14.15,100,1,14.25,53,1,14.28,100,1,14.45,100,1,14.56,800,2,14.6,700,1,14.66,100,1,ARL,285587281
1147,2025-07-17T16:03:27.536343943Z,2025-07-17T16:03:27.536178718Z,10,2,1108,C,A,-1,14.25,53,130,165225,272791410,13.12,200,2,13.11,100,1,13,2,1,12.86,100,1,12.73,100,1,12.71,100,1,12.5,700,1,12.46,100,1,12.43,700,1,12.42,700,1,13.87,200,2,13.88,100,1,14.03,2,1,14.15,100,1,14.28,100,1,14.45,100,1,14.56,800,2,14.6,700,1,14.66,100,1,14.68,1400,2,ARL,327112281
1148,2025-07-17T16:03:56.548348047Z,2025-07-17T16:03:56.548182793Z,10,2,1108,A,A,0,13.8,15,130,165254,273208310,13.12,200,2,13.11,100,1,13,2,1,12.86,100,1,12.73,100,1,12.71,100,1,12.5,700,1,12.46,100,1,12.43,700,1,12.42,700,1,13.8,15,1,13.87,200,2,13.88,100,1,14.03,2,1,14.15,100,1,14.28,100,1,14.45,100,1,14.56,800,2,14.6,700,1,14.66,100,1,ARL,327675057
1149,2025-07-17T16:03:56.548611716Z,2025-07-17T16:03:56.548446336Z,10,2,1108,C,A,-1,13.88,100,0,165380,273208316,13.12,200,2,13.11,100,1,13,2,1,12.86,100,1,12.73,100,1,12.71,100,1,12.5,700,1,12.46,100,1,12.43,700,1,12.42,700,1,13.8,15,1,13.87,200,2,14.03,2,1,14.15,100,1,14.28,100,1,14.45,100,1,14.56,800,2,14.6,700,1,14.66,100,1,14.68,1400,2,ARL,326899125
1150,2025-07-17T16:03:56.548611716Z,2025-07-17T16:03:56.548446336Z,10,2,1108,A,A,1,13.81,100,130,165380,273208316,13.12,200,2,13.11,100,1,13,2,1,12.86,100,1,12.73,100,1,12.71,100,1,12.5,700,1,12.46,100,1,12.43,700,1,12.42,700,1,13.8,15,1,13.81,100,1,13.87,200,2,14.03,2,1,14.15,100,1,14.28,100,1,14.45,100,1,14.56,800,2,14.6,700,1,14.66,100,1,ARL,327675065
1151,2025-07-17T16:04:06.233858611Z,2025-07-17T16:04:06.233692491Z,10,2,1108,A,A,9,14.64,100,130,166120,273345719,13.12,200,2,13.11,100,1,13,2,1,12.86,100,1,12.73,100,1,12.71,100,1,12.5,700,1,12.46,100,1,12.43,700,1,12.42,700,1,13.8,15,1,13.81,100,1,13.87,200,2,14.03,2,1,14.15,100,1,14.28,100,1,14.45,100,1,14.56,800,2,14.6,700,1,14.64,100,1,ARL,327856297
1152,2025-07-17T16:04:06.234600198Z,2025-07-17T16:04:06.234433294Z,10,2,1108,A,A,9,14.64,100,130,166904,273345721,13.12,200,2,13.11,100,1,13,2,1,12.86,100,1,12.73,100,1,12.71,100,1,12.5,700,1,12.46,100,1,12.43,700,1,12.42,700,1,13.8,15,1,13.81,100,1,13.87,200,2,14.03,2,1,14.15,100,1,14.28,100,1,14.45,100,1,14.56,800,2,14.6,700,1,14.64,200,2,ARL,327856309
1153,2025-07-17T16:04:06.510914101Z,2025-07-17T16:04:06.510748731Z,10,2,1108,A,A,0,13.72,15,130,165370,273352664,13.12,200,2,13.11,100,1,13,2,1,12.86,100,1,12.73,100,1,12.71,100,1,12.5,700,1,12.46,100,1,12.43,700,1,12.42,700,1,13.72,15,1,13.8,15,1,13.81,100,1,13.87,200,2,14.03,2,1,14.15,100,1,14.28,100,1,14.45,100,1,14.56,800,2,14.6,700,1,ARL,327863853
1154,2025-07-17T16:04:06.512413102Z,2025-07-17T16:04:06.512244746Z,10,2,1108,C,A,-1,13.81,100,0,168356,273352888,13.12,200,2,13.11,100,1,13,2,1,12.86,100,1,12.73,100,1,12.71,100,1,12.5,700,1,12.46,100,1,12.43,700,1,12.42,700,1,13.72,15,1,13.8,15,1,13.87,200,2,14.03,2,1,14.15,100,1,14.28,100,1,14.45,100,1,14.56,800,2,14.6,700,1,14.64,200,2,ARL,327675065
1155,2025-07-17T16:04:06.512413102Z,2025-07-17T16:04:06.512244746Z,10,2,1108,A,A,1,13.73,100,128,168356,273352888,13.12,200,2,13.11,100,1,13,2,1,12.86,100,1,12.73,100,1,12.71,100,1,12.5,700,1,12.46,100,1,12.43,700,1,12.42,700,1,13.72,15,1,13.73,100,1,13.8,15,1,13.87,200,2,14.03,2,1,14.15,100,1,14.28,100,1,14.45,100,1,14.56,800,2,14.6,700,1,ARL,327864137
1156,2025-07-17T16:04:06.525550815Z,2025-07-17T16:04:06.525385108Z,10,2,1108,C,A,-1,14.15,100,130,165707,273358260,13.12,200,2,13.11,100,1,13,2,1,12.86,100,1,12.73,100,1,12.71,100,1,12.5,700,1,12.46,100,1,12.43,700,1,12.42,700,1,13.72,15,1,13.73,100,1,13.8,15,1,13.87,200,2,14.03,2,1,14.28,100,1,14.45,100,1,14.56,800,2,14.6,700,1,14.64,200,2,ARL,326893213
1157,2025-07-17T16:04:06.525608746Z,2025-07-17T16:04:06.525442486Z,10,2,1108,A,A,4,14,100,128,166260,273358273,13.12,200,2,13.11,100,1,13,2,1,12.86,100,1,12.73,100,1,12.71,100,1,12.5,700,1,12.46,100,1,12.43,700,1,12.42,700,1,13.72,15,1,13.73,100,1,13.8,15,1,13.87,200,2,14,100,1,14.03,2,1,14.28,100,1,14.45,100,1,14.56,800,2,14.6,700,1,ARL,327869193
1158,2025-07-17T16:04:06.528329048Z,2025-07-17T16:04:06.528161631Z,10,2,1108,A,A,8,14.52,100,128,167417,273358642,13.12,200,2,13.11,100,1,13,2,1,12.86,100,1,12.73,100,1,12.71,100,1,12.5,700,1,12.46,100,1,12.43,700,1,12.42,700,1,13.72,15,1,13.73,100,1,13.8,15,1,13.87,200,2,14,100,1,14.03,2,1,14.28,100,1,14.45,100,1,14.52,100,1,14.56,800,2,ARL,327869529
1159,2025-07-17T16:04:06.805500523Z,2025-07-17T16:04:06.805335354Z,10,2,1108,C,A,-1,13.72,15,130,165169,273364089,13.12,200,2,13.11,100,1,13,2,1,12.86,100,1,12.73,100,1,12.71,100,1,12.5,700,1,12.46,100,1,12.43,700,1,12.42,700,1,13.73,100,1,13.8,15,1,13.87,200,2,14,100,1,14.03,2,1,14.28,100,1,14.45,100,1,14.52,100,1,14.56,800,2,14.6,700,1,ARL,327863853
1160,2025-07-17T16:04:06.806217584Z,2025-07-17T16:04:06.806052396Z,10,2,1108,C,A,-1,13.8,15,130,165188,273364090,13.12,200,2,13.11,100,1,13,2,1,12.86,100,1,12.73,100,1,12.71,100,1,12.5,700,1,12.46,100,1,12.43,700,1,12.42,700,1,13.73,100,1,13.87,200,2,14,100,1,14.03,2,1,14.28,100,1,14.45,100,1,14.52,100,1,14.56,800,2,14.6,700,1,14.64,200,2,ARL,327675057
1161,2025-07-17T16:04:21.277142662Z,2025-07-17T16:04:21.276976977Z,10,2,1108,A,A,1,13.77,100,130,165685,273687857,13.12,200,2,13.11,100,1,13,2,1,12.86,100,1,12.73,100,1,12.71,100,1,12.5,700,1,12.46,100,1,12.43,700,1,12.42,700,1,13.73,100,1,13.77,100,1,13.87,200,2,14,100,1,14.03,2,1,14.28,100,1,14.45,100,1,14.52,100,1,14.56,800,2,14.6,700,1,ARL,328239293
1162,2025-07-17T16:04:27.791055146Z,2025-07-17T16:04:27.790889618Z,10,2,1108,C,A,-1,14.03,2,0,165528,273775264,13.12,200,2,13.11,100,1,13,2,1,12.86,100,1,12.73,100,1,12.71,100,1,12.5,700,1,12.46,100,1,12.43,700,1,12.42,700,1,13.73,100,1,13.77,100,1,13.87,200,2,14,100,1,14.28,100,1,14.45,100,1,14.52,100,1,14.56,800,2,14.6,700,1,14.64,200,2,ARL,326159041
1163,2025-07-17T16:04:27.791055146Z,2025-07-17T16:04:27.790889618Z,10,2,1108,A,A,3,13.94,2,130,165528,273775264,13.12,200,2,13.11,100,1,13,2,1,12.86,100,1,12.73,100,1,12.71,100,1,12.5,700,1,12.46,100,1,12.43,700,1,12.42,700,1,13.73,100,1,13.77,100,1,13.87,200,2,13.94,2,1,14,100,1,14.28,100,1,14.45,100,1,14.52,100,1,14.56,800,2,14.6,700,1,ARL,328351217
1164,2025-07-17T16:04:31.232053154Z,2025-07-17T16:04:31.231887784Z,10,2,1108,A,A,0,13.68,15,130,165370,273846737,13.12,200,2,13.11,100,1,13,2,1,12.86,100,1,12.73,100,1,12.71,100,1,12.5,700,1,12.46,100,1,12.43,700,1,12.42,700,1,13.68,15,1,13.73,100,1,13.77,100,1,13.87,200,2,13.94,2,1,14,100,1,14.28,100,1,14.45,100,1,14.52,100,1,14.56,800,2,ARL,328437797
1165,2025-07-17T16:04:31.232606440Z,2025-07-17T16:04:31.232440773Z,10,2,1108,A,A,1,13.72,100,130,165667,273846745,13.12,200,2,13.11,100,1,13,2,1,12.86,100,1,12.73,100,1,12.71,100,1,12.5,700,1,12.46,100,1,12.43,700,1,12.42,700,1,13.68,15,1,13.72,100,1,13.73,100,1,13.77,100,1,13.87,200,2,13.94,2,1,14,100,1,14.28,100,1,14.45,100,1,14.52,100,1,ARL,328437805
1166,2025-07-17T16:04:31.246681162Z,2025-07-17T16:04:31.246515467Z,10,2,1108,C,A,-1,13.77,100,130,165695,273847000,13.12,200,2,13.11,100,1,13,2,1,12.86,100,1,12.73,100,1,12.71,100,1,12.5,700,1,12.46,100,1,12.43,700,1,12.42,700,1,13.68,15,1,13.72,100,1,13.73,100,1,13.87,200,2,13.94,2,1,14,100,1,14.28,100,1,14.45,100,1,14.52,100,1,14.56,800,2,ARL,328239293
1167,2025-07-17T16:04:32.836802111Z,2025-07-17T16:04:32.836635838Z,10,2,1108,C,A,-1,13.73,100,0,166273,273882084,13.12,200,2,13.11,100,1,13,2,1,12.86,100,1,12.73,100,1,12.71,100,1,12.5,700,1,12.46,100,1,12.43,700,1,12.42,700,1,13.68,15,1,13.72,100,1,13.87,200,2,13.94,2,1,14,100,1,14.28,100,1,14.45,100,1,14.52,100,1,14.56,800,2,14.6,700,1,ARL,327864137
1168,2025-07-17T16:04:32.836802111Z,2025-07-17T16:04:32.836635838Z,10,2,1108,A,A,1,13.69,100,130,166273,273882084,13.12,200,2,13.11,100,1,13,2,1,12.86,100,1,12.73,100,1,12.71,100,1,12.5,700,1,12.46,100,1,12.43,700,1,12.42,700,1,13.68,15,1,13.69,100,1,13.72,100,1,13.87,200,2,13.94,2,1,14,100,1,14.28,100,1,14.45,100,1,14.52,100,1,14.56,800,2,ARL,328489153
1169,2025-07-17T16:04:32.837165431Z,2025-07-17T16:04:32.837000154Z,10,2,1108,C,B,0,13.12,100,130,165277,273882201,13.12,100,1,13.11,100,1,13,2,1,12.86,100,1,12.73,100,1,12.71,100,1,12.5,700,1,12.46,100,1,12.43,700,1,12.42,700,1,13.68,15,1,13.69,100,1,13.72,100,1,13.87,200,2,13.94,2,1,14,100,1,14.28,100,1,14.45,100,1,14.52,100,1,14.56,800,2,ARL,325718833
1170,2025-07-17T16:04:32.837169083Z,2025-07-17T16:04:32.837002825Z,10,2,1108,C,B,-1,13.12,100,128,166258,273882202,13.11,100,1,13,2,1,12.86,100,1,12.73,100,1,12.71,100,1,12.5,700,1,12.46,100,1,12.43,700,1,12.42,700,1,12.37,700,1,13.68,15,1,13.69,100,1,13.72,100,1,13.87,200,2,13.94,2,1,14,100,1,14.28,100,1,14.45,100,1,14.52,100,1,14.56,800,2,ARL,325718837
1171,2025-07-17T16:04:32.837179568Z,2025-07-17T16:04:32.837013456Z,10,2,1108,A,B,2,12.98,100,130,166112,273882207,13.11,100,1,13,2,1,12.98,100,1,12.86,100,1,12.73,100,1,12.71,100,1,12.5,700,1,12.46,100,1,12.43,700,1,12.42,700,1,13.68,15,1,13.69,100,1,13.72,100,1,13.87,200,2,13.94,2,1,14,100,1,14.28,100,1,14.45,100,1,14.52,100,1,14.56,800,2,ARL,328489377
1172,2025-07-17T16:04:32.837181582Z,2025-07-17T16:04:32.837016087Z,10,2,1108,A,B,2,12.98,100,130,165495,273882208,13.11,100,1,13,2,1,12.98,200,2,12.86,100,1,12.73,100,1,12.71,100,1,12.5,700,1,12.46,100,1,12.43,700,1,12.42,700,1,13.68,15,1,13.69,100,1,13.72,100,1,13.87,200,2,13.94,2,1,14,100,1,14.28,100,1,14.45,100,1,14.52,100,1,14.56,800,2,ARL,328489385
1173,2025-07-17T16:04:36.810717146Z,2025-07-17T16:04:36.810551890Z,10,2,1108,A,A,0,13.65,15,130,165256,273963456,13.11,100,1,13,2,1,12.98,200,2,12.86,100,1,12.73,100,1,12.71,100,1,12.5,700,1,12.46,100,1,12.43,700,1,12.42,700,1,13.65,15,1,13.68,15,1,13.69,100,1,13.72,100,1,13.87,200,2,13.94,2,1,14,100,1,14.28,100,1,14.45,100,1,14.52,100,1,ARL,328603377
1174,2025-07-17T16:04:37.026937493Z,2025-07-17T16:04:37.026771973Z,10,2,1108,A,A,2,13.69,100,130,165520,273965417,13.11,100,1,13,2,1,12.98,200,2,12.86,100,1,12.73,100,1,12.71,100,1,12.5,700,1,12.46,100,1,12.43,700,1,12.42,700,1,13.65,15,1,13.68,15,1,13.69,200,2,13.72,100,1,13.87,200,2,13.94,2,1,14,100,1,14.28,100,1,14.45,100,1,14.52,100,1,ARL,328606289
1175,2025-07-17T16:04:37.033554557Z,2025-07-17T16:04:37.033389265Z,10,2,1108,C,A,-1,13.72,100,130,165292,273965562,13.11,100,1,13,2,1,12.98,200,2,12.86,100,1,12.73,100,1,12.71,100,1,12.5,700,1,12.46,100,1,12.43,700,1,12.42,700,1,13.65,15,1,13.68,15,1,13.69,200,2,13.87,200,2,13.94,2,1,14,100,1,14.28,100,1,14.45,100,1,14.52,100,1,14.56,800,2,ARL,328437805
1176,2025-07-17T16:04:37.542961161Z,2025-07-17T16:04:37.542795711Z,10,2,1108,C,A,2,13.69,100,0,165450,273971021,13.11,100,1,13,2,1,12.98,200,2,12.86,100,1,12.73,100,1,12.71,100,1,12.5,700,1,12.46,100,1,12.43,700,1,12.42,700,1,13.65,15,1,13.68,15,1,13.69,100,1,13.87,200,2,13.94,2,1,14,100,1,14.28,100,1,14.45,100,1,14.52,100,1,14.56,800,2,ARL,328489153
1177,2025-07-17T16:04:37.542961161Z,2025-07-17T16:04:37.542795711Z,10,2,1108,A,A,1,13.66,100,130,165450,273971021,13.11,100,1,13,2,1,12.98,200,2,12.86,100,1,12.73,100,1,12.71,100,1,12.5,700,1,12.46,100,1,12.43,700,1,12.42,700,1,13.65,15,1,13.66,100,1,13.68,15,1,13.69,100,1,13.87,200,2,13.94,2,1,14,100,1,14.28,100,1,14.45,100,1,14.52,100,1,ARL,328614509
1178,2025-07-17T16:04:37.543230680Z,2025-07-17T16:04:37.543063240Z,10,2,1108,C,A,4,13.87,100,0,167440,273971035,13.11,100,1,13,2,1,12.98,200,2,12.86,100,1,12.73,100,1,12.71,100,1,12.5,700,1,12.46,100,1,12.43,700,1,12.42,700,1,13.65,15,1,13.66,100,1,13.68,15,1,13.69,100,1,13.87,100,1,13.94,2,1,14,100,1,14.28,100,1,14.45,100,1,14.52,100,1,ARL,326730517
1179,2025-07-17T16:04:37.543230680Z,2025-07-17T16:04:37.543064690Z,10,2,1108,C,A,-1,13.87,100,130,165990,273971037,13.11,100,1,13,2,1,12.98,200,2,12.86,100,1,12.73,100,1,12.71,100,1,12.5,700,1,12.46,100,1,12.43,700,1,12.42,700,1,13.65,15,1,13.66,100,1,13.68,15,1,13.69,100,1,13.94,2,1,14,100,1,14.28,100,1,14.45,100,1,14.52,100,1,14.56,800,2,ARL,326730521
1180,2025-07-17T16:04:37.543242390Z,2025-07-17T16:04:37.543077174Z,10,2,1108,A,A,4,13.8,100,130,165216,273971040,13.11,100,1,13,2,1,12.98,200,2,12.86,100,1,12.73,100,1,12.71,100,1,12.5,700,1,12.46,100,1,12.43,700,1,12.42,700,1,13.65,15,1,13.66,100,1,13.68,15,1,13.69,100,1,13.8,100,1,13.94,2,1,14,100,1,14.28,100,1,14.45,100,1,14.52,100,1,ARL,328614525
1181,2025-07-17T16:04:37.543244193Z,2025-07-17T16:04:37.543078532Z,10,2,1108,A,A,4,13.8,100,130,165661,273971041,13.11,100,1,13,2,1,12.98,200,2,12.86,100,1,12.73,100,1,12.71,100,1,12.5,700,1,12.46,100,1,12.43,700,1,12.42,700,1,13.65,15,1,13.66,100,1,13.68,15,1,13.69,100,1,13.8,200,2,13.94,2,1,14,100,1,14.28,100,1,14.45,100,1,14.52,100,1,ARL,328614529
1182,2025-07-17T16:04:37.549684713Z,2025-07-17T16:04:37.549519006Z,10,2,1108,C,A,-1,14,100,130,165707,273973481,13.11,100,1,13,2,1,12.98,200,2,12.86,100,1,12.73,100,1,12.71,100,1,12.5,700,1,12.46,100,1,12.43,700,1,12.42,700,1,13.65,15,1,13.66,100,1,13.68,15,1,13.69,100,1,13.8,200,2,13.94,2,1,14.28,100,1,14.45,100,1,14.52,100,1,14.56,800,2,ARL,327869193
1183,2025-07-17T16:04:37.549735824Z,2025-07-17T16:04:37.549570649Z,10,2,1108,A,A,5,13.93,100,130,165175,273973485,13.11,100,1,13,2,1,12.98,200,2,12.86,100,1,12.73,100,1,12.71,100,1,12.5,700,1,12.46,100,1,12.43,700,1,12.42,700,1,13.65,15,1,13.66,100,1,13.68,15,1,13.69,100,1,13.8,200,2,13.93,100,1,13.94,2,1,14.28,100,1,14.45,100,1,14.52,100,1,ARL,328616925
1184,2025-07-17T16:04:44.524526545Z,2025-07-17T16:04:44.524360626Z,10,2,1108,C,A,-1,13.68,15,130,165919,274066152,13.11,100,1,13,2,1,12.98,200,2,12.86,100,1,12.73,100,1,12.71,100,1,12.5,700,1,12.46,100,1,12.43,700,1,12.42,700,1,13.65,15,1,13.66,100,1,13.69,100,1,13.8,200,2,13.93,100,1,13.94,2,1,14.28,100,1,14.45,100,1,14.52,100,1,14.56,800,2,ARL,328437797
1185,2025-07-17T16:04:45.528000143Z,2025-07-17T16:04:45.527835033Z,10,2,1108,A,A,0,13.63,15,130,165110,274088918,13.11,100,1,13,2,1,12.98,200,2,12.86,100,1,12.73,100,1,12.71,100,1,12.5,700,1,12.46,100,1,12.43,700,1,12.42,700,1,13.63,15,1,13.65,15,1,13.66,100,1,13.69,100,1,13.8,200,2,13.93,100,1,13.94,2,1,14.28,100,1,14.45,100,1,14.52,100,1,ARL,328780565
1186,2025-07-17T16:04:45.528629613Z,2025-07-17T16:04:45.528464092Z,10,2,1108,A,A,9,14.52,100,130,165521,274088922,13.11,100,1,13,2,1,12.98,200,2,12.86,100,1,12.73,100,1,12.71,100,1,12.5,700,1,12.46,100,1,12.43,700,1,12.42,700,1,13.63,15,1,13.65,15,1,13.66,100,1,13.69,100,1,13.8,200,2,13.93,100,1,13.94,2,1,14.28,100,1,14.45,100,1,14.52,200,2,ARL,328780577
1187,2025-07-17T16:04:45.530418278Z,2025-07-17T16:04:45.530252804Z,10,2,1108,A,A,9,14.52,100,130,165474,274088937,13.11,100,1,13,2,1,12.98,200,2,12.86,100,1,12.73,100,1,12.71,100,1,12.5,700,1,12.46,100,1,12.43,700,1,12.42,700,1,13.63,15,1,13.65,15,1,13.66,100,1,13.69,100,1,13.8,200,2,13.93,100,1,13.94,2,1,14.28,100,1,14.45,100,1,14.52,300,3,ARL,328780597
1188,2025-07-17T16:04:45.533067029Z,2025-07-17T16:04:45.532901874Z,10,2,1108,C,A,-1,13.66,100,0,165155,274088955,13.11,100,1,13,2,1,12.98,200,2,12.86,100,1,12.73,100,1,12.71,100,1,12.5,700,1,12.46,100,1,12.43,700,1,12.42,700,1,13.63,15,1,13.65,15,1,13.69,100,1,13.8,200,2,13.93,100,1,13.94,2,1,14.28,100,1,14.45,100,1,14.52,300,3,14.56,800,2,ARL,328614509
1189,2025-07-17T16:04:45.533067029Z,2025-07-17T16:04:45.532901874Z,10,2,1108,A,A,1,13.64,100,130,165155,274088955,13.11,100,1,13,2,1,12.98,200,2,12.86,100,1,12.73,100,1,12.71,100,1,12.5,700,1,12.46,100,1,12.43,700,1,12.42,700,1,13.63,15,1,13.64,100,1,13.65,15,1,13.69,100,1,13.8,200,2,13.93,100,1,13.94,2,1,14.28,100,1,14.45,100,1,14.52,300,3,ARL,328780669
1190,2025-07-17T16:04:45.533870711Z,2025-07-17T16:04:45.533705428Z,10,2,1108,A,A,3,13.67,100,130,165283,274088959,13.11,100,1,13,2,1,12.98,200,2,12.86,100,1,12.73,100,1,12.71,100,1,12.5,700,1,12.46,100,1,12.43,700,1,12.42,700,1,13.63,15,1,13.64,100,1,13.65,15,1,13.67,100,1,13.69,100,1,13.8,200,2,13.93,100,1,13.94,2,1,14.28,100,1,14.45,100,1,ARL,328780689
1191,2025-07-17T16:04:45.563137443Z,2025-07-17T16:04:45.562972204Z,10,2,1108,C,A,-1,13.69,100,130,165239,274089319,13.11,100,1,13,2,1,12.98,200,2,12.86,100,1,12.73,100,1,12.71,100,1,12.5,700,1,12.46,100,1,12.43,700,1,12.42,700,1,13.63,15,1,13.64,100,1,13.65,15,1,13.67,100,1,13.8,200,2,13.93,100,1,13.94,2,1,14.28,100,1,14.45,100,1,14.52,300,3,ARL,328606289
1192,2025-07-17T16:04:56.809749973Z,2025-07-17T16:04:56.809584701Z,10,2,1108,C,A,-1,13.65,15,130,165272,274293432,13.11,100,1,13,2,1,12.98,200,2,12.86,100,1,12.73,100,1,12.71,100,1,12.5,700,1,12.46,100,1,12.43,700,1,12.42,700,1,13.63,15,1,13.64,100,1,13.67,100,1,13.8,200,2,13.93,100,1,13.94,2,1,14.28,100,1,14.45,100,1,14.52,300,3,14.56,800,2,ARL,328603377
1193,2025-07-17T16:04:57.827079009Z,2025-07-17T16:04:57.826913717Z,10,2,1108,A,A,0,13.61,15,130,165292,274310244,13.11,100,1,13,2,1,12.98,200,2,12.86,100,1,12.73,100,1,12.71,100,1,12.5,700,1,12.46,100,1,12.43,700,1,12.42,700,1,13.61,15,1,13.63,15,1,13.64,100,1,13.67,100,1,13.8,200,2,13.93,100,1,13.94,2,1,14.28,100,1,14.45,100,1,14.52,300,3,ARL,329068341
1194,2025-07-17T16:04:57.970616610Z,2025-07-17T16:04:57.970451236Z,10,2,1108,C,A,-1,13.64,100,0,165374,274316281,13.11,100,1,13,2,1,12.98,200,2,12.86,100,1,12.73,100,1,12.71,100,1,12.5,700,1,12.46,100,1,12.43,700,1,12.42,700,1,13.61,15,1,13.63,15,1,13.67,100,1,13.8,200,2,13.93,100,1,13.94,2,1,14.28,100,1,14.45,100,1,14.52,300,3,14.56,800,2,ARL,328780669
1195,2025-07-17T16:04:57.970616610Z,2025-07-17T16:04:57.970451236Z,10,2,1108,A,A,1,13.62,100,130,165374,274316281,13.11,100,1,13,2,1,12.98,200,2,12.86,100,1,12.73,100,1,12.71,100,1,12.5,700,1,12.46,100,1,12.43,700,1,12.42,700,1,13.61,15,1,13.62,100,1,13.63,15,1,13.67,100,1,13.8,200,2,13.93,100,1,13.94,2,1,14.28,100,1,14.45,100,1,14.52,300,3,ARL,329074609
1196,2025-07-17T16:04:57.971360344Z,2025-07-17T16:04:57.971193734Z,10,2,1108,C,A,-1,14.45,100,128,166610,274316507,13.11,100,1,13,2,1,12.98,200,2,12.86,100,1,12.73,100,1,12.71,100,1,12.5,700,1,12.46,100,1,12.43,700,1,12.42,700,1,13.61,15,1,13.62,100,1,13.63,15,1,13.67,100,1,13.8,200,2,13.93,100,1,13.94,2,1,14.28,100,1,14.52,300,3,14.56,800,2,ARL,325714601
1197,2025-07-17T16:04:57.971717511Z,2025-07-17T16:04:57.971552262Z,10,2,1108,A,A,7,14.23,100,130,165249,274316527,13.11,100,1,13,2,1,12.98,200,2,12.86,100,1,12.73,100,1,12.71,100,1,12.5,700,1,12.46,100,1,12.43,700,1,12.42,700,1,13.61,15,1,13.62,100,1,13.63,15,1,13.67,100,1,13.8,200,2,13.93,100,1,13.94,2,1,14.23,100,1,14.28,100,1,14.52,300,3,ARL,329074833
1198,2025-07-17T16:04:57.992131878Z,2025-07-17T16:04:57.991966904Z,10,2,1108,C,A,-1,13.61,15,130,164974,274318490,13.11,100,1,13,2,1,12.98,200,2,12.86,100,1,12.73,100,1,12.71,100,1,12.5,700,1,12.46,100,1,12.43,700,1,12.42,700,1,13.62,100,1,13.63,15,1,13.67,100,1,13.8,200,2,13.93,100,1,13.94,2,1,14.23,100,1,14.28,100,1,14.52,300,3,14.56,800,2,ARL,329068341
1199,2025-07-17T16:04:57.993141438Z,2025-07-17T16:04:57.992976406Z,10,2,1108,C,A,-1,13.62,100,130,165032,274318579,13.11,100,1,13,2,1,12.98,200,2,12.86,100,1,12.73,100,1,12.71,100,1,12.5,700,1,12.46,100,1,12.43,700,1,12.42,700,1,13.63,15,1,13.67,100,1,13.8,200,2,13.93,100,1,13.94,2,1,14.23,100,1,14.28,100,1,14.52,300,3,14.56,800,2,14.6,700,1,ARL,329074609
1200,2025-07-17T16:04:57.993309561Z,2025-07-17T16:04:57.993143873Z,10,2,1108,C,A,-1,13.63,15,130,165688,274318603,13.11,100,1,13,2,1,12.98,200,2,12.86,100,1,12.73,100,1,12.71,100,1,12.5,700,1,12.46,100,1,12.43,700,1,12.42,700,1,13.67,100,1,13.8,200,2,13.93,100,1,13.94,2,1,14.23,100,1,14.28,100,1,14.52,300,3,14.56,800,2,14.6,700,1,14.68,1400,2,ARL,328780565
1201,2025-07-17T16:04:58.002259715Z,2025-07-17T16:04:58.002094377Z,10,2,1108,C,A,-1,13.67,100,130,165338,274319058,13.11,100,1,13,2,1,12.98,200,2,12.86,100,1,12.73,100,1,12.71,100,1,12.5,700,1,12.46,100,1,12.43,700,1,12.42,700,1,13.8,200,2,13.93,100,1,13.94,2,1,14.23,100,1,14.28,100,1,14.52,300,3,14.56,800,2,14.6,700,1,14.68,1400,2,14.7,300,3,ARL,328780689
1202,2025-07-17T16:04:58.002989430Z,2025-07-17T16:04:58.002823841Z,10,2,1108,C,A,9,14.7,100,0,165589,274319069,13.11,100,1,13,2,1,12.98,200,2,12.86,100,1,12.73,100,1,12.71,100,1,12.5,700,1,12.46,100,1,12.43,700,1,12.42,700,1,13.8,200,2,13.93,100,1,13.94,2,1,14.23,100,1,14.28,100,1,14.52,300,3,14.56,800,2,14.6,700,1,14.68,1400,2,14.7,200,2,ARL,328780685
1203,2025-07-17T16:04:58.013904697Z,2025-07-17T16:04:58.013739242Z,10,2,1108,C,A,-1,13.93,100,130,165455,274319298,13.11,100,1,13,2,1,12.98,200,2,12.86,100,1,12.73,100,1,12.71,100,1,12.5,700,1,12.46,100,1,12.43,700,1,12.42,700,1,13.8,200,2,13.94,2,1,14.23,100,1,14.28,100,1,14.52,300,3,14.56,800,2,14.6,700,1,14.68,1400,2,14.7,200,2,14.87,100,1,ARL,328616925
1204,2025-07-17T16:04:58.013959233Z,2025-07-17T16:04:58.013793974Z,10,2,1108,A,A,2,14.08,100,130,165259,274319304,13.11,100,1,13,2,1,12.98,200,2,12.86,100,1,12.73,100,1,12.71,100,1,12.5,700,1,12.46,100,1,12.43,700,1,12.42,700,1,13.8,200,2,13.94,2,1,14.08,100,1,14.23,100,1,14.28,100,1,14.52,300,3,14.56,800,2,14.6,700,1,14.68,1400,2,14.7,200,2,ARL,329078953
1205,2025-07-17T16:04:58.536617917Z,2025-07-17T16:04:58.536452621Z,10,2,1108,A,A,1,13.81,100,130,165296,274326535,13.11,100,1,13,2,1,12.98,200,2,12.86,100,1,12.73,100,1,12.71,100,1,12.5,700,1,12.46,100,1,12.43,700,1,12.42,700,1,13.8,200,2,13.81,100,1,13.94,2,1,14.08,100,1,14.23,100,1,14.28,100,1,14.52,300,3,14.56,800,2,14.6,700,1,14.68,1400,2,ARL,329088265
1206,2025-07-17T16:05:46.594131664Z,2025-07-17T16:05:46.593966383Z,10,2,1108,A,A,0,13.76,100,130,165281,275083968,13.11,100,1,13,2,1,12.98,200,2,12.86,100,1,12.73,100,1,12.71,100,1,12.5,700,1,12.46,100,1,12.43,700,1,12.42,700,1,13.76,100,1,13.8,200,2,13.81,100,1,13.94,2,1,14.08,100,1,14.23,100,1,14.28,100,1,14.52,300,3,14.56,800,2,14.6,700,1,ARL,330066537
1207,2025-07-17T16:05:46.996003552Z,2025-07-17T16:05:46.995837526Z,10,2,1108,C,A,-1,13.81,100,0,166026,275092978,13.11,100,1,13,2,1,12.98,200,2,12.86,100,1,12.73,100,1,12.71,100,1,12.5,700,1,12.46,100,1,12.43,700,1,12.42,700,1,13.76,100,1,13.8,200,2,13.94,2,1,14.08,100,1,14.23,100,1,14.28,100,1,14.52,300,3,14.56,800,2,14.6,700,1,14.68,1400,2,ARL,329088265
1208,2025-07-17T16:05:46.996003552Z,2025-07-17T16:05:46.995837526Z,10,2,1108,A,A,1,13.77,100,130,166026,275092978,13.11,100,1,13,2,1,12.98,200,2,12.86,100,1,12.73,100,1,12.71,100,1,12.5,700,1,12.46,100,1,12.43,700,1,12.42,700,1,13.76,100,1,13.77,100,1,13.8,200,2,13.94,2,1,14.08,100,1,14.23,100,1,14.28,100,1,14.52,300,3,14.56,800,2,14.6,700,1,ARL,330075425
1209,2025-07-17T16:05:50.680333151Z,2025-07-17T16:05:50.680167632Z,10,2,1108,A,A,0,13.68,15,130,165519,275152014,13.11,100,1,13,2,1,12.98,200,2,12.86,100,1,12.73,100,1,12.71,100,1,12.5,700,1,12.46,100,1,12.43,700,1,12.42,700,1,13.68,15,1,13.76,100,1,13.77,100,1,13.8,200,2,13.94,2,1,14.08,100,1,14.23,100,1,14.28,100,1,14.52,300,3,14.56,800,2,ARL,330143813
1210,2025-07-17T16:05:50.697170320Z,2025-07-17T16:05:50.697005084Z,10,2,1108,A,A,1,13.72,100,130,165236,275152383,13.11,100,1,13,2,1,12.98,200,2,12.86,100,1,12.73,100,1,12.71,100,1,12.5,700,1,12.46,100,1,12.43,700,1,12.42,700,1,13.68,15,1,13.72,100,1,13.76,100,1,13.77,100,1,13.8,200,2,13.94,2,1,14.08,100,1,14.23,100,1,14.28,100,1,14.52,300,3,ARL,330144301
1211,2025-07-17T16:05:50.704531748Z,2025-07-17T16:05:50.704366332Z,10,2,1108,C,A,-1,13.76,100,130,165416,275152443,13.11,100,1,13,2,1,12.98,200,2,12.86,100,1,12.73,100,1,12.71,100,1,12.5,700,1,12.46,100,1,12.43,700,1,12.42,700,1,13.68,15,1,13.72,100,1,13.77,100,1,13.8,200,2,13.94,2,1,14.08,100,1,14.23,100,1,14.28,100,1,14.52,300,3,14.56,800,2,ARL,330066537
1212,2025-07-17T16:05:50.708879311Z,2025-07-17T16:05:50.708714027Z,10,2,1108,C,A,-1,14.08,100,130,165284,275152465,13.11,100,1,13,2,1,12.98,200,2,12.86,100,1,12.73,100,1,12.71,100,1,12.5,700,1,12.46,100,1,12.43,700,1,12.42,700,1,13.68,15,1,13.72,100,1,13.77,100,1,13.8,200,2,13.94,2,1,14.23,100,1,14.28,100,1,14.52,300,3,14.56,800,2,14.6,700,1,ARL,329078953
1213,2025-07-17T16:05:50.708931189Z,2025-07-17T16:05:50.708766050Z,10,2,1108,A,A,5,13.99,100,130,165139,275152466,13.11,100,1,13,2,1,12.98,200,2,12.86,100,1,12.73,100,1,12.71,100,1,12.5,700,1,12.46,100,1,12.43,700,1,12.42,700,1,13.68,15,1,13.72,100,1,13.77,100,1,13.8,200,2,13.94,2,1,13.99,100,1,14.23,100,1,14.28,100,1,14.52,300,3,14.56,800,2,ARL,330144513
1214,2025-07-17T16:05:50.913476268Z,2025-07-17T16:05:50.913310799Z,10,2,1108,C,A,-1,13.77,100,0,165469,275159685,13.11,100,1,13,2,1,12.98,200,2,12.86,100,1,12.73,100,1,12.71,100,1,12.5,700,1,12.46,100,1,12.43,700,1,12.42,700,1,13.68,15,1,13.72,100,1,13.8,200,2,13.94,2,1,13.99,100,1,14.23,100,1,14.28,100,1,14.52,300,3,14.56,800,2,14.6,700,1,ARL,330075425
1215,2025-07-17T16:05:50.913476268Z,2025-07-17T16:05:50.913310799Z,10,2,1108,A,A,1,13.69,100,130,165469,275159685,13.11,100,1,13,2,1,12.98,200,2,12.86,100,1,12.73,100,1,12.71,100,1,12.5,700,1,12.46,100,1,12.43,700,1,12.42,700,1,13.68,15,1,13.69,100,1,13.72,100,1,13.8,200,2,13.94,2,1,13.99,100,1,14.23,100,1,14.28,100,1,14.52,300,3,14.56,800,2,ARL,330151389
1216,2025-07-17T16:05:59.704955970Z,2025-07-17T16:05:59.704790753Z,10,2,1108,A,A,0,13.64,15,130,165217,275325555,13.11,100,1,13,2,1,12.98,200,2,12.86,100,1,12.73,100,1,12.71,100,1,12.5,700,1,12.46,100,1,12.43,700,1,12.42,700,1,13.64,15,1,13.68,15,1,13.69,100,1,13.72,100,1,13.8,200,2,13.94,2,1,13.99,100,1,14.23,100,1,14.28,100,1,14.52,300,3,ARL,330357473
1217,2025-07-17T16:05:59.715090662Z,2025-07-17T16:05:59.714925412Z,10,2,1108,A,A,1,13.68,100,130,165250,275325807,13.11,100,1,13,2,1,12.98,200,2,12.86,100,1,12.73,100,1,12.71,100,1,12.5,700,1,12.46,100,1,12.43,700,1,12.42,700,1,13.64,15,1,13.68,115,2,13.69,100,1,13.72,100,1,13.8,200,2,13.94,2,1,13.99,100,1,14.23,100,1,14.28,100,1,14.52,300,3,ARL,330357633
1218,2025-07-17T16:05:59.722895750Z,2025-07-17T16:05:59.722730507Z,10,2,1108,C,A,-1,13.72,100,130,165243,275325854,13.11,100,1,13,2,1,12.98,200,2,12.86,100,1,12.73,100,1,12.71,100,1,12.5,700,1,12.46,100,1,12.43,700,1,12.42,700,1,13.64,15,1,13.68,115,2,13.69,100,1,13.8,200,2,13.94,2,1,13.99,100,1,14.23,100,1,14.28,100,1,14.52,300,3,14.56,800,2,ARL,330144301
1219,2025-07-17T16:05:59.802762087Z,2025-07-17T16:05:59.802596747Z,10,2,1108,C,A,-1,13.69,100,0,165340,275327082,13.11,100,1,13,2,1,12.98,200,2,12.86,100,1,12.73,100,1,12.71,100,1,12.5,700,1,12.46,100,1,12.43,700,1,12.42,700,1,13.64,15,1,13.68,115,2,13.8,200,2,13.94,2,1,13.99,100,1,14.23,100,1,14.28,100,1,14.52,300,3,14.56,800,2,14.6,700,1,ARL,330151389
1220,2025-07-17T16:05:59.802762087Z,2025-07-17T16:05:59.802596747Z,10,2,1108,A,A,1,13.65,100,130,165340,275327082,13.11,100,1,13,2,1,12.98,200,2,12.86,100,1,12.73,100,1,12.71,100,1,12.5,700,1,12.46,100,1,12.43,700,1,12.42,700,1,13.64,15,1,13.65,100,1,13.68,115,2,13.8,200,2,13.94,2,1,13.99,100,1,14.23,100,1,14.28,100,1,14.52,300,3,14.56,800,2,ARL,330359197
1221,2025-07-17T16:05:59.827787837Z,2025-07-17T16:05:59.827622529Z,10,2,1108,C,A,-1,13.99,100,130,165308,275327416,13.11,100,1,13,2,1,12.98,200,2,12.86,100,1,12.73,100,1,12.71,100,1,12.5,700,1,12.46,100,1,12.43,700,1,12.42,700,1,13.64,15,1,13.65,100,1,13.68,115,2,13.8,200,2,13.94,2,1,14.23,100,1,14.28,100,1,14.52,300,3,14.56,800,2,14.6,700,1,ARL,330144513
1222,2025-07-17T16:05:59.827839802Z,2025-07-17T16:05:59.827674437Z,10,2,1108,A,A,4,13.92,100,130,165365,275327417,13.11,100,1,13,2,1,12.98,200,2,12.86,100,1,12.73,100,1,12.71,100,1,12.5,700,1,12.46,100,1,12.43,700,1,12.42,700,1,13.64,15,1,13.65,100,1,13.68,115,2,13.8,200,2,13.92,100,1,13.94,2,1,14.23,100,1,14.28,100,1,14.52,300,3,14.56,800,2,ARL,330359625
1223,2025-07-17T16:06:02.724446337Z,2025-07-17T16:06:02.724280161Z,10,2,1108,C,A,2,13.68,15,128,166176,275430576,13.11,100,1,13,2,1,12.98,200,2,12.86,100,1,12.73,100,1,12.71,100,1,12.5,700,1,12.46,100,1,12.43,700,1,12.42,700,1,13.64,15,1,13.65,100,1,13.68,100,1,13.8,200,2,13.92,100,1,13.94,2,1,14.23,100,1,14.28,100,1,14.52,300,3,14.56,800,2,ARL,330143813
1224,2025-07-17T16:06:03.729377770Z,2025-07-17T16:06:03.729212428Z,10,2,1108,A,A,0,13.62,15,130,165342,275517342,13.11,100,1,13,2,1,12.98,200,2,12.86,100,1,12.73,100,1,12.71,100,1,12.5,700,1,12.46,100,1,12.43,700,1,12.42,700,1,13.62,15,1,13.64,15,1,13.65,100,1,13.68,100,1,13.8,200,2,13.92,100,1,13.94,2,1,14.23,100,1,14.28,100,1,14.52,300,3,ARL,330577045
1225,2025-07-17T16:06:03.738497645Z,2025-07-17T16:06:03.738332427Z,10,2,1108,A,A,2,13.65,100,130,165218,275517997,13.11,100,1,13,2,1,12.98,200,2,12.86,100,1,12.73,100,1,12.71,100,1,12.5,700,1,12.46,100,1,12.43,700,1,12.42,700,1,13.62,15,1,13.64,15,1,13.65,200,2,13.68,100,1,13.8,200,2,13.92,100,1,13.94,2,1,14.23,100,1,14.28,100,1,14.52,300,3,ARL,330577773
1226,2025-07-17T16:06:03.747495669Z,2025-07-17T16:06:03.747330178Z,10,2,1108,C,A,-1,13.68,100,130,165491,275518621,13.11,100,1,13,2,1,12.98,200,2,12.86,100,1,12.73,100,1,12.71,100,1,12.5,700,1,12.46,100,1,12.43,700,1,12.42,700,1,13.62,15,1,13.64,15,1,13.65,200,2,13.8,200,2,13.92,100,1,13.94,2,1,14.23,100,1,14.28,100,1,14.52,300,3,14.56,800,2,ARL,330357633
1227,2025-07-17T16:06:03.887274670Z,2025-07-17T16:06:03.887107153Z,10,2,1108,C,A,2,13.65,100,0,167517,275532429,13.11,100,1,13,2,1,12.98,200,2,12.86,100,1,12.73,100,1,12.71,100,1,12.5,700,1,12.46,100,1,12.43,700,1,12.42,700,1,13.62,15,1,13.64,15,1,13.65,100,1,13.8,200,2,13.92,100,1,13.94,2,1,14.23,100,1,14.28,100,1,14.52,300,3,14.56,800,2,ARL,330359197
1228,2025-07-17T16:06:03.887274670Z,2025-07-17T16:06:03.887107153Z,10,2,1108,A,A,1,13.63,100,130,167517,275532429,13.11,100,1,13,2,1,12.98,200,2,12.86,100,1,12.73,100,1,12.71,100,1,12.5,700,1,12.46,100,1,12.43,700,1,12.42,700,1,13.62,15,1,13.63,100,1,13.64,15,1,13.65,100,1,13.8,200,2,13.92,100,1,13.94,2,1,14.23,100,1,14.28,100,1,14.52,300,3,ARL,330592465
1229,2025-07-17T16:06:07.510050758Z,2025-07-17T16:06:07.509885114Z,10,2,1108,C,A,-1,13.64,15,130,165644,275647392,13.11,100,1,13,2,1,12.98,200,2,12.86,100,1,12.73,100,1,12.71,100,1,12.5,700,1,12.46,100,1,12.43,700,1,12.42,700,1,13.62,15,1,13.63,100,1,13.65,100,1,13.8,200,2,13.92,100,1,13.94,2,1,14.23,100,1,14.28,100,1,14.52,300,3,14.56,800,2,ARL,330357473
1230,2025-07-17T16:06:09.885143909Z,2025-07-17T16:06:09.884978592Z,10,2,1108,A,A,0,13.6,15,130,165317,275699092,13.11,100,1,13,2,1,12.98,200,2,12.86,100,1,12.73,100,1,12.71,100,1,12.5,700,1,12.46,100,1,12.43,700,1,12.42,700,1,13.6,15,1,13.62,15,1,13.63,100,1,13.65,100,1,13.8,200,2,13.92,100,1,13.94,2,1,14.23,100,1,14.28,100,1,14.52,300,3,ARL,330788421
1231,2025-07-17T16:06:09.967608061Z,2025-07-17T16:06:09.967442600Z,10,2,1108,C,A,-1,13.63,100,0,165461,275700261,13.11,100,1,13,2,1,12.98,200,2,12.86,100,1,12.73,100,1,12.71,100,1,12.5,700,1,12.46,100,1,12.43,700,1,12.42,700,1,13.6,15,1,13.62,15,1,13.65,100,1,13.8,200,2,13.92,100,1,13.94,2,1,14.23,100,1,14.28,100,1,14.52,300,3,14.56,800,2,ARL,330592465
1232,2025-07-17T16:06:09.967608061Z,2025-07-17T16:06:09.967442600Z,10,2,1108,A,A,1,13.61,100,130,165461,275700261,13.11,100,1,13,2,1,12.98,200,2,12.86,100,1,12.73,100,1,12.71,100,1,12.5,700,1,12.46,100,1,12.43,700,1,12.42,700,1,13.6,15,1,13.61,100,1,13.62,15,1,13.65,100,1,13.8,200,2,13.92,100,1,13.94,2,1,14.23,100,1,14.28,100,1,14.52,300,3,ARL,330789481
1233,2025-07-17T16:06:20.470889851Z,2025-07-17T16:06:20.470724464Z,10,2,1108,A,A,3,13.63,100,130,165387,275896138,13.11,100,1,13,2,1,12.98,200,2,12.86,100,1,12.73,100,1,12.71,100,1,12.5,700,1,12.46,100,1,12.43,700,1,12.42,700,1,13.6,15,1,13.61,100,1,13.62,15,1,13.63,100,1,13.65,100,1,13.8,200,2,13.92,100,1,13.94,2,1,14.23,100,1,14.28,100,1,ARL,331018065
1234,2025-07-17T16:06:20.477598578Z,2025-07-17T16:06:20.477432988Z,10,2,1108,C,A,-1,13.65,100,130,165590,275896242,13.11,100,1,13,2,1,12.98,200,2,12.86,100,1,12.73,100,1,12.71,100,1,12.5,700,1,12.46,100,1,12.43,700,1,12.42,700,1,13.6,15,1,13.61,100,1,13.62,15,1,13.63,100,1,13.8,200,2,13.92,100,1,13.94,2,1,14.23,100,1,14.28,100,1,14.52,300,3,ARL,330577773
1235,2025-07-17T16:06:20.811164178Z,2025-07-17T16:06:20.810998706Z,10,2,1108,C,A,-1,13.62,15,130,165472,275900161,13.11,100,1,13,2,1,12.98,200,2,12.86,100,1,12.73,100,1,12.71,100,1,12.5,700,1,12.46,100,1,12.43,700,1,12.42,700,1,13.6,15,1,13.61,100,1,13.63,100,1,13.8,200,2,13.92,100,1,13.94,2,1,14.23,100,1,14.28,100,1,14.52,300,3,14.56,800,2,ARL,330577045
1236,2025-07-17T16:06:22.151222819Z,2025-07-17T16:06:22.151057292Z,10,2,1108,A,A,0,13.58,15,130,165527,275926927,13.11,100,1,13,2,1,12.98,200,2,12.86,100,1,12.73,100,1,12.71,100,1,12.5,700,1,12.46,100,1,12.43,700,1,12.42,700,1,13.58,15,1,13.6,15,1,13.61,100,1,13.63,100,1,13.8,200,2,13.92,100,1,13.94,2,1,14.23,100,1,14.28,100,1,14.52,300,3,ARL,331050981
1237,2025-07-17T16:06:22.151491832Z,2025-07-17T16:06:22.151326300Z,10,2,1108,C,A,-1,13.61,100,0,165532,275926940,13.11,100,1,13,2,1,12.98,200,2,12.86,100,1,12.73,100,1,12.71,100,1,12.5,700,1,12.46,100,1,12.43,700,1,12.42,700,1,13.58,15,1,13.6,15,1,13.63,100,1,13.8,200,2,13.92,100,1,13.94,2,1,14.23,100,1,14.28,100,1,14.52,300,3,14.56,800,2,ARL,330789481
1238,2025-07-17T16:06:22.151491832Z,2025-07-17T16:06:22.151326300Z,10,2,1108,A,A,1,13.59,100,130,165532,275926940,13.11,100,1,13,2,1,12.98,200,2,12.86,100,1,12.73,100,1,12.71,100,1,12.5,700,1,12.46,100,1,12.43,700,1,12.42,700,1,13.58,15,1,13.59,100,1,13.6,15,1,13.63,100,1,13.8,200,2,13.92,100,1,13.94,2,1,14.23,100,1,14.28,100,1,14.52,300,3,ARL,331050989
1239,2025-07-17T16:06:22.151761329Z,2025-07-17T16:06:22.151595415Z,10,2,1108,C,A,4,13.8,100,0,165914,275926966,13.11,100,1,13,2,1,12.98,200,2,12.86,100,1,12.73,100,1,12.71,100,1,12.5,700,1,12.46,100,1,12.43,700,1,12.42,700,1,13.58,15,1,13.59,100,1,13.6,15,1,13.63,100,1,13.8,100,1,13.92,100,1,13.94,2,1,14.23,100,1,14.28,100,1,14.52,300,3,ARL,328614525
1240,2025-07-17T16:06:22.151761329Z,2025-07-17T16:06:22.151595781Z,10,2,1108,C,A,-1,13.8,100,130,165548,275926967,13.11,100,1,13,2,1,12.98,200,2,12.86,100,1,12.73,100,1,12.71,100,1,12.5,700,1,12.46,100,1,12.43,700,1,12.42,700,1,13.58,15,1,13.59,100,1,13.6,15,1,13.63,100,1,13.92,100,1,13.94,2,1,14.23,100,1,14.28,100,1,14.52,300,3,14.56,800,2,ARL,328614529
1241,2025-07-17T16:06:22.153916169Z,2025-07-17T16:06:22.153749481Z,10,2,1108,A,A,9,14.55,100,130,166688,275927046,13.11,100,1,13,2,1,12.98,200,2,12.86,100,1,12.73,100,1,12.71,100,1,12.5,700,1,12.46,100,1,12.43,700,1,12.42,700,1,13.58,15,1,13.59,100,1,13.6,15,1,13.63,100,1,13.92,100,1,13.94,2,1,14.23,100,1,14.28,100,1,14.52,300,3,14.55,100,1,ARL,331051173
1242,2025-07-17T16:06:22.156070698Z,2025-07-17T16:06:22.155905240Z,10,2,1108,C,A,8,14.52,100,0,165458,275927117,13.11,100,1,13,2,1,12.98,200,2,12.86,100,1,12.73,100,1,12.71,100,1,12.5,700,1,12.46,100,1,12.43,700,1,12.42,700,1,13.58,15,1,13.59,100,1,13.6,15,1,13.63,100,1,13.92,100,1,13.94,2,1,14.23,100,1,14.28,100,1,14.52,200,2,14.55,100,1,ARL,327869529
1243,2025-07-17T16:06:22.156070698Z,2025-07-17T16:06:22.155905240Z,10,2,1108,A,A,8,14.38,100,130,165458,275927117,13.11,100,1,13,2,1,12.98,200,2,12.86,100,1,12.73,100,1,12.71,100,1,12.5,700,1,12.46,100,1,12.43,700,1,12.42,700,1,13.58,15,1,13.59,100,1,13.6,15,1,13.63,100,1,13.92,100,1,13.94,2,1,14.23,100,1,14.28,100,1,14.38,100,1,14.52,200,2,ARL,331051369
1244,2025-07-17T16:06:24.519511128Z,2025-07-17T16:06:24.519345743Z,10,2,1108,A,A,2,13.6,100,130,165385,275968354,13.11,100,1,13,2,1,12.98,200,2,12.86,100,1,12.73,100,1,12.71,100,1,12.5,700,1,12.46,100,1,12.43,700,1,12.42,700,1,13.58,15,1,13.59,100,1,13.6,115,2,13.63,100,1,13.92,100,1,13.94,2,1,14.23,100,1,14.28,100,1,14.38,100,1,14.52,200,2,ARL,331104725
1245,2025-07-17T16:06:24.526359716Z,2025-07-17T16:06:24.526194457Z,10,2,1108,C,A,-1,13.63,100,130,165259,275968393,13.11,100,1,13,2,1,12.98,200,2,12.86,100,1,12.73,100,1,12.71,100,1,12.5,700,1,12.46,100,1,12.43,700,1,12.42,700,1,13.58,15,1,13.59,100,1,13.6,115,2,13.92,100,1,13.94,2,1,14.23,100,1,14.28,100,1,14.38,100,1,14.52,200,2,14.55,200,2,ARL,331018065
1246,2025-07-17T16:06:26.610345800Z,2025-07-17T16:06:26.610180184Z,10,2,1108,C,A,-1,13.94,2,0,165616,276013080,13.11,100,1,13,2,1,12.98,200,2,12.86,100,1,12.73,100,1,12.71,100,1,12.5,700,1,12.46,100,1,12.43,700,1,12.42,700,1,13.58,15,1,13.59,100,1,13.6,115,2,13.92,100,1,14.23,100,1,14.28,100,1,14.38,100,1,14.52,200,2,14.55,200,2,14.56,800,2,ARL,328351217
1247,2025-07-17T16:06:26.610345800Z,2025-07-17T16:06:26.610180184Z,10,2,1108,A,A,3,13.85,2,130,165616,276013080,13.11,100,1,13,2,1,12.98,200,2,12.86,100,1,12.73,100,1,12.71,100,1,12.5,700,1,12.46,100,1,12.43,700,1,12.42,700,1,13.58,15,1,13.59,100,1,13.6,115,2,13.85,2,1,13.92,100,1,14.23,100,1,14.28,100,1,14.38,100,1,14.52,200,2,14.55,200,2,ARL,331155889
1248,2025-07-17T16:06:30.625877214Z,2025-07-17T16:06:30.625711923Z,10,2,1108,A,A,6,14.27,700,130,165291,276103282,13.11,100,1,13,2,1,12.98,200,2,12.86,100,1,12.73,100,1,12.71,100,1,12.5,700,1,12.46,100,1,12.43,700,1,12.42,700,1,13.58,15,1,13.59,100,1,13.6,115,2,13.85,2,1,13.92,100,1,14.23,100,1,14.27,700,1,14.28,100,1,14.38,100,1,14.52,200,2,ARL,331257169
1249,2025-07-17T16:06:31.127827805Z,2025-07-17T16:06:31.127662311Z,10,2,1108,A,A,9,14.48,700,130,165494,276118990,13.11,100,1,13,2,1,12.98,200,2,12.86,100,1,12.73,100,1,12.71,100,1,12.5,700,1,12.46,100,1,12.43,700,1,12.42,700,1,13.58,15,1,13.59,100,1,13.6,115,2,13.85,2,1,13.92,100,1,14.23,100,1,14.27,700,1,14.28,100,1,14.38,100,1,14.48,700,1,ARL,331272997
1250,2025-07-17T16:06:31.990649229Z,2025-07-17T16:06:31.990483799Z,10,2,1108,C,A,2,13.6,15,130,165430,276135226,13.11,100,1,13,2,1,12.98,200,2,12.86,100,1,12.73,100,1,12.71,100,1,12.5,700,1,12.46,100,1,12.43,700,1,12.42,700,1,13.58,15,1,13.59,100,1,13.6,100,1,13.85,2,1,13.92,100,1,14.23,100,1,14.27,700,1,14.28,100,1,14.38,100,1,14.48,700,1,ARL,330788421
1251,2025-07-17T16:06:42.812807096Z,2025-07-17T16:06:42.812641697Z,10,2,1108,A,A,0,13.56,15,130,165399,276276783,13.11,100,1,13,2,1,12.98,200,2,12.86,100,1,12.73,100,1,12.71,100,1,12.5,700,1,12.46,100,1,12.43,700,1,12.42,700,1,13.56,15,1,13.58,15,1,13.59,100,1,13.6,100,1,13.85,2,1,13.92,100,1,14.23,100,1,14.27,700,1,14.28,100,1,14.38,100,1,ARL,331488089
1252,2025-07-17T16:06:43.012965957Z,2025-07-17T16:06:43.012799164Z,10,2,1108,C,A,-1,13.59,100,0,166793,276279311,13.11,100,1,13,2,1,12.98,200,2,12.86,100,1,12.73,100,1,12.71,100,1,12.5,700,1,12.46,100,1,12.43,700,1,12.42,700,1,13.56,15,1,13.58,15,1,13.6,100,1,13.85,2,1,13.92,100,1,14.23,100,1,14.27,700,1,14.28,100,1,14.38,100,1,14.48,700,1,ARL,331050989
1253,2025-07-17T16:06:43.012965957Z,2025-07-17T16:06:43.012799164Z,10,2,1108,A,A,1,13.57,100,128,166793,276279311,13.11,100,1,13,2,1,12.98,200,2,12.86,100,1,12.73,100,1,12.71,100,1,12.5,700,1,12.46,100,1,12.43,700,1,12.42,700,1,13.56,15,1,13.57,100,1,13.58,15,1,13.6,100,1,13.85,2,1,13.92,100,1,14.23,100,1,14.27,700,1,14.28,100,1,14.38,100,1,ARL,331491049
1254,2025-07-17T16:06:43.024656023Z,2025-07-17T16:06:43.024490355Z,10,2,1108,C,A,-1,13.92,100,130,165668,276279620,13.11,100,1,13,2,1,12.98,200,2,12.86,100,1,12.73,100,1,12.71,100,1,12.5,700,1,12.46,100,1,12.43,700,1,12.42,700,1,13.56,15,1,13.57,100,1,13.58,15,1,13.6,100,1,13.85,2,1,14.23,100,1,14.27,700,1,14.28,100,1,14.38,100,1,14.48,700,1,ARL,330359625
1255,2025-07-17T16:06:43.024708304Z,2025-07-17T16:06:43.024543099Z,10,2,1108,A,A,4,13.84,100,130,165205,276279621,13.11,100,1,13,2,1,12.98,200,2,12.86,100,1,12.73,100,1,12.71,100,1,12.5,700,1,12.46,100,1,12.43,700,1,12.42,700,1,13.56,15,1,13.57,100,1,13.58,15,1,13.6,100,1,13.84,100,1,13.85,2,1,14.23,100,1,14.27,700,1,14.28,100,1,14.38,100,1,ARL,331491269
1256,2025-07-17T16:06:49.613941821Z,2025-07-17T16:06:49.613776144Z,10,2,1108,C,A,-1,13.58,15,130,165677,276382302,13.11,100,1,13,2,1,12.98,200,2,12.86,100,1,12.73,100,1,12.71,100,1,12.5,700,1,12.46,100,1,12.43,700,1,12.42,700,1,13.56,15,1,13.57,100,1,13.6,100,1,13.84,100,1,13.85,2,1,14.23,100,1,14.27,700,1,14.28,100,1,14.38,100,1,14.48,700,1,ARL,331050981
1257,2025-07-17T16:06:50.618669843Z,2025-07-17T16:06:50.618504506Z,10,2,1108,A,A,0,13.54,15,130,165337,276408477,13.11,100,1,13,2,1,12.98,200,2,12.86,100,1,12.73,100,1,12.71,100,1,12.5,700,1,12.46,100,1,12.43,700,1,12.42,700,1,13.54,15,1,13.56,15,1,13.57,100,1,13.6,100,1,13.84,100,1,13.85,2,1,14.23,100,1,14.27,700,1,14.28,100,1,14.38,100,1,ARL,331666961
1258,2025-07-17T16:06:50.626438205Z,2025-07-17T16:06:50.626272828Z,10,2,1108,A,A,3,13.58,100,130,165377,276408566,13.11,100,1,13,2,1,12.98,200,2,12.86,100,1,12.73,100,1,12.71,100,1,12.5,700,1,12.46,100,1,12.43,700,1,12.42,700,1,13.54,15,1,13.56,15,1,13.57,100,1,13.58,100,1,13.6,100,1,13.84,100,1,13.85,2,1,14.23,100,1,14.27,700,1,14.28,100,1,ARL,331667121
1259,2025-07-17T16:06:50.633113557Z,2025-07-17T16:06:50.632947998Z,10,2,1108,C,A,-1,13.6,100,130,165559,276408644,13.11,100,1,13,2,1,12.98,200,2,12.86,100,1,12.73,100,1,12.71,100,1,12.5,700,1,12.46,100,1,12.43,700,1,12.42,700,1,13.54,15,1,13.56,15,1,13.57,100,1,13.58,100,1,13.84,100,1,13.85,2,1,14.23,100,1,14.27,700,1,14.28,100,1,14.38,100,1,ARL,331104725
1260,2025-07-17T16:06:51.754576322Z,2025-07-17T16:06:51.754410704Z,10,2,1108,C,A,-1,13.57,100,0,165618,276428315,13.11,100,1,13,2,1,12.98,200,2,12.86,100,1,12.73,100,1,12.71,100,1,12.5,700,1,12.46,100,1,12.43,700,1,12.42,700,1,13.54,15,1,13.56,15,1,13.58,100,1,13.84,100,1,13.85,2,1,14.23,100,1,14.27,700,1,14.28,100,1,14.38,100,1,14.48,700,1,ARL,331491049
1261,2025-07-17T16:06:51.754576322Z,2025-07-17T16:06:51.754410704Z,10,2,1108,A,A,1,13.55,100,130,165618,276428315,13.11,100,1,13,2,1,12.98,200,2,12.86,100,1,12.73,100,1,12.71,100,1,12.5,700,1,12.46,100,1,12.43,700,1,12.42,700,1,13.54,15,1,13.55,100,1,13.56,15,1,13.58,100,1,13.84,100,1,13.85,2,1,14.23,100,1,14.27,700,1,14.28,100,1,14.38,100,1,ARL,331694265
1262,2025-07-17T16:06:51.757403109Z,2025-07-17T16:06:51.757237300Z,10,2,1108,C,B,-1,13,2,0,165809,276428333,13.11,100,1,12.98,200,2,12.86,100,1,12.73,100,1,12.71,100,1,12.5,700,1,12.46,100,1,12.43,700,1,12.42,700,1,12.37,700,1,13.54,15,1,13.55,100,1,13.56,15,1,13.58,100,1,13.84,100,1,13.85,2,1,14.23,100,1,14.27,700,1,14.28,100,1,14.38,100,1,ARL,325967705
1263,2025-07-17T16:06:51.757403109Z,2025-07-17T16:06:51.757237300Z,10,2,1108,A,B,2,12.9,2,130,165809,276428333,13.11,100,1,12.98,200,2,12.9,2,1,12.86,100,1,12.73,100,1,12.71,100,1,12.5,700,1,12.46,100,1,12.43,700,1,12.42,700,1,13.54,15,1,13.55,100,1,13.56,15,1,13.58,100,1,13.84,100,1,13.85,2,1,14.23,100,1,14.27,700,1,14.28,100,1,14.38,100,1,ARL,331694297
1264,2025-07-17T16:06:55.056300861Z,2025-07-17T16:06:55.056135380Z,10,2,1108,C,A,-1,13.54,15,130,165481,276516227,13.11,100,1,12.98,200,2,12.9,2,1,12.86,100,1,12.73,100,1,12.71,100,1,12.5,700,1,12.46,100,1,12.43,700,1,12.42,700,1,13.55,100,1,13.56,15,1,13.58,100,1,13.84,100,1,13.85,2,1,14.23,100,1,14.27,700,1,14.28,100,1,14.38,100,1,14.48,700,1,ARL,331666961
1265,2025-07-17T16:06:55.056466231Z,2025-07-17T16:06:55.056301001Z,10,2,1108,C,A,-1,13.56,15,130,165230,276516239,13.11,100,1,12.98,200,2,12.9,2,1,12.86,100,1,12.73,100,1,12.71,100,1,12.5,700,1,12.46,100,1,12.43,700,1,12.42,700,1,13.55,100,1,13.58,100,1,13.84,100,1,13.85,2,1,14.23,100,1,14.27,700,1,14.28,100,1,14.38,100,1,14.48,700,1,14.52,200,2,ARL,331488089
1266,2025-07-17T16:07:00.010995558Z,2025-07-17T16:07:00.010829521Z,10,2,1108,C,A,-1,13.55,100,130,166037,276611719,13.11,100,1,12.98,200,2,12.9,2,1,12.86,100,1,12.73,100,1,12.71,100,1,12.5,700,1,12.46,100,1,12.43,700,1,12.42,700,1,13.58,100,1,13.84,100,1,13.85,2,1,14.23,100,1,14.27,700,1,14.28,100,1,14.38,100,1,14.48,700,1,14.52,200,2,14.55,200,2,ARL,331694265
1267,2025-07-17T16:07:00.023849180Z,2025-07-17T16:07:00.023683961Z,10,2,1108,C,A,-1,13.58,100,130,165219,276613073,13.11,100,1,12.98,200,2,12.9,2,1,12.86,100,1,12.73,100,1,12.71,100,1,12.5,700,1,12.46,100,1,12.43,700,1,12.42,700,1,13.84,100,1,13.85,2,1,14.23,100,1,14.27,700,1,14.28,100,1,14.38,100,1,14.48,700,1,14.52,200,2,14.55,200,2,14.56,800,2,ARL,331667121
1268,2025-07-17T16:07:00.023917543Z,2025-07-17T16:07:00.023752163Z,10,2,1108,C,A,-1,14.27,700,130,165380,276613077,13.11,100,1,12.98,200,2,12.9,2,1,12.86,100,1,12.73,100,1,12.71,100,1,12.5,700,1,12.46,100,1,12.43,700,1,12.42,700,1,13.84,100,1,13.85,2,1,14.23,100,1,14.28,100,1,14.38,100,1,14.48,700,1,14.52,200,2,14.55,200,2,14.56,800,2,14.6,700,1,ARL,331257169
1269,2025-07-17T16:07:00.023980805Z,2025-07-17T16:07:00.023815326Z,10,2,1108,A,A,6,14.51,700,130,165479,276613078,13.11,100,1,12.98,200,2,12.9,2,1,12.86,100,1,12.73,100,1,12.71,100,1,12.5,700,1,12.46,100,1,12.43,700,1,12.42,700,1,13.84,100,1,13.85,2,1,14.23,100,1,14.28,100,1,14.38,100,1,14.48,700,1,14.51,700,1,14.52,200,2,14.55,200,2,14.56,800,2,ARL,331926981
1270,2025-07-17T16:07:00.025231164Z,2025-07-17T16:07:00.025064913Z,10,2,1108,C,A,-1,14.23,100,130,166251,276613157,13.11,100,1,12.98,200,2,12.9,2,1,12.86,100,1,12.73,100,1,12.71,100,1,12.5,700,1,12.46,100,1,12.43,700,1,12.42,700,1,13.84,100,1,13.85,2,1,14.28,100,1,14.38,100,1,14.48,700,1,14.51,700,1,14.52,200,2,14.55,200,2,14.56,800,2,14.6,700,1,ARL,329074833
1271,2025-07-17T16:07:00.025587549Z,2025-07-17T16:07:00.025422082Z,10,2,1108,A,A,4,14.46,100,130,165467,276613175,13.11,100,1,12.98,200,2,12.9,2,1,12.86,100,1,12.73,100,1,12.71,100,1,12.5,700,1,12.46,100,1,12.43,700,1,12.42,700,1,13.84,100,1,13.85,2,1,14.28,100,1,14.38,100,1,14.46,100,1,14.48,700,1,14.51,700,1,14.52,200,2,14.55,200,2,14.56,800,2,ARL,331927161
1272,2025-07-17T16:07:00.025793260Z,2025-07-17T16:07:00.025628157Z,10,2,1108,A,A,0,13.59,100,130,165103,276613194,13.11,100,1,12.98,200,2,12.9,2,1,12.86,100,1,12.73,100,1,12.71,100,1,12.5,700,1,12.46,100,1,12.43,700,1,12.42,700,1,13.59,100,1,13.84,100,1,13.85,2,1,14.28,100,1,14.38,100,1,14.46,100,1,14.48,700,1,14.51,700,1,14.52,200,2,14.55,200,2,ARL,331927177
1273,2025-07-17T16:07:00.026998695Z,2025-07-17T16:07:00.026833761Z,10,2,1108,C,A,-1,13.59,100,130,164934,276613224,13.11,100,1,12.98,200,2,12.9,2,1,12.86,100,1,12.73,100,1,12.71,100,1,12.5,700,1,12.46,100,1,12.43,700,1,12.42,700,1,13.84,100,1,13.85,2,1,14.28,100,1,14.38,100,1,14.46,100,1,14.48,700,1,14.51,700,1,14.52,200,2,14.55,200,2,14.56,800,2,ARL,331927177
1274,2025-07-17T16:07:00.032762182Z,2025-07-17T16:07:00.032596898Z,10,2,1108,C,A,-1,14.38,100,130,165284,276613329,13.11,100,1,12.98,200,2,12.9,2,1,12.86,100,1,12.73,100,1,12.71,100,1,12.5,700,1,12.46,100,1,12.43,700,1,12.42,700,1,13.84,100,1,13.85,2,1,14.28,100,1,14.46,100,1,14.48,700,1,14.51,700,1,14.52,200,2,14.55,200,2,14.56,800,2,14.6,700,1,ARL,331051369
1275,2025-07-17T16:07:00.045525047Z,2025-07-17T16:07:00.045359807Z,10,2,1108,C,A,-1,13.84,100,130,165240,276613663,13.11,100,1,12.98,200,2,12.9,2,1,12.86,100,1,12.73,100,1,12.71,100,1,12.5,700,1,12.46,100,1,12.43,700,1,12.42,700,1,13.85,2,1,14.28,100,1,14.46,100,1,14.48,700,1,14.51,700,1,14.52,200,2,14.55,200,2,14.56,800,2,14.6,700,1,14.63,100,1,ARL,331491269
1276,2025-07-17T16:07:00.045559272Z,2025-07-17T16:07:00.045394317Z,10,2,1108,C,A,-1,14.51,700,130,164955,276613664,13.11,100,1,12.98,200,2,12.9,2,1,12.86,100,1,12.73,100,1,12.71,100,1,12.5,700,1,12.46,100,1,12.43,700,1,12.42,700,1,13.85,2,1,14.28,100,1,14.46,100,1,14.48,700,1,14.52,200,2,14.55,200,2,14.56,800,2,14.6,700,1,14.63,100,1,14.88,100,1,ARL,331926981
1277,2025-07-17T16:07:00.045574786Z,2025-07-17T16:07:00.045409635Z,10,2,1108,A,A,1,14.09,100,130,165151,276613665,13.11,100,1,12.98,200,2,12.9,2,1,12.86,100,1,12.73,100,1,12.71,100,1,12.5,700,1,12.46,100,1,12.43,700,1,12.42,700,1,13.85,2,1,14.09,100,1,14.28,100,1,14.46,100,1,14.48,700,1,14.52,200,2,14.55,200,2,14.56,800,2,14.6,700,1,14.63,100,1,ARL,331927857
1278,2025-07-17T16:07:00.046838602Z,2025-07-17T16:07:00.046672908Z,10,2,1108,C,A,-1,14.09,100,130,165694,276613680,13.11,100,1,12.98,200,2,12.9,2,1,12.86,100,1,12.73,100,1,12.71,100,1,12.5,700,1,12.46,100,1,12.43,700,1,12.42,700,1,13.85,2,1,14.28,100,1,14.46,100,1,14.48,700,1,14.52,200,2,14.55,200,2,14.56,800,2,14.6,700,1,14.63,100,1,14.88,100,1,ARL,331927857
1279,2025-07-17T16:07:00.046887005Z,2025-07-17T16:07:00.046721624Z,10,2,1108,A,A,1,13.86,100,130,165381,276613681,13.11,100,1,12.98,200,2,12.9,2,1,12.86,100,1,12.73,100,1,12.71,100,1,12.5,700,1,12.46,100,1,12.43,700,1,12.42,700,1,13.85,2,1,13.86,100,1,14.28,100,1,14.46,100,1,14.48,700,1,14.52,200,2,14.55,200,2,14.56,800,2,14.6,700,1,14.63,100,1,ARL,331927877
1280,2025-07-17T16:07:00.047708936Z,2025-07-17T16:07:00.047544064Z,10,2,1108,C,A,-1,13.86,100,130,164872,276613692,13.11,100,1,12.98,200,2,12.9,2,1,12.86,100,1,12.73,100,1,12.71,100,1,12.5,700,1,12.46,100,1,12.43,700,1,12.42,700,1,13.85,2,1,14.28,100,1,14.46,100,1,14.48,700,1,14.52,200,2,14.55,200,2,14.56,800,2,14.6,700,1,14.63,100,1,14.88,100,1,ARL,331927877
1281,2025-07-17T16:07:00.047755498Z,2025-07-17T16:07:00.047590313Z,10,2,1108,A,A,1,14.12,100,130,165185,276613693,13.11,100,1,12.98,200,2,12.9,2,1,12.86,100,1,12.73,100,1,12.71,100,1,12.5,700,1,12.46,100,1,12.43,700,1,12.42,700,1,13.85,2,1,14.12,100,1,14.28,100,1,14.46,100,1,14.48,700,1,14.52,200,2,14.55,200,2,14.56,800,2,14.6,700,1,14.63,100,1,ARL,331927921
1282,2025-07-17T16:07:00.053448670Z,2025-07-17T16:07:00.053283700Z,10,2,1108,C,A,-1,14.12,100,130,164970,276613731,13.11,100,1,12.98,200,2,12.9,2,1,12.86,100,1,12.73,100,1,12.71,100,1,12.5,700,1,12.46,100,1,12.43,700,1,12.42,700,1,13.85,2,1,14.28,100,1,14.46,100,1,14.48,700,1,14.52,200,2,14.55,200,2,14.56,800,2,14.6,700,1,14.63,100,1,14.88,100,1,ARL,331927921
1283,2025-07-17T16:07:00.053495095Z,2025-07-17T16:07:00.053329959Z,10,2,1108,A,A,1,14.26,100,130,165136,276613732,13.11,100,1,12.98,200,2,12.9,2,1,12.86,100,1,12.73,100,1,12.71,100,1,12.5,700,1,12.46,100,1,12.43,700,1,12.42,700,1,13.85,2,1,14.26,100,1,14.28,100,1,14.46,100,1,14.48,700,1,14.52,200,2,14.55,200,2,14.56,800,2,14.6,700,1,14.63,100,1,ARL,331928009
1284,2025-07-17T16:07:00.057809857Z,2025-07-17T16:07:00.057644427Z,10,2,1108,C,A,6,14.55,100,0,165430,276613800,13.11,100,1,12.98,200,2,12.9,2,1,12.86,100,1,12.73,100,1,12.71,100,1,12.5,700,1,12.46,100,1,12.43,700,1,12.42,700,1,13.85,2,1,14.26,100,1,14.28,100,1,14.46,100,1,14.48,700,1,14.52,200,2,14.55,100,1,14.56,800,2,14.6,700,1,14.63,100,1,ARL,331052197
1285,2025-07-17T16:07:00.070490835Z,2025-07-17T16:07:00.070325784Z,10,2,1108,C,A,-1,14.26,100,130,165051,276614087,13.11,100,1,12.98,200,2,12.9,2,1,12.86,100,1,12.73,100,1,12.71,100,1,12.5,700,1,12.46,100,1,12.43,700,1,12.42,700,1,13.85,2,1,14.28,100,1,14.46,100,1,14.48,700,1,14.52,200,2,14.55,100,1,14.56,800,2,14.6,700,1,14.63,100,1,14.88,100,1,ARL,331928009
1286,2025-07-17T16:07:00.070539222Z,2025-07-17T16:07:00.070373975Z,10,2,1108,A,A,1,14.14,100,130,165247,276614089,13.11,100,1,12.98,200,2,12.9,2,1,12.86,100,1,12.73,100,1,12.71,100,1,12.5,700,1,12.46,100,1,12.43,700,1,12.42,700,1,13.85,2,1,14.14,100,1,14.28,100,1,14.46,100,1,14.48,700,1,14.52,200,2,14.55,100,1,14.56,800,2,14.6,700,1,14.63,100,1,ARL,331929033
1287,2025-07-17T16:07:00.071359350Z,2025-07-17T16:07:00.071194493Z,10,2,1108,C,A,-1,14.14,100,130,164857,276614094,13.11,100,1,12.98,200,2,12.9,2,1,12.86,100,1,12.73,100,1,12.71,100,1,12.5,700,1,12.46,100,1,12.43,700,1,12.42,700,1,13.85,2,1,14.28,100,1,14.46,100,1,14.48,700,1,14.52,200,2,14.55,100,1,14.56,800,2,14.6,700,1,14.63,100,1,14.88,100,1,ARL,331929033
1288,2025-07-17T16:07:00.071405105Z,2025-07-17T16:07:00.071239867Z,10,2,1108,A,A,1,14.26,100,130,165238,276614095,13.11,100,1,12.98,200,2,12.9,2,1,12.86,100,1,12.73,100,1,12.71,100,1,12.5,700,1,12.46,100,1,12.43,700,1,12.42,700,1,13.85,2,1,14.26,100,1,14.28,100,1,14.46,100,1,14.48,700,1,14.52,200,2,14.55,100,1,14.56,800,2,14.6,700,1,14.63,100,1,ARL,331929041
1289,2025-07-17T16:07:00.090359757Z,2025-07-17T16:07:00.090194106Z,10,2,1108,C,A,-1,14.55,100,0,165651,276614378,13.11,100,1,12.98,200,2,12.9,2,1,12.86,100,1,12.73,100,1,12.71,100,1,12.5,700,1,12.46,100,1,12.43,700,1,12.42,700,1,13.85,2,1,14.26,100,1,14.28,100,1,14.46,100,1,14.48,700,1,14.52,200,2,14.56,800,2,14.6,700,1,14.63,100,1,14.96,100,1,ARL,331051173
1290,2025-07-17T16:07:00.090359757Z,2025-07-17T16:07:00.090194106Z,10,2,1108,A,A,9,14.96,100,130,165651,276614378,13.11,100,1,12.98,200,2,12.9,2,1,12.86,100,1,12.73,100,1,12.71,100,1,12.5,700,1,12.46,100,1,12.43,700,1,12.42,700,1,13.85,2,1,14.26,100,1,14.28,100,1,14.46,100,1,14.48,700,1,14.52,200,2,14.56,800,2,14.6,700,1,14.63,100,1,14.96,200,2,ARL,331929633
1291,2025-07-17T16:07:00.102092147Z,2025-07-17T16:07:00.101927028Z,10,2,1108,A,A,9,14.68,700,130,165119,276614699,13.11,100,1,12.98,200,2,12.9,2,1,12.86,100,1,12.73,100,1,12.71,100,1,12.5,700,1,12.46,100,1,12.43,700,1,12.42,700,1,13.85,2,1,14.26,100,1,14.28,100,1,14.46,100,1,14.48,700,1,14.52,200,2,14.56,800,2,14.6,700,1,14.63,100,1,14.68,700,1,ARL,331929977
1292,2025-07-17T16:07:00.494657495Z,2025-07-17T16:07:00.494492099Z,10,2,1108,A,A,1,13.86,100,130,165396,276622423,13.11,100,1,12.98,200,2,12.9,2,1,12.86,100,1,12.73,100,1,12.71,100,1,12.5,700,1,12.46,100,1,12.43,700,1,12.42,700,1,13.85,2,1,13.86,100,1,14.26,100,1,14.28,100,1,14.46,100,1,14.48,700,1,14.52,200,2,14.56,800,2,14.6,700,1,14.63,100,1,ARL,331942821
1293,2025-07-17T16:07:00.495318245Z,2025-07-17T16:07:00.495152219Z,10,2,1108,A,B,7,12.49,100,130,166026,276622452,13.11,100,1,12.98,200,2,12.9,2,1,12.86,100,1,12.73,100,1,12.71,100,1,12.5,700,1,12.49,100,1,12.46,100,1,12.43,700,1,13.85,2,1,13.86,100,1,14.26,100,1,14.28,100,1,14.46,100,1,14.48,700,1,14.52,200,2,14.56,800,2,14.6,700,1,14.63,100,1,ARL,331942901
1294,2025-07-17T16:07:00.495989598Z,2025-07-17T16:07:00.495823953Z,10,2,1108,A,B,7,12.49,100,130,165645,276622469,13.11,100,1,12.98,200,2,12.9,2,1,12.86,100,1,12.73,100,1,12.71,100,1,12.5,700,1,12.49,200,2,12.46,100,1,12.43,700,1,13.85,2,1,13.86,100,1,14.26,100,1,14.28,100,1,14.46,100,1,14.48,700,1,14.52,200,2,14.56,800,2,14.6,700,1,14.63,100,1,ARL,331942945
1295,2025-07-17T16:07:00.499666149Z,2025-07-17T16:07:00.499501052Z,10,2,1108,C,A,-1,14.26,100,130,165097,276622569,13.11,100,1,12.98,200,2,12.9,2,1,12.86,100,1,12.73,100,1,12.71,100,1,12.5,700,1,12.49,200,2,12.46,100,1,12.43,700,1,13.85,2,1,13.86,100,1,14.28,100,1,14.46,100,1,14.48,700,1,14.52,200,2,14.56,800,2,14.6,700,1,14.63,100,1,14.68,700,1,ARL,331929041
1296,2025-07-17T16:07:00.499714918Z,2025-07-17T16:07:00.499549738Z,10,2,1108,A,A,2,14.14,100,130,165180,276622571,13.11,100,1,12.98,200,2,12.9,2,1,12.86,100,1,12.73,100,1,12.71,100,1,12.5,700,1,12.49,200,2,12.46,100,1,12.43,700,1,13.85,2,1,13.86,100,1,14.14,100,1,14.28,100,1,14.46,100,1,14.48,700,1,14.52,200,2,14.56,800,2,14.6,700,1,14.63,100,1,ARL,331943133
1297,2025-07-17T16:07:22.814941809Z,2025-07-17T16:07:22.814776694Z,10,2,1108,A,A,0,13.69,15,130,165115,276946179,13.11,100,1,12.98,200,2,12.9,2,1,12.86,100,1,12.73,100,1,12.71,100,1,12.5,700,1,12.49,200,2,12.46,100,1,12.43,700,1,13.69,15,1,13.85,2,1,13.86,100,1,14.14,100,1,14.28,100,1,14.46,100,1,14.48,700,1,14.52,200,2,14.56,800,2,14.6,700,1,ARL,332385317
1298,2025-07-17T16:07:22.815057507Z,2025-07-17T16:07:22.814891345Z,10,2,1108,C,A,-1,13.86,100,0,166162,276946183,13.11,100,1,12.98,200,2,12.9,2,1,12.86,100,1,12.73,100,1,12.71,100,1,12.5,700,1,12.49,200,2,12.46,100,1,12.43,700,1,13.69,15,1,13.85,2,1,14.14,100,1,14.28,100,1,14.46,100,1,14.48,700,1,14.52,200,2,14.56,800,2,14.6,700,1,14.63,100,1,ARL,331942821
1299,2025-07-17T16:07:22.815057507Z,2025-07-17T16:07:22.814891345Z,10,2,1108,A,A,1,13.7,100,130,166162,276946183,13.11,100,1,12.98,200,2,12.9,2,1,12.86,100,1,12.73,100,1,12.71,100,1,12.5,700,1,12.49,200,2,12.46,100,1,12.43,700,1,13.69,15,1,13.7,100,1,13.85,2,1,14.14,100,1,14.28,100,1,14.46,100,1,14.48,700,1,14.52,200,2,14.56,800,2,14.6,700,1,ARL,332385325
1300,2025-07-17T16:07:22.819772408Z,2025-07-17T16:07:22.819606945Z,10,2,1108,A,A,7,14.49,100,130,165463,276946337,13.11,100,1,12.98,200,2,12.9,2,1,12.86,100,1,12.73,100,1,12.71,100,1,12.5,700,1,12.49,200,2,12.46,100,1,12.43,700,1,13.69,15,1,13.7,100,1,13.85,2,1,14.14,100,1,14.28,100,1,14.46,100,1,14.48,700,1,14.49,100,1,14.52,200,2,14.56,800,2,ARL,332385597
1301,2025-07-17T16:07:22.821165451Z,2025-07-17T16:07:22.821000003Z,10,2,1108,C,A,-1,14.14,100,130,165448,276946343,13.11,100,1,12.98,200,2,12.9,2,1,12.86,100,1,12.73,100,1,12.71,100,1,12.5,700,1,12.49,200,2,12.46,100,1,12.43,700,1,13.69,15,1,13.7,100,1,13.85,2,1,14.28,100,1,14.46,100,1,14.48,700,1,14.49,100,1,14.52,200,2,14.56,800,2,14.6,700,1,ARL,331943133
1302,2025-07-17T16:07:22.821218207Z,2025-07-17T16:07:22.821052982Z,10,2,1108,A,A,3,13.97,100,130,165225,276946344,13.11,100,1,12.98,200,2,12.9,2,1,12.86,100,1,12.73,100,1,12.71,100,1,12.5,700,1,12.49,200,2,12.46,100,1,12.43,700,1,13.69,15,1,13.7,100,1,13.85,2,1,13.97,100,1,14.28,100,1,14.46,100,1,14.48,700,1,14.49,100,1,14.52,200,2,14.56,800,2,ARL,332385613
1303,2025-07-17T16:07:28.273823608Z,2025-07-17T16:07:28.273658191Z,10,2,1108,C,A,-1,13.69,15,130,165417,277012951,13.11,100,1,12.98,200,2,12.9,2,1,12.86,100,1,12.73,100,1,12.71,100,1,12.5,700,1,12.49,200,2,12.46,100,1,12.43,700,1,13.7,100,1,13.85,2,1,13.97,100,1,14.28,100,1,14.46,100,1,14.48,700,1,14.49,100,1,14.52,200,2,14.56,800,2,14.6,700,1,ARL,332385317
1304,2025-07-17T16:07:28.700981149Z,2025-07-17T16:07:28.700815737Z,10,2,1108,C,A,-1,13.7,100,130,165412,277019711,13.11,100,1,12.98,200,2,12.9,2,1,12.86,100,1,12.73,100,1,12.71,100,1,12.5,700,1,12.49,200,2,12.46,100,1,12.43,700,1,13.85,2,1,13.97,100,1,14.28,100,1,14.46,100,1,14.48,700,1,14.49,100,1,14.52,200,2,14.56,800,2,14.6,700,1,14.66,200,2,ARL,332385325
1305,2025-07-17T16:07:28.701396669Z,2025-07-17T16:07:28.701230409Z,10,2,1108,C,B,-1,12.9,2,0,166260,277019718,13.11,100,1,12.98,200,2,12.86,100,1,12.73,100,1,12.71,100,1,12.5,700,1,12.49,200,2,12.46,100,1,12.43,700,1,12.42,700,1,13.85,2,1,13.97,100,1,14.28,100,1,14.46,100,1,14.48,700,1,14.49,100,1,14.52,200,2,14.56,800,2,14.6,700,1,14.66,200,2,ARL,331694297
1306,2025-07-17T16:07:28.701396669Z,2025-07-17T16:07:28.701230409Z,10,2,1108,A,B,1,13.01,2,130,166260,277019718,13.11,100,1,13.01,2,1,12.98,200,2,12.86,100,1,12.73,100,1,12.71,100,1,12.5,700,1,12.49,200,2,12.46,100,1,12.43,700,1,13.85,2,1,13.97,100,1,14.28,100,1,14.46,100,1,14.48,700,1,14.49,100,1,14.52,200,2,14.56,800,2,14.6,700,1,14.66,200,2,ARL,332494213
1307,2025-07-17T16:07:28.702642020Z,2025-07-17T16:07:28.702476699Z,10,2,1108,C,A,9,14.66,100,0,165321,277019729,13.11,100,1,13.01,2,1,12.98,200,2,12.86,100,1,12.73,100,1,12.71,100,1,12.5,700,1,12.49,200,2,12.46,100,1,12.43,700,1,13.85,2,1,13.97,100,1,14.28,100,1,14.46,100,1,14.48,700,1,14.49,100,1,14.52,200,2,14.56,800,2,14.6,700,1,14.66,100,1,ARL,332386121
1308,2025-07-17T16:07:28.703523092Z,2025-07-17T16:07:28.703357714Z,10,2,1108,C,A,-1,14.66,100,0,165378,277019733,13.11,100,1,13.01,2,1,12.98,200,2,12.86,100,1,12.73,100,1,12.71,100,1,12.5,700,1,12.49,200,2,12.46,100,1,12.43,700,1,13.85,2,1,13.97,100,1,14.28,100,1,14.46,100,1,14.48,700,1,14.49,100,1,14.52,200,2,14.56,800,2,14.6,700,1,14.68,700,1,ARL,332385565
1309,2025-07-17T16:07:28.724201840Z,2025-07-17T16:07:28.724036175Z,10,2,1108,C,A,-1,13.97,100,130,165665,277019926,13.11,100,1,13.01,2,1,12.98,200,2,12.86,100,1,12.73,100,1,12.71,100,1,12.5,700,1,12.49,200,2,12.46,100,1,12.43,700,1,13.85,2,1,14.28,100,1,14.46,100,1,14.48,700,1,14.49,100,1,14.52,200,2,14.56,800,2,14.6,700,1,14.68,700,1,14.82,100,1,ARL,332385613
1310,2025-07-17T16:07:28.724250835Z,2025-07-17T16:07:28.724085453Z,10,2,1108,A,A,1,14.2,100,130,165382,277019929,13.11,100,1,13.01,2,1,12.98,200,2,12.86,100,1,12.73,100,1,12.71,100,1,12.5,700,1,12.49,200,2,12.46,100,1,12.43,700,1,13.85,2,1,14.2,100,1,14.28,100,1,14.46,100,1,14.48,700,1,14.49,100,1,14.52,200,2,14.56,800,2,14.6,700,1,14.68,700,1,ARL,332494893
1311,2025-07-17T16:07:28.831160987Z,2025-07-17T16:07:28.830995364Z,10,2,1108,C,A,-1,14.49,100,130,165623,277021007,13.11,100,1,13.01,2,1,12.98,200,2,12.86,100,1,12.73,100,1,12.71,100,1,12.5,700,1,12.49,200,2,12.46,100,1,12.43,700,1,13.85,2,1,14.2,100,1,14.28,100,1,14.46,100,1,14.48,700,1,14.52,200,2,14.56,800,2,14.6,700,1,14.68,700,1,14.95,200,2,ARL,332385597
1312,2025-07-17T16:07:28.831291377Z,2025-07-17T16:07:28.831125667Z,10,2,1108,A,A,9,14.77,100,130,165710,277021012,13.11,100,1,13.01,2,1,12.98,200,2,12.86,100,1,12.73,100,1,12.71,100,1,12.5,700,1,12.49,200,2,12.46,100,1,12.43,700,1,13.85,2,1,14.2,100,1,14.28,100,1,14.46,100,1,14.48,700,1,14.52,200,2,14.56,800,2,14.6,700,1,14.68,700,1,14.77,100,1,ARL,332497653
1313,2025-07-17T16:07:29.214667270Z,2025-07-17T16:07:29.214500816Z,10,2,1108,A,A,1,13.86,100,128,166454,277029015,13.11,100,1,13.01,2,1,12.98,200,2,12.86,100,1,12.73,100,1,12.71,100,1,12.5,700,1,12.49,200,2,12.46,100,1,12.43,700,1,13.85,2,1,13.86,100,1,14.2,100,1,14.28,100,1,14.46,100,1,14.48,700,1,14.52,200,2,14.56,800,2,14.6,700,1,14.68,700,1,ARL,332508813
1314,2025-07-17T16:08:20.816252850Z,2025-07-17T16:08:20.816087447Z,10,2,1108,A,A,0,13.68,15,130,165403,277732167,13.11,100,1,13.01,2,1,12.98,200,2,12.86,100,1,12.73,100,1,12.71,100,1,12.5,700,1,12.49,200,2,12.46,100,1,12.43,700,1,13.68,15,1,13.85,2,1,13.86,100,1,14.2,100,1,14.28,100,1,14.46,100,1,14.48,700,1,14.52,200,2,14.56,800,2,14.6,700,1,ARL,333436357
1315,2025-07-17T16:08:20.816366205Z,2025-07-17T16:08:20.816200644Z,10,2,1108,C,A,-1,13.86,100,0,165561,277732170,13.11,100,1,13.01,2,1,12.98,200,2,12.86,100,1,12.73,100,1,12.71,100,1,12.5,700,1,12.49,200,2,12.46,100,1,12.43,700,1,13.68,15,1,13.85,2,1,14.2,100,1,14.28,100,1,14.46,100,1,14.48,700,1,14.52,200,2,14.56,800,2,14.6,700,1,14.68,700,1,ARL,332508813
1316,2025-07-17T16:08:20.816366205Z,2025-07-17T16:08:20.816200644Z,10,2,1108,A,A,1,13.69,100,130,165561,277732170,13.11,100,1,13.01,2,1,12.98,200,2,12.86,100,1,12.73,100,1,12.71,100,1,12.5,700,1,12.49,200,2,12.46,100,1,12.43,700,1,13.68,15,1,13.69,100,1,13.85,2,1,14.2,100,1,14.28,100,1,14.46,100,1,14.48,700,1,14.52,200,2,14.56,800,2,14.6,700,1,ARL,333436361
1317,2025-07-17T16:08:20.822089544Z,2025-07-17T16:08:20.821924168Z,10,2,1108,C,A,-1,14.2,100,130,165376,277732239,13.11,100,1,13.01,2,1,12.98,200,2,12.86,100,1,12.73,100,1,12.71,100,1,12.5,700,1,12.49,200,2,12.46,100,1,12.43,700,1,13.68,15,1,13.69,100,1,13.85,2,1,14.28,100,1,14.46,100,1,14.48,700,1,14.52,200,2,14.56,800,2,14.6,700,1,14.65,100,1,ARL,332494893
1318,2025-07-17T16:08:20.822139541Z,2025-07-17T16:08:20.821974299Z,10,2,1108,A,A,3,13.96,100,130,165242,277732240,13.11,100,1,13.01,2,1,12.98,200,2,12.86,100,1,12.73,100,1,12.71,100,1,12.5,700,1,12.49,200,2,12.46,100,1,12.43,700,1,13.68,15,1,13.69,100,1,13.85,2,1,13.96,100,1,14.28,100,1,14.46,100,1,14.48,700,1,14.52,200,2,14.56,800,2,14.6,700,1,ARL,333436473
1319,2025-07-17T16:08:20.966229266Z,2025-07-17T16:08:20.966063681Z,10,2,1108,A,A,6,14.48,100,130,165585,277733304,13.11,100,1,13.01,2,1,12.98,200,2,12.86,100,1,12.73,100,1,12.71,100,1,12.5,700,1,12.49,200,2,12.46,100,1,12.43,700,1,13.68,15,1,13.69,100,1,13.85,2,1,13.96,100,1,14.28,100,1,14.46,100,1,14.48,800,2,14.52,200,2,14.56,800,2,14.6,700,1,ARL,333438545
1320,2025-07-17T16:08:22.998168186Z,2025-07-17T16:08:22.998002821Z,10,2,1108,C,A,-1,13.68,15,130,165365,277766492,13.11,100,1,13.01,2,1,12.98,200,2,12.86,100,1,12.73,100,1,12.71,100,1,12.5,700,1,12.49,200,2,12.46,100,1,12.43,700,1,13.69,100,1,13.85,2,1,13.96,100,1,14.28,100,1,14.46,100,1,14.48,800,2,14.52,200,2,14.56,800,2,14.6,700,1,14.65,200,2,ARL,333436357
1321,2025-07-17T16:08:27.482509684Z,2025-07-17T16:08:27.482344236Z,10,2,1108,C,A,-1,13.69,100,130,165448,277841171,13.11,100,1,13.01,2,1,12.98,200,2,12.86,100,1,12.73,100,1,12.71,100,1,12.5,700,1,12.49,200,2,12.46,100,1,12.43,700,1,13.85,2,1,13.96,100,1,14.28,100,1,14.46,100,1,14.48,800,2,14.52,200,2,14.56,800,2,14.6,700,1,14.65,200,2,14.68,700,1,ARL,333436361
1322,2025-07-17T16:08:27.483585892Z,2025-07-17T16:08:27.483420069Z,10,2,1108,C,A,5,14.52,100,0,165823,277841178,13.11,100,1,13.01,2,1,12.98,200,2,12.86,100,1,12.73,100,1,12.71,100,1,12.5,700,1,12.49,200,2,12.46,100,1,12.43,700,1,13.85,2,1,13.96,100,1,14.28,100,1,14.46,100,1,14.48,800,2,14.52,100,1,14.56,800,2,14.6,700,1,14.65,200,2,14.68,700,1,ARL,328780577
1323,2025-07-17T16:08:27.484079224Z,2025-07-17T16:08:27.483913735Z,10,2,1108,C,A,8,14.65,100,0,165489,277841218,13.11,100,1,13.01,2,1,12.98,200,2,12.86,100,1,12.73,100,1,12.71,100,1,12.5,700,1,12.49,200,2,12.46,100,1,12.43,700,1,13.85,2,1,13.96,100,1,14.28,100,1,14.46,100,1,14.48,800,2,14.52,100,1,14.56,800,2,14.6,700,1,14.65,100,1,14.68,700,1,ARL,333436589
1324,2025-07-17T16:08:27.484965957Z,2025-07-17T16:08:27.484800296Z,10,2,1108,C,A,-1,14.65,100,0,165661,277841228,13.11,100,1,13.01,2,1,12.98,200,2,12.86,100,1,12.73,100,1,12.71,100,1,12.5,700,1,12.49,200,2,12.46,100,1,12.43,700,1,13.85,2,1,13.96,100,1,14.28,100,1,14.46,100,1,14.48,800,2,14.52,100,1,14.56,800,2,14.6,700,1,14.68,700,1,14.74,100,1,ARL,333436425
1325,2025-07-17T16:08:27.487263276Z,2025-07-17T16:08:27.487097702Z,10,2,1108,C,A,-1,14.52,100,0,165574,277841319,13.11,100,1,13.01,2,1,12.98,200,2,12.86,100,1,12.73,100,1,12.71,100,1,12.5,700,1,12.49,200,2,12.46,100,1,12.43,700,1,13.85,2,1,13.96,100,1,14.28,100,1,14.46,100,1,14.48,800,2,14.56,800,2,14.6,700,1,14.68,700,1,14.74,100,1,14.94,200,2,ARL,328780597
1326,2025-07-17T16:08:27.487263276Z,2025-07-17T16:08:27.487097702Z,10,2,1108,A,A,8,14.74,100,130,165574,277841319,13.11,100,1,13.01,2,1,12.98,200,2,12.86,100,1,12.73,100,1,12.71,100,1,12.5,700,1,12.49,200,2,12.46,100,1,12.43,700,1,13.85,2,1,13.96,100,1,14.28,100,1,14.46,100,1,14.48,800,2,14.56,800,2,14.6,700,1,14.68,700,1,14.74,200,2,14.94,200,2,ARL,333581481
1327,2025-07-17T16:08:27.492258906Z,2025-07-17T16:08:27.492093401Z,10,2,1108,C,A,4,14.48,100,130,165505,277841396,13.11,100,1,13.01,2,1,12.98,200,2,12.86,100,1,12.73,100,1,12.71,100,1,12.5,700,1,12.49,200,2,12.46,100,1,12.43,700,1,13.85,2,1,13.96,100,1,14.28,100,1,14.46,100,1,14.48,700,1,14.56,800,2,14.6,700,1,14.68,700,1,14.74,200,2,14.94,200,2,ARL,333438545
1328,2025-07-17T16:08:27.492385750Z,2025-07-17T16:08:27.492220454Z,10,2,1108,A,A,9,14.75,100,130,165296,277841397,13.11,100,1,13.01,2,1,12.98,200,2,12.86,100,1,12.73,100,1,12.71,100,1,12.5,700,1,12.49,200,2,12.46,100,1,12.43,700,1,13.85,2,1,13.96,100,1,14.28,100,1,14.46,100,1,14.48,700,1,14.56,800,2,14.6,700,1,14.68,700,1,14.74,200,2,14.75,100,1,ARL,333581569
1329,2025-07-17T16:08:27.496936122Z,2025-07-17T16:08:27.496770678Z,10,2,1108,C,A,-1,13.96,100,130,165444,277841427,13.11,100,1,13.01,2,1,12.98,200,2,12.86,100,1,12.73,100,1,12.71,100,1,12.5,700,1,12.49,200,2,12.46,100,1,12.43,700,1,13.85,2,1,14.28,100,1,14.46,100,1,14.48,700,1,14.56,800,2,14.6,700,1,14.68,700,1,14.74,200,2,14.75,100,1,14.94,200,2,ARL,333436473
1330,2025-07-17T16:08:27.496987832Z,2025-07-17T16:08:27.496822540Z,10,2,1108,A,A,1,14.19,100,130,165292,277841428,13.11,100,1,13.01,2,1,12.98,200,2,12.86,100,1,12.73,100,1,12.71,100,1,12.5,700,1,12.49,200,2,12.46,100,1,12.43,700,1,13.85,2,1,14.19,100,1,14.28,100,1,14.46,100,1,14.48,700,1,14.56,800,2,14.6,700,1,14.68,700,1,14.74,200,2,14.75,100,1,ARL,333581625
1331,2025-07-17T16:08:27.501093618Z,2025-07-17T16:08:27.500928061Z,10,2,1108,C,A,-1,13.85,2,0,165557,277841469,13.11,100,1,13.01,2,1,12.98,200,2,12.86,100,1,12.73,100,1,12.71,100,1,12.5,700,1,12.49,200,2,12.46,100,1,12.43,700,1,14.19,100,1,14.28,100,1,14.46,100,1,14.48,700,1,14.56,800,2,14.6,700,1,14.68,700,1,14.74,200,2,14.75,100,1,14.94,200,2,ARL,331155889
1332,2025-07-17T16:08:27.501093618Z,2025-07-17T16:08:27.500928061Z,10,2,1108,A,A,0,13.98,2,130,165557,277841469,13.11,100,1,13.01,2,1,12.98,200,2,12.86,100,1,12.73,100,1,12.71,100,1,12.5,700,1,12.49,200,2,12.46,100,1,12.43,700,1,13.98,2,1,14.19,100,1,14.28,100,1,14.46,100,1,14.48,700,1,14.56,800,2,14.6,700,1,14.68,700,1,14.74,200,2,14.75,100,1,ARL,333581677
1333,2025-07-17T16:08:27.516614373Z,2025-07-17T16:08:27.516449334Z,10,2,1108,C,A,-1,14.19,100,130,165039,277841551,13.11,100,1,13.01,2,1,12.98,200,2,12.86,100,1,12.73,100,1,12.71,100,1,12.5,700,1,12.49,200,2,12.46,100,1,12.43,700,1,13.98,2,1,14.28,100,1,14.46,100,1,14.48,700,1,14.56,800,2,14.6,700,1,14.68,700,1,14.74,200,2,14.75,100,1,14.94,200,2,ARL,333581625
1334,2025-07-17T16:08:27.516662099Z,2025-07-17T16:08:27.516496962Z,10,2,1108,A,A,1,14.26,100,130,165137,277841552,13.11,100,1,13.01,2,1,12.98,200,2,12.86,100,1,12.73,100,1,12.71,100,1,12.5,700,1,12.49,200,2,12.46,100,1,12.43,700,1,13.98,2,1,14.26,100,1,14.28,100,1,14.46,100,1,14.48,700,1,14.56,800,2,14.6,700,1,14.68,700,1,14.74,200,2,14.75,100,1,ARL,333581765
1335,2025-07-17T16:08:27.987678739Z,2025-07-17T16:08:27.987513451Z,10,2,1108,A,A,1,13.99,100,130,165288,277846288,13.11,100,1,13.01,2,1,12.98,200,2,12.86,100,1,12.73,100,1,12.71,100,1,12.5,700,1,12.49,200,2,12.46,100,1,12.43,700,1,13.98,2,1,13.99,100,1,14.26,100,1,14.28,100,1,14.46,100,1,14.48,700,1,14.56,800,2,14.6,700,1,14.68,700,1,14.74,200,2,ARL,333590057
1336,2025-07-17T16:08:58.024979382Z,2025-07-17T16:08:58.024814068Z,10,2,1108,A,A,0,13.81,15,130,165314,278261182,13.11,100,1,13.01,2,1,12.98,200,2,12.86,100,1,12.73,100,1,12.71,100,1,12.5,700,1,12.49,200,2,12.46,100,1,12.43,700,1,13.81,15,1,13.98,2,1,13.99,100,1,14.26,100,1,14.28,100,1,14.46,100,1,14.48,700,1,14.56,800,2,14.6,700,1,14.68,700,1,ARL,334141429
1337,2025-07-17T16:09:00.222675234Z,2025-07-17T16:09:00.222509491Z,10,2,1108,C,A,-1,13.99,100,0,165743,278295684,13.11,100,1,13.01,2,1,12.98,200,2,12.86,100,1,12.73,100,1,12.71,100,1,12.5,700,1,12.49,200,2,12.46,100,1,12.43,700,1,13.81,15,1,13.98,2,1,14.26,100,1,14.28,100,1,14.46,100,1,14.48,700,1,14.56,800,2,14.6,700,1,14.68,700,1,14.74,200,2,ARL,333590057
1338,2025-07-17T16:09:00.222675234Z,2025-07-17T16:09:00.222509491Z,10,2,1108,A,A,1,13.82,100,130,165743,278295684,13.11,100,1,13.01,2,1,12.98,200,2,12.86,100,1,12.73,100,1,12.71,100,1,12.5,700,1,12.49,200,2,12.46,100,1,12.43,700,1,13.81,15,1,13.82,100,1,13.98,2,1,14.26,100,1,14.28,100,1,14.46,100,1,14.48,700,1,14.56,800,2,14.6,700,1,14.68,700,1,ARL,334189729
1339,2025-07-17T16:09:00.226504346Z,2025-07-17T16:09:00.226338384Z,10,2,1108,A,A,9,14.61,100,130,165962,278296281,13.11,100,1,13.01,2,1,12.98,200,2,12.86,100,1,12.73,100,1,12.71,100,1,12.5,700,1,12.49,200,2,12.46,100,1,12.43,700,1,13.81,15,1,13.82,100,1,13.98,2,1,14.26,100,1,14.28,100,1,14.46,100,1,14.48,700,1,14.56,800,2,14.6,700,1,14.61,100,1,ARL,334190189
1340,2025-07-17T16:09:00.227929061Z,2025-07-17T16:09:00.227763275Z,10,2,1108,C,A,-1,14.26,100,130,165786,278296402,13.11,100,1,13.01,2,1,12.98,200,2,12.86,100,1,12.73,100,1,12.71,100,1,12.5,700,1,12.49,200,2,12.46,100,1,12.43,700,1,13.81,15,1,13.82,100,1,13.98,2,1,14.28,100,1,14.46,100,1,14.48,700,1,14.56,800,2,14.6,700,1,14.61,100,1,14.68,700,1,ARL,333581765
1341,2025-07-17T16:09:00.227983483Z,2025-07-17T16:09:00.227818153Z,10,2,1108,A,A,3,14.1,100,130,165330,278296411,13.11,100,1,13.01,2,1,12.98,200,2,12.86,100,1,12.73,100,1,12.71,100,1,12.5,700,1,12.49,200,2,12.46,100,1,12.43,700,1,13.81,15,1,13.82,100,1,13.98,2,1,14.1,100,1,14.28,100,1,14.46,100,1,14.48,700,1,14.56,800,2,14.6,700,1,14.61,100,1,ARL,334190225
1342,2025-07-17T16:09:08.719690693Z,2025-07-17T16:09:08.719524374Z,10,2,1108,A,A,0,13.75,15,130,166319,278436950,13.11,100,1,13.01,2,1,12.98,200,2,12.86,100,1,12.73,100,1,12.71,100,1,12.5,700,1,12.49,200,2,12.46,100,1,12.43,700,1,13.75,15,1,13.81,15,1,13.82,100,1,13.98,2,1,14.1,100,1,14.28,100,1,14.46,100,1,14.48,700,1,14.56,800,2,14.6,700,1,ARL,334366613
1343,2025-07-17T16:09:08.719871410Z,2025-07-17T16:09:08.719706070Z,10,2,1108,C,A,-1,13.82,100,0,165340,278436967,13.11,100,1,13.01,2,1,12.98,200,2,12.86,100,1,12.73,100,1,12.71,100,1,12.5,700,1,12.49,200,2,12.46,100,1,12.43,700,1,13.75,15,1,13.81,15,1,13.98,2,1,14.1,100,1,14.28,100,1,14.46,100,1,14.48,700,1,14.56,800,2,14.6,700,1,14.61,100,1,ARL,334189729
1344,2025-07-17T16:09:08.719871410Z,2025-07-17T16:09:08.719706070Z,10,2,1108,A,A,1,13.76,100,130,165340,278436967,13.11,100,1,13.01,2,1,12.98,200,2,12.86,100,1,12.73,100,1,12.71,100,1,12.5,700,1,12.49,200,2,12.46,100,1,12.43,700,1,13.75,15,1,13.76,100,1,13.81,15,1,13.98,2,1,14.1,100,1,14.28,100,1,14.46,100,1,14.48,700,1,14.56,800,2,14.6,700,1,ARL,334366617
1345,2025-07-17T16:09:18.819300735Z,2025-07-17T16:09:18.819135505Z,10,2,1108,C,A,-1,13.81,15,130,165230,278596985,13.11,100,1,13.01,2,1,12.98,200,2,12.86,100,1,12.73,100,1,12.71,100,1,12.5,700,1,12.49,200,2,12.46,100,1,12.43,700,1,13.75,15,1,13.76,100,1,13.98,2,1,14.1,100,1,14.28,100,1,14.46,100,1,14.48,700,1,14.56,800,2,14.6,700,1,14.61,100,1,ARL,334141429
1346,2025-07-17T16:09:19.927205023Z,2025-07-17T16:09:19.927039122Z,10,2,1108,A,A,0,13.73,15,130,165901,278621672,13.11,100,1,13.01,2,1,12.98,200,2,12.86,100,1,12.73,100,1,12.71,100,1,12.5,700,1,12.49,200,2,12.46,100,1,12.43,700,1,13.73,15,1,13.75,15,1,13.76,100,1,13.98,2,1,14.1,100,1,14.28,100,1,14.46,100,1,14.48,700,1,14.56,800,2,14.6,700,1,ARL,334583329
1347,2025-07-17T16:09:20.284861075Z,2025-07-17T16:09:20.284695585Z,10,2,1108,C,A,-1,13.76,100,0,165490,278629057,13.11,100,1,13.01,2,1,12.98,200,2,12.86,100,1,12.73,100,1,12.71,100,1,12.5,700,1,12.49,200,2,12.46,100,1,12.43,700,1,13.73,15,1,13.75,15,1,13.98,2,1,14.1,100,1,14.28,100,1,14.46,100,1,14.48,700,1,14.56,800,2,14.6,700,1,14.61,100,1,ARL,334366617
1348,2025-07-17T16:09:20.284861075Z,2025-07-17T16:09:20.284695585Z,10,2,1108,A,A,1,13.74,100,130,165490,278629057,13.11,100,1,13.01,2,1,12.98,200,2,12.86,100,1,12.73,100,1,12.71,100,1,12.5,700,1,12.49,200,2,12.46,100,1,12.43,700,1,13.73,15,1,13.74,100,1,13.75,15,1,13.98,2,1,14.1,100,1,14.28,100,1,14.46,100,1,14.48,700,1,14.56,800,2,14.6,700,1,ARL,334593569
1349,2025-07-17T16:09:20.293271620Z,2025-07-17T16:09:20.293106270Z,10,2,1108,C,A,-1,14.1,100,130,165350,278629219,13.11,100,1,13.01,2,1,12.98,200,2,12.86,100,1,12.73,100,1,12.71,100,1,12.5,700,1,12.49,200,2,12.46,100,1,12.43,700,1,13.73,15,1,13.74,100,1,13.75,15,1,13.98,2,1,14.28,100,1,14.46,100,1,14.48,700,1,14.56,800,2,14.6,700,1,14.61,100,1,ARL,334190225
1350,2025-07-17T16:09:20.293326641Z,2025-07-17T16:09:20.293161454Z,10,2,1108,A,A,4,14.01,100,130,165187,278629220,13.11,100,1,13.01,2,1,12.98,200,2,12.86,100,1,12.73,100,1,12.71,100,1,12.5,700,1,12.49,200,2,12.46,100,1,12.43,700,1,13.73,15,1,13.74,100,1,13.75,15,1,13.98,2,1,14.01,100,1,14.28,100,1,14.46,100,1,14.48,700,1,14.56,800,2,14.6,700,1,ARL,334593753
1351,2025-07-17T16:09:20.818813935Z,2025-07-17T16:09:20.818648795Z,10,2,1108,C,A,-1,13.73,15,130,165140,278640667,13.11,100,1,13.01,2,1,12.98,200,2,12.86,100,1,12.73,100,1,12.71,100,1,12.5,700,1,12.49,200,2,12.46,100,1,12.43,700,1,13.74,100,1,13.75,15,1,13.98,2,1,14.01,100,1,14.28,100,1,14.46,100,1,14.48,700,1,14.56,800,2,14.6,700,1,14.61,100,1,ARL,334583329
1352,2025-07-17T16:09:20.818926356Z,2025-07-17T16:09:20.818761228Z,10,2,1108,C,A,-1,13.75,15,130,165128,278640670,13.11,100,1,13.01,2,1,12.98,200,2,12.86,100,1,12.73,100,1,12.71,100,1,12.5,700,1,12.49,200,2,12.46,100,1,12.43,700,1,13.74,100,1,13.98,2,1,14.01,100,1,14.28,100,1,14.46,100,1,14.48,700,1,14.56,800,2,14.6,700,1,14.61,100,1,14.62,200,2,ARL,334366613
1353,2025-07-17T16:09:28.986122432Z,2025-07-17T16:09:28.985956629Z,10,2,1108,C,A,-1,13.98,2,0,165803,278784943,13.11,100,1,13.01,2,1,12.98,200,2,12.86,100,1,12.73,100,1,12.71,100,1,12.5,700,1,12.49,200,2,12.46,100,1,12.43,700,1,13.74,100,1,14.01,100,1,14.28,100,1,14.46,100,1,14.48,700,1,14.56,800,2,14.6,700,1,14.61,100,1,14.62,200,2,14.68,700,1,ARL,333581677
1354,2025-07-17T16:09:28.986122432Z,2025-07-17T16:09:28.985956629Z,10,2,1108,A,A,1,13.9,2,130,165803,278784943,13.11,100,1,13.01,2,1,12.98,200,2,12.86,100,1,12.73,100,1,12.71,100,1,12.5,700,1,12.49,200,2,12.46,100,1,12.43,700,1,13.74,100,1,13.9,2,1,14.01,100,1,14.28,100,1,14.46,100,1,14.48,700,1,14.56,800,2,14.6,700,1,14.61,100,1,14.62,200,2,ARL,334804177
1355,2025-07-17T16:09:40.821687905Z,2025-07-17T16:09:40.821522565Z,10,2,1108,A,A,0,13.7,15,130,165340,278938091,13.11,100,1,13.01,2,1,12.98,200,2,12.86,100,1,12.73,100,1,12.71,100,1,12.5,700,1,12.49,200,2,12.46,100,1,12.43,700,1,13.7,15,1,13.74,100,1,13.9,2,1,14.01,100,1,14.28,100,1,14.46,100,1,14.48,700,1,14.56,800,2,14.6,700,1,14.61,100,1,ARL,335003269
1356,2025-07-17T16:09:40.853604577Z,2025-07-17T16:09:40.853439053Z,10,2,1108,C,A,-1,13.74,100,0,165524,278938747,13.11,100,1,13.01,2,1,12.98,200,2,12.86,100,1,12.73,100,1,12.71,100,1,12.5,700,1,12.49,200,2,12.46,100,1,12.43,700,1,13.7,15,1,13.9,2,1,14.01,100,1,14.28,100,1,14.46,100,1,14.48,700,1,14.56,800,2,14.6,700,1,14.61,100,1,14.62,200,2,ARL,334593569
1357,2025-07-17T16:09:40.853604577Z,2025-07-17T16:09:40.853439053Z,10,2,1108,A,A,1,13.71,100,130,165524,278938747,13.11,100,1,13.01,2,1,12.98,200,2,12.86,100,1,12.73,100,1,12.71,100,1,12.5,700,1,12.49,200,2,12.46,100,1,12.43,700,1,13.7,15,1,13.71,100,1,13.9,2,1,14.01,100,1,14.28,100,1,14.46,100,1,14.48,700,1,14.56,800,2,14.6,700,1,14.61,100,1,ARL,335003813
1358,2025-07-17T16:09:50.820949131Z,2025-07-17T16:09:50.820783486Z,10,2,1108,A,A,0,13.67,15,130,165645,279081140,13.11,100,1,13.01,2,1,12.98,200,2,12.86,100,1,12.73,100,1,12.71,100,1,12.5,700,1,12.49,200,2,12.46,100,1,12.43,700,1,13.67,15,1,13.7,15,1,13.71,100,1,13.9,2,1,14.01,100,1,14.28,100,1,14.46,100,1,14.48,700,1,14.56,800,2,14.6,700,1,ARL,335178437
1359,2025-07-17T16:09:52.678777358Z,2025-07-17T16:09:52.678611805Z,10,2,1108,C,A,-1,13.71,100,0,165553,279109959,13.11,100,1,13.01,2,1,12.98,200,2,12.86,100,1,12.73,100,1,12.71,100,1,12.5,700,1,12.49,200,2,12.46,100,1,12.43,700,1,13.67,15,1,13.7,15,1,13.9,2,1,14.01,100,1,14.28,100,1,14.46,100,1,14.48,700,1,14.56,800,2,14.6,700,1,14.61,100,1,ARL,335003813
1360,2025-07-17T16:09:52.678777358Z,2025-07-17T16:09:52.678611805Z,10,2,1108,A,A,1,13.68,100,130,165553,279109959,13.11,100,1,13.01,2,1,12.98,200,2,12.86,100,1,12.73,100,1,12.71,100,1,12.5,700,1,12.49,200,2,12.46,100,1,12.43,700,1,13.67,15,1,13.68,100,1,13.7,15,1,13.9,2,1,14.01,100,1,14.28,100,1,14.46,100,1,14.48,700,1,14.56,800,2,14.6,700,1,ARL,335220349
1361,2025-07-17T16:09:52.682127530Z,2025-07-17T16:09:52.681961200Z,10,2,1108,A,A,7,14.47,100,130,166330,279110068,13.11,100,1,13.01,2,1,12.98,200,2,12.86,100,1,12.73,100,1,12.71,100,1,12.5,700,1,12.49,200,2,12.46,100,1,12.43,700,1,13.67,15,1,13.68,100,1,13.7,15,1,13.9,2,1,14.01,100,1,14.28,100,1,14.46,100,1,14.47,100,1,14.48,700,1,14.56,800,2,ARL,335220561
1362,2025-07-17T16:10:04.521471804Z,2025-07-17T16:10:04.521306513Z,10,2,1108,C,A,-1,13.67,15,130,165291,279306715,13.11,100,1,13.01,2,1,12.98,200,2,12.86,100,1,12.73,100,1,12.71,100,1,12.5,700,1,12.49,200,2,12.46,100,1,12.43,700,1,13.68,100,1,13.7,15,1,13.9,2,1,14.01,100,1,14.28,100,1,14.46,100,1,14.47,100,1,14.48,700,1,14.56,800,2,14.6,700,1,ARL,335178437
1363,2025-07-17T16:10:04.561854856Z,2025-07-17T16:10:04.561688313Z,10,2,1108,C,A,-1,13.7,15,128,166543,279312083,13.11,100,1,13.01,2,1,12.98,200,2,12.86,100,1,12.73,100,1,12.71,100,1,12.5,700,1,12.49,200,2,12.46,100,1,12.43,700,1,13.68,100,1,13.9,2,1,14.01,100,1,14.28,100,1,14.46,100,1,14.47,100,1,14.48,700,1,14.56,800,2,14.6,700,1,14.62,200,2,ARL,335003269
1364,2025-07-17T16:10:32.822660498Z,2025-07-17T16:10:32.822495087Z,10,2,1108,A,A,0,13.65,15,130,165411,279705339,13.11,100,1,13.01,2,1,12.98,200,2,12.86,100,1,12.73,100,1,12.71,100,1,12.5,700,1,12.49,200,2,12.46,100,1,12.43,700,1,13.65,15,1,13.68,100,1,13.9,2,1,14.01,100,1,14.28,100,1,14.46,100,1,14.47,100,1,14.48,700,1,14.56,800,2,14.6,700,1,ARL,335996705
1365,2025-07-17T16:10:32.822923138Z,2025-07-17T16:10:32.822757517Z,10,2,1108,C,A,-1,13.68,100,0,165621,279705347,13.11,100,1,13.01,2,1,12.98,200,2,12.86,100,1,12.73,100,1,12.71,100,1,12.5,700,1,12.49,200,2,12.46,100,1,12.43,700,1,13.65,15,1,13.9,2,1,14.01,100,1,14.28,100,1,14.46,100,1,14.47,100,1,14.48,700,1,14.56,800,2,14.6,700,1,14.62,200,2,ARL,335220349
1366,2025-07-17T16:10:32.822923138Z,2025-07-17T16:10:32.822757517Z,10,2,1108,A,A,1,13.66,100,130,165621,279705347,13.11,100,1,13.01,2,1,12.98,200,2,12.86,100,1,12.73,100,1,12.71,100,1,12.5,700,1,12.49,200,2,12.46,100,1,12.43,700,1,13.65,15,1,13.66,100,1,13.9,2,1,14.01,100,1,14.28,100,1,14.46,100,1,14.47,100,1,14.48,700,1,14.56,800,2,14.6,700,1,ARL,335996709
1367,2025-07-17T16:10:32.830200844Z,2025-07-17T16:10:32.830032662Z,10,2,1108,C,A,-1,14.01,100,130,168182,279705485,13.11,100,1,13.01,2,1,12.98,200,2,12.86,100,1,12.73,100,1,12.71,100,1,12.5,700,1,12.49,200,2,12.46,100,1,12.43,700,1,13.65,15,1,13.66,100,1,13.9,2,1,14.28,100,1,14.46,100,1,14.47,100,1,14.48,700,1,14.56,800,2,14.6,700,1,14.62,200,2,ARL,334593753
1368,2025-07-17T16:10:32.830250720Z,2025-07-17T16:10:32.830085472Z,10,2,1108,A,A,3,13.93,100,130,165248,279705486,13.11,100,1,13.01,2,1,12.98,200,2,12.86,100,1,12.73,100,1,12.71,100,1,12.5,700,1,12.49,200,2,12.46,100,1,12.43,700,1,13.65,15,1,13.66,100,1,13.9,2,1,13.93,100,1,14.28,100,1,14.46,100,1,14.47,100,1,14.48,700,1,14.56,800,2,14.6,700,1,ARL,335996777
1369,2025-07-17T16:10:42.822354869Z,2025-07-17T16:10:42.822189504Z,10,2,1108,A,A,0,13.63,15,130,165365,279834760,13.11,100,1,13.01,2,1,12.98,200,2,12.86,100,1,12.73,100,1,12.71,100,1,12.5,700,1,12.49,200,2,12.46,100,1,12.43,700,1,13.63,15,1,13.65,15,1,13.66,100,1,13.9,2,1,13.93,100,1,14.28,100,1,14.46,100,1,14.47,100,1,14.48,700,1,14.56,800,2,ARL,336161333
1370,2025-07-17T16:10:42.822424663Z,2025-07-17T16:10:42.822258887Z,10,2,1108,C,A,-1,13.66,100,0,165776,279834761,13.11,100,1,13.01,2,1,12.98,200,2,12.86,100,1,12.73,100,1,12.71,100,1,12.5,700,1,12.49,200,2,12.46,100,1,12.43,700,1,13.63,15,1,13.65,15,1,13.9,2,1,13.93,100,1,14.28,100,1,14.46,100,1,14.47,100,1,14.48,700,1,14.56,800,2,14.6,700,1,ARL,335996709
1371,2025-07-17T16:10:42.822424663Z,2025-07-17T16:10:42.822258887Z,10,2,1108,A,A,1,13.64,100,130,165776,279834761,13.11,100,1,13.01,2,1,12.98,200,2,12.86,100,1,12.73,100,1,12.71,100,1,12.5,700,1,12.49,200,2,12.46,100,1,12.43,700,1,13.63,15,1,13.64,100,1,13.65,15,1,13.9,2,1,13.93,100,1,14.28,100,1,14.46,100,1,14.47,100,1,14.48,700,1,14.56,800,2,ARL,336161337
1372,2025-07-17T16:10:42.823163929Z,2025-07-17T16:10:42.822998664Z,10,2,1108,C,A,-1,14.46,100,130,165265,279834765,13.11,100,1,13.01,2,1,12.98,200,2,12.86,100,1,12.73,100,1,12.71,100,1,12.5,700,1,12.49,200,2,12.46,100,1,12.43,700,1,13.63,15,1,13.64,100,1,13.65,15,1,13.9,2,1,13.93,100,1,14.28,100,1,14.47,100,1,14.48,700,1,14.56,800,2,14.6,700,1,ARL,331927161
1373,2025-07-17T16:10:42.823517444Z,2025-07-17T16:10:42.823352130Z,10,2,1108,A,A,5,14.25,100,130,165314,279834767,13.11,100,1,13.01,2,1,12.98,200,2,12.86,100,1,12.73,100,1,12.71,100,1,12.5,700,1,12.49,200,2,12.46,100,1,12.43,700,1,13.63,15,1,13.64,100,1,13.65,15,1,13.9,2,1,13.93,100,1,14.25,100,1,14.28,100,1,14.47,100,1,14.48,700,1,14.56,800,2,ARL,336161365
1374,2025-07-17T16:10:46.534055942Z,2025-07-17T16:10:46.533890361Z,10,2,1108,A,A,9,14.51,100,130,165581,279921726,13.11,100,1,13.01,2,1,12.98,200,2,12.86,100,1,12.73,100,1,12.71,100,1,12.5,700,1,12.49,200,2,12.46,100,1,12.43,700,1,13.63,15,1,13.64,100,1,13.65,15,1,13.9,2,1,13.93,100,1,14.25,100,1,14.28,100,1,14.47,100,1,14.48,700,1,14.51,100,1,ARL,336259225
1375,2025-07-17T16:10:46.538158874Z,2025-07-17T16:10:46.537992315Z,10,2,1108,C,A,-1,13.65,15,128,166559,279921911,13.11,100,1,13.01,2,1,12.98,200,2,12.86,100,1,12.73,100,1,12.71,100,1,12.5,700,1,12.49,200,2,12.46,100,1,12.43,700,1,13.63,15,1,13.64,100,1,13.9,2,1,13.93,100,1,14.25,100,1,14.28,100,1,14.47,100,1,14.48,700,1,14.51,100,1,14.56,800,2,ARL,335996705
1376,2025-07-17T16:10:46.561246030Z,2025-07-17T16:10:46.561080616Z,10,2,1108,A,A,8,14.51,100,130,165414,279924883,13.11,100,1,13.01,2,1,12.98,200,2,12.86,100,1,12.73,100,1,12.71,100,1,12.5,700,1,12.49,200,2,12.46,100,1,12.43,700,1,13.63,15,1,13.64,100,1,13.9,2,1,13.93,100,1,14.25,100,1,14.28,100,1,14.47,100,1,14.48,700,1,14.51,200,2,14.56,800,2,ARL,336261905
1377,2025-07-17T16:10:47.543404001Z,2025-07-17T16:10:47.543238729Z,10,2,1108,A,A,0,13.61,15,130,165272,279938097,13.11,100,1,13.01,2,1,12.98,200,2,12.86,100,1,12.73,100,1,12.71,100,1,12.5,700,1,12.49,200,2,12.46,100,1,12.43,700,1,13.61,15,1,13.63,15,1,13.64,100,1,13.9,2,1,13.93,100,1,14.25,100,1,14.28,100,1,14.47,100,1,14.48,700,1,14.51,200,2,ARL,336278197
1378,2025-07-17T16:10:48.657456395Z,2025-07-17T16:10:48.657290980Z,10,2,1108,C,A,-1,13.64,100,0,165415,279952266,13.11,100,1,13.01,2,1,12.98,200,2,12.86,100,1,12.73,100,1,12.71,100,1,12.5,700,1,12.49,200,2,12.46,100,1,12.43,700,1,13.61,15,1,13.63,15,1,13.9,2,1,13.93,100,1,14.25,100,1,14.28,100,1,14.47,100,1,14.48,700,1,14.51,200,2,14.56,800,2,ARL,336161337
1379,2025-07-17T16:10:48.657456395Z,2025-07-17T16:10:48.657290980Z,10,2,1108,A,A,1,13.62,100,130,165415,279952266,13.11,100,1,13.01,2,1,12.98,200,2,12.86,100,1,12.73,100,1,12.71,100,1,12.5,700,1,12.49,200,2,12.46,100,1,12.43,700,1,13.61,15,1,13.62,100,1,13.63,15,1,13.9,2,1,13.93,100,1,14.25,100,1,14.28,100,1,14.47,100,1,14.48,700,1,14.51,200,2,ARL,336295769
1380,2025-07-17T16:10:51.059044292Z,2025-07-17T16:10:51.058878264Z,10,2,1108,C,A,-1,13.61,15,128,166028,280001840,13.11,100,1,13.01,2,1,12.98,200,2,12.86,100,1,12.73,100,1,12.71,100,1,12.5,700,1,12.49,200,2,12.46,100,1,12.43,700,1,13.62,100,1,13.63,15,1,13.9,2,1,13.93,100,1,14.25,100,1,14.28,100,1,14.47,100,1,14.48,700,1,14.51,200,2,14.56,800,2,ARL,336278197
1381,2025-07-17T16:10:51.059183923Z,2025-07-17T16:10:51.059016199Z,10,2,1108,C,A,-1,13.63,15,128,167724,280001873,13.11,100,1,13.01,2,1,12.98,200,2,12.86,100,1,12.73,100,1,12.71,100,1,12.5,700,1,12.49,200,2,12.46,100,1,12.43,700,1,13.62,100,1,13.9,2,1,13.93,100,1,14.25,100,1,14.28,100,1,14.47,100,1,14.48,700,1,14.51,200,2,14.56,800,2,14.6,700,1,ARL,336161333
1382,2025-07-17T16:10:51.059608753Z,2025-07-17T16:10:51.059443298Z,10,2,1108,C,A,-1,13.62,100,130,165455,280001952,13.11,100,1,13.01,2,1,12.98,200,2,12.86,100,1,12.73,100,1,12.71,100,1,12.5,700,1,12.49,200,2,12.46,100,1,12.43,700,1,13.9,2,1,13.93,100,1,14.25,100,1,14.28,100,1,14.47,100,1,14.48,700,1,14.51,200,2,14.56,800,2,14.6,700,1,14.64,200,2,ARL,336295769
1383,2025-07-17T16:10:51.170710609Z,2025-07-17T16:10:51.170545251Z,10,2,1108,A,A,1,13.91,100,130,165358,280003702,13.11,100,1,13.01,2,1,12.98,200,2,12.86,100,1,12.73,100,1,12.71,100,1,12.5,700,1,12.49,200,2,12.46,100,1,12.43,700,1,13.9,2,1,13.91,100,1,13.93,100,1,14.25,100,1,14.28,100,1,14.47,100,1,14.48,700,1,14.51,200,2,14.56,800,2,14.6,700,1,ARL,336351081
1384,2025-07-17T16:10:52.958453641Z,2025-07-17T16:10:52.958288317Z,10,2,1108,A,A,0,13.6,15,130,165324,280050139,13.11,100,1,13.01,2,1,12.98,200,2,12.86,100,1,12.73,100,1,12.71,100,1,12.5,700,1,12.49,200,2,12.46,100,1,12.43,700,1,13.6,15,1,13.9,2,1,13.91,100,1,13.93,100,1,14.25,100,1,14.28,100,1,14.47,100,1,14.48,700,1,14.51,200,2,14.56,800,2,ARL,336402845
1385,2025-07-17T16:10:53.102037173Z,2025-07-17T16:10:53.101871639Z,10,2,1108,C,A,-1,13.91,100,0,165534,280057228,13.11,100,1,13.01,2,1,12.98,200,2,12.86,100,1,12.73,100,1,12.71,100,1,12.5,700,1,12.49,200,2,12.46,100,1,12.43,700,1,13.6,15,1,13.9,2,1,13.93,100,1,14.25,100,1,14.28,100,1,14.47,100,1,14.48,700,1,14.51,200,2,14.56,800,2,14.6,700,1,ARL,336351081
1386,2025-07-17T16:10:53.102037173Z,2025-07-17T16:10:53.101871639Z,10,2,1108,A,A,1,13.61,100,130,165534,280057228,13.11,100,1,13.01,2,1,12.98,200,2,12.86,100,1,12.73,100,1,12.71,100,1,12.5,700,1,12.49,200,2,12.46,100,1,12.43,700,1,13.6,15,1,13.61,100,1,13.9,2,1,13.93,100,1,14.25,100,1,14.28,100,1,14.47,100,1,14.48,700,1,14.51,200,2,14.56,800,2,ARL,336410125
1387,2025-07-17T16:10:54.959307592Z,2025-07-17T16:10:54.959141873Z,10,2,1108,C,A,-1,13.9,2,0,165719,280084546,13.11,100,1,13.01,2,1,12.98,200,2,12.86,100,1,12.73,100,1,12.71,100,1,12.5,700,1,12.49,200,2,12.46,100,1,12.43,700,1,13.6,15,1,13.61,100,1,13.93,100,1,14.25,100,1,14.28,100,1,14.47,100,1,14.48,700,1,14.51,200,2,14.56,800,2,14.6,700,1,ARL,334804177
1388,2025-07-17T16:10:54.959307592Z,2025-07-17T16:10:54.959141873Z,10,2,1108,A,A,2,13.82,2,130,165719,280084546,13.11,100,1,13.01,2,1,12.98,200,2,12.86,100,1,12.73,100,1,12.71,100,1,12.5,700,1,12.49,200,2,12.46,100,1,12.43,700,1,13.6,15,1,13.61,100,1,13.82,2,1,13.93,100,1,14.25,100,1,14.28,100,1,14.47,100,1,14.48,700,1,14.51,200,2,14.56,800,2,ARL,336447325
1389,2025-07-17T16:10:59.518035805Z,2025-07-17T16:10:59.517870358Z,10,2,1108,A,A,0,13.58,15,130,165447,280173685,13.11,100,1,13.01,2,1,12.98,200,2,12.86,100,1,12.73,100,1,12.71,100,1,12.5,700,1,12.49,200,2,12.46,100,1,12.43,700,1,13.58,15,1,13.6,15,1,13.61,100,1,13.82,2,1,13.93,100,1,14.25,100,1,14.28,100,1,14.47,100,1,14.48,700,1,14.51,200,2,ARL,336555153
1390,2025-07-17T16:11:00.215885294Z,2025-07-17T16:11:00.215719725Z,10,2,1108,C,A,-1,13.61,100,0,165569,280184406,13.11,100,1,13.01,2,1,12.98,200,2,12.86,100,1,12.73,100,1,12.71,100,1,12.5,700,1,12.49,200,2,12.46,100,1,12.43,700,1,13.58,15,1,13.6,15,1,13.82,2,1,13.93,100,1,14.25,100,1,14.28,100,1,14.47,100,1,14.48,700,1,14.51,200,2,14.56,800,2,ARL,336410125
1391,2025-07-17T16:11:00.215885294Z,2025-07-17T16:11:00.215719725Z,10,2,1108,A,A,1,13.59,100,130,165569,280184406,13.11,100,1,13.01,2,1,12.98,200,2,12.86,100,1,12.73,100,1,12.71,100,1,12.5,700,1,12.49,200,2,12.46,100,1,12.43,700,1,13.58,15,1,13.59,100,1,13.6,15,1,13.82,2,1,13.93,100,1,14.25,100,1,14.28,100,1,14.47,100,1,14.48,700,1,14.51,200,2,ARL,336567189
1392,2025-07-17T16:11:00.228999377Z,2025-07-17T16:11:00.228833925Z,10,2,1108,C,A,-1,13.93,100,130,165452,280184613,13.11,100,1,13.01,2,1,12.98,200,2,12.86,100,1,12.73,100,1,12.71,100,1,12.5,700,1,12.49,200,2,12.46,100,1,12.43,700,1,13.58,15,1,13.59,100,1,13.6,15,1,13.82,2,1,14.25,100,1,14.28,100,1,14.47,100,1,14.48,700,1,14.51,200,2,14.56,800,2,ARL,335996777
1393,2025-07-17T16:11:00.229051124Z,2025-07-17T16:11:00.228885790Z,10,2,1108,A,A,4,13.86,100,130,165334,280184614,13.11,100,1,13.01,2,1,12.98,200,2,12.86,100,1,12.73,100,1,12.71,100,1,12.5,700,1,12.49,200,2,12.46,100,1,12.43,700,1,13.58,15,1,13.59,100,1,13.6,15,1,13.82,2,1,13.86,100,1,14.25,100,1,14.28,100,1,14.47,100,1,14.48,700,1,14.51,200,2,ARL,336567333
1394,2025-07-17T16:11:00.366811541Z,2025-07-17T16:11:00.366645846Z,10,2,1108,A,A,3,13.62,1,130,165695,280189435,13.11,100,1,13.01,2,1,12.98,200,2,12.86,100,1,12.73,100,1,12.71,100,1,12.5,700,1,12.49,200,2,12.46,100,1,12.43,700,1,13.58,15,1,13.59,100,1,13.6,15,1,13.62,1,1,13.82,2,1,13.86,100,1,14.25,100,1,14.28,100,1,14.47,100,1,14.48,700,1,ARL,336572049
1395,2025-07-17T16:11:00.367374773Z,2025-07-17T16:11:00.367209243Z,10,2,1108,C,B,7,12.49,100,0,165530,280189439,13.11,100,1,13.01,2,1,12.98,200,2,12.86,100,1,12.73,100,1,12.71,100,1,12.5,700,1,12.49,100,1,12.46,100,1,12.43,700,1,13.58,15,1,13.59,100,1,13.6,15,1,13.62,1,1,13.82,2,1,13.86,100,1,14.25,100,1,14.28,100,1,14.47,100,1,14.48,700,1,ARL,331942945
1396,2025-07-17T16:11:00.367485094Z,2025-07-17T16:11:00.367319059Z,10,2,1108,C,B,-1,12.49,100,0,166035,280189441,13.11,100,1,13.01,2,1,12.98,200,2,12.86,100,1,12.73,100,1,12.71,100,1,12.5,700,1,12.46,100,1,12.43,700,1,12.42,700,1,13.58,15,1,13.59,100,1,13.6,15,1,13.62,1,1,13.82,2,1,13.86,100,1,14.25,100,1,14.28,100,1,14.47,100,1,14.48,700,1,ARL,331942901
1397,2025-07-17T16:11:00.466868624Z,2025-07-17T16:11:00.466703632Z,10,2,1108,C,A,-1,13.62,1,130,164992,280191783,13.11,100,1,13.01,2,1,12.98,200,2,12.86,100,1,12.73,100,1,12.71,100,1,12.5,700,1,12.46,100,1,12.43,700,1,12.42,700,1,13.58,15,1,13.59,100,1,13.6,15,1,13.82,2,1,13.86,100,1,14.25,100,1,14.28,100,1,14.47,100,1,14.48,700,1,14.51,200,2,ARL,336572049
1398,2025-07-17T16:11:06.626831799Z,2025-07-17T16:11:06.626666474Z,10,2,1108,A,A,6,14.27,700,130,165325,280342316,13.11,100,1,13.01,2,1,12.98,200,2,12.86,100,1,12.73,100,1,12.71,100,1,12.5,700,1,12.46,100,1,12.43,700,1,12.42,700,1,13.58,15,1,13.59,100,1,13.6,15,1,13.82,2,1,13.86,100,1,14.25,100,1,14.27,700,1,14.28,100,1,14.47,100,1,14.48,700,1,ARL,336747457
1399,2025-07-17T16:11:08.308034538Z,2025-07-17T16:11:08.307868957Z,10,2,1108,C,A,-1,13.6,15,130,165581,280374785,13.11,100,1,13.01,2,1,12.98,200,2,12.86,100,1,12.73,100,1,12.71,100,1,12.5,700,1,12.46,100,1,12.43,700,1,12.42,700,1,13.58,15,1,13.59,100,1,13.82,2,1,13.86,100,1,14.25,100,1,14.27,700,1,14.28,100,1,14.47,100,1,14.48,700,1,14.51,200,2,ARL,336402845
1400,2025-07-17T16:11:09.568536292Z,2025-07-17T16:11:09.568370995Z,10,2,1108,A,A,0,13.56,15,130,165297,280401189,13.11,100,1,13.01,2,1,12.98,200,2,12.86,100,1,12.73,100,1,12.71,100,1,12.5,700,1,12.46,100,1,12.43,700,1,12.42,700,1,13.56,15,1,13.58,15,1,13.59,100,1,13.82,2,1,13.86,100,1,14.25,100,1,14.27,700,1,14.28,100,1,14.47,100,1,14.48,700,1,ARL,336816813
1401,2025-07-17T16:11:10.341953971Z,2025-07-17T16:11:10.341788521Z,10,2,1108,C,A,-1,13.59,100,0,165450,280411396,13.11,100,1,13.01,2,1,12.98,200,2,12.86,100,1,12.73,100,1,12.71,100,1,12.5,700,1,12.46,100,1,12.43,700,1,12.42,700,1,13.56,15,1,13.58,15,1,13.82,2,1,13.86,100,1,14.25,100,1,14.27,700,1,14.28,100,1,14.47,100,1,14.48,700,1,14.51,200,2,ARL,336567189
1402,2025-07-17T16:11:10.341953971Z,2025-07-17T16:11:10.341788521Z,10,2,1108,A,A,1,13.57,100,130,165450,280411396,13.11,100,1,13.01,2,1,12.98,200,2,12.86,100,1,12.73,100,1,12.71,100,1,12.5,700,1,12.46,100,1,12.43,700,1,12.42,700,1,13.56,15,1,13.57,100,1,13.58,15,1,13.82,2,1,13.86,100,1,14.25,100,1,14.27,700,1,14.28,100,1,14.47,100,1,14.48,700,1,ARL,336828765
1403,2025-07-17T16:11:14.610701450Z,2025-07-17T16:11:14.610535763Z,10,2,1108,C,A,-1,13.58,15,130,165687,280482371,13.11,100,1,13.01,2,1,12.98,200,2,12.86,100,1,12.73,100,1,12.71,100,1,12.5,700,1,12.46,100,1,12.43,700,1,12.42,700,1,13.56,15,1,13.57,100,1,13.82,2,1,13.86,100,1,14.25,100,1,14.27,700,1,14.28,100,1,14.47,100,1,14.48,700,1,14.51,200,2,ARL,336555153
1404,2025-07-17T16:11:16.025458231Z,2025-07-17T16:11:16.025292936Z,10,2,1108,C,A,-1,13.56,15,130,165295,280514282,13.11,100,1,13.01,2,1,12.98,200,2,12.86,100,1,12.73,100,1,12.71,100,1,12.5,700,1,12.46,100,1,12.43,700,1,12.42,700,1,13.57,100,1,13.82,2,1,13.86,100,1,14.25,100,1,14.27,700,1,14.28,100,1,14.47,100,1,14.48,700,1,14.51,200,2,14.56,800,2,ARL,336816813
1405,2025-07-17T16:11:50.026837358Z,2025-07-17T16:11:50.026672014Z,10,2,1108,A,A,0,13.55,15,130,165344,281078802,13.11,100,1,13.01,2,1,12.98,200,2,12.86,100,1,12.73,100,1,12.71,100,1,12.5,700,1,12.46,100,1,12.43,700,1,12.42,700,1,13.55,15,1,13.57,100,1,13.82,2,1,13.86,100,1,14.25,100,1,14.27,700,1,14.28,100,1,14.47,100,1,14.48,700,1,14.51,200,2,ARL,337690189
1406,2025-07-17T16:11:50.027004977Z,2025-07-17T16:11:50.026839463Z,10,2,1108,C,A,-1,13.57,100,0,165514,281078803,13.11,100,1,13.01,2,1,12.98,200,2,12.86,100,1,12.73,100,1,12.71,100,1,12.5,700,1,12.46,100,1,12.43,700,1,12.42,700,1,13.55,15,1,13.82,2,1,13.86,100,1,14.25,100,1,14.27,700,1,14.28,100,1,14.47,100,1,14.48,700,1,14.51,200,2,14.56,800,2,ARL,336828765
1407,2025-07-17T16:11:50.027004977Z,2025-07-17T16:11:50.026839463Z,10,2,1108,A,A,1,13.56,100,130,165514,281078803,13.11,100,1,13.01,2,1,12.98,200,2,12.86,100,1,12.73,100,1,12.71,100,1,12.5,700,1,12.46,100,1,12.43,700,1,12.42,700,1,13.55,15,1,13.56,100,1,13.82,2,1,13.86,100,1,14.25,100,1,14.27,700,1,14.28,100,1,14.47,100,1,14.48,700,1,14.51,200,2,ARL,337690193
1408,2025-07-17T16:11:53.859909462Z,2025-07-17T16:11:53.859743991Z,10,2,1108,A,A,0,13.53,15,130,165471,281142794,13.11,100,1,13.01,2,1,12.98,200,2,12.86,100,1,12.73,100,1,12.71,100,1,12.5,700,1,12.46,100,1,12.43,700,1,12.42,700,1,13.53,15,1,13.55,15,1,13.56,100,1,13.82,2,1,13.86,100,1,14.25,100,1,14.27,700,1,14.28,100,1,14.47,100,1,14.48,700,1,ARL,337772837
1409,2025-07-17T16:11:54.662527332Z,2025-07-17T16:11:54.662361841Z,10,2,1108,C,A,-1,13.56,100,0,165491,281156215,13.11,100,1,13.01,2,1,12.98,200,2,12.86,100,1,12.73,100,1,12.71,100,1,12.5,700,1,12.46,100,1,12.43,700,1,12.42,700,1,13.53,15,1,13.55,15,1,13.82,2,1,13.86,100,1,14.25,100,1,14.27,700,1,14.28,100,1,14.47,100,1,14.48,700,1,14.51,200,2,ARL,337690193
1410,2025-07-17T16:11:54.662527332Z,2025-07-17T16:11:54.662361841Z,10,2,1108,A,A,1,13.54,100,130,165491,281156215,13.11,100,1,13.01,2,1,12.98,200,2,12.86,100,1,12.73,100,1,12.71,100,1,12.5,700,1,12.46,100,1,12.43,700,1,12.42,700,1,13.53,15,1,13.54,100,1,13.55,15,1,13.82,2,1,13.86,100,1,14.25,100,1,14.27,700,1,14.28,100,1,14.47,100,1,14.48,700,1,ARL,337790717
1411,2025-07-17T16:11:54.666326600Z,2025-07-17T16:11:54.666160990Z,10,2,1108,C,A,-1,14.47,100,0,165610,281156243,13.11,100,1,13.01,2,1,12.98,200,2,12.86,100,1,12.73,100,1,12.71,100,1,12.5,700,1,12.46,100,1,12.43,700,1,12.42,700,1,13.53,15,1,13.54,100,1,13.55,15,1,13.82,2,1,13.86,100,1,14.25,100,1,14.27,700,1,14.28,100,1,14.48,700,1,14.49,100,1,ARL,335220561
1412,2025-07-17T16:11:54.666326600Z,2025-07-17T16:11:54.666160990Z,10,2,1108,A,A,8,14.33,100,130,165610,281156243,13.11,100,1,13.01,2,1,12.98,200,2,12.86,100,1,12.73,100,1,12.71,100,1,12.5,700,1,12.46,100,1,12.43,700,1,12.42,700,1,13.53,15,1,13.54,100,1,13.55,15,1,13.82,2,1,13.86,100,1,14.25,100,1,14.27,700,1,14.28,100,1,14.33,100,1,14.48,700,1,ARL,337790761
1413,2025-07-17T16:11:59.382515678Z,2025-07-17T16:11:59.382350338Z,10,2,1108,C,A,-1,13.55,15,130,165340,281270010,13.11,100,1,13.01,2,1,12.98,200,2,12.86,100,1,12.73,100,1,12.71,100,1,12.5,700,1,12.46,100,1,12.43,700,1,12.42,700,1,13.53,15,1,13.54,100,1,13.82,2,1,13.86,100,1,14.25,100,1,14.27,700,1,14.28,100,1,14.33,100,1,14.48,700,1,14.49,200,2,ARL,337690189
1414,2025-07-17T16:12:02.982078719Z,2025-07-17T16:12:02.981913204Z,10,2,1108,A,A,0,13.51,15,130,165515,281348152,13.11,100,1,13.01,2,1,12.98,200,2,12.86,100,1,12.73,100,1,12.71,100,1,12.5,700,1,12.46,100,1,12.43,700,1,12.42,700,1,13.51,15,1,13.53,15,1,13.54,100,1,13.82,2,1,13.86,100,1,14.25,100,1,14.27,700,1,14.28,100,1,14.33,100,1,14.48,700,1,ARL,338041605
1415,2025-07-17T16:12:03.064162605Z,2025-07-17T16:12:03.063997054Z,10,2,1108,C,A,-1,13.54,100,0,165551,281351122,13.11,100,1,13.01,2,1,12.98,200,2,12.86,100,1,12.73,100,1,12.71,100,1,12.5,700,1,12.46,100,1,12.43,700,1,12.42,700,1,13.51,15,1,13.53,15,1,13.82,2,1,13.86,100,1,14.25,100,1,14.27,700,1,14.28,100,1,14.33,100,1,14.48,700,1,14.49,200,2,ARL,337790717
1416,2025-07-17T16:12:03.064162605Z,2025-07-17T16:12:03.063997054Z,10,2,1108,A,A,1,13.52,100,130,165551,281351122,13.11,100,1,13.01,2,1,12.98,200,2,12.86,100,1,12.73,100,1,12.71,100,1,12.5,700,1,12.46,100,1,12.43,700,1,12.42,700,1,13.51,15,1,13.52,100,1,13.53,15,1,13.82,2,1,13.86,100,1,14.25,100,1,14.27,700,1,14.28,100,1,14.33,100,1,14.48,700,1,ARL,338044041
1417,2025-07-17T16:12:03.068467146Z,2025-07-17T16:12:03.068301745Z,10,2,1108,C,B,-1,13.01,2,0,165401,281351235,13.11,100,1,12.98,200,2,12.86,100,1,12.73,100,1,12.71,100,1,12.5,700,1,12.46,100,1,12.43,700,1,12.42,700,1,12.37,700,1,13.51,15,1,13.52,100,1,13.53,15,1,13.82,2,1,13.86,100,1,14.25,100,1,14.27,700,1,14.28,100,1,14.33,100,1,14.48,700,1,ARL,332494213
1418,2025-07-17T16:12:03.068467146Z,2025-07-17T16:12:03.068301745Z,10,2,1108,A,B,2,12.92,2,130,165401,281351235,13.11,100,1,12.98,200,2,12.92,2,1,12.86,100,1,12.73,100,1,12.71,100,1,12.5,700,1,12.46,100,1,12.43,700,1,12.42,700,1,13.51,15,1,13.52,100,1,13.53,15,1,13.82,2,1,13.86,100,1,14.25,100,1,14.27,700,1,14.28,100,1,14.33,100,1,14.48,700,1,ARL,338044113
1419,2025-07-17T16:12:03.075200038Z,2025-07-17T16:12:03.075034550Z,10,2,1108,C,A,-1,13.86,100,130,165488,281351372,13.11,100,1,12.98,200,2,12.92,2,1,12.86,100,1,12.73,100,1,12.71,100,1,12.5,700,1,12.46,100,1,12.43,700,1,12.42,700,1,13.51,15,1,13.52,100,1,13.53,15,1,13.82,2,1,14.25,100,1,14.27,700,1,14.28,100,1,14.33,100,1,14.48,700,1,14.49,200,2,ARL,336567333
1420,2025-07-17T16:12:03.075260529Z,2025-07-17T16:12:03.075095341Z,10,2,1108,A,A,3,13.79,100,130,165188,281351373,13.11,100,1,12.98,200,2,12.92,2,1,12.86,100,1,12.73,100,1,12.71,100,1,12.5,700,1,12.46,100,1,12.43,700,1,12.42,700,1,13.51,15,1,13.52,100,1,13.53,15,1,13.79,100,1,13.82,2,1,14.25,100,1,14.27,700,1,14.28,100,1,14.33,100,1,14.48,700,1,ARL,338044233
1421,2025-07-17T16:12:06.775177637Z,2025-07-17T16:12:06.775011783Z,10,2,1108,A,A,9,14.4,100,130,165854,281422697,13.11,100,1,12.98,200,2,12.92,2,1,12.86,100,1,12.73,100,1,12.71,100,1,12.5,700,1,12.46,100,1,12.43,700,1,12.42,700,1,13.51,15,1,13.52,100,1,13.53,15,1,13.79,100,1,13.82,2,1,14.25,100,1,14.27,700,1,14.28,100,1,14.33,100,1,14.4,100,1,ARL,338139585
1422,2025-07-17T16:12:06.775614536Z,2025-07-17T16:12:06.775449017Z,10,2,1108,A,A,9,14.4,100,130,165519,281422702,13.11,100,1,12.98,200,2,12.92,2,1,12.86,100,1,12.73,100,1,12.71,100,1,12.5,700,1,12.46,100,1,12.43,700,1,12.42,700,1,13.51,15,1,13.52,100,1,13.53,15,1,13.79,100,1,13.82,2,1,14.25,100,1,14.27,700,1,14.28,100,1,14.33,100,1,14.4,200,2,ARL,338139601
1423,2025-07-17T16:12:06.779705717Z,2025-07-17T16:12:06.779540143Z,10,2,1108,C,A,-1,13.53,15,130,165574,281422782,13.11,100,1,12.98,200,2,12.92,2,1,12.86,100,1,12.73,100,1,12.71,100,1,12.5,700,1,12.46,100,1,12.43,700,1,12.42,700,1,13.51,15,1,13.52,100,1,13.79,100,1,13.82,2,1,14.25,100,1,14.27,700,1,14.28,100,1,14.33,100,1,14.4,200,2,14.48,700,1,ARL,337772837
1424,2025-07-17T16:12:07.784698893Z,2025-07-17T16:12:07.784533539Z,10,2,1108,A,A,0,13.49,15,130,165354,281443568,13.11,100,1,12.98,200,2,12.92,2,1,12.86,100,1,12.73,100,1,12.71,100,1,12.5,700,1,12.46,100,1,12.43,700,1,12.42,700,1,13.49,15,1,13.51,15,1,13.52,100,1,13.79,100,1,13.82,2,1,14.25,100,1,14.27,700,1,14.28,100,1,14.33,100,1,14.4,200,2,ARL,338167057
1425,2025-07-17T16:12:08.585194585Z,2025-07-17T16:12:08.585029039Z,10,2,1108,C,A,-1,13.52,100,0,165546,281451898,13.11,100,1,12.98,200,2,12.92,2,1,12.86,100,1,12.73,100,1,12.71,100,1,12.5,700,1,12.46,100,1,12.43,700,1,12.42,700,1,13.49,15,1,13.51,15,1,13.79,100,1,13.82,2,1,14.25,100,1,14.27,700,1,14.28,100,1,14.33,100,1,14.4,200,2,14.48,700,1,ARL,338044041
1426,2025-07-17T16:12:08.585194585Z,2025-07-17T16:12:08.585029039Z,10,2,1108,A,A,1,13.5,100,130,165546,281451898,13.11,100,1,12.98,200,2,12.92,2,1,12.86,100,1,12.73,100,1,12.71,100,1,12.5,700,1,12.46,100,1,12.43,700,1,12.42,700,1,13.49,15,1,13.5,100,1,13.51,15,1,13.79,100,1,13.82,2,1,14.25,100,1,14.27,700,1,14.28,100,1,14.33,100,1,14.4,200,2,ARL,338180793
1427,2025-07-17T16:12:18.789922022Z,2025-07-17T16:12:18.789756367Z,10,2,1108,C,A,-1,13.82,2,0,165655,281613266,13.11,100,1,12.98,200,2,12.92,2,1,12.86,100,1,12.73,100,1,12.71,100,1,12.5,700,1,12.46,100,1,12.43,700,1,12.42,700,1,13.49,15,1,13.5,100,1,13.51,15,1,13.79,100,1,14.25,100,1,14.27,700,1,14.28,100,1,14.33,100,1,14.4,200,2,14.48,700,1,ARL,336447325
1428,2025-07-17T16:12:18.789922022Z,2025-07-17T16:12:18.789756367Z,10,2,1108,A,A,3,13.74,2,130,165655,281613266,13.11,100,1,12.98,200,2,12.92,2,1,12.86,100,1,12.73,100,1,12.71,100,1,12.5,700,1,12.46,100,1,12.43,700,1,12.42,700,1,13.49,15,1,13.5,100,1,13.51,15,1,13.74,2,1,13.79,100,1,14.25,100,1,14.27,700,1,14.28,100,1,14.33,100,1,14.4,200,2,ARL,338371797
1429,2025-07-17T16:12:19.370986404Z,2025-07-17T16:12:19.370820933Z,10,2,1108,A,A,6,14.27,700,130,165471,281622545,13.11,100,1,12.98,200,2,12.92,2,1,12.86,100,1,12.73,100,1,12.71,100,1,12.5,700,1,12.46,100,1,12.43,700,1,12.42,700,1,13.49,15,1,13.5,100,1,13.51,15,1,13.74,2,1,13.79,100,1,14.25,100,1,14.27,1400,2,14.28,100,1,14.33,100,1,14.4,200,2,ARL,338382329
1430,2025-07-17T16:12:19.696689718Z,2025-07-17T16:12:19.696521343Z,10,2,1108,C,A,-1,13.49,15,128,168375,281630053,13.11,100,1,12.98,200,2,12.92,2,1,12.86,100,1,12.73,100,1,12.71,100,1,12.5,700,1,12.46,100,1,12.43,700,1,12.42,700,1,13.5,100,1,13.51,15,1,13.74,2,1,13.79,100,1,14.25,100,1,14.27,1400,2,14.28,100,1,14.33,100,1,14.4,200,2,14.48,700,1,ARL,338167057
1431,2025-07-17T16:12:19.711773364Z,2025-07-17T16:12:19.711591494Z,10,2,1108,C,A,-1,13.51,15,128,181870,281634812,13.11,100,1,12.98,200,2,12.92,2,1,12.86,100,1,12.73,100,1,12.71,100,1,12.5,700,1,12.46,100,1,12.43,700,1,12.42,700,1,13.5,100,1,13.74,2,1,13.79,100,1,14.25,100,1,14.27,1400,2,14.28,100,1,14.33,100,1,14.4,200,2,14.48,700,1,14.49,200,2,ARL,338041605
1432,2025-07-17T16:12:32.761277424Z,2025-07-17T16:12:32.761112078Z,10,2,1108,A,A,0,13.48,15,130,165346,281880398,13.11,100,1,12.98,200,2,12.92,2,1,12.86,100,1,12.73,100,1,12.71,100,1,12.5,700,1,12.46,100,1,12.43,700,1,12.42,700,1,13.48,15,1,13.5,100,1,13.74,2,1,13.79,100,1,14.25,100,1,14.27,1400,2,14.28,100,1,14.33,100,1,14.4,200,2,14.48,700,1,ARL,338707945
1433,2025-07-17T16:12:32.761413202Z,2025-07-17T16:12:32.761246859Z,10,2,1108,C,A,-1,13.5,100,0,166343,281880409,13.11,100,1,12.98,200,2,12.92,2,1,12.86,100,1,12.73,100,1,12.71,100,1,12.5,700,1,12.46,100,1,12.43,700,1,12.42,700,1,13.48,15,1,13.74,2,1,13.79,100,1,14.25,100,1,14.27,1400,2,14.28,100,1,14.33,100,1,14.4,200,2,14.48,700,1,14.49,200,2,ARL,338180793
1434,2025-07-17T16:12:32.761413202Z,2025-07-17T16:12:32.761246859Z,10,2,1108,A,A,1,13.49,100,130,166343,281880409,13.11,100,1,12.98,200,2,12.92,2,1,12.86,100,1,12.73,100,1,12.71,100,1,12.5,700,1,12.46,100,1,12.43,700,1,12.42,700,1,13.48,15,1,13.49,100,1,13.74,2,1,13.79,100,1,14.25,100,1,14.27,1400,2,14.28,100,1,14.33,100,1,14.4,200,2,14.48,700,1,ARL,338707949
1435,2025-07-17T16:12:40.993064296Z,2025-07-17T16:12:40.992898990Z,10,2,1108,C,A,-1,13.49,100,130,165306,282007871,13.11,100,1,12.98,200,2,12.92,2,1,12.86,100,1,12.73,100,1,12.71,100,1,12.5,700,1,12.46,100,1,12.43,700,1,12.42,700,1,13.48,15,1,13.74,2,1,13.79,100,1,14.25,100,1,14.27,1400,2,14.28,100,1,14.33,100,1,14.4,200,2,14.48,700,1,14.49,200,2,ARL,338707949
1436,2025-07-17T16:12:40.993332664Z,2025-07-17T16:12:40.993167418Z,10,2,1108,C,A,4,14.27,700,130,165246,282007875,13.11,100,1,12.98,200,2,12.92,2,1,12.86,100,1,12.73,100,1,12.71,100,1,12.5,700,1,12.46,100,1,12.43,700,1,12.42,700,1,13.48,15,1,13.74,2,1,13.79,100,1,14.25,100,1,14.27,700,1,14.28,100,1,14.33,100,1,14.4,200,2,14.48,700,1,14.49,200,2,ARL,338382329
1437,2025-07-17T16:12:40.993333790Z,2025-07-17T16:12:40.993168470Z,10,2,1108,C,A,-1,14.27,700,130,165320,282007876,13.11,100,1,12.98,200,2,12.92,2,1,12.86,100,1,12.73,100,1,12.71,100,1,12.5,700,1,12.46,100,1,12.43,700,1,12.42,700,1,13.48,15,1,13.74,2,1,13.79,100,1,14.25,100,1,14.28,100,1,14.33,100,1,14.4,200,2,14.48,700,1,14.49,200,2,14.55,100,1,ARL,336747457
1438,2025-07-17T16:12:40.993379626Z,2025-07-17T16:12:40.993214193Z,10,2,1108,A,A,9,14.54,700,130,165433,282007877,13.11,100,1,12.98,200,2,12.92,2,1,12.86,100,1,12.73,100,1,12.71,100,1,12.5,700,1,12.46,100,1,12.43,700,1,12.42,700,1,13.48,15,1,13.74,2,1,13.79,100,1,14.25,100,1,14.28,100,1,14.33,100,1,14.4,200,2,14.48,700,1,14.49,200,2,14.54,700,1,ARL,338864169
1439,2025-07-17T16:12:40.993393440Z,2025-07-17T16:12:40.993227993Z,10,2,1108,A,A,7,14.47,700,130,165447,282007878,13.11,100,1,12.98,200,2,12.92,2,1,12.86,100,1,12.73,100,1,12.71,100,1,12.5,700,1,12.46,100,1,12.43,700,1,12.42,700,1,13.48,15,1,13.74,2,1,13.79,100,1,14.25,100,1,14.28,100,1,14.33,100,1,14.4,200,2,14.47,700,1,14.48,700,1,14.49,200,2,ARL,338864173
1440,2025-07-17T16:12:40.994783297Z,2025-07-17T16:12:40.994617858Z,10,2,1108,C,A,9,14.49,100,0,165439,282007892,13.11,100,1,12.98,200,2,12.92,2,1,12.86,100,1,12.73,100,1,12.71,100,1,12.5,700,1,12.46,100,1,12.43,700,1,12.42,700,1,13.48,15,1,13.74,2,1,13.79,100,1,14.25,100,1,14.28,100,1,14.33,100,1,14.4,200,2,14.47,700,1,14.48,700,1,14.49,100,1,ARL,337790745
1441,2025-07-17T16:12:40.997300700Z,2025-07-17T16:12:40.997135307Z,10,2,1108,C,A,-1,14.33,100,130,165393,282007914,13.11,100,1,12.98,200,2,12.92,2,1,12.86,100,1,12.73,100,1,12.71,100,1,12.5,700,1,12.46,100,1,12.43,700,1,12.42,700,1,13.48,15,1,13.74,2,1,13.79,100,1,14.25,100,1,14.28,100,1,14.4,200,2,14.47,700,1,14.48,700,1,14.49,100,1,14.54,700,1,ARL,337790761
1442,2025-07-17T16:12:41.004229622Z,2025-07-17T16:12:41.004063876Z,10,2,1108,C,A,-1,14.49,100,0,165746,282007959,13.11,100,1,12.98,200,2,12.92,2,1,12.86,100,1,12.73,100,1,12.71,100,1,12.5,700,1,12.46,100,1,12.43,700,1,12.42,700,1,13.48,15,1,13.74,2,1,13.79,100,1,14.25,100,1,14.28,100,1,14.4,200,2,14.47,700,1,14.48,700,1,14.54,700,1,14.56,800,2,ARL,337790777
1443,2025-07-17T16:12:41.005576053Z,2025-07-17T16:12:41.005406614Z,10,2,1108,A,A,1,13.49,100,128,169439,282008256,13.11,100,1,12.98,200,2,12.92,2,1,12.86,100,1,12.73,100,1,12.71,100,1,12.5,700,1,12.46,100,1,12.43,700,1,12.42,700,1,13.48,15,1,13.49,100,1,13.74,2,1,13.79,100,1,14.25,100,1,14.28,100,1,14.4,200,2,14.47,700,1,14.48,700,1,14.54,700,1,ARL,338864581
1444,2025-07-17T16:12:41.010638351Z,2025-07-17T16:12:41.010473041Z,10,2,1108,A,A,7,14.44,100,130,165310,282008884,13.11,100,1,12.98,200,2,12.92,2,1,12.86,100,1,12.73,100,1,12.71,100,1,12.5,700,1,12.46,100,1,12.43,700,1,12.42,700,1,13.48,15,1,13.49,100,1,13.74,2,1,13.79,100,1,14.25,100,1,14.28,100,1,14.4,200,2,14.44,100,1,14.47,700,1,14.48,700,1,ARL,338865133
1445,2025-07-17T16:12:41.011160341Z,2025-07-17T16:12:41.010994859Z,10,2,1108,C,A,-1,13.79,100,130,165482,282008914,13.11,100,1,12.98,200,2,12.92,2,1,12.86,100,1,12.73,100,1,12.71,100,1,12.5,700,1,12.46,100,1,12.43,700,1,12.42,700,1,13.48,15,1,13.49,100,1,13.74,2,1,14.25,100,1,14.28,100,1,14.4,200,2,14.44,100,1,14.47,700,1,14.48,700,1,14.54,700,1,ARL,338044233
1446,2025-07-17T16:12:41.011211986Z,2025-07-17T16:12:41.011046717Z,10,2,1108,A,A,3,14.06,100,130,165269,282008916,13.11,100,1,12.98,200,2,12.92,2,1,12.86,100,1,12.73,100,1,12.71,100,1,12.5,700,1,12.46,100,1,12.43,700,1,12.42,700,1,13.48,15,1,13.49,100,1,13.74,2,1,14.06,100,1,14.25,100,1,14.28,100,1,14.4,200,2,14.44,100,1,14.47,700,1,14.48,700,1,ARL,338865141
1447,2025-07-17T16:12:41.011555342Z,2025-07-17T16:12:41.011390077Z,10,2,1108,A,A,7,14.44,100,130,165265,282008942,13.11,100,1,12.98,200,2,12.92,2,1,12.86,100,1,12.73,100,1,12.71,100,1,12.5,700,1,12.46,100,1,12.43,700,1,12.42,700,1,13.48,15,1,13.49,100,1,13.74,2,1,14.06,100,1,14.25,100,1,14.28,100,1,14.4,200,2,14.44,200,2,14.47,700,1,14.48,700,1,ARL,338865165
1448,2025-07-17T16:12:41.012044919Z,2025-07-17T16:12:41.011879795Z,10,2,1108,C,A,-1,14.06,100,130,165124,282008953,13.11,100,1,12.98,200,2,12.92,2,1,12.86,100,1,12.73,100,1,12.71,100,1,12.5,700,1,12.46,100,1,12.43,700,1,12.42,700,1,13.48,15,1,13.49,100,1,13.74,2,1,14.25,100,1,14.28,100,1,14.4,200,2,14.44,200,2,14.47,700,1,14.48,700,1,14.54,700,1,ARL,338865141
1449,2025-07-17T16:12:41.012094494Z,2025-07-17T16:12:41.011929033Z,10,2,1108,A,A,3,13.76,100,130,165461,282008954,13.11,100,1,12.98,200,2,12.92,2,1,12.86,100,1,12.73,100,1,12.71,100,1,12.5,700,1,12.46,100,1,12.43,700,1,12.42,700,1,13.48,15,1,13.49,100,1,13.74,2,1,13.76,100,1,14.25,100,1,14.28,100,1,14.4,200,2,14.44,200,2,14.47,700,1,14.48,700,1,ARL,338865177
1450,2025-07-17T16:12:42.001347844Z,2025-07-17T16:12:42.001182016Z,10,2,1108,A,A,5,14.28,100,130,165828,282033913,13.11,100,1,12.98,200,2,12.92,2,1,12.86,100,1,12.73,100,1,12.71,100,1,12.5,700,1,12.46,100,1,12.43,700,1,12.42,700,1,13.48,15,1,13.49,100,1,13.74,2,1,13.76,100,1,14.25,100,1,14.28,200,2,14.4,200,2,14.44,200,2,14.47,700,1,14.48,700,1,ARL,338894329
1451,2025-07-17T16:12:42.762154469Z,2025-07-17T16:12:42.761989222Z,10,2,1108,A,A,0,13.46,15,130,165247,282042242,13.11,100,1,12.98,200,2,12.92,2,1,12.86,100,1,12.73,100,1,12.71,100,1,12.5,700,1,12.46,100,1,12.43,700,1,12.42,700,1,13.46,15,1,13.48,15,1,13.49,100,1,13.74,2,1,13.76,100,1,14.25,100,1,14.28,200,2,14.4,200,2,14.44,200,2,14.47,700,1,ARL,338904977
1452,2025-07-17T16:12:43.022127902Z,2025-07-17T16:12:43.021951997Z,10,2,1108,C,A,-1,13.49,100,0,175905,282057719,13.11,100,1,12.98,200,2,12.92,2,1,12.86,100,1,12.73,100,1,12.71,100,1,12.5,700,1,12.46,100,1,12.43,700,1,12.42,700,1,13.46,15,1,13.48,15,1,13.74,2,1,13.76,100,1,14.25,100,1,14.28,200,2,14.4,200,2,14.44,200,2,14.47,700,1,14.48,700,1,ARL,338864581
1453,2025-07-17T16:12:43.022127902Z,2025-07-17T16:12:43.021951997Z,10,2,1108,A,A,1,13.47,100,128,175905,282057719,13.11,100,1,12.98,200,2,12.92,2,1,12.86,100,1,12.73,100,1,12.71,100,1,12.5,700,1,12.46,100,1,12.43,700,1,12.42,700,1,13.46,15,1,13.47,100,1,13.48,15,1,13.74,2,1,13.76,100,1,14.25,100,1,14.28,200,2,14.4,200,2,14.44,200,2,14.47,700,1,ARL,338918217
1454,2025-07-17T16:12:43.154952375Z,2025-07-17T16:12:43.154787212Z,10,2,1108,A,A,6,14.27,100,130,165163,282073056,13.11,100,1,12.98,200,2,12.92,2,1,12.86,100,1,12.73,100,1,12.71,100,1,12.5,700,1,12.46,100,1,12.43,700,1,12.42,700,1,13.46,15,1,13.47,100,1,13.48,15,1,13.74,2,1,13.76,100,1,14.25,100,1,14.27,100,1,14.28,200,2,14.4,200,2,14.44,200,2,ARL,338932853
1455,2025-07-17T16:12:43.915552526Z,2025-07-17T16:12:43.915387059Z,10,2,1108,C,A,7,14.28,100,130,165467,282085822,13.11,100,1,12.98,200,2,12.92,2,1,12.86,100,1,12.73,100,1,12.71,100,1,12.5,700,1,12.46,100,1,12.43,700,1,12.42,700,1,13.46,15,1,13.47,100,1,13.48,15,1,13.74,2,1,13.76,100,1,14.25,100,1,14.27,100,1,14.28,100,1,14.4,200,2,14.44,200,2,ARL,302681357
1456,2025-07-17T16:12:43.915555340Z,2025-07-17T16:12:43.915389642Z,10,2,1108,A,A,5,14,100,130,165698,282085823,13.11,100,1,12.98,200,2,12.92,2,1,12.86,100,1,12.73,100,1,12.71,100,1,12.5,700,1,12.46,100,1,12.43,700,1,12.42,700,1,13.46,15,1,13.47,100,1,13.48,15,1,13.74,2,1,13.76,100,1,14,100,1,14.25,100,1,14.27,100,1,14.28,100,1,14.4,200,2,ARL,338945933
1457,2025-07-17T16:12:50.729244449Z,2025-07-17T16:12:50.729079105Z,10,2,1108,C,A,-1,13.46,15,130,165344,282168721,13.11,100,1,12.98,200,2,12.92,2,1,12.86,100,1,12.73,100,1,12.71,100,1,12.5,700,1,12.46,100,1,12.43,700,1,12.42,700,1,13.47,100,1,13.48,15,1,13.74,2,1,13.76,100,1,14,100,1,14.25,100,1,14.27,100,1,14.28,100,1,14.4,200,2,14.44,200,2,ARL,338904977
1458,2025-07-17T16:12:50.729418237Z,2025-07-17T16:12:50.729252907Z,10,2,1108,C,A,-1,13.48,15,130,165330,282168744,13.11,100,1,12.98,200,2,12.92,2,1,12.86,100,1,12.73,100,1,12.71,100,1,12.5,700,1,12.46,100,1,12.43,700,1,12.42,700,1,13.47,100,1,13.74,2,1,13.76,100,1,14,100,1,14.25,100,1,14.27,100,1,14.28,100,1,14.4,200,2,14.44,200,2,14.47,700,1,ARL,338707945
1459,2025-07-17T16:12:50.729575741Z,2025-07-17T16:12:50.729409745Z,10,2,1108,A,A,0,13.47,96,130,165996,282168754,13.11,100,1,12.98,200,2,12.92,2,1,12.86,100,1,12.73,100,1,12.71,100,1,12.5,700,1,12.46,100,1,12.43,700,1,12.42,700,1,13.47,196,2,13.74,2,1,13.76,100,1,14,100,1,14.25,100,1,14.27,100,1,14.28,100,1,14.4,200,2,14.44,200,2,14.47,700,1,ARL,339054149
1460,2025-07-17T16:12:53.021914652Z,2025-07-17T16:12:53.021749348Z,10,2,1108,A,A,0,13.46,15,130,165304,282194154,13.11,100,1,12.98,200,2,12.92,2,1,12.86,100,1,12.73,100,1,12.71,100,1,12.5,700,1,12.46,100,1,12.43,700,1,12.42,700,1,13.46,15,1,13.47,196,2,13.74,2,1,13.76,100,1,14,100,1,14.25,100,1,14.27,100,1,14.28,100,1,14.4,200,2,14.44,200,2,ARL,339096733
1461,2025-07-17T16:12:53.021959141Z,2025-07-17T16:12:53.021793735Z,10,2,1108,C,A,1,13.47,100,130,165406,282194157,13.11,100,1,12.98,200,2,12.92,2,1,12.86,100,1,12.73,100,1,12.71,100,1,12.5,700,1,12.46,100,1,12.43,700,1,12.42,700,1,13.46,15,1,13.47,96,1,13.74,2,1,13.76,100,1,14,100,1,14.25,100,1,14.27,100,1,14.28,100,1,14.4,200,2,14.44,200,2,ARL,338918217
1462,2025-07-17T16:12:53.022230122Z,2025-07-17T16:12:53.022064745Z,10,2,1108,C,A,-1,13.47,96,130,165377,282194159,13.11,100,1,12.98,200,2,12.92,2,1,12.86,100,1,12.73,100,1,12.71,100,1,12.5,700,1,12.46,100,1,12.43,700,1,12.42,700,1,13.46,15,1,13.74,2,1,13.76,100,1,14,100,1,14.25,100,1,14.27,100,1,14.28,100,1,14.4,200,2,14.44,200,2,14.47,700,1,ARL,339054149
1463,2025-07-17T16:12:53.023589530Z,2025-07-17T16:12:53.023423468Z,10,2,1108,C,A,8,14.44,100,0,166062,282194181,13.11,100,1,12.98,200,2,12.92,2,1,12.86,100,1,12.73,100,1,12.71,100,1,12.5,700,1,12.46,100,1,12.43,700,1,12.42,700,1,13.46,15,1,13.74,2,1,13.76,100,1,14,100,1,14.25,100,1,14.27,100,1,14.28,100,1,14.4,200,2,14.44,100,1,14.47,700,1,ARL,338865165
1464,2025-07-17T16:12:53.025651983Z,2025-07-17T16:12:53.025486466Z,10,2,1108,C,A,-1,14.44,100,0,165517,282194189,13.11,100,1,12.98,200,2,12.92,2,1,12.86,100,1,12.73,100,1,12.71,100,1,12.5,700,1,12.46,100,1,12.43,700,1,12.42,700,1,13.46,15,1,13.74,2,1,13.76,100,1,14,100,1,14.25,100,1,14.27,100,1,14.28,100,1,14.4,200,2,14.47,700,1,14.48,700,1,ARL,338865133
1465,2025-07-17T16:12:53.027715026Z,2025-07-17T16:12:53.027549524Z,10,2,1108,C,A,-1,14.28,100,130,165502,282194224,13.11,100,1,12.98,200,2,12.92,2,1,12.86,100,1,12.73,100,1,12.71,100,1,12.5,700,1,12.46,100,1,12.43,700,1,12.42,700,1,13.46,15,1,13.74,2,1,13.76,100,1,14,100,1,14.25,100,1,14.27,100,1,14.4,200,2,14.47,700,1,14.48,700,1,14.54,700,1,ARL,338894329
1466,2025-07-17T16:12:53.033266537Z,2025-07-17T16:12:53.033101265Z,10,2,1108,C,A,-1,13.76,100,130,165272,282194348,13.11,100,1,12.98,200,2,12.92,2,1,12.86,100,1,12.73,100,1,12.71,100,1,12.5,700,1,12.46,100,1,12.43,700,1,12.42,700,1,13.46,15,1,13.74,2,1,14,100,1,14.25,100,1,14.27,100,1,14.4,200,2,14.47,700,1,14.48,700,1,14.54,700,1,14.55,100,1,ARL,338865177
1467,2025-07-17T16:12:53.033302848Z,2025-07-17T16:12:53.033137644Z,10,2,1108,C,A,-1,14.47,700,130,165204,282194349,13.11,100,1,12.98,200,2,12.92,2,1,12.86,100,1,12.73,100,1,12.71,100,1,12.5,700,1,12.46,100,1,12.43,700,1,12.42,700,1,13.46,15,1,13.74,2,1,14,100,1,14.25,100,1,14.27,100,1,14.4,200,2,14.48,700,1,14.54,700,1,14.55,100,1,14.56,700,1,ARL,338864173
1468,2025-07-17T16:12:53.033318818Z,2025-07-17T16:12:53.033153612Z,10,2,1108,A,A,3,14.04,100,130,165206,282194350,13.11,100,1,12.98,200,2,12.92,2,1,12.86,100,1,12.73,100,1,12.71,100,1,12.5,700,1,12.46,100,1,12.43,700,1,12.42,700,1,13.46,15,1,13.74,2,1,14,100,1,14.04,100,1,14.25,100,1,14.27,100,1,14.4,200,2,14.48,700,1,14.54,700,1,14.55,100,1,ARL,339096893
1469,2025-07-17T16:12:53.033762072Z,2025-07-17T16:12:53.033596046Z,10,2,1108,C,A,-1,13.74,2,0,166026,282194354,13.11,100,1,12.98,200,2,12.92,2,1,12.86,100,1,12.73,100,1,12.71,100,1,12.5,700,1,12.46,100,1,12.43,700,1,12.42,700,1,13.46,15,1,14,100,1,14.04,100,1,14.25,100,1,14.27,100,1,14.4,200,2,14.48,700,1,14.54,700,1,14.55,100,1,14.56,700,1,ARL,338371797
1470,2025-07-17T16:12:53.033762072Z,2025-07-17T16:12:53.033596046Z,10,2,1108,A,A,1,13.98,2,130,166026,282194354,13.11,100,1,12.98,200,2,12.92,2,1,12.86,100,1,12.73,100,1,12.71,100,1,12.5,700,1,12.46,100,1,12.43,700,1,12.42,700,1,13.46,15,1,13.98,2,1,14,100,1,14.04,100,1,14.25,100,1,14.27,100,1,14.4,200,2,14.48,700,1,14.54,700,1,14.55,100,1,ARL,339096909
1471,2025-07-17T16:12:53.034000646Z,2025-07-17T16:12:53.033835120Z,10,2,1108,C,A,-1,14.25,100,130,165526,282194360,13.11,100,1,12.98,200,2,12.92,2,1,12.86,100,1,12.73,100,1,12.71,100,1,12.5,700,1,12.46,100,1,12.43,700,1,12.42,700,1,13.46,15,1,13.98,2,1,14,100,1,14.04,100,1,14.27,100,1,14.4,200,2,14.48,700,1,14.54,700,1,14.55,100,1,14.56,700,1,ARL,336161365
1472,2025-07-17T16:12:53.043727225Z,2025-07-17T16:12:53.043562198Z,10,2,1108,C,A,-1,14.04,100,130,165027,282194436,13.11,100,1,12.98,200,2,12.92,2,1,12.86,100,1,12.73,100,1,12.71,100,1,12.5,700,1,12.46,100,1,12.43,700,1,12.42,700,1,13.46,15,1,13.98,2,1,14,100,1,14.27,100,1,14.4,200,2,14.48,700,1,14.54,700,1,14.55,100,1,14.56,700,1,14.6,100,1,ARL,339096893
1473,2025-07-17T16:12:53.043775299Z,2025-07-17T16:12:53.043610101Z,10,2,1108,A,A,3,14.26,100,130,165198,282194438,13.11,100,1,12.98,200,2,12.92,2,1,12.86,100,1,12.73,100,1,12.71,100,1,12.5,700,1,12.46,100,1,12.43,700,1,12.42,700,1,13.46,15,1,13.98,2,1,14,100,1,14.26,100,1,14.27,100,1,14.4,200,2,14.48,700,1,14.54,700,1,14.55,100,1,14.56,700,1,ARL,339097005
1474,2025-07-17T16:12:53.332729487Z,2025-07-17T16:12:53.332564148Z,10,2,1108,C,A,-1,14,100,130,165339,282196976,13.11,100,1,12.98,200,2,12.92,2,1,12.86,100,1,12.73,100,1,12.71,100,1,12.5,700,1,12.46,100,1,12.43,700,1,12.42,700,1,13.46,15,1,13.98,2,1,14.26,100,1,14.27,100,1,14.4,200,2,14.48,700,1,14.54,700,1,14.55,100,1,14.56,700,1,14.6,100,1,ARL,338945933
1475,2025-07-17T16:12:53.332730508Z,2025-07-17T16:12:53.332565150Z,10,2,1108,A,A,6,14.53,100,130,165358,282196977,13.11,100,1,12.98,200,2,12.92,2,1,12.86,100,1,12.73,100,1,12.71,100,1,12.5,700,1,12.46,100,1,12.43,700,1,12.42,700,1,13.46,15,1,13.98,2,1,14.26,100,1,14.27,100,1,14.4,200,2,14.48,700,1,14.53,100,1,14.54,700,1,14.55,100,1,14.56,700,1,ARL,339100477
1476,2025-07-17T16:12:53.587810242Z,2025-07-17T16:12:53.587644886Z,10,2,1108,C,A,-1,14.27,100,130,165356,282200200,13.11,100,1,12.98,200,2,12.92,2,1,12.86,100,1,12.73,100,1,12.71,100,1,12.5,700,1,12.46,100,1,12.43,700,1,12.42,700,1,13.46,15,1,13.98,2,1,14.26,100,1,14.4,200,2,14.48,700,1,14.53,100,1,14.54,700,1,14.55,100,1,14.56,700,1,14.6,100,1,ARL,338932853
1477,2025-07-17T16:12:54.015217279Z,2025-07-17T16:12:54.015051915Z,10,2,1108,A,A,1,13.47,100,130,165364,282207405,13.11,100,1,12.98,200,2,12.92,2,1,12.86,100,1,12.73,100,1,12.71,100,1,12.5,700,1,12.46,100,1,12.43,700,1,12.42,700,1,13.46,15,1,13.47,100,1,13.98,2,1,14.26,100,1,14.4,200,2,14.48,700,1,14.53,100,1,14.54,700,1,14.55,100,1,14.56,700,1,ARL,339110853
1478,2025-07-17T16:12:54.015954059Z,2025-07-17T16:12:54.015788678Z,10,2,1108,A,A,6,14.52,100,130,165381,282207429,13.11,100,1,12.98,200,2,12.92,2,1,12.86,100,1,12.73,100,1,12.71,100,1,12.5,700,1,12.46,100,1,12.43,700,1,12.42,700,1,13.46,15,1,13.47,100,1,13.98,2,1,14.26,100,1,14.4,200,2,14.48,700,1,14.52,100,1,14.53,100,1,14.54,700,1,14.55,100,1,ARL,339110897
1479,2025-07-17T16:12:54.016305036Z,2025-07-17T16:12:54.016139684Z,10,2,1108,A,A,3,14.07,100,130,165352,282207437,13.11,100,1,12.98,200,2,12.92,2,1,12.86,100,1,12.73,100,1,12.71,100,1,12.5,700,1,12.46,100,1,12.43,700,1,12.42,700,1,13.46,15,1,13.47,100,1,13.98,2,1,14.07,100,1,14.26,100,1,14.4,200,2,14.48,700,1,14.52,100,1,14.53,100,1,14.54,700,1,ARL,339110909
1480,2025-07-17T16:12:54.017154493Z,2025-07-17T16:12:54.016988897Z,10,2,1108,A,A,6,14.42,100,130,165596,282207488,13.11,100,1,12.98,200,2,12.92,2,1,12.86,100,1,12.73,100,1,12.71,100,1,12.5,700,1,12.46,100,1,12.43,700,1,12.42,700,1,13.46,15,1,13.47,100,1,13.98,2,1,14.07,100,1,14.26,100,1,14.4,200,2,14.42,100,1,14.48,700,1,14.52,100,1,14.53,100,1,ARL,339110981
1481,2025-07-17T16:12:54.017381126Z,2025-07-17T16:12:54.017215883Z,10,2,1108,C,A,-1,13.98,2,0,165243,282207495,13.11,100,1,12.98,200,2,12.92,2,1,12.86,100,1,12.73,100,1,12.71,100,1,12.5,700,1,12.46,100,1,12.43,700,1,12.42,700,1,13.46,15,1,13.47,100,1,14.07,100,1,14.26,100,1,14.4,200,2,14.42,100,1,14.48,700,1,14.52,100,1,14.53,100,1,14.54,700,1,ARL,339096909
1482,2025-07-17T16:12:54.017381126Z,2025-07-17T16:12:54.017215883Z,10,2,1108,A,A,2,13.73,2,130,165243,282207495,13.11,100,1,12.98,200,2,12.92,2,1,12.86,100,1,12.73,100,1,12.71,100,1,12.5,700,1,12.46,100,1,12.43,700,1,12.42,700,1,13.46,15,1,13.47,100,1,13.73,2,1,14.07,100,1,14.26,100,1,14.4,200,2,14.42,100,1,14.48,700,1,14.52,100,1,14.53,100,1,ARL,339110993
1483,2025-07-17T16:12:54.020179178Z,2025-07-17T16:12:54.020013940Z,10,2,1108,C,A,-1,14.26,100,130,165238,282207539,13.11,100,1,12.98,200,2,12.92,2,1,12.86,100,1,12.73,100,1,12.71,100,1,12.5,700,1,12.46,100,1,12.43,700,1,12.42,700,1,13.46,15,1,13.47,100,1,13.73,2,1,14.07,100,1,14.4,200,2,14.42,100,1,14.48,700,1,14.52,100,1,14.53,100,1,14.54,700,1,ARL,339097005
1484,2025-07-17T16:12:54.020233019Z,2025-07-17T16:12:54.020067630Z,10,2,1108,A,A,3,13.74,100,130,165389,282207540,13.11,100,1,12.98,200,2,12.92,2,1,12.86,100,1,12.73,100,1,12.71,100,1,12.5,700,1,12.46,100,1,12.43,700,1,12.42,700,1,13.46,15,1,13.47,100,1,13.73,2,1,13.74,100,1,14.07,100,1,14.4,200,2,14.42,100,1,14.48,700,1,14.52,100,1,14.53,100,1,ARL,339111029
1485,2025-07-17T16:12:54.029232379Z,2025-07-17T16:12:54.029066847Z,10,2,1108,A,A,5,14.26,100,130,165532,282207737,13.11,100,1,12.98,200,2,12.92,2,1,12.86,100,1,12.73,100,1,12.71,100,1,12.5,700,1,12.46,100,1,12.43,700,1,12.42,700,1,13.46,15,1,13.47,100,1,13.73,2,1,13.74,100,1,14.07,100,1,14.26,100,1,14.4,200,2,14.42,100,1,14.48,700,1,14.52,100,1,ARL,339111189
1486,2025-07-17T16:12:54.069779810Z,2025-07-17T16:12:54.069614114Z,10,2,1108,A,A,7,14.42,100,130,165696,282210148,13.11,100,1,12.98,200,2,12.92,2,1,12.86,100,1,12.73,100,1,12.71,100,1,12.5,700,1,12.46,100,1,12.43,700,1,12.42,700,1,13.46,15,1,13.47,100,1,13.73,2,1,13.74,100,1,14.07,100,1,14.26,100,1,14.4,200,2,14.42,200,2,14.48,700,1,14.52,100,1,ARL,339112945
1487,2025-07-17T16:12:54.694796063Z,2025-07-17T16:12:54.694630780Z,10,2,1108,A,A,6,14.27,100,130,165283,282224916,13.11,100,1,12.98,200,2,12.92,2,1,12.86,100,1,12.73,100,1,12.71,100,1,12.5,700,1,12.46,100,1,12.43,700,1,12.42,700,1,13.46,15,1,13.47,100,1,13.73,2,1,13.74,100,1,14.07,100,1,14.26,100,1,14.27,100,1,14.4,200,2,14.42,200,2,14.48,700,1,ARL,339126221
1488,2025-07-17T16:12:55.255327586Z,2025-07-17T16:12:55.255162003Z,10,2,1108,A,A,4,14,100,130,165583,282231441,13.11,100,1,12.98,200,2,12.92,2,1,12.86,100,1,12.73,100,1,12.71,100,1,12.5,700,1,12.46,100,1,12.43,700,1,12.42,700,1,13.46,15,1,13.47,100,1,13.73,2,1,13.74,100,1,14,100,1,14.07,100,1,14.26,100,1,14.27,100,1,14.4,200,2,14.42,200,2,ARL,339133353
1489,2025-07-17T16:12:58.302183447Z,2025-07-17T16:12:58.302017238Z,10,2,1108,C,A,-1,13.46,15,128,166209,282279351,13.11,100,1,12.98,200,2,12.92,2,1,12.86,100,1,12.73,100,1,12.71,100,1,12.5,700,1,12.46,100,1,12.43,700,1,12.42,700,1,13.47,100,1,13.73,2,1,13.74,100,1,14,100,1,14.07,100,1,14.26,100,1,14.27,100,1,14.4,200,2,14.42,200,2,14.48,700,1,ARL,339096733
1490,2025-07-17T16:12:58.420887746Z,2025-07-17T16:12:58.420710579Z,10,2,1108,C,A,-1,13.47,100,128,177167,282288716,13.11,100,1,12.98,200,2,12.92,2,1,12.86,100,1,12.73,100,1,12.71,100,1,12.5,700,1,12.46,100,1,12.43,700,1,12.42,700,1,13.73,2,1,13.74,100,1,14,100,1,14.07,100,1,14.26,100,1,14.27,100,1,14.4,200,2,14.42,200,2,14.48,700,1,14.52,100,1,ARL,339110853
1491,2025-07-17T16:12:58.420950587Z,2025-07-17T16:12:58.420776003Z,10,2,1108,A,A,0,13.47,96,128,174584,282288757,13.11,100,1,12.98,200,2,12.92,2,1,12.86,100,1,12.73,100,1,12.71,100,1,12.5,700,1,12.46,100,1,12.43,700,1,12.42,700,1,13.47,96,1,13.73,2,1,13.74,100,1,14,100,1,14.07,100,1,14.26,100,1,14.27,100,1,14.4,200,2,14.42,200,2,14.48,700,1,ARL,339201549
1492,2025-07-17T16:12:58.421338553Z,2025-07-17T16:12:58.421165414Z,10,2,1108,C,A,-1,13.47,96,130,173139,282289082,13.11,100,1,12.98,200,2,12.92,2,1,12.86,100,1,12.73,100,1,12.71,100,1,12.5,700,1,12.46,100,1,12.43,700,1,12.42,700,1,13.73,2,1,13.74,100,1,14,100,1,14.07,100,1,14.26,100,1,14.27,100,1,14.4,200,2,14.42,200,2,14.48,700,1,14.52,100,1,ARL,339201549
1493,2025-07-17T16:12:58.421756726Z,2025-07-17T16:12:58.421581692Z,10,2,1108,C,A,-1,14.07,100,130,175034,282289338,13.11,100,1,12.98,200,2,12.92,2,1,12.86,100,1,12.73,100,1,12.71,100,1,12.5,700,1,12.46,100,1,12.43,700,1,12.42,700,1,13.73,2,1,13.74,100,1,14,100,1,14.26,100,1,14.27,100,1,14.4,200,2,14.42,200,2,14.48,700,1,14.52,100,1,14.54,700,1,ARL,339110909
1494,2025-07-17T16:12:58.422145785Z,2025-07-17T16:12:58.421969675Z,10,2,1108,A,A,5,14.35,100,128,176110,282289650,13.11,100,1,12.98,200,2,12.92,2,1,12.86,100,1,12.73,100,1,12.71,100,1,12.5,700,1,12.46,100,1,12.43,700,1,12.42,700,1,13.73,2,1,13.74,100,1,14,100,1,14.26,100,1,14.27,100,1,14.35,100,1,14.4,200,2,14.42,200,2,14.48,700,1,14.52,100,1,ARL,339202733
1495,2025-07-17T16:12:58.422247877Z,2025-07-17T16:12:58.422073305Z,10,2,1108,C,A,-1,14.52,100,0,174572,282289747,13.11,100,1,12.98,200,2,12.92,2,1,12.86,100,1,12.73,100,1,12.71,100,1,12.5,700,1,12.46,100,1,12.43,700,1,12.42,700,1,13.73,2,1,13.74,100,1,14,100,1,14.26,100,1,14.27,100,1,14.35,100,1,14.4,200,2,14.42,200,2,14.48,700,1,14.54,700,1,ARL,339110897
1496,2025-07-17T16:12:58.424958370Z,2025-07-17T16:12:58.424789366Z,10,2,1108,C,A,6,14.4,100,0,169004,282290622,13.11,100,1,12.98,200,2,12.92,2,1,12.86,100,1,12.73,100,1,12.71,100,1,12.5,700,1,12.46,100,1,12.43,700,1,12.42,700,1,13.73,2,1,13.74,100,1,14,100,1,14.26,100,1,14.27,100,1,14.35,100,1,14.4,100,1,14.42,200,2,14.48,700,1,14.54,700,1,ARL,338139585
1497,2025-07-17T16:12:58.425450176Z,2025-07-17T16:12:58.425283932Z,10,2,1108,C,A,-1,14.4,100,0,166244,282290769,13.11,100,1,12.98,200,2,12.92,2,1,12.86,100,1,12.73,100,1,12.71,100,1,12.5,700,1,12.46,100,1,12.43,700,1,12.42,700,1,13.73,2,1,13.74,100,1,14,100,1,14.26,100,1,14.27,100,1,14.35,100,1,14.42,200,2,14.48,700,1,14.54,700,1,14.56,700,1,ARL,338139601
1498,2025-07-17T16:12:58.426423622Z,2025-07-17T16:12:58.426258092Z,10,2,1108,C,A,-1,14.26,100,130,165530,282290946,13.11,100,1,12.98,200,2,12.92,2,1,12.86,100,1,12.73,100,1,12.71,100,1,12.5,700,1,12.46,100,1,12.43,700,1,12.42,700,1,13.73,2,1,13.74,100,1,14,100,1,14.27,100,1,14.35,100,1,14.42,200,2,14.48,700,1,14.54,700,1,14.56,700,1,14.57,200,2,ARL,339111189
1499,2025-07-17T16:12:58.426544477Z,2025-07-17T16:12:58.426378483Z,10,2,1108,A,A,7,14.53,100,130,165994,282290959,13.11,100,1,12.98,200,2,12.92,2,1,12.86,100,1,12.73,100,1,12.71,100,1,12.5,700,1,12.46,100,1,12.43,700,1,12.42,700,1,13.73,2,1,13.74,100,1,14,100,1,14.27,100,1,14.35,100,1,14.42,200,2,14.48,700,1,14.53,100,1,14.54,700,1,14.56,700,1,ARL,339204077
1500,2025-07-17T16:12:58.430830694Z,2025-07-17T16:12:58.430665639Z,10,2,1108,C,A,-1,13.74,100,130,165055,282291933,13.11,100,1,12.98,200,2,12.92,2,1,12.86,100,1,12.73,100,1,12.71,100,1,12.5,700,1,12.46,100,1,12.43,700,1,12.42,700,1,13.73,2,1,14,100,1,14.27,100,1,14.35,100,1,14.42,200,2,14.48,700,1,14.53,100,1,14.54,700,1,14.56,700,1,14.57,200,2,ARL,339111029
1501,2025-07-17T16:12:58.430888526Z,2025-07-17T16:12:58.430720526Z,10,2,1108,A,A,2,14.01,100,128,168000,282291946,13.11,100,1,12.98,200,2,12.92,2,1,12.86,100,1,12.73,100,1,12.71,100,1,12.5,700,1,12.46,100,1,12.43,700,1,12.42,700,1,13.73,2,1,14,100,1,14.01,100,1,14.27,100,1,14.35,100,1,14.42,200,2,14.48,700,1,14.53,100,1,14.54,700,1,14.56,700,1,ARL,339205213
1502,2025-07-17T16:12:58.438073339Z,2025-07-17T16:12:58.437907652Z,10,2,1108,C,B,-1,12.92,2,0,165687,282292938,13.11,100,1,12.98,200,2,12.86,100,1,12.73,100,1,12.71,100,1,12.5,700,1,12.46,100,1,12.43,700,1,12.42,700,1,12.37,700,1,13.73,2,1,14,100,1,14.01,100,1,14.27,100,1,14.35,100,1,14.42,200,2,14.48,700,1,14.53,100,1,14.54,700,1,14.56,700,1,ARL,338044113
1503,2025-07-17T16:12:58.438073339Z,2025-07-17T16:12:58.437907652Z,10,2,1108,A,B,1,13.02,2,130,165687,282292938,13.11,100,1,13.02,2,1,12.98,200,2,12.86,100,1,12.73,100,1,12.71,100,1,12.5,700,1,12.46,100,1,12.43,700,1,12.42,700,1,13.73,2,1,14,100,1,14.01,100,1,14.27,100,1,14.35,100,1,14.42,200,2,14.48,700,1,14.53,100,1,14.54,700,1,14.56,700,1,ARL,339207125
1504,2025-07-17T16:12:58.438076762Z,2025-07-17T16:12:58.437911392Z,10,2,1108,C,A,-1,13.73,2,0,165370,282292939,13.11,100,1,13.02,2,1,12.98,200,2,12.86,100,1,12.73,100,1,12.71,100,1,12.5,700,1,12.46,100,1,12.43,700,1,12.42,700,1,14,100,1,14.01,100,1,14.27,100,1,14.35,100,1,14.42,200,2,14.48,700,1,14.53,100,1,14.54,700,1,14.56,700,1,14.57,200,2,ARL,339110993
1505,2025-07-17T16:12:58.438076762Z,2025-07-17T16:12:58.437911392Z,10,2,1108,A,A,0,13.98,2,130,165370,282292939,13.11,100,1,13.02,2,1,12.98,200,2,12.86,100,1,12.73,100,1,12.71,100,1,12.5,700,1,12.46,100,1,12.43,700,1,12.42,700,1,13.98,2,1,14,100,1,14.01,100,1,14.27,100,1,14.35,100,1,14.42,200,2,14.48,700,1,14.53,100,1,14.54,700,1,14.56,700,1,ARL,339207129
1506,2025-07-17T16:12:58.438843944Z,2025-07-17T16:12:58.438678961Z,10,2,1108,C,A,-1,14.01,100,130,164983,282293023,13.11,100,1,13.02,2,1,12.98,200,2,12.86,100,1,12.73,100,1,12.71,100,1,12.5,700,1,12.46,100,1,12.43,700,1,12.42,700,1,13.98,2,1,14,100,1,14.27,100,1,14.35,100,1,14.42,200,2,14.48,700,1,14.53,100,1,14.54,700,1,14.56,700,1,14.57,200,2,ARL,339205213
1507,2025-07-17T16:12:58.438894336Z,2025-07-17T16:12:58.438728994Z,10,2,1108,A,A,2,14.24,100,130,165342,282293026,13.11,100,1,13.02,2,1,12.98,200,2,12.86,100,1,12.73,100,1,12.71,100,1,12.5,700,1,12.46,100,1,12.43,700,1,12.42,700,1,13.98,2,1,14,100,1,14.24,100,1,14.27,100,1,14.35,100,1,14.42,200,2,14.48,700,1,14.53,100,1,14.54,700,1,14.56,700,1,ARL,339207197
1508,2025-07-17T16:12:58.441834497Z,2025-07-17T16:12:58.441669159Z,10,2,1108,C,A,5,14.42,100,0,165338,282293191,13.11,100,1,13.02,2,1,12.98,200,2,12.86,100,1,12.73,100,1,12.71,100,1,12.5,700,1,12.46,100,1,12.43,700,1,12.42,700,1,13.98,2,1,14,100,1,14.24,100,1,14.27,100,1,14.35,100,1,14.42,100,1,14.48,700,1,14.53,100,1,14.54,700,1,14.56,700,1,ARL,339110981
1509,2025-07-17T16:12:58.619404102Z,2025-07-17T16:12:58.619238614Z,10,2,1108,C,A,-1,14.42,100,0,165488,282299781,13.11,100,1,13.02,2,1,12.98,200,2,12.86,100,1,12.73,100,1,12.71,100,1,12.5,700,1,12.46,100,1,12.43,700,1,12.42,700,1,13.98,2,1,14,100,1,14.24,100,1,14.27,100,1,14.35,100,1,14.48,700,1,14.53,100,1,14.54,700,1,14.56,700,1,14.57,200,2,ARL,339112945
1510,2025-07-17T16:12:58.986093948Z,2025-07-17T16:12:58.985928594Z,10,2,1108,C,B,-1,13.02,2,0,165354,282305386,13.11,100,1,12.98,200,2,12.86,100,1,12.73,100,1,12.71,100,1,12.5,700,1,12.46,100,1,12.43,700,1,12.42,700,1,12.37,700,1,13.98,2,1,14,100,1,14.24,100,1,14.27,100,1,14.35,100,1,14.48,700,1,14.53,100,1,14.54,700,1,14.56,700,1,14.57,200,2,ARL,339207125
1511,2025-07-17T16:12:58.986093948Z,2025-07-17T16:12:58.985928594Z,10,2,1108,A,B,2,12.86,2,130,165354,282305386,13.11,100,1,12.98,200,2,12.86,102,2,12.73,100,1,12.71,100,1,12.5,700,1,12.46,100,1,12.43,700,1,12.42,700,1,12.37,700,1,13.98,2,1,14,100,1,14.24,100,1,14.27,100,1,14.35,100,1,14.48,700,1,14.53,100,1,14.54,700,1,14.56,700,1,14.57,200,2,ARL,339222617
1512,2025-07-17T16:12:59.063108412Z,2025-07-17T16:12:59.062943193Z,10,2,1108,A,A,1,13.99,100,130,165219,282306400,13.11,100,1,12.98,200,2,12.86,102,2,12.73,100,1,12.71,100,1,12.5,700,1,12.46,100,1,12.43,700,1,12.42,700,1,12.37,700,1,13.98,2,1,13.99,100,1,14,100,1,14.24,100,1,14.27,100,1,14.35,100,1,14.48,700,1,14.53,100,1,14.54,700,1,14.56,700,1,ARL,339224109
1513,2025-07-17T16:12:59.082855570Z,2025-07-17T16:12:59.082690430Z,10,2,1108,C,A,-1,14,100,130,165140,282307908,13.11,100,1,12.98,200,2,12.86,102,2,12.73,100,1,12.71,100,1,12.5,700,1,12.46,100,1,12.43,700,1,12.42,700,1,12.37,700,1,13.98,2,1,13.99,100,1,14.24,100,1,14.27,100,1,14.35,100,1,14.48,700,1,14.53,100,1,14.54,700,1,14.56,700,1,14.57,200,2,ARL,339133353
1514,2025-07-17T16:12:59.082856640Z,2025-07-17T16:12:59.082691385Z,10,2,1108,A,A,6,14.53,100,130,165255,282307909,13.11,100,1,12.98,200,2,12.86,102,2,12.73,100,1,12.71,100,1,12.5,700,1,12.46,100,1,12.43,700,1,12.42,700,1,12.37,700,1,13.98,2,1,13.99,100,1,14.24,100,1,14.27,100,1,14.35,100,1,14.48,700,1,14.53,200,2,14.54,700,1,14.56,700,1,14.57,200,2,ARL,339225769
1515,2025-07-17T16:12:59.088808117Z,2025-07-17T16:12:59.088642718Z,10,2,1108,C,A,-1,14.27,100,130,165399,282308094,13.11,100,1,12.98,200,2,12.86,102,2,12.73,100,1,12.71,100,1,12.5,700,1,12.46,100,1,12.43,700,1,12.42,700,1,12.37,700,1,13.98,2,1,13.99,100,1,14.24,100,1,14.35,100,1,14.48,700,1,14.53,200,2,14.54,700,1,14.56,700,1,14.57,200,2,14.68,700,1,ARL,339126221
1516,2025-07-17T16:12:59.092927842Z,2025-07-17T16:12:59.092762564Z,10,2,1108,C,A,-1,14.35,100,130,165278,282308154,13.11,100,1,12.98,200,2,12.86,102,2,12.73,100,1,12.71,100,1,12.5,700,1,12.46,100,1,12.43,700,1,12.42,700,1,12.37,700,1,13.98,2,1,13.99,100,1,14.24,100,1,14.48,700,1,14.53,200,2,14.54,700,1,14.56,700,1,14.57,200,2,14.68,700,1,14.81,100,1,ARL,339202733
1517,2025-07-17T16:12:59.093278915Z,2025-07-17T16:12:59.093113488Z,10,2,1108,A,A,8,14.6,100,130,165427,282308163,13.11,100,1,12.98,200,2,12.86,102,2,12.73,100,1,12.71,100,1,12.5,700,1,12.46,100,1,12.43,700,1,12.42,700,1,12.37,700,1,13.98,2,1,13.99,100,1,14.24,100,1,14.48,700,1,14.53,200,2,14.54,700,1,14.56,700,1,14.57,200,2,14.6,100,1,14.68,700,1,ARL,339226021
1518,2025-07-17T16:12:59.430486012Z,2025-07-17T16:12:59.430320610Z,10,2,1108,C,A,4,14.53,100,0,165402,282313368,13.11,100,1,12.98,200,2,12.86,102,2,12.73,100,1,12.71,100,1,12.5,700,1,12.46,100,1,12.43,700,1,12.42,700,1,12.37,700,1,13.98,2,1,13.99,100,1,14.24,100,1,14.48,700,1,14.53,100,1,14.54,700,1,14.56,700,1,14.57,200,2,14.6,100,1,14.68,700,1,ARL,339204077
1519,2025-07-17T16:13:04.825902166Z,2025-07-17T16:13:04.825736034Z,10,2,1108,A,A,0,13.66,15,128,166132,282392593,13.11,100,1,12.98,200,2,12.86,102,2,12.73,100,1,12.71,100,1,12.5,700,1,12.46,100,1,12.43,700,1,12.42,700,1,12.37,700,1,13.66,15,1,13.98,2,1,13.99,100,1,14.24,100,1,14.48,700,1,14.53,100,1,14.54,700,1,14.56,700,1,14.57,200,2,14.6,100,1,ARL,339332865
1520,2025-07-17T16:13:06.189275812Z,2025-07-17T16:13:06.189110140Z,10,2,1108,C,B,2,12.86,2,0,165672,282411935,13.11,100,1,12.98,200,2,12.86,100,1,12.73,100,1,12.71,100,1,12.5,700,1,12.46,100,1,12.43,700,1,12.42,700,1,12.37,700,1,13.66,15,1,13.98,2,1,13.99,100,1,14.24,100,1,14.48,700,1,14.53,100,1,14.54,700,1,14.56,700,1,14.57,200,2,14.6,100,1,ARL,339222617
1521,2025-07-17T16:13:06.189275812Z,2025-07-17T16:13:06.189110140Z,10,2,1108,A,B,2,12.96,2,130,165672,282411935,13.11,100,1,12.98,200,2,12.96,2,1,12.86,100,1,12.73,100,1,12.71,100,1,12.5,700,1,12.46,100,1,12.43,700,1,12.42,700,1,13.66,15,1,13.98,2,1,13.99,100,1,14.24,100,1,14.48,700,1,14.53,100,1,14.54,700,1,14.56,700,1,14.57,200,2,14.6,100,1,ARL,339356397
1522,2025-07-17T16:13:06.224898389Z,2025-07-17T16:13:06.224732787Z,10,2,1108,C,A,-1,13.99,100,0,165602,282413599,13.11,100,1,12.98,200,2,12.96,2,1,12.86,100,1,12.73,100,1,12.71,100,1,12.5,700,1,12.46,100,1,12.43,700,1,12.42,700,1,13.66,15,1,13.98,2,1,14.24,100,1,14.48,700,1,14.53,100,1,14.54,700,1,14.56,700,1,14.57,200,2,14.6,100,1,14.68,700,1,ARL,339224109
1523,2025-07-17T16:13:06.224898389Z,2025-07-17T16:13:06.224732787Z,10,2,1108,A,A,1,13.67,100,130,165602,282413599,13.11,100,1,12.98,200,2,12.96,2,1,12.86,100,1,12.73,100,1,12.71,100,1,12.5,700,1,12.46,100,1,12.43,700,1,12.42,700,1,13.66,15,1,13.67,100,1,13.98,2,1,14.24,100,1,14.48,700,1,14.53,100,1,14.54,700,1,14.56,700,1,14.57,200,2,14.6,100,1,ARL,339358233
1524,2025-07-17T16:13:06.225642781Z,2025-07-17T16:13:06.225475906Z,10,2,1108,C,A,-1,14.6,100,128,166875,282413678,13.11,100,1,12.98,200,2,12.96,2,1,12.86,100,1,12.73,100,1,12.71,100,1,12.5,700,1,12.46,100,1,12.43,700,1,12.42,700,1,13.66,15,1,13.67,100,1,13.98,2,1,14.24,100,1,14.48,700,1,14.53,100,1,14.54,700,1,14.56,700,1,14.57,200,2,14.68,700,1,ARL,339226021
1525,2025-07-17T16:13:06.225995297Z,2025-07-17T16:13:06.225829921Z,10,2,1108,A,A,4,14.28,100,130,165376,282413699,13.11,100,1,12.98,200,2,12.96,2,1,12.86,100,1,12.73,100,1,12.71,100,1,12.5,700,1,12.46,100,1,12.43,700,1,12.42,700,1,13.66,15,1,13.67,100,1,13.98,2,1,14.24,100,1,14.28,100,1,14.48,700,1,14.53,100,1,14.54,700,1,14.56,700,1,14.57,200,2,ARL,339358333
1526,2025-07-17T16:13:06.229858538Z,2025-07-17T16:13:06.229693020Z,10,2,1108,C,A,-1,13.98,2,0,165518,282413801,13.11,100,1,12.98,200,2,12.96,2,1,12.86,100,1,12.73,100,1,12.71,100,1,12.5,700,1,12.46,100,1,12.43,700,1,12.42,700,1,13.66,15,1,13.67,100,1,14.24,100,1,14.28,100,1,14.48,700,1,14.53,100,1,14.54,700,1,14.56,700,1,14.57,200,2,14.63,100,1,ARL,339207129
1527,2025-07-17T16:13:06.229858538Z,2025-07-17T16:13:06.229693020Z,10,2,1108,A,A,2,13.81,2,130,165518,282413801,13.11,100,1,12.98,200,2,12.96,2,1,12.86,100,1,12.73,100,1,12.71,100,1,12.5,700,1,12.46,100,1,12.43,700,1,12.42,700,1,13.66,15,1,13.67,100,1,13.81,2,1,14.24,100,1,14.28,100,1,14.48,700,1,14.53,100,1,14.54,700,1,14.56,700,1,14.57,200,2,ARL,339358409
1528,2025-07-17T16:13:06.236567790Z,2025-07-17T16:13:06.236401579Z,10,2,1108,C,A,-1,14.24,100,130,166211,282414131,13.11,100,1,12.98,200,2,12.96,2,1,12.86,100,1,12.73,100,1,12.71,100,1,12.5,700,1,12.46,100,1,12.43,700,1,12.42,700,1,13.66,15,1,13.67,100,1,13.81,2,1,14.28,100,1,14.48,700,1,14.53,100,1,14.54,700,1,14.56,700,1,14.57,200,2,14.63,100,1,ARL,339207197
1529,2025-07-17T16:13:06.236621535Z,2025-07-17T16:13:06.236456489Z,10,2,1108,A,A,3,13.94,100,130,165046,282414141,13.11,100,1,12.98,200,2,12.96,2,1,12.86,100,1,12.73,100,1,12.71,100,1,12.5,700,1,12.46,100,1,12.43,700,1,12.42,700,1,13.66,15,1,13.67,100,1,13.81,2,1,13.94,100,1,14.28,100,1,14.48,700,1,14.53,100,1,14.54,700,1,14.56,700,1,14.57,200,2,ARL,339358741
1530,2025-07-17T16:13:06.277178914Z,2025-07-17T16:13:06.277013512Z,10,2,1108,A,A,5,14.46,100,130,165402,282414660,13.11,100,1,12.98,200,2,12.96,2,1,12.86,100,1,12.73,100,1,12.71,100,1,12.5,700,1,12.46,100,1,12.43,700,1,12.42,700,1,13.66,15,1,13.67,100,1,13.81,2,1,13.94,100,1,14.28,100,1,14.46,100,1,14.48,700,1,14.53,100,1,14.54,700,1,14.56,700,1,ARL,339359421
1531,2025-07-17T16:13:06.622659102Z,2025-07-17T16:13:06.622493734Z,10,2,1108,A,A,4,14.22,100,130,165368,282418746,13.11,100,1,12.98,200,2,12.96,2,1,12.86,100,1,12.73,100,1,12.71,100,1,12.5,700,1,12.46,100,1,12.43,700,1,12.42,700,1,13.66,15,1,13.67,100,1,13.81,2,1,13.94,100,1,14.22,100,1,14.28,100,1,14.46,100,1,14.48,700,1,14.53,100,1,14.54,700,1,ARL,339365193
1532,2025-07-17T16:13:06.663836744Z,2025-07-17T16:13:06.663671305Z,10,2,1108,C,A,-1,14.53,100,130,165439,282418921,13.11,100,1,12.98,200,2,12.96,2,1,12.86,100,1,12.73,100,1,12.71,100,1,12.5,700,1,12.46,100,1,12.43,700,1,12.42,700,1,13.66,15,1,13.67,100,1,13.81,2,1,13.94,100,1,14.22,100,1,14.28,100,1,14.46,100,1,14.48,700,1,14.54,700,1,14.56,700,1,ARL,339225769
1533,2025-07-17T16:13:06.759791103Z,2025-07-17T16:13:06.759625628Z,10,2,1108,A,A,8,14.49,100,130,165475,282419471,13.11,100,1,12.98,200,2,12.96,2,1,12.86,100,1,12.73,100,1,12.71,100,1,12.5,700,1,12.46,100,1,12.43,700,1,12.42,700,1,13.66,15,1,13.67,100,1,13.81,2,1,13.94,100,1,14.22,100,1,14.28,100,1,14.46,100,1,14.48,700,1,14.49,100,1,14.54,700,1,ARL,339366385
1534,2025-07-17T16:13:09.354048740Z,2025-07-17T16:13:09.353883614Z,10,2,1108,A,A,0,13.64,15,130,165126,282469242,13.11,100,1,12.98,200,2,12.96,2,1,12.86,100,1,12.73,100,1,12.71,100,1,12.5,700,1,12.46,100,1,12.43,700,1,12.42,700,1,13.64,15,1,13.66,15,1,13.67,100,1,13.81,2,1,13.94,100,1,14.22,100,1,14.28,100,1,14.46,100,1,14.48,700,1,14.49,100,1,ARL,339425837
1535,2025-07-17T16:13:09.368197659Z,2025-07-17T16:13:09.368030843Z,10,2,1108,C,A,-1,13.67,100,0,166816,282470466,13.11,100,1,12.98,200,2,12.96,2,1,12.86,100,1,12.73,100,1,12.71,100,1,12.5,700,1,12.46,100,1,12.43,700,1,12.42,700,1,13.64,15,1,13.66,15,1,13.81,2,1,13.94,100,1,14.22,100,1,14.28,100,1,14.46,100,1,14.48,700,1,14.49,100,1,14.54,700,1,ARL,339358233
1536,2025-07-17T16:13:09.368197659Z,2025-07-17T16:13:09.368030843Z,10,2,1108,A,A,1,13.65,100,128,166816,282470466,13.11,100,1,12.98,200,2,12.96,2,1,12.86,100,1,12.73,100,1,12.71,100,1,12.5,700,1,12.46,100,1,12.43,700,1,12.42,700,1,13.64,15,1,13.65,100,1,13.66,15,1,13.81,2,1,13.94,100,1,14.22,100,1,14.28,100,1,14.46,100,1,14.48,700,1,14.49,100,1,ARL,339427217
1537,2025-07-17T16:13:14.046267875Z,2025-07-17T16:13:14.046102556Z,10,2,1108,C,A,-1,13.66,15,130,165319,282563502,13.11,100,1,12.98,200,2,12.96,2,1,12.86,100,1,12.73,100,1,12.71,100,1,12.5,700,1,12.46,100,1,12.43,700,1,12.42,700,1,13.64,15,1,13.65,100,1,13.81,2,1,13.94,100,1,14.22,100,1,14.28,100,1,14.46,100,1,14.48,700,1,14.49,100,1,14.54,700,1,ARL,339332865
1538,2025-07-17T16:13:17.775210916Z,2025-07-17T16:13:17.775045316Z,10,2,1108,A,A,0,13.57,15,130,165600,282616566,13.11,100,1,12.98,200,2,12.96,2,1,12.86,100,1,12.73,100,1,12.71,100,1,12.5,700,1,12.46,100,1,12.43,700,1,12.42,700,1,13.57,15,1,13.64,15,1,13.65,100,1,13.81,2,1,13.94,100,1,14.22,100,1,14.28,100,1,14.46,100,1,14.48,700,1,14.49,100,1,ARL,339610637
1539,2025-07-17T16:13:19.781143691Z,2025-07-17T16:13:19.780978185Z,10,2,1108,C,A,-1,13.65,100,0,165506,282644181,13.11,100,1,12.98,200,2,12.96,2,1,12.86,100,1,12.73,100,1,12.71,100,1,12.5,700,1,12.46,100,1,12.43,700,1,12.42,700,1,13.57,15,1,13.64,15,1,13.81,2,1,13.94,100,1,14.22,100,1,14.28,100,1,14.46,100,1,14.48,700,1,14.49,100,1,14.54,700,1,ARL,339427217
1540,2025-07-17T16:13:19.781143691Z,2025-07-17T16:13:19.780978185Z,10,2,1108,A,A,1,13.58,100,130,165506,282644181,13.11,100,1,12.98,200,2,12.96,2,1,12.86,100,1,12.73,100,1,12.71,100,1,12.5,700,1,12.46,100,1,12.43,700,1,12.42,700,1,13.57,15,1,13.58,100,1,13.64,15,1,13.81,2,1,13.94,100,1,14.22,100,1,14.28,100,1,14.46,100,1,14.48,700,1,14.49,100,1,ARL,339641813
1541,2025-07-17T16:13:19.789771458Z,2025-07-17T16:13:19.789606057Z,10,2,1108,C,A,-1,13.94,100,130,165401,282644321,13.11,100,1,12.98,200,2,12.96,2,1,12.86,100,1,12.73,100,1,12.71,100,1,12.5,700,1,12.46,100,1,12.43,700,1,12.42,700,1,13.57,15,1,13.58,100,1,13.64,15,1,13.81,2,1,14.22,100,1,14.28,100,1,14.46,100,1,14.48,700,1,14.49,100,1,14.54,700,1,ARL,339358741
1542,2025-07-17T16:13:19.789822010Z,2025-07-17T16:13:19.789656689Z,10,2,1108,A,A,4,13.85,100,130,165321,282644322,13.11,100,1,12.98,200,2,12.96,2,1,12.86,100,1,12.73,100,1,12.71,100,1,12.5,700,1,12.46,100,1,12.43,700,1,12.42,700,1,13.57,15,1,13.58,100,1,13.64,15,1,13.81,2,1,13.85,100,1,14.22,100,1,14.28,100,1,14.46,100,1,14.48,700,1,14.49,100,1,ARL,339642033
1543,2025-07-17T16:13:19.863618706Z,2025-07-17T16:13:19.863452537Z,10,2,1108,C,A,-1,13.57,15,130,166169,282645966,13.11,100,1,12.98,200,2,12.96,2,1,12.86,100,1,12.73,100,1,12.71,100,1,12.5,700,1,12.46,100,1,12.43,700,1,12.42,700,1,13.58,100,1,13.64,15,1,13.81,2,1,13.85,100,1,14.22,100,1,14.28,100,1,14.46,100,1,14.48,700,1,14.49,100,1,14.54,700,1,ARL,339610637
1544,2025-07-17T16:13:19.863790083Z,2025-07-17T16:13:19.863624798Z,10,2,1108,C,A,-1,13.64,15,130,165285,282646001,13.11,100,1,12.98,200,2,12.96,2,1,12.86,100,1,12.73,100,1,12.71,100,1,12.5,700,1,12.46,100,1,12.43,700,1,12.42,700,1,13.58,100,1,13.81,2,1,13.85,100,1,14.22,100,1,14.28,100,1,14.46,100,1,14.48,700,1,14.49,100,1,14.54,700,1,14.56,700,1,ARL,339425837
1545,2025-07-17T16:13:19.863968792Z,2025-07-17T16:13:19.863803503Z,10,2,1108,A,A,0,13.58,96,130,165289,282646014,13.11,100,1,12.98,200,2,12.96,2,1,12.86,100,1,12.73,100,1,12.71,100,1,12.5,700,1,12.46,100,1,12.43,700,1,12.42,700,1,13.58,196,2,13.81,2,1,13.85,100,1,14.22,100,1,14.28,100,1,14.46,100,1,14.48,700,1,14.49,100,1,14.54,700,1,14.56,700,1,ARL,339643285
1546,2025-07-17T16:13:24.182625011Z,2025-07-17T16:13:24.182459676Z,10,2,1108,A,A,0,13.57,15,130,165335,282694909,13.11,100,1,12.98,200,2,12.96,2,1,12.86,100,1,12.73,100,1,12.71,100,1,12.5,700,1,12.46,100,1,12.43,700,1,12.42,700,1,13.57,15,1,13.58,196,2,13.81,2,1,13.85,100,1,14.22,100,1,14.28,100,1,14.46,100,1,14.48,700,1,14.49,100,1,14.54,700,1,ARL,339710089
1547,2025-07-17T16:13:24.182918202Z,2025-07-17T16:13:24.182753004Z,10,2,1108,C,A,1,13.58,96,130,165198,282694924,13.11,100,1,12.98,200,2,12.96,2,1,12.86,100,1,12.73,100,1,12.71,100,1,12.5,700,1,12.46,100,1,12.43,700,1,12.42,700,1,13.57,15,1,13.58,100,1,13.81,2,1,13.85,100,1,14.22,100,1,14.28,100,1,14.46,100,1,14.48,700,1,14.49,100,1,14.54,700,1,ARL,339643285
1548,2025-07-17T16:13:24.627374514Z,2025-07-17T16:13:24.627209125Z,10,2,1108,A,A,5,14.26,700,130,165389,282700118,13.11,100,1,12.98,200,2,12.96,2,1,12.86,100,1,12.73,100,1,12.71,100,1,12.5,700,1,12.46,100,1,12.43,700,1,12.42,700,1,13.57,15,1,13.58,100,1,13.81,2,1,13.85,100,1,14.22,100,1,14.26,700,1,14.28,100,1,14.46,100,1,14.48,700,1,14.49,100,1,ARL,339716321
1549,2025-07-17T16:13:25.962717944Z,2025-07-17T16:13:25.962552288Z,10,2,1108,A,A,7,14.46,100,130,165656,282719507,13.11,100,1,12.98,200,2,12.96,2,1,12.86,100,1,12.73,100,1,12.71,100,1,12.5,700,1,12.46,100,1,12.43,700,1,12.42,700,1,13.57,15,1,13.58,100,1,13.81,2,1,13.85,100,1,14.22,100,1,14.26,700,1,14.28,100,1,14.46,200,2,14.48,700,1,14.49,100,1,ARL,339739285
1550,2025-07-17T16:13:25.963209328Z,2025-07-17T16:13:25.963043858Z,10,2,1108,A,A,7,14.46,100,130,165470,282719515,13.11,100,1,12.98,200,2,12.96,2,1,12.86,100,1,12.73,100,1,12.71,100,1,12.5,700,1,12.46,100,1,12.43,700,1,12.42,700,1,13.57,15,1,13.58,100,1,13.81,2,1,13.85,100,1,14.22,100,1,14.26,700,1,14.28,100,1,14.46,300,3,14.48,700,1,14.49,100,1,ARL,339739297
1551,2025-07-17T16:13:34.825229037Z,2025-07-17T16:13:34.825063658Z,10,2,1108,A,A,0,13.55,15,130,165379,282849136,13.11,100,1,12.98,200,2,12.96,2,1,12.86,100,1,12.73,100,1,12.71,100,1,12.5,700,1,12.46,100,1,12.43,700,1,12.42,700,1,13.55,15,1,13.57,15,1,13.58,100,1,13.81,2,1,13.85,100,1,14.22,100,1,14.26,700,1,14.28,100,1,14.46,300,3,14.48,700,1,ARL,339897885
1552,2025-07-17T16:13:36.525450545Z,2025-07-17T16:13:36.525285006Z,10,2,1108,C,A,-1,13.58,100,0,165539,282880671,13.11,100,1,12.98,200,2,12.96,2,1,12.86,100,1,12.73,100,1,12.71,100,1,12.5,700,1,12.46,100,1,12.43,700,1,12.42,700,1,13.55,15,1,13.57,15,1,13.81,2,1,13.85,100,1,14.22,100,1,14.26,700,1,14.28,100,1,14.46,300,3,14.48,700,1,14.49,100,1,ARL,339641813
1553,2025-07-17T16:13:36.525450545Z,2025-07-17T16:13:36.525285006Z,10,2,1108,A,A,1,13.56,100,130,165539,282880671,13.11,100,1,12.98,200,2,12.96,2,1,12.86,100,1,12.73,100,1,12.71,100,1,12.5,700,1,12.46,100,1,12.43,700,1,12.42,700,1,13.55,15,1,13.56,100,1,13.57,15,1,13.81,2,1,13.85,100,1,14.22,100,1,14.26,700,1,14.28,100,1,14.46,300,3,14.48,700,1,ARL,339937253
1554,2025-07-17T16:13:40.166698198Z,2025-07-17T16:13:40.166532673Z,10,2,1108,C,A,-1,13.57,15,130,165525,282934517,13.11,100,1,12.98,200,2,12.96,2,1,12.86,100,1,12.73,100,1,12.71,100,1,12.5,700,1,12.46,100,1,12.43,700,1,12.42,700,1,13.55,15,1,13.56,100,1,13.81,2,1,13.85,100,1,14.22,100,1,14.26,700,1,14.28,100,1,14.46,300,3,14.48,700,1,14.49,100,1,ARL,339710089
1555,2025-07-17T16:13:41.168681977Z,2025-07-17T16:13:41.168516592Z,10,2,1108,A,A,0,13.53,15,130,165385,282947373,13.11,100,1,12.98,200,2,12.96,2,1,12.86,100,1,12.73,100,1,12.71,100,1,12.5,700,1,12.46,100,1,12.43,700,1,12.42,700,1,13.53,15,1,13.55,15,1,13.56,100,1,13.81,2,1,13.85,100,1,14.22,100,1,14.26,700,1,14.28,100,1,14.46,300,3,14.48,700,1,ARL,340027925
1556,2025-07-17T16:13:41.810648775Z,2025-07-17T16:13:41.810482971Z,10,2,1108,C,A,-1,13.56,100,0,165804,282959674,13.11,100,1,12.98,200,2,12.96,2,1,12.86,100,1,12.73,100,1,12.71,100,1,12.5,700,1,12.46,100,1,12.43,700,1,12.42,700,1,13.53,15,1,13.55,15,1,13.81,2,1,13.85,100,1,14.22,100,1,14.26,700,1,14.28,100,1,14.46,300,3,14.48,700,1,14.49,100,1,ARL,339937253
1557,2025-07-17T16:13:41.810648775Z,2025-07-17T16:13:41.810482971Z,10,2,1108,A,A,1,13.54,100,130,165804,282959674,13.11,100,1,12.98,200,2,12.96,2,1,12.86,100,1,12.73,100,1,12.71,100,1,12.5,700,1,12.46,100,1,12.43,700,1,12.42,700,1,13.53,15,1,13.54,100,1,13.55,15,1,13.81,2,1,13.85,100,1,14.22,100,1,14.26,700,1,14.28,100,1,14.46,300,3,14.48,700,1,ARL,340046965
1558,2025-07-17T16:13:53.138391930Z,2025-07-17T16:13:53.138226660Z,10,2,1108,C,A,-1,13.53,15,130,165270,283090735,13.11,100,1,12.98,200,2,12.96,2,1,12.86,100,1,12.73,100,1,12.71,100,1,12.5,700,1,12.46,100,1,12.43,700,1,12.42,700,1,13.54,100,1,13.55,15,1,13.81,2,1,13.85,100,1,14.22,100,1,14.26,700,1,14.28,100,1,14.46,300,3,14.48,700,1,14.49,100,1,ARL,340027925
1559,2025-07-17T16:13:53.784302227Z,2025-07-17T16:13:53.784124590Z,10,2,1108,C,A,-1,13.55,15,128,177637,283098338,13.11,100,1,12.98,200,2,12.96,2,1,12.86,100,1,12.73,100,1,12.71,100,1,12.5,700,1,12.46,100,1,12.43,700,1,12.42,700,1,13.54,100,1,13.81,2,1,13.85,100,1,14.22,100,1,14.26,700,1,14.28,100,1,14.46,300,3,14.48,700,1,14.49,100,1,14.54,700,1,ARL,339897885
1560,2025-07-17T16:14:06.190866982Z,2025-07-17T16:14:06.190701389Z,10,2,1108,C,A,-1,13.81,2,0,165593,283262191,13.11,100,1,12.98,200,2,12.96,2,1,12.86,100,1,12.73,100,1,12.71,100,1,12.5,700,1,12.46,100,1,12.43,700,1,12.42,700,1,13.54,100,1,13.85,100,1,14.22,100,1,14.26,700,1,14.28,100,1,14.46,300,3,14.48,700,1,14.49,100,1,14.54,700,1,14.56,700,1,ARL,339358409
1561,2025-07-17T16:14:06.190866982Z,2025-07-17T16:14:06.190701389Z,10,2,1108,A,A,1,13.74,2,130,165593,283262191,13.11,100,1,12.98,200,2,12.96,2,1,12.86,100,1,12.73,100,1,12.71,100,1,12.5,700,1,12.46,100,1,12.43,700,1,12.42,700,1,13.54,100,1,13.74,2,1,13.85,100,1,14.22,100,1,14.26,700,1,14.28,100,1,14.46,300,3,14.48,700,1,14.49,100,1,14.54,700,1,ARL,340449865
1562,2025-07-17T16:14:10.827419207Z,2025-07-17T16:14:10.827253317Z,10,2,1108,A,A,0,13.51,15,130,165890,283315922,13.11,100,1,12.98,200,2,12.96,2,1,12.86,100,1,12.73,100,1,12.71,100,1,12.5,700,1,12.46,100,1,12.43,700,1,12.42,700,1,13.51,15,1,13.54,100,1,13.74,2,1,13.85,100,1,14.22,100,1,14.26,700,1,14.28,100,1,14.46,300,3,14.48,700,1,14.49,100,1,ARL,340526285
1563,2025-07-17T16:14:10.876894854Z,2025-07-17T16:14:10.876729278Z,10,2,1108,C,A,-1,13.54,100,0,165576,283317356,13.11,100,1,12.98,200,2,12.96,2,1,12.86,100,1,12.73,100,1,12.71,100,1,12.5,700,1,12.46,100,1,12.43,700,1,12.42,700,1,13.51,15,1,13.74,2,1,13.85,100,1,14.22,100,1,14.26,700,1,14.28,100,1,14.46,300,3,14.48,700,1,14.49,100,1,14.54,700,1,ARL,340046965
1564,2025-07-17T16:14:10.876894854Z,2025-07-17T16:14:10.876729278Z,10,2,1108,A,A,1,13.52,100,130,165576,283317356,13.11,100,1,12.98,200,2,12.96,2,1,12.86,100,1,12.73,100,1,12.71,100,1,12.5,700,1,12.46,100,1,12.43,700,1,12.42,700,1,13.51,15,1,13.52,100,1,13.74,2,1,13.85,100,1,14.22,100,1,14.26,700,1,14.28,100,1,14.46,300,3,14.48,700,1,14.49,100,1,ARL,340527921
1565,2025-07-17T16:14:10.878601199Z,2025-07-17T16:14:10.878435316Z,10,2,1108,A,A,8,14.47,100,130,165883,283317367,13.11,100,1,12.98,200,2,12.96,2,1,12.86,100,1,12.73,100,1,12.71,100,1,12.5,700,1,12.46,100,1,12.43,700,1,12.42,700,1,13.51,15,1,13.52,100,1,13.74,2,1,13.85,100,1,14.22,100,1,14.26,700,1,14.28,100,1,14.46,300,3,14.47,100,1,14.48,700,1,ARL,340527969
1566,2025-07-17T16:14:10.892679514Z,2025-07-17T16:14:10.892513823Z,10,2,1108,A,A,8,14.47,100,130,165691,283317451,13.11,100,1,12.98,200,2,12.96,2,1,12.86,100,1,12.73,100,1,12.71,100,1,12.5,700,1,12.46,100,1,12.43,700,1,12.42,700,1,13.51,15,1,13.52,100,1,13.74,2,1,13.85,100,1,14.22,100,1,14.26,700,1,14.28,100,1,14.46,300,3,14.47,200,2,14.48,700,1,ARL,340528121
1567,2025-07-17T16:14:10.985507716Z,2025-07-17T16:14:10.985342000Z,10,2,1108,C,A,7,14.46,100,0,165716,283318181,13.11,100,1,12.98,200,2,12.96,2,1,12.86,100,1,12.73,100,1,12.71,100,1,12.5,700,1,12.46,100,1,12.43,700,1,12.42,700,1,13.51,15,1,13.52,100,1,13.74,2,1,13.85,100,1,14.22,100,1,14.26,700,1,14.28,100,1,14.46,200,2,14.47,200,2,14.48,700,1,ARL,339359421
1568,2025-07-17T16:14:10.985507716Z,2025-07-17T16:14:10.985342000Z,10,2,1108,A,A,7,14.31,100,130,165716,283318181,13.11,100,1,12.98,200,2,12.96,2,1,12.86,100,1,12.73,100,1,12.71,100,1,12.5,700,1,12.46,100,1,12.43,700,1,12.42,700,1,13.51,15,1,13.52,100,1,13.74,2,1,13.85,100,1,14.22,100,1,14.26,700,1,14.28,100,1,14.31,100,1,14.46,200,2,14.47,200,2,ARL,340529021
1569,2025-07-17T16:14:19.528488233Z,2025-07-17T16:14:19.528322793Z,10,2,1108,A,A,0,13.49,15,130,165440,283419160,13.11,100,1,12.98,200,2,12.96,2,1,12.86,100,1,12.73,100,1,12.71,100,1,12.5,700,1,12.46,100,1,12.43,700,1,12.42,700,1,13.49,15,1,13.51,15,1,13.52,100,1,13.74,2,1,13.85,100,1,14.22,100,1,14.26,700,1,14.28,100,1,14.31,100,1,14.46,200,2,ARL,340664453
1570,2025-07-17T16:14:21.306764970Z,2025-07-17T16:14:21.306599291Z,10,2,1108,C,A,-1,13.52,100,0,165679,283454179,13.11,100,1,12.98,200,2,12.96,2,1,12.86,100,1,12.73,100,1,12.71,100,1,12.5,700,1,12.46,100,1,12.43,700,1,12.42,700,1,13.49,15,1,13.51,15,1,13.74,2,1,13.85,100,1,14.22,100,1,14.26,700,1,14.28,100,1,14.31,100,1,14.46,200,2,14.47,200,2,ARL,340527921
1571,2025-07-17T16:14:21.306764970Z,2025-07-17T16:14:21.306599291Z,10,2,1108,A,A,1,13.5,100,130,165679,283454179,13.11,100,1,12.98,200,2,12.96,2,1,12.86,100,1,12.73,100,1,12.71,100,1,12.5,700,1,12.46,100,1,12.43,700,1,12.42,700,1,13.49,15,1,13.5,100,1,13.51,15,1,13.74,2,1,13.85,100,1,14.22,100,1,14.26,700,1,14.28,100,1,14.31,100,1,14.46,200,2,ARL,340704401
1572,2025-07-17T16:14:21.317261991Z,2025-07-17T16:14:21.317096752Z,10,2,1108,C,A,-1,13.85,100,130,165239,283454878,13.11,100,1,12.98,200,2,12.96,2,1,12.86,100,1,12.73,100,1,12.71,100,1,12.5,700,1,12.46,100,1,12.43,700,1,12.42,700,1,13.49,15,1,13.5,100,1,13.51,15,1,13.74,2,1,14.22,100,1,14.26,700,1,14.28,100,1,14.31,100,1,14.46,200,2,14.47,200,2,ARL,339642033
1573,2025-07-17T16:14:21.317314136Z,2025-07-17T16:14:21.317148983Z,10,2,1108,A,A,4,13.77,100,130,165153,283454882,13.11,100,1,12.98,200,2,12.96,2,1,12.86,100,1,12.73,100,1,12.71,100,1,12.5,700,1,12.46,100,1,12.43,700,1,12.42,700,1,13.49,15,1,13.5,100,1,13.51,15,1,13.74,2,1,13.77,100,1,14.22,100,1,14.26,700,1,14.28,100,1,14.31,100,1,14.46,200,2,ARL,340705133
1574,2025-07-17T16:14:36.523553349Z,2025-07-17T16:14:36.523382949Z,10,2,1108,C,A,-1,13.49,15,128,170400,283655411,13.11,100,1,12.98,200,2,12.96,2,1,12.86,100,1,12.73,100,1,12.71,100,1,12.5,700,1,12.46,100,1,12.43,700,1,12.42,700,1,13.5,100,1,13.51,15,1,13.74,2,1,13.77,100,1,14.22,100,1,14.26,700,1,14.28,100,1,14.31,100,1,14.46,200,2,14.47,200,2,ARL,340664453
1575,2025-07-17T16:14:36.523730500Z,2025-07-17T16:14:36.523564373Z,10,2,1108,C,A,-1,13.51,15,128,166127,283655455,13.11,100,1,12.98,200,2,12.96,2,1,12.86,100,1,12.73,100,1,12.71,100,1,12.5,700,1,12.46,100,1,12.43,700,1,12.42,700,1,13.5,100,1,13.74,2,1,13.77,100,1,14.22,100,1,14.26,700,1,14.28,100,1,14.31,100,1,14.46,200,2,14.47,200,2,14.48,700,1,ARL,340526285
1576,2025-07-17T16:14:36.523862340Z,2025-07-17T16:14:36.523696080Z,10,2,1108,A,A,0,13.5,99,128,166260,283655477,13.11,100,1,12.98,200,2,12.96,2,1,12.86,100,1,12.73,100,1,12.71,100,1,12.5,700,1,12.46,100,1,12.43,700,1,12.42,700,1,13.5,199,2,13.74,2,1,13.77,100,1,14.22,100,1,14.26,700,1,14.28,100,1,14.31,100,1,14.46,200,2,14.47,200,2,14.48,700,1,ARL,340971661
1577,2025-07-17T16:14:52.280593678Z,2025-07-17T16:14:52.280428336Z,10,2,1108,C,A,0,13.5,99,130,165342,283870929,13.11,100,1,12.98,200,2,12.96,2,1,12.86,100,1,12.73,100,1,12.71,100,1,12.5,700,1,12.46,100,1,12.43,700,1,12.42,700,1,13.5,100,1,13.74,2,1,13.77,100,1,14.22,100,1,14.26,700,1,14.28,100,1,14.31,100,1,14.46,200,2,14.47,200,2,14.48,700,1,ARL,340971661
1578,2025-07-17T16:14:52.297037125Z,2025-07-17T16:14:52.296871817Z,10,2,1108,A,A,0,13.48,15,130,165308,283871393,13.11,100,1,12.98,200,2,12.96,2,1,12.86,100,1,12.73,100,1,12.71,100,1,12.5,700,1,12.46,100,1,12.43,700,1,12.42,700,1,13.48,15,1,13.5,100,1,13.74,2,1,13.77,100,1,14.22,100,1,14.26,700,1,14.28,100,1,14.31,100,1,14.46,200,2,14.47,200,2,ARL,341248825
1579,2025-07-17T16:14:52.828721867Z,2025-07-17T16:14:52.828556785Z,10,2,1108,C,A,-1,13.48,15,130,165082,283875146,13.11,100,1,12.98,200,2,12.96,2,1,12.86,100,1,12.73,100,1,12.71,100,1,12.5,700,1,12.46,100,1,12.43,700,1,12.42,700,1,13.5,100,1,13.74,2,1,13.77,100,1,14.22,100,1,14.26,700,1,14.28,100,1,14.31,100,1,14.46,200,2,14.47,200,2,14.48,700,1,ARL,341248825
1580,2025-07-17T16:14:52.829033713Z,2025-07-17T16:14:52.828868258Z,10,2,1108,A,A,0,13.5,99,130,165455,283875150,13.11,100,1,12.98,200,2,12.96,2,1,12.86,100,1,12.73,100,1,12.71,100,1,12.5,700,1,12.46,100,1,12.43,700,1,12.42,700,1,13.5,199,2,13.74,2,1,13.77,100,1,14.22,100,1,14.26,700,1,14.28,100,1,14.31,100,1,14.46,200,2,14.47,200,2,14.48,700,1,ARL,341253573
1581,2025-07-17T16:15:16.987369971Z,2025-07-17T16:15:16.987204735Z,10,2,1108,C,A,0,13.5,99,130,165236,284194889,13.11,100,1,12.98,200,2,12.96,2,1,12.86,100,1,12.73,100,1,12.71,100,1,12.5,700,1,12.46,100,1,12.43,700,1,12.42,700,1,13.5,100,1,13.74,2,1,13.77,100,1,14.22,100,1,14.26,700,1,14.28,100,1,14.31,100,1,14.46,200,2,14.47,200,2,14.48,700,1,ARL,341253573
1582,2025-07-17T16:15:16.987414675Z,2025-07-17T16:15:16.987249289Z,10,2,1108,C,A,-1,13.5,100,130,165386,284194891,13.11,100,1,12.98,200,2,12.96,2,1,12.86,100,1,12.73,100,1,12.71,100,1,12.5,700,1,12.46,100,1,12.43,700,1,12.42,700,1,13.74,2,1,13.77,100,1,14.22,100,1,14.26,700,1,14.28,100,1,14.31,100,1,14.46,200,2,14.47,200,2,14.48,700,1,14.49,100,1,ARL,340704401
1583,2025-07-17T16:15:16.987689493Z,2025-07-17T16:15:16.987524101Z,10,2,1108,C,A,-1,14.26,700,130,165392,284194901,13.11,100,1,12.98,200,2,12.96,2,1,12.86,100,1,12.73,100,1,12.71,100,1,12.5,700,1,12.46,100,1,12.43,700,1,12.42,700,1,13.74,2,1,13.77,100,1,14.22,100,1,14.28,100,1,14.31,100,1,14.46,200,2,14.47,200,2,14.48,700,1,14.49,100,1,14.54,700,1,ARL,339716321
1584,2025-07-17T16:15:16.987744468Z,2025-07-17T16:15:16.987579177Z,10,2,1108,A,A,5,14.46,700,130,165291,284194908,13.11,100,1,12.98,200,2,12.96,2,1,12.86,100,1,12.73,100,1,12.71,100,1,12.5,700,1,12.46,100,1,12.43,700,1,12.42,700,1,13.74,2,1,13.77,100,1,14.22,100,1,14.28,100,1,14.31,100,1,14.46,900,3,14.47,200,2,14.48,700,1,14.49,100,1,14.54,700,1,ARL,341661841
1585,2025-07-17T16:15:16.988410269Z,2025-07-17T16:15:16.988244795Z,10,2,1108,C,A,6,14.47,100,0,165474,284194952,13.11,100,1,12.98,200,2,12.96,2,1,12.86,100,1,12.73,100,1,12.71,100,1,12.5,700,1,12.46,100,1,12.43,700,1,12.42,700,1,13.74,2,1,13.77,100,1,14.22,100,1,14.28,100,1,14.31,100,1,14.46,900,3,14.47,100,1,14.48,700,1,14.49,100,1,14.54,700,1,ARL,340527969
1586,2025-07-17T16:15:16.989886697Z,2025-07-17T16:15:16.989720957Z,10,2,1108,C,A,-1,14.47,100,0,165740,284195185,13.11,100,1,12.98,200,2,12.96,2,1,12.86,100,1,12.73,100,1,12.71,100,1,12.5,700,1,12.46,100,1,12.43,700,1,12.42,700,1,13.74,2,1,13.77,100,1,14.22,100,1,14.28,100,1,14.31,100,1,14.46,900,3,14.48,700,1,14.49,100,1,14.54,700,1,14.56,700,1,ARL,340528121
1587,2025-07-17T16:15:16.992804347Z,2025-07-17T16:15:16.992638952Z,10,2,1108,C,A,-1,14.31,100,130,165395,284195309,13.11,100,1,12.98,200,2,12.96,2,1,12.86,100,1,12.73,100,1,12.71,100,1,12.5,700,1,12.46,100,1,12.43,700,1,12.42,700,1,13.74,2,1,13.77,100,1,14.22,100,1,14.28,100,1,14.46,900,3,14.48,700,1,14.49,100,1,14.54,700,1,14.56,700,1,14.6,100,1,ARL,340529021
1588,2025-07-17T16:15:16.992941967Z,2025-07-17T16:15:16.992776612Z,10,2,1108,A,A,8,14.56,100,130,165355,284195310,13.11,100,1,12.98,200,2,12.96,2,1,12.86,100,1,12.73,100,1,12.71,100,1,12.5,700,1,12.46,100,1,12.43,700,1,12.42,700,1,13.74,2,1,13.77,100,1,14.22,100,1,14.28,100,1,14.46,900,3,14.48,700,1,14.49,100,1,14.54,700,1,14.56,800,2,14.6,100,1,ARL,341661985
1589,2025-07-17T16:15:17.000588174Z,2025-07-17T16:15:17.000422944Z,10,2,1108,C,A,-1,13.77,100,130,165230,284195454,13.11,100,1,12.98,200,2,12.96,2,1,12.86,100,1,12.73,100,1,12.71,100,1,12.5,700,1,12.46,100,1,12.43,700,1,12.42,700,1,13.74,2,1,14.22,100,1,14.28,100,1,14.46,900,3,14.48,700,1,14.49,100,1,14.54,700,1,14.56,800,2,14.6,100,1,14.74,200,2,ARL,340705133
1590,2025-07-17T16:15:17.000621056Z,2025-07-17T16:15:17.000456046Z,10,2,1108,C,A,3,14.46,700,130,165010,284195456,13.11,100,1,12.98,200,2,12.96,2,1,12.86,100,1,12.73,100,1,12.71,100,1,12.5,700,1,12.46,100,1,12.43,700,1,12.42,700,1,13.74,2,1,14.22,100,1,14.28,100,1,14.46,200,2,14.48,700,1,14.49,100,1,14.54,700,1,14.56,800,2,14.6,100,1,14.74,200,2,ARL,341661841
1591,2025-07-17T16:15:17.000640033Z,2025-07-17T16:15:17.000474862Z,10,2,1108,A,A,1,14.05,100,130,165171,284195458,13.11,100,1,12.98,200,2,12.96,2,1,12.86,100,1,12.73,100,1,12.71,100,1,12.5,700,1,12.46,100,1,12.43,700,1,12.42,700,1,13.74,2,1,14.05,100,1,14.22,100,1,14.28,100,1,14.46,200,2,14.48,700,1,14.49,100,1,14.54,700,1,14.56,800,2,14.6,100,1,ARL,341662085
1592,2025-07-17T16:15:17.001323406Z,2025-07-17T16:15:17.001158038Z,10,2,1108,C,A,-1,14.28,100,130,165368,284195476,13.11,100,1,12.98,200,2,12.96,2,1,12.86,100,1,12.73,100,1,12.71,100,1,12.5,700,1,12.46,100,1,12.43,700,1,12.42,700,1,13.74,2,1,14.05,100,1,14.22,100,1,14.46,200,2,14.48,700,1,14.49,100,1,14.54,700,1,14.56,800,2,14.6,100,1,14.74,200,2,ARL,339358333
1593,2025-07-17T16:15:17.001687312Z,2025-07-17T16:15:17.001522171Z,10,2,1108,A,A,8,14.6,100,130,165141,284195477,13.11,100,1,12.98,200,2,12.96,2,1,12.86,100,1,12.73,100,1,12.71,100,1,12.5,700,1,12.46,100,1,12.43,700,1,12.42,700,1,13.74,2,1,14.05,100,1,14.22,100,1,14.46,200,2,14.48,700,1,14.49,100,1,14.54,700,1,14.56,800,2,14.6,200,2,14.74,200,2,ARL,341662113
1594,2025-07-17T16:15:17.002229963Z,2025-07-17T16:15:17.002064284Z,10,2,1108,C,A,9,14.74,100,0,165679,284195479,13.11,100,1,12.98,200,2,12.96,2,1,12.86,100,1,12.73,100,1,12.71,100,1,12.5,700,1,12.46,100,1,12.43,700,1,12.42,700,1,13.74,2,1,14.05,100,1,14.22,100,1,14.46,200,2,14.48,700,1,14.49,100,1,14.54,700,1,14.56,800,2,14.6,200,2,14.74,100,1,ARL,341661905
1595,2025-07-17T16:15:17.003246802Z,2025-07-17T16:15:17.003081581Z,10,2,1108,C,A,-1,14.74,100,0,165221,284195486,13.11,100,1,12.98,200,2,12.96,2,1,12.86,100,1,12.73,100,1,12.71,100,1,12.5,700,1,12.46,100,1,12.43,700,1,12.42,700,1,13.74,2,1,14.05,100,1,14.22,100,1,14.46,200,2,14.48,700,1,14.49,100,1,14.54,700,1,14.56,800,2,14.6,200,2,14.96,100,1,ARL,341661877
1596,2025-07-17T16:15:17.003246802Z,2025-07-17T16:15:17.003081581Z,10,2,1108,A,A,9,14.96,100,130,165221,284195486,13.11,100,1,12.98,200,2,12.96,2,1,12.86,100,1,12.73,100,1,12.71,100,1,12.5,700,1,12.46,100,1,12.43,700,1,12.42,700,1,13.74,2,1,14.05,100,1,14.22,100,1,14.46,200,2,14.48,700,1,14.49,100,1,14.54,700,1,14.56,800,2,14.6,200,2,14.96,200,2,ARL,341662133
1597,2025-07-17T16:15:17.019567564Z,2025-07-17T16:15:17.019402521Z,10,2,1108,C,A,-1,14.05,100,130,165043,284195602,13.11,100,1,12.98,200,2,12.96,2,1,12.86,100,1,12.73,100,1,12.71,100,1,12.5,700,1,12.46,100,1,12.43,700,1,12.42,700,1,13.74,2,1,14.22,100,1,14.46,200,2,14.48,700,1,14.49,100,1,14.54,700,1,14.56,800,2,14.6,200,2,14.96,200,2,15.3,100,1,ARL,341662085
1598,2025-07-17T16:15:17.019617602Z,2025-07-17T16:15:17.019452245Z,10,2,1108,A,A,2,14.26,100,130,165357,284195603,13.11,100,1,12.98,200,2,12.96,2,1,12.86,100,1,12.73,100,1,12.71,100,1,12.5,700,1,12.46,100,1,12.43,700,1,12.42,700,1,13.74,2,1,14.22,100,1,14.26,100,1,14.46,200,2,14.48,700,1,14.49,100,1,14.54,700,1,14.56,800,2,14.6,200,2,14.96,200,2,ARL,341662313
1599,2025-07-17T16:15:17.037261626Z,2025-07-17T16:15:17.037096157Z,10,2,1108,C,A,8,14.6,100,0,165469,284195665,13.11,100,1,12.98,200,2,12.96,2,1,12.86,100,1,12.73,100,1,12.71,100,1,12.5,700,1,12.46,100,1,12.43,700,1,12.42,700,1,13.74,2,1,14.22,100,1,14.26,100,1,14.46,200,2,14.48,700,1,14.49,100,1,14.54,700,1,14.56,800,2,14.6,100,1,14.96,200,2,ARL,341661869
1600,2025-07-17T16:15:17.049066370Z,2025-07-17T16:15:17.048901142Z,10,2,1108,A,A,1,13.75,100,130,165228,284196195,13.11,100,1,12.98,200,2,12.96,2,1,12.86,100,1,12.73,100,1,12.71,100,1,12.5,700,1,12.46,100,1,12.43,700,1,12.42,700,1,13.74,2,1,13.75,100,1,14.22,100,1,14.26,100,1,14.46,200,2,14.48,700,1,14.49,100,1,14.54,700,1,14.56,800,2,14.6,100,1,ARL,341663101
1601,2025-07-17T16:15:17.059504149Z,2025-07-17T16:15:17.059338704Z,10,2,1108,C,A,-1,14.26,100,130,165445,284196314,13.11,100,1,12.98,200,2,12.96,2,1,12.86,100,1,12.73,100,1,12.71,100,1,12.5,700,1,12.46,100,1,12.43,700,1,12.42,700,1,13.74,2,1,13.75,100,1,14.22,100,1,14.46,200,2,14.48,700,1,14.49,100,1,14.54,700,1,14.56,800,2,14.6,100,1,14.68,700,1,ARL,341662313
1602,2025-07-17T16:15:17.059552653Z,2025-07-17T16:15:17.059387360Z,10,2,1108,A,A,2,14.03,100,130,165293,284196315,13.11,100,1,12.98,200,2,12.96,2,1,12.86,100,1,12.73,100,1,12.71,100,1,12.5,700,1,12.46,100,1,12.43,700,1,12.42,700,1,13.74,2,1,13.75,100,1,14.03,100,1,14.22,100,1,14.46,200,2,14.48,700,1,14.49,100,1,14.54,700,1,14.56,800,2,14.6,100,1,ARL,341663401
1603,2025-07-17T16:15:17.643818240Z,2025-07-17T16:15:17.643653020Z,10,2,1108,C,A,-1,14.6,100,130,165220,284202090,13.11,100,1,12.98,200,2,12.96,2,1,12.86,100,1,12.73,100,1,12.71,100,1,12.5,700,1,12.46,100,1,12.43,700,1,12.42,700,1,13.74,2,1,13.75,100,1,14.03,100,1,14.22,100,1,14.46,200,2,14.48,700,1,14.49,100,1,14.54,700,1,14.56,800,2,14.68,700,1,ARL,341662113
1604,2025-07-17T16:15:17.644168944Z,2025-07-17T16:15:17.644003726Z,10,2,1108,A,A,4,14.36,100,130,165218,284202091,13.11,100,1,12.98,200,2,12.96,2,1,12.86,100,1,12.73,100,1,12.71,100,1,12.5,700,1,12.46,100,1,12.43,700,1,12.42,700,1,13.74,2,1,13.75,100,1,14.03,100,1,14.22,100,1,14.36,100,1,14.46,200,2,14.48,700,1,14.49,100,1,14.54,700,1,14.56,800,2,ARL,341671053
1605,2025-07-17T16:16:30.787448429Z,2025-07-17T16:16:30.787282866Z,10,2,1108,C,B,-1,12.96,2,0,165563,285308466,13.11,100,1,12.98,200,2,12.86,100,1,12.73,100,1,12.71,100,1,12.5,700,1,12.46,100,1,12.43,700,1,12.42,700,1,12.37,700,1,13.74,2,1,13.75,100,1,14.03,100,1,14.22,100,1,14.36,100,1,14.46,200,2,14.48,700,1,14.49,100,1,14.54,700,1,14.56,800,2,ARL,339356397
1606,2025-07-17T16:16:30.787448429Z,2025-07-17T16:16:30.787282866Z,10,2,1108,A,B,1,13.03,2,130,165563,285308466,13.11,100,1,13.03,2,1,12.98,200,2,12.86,100,1,12.73,100,1,12.71,100,1,12.5,700,1,12.46,100,1,12.43,700,1,12.42,700,1,13.74,2,1,13.75,100,1,14.03,100,1,14.22,100,1,14.36,100,1,14.46,200,2,14.48,700,1,14.49,100,1,14.54,700,1,14.56,800,2,ARL,343084165
1607,2025-07-17T16:17:22.832948558Z,2025-07-17T16:17:22.832783132Z,10,2,1108,A,A,0,13.47,15,130,165426,286207282,13.11,100,1,13.03,2,1,12.98,200,2,12.86,100,1,12.73,100,1,12.71,100,1,12.5,700,1,12.46,100,1,12.43,700,1,12.42,700,1,13.47,15,1,13.74,2,1,13.75,100,1,14.03,100,1,14.22,100,1,14.36,100,1,14.46,200,2,14.48,700,1,14.49,100,1,14.54,700,1,ARL,344211173
1608,2025-07-17T16:17:23.620456421Z,2025-07-17T16:17:23.620290881Z,10,2,1108,C,A,-1,13.75,100,0,165540,286219821,13.11,100,1,13.03,2,1,12.98,200,2,12.86,100,1,12.73,100,1,12.71,100,1,12.5,700,1,12.46,100,1,12.43,700,1,12.42,700,1,13.47,15,1,13.74,2,1,14.03,100,1,14.22,100,1,14.36,100,1,14.46,200,2,14.48,700,1,14.49,100,1,14.54,700,1,14.56,800,2,ARL,341663101
1609,2025-07-17T16:17:23.620456421Z,2025-07-17T16:17:23.620290881Z,10,2,1108,A,A,1,13.48,100,130,165540,286219821,13.11,100,1,13.03,2,1,12.98,200,2,12.86,100,1,12.73,100,1,12.71,100,1,12.5,700,1,12.46,100,1,12.43,700,1,12.42,700,1,13.47,15,1,13.48,100,1,13.74,2,1,14.03,100,1,14.22,100,1,14.36,100,1,14.46,200,2,14.48,700,1,14.49,100,1,14.54,700,1,ARL,344225341
1610,2025-07-17T16:17:23.621199578Z,2025-07-17T16:17:23.621034171Z,10,2,1108,C,A,-1,14.36,100,130,165407,286219868,13.11,100,1,13.03,2,1,12.98,200,2,12.86,100,1,12.73,100,1,12.71,100,1,12.5,700,1,12.46,100,1,12.43,700,1,12.42,700,1,13.47,15,1,13.48,100,1,13.74,2,1,14.03,100,1,14.22,100,1,14.46,200,2,14.48,700,1,14.49,100,1,14.54,700,1,14.56,800,2,ARL,341671053
1611,2025-07-17T16:17:23.621205573Z,2025-07-17T16:17:23.621040069Z,10,2,1108,A,A,8,14.53,100,130,165504,286219869,13.11,100,1,13.03,2,1,12.98,200,2,12.86,100,1,12.73,100,1,12.71,100,1,12.5,700,1,12.46,100,1,12.43,700,1,12.42,700,1,13.47,15,1,13.48,100,1,13.74,2,1,14.03,100,1,14.22,100,1,14.46,200,2,14.48,700,1,14.49,100,1,14.53,100,1,14.54,700,1,ARL,344225385
1612,2025-07-17T16:17:23.621555609Z,2025-07-17T16:17:23.621389325Z,10,2,1108,A,A,4,14.08,100,130,166284,286219881,13.11,100,1,13.03,2,1,12.98,200,2,12.86,100,1,12.73,100,1,12.71,100,1,12.5,700,1,12.46,100,1,12.43,700,1,12.42,700,1,13.47,15,1,13.48,100,1,13.74,2,1,14.03,100,1,14.08,100,1,14.22,100,1,14.46,200,2,14.48,700,1,14.49,100,1,14.53,100,1,ARL,344225397
1613,2025-07-17T16:17:23.622834183Z,2025-07-17T16:17:23.622668656Z,10,2,1108,A,A,6,14.43,100,130,165527,286219894,13.11,100,1,13.03,2,1,12.98,200,2,12.86,100,1,12.73,100,1,12.71,100,1,12.5,700,1,12.46,100,1,12.43,700,1,12.42,700,1,13.47,15,1,13.48,100,1,13.74,2,1,14.03,100,1,14.08,100,1,14.22,100,1,14.43,100,1,14.46,200,2,14.48,700,1,14.49,100,1,ARL,344225449
1614,2025-07-17T16:17:23.623011421Z,2025-07-17T16:17:23.622845856Z,10,2,1108,A,A,6,14.27,100,130,165565,286219895,13.11,100,1,13.03,2,1,12.98,200,2,12.86,100,1,12.73,100,1,12.71,100,1,12.5,700,1,12.46,100,1,12.43,700,1,12.42,700,1,13.47,15,1,13.48,100,1,13.74,2,1,14.03,100,1,14.08,100,1,14.22,100,1,14.27,100,1,14.43,100,1,14.46,200,2,14.48,700,1,ARL,344225453
1615,2025-07-17T16:17:23.624638111Z,2025-07-17T16:17:23.624472504Z,10,2,1108,A,A,7,14.43,100,130,165607,286219911,13.11,100,1,13.03,2,1,12.98,200,2,12.86,100,1,12.73,100,1,12.71,100,1,12.5,700,1,12.46,100,1,12.43,700,1,12.42,700,1,13.47,15,1,13.48,100,1,13.74,2,1,14.03,100,1,14.08,100,1,14.22,100,1,14.27,100,1,14.43,200,2,14.46,200,2,14.48,700,1,ARL,344225489
1616,2025-07-17T16:17:23.627653611Z,2025-07-17T16:17:23.627488304Z,10,2,1108,C,A,-1,14.03,100,130,165307,286219940,13.11,100,1,13.03,2,1,12.98,200,2,12.86,100,1,12.73,100,1,12.71,100,1,12.5,700,1,12.46,100,1,12.43,700,1,12.42,700,1,13.47,15,1,13.48,100,1,13.74,2,1,14.08,100,1,14.22,100,1,14.27,100,1,14.43,200,2,14.46,200,2,14.48,700,1,14.49,100,1,ARL,341663401
1617,2025-07-17T16:17:23.627704598Z,2025-07-17T16:17:23.627539425Z,10,2,1108,A,A,3,13.75,100,130,165173,286219941,13.11,100,1,13.03,2,1,12.98,200,2,12.86,100,1,12.73,100,1,12.71,100,1,12.5,700,1,12.46,100,1,12.43,700,1,12.42,700,1,13.47,15,1,13.48,100,1,13.74,2,1,13.75,100,1,14.08,100,1,14.22,100,1,14.27,100,1,14.43,200,2,14.46,200,2,14.48,700,1,ARL,344225533
1618,2025-07-17T16:17:24.832340976Z,2025-07-17T16:17:24.832175508Z,10,2,1108,C,A,-1,13.47,15,130,165468,286237340,13.11,100,1,13.03,2,1,12.98,200,2,12.86,100,1,12.73,100,1,12.71,100,1,12.5,700,1,12.46,100,1,12.43,700,1,12.42,700,1,13.48,100,1,13.74,2,1,13.75,100,1,14.08,100,1,14.22,100,1,14.27,100,1,14.43,200,2,14.46,200,2,14.48,700,1,14.49,100,1,ARL,344211173
1619,2025-07-17T16:17:26.823562625Z,2025-07-17T16:17:26.823396428Z,10,2,1108,C,A,-1,13.48,100,130,166197,286261717,13.11,100,1,13.03,2,1,12.98,200,2,12.86,100,1,12.73,100,1,12.71,100,1,12.5,700,1,12.46,100,1,12.43,700,1,12.42,700,1,13.74,2,1,13.75,100,1,14.08,100,1,14.22,100,1,14.27,100,1,14.43,200,2,14.46,200,2,14.48,700,1,14.49,100,1,14.53,100,1,ARL,344225341
1620,2025-07-17T16:17:26.824304510Z,2025-07-17T16:17:26.824137854Z,10,2,1108,C,A,-1,14.53,100,0,166656,286261743,13.11,100,1,13.03,2,1,12.98,200,2,12.86,100,1,12.73,100,1,12.71,100,1,12.5,700,1,12.46,100,1,12.43,700,1,12.42,700,1,13.74,2,1,13.75,100,1,14.08,100,1,14.22,100,1,14.27,100,1,14.43,200,2,14.46,200,2,14.48,700,1,14.49,100,1,14.54,700,1,ARL,344225385
1621,2025-07-17T16:17:26.824304510Z,2025-07-17T16:17:26.824138799Z,10,2,1108,C,A,-1,14.08,100,130,165711,286261744,13.11,100,1,13.03,2,1,12.98,200,2,12.86,100,1,12.73,100,1,12.71,100,1,12.5,700,1,12.46,100,1,12.43,700,1,12.42,700,1,13.74,2,1,13.75,100,1,14.22,100,1,14.27,100,1,14.43,200,2,14.46,200,2,14.48,700,1,14.49,100,1,14.54,700,1,14.56,700,1,ARL,344225397
1622,2025-07-17T16:17:26.824657956Z,2025-07-17T16:17:26.824492765Z,10,2,1108,A,A,4,14.36,100,130,165191,286261759,13.11,100,1,13.03,2,1,12.98,200,2,12.86,100,1,12.73,100,1,12.71,100,1,12.5,700,1,12.46,100,1,12.43,700,1,12.42,700,1,13.74,2,1,13.75,100,1,14.22,100,1,14.27,100,1,14.36,100,1,14.43,200,2,14.46,200,2,14.48,700,1,14.49,100,1,14.54,700,1,ARL,344280617
1623,2025-07-17T16:17:26.825988253Z,2025-07-17T16:17:26.825823014Z,10,2,1108,C,A,-1,14.27,100,130,165239,286261769,13.11,100,1,13.03,2,1,12.98,200,2,12.86,100,1,12.73,100,1,12.71,100,1,12.5,700,1,12.46,100,1,12.43,700,1,12.42,700,1,13.74,2,1,13.75,100,1,14.22,100,1,14.36,100,1,14.43,200,2,14.46,200,2,14.48,700,1,14.49,100,1,14.54,700,1,14.56,700,1,ARL,344225453
1624,2025-07-17T16:17:26.826051208Z,2025-07-17T16:17:26.825885765Z,10,2,1108,C,A,4,14.43,100,0,165443,286261770,13.11,100,1,13.03,2,1,12.98,200,2,12.86,100,1,12.73,100,1,12.71,100,1,12.5,700,1,12.46,100,1,12.43,700,1,12.42,700,1,13.74,2,1,13.75,100,1,14.22,100,1,14.36,100,1,14.43,100,1,14.46,200,2,14.48,700,1,14.49,100,1,14.54,700,1,14.56,700,1,ARL,344225449
1625,2025-07-17T16:17:26.826159189Z,2025-07-17T16:17:26.825993909Z,10,2,1108,A,A,8,14.54,100,130,165280,286261771,13.11,100,1,13.03,2,1,12.98,200,2,12.86,100,1,12.73,100,1,12.71,100,1,12.5,700,1,12.46,100,1,12.43,700,1,12.42,700,1,13.74,2,1,13.75,100,1,14.22,100,1,14.36,100,1,14.43,100,1,14.46,200,2,14.48,700,1,14.49,100,1,14.54,800,2,14.56,700,1,ARL,344280645
1626,2025-07-17T16:17:26.828538841Z,2025-07-17T16:17:26.828373551Z,10,2,1108,C,A,-1,13.75,100,130,165290,286261785,13.11,100,1,13.03,2,1,12.98,200,2,12.86,100,1,12.73,100,1,12.71,100,1,12.5,700,1,12.46,100,1,12.43,700,1,12.42,700,1,13.74,2,1,14.22,100,1,14.36,100,1,14.43,100,1,14.46,200,2,14.48,700,1,14.49,100,1,14.54,800,2,14.56,700,1,14.58,100,1,ARL,344225533
1627,2025-07-17T16:17:26.828589142Z,2025-07-17T16:17:26.828423432Z,10,2,1108,A,A,1,14.03,100,130,165710,286261786,13.11,100,1,13.03,2,1,12.98,200,2,12.86,100,1,12.73,100,1,12.71,100,1,12.5,700,1,12.46,100,1,12.43,700,1,12.42,700,1,13.74,2,1,14.03,100,1,14.22,100,1,14.36,100,1,14.43,100,1,14.46,200,2,14.48,700,1,14.49,100,1,14.54,800,2,14.56,700,1,ARL,344280689
1628,2025-07-17T16:17:26.828846606Z,2025-07-17T16:17:26.828681062Z,10,2,1108,C,A,-1,13.74,2,0,165544,286261788,13.11,100,1,13.03,2,1,12.98,200,2,12.86,100,1,12.73,100,1,12.71,100,1,12.5,700,1,12.46,100,1,12.43,700,1,12.42,700,1,14.03,100,1,14.22,100,1,14.36,100,1,14.43,100,1,14.46,200,2,14.48,700,1,14.49,100,1,14.54,800,2,14.56,700,1,14.58,100,1,ARL,340449865
1629,2025-07-17T16:17:26.828846606Z,2025-07-17T16:17:26.828681062Z,10,2,1108,A,A,0,13.97,2,130,165544,286261788,13.11,100,1,13.03,2,1,12.98,200,2,12.86,100,1,12.73,100,1,12.71,100,1,12.5,700,1,12.46,100,1,12.43,700,1,12.42,700,1,13.97,2,1,14.03,100,1,14.22,100,1,14.36,100,1,14.43,100,1,14.46,200,2,14.48,700,1,14.49,100,1,14.54,800,2,14.56,700,1,ARL,344280721
1630,2025-07-17T16:17:26.834911649Z,2025-07-17T16:17:26.834746475Z,10,2,1108,C,A,-1,14.03,100,130,165174,286262165,13.11,100,1,13.03,2,1,12.98,200,2,12.86,100,1,12.73,100,1,12.71,100,1,12.5,700,1,12.46,100,1,12.43,700,1,12.42,700,1,13.97,2,1,14.22,100,1,14.36,100,1,14.43,100,1,14.46,200,2,14.48,700,1,14.49,100,1,14.54,800,2,14.56,700,1,14.58,100,1,ARL,344280689
1631,2025-07-17T16:17:26.834961494Z,2025-07-17T16:17:26.834796238Z,10,2,1108,A,A,2,14.25,100,130,165256,286262166,13.11,100,1,13.03,2,1,12.98,200,2,12.86,100,1,12.73,100,1,12.71,100,1,12.5,700,1,12.46,100,1,12.43,700,1,12.42,700,1,13.97,2,1,14.22,100,1,14.25,100,1,14.36,100,1,14.43,100,1,14.46,200,2,14.48,700,1,14.49,100,1,14.54,800,2,14.56,700,1,ARL,344280953
1632,2025-07-17T16:17:26.849670659Z,2025-07-17T16:17:26.849505109Z,10,2,1108,C,A,-1,14.43,100,0,165550,286262262,13.11,100,1,13.03,2,1,12.98,200,2,12.86,100,1,12.73,100,1,12.71,100,1,12.5,700,1,12.46,100,1,12.43,700,1,12.42,700,1,13.97,2,1,14.22,100,1,14.25,100,1,14.36,100,1,14.46,200,2,14.48,700,1,14.49,100,1,14.54,800,2,14.56,700,1,14.58,100,1,ARL,344225489
1633,2025-07-17T16:17:26.874430238Z,2025-07-17T16:17:26.874264677Z,10,2,1108,C,A,-1,14.58,100,0,165561,286262413,13.11,100,1,13.03,2,1,12.98,200,2,12.86,100,1,12.73,100,1,12.71,100,1,12.5,700,1,12.46,100,1,12.43,700,1,12.42,700,1,13.97,2,1,14.22,100,1,14.25,100,1,14.36,100,1,14.46,200,2,14.48,700,1,14.49,100,1,14.54,800,2,14.56,700,1,14.68,700,1,ARL,344280577
1634,2025-07-17T16:17:27.000782790Z,2025-07-17T16:17:27.000617575Z,10,2,1108,A,A,1,13.98,100,130,165215,286264622,13.11,100,1,13.03,2,1,12.98,200,2,12.86,100,1,12.73,100,1,12.71,100,1,12.5,700,1,12.46,100,1,12.43,700,1,12.42,700,1,13.97,2,1,13.98,100,1,14.22,100,1,14.25,100,1,14.36,100,1,14.46,200,2,14.48,700,1,14.49,100,1,14.54,800,2,14.56,700,1,ARL,344283633
1635,2025-07-17T16:17:27.204893988Z,2025-07-17T16:17:27.204728176Z,10,2,1108,C,A,-1,14.22,100,130,165812,286267644,13.11,100,1,13.03,2,1,12.98,200,2,12.86,100,1,12.73,100,1,12.71,100,1,12.5,700,1,12.46,100,1,12.43,700,1,12.42,700,1,13.97,2,1,13.98,100,1,14.25,100,1,14.36,100,1,14.46,200,2,14.48,700,1,14.49,100,1,14.54,800,2,14.56,700,1,14.68,700,1,ARL,339365193
1636,2025-07-17T16:17:27.204895267Z,2025-07-17T16:17:27.204730160Z,10,2,1108,A,A,7,14.53,100,130,165107,286267645,13.11,100,1,13.03,2,1,12.98,200,2,12.86,100,1,12.73,100,1,12.71,100,1,12.5,700,1,12.46,100,1,12.43,700,1,12.42,700,1,13.97,2,1,13.98,100,1,14.25,100,1,14.36,100,1,14.46,200,2,14.48,700,1,14.49,100,1,14.53,100,1,14.54,800,2,14.56,700,1,ARL,344288585
1637,2025-07-17T16:17:27.381809823Z,2025-07-17T16:17:27.381644366Z,10,2,1108,C,A,-1,14.49,100,130,165457,286271010,13.11,100,1,13.03,2,1,12.98,200,2,12.86,100,1,12.73,100,1,12.71,100,1,12.5,700,1,12.46,100,1,12.43,700,1,12.42,700,1,13.97,2,1,13.98,100,1,14.25,100,1,14.36,100,1,14.46,200,2,14.48,700,1,14.53,100,1,14.54,800,2,14.56,700,1,14.68,700,1,ARL,339366385
1638,2025-07-17T16:17:27.443162448Z,2025-07-17T16:17:27.442997426Z,10,2,1108,C,A,-1,14.36,100,130,165022,286271749,13.11,100,1,13.03,2,1,12.98,200,2,12.86,100,1,12.73,100,1,12.71,100,1,12.5,700,1,12.46,100,1,12.43,700,1,12.42,700,1,13.97,2,1,13.98,100,1,14.25,100,1,14.46,200,2,14.48,700,1,14.53,100,1,14.54,800,2,14.56,700,1,14.68,700,1,14.81,100,1,ARL,344280617
1639,2025-07-17T16:17:27.443512590Z,2025-07-17T16:17:27.443347265Z,10,2,1108,A,A,8,14.6,100,130,165325,286271751,13.11,100,1,13.03,2,1,12.98,200,2,12.86,100,1,12.73,100,1,12.71,100,1,12.5,700,1,12.46,100,1,12.43,700,1,12.42,700,1,13.97,2,1,13.98,100,1,14.25,100,1,14.46,200,2,14.48,700,1,14.53,100,1,14.54,800,2,14.56,700,1,14.6,100,1,14.68,700,1,ARL,344294245
1640,2025-07-17T16:17:27.829055288Z,2025-07-17T16:17:27.828890080Z,10,2,1108,C,A,6,14.54,100,0,165208,286275353,13.11,100,1,13.03,2,1,12.98,200,2,12.86,100,1,12.73,100,1,12.71,100,1,12.5,700,1,12.46,100,1,12.43,700,1,12.42,700,1,13.97,2,1,13.98,100,1,14.25,100,1,14.46,200,2,14.48,700,1,14.53,100,1,14.54,700,1,14.56,700,1,14.6,100,1,14.68,700,1,ARL,344280645
1641,2025-07-17T16:17:39.514690751Z,2025-07-17T16:17:39.514525397Z,10,2,1108,A,A,0,13.47,15,130,165354,286508705,13.11,100,1,13.03,2,1,12.98,200,2,12.86,100,1,12.73,100,1,12.71,100,1,12.5,700,1,12.46,100,1,12.43,700,1,12.42,700,1,13.47,15,1,13.97,2,1,13.98,100,1,14.25,100,1,14.46,200,2,14.48,700,1,14.53,100,1,14.54,700,1,14.56,700,1,14.6,100,1,ARL,344587533
1642,2025-07-17T16:17:39.829017289Z,2025-07-17T16:17:39.828851797Z,10,2,1108,C,A,4,14.46,100,0,165492,286513833,13.11,100,1,13.03,2,1,12.98,200,2,12.86,100,1,12.73,100,1,12.71,100,1,12.5,700,1,12.46,100,1,12.43,700,1,12.42,700,1,13.47,15,1,13.97,2,1,13.98,100,1,14.25,100,1,14.46,100,1,14.48,700,1,14.53,100,1,14.54,700,1,14.56,700,1,14.6,100,1,ARL,339739285
1643,2025-07-17T16:17:39.829017289Z,2025-07-17T16:17:39.828851797Z,10,2,1108,A,A,4,14.35,100,130,165492,286513833,13.11,100,1,13.03,2,1,12.98,200,2,12.86,100,1,12.73,100,1,12.71,100,1,12.5,700,1,12.46,100,1,12.43,700,1,12.42,700,1,13.47,15,1,13.97,2,1,13.98,100,1,14.25,100,1,14.35,100,1,14.46,100,1,14.48,700,1,14.53,100,1,14.54,700,1,14.56,700,1,ARL,344593405
1644,2025-07-17T16:17:39.829247357Z,2025-07-17T16:17:39.829081898Z,10,2,1108,C,A,-1,14.46,100,0,165459,286513835,13.11,100,1,13.03,2,1,12.98,200,2,12.86,100,1,12.73,100,1,12.71,100,1,12.5,700,1,12.46,100,1,12.43,700,1,12.42,700,1,13.47,15,1,13.97,2,1,13.98,100,1,14.25,100,1,14.35,100,1,14.48,700,1,14.53,100,1,14.54,700,1,14.56,700,1,14.6,100,1,ARL,339739297
1645,2025-07-17T16:17:39.829247357Z,2025-07-17T16:17:39.829081898Z,10,2,1108,A,A,4,14.35,100,130,165459,286513835,13.11,100,1,13.03,2,1,12.98,200,2,12.86,100,1,12.73,100,1,12.71,100,1,12.5,700,1,12.46,100,1,12.43,700,1,12.42,700,1,13.47,15,1,13.97,2,1,13.98,100,1,14.25,100,1,14.35,200,2,14.48,700,1,14.53,100,1,14.54,700,1,14.56,700,1,14.6,100,1,ARL,344593409
1646,2025-07-17T16:17:40.321326768Z,2025-07-17T16:17:40.321161439Z,10,2,1108,C,A,-1,13.98,100,0,165329,286524785,13.11,100,1,13.03,2,1,12.98,200,2,12.86,100,1,12.73,100,1,12.71,100,1,12.5,700,1,12.46,100,1,12.43,700,1,12.42,700,1,13.47,15,1,13.97,2,1,14.25,100,1,14.35,200,2,14.48,700,1,14.53,100,1,14.54,700,1,14.56,700,1,14.6,100,1,14.68,700,1,ARL,344283633
1647,2025-07-17T16:17:40.321326768Z,2025-07-17T16:17:40.321161439Z,10,2,1108,A,A,1,13.48,100,130,165329,286524785,13.11,100,1,13.03,2,1,12.98,200,2,12.86,100,1,12.73,100,1,12.71,100,1,12.5,700,1,12.46,100,1,12.43,700,1,12.42,700,1,13.47,15,1,13.48,100,1,13.97,2,1,14.25,100,1,14.35,200,2,14.48,700,1,14.53,100,1,14.54,700,1,14.56,700,1,14.6,100,1,ARL,344607833
1648,2025-07-17T16:17:40.322064038Z,2025-07-17T16:17:40.321898765Z,10,2,1108,C,A,-1,14.6,100,130,165273,286524815,13.11,100,1,13.03,2,1,12.98,200,2,12.86,100,1,12.73,100,1,12.71,100,1,12.5,700,1,12.46,100,1,12.43,700,1,12.42,700,1,13.47,15,1,13.48,100,1,13.97,2,1,14.25,100,1,14.35,200,2,14.48,700,1,14.53,100,1,14.54,700,1,14.56,700,1,14.68,700,1,ARL,344294245
1649,2025-07-17T16:17:40.322069742Z,2025-07-17T16:17:40.321903984Z,10,2,1108,A,A,6,14.53,100,130,165758,286524817,13.11,100,1,13.03,2,1,12.98,200,2,12.86,100,1,12.73,100,1,12.71,100,1,12.5,700,1,12.46,100,1,12.43,700,1,12.42,700,1,13.47,15,1,13.48,100,1,13.97,2,1,14.25,100,1,14.35,200,2,14.48,700,1,14.53,200,2,14.54,700,1,14.56,700,1,14.68,700,1,ARL,344607889
1650,2025-07-17T16:17:40.322416015Z,2025-07-17T16:17:40.322250847Z,10,2,1108,A,A,3,14.08,100,130,165168,286524822,13.11,100,1,13.03,2,1,12.98,200,2,12.86,100,1,12.73,100,1,12.71,100,1,12.5,700,1,12.46,100,1,12.43,700,1,12.42,700,1,13.47,15,1,13.48,100,1,13.97,2,1,14.08,100,1,14.25,100,1,14.35,200,2,14.48,700,1,14.53,200,2,14.54,700,1,14.56,700,1,ARL,344607893
1651,2025-07-17T16:17:40.329180897Z,2025-07-17T16:17:40.329015669Z,10,2,1108,C,A,-1,14.25,100,130,165228,286524967,13.11,100,1,13.03,2,1,12.98,200,2,12.86,100,1,12.73,100,1,12.71,100,1,12.5,700,1,12.46,100,1,12.43,700,1,12.42,700,1,13.47,15,1,13.48,100,1,13.97,2,1,14.08,100,1,14.35,200,2,14.48,700,1,14.53,200,2,14.54,700,1,14.56,700,1,14.68,700,1,ARL,344280953
1652,2025-07-17T16:17:40.329233157Z,2025-07-17T16:17:40.329067996Z,10,2,1108,A,A,2,13.75,100,130,165161,286524969,13.11,100,1,13.03,2,1,12.98,200,2,12.86,100,1,12.73,100,1,12.71,100,1,12.5,700,1,12.46,100,1,12.43,700,1,12.42,700,1,13.47,15,1,13.48,100,1,13.75,100,1,13.97,2,1,14.08,100,1,14.35,200,2,14.48,700,1,14.53,200,2,14.54,700,1,14.56,700,1,ARL,344608193
1653,2025-07-17T16:17:40.331551656Z,2025-07-17T16:17:40.331386492Z,10,2,1108,A,A,5,14.27,100,130,165164,286525005,13.11,100,1,13.03,2,1,12.98,200,2,12.86,100,1,12.73,100,1,12.71,100,1,12.5,700,1,12.46,100,1,12.43,700,1,12.42,700,1,13.47,15,1,13.48,100,1,13.75,100,1,13.97,2,1,14.08,100,1,14.27,100,1,14.35,200,2,14.48,700,1,14.53,200,2,14.54,700,1,ARL,344608225
1654,2025-07-17T16:17:40.333679181Z,2025-07-17T16:17:40.333513866Z,10,2,1108,A,A,7,14.43,100,130,165315,286525029,13.11,100,1,13.03,2,1,12.98,200,2,12.86,100,1,12.73,100,1,12.71,100,1,12.5,700,1,12.46,100,1,12.43,700,1,12.42,700,1,13.47,15,1,13.48,100,1,13.75,100,1,13.97,2,1,14.08,100,1,14.27,100,1,14.35,200,2,14.43,100,1,14.48,700,1,14.53,200,2,ARL,344608253
1655,2025-07-17T16:17:40.426590567Z,2025-07-17T16:17:40.426425205Z,10,2,1108,A,A,7,14.43,100,130,165362,286526540,13.11,100,1,13.03,2,1,12.98,200,2,12.86,100,1,12.73,100,1,12.71,100,1,12.5,700,1,12.46,100,1,12.43,700,1,12.42,700,1,13.47,15,1,13.48,100,1,13.75,100,1,13.97,2,1,14.08,100,1,14.27,100,1,14.35,200,2,14.43,200,2,14.48,700,1,14.53,200,2,ARL,344610073
1656,2025-07-17T16:17:40.474841118Z,2025-07-17T16:17:40.474675991Z,10,2,1108,A,A,4,14.01,100,130,165127,286527611,13.11,100,1,13.03,2,1,12.98,200,2,12.86,100,1,12.73,100,1,12.71,100,1,12.5,700,1,12.46,100,1,12.43,700,1,12.42,700,1,13.47,15,1,13.48,100,1,13.75,100,1,13.97,2,1,14.01,100,1,14.08,100,1,14.27,100,1,14.35,200,2,14.43,200,2,14.48,700,1,ARL,344612049
1657,2025-07-17T16:17:40.697721205Z,2025-07-17T16:17:40.697555911Z,10,2,1108,A,A,7,14.28,100,130,165294,286530329,13.11,100,1,13.03,2,1,12.98,200,2,12.86,100,1,12.73,100,1,12.71,100,1,12.5,700,1,12.46,100,1,12.43,700,1,12.42,700,1,13.47,15,1,13.48,100,1,13.75,100,1,13.97,2,1,14.01,100,1,14.08,100,1,14.27,100,1,14.28,100,1,14.35,200,2,14.43,200,2,ARL,344615393
1658,2025-07-17T16:17:41.586151161Z,2025-07-17T16:17:41.585985709Z,10,2,1108,C,A,-1,13.97,2,0,165452,286543225,13.11,100,1,13.03,2,1,12.98,200,2,12.86,100,1,12.73,100,1,12.71,100,1,12.5,700,1,12.46,100,1,12.43,700,1,12.42,700,1,13.47,15,1,13.48,100,1,13.75,100,1,14.01,100,1,14.08,100,1,14.27,100,1,14.28,100,1,14.35,200,2,14.43,200,2,14.48,700,1,ARL,344280721
1659,2025-07-17T16:17:41.586151161Z,2025-07-17T16:17:41.585985709Z,10,2,1108,A,A,3,13.87,2,130,165452,286543225,13.11,100,1,13.03,2,1,12.98,200,2,12.86,100,1,12.73,100,1,12.71,100,1,12.5,700,1,12.46,100,1,12.43,700,1,12.42,700,1,13.47,15,1,13.48,100,1,13.75,100,1,13.87,2,1,14.01,100,1,14.08,100,1,14.27,100,1,14.28,100,1,14.35,200,2,14.43,200,2,ARL,344631921
1660,2025-07-17T16:17:42.553133650Z,2025-07-17T16:17:42.552968542Z,10,2,1108,A,A,0,13.45,15,130,165108,286561347,13.11,100,1,13.03,2,1,12.98,200,2,12.86,100,1,12.73,100,1,12.71,100,1,12.5,700,1,12.46,100,1,12.43,700,1,12.42,700,1,13.45,15,1,13.47,15,1,13.48,100,1,13.75,100,1,13.87,2,1,14.01,100,1,14.08,100,1,14.27,100,1,14.28,100,1,14.35,200,2,ARL,344653009
1661,2025-07-17T16:17:44.014614049Z,2025-07-17T16:17:44.014448587Z,10,2,1108,C,A,-1,13.48,100,0,165462,286577648,13.11,100,1,13.03,2,1,12.98,200,2,12.86,100,1,12.73,100,1,12.71,100,1,12.5,700,1,12.46,100,1,12.43,700,1,12.42,700,1,13.45,15,1,13.47,15,1,13.75,100,1,13.87,2,1,14.01,100,1,14.08,100,1,14.27,100,1,14.28,100,1,14.35,200,2,14.43,200,2,ARL,344607833
1662,2025-07-17T16:17:44.014614049Z,2025-07-17T16:17:44.014448587Z,10,2,1108,A,A,1,13.46,100,130,165462,286577648,13.11,100,1,13.03,2,1,12.98,200,2,12.86,100,1,12.73,100,1,12.71,100,1,12.5,700,1,12.46,100,1,12.43,700,1,12.42,700,1,13.45,15,1,13.46,100,1,13.47,15,1,13.75,100,1,13.87,2,1,14.01,100,1,14.08,100,1,14.27,100,1,14.28,100,1,14.35,200,2,ARL,344673481
1663,2025-07-17T16:17:46.828260391Z,2025-07-17T16:17:46.828095134Z,10,2,1108,A,A,7,14.18,700,130,165257,286618024,13.11,100,1,13.03,2,1,12.98,200,2,12.86,100,1,12.73,100,1,12.71,100,1,12.5,700,1,12.46,100,1,12.43,700,1,12.42,700,1,13.45,15,1,13.46,100,1,13.47,15,1,13.75,100,1,13.87,2,1,14.01,100,1,14.08,100,1,14.18,700,1,14.27,100,1,14.28,100,1,ARL,344724301
1664,2025-07-17T16:17:49.387530942Z,2025-07-17T16:17:49.387365405Z,10,2,1108,C,A,-1,13.87,2,0,165537,286651544,13.11,100,1,13.03,2,1,12.98,200,2,12.86,100,1,12.73,100,1,12.71,100,1,12.5,700,1,12.46,100,1,12.43,700,1,12.42,700,1,13.45,15,1,13.46,100,1,13.47,15,1,13.75,100,1,14.01,100,1,14.08,100,1,14.18,700,1,14.27,100,1,14.28,100,1,14.35,200,2,ARL,344631921
1665,2025-07-17T16:17:49.387530942Z,2025-07-17T16:17:49.387365405Z,10,2,1108,A,A,4,13.79,2,130,165537,286651544,13.11,100,1,13.03,2,1,12.98,200,2,12.86,100,1,12.73,100,1,12.71,100,1,12.5,700,1,12.46,100,1,12.43,700,1,12.42,700,1,13.45,15,1,13.46,100,1,13.47,15,1,13.75,100,1,13.79,2,1,14.01,100,1,14.08,100,1,14.18,700,1,14.27,100,1,14.28,100,1,ARL,344765077
1666,2025-07-17T16:17:52.834173973Z,2025-07-17T16:17:52.834008196Z,10,2,1108,C,A,-1,13.47,15,130,165777,286689853,13.11,100,1,13.03,2,1,12.98,200,2,12.86,100,1,12.73,100,1,12.71,100,1,12.5,700,1,12.46,100,1,12.43,700,1,12.42,700,1,13.45,15,1,13.46,100,1,13.75,100,1,13.79,2,1,14.01,100,1,14.08,100,1,14.18,700,1,14.27,100,1,14.28,100,1,14.35,200,2,ARL,344587533
1667,2025-07-17T16:17:58.033327053Z,2025-07-17T16:17:58.033161898Z,10,2,1108,C,A,-1,13.45,15,130,165155,286753046,13.11,100,1,13.03,2,1,12.98,200,2,12.86,100,1,12.73,100,1,12.71,100,1,12.5,700,1,12.46,100,1,12.43,700,1,12.42,700,1,13.46,100,1,13.75,100,1,13.79,2,1,14.01,100,1,14.08,100,1,14.18,700,1,14.27,100,1,14.28,100,1,14.35,200,2,14.43,200,2,ARL,344653009
1668,2025-07-17T16:17:58.036588469Z,2025-07-17T16:17:58.036423237Z,10,2,1108,C,A,-1,13.46,100,130,165232,286753126,13.11,100,1,13.03,2,1,12.98,200,2,12.86,100,1,12.73,100,1,12.71,100,1,12.5,700,1,12.46,100,1,12.43,700,1,12.42,700,1,13.75,100,1,13.79,2,1,14.01,100,1,14.08,100,1,14.18,700,1,14.27,100,1,14.28,100,1,14.35,200,2,14.43,200,2,14.48,700,1,ARL,344673481
1669,2025-07-17T16:17:58.036861922Z,2025-07-17T16:17:58.036696806Z,10,2,1108,C,A,-1,14.18,700,130,165116,286753127,13.11,100,1,13.03,2,1,12.98,200,2,12.86,100,1,12.73,100,1,12.71,100,1,12.5,700,1,12.46,100,1,12.43,700,1,12.42,700,1,13.75,100,1,13.79,2,1,14.01,100,1,14.08,100,1,14.27,100,1,14.28,100,1,14.35,200,2,14.43,200,2,14.48,700,1,14.53,100,1,ARL,344724301
1670,2025-07-17T16:17:58.036914002Z,2025-07-17T16:17:58.036748831Z,10,2,1108,A,A,8,14.44,700,130,165171,286753128,13.11,100,1,13.03,2,1,12.98,200,2,12.86,100,1,12.73,100,1,12.71,100,1,12.5,700,1,12.46,100,1,12.43,700,1,12.42,700,1,13.75,100,1,13.79,2,1,14.01,100,1,14.08,100,1,14.27,100,1,14.28,100,1,14.35,200,2,14.43,200,2,14.44,700,1,14.48,700,1,ARL,344897921
1671,2025-07-17T16:17:58.037330946Z,2025-07-17T16:17:58.037165870Z,10,2,1108,C,A,-1,14.08,100,130,165076,286753137,13.11,100,1,13.03,2,1,12.98,200,2,12.86,100,1,12.73,100,1,12.71,100,1,12.5,700,1,12.46,100,1,12.43,700,1,12.42,700,1,13.75,100,1,13.79,2,1,14.01,100,1,14.27,100,1,14.28,100,1,14.35,200,2,14.43,200,2,14.44,700,1,14.48,700,1,14.54,700,1,ARL,344607893
1672,2025-07-17T16:17:58.037686676Z,2025-07-17T16:17:58.037521442Z,10,2,1108,A,A,6,14.36,100,130,165234,286753149,13.11,100,1,13.03,2,1,12.98,200,2,12.86,100,1,12.73,100,1,12.71,100,1,12.5,700,1,12.46,100,1,12.43,700,1,12.42,700,1,13.75,100,1,13.79,2,1,14.01,100,1,14.27,100,1,14.28,100,1,14.35,200,2,14.36,100,1,14.43,200,2,14.44,700,1,14.48,700,1,ARL,344897953
1673,2025-07-17T16:17:58.038759735Z,2025-07-17T16:17:58.038594284Z,10,2,1108,C,A,7,14.43,100,0,165451,286753168,13.11,100,1,13.03,2,1,12.98,200,2,12.86,100,1,12.73,100,1,12.71,100,1,12.5,700,1,12.46,100,1,12.43,700,1,12.42,700,1,13.75,100,1,13.79,2,1,14.01,100,1,14.27,100,1,14.28,100,1,14.35,200,2,14.36,100,1,14.43,100,1,14.44,700,1,14.48,700,1,ARL,344608253
1674,2025-07-17T16:17:58.054049362Z,2025-07-17T16:17:58.053883828Z,10,2,1108,C,A,-1,13.75,100,130,165534,286753747,13.11,100,1,13.03,2,1,12.98,200,2,12.86,100,1,12.73,100,1,12.71,100,1,12.5,700,1,12.46,100,1,12.43,700,1,12.42,700,1,13.79,2,1,14.01,100,1,14.27,100,1,14.28,100,1,14.35,200,2,14.36,100,1,14.43,100,1,14.44,700,1,14.48,700,1,14.54,700,1,ARL,344608193
1675,2025-07-17T16:17:58.054100805Z,2025-07-17T16:17:58.053934652Z,10,2,1108,C,A,-1,14.44,700,130,166153,286753751,13.11,100,1,13.03,2,1,12.98,200,2,12.86,100,1,12.73,100,1,12.71,100,1,12.5,700,1,12.46,100,1,12.43,700,1,12.42,700,1,13.79,2,1,14.01,100,1,14.27,100,1,14.28,100,1,14.35,200,2,14.36,100,1,14.43,100,1,14.48,700,1,14.54,700,1,14.56,700,1,ARL,344897921
1676,2025-07-17T16:17:58.054101429Z,2025-07-17T16:17:58.053935872Z,10,2,1108,A,A,2,14.03,100,130,165557,286753752,13.11,100,1,13.03,2,1,12.98,200,2,12.86,100,1,12.73,100,1,12.71,100,1,12.5,700,1,12.46,100,1,12.43,700,1,12.42,700,1,13.79,2,1,14.01,100,1,14.03,100,1,14.27,100,1,14.28,100,1,14.35,200,2,14.36,100,1,14.43,100,1,14.48,700,1,14.54,700,1,ARL,344898949
1677,2025-07-17T16:17:58.061670860Z,2025-07-17T16:17:58.061505885Z,10,2,1108,C,A,-1,14.03,100,130,164975,286754272,13.11,100,1,13.03,2,1,12.98,200,2,12.86,100,1,12.73,100,1,12.71,100,1,12.5,700,1,12.46,100,1,12.43,700,1,12.42,700,1,13.79,2,1,14.01,100,1,14.27,100,1,14.28,100,1,14.35,200,2,14.36,100,1,14.43,100,1,14.48,700,1,14.54,700,1,14.56,700,1,ARL,344898949
1678,2025-07-17T16:17:58.061730836Z,2025-07-17T16:17:58.061563628Z,10,2,1108,A,A,2,14.25,100,130,167208,286754286,13.11,100,1,13.03,2,1,12.98,200,2,12.86,100,1,12.73,100,1,12.71,100,1,12.5,700,1,12.46,100,1,12.43,700,1,12.42,700,1,13.79,2,1,14.01,100,1,14.25,100,1,14.27,100,1,14.28,100,1,14.35,200,2,14.36,100,1,14.43,100,1,14.48,700,1,14.54,700,1,ARL,344899417
1679,2025-07-17T16:17:58.086582033Z,2025-07-17T16:17:58.086415950Z,10,2,1108,C,A,-1,14.27,100,0,166083,286754819,13.11,100,1,13.03,2,1,12.98,200,2,12.86,100,1,12.73,100,1,12.71,100,1,12.5,700,1,12.46,100,1,12.43,700,1,12.42,700,1,13.79,2,1,14.01,100,1,14.25,100,1,14.28,100,1,14.35,200,2,14.36,100,1,14.43,100,1,14.48,700,1,14.54,700,1,14.56,700,1,ARL,344608225
1680,2025-07-17T16:17:58.086582033Z,2025-07-17T16:17:58.086415950Z,10,2,1108,A,A,8,14.54,100,130,166083,286754819,13.11,100,1,13.03,2,1,12.98,200,2,12.86,100,1,12.73,100,1,12.71,100,1,12.5,700,1,12.46,100,1,12.43,700,1,12.42,700,1,13.79,2,1,14.01,100,1,14.25,100,1,14.28,100,1,14.35,200,2,14.36,100,1,14.43,100,1,14.48,700,1,14.54,800,2,14.56,700,1,ARL,344899913
1681,2025-07-17T16:17:58.145548497Z,2025-07-17T16:17:58.145382853Z,10,2,1108,C,A,-1,14.43,100,0,165644,286755340,13.11,100,1,13.03,2,1,12.98,200,2,12.86,100,1,12.73,100,1,12.71,100,1,12.5,700,1,12.46,100,1,12.43,700,1,12.42,700,1,13.79,2,1,14.01,100,1,14.25,100,1,14.28,100,1,14.35,200,2,14.36,100,1,14.48,700,1,14.54,800,2,14.56,700,1,14.96,100,1,ARL,344610073
1682,2025-07-17T16:17:58.145548497Z,2025-07-17T16:17:58.145382853Z,10,2,1108,A,A,9,14.96,100,130,165644,286755340,13.11,100,1,13.03,2,1,12.98,200,2,12.86,100,1,12.73,100,1,12.71,100,1,12.5,700,1,12.46,100,1,12.43,700,1,12.42,700,1,13.79,2,1,14.01,100,1,14.25,100,1,14.28,100,1,14.35,200,2,14.36,100,1,14.48,700,1,14.54,800,2,14.56,700,1,14.96,200,2,ARL,344900597
1683,2025-07-17T16:17:58.173831273Z,2025-07-17T16:17:58.173665745Z,10,2,1108,A,A,9,14.81,100,130,165528,286755602,13.11,100,1,13.03,2,1,12.98,200,2,12.86,100,1,12.73,100,1,12.71,100,1,12.5,700,1,12.46,100,1,12.43,700,1,12.42,700,1,13.79,2,1,14.01,100,1,14.25,100,1,14.28,100,1,14.35,200,2,14.36,100,1,14.48,700,1,14.54,800,2,14.56,700,1,14.81,100,1,ARL,344900925
1684,2025-07-17T16:17:58.173852767Z,2025-07-17T16:17:58.173687330Z,10,2,1108,C,A,-1,14.28,100,130,165437,286755603,13.11,100,1,13.03,2,1,12.98,200,2,12.86,100,1,12.73,100,1,12.71,100,1,12.5,700,1,12.46,100,1,12.43,700,1,12.42,700,1,13.79,2,1,14.01,100,1,14.25,100,1,14.35,200,2,14.36,100,1,14.48,700,1,14.54,800,2,14.56,700,1,14.81,100,1,14.96,200,2,ARL,344615393
1685,2025-07-17T16:17:58.235788576Z,2025-07-17T16:17:58.235623452Z,10,2,1108,A,A,8,14.68,700,130,165124,286756143,13.11,100,1,13.03,2,1,12.98,200,2,12.86,100,1,12.73,100,1,12.71,100,1,12.5,700,1,12.46,100,1,12.43,700,1,12.42,700,1,13.79,2,1,14.01,100,1,14.25,100,1,14.35,200,2,14.36,100,1,14.48,700,1,14.54,800,2,14.56,700,1,14.68,700,1,14.81,100,1,ARL,344902153
1686,2025-07-17T16:17:58.502856372Z,2025-07-17T16:17:58.502691073Z,10,2,1108,A,A,6,14.53,100,130,165299,286758830,13.11,100,1,13.03,2,1,12.98,200,2,12.86,100,1,12.73,100,1,12.71,100,1,12.5,700,1,12.46,100,1,12.43,700,1,12.42,700,1,13.79,2,1,14.01,100,1,14.25,100,1,14.35,200,2,14.36,100,1,14.48,700,1,14.53,100,1,14.54,800,2,14.56,700,1,14.68,700,1,ARL,344905321
1687,2025-07-17T16:17:58.502858100Z,2025-07-17T16:17:58.502692641Z,10,2,1108,C,A,-1,14.01,100,130,165459,286758831,13.11,100,1,13.03,2,1,12.98,200,2,12.86,100,1,12.73,100,1,12.71,100,1,12.5,700,1,12.46,100,1,12.43,700,1,12.42,700,1,13.79,2,1,14.25,100,1,14.35,200,2,14.36,100,1,14.48,700,1,14.53,100,1,14.54,800,2,14.56,700,1,14.68,700,1,14.81,100,1,ARL,344612049
1688,2025-07-17T16:17:58.704865076Z,2025-07-17T16:17:58.704699676Z,10,2,1108,C,A,-1,14.36,100,130,165400,286760091,13.11,100,1,13.03,2,1,12.98,200,2,12.86,100,1,12.73,100,1,12.71,100,1,12.5,700,1,12.46,100,1,12.43,700,1,12.42,700,1,13.79,2,1,14.25,100,1,14.35,200,2,14.48,700,1,14.53,100,1,14.54,800,2,14.56,700,1,14.68,700,1,14.81,100,1,14.96,200,2,ARL,344897953
1689,2025-07-17T16:17:58.705216838Z,2025-07-17T16:17:58.705051532Z,10,2,1108,A,A,7,14.6,100,130,165306,286760096,13.11,100,1,13.03,2,1,12.98,200,2,12.86,100,1,12.73,100,1,12.71,100,1,12.5,700,1,12.46,100,1,12.43,700,1,12.42,700,1,13.79,2,1,14.25,100,1,14.35,200,2,14.48,700,1,14.53,100,1,14.54,800,2,14.56,700,1,14.6,100,1,14.68,700,1,14.81,100,1,ARL,344906945
1690,2025-07-17T16:17:59.086439158Z,2025-07-17T16:17:59.086273873Z,10,2,1108,C,A,5,14.54,100,130,165285,286766349,13.11,100,1,13.03,2,1,12.98,200,2,12.86,100,1,12.73,100,1,12.71,100,1,12.5,700,1,12.46,100,1,12.43,700,1,12.42,700,1,13.79,2,1,14.25,100,1,14.35,200,2,14.48,700,1,14.53,100,1,14.54,700,1,14.56,700,1,14.6,100,1,14.68,700,1,14.81,100,1,ARL,344899913
1691,2025-07-17T16:17:59.086561438Z,2025-07-17T16:17:59.086395964Z,10,2,1108,A,A,9,14.77,100,130,165474,286766355,13.11,100,1,13.03,2,1,12.98,200,2,12.86,100,1,12.73,100,1,12.71,100,1,12.5,700,1,12.46,100,1,12.43,700,1,12.42,700,1,13.79,2,1,14.25,100,1,14.35,200,2,14.48,700,1,14.53,100,1,14.54,700,1,14.56,700,1,14.6,100,1,14.68,700,1,14.77,100,1,ARL,344914361
1692,2025-07-17T16:18:02.178629167Z,2025-07-17T16:18:02.178463984Z,10,2,1108,A,A,1,13.8,100,130,165183,286829047,13.11,100,1,13.03,2,1,12.98,200,2,12.86,100,1,12.73,100,1,12.71,100,1,12.5,700,1,12.46,100,1,12.43,700,1,12.42,700,1,13.79,2,1,13.8,100,1,14.25,100,1,14.35,200,2,14.48,700,1,14.53,100,1,14.54,700,1,14.56,700,1,14.6,100,1,14.68,700,1,ARL,344989393
1693,2025-07-17T16:18:02.184788371Z,2025-07-17T16:18:02.184622698Z,10,2,1108,C,A,-1,14.25,100,130,165673,286829173,13.11,100,1,13.03,2,1,12.98,200,2,12.86,100,1,12.73,100,1,12.71,100,1,12.5,700,1,12.46,100,1,12.43,700,1,12.42,700,1,13.79,2,1,13.8,100,1,14.35,200,2,14.48,700,1,14.53,100,1,14.54,700,1,14.56,700,1,14.6,100,1,14.68,700,1,14.77,200,2,ARL,344899417
1694,2025-07-17T16:18:02.184840010Z,2025-07-17T16:18:02.184674810Z,10,2,1108,A,A,2,14.08,100,130,165200,286829174,13.11,100,1,13.03,2,1,12.98,200,2,12.86,100,1,12.73,100,1,12.71,100,1,12.5,700,1,12.46,100,1,12.43,700,1,12.42,700,1,13.79,2,1,13.8,100,1,14.08,100,1,14.35,200,2,14.48,700,1,14.53,100,1,14.54,700,1,14.56,700,1,14.6,100,1,14.68,700,1,ARL,344989601
1695,2025-07-17T16:18:02.186910586Z,2025-07-17T16:18:02.186745185Z,10,2,1108,A,A,8,14.59,100,130,165401,286829206,13.11,100,1,13.03,2,1,12.98,200,2,12.86,100,1,12.73,100,1,12.71,100,1,12.5,700,1,12.46,100,1,12.43,700,1,12.42,700,1,13.79,2,1,13.8,100,1,14.08,100,1,14.35,200,2,14.48,700,1,14.53,100,1,14.54,700,1,14.56,700,1,14.59,100,1,14.6,100,1,ARL,344989661
1696,2025-07-17T16:18:44.836233374Z,2025-07-17T16:18:44.836067409Z,10,2,1108,A,A,0,13.47,15,130,165965,287534438,13.11,100,1,13.03,2,1,12.98,200,2,12.86,100,1,12.73,100,1,12.71,100,1,12.5,700,1,12.46,100,1,12.43,700,1,12.42,700,1,13.47,15,1,13.79,2,1,13.8,100,1,14.08,100,1,14.35,200,2,14.48,700,1,14.53,100,1,14.54,700,1,14.56,700,1,14.59,100,1,ARL,345869437
1697,2025-07-17T16:18:45.977564112Z,2025-07-17T16:18:45.977398557Z,10,2,1108,C,A,-1,13.8,100,0,165555,287547865,13.11,100,1,13.03,2,1,12.98,200,2,12.86,100,1,12.73,100,1,12.71,100,1,12.5,700,1,12.46,100,1,12.43,700,1,12.42,700,1,13.47,15,1,13.79,2,1,14.08,100,1,14.35,200,2,14.48,700,1,14.53,100,1,14.54,700,1,14.56,700,1,14.59,100,1,14.6,100,1,ARL,344989393
1698,2025-07-17T16:18:45.977564112Z,2025-07-17T16:18:45.977398557Z,10,2,1108,A,A,1,13.48,100,130,165555,287547865,13.11,100,1,13.03,2,1,12.98,200,2,12.86,100,1,12.73,100,1,12.71,100,1,12.5,700,1,12.46,100,1,12.43,700,1,12.42,700,1,13.47,15,1,13.48,100,1,13.79,2,1,14.08,100,1,14.35,200,2,14.48,700,1,14.53,100,1,14.54,700,1,14.56,700,1,14.59,100,1,ARL,345889137
1699,2025-07-17T16:18:45.978307201Z,2025-07-17T16:18:45.978141738Z,10,2,1108,A,A,6,14.53,100,130,165463,287547871,13.11,100,1,13.03,2,1,12.98,200,2,12.86,100,1,12.73,100,1,12.71,100,1,12.5,700,1,12.46,100,1,12.43,700,1,12.42,700,1,13.47,15,1,13.48,100,1,13.79,2,1,14.08,100,1,14.35,200,2,14.48,700,1,14.53,200,2,14.54,700,1,14.56,700,1,14.59,100,1,ARL,345889161
