,ts_recv,ts_event,rtype,publisher_id,instrument_id,action,side,depth,price,size,flags,ts_in_delta,sequence,bid_px_00,bid_sz_00,bid_ct_00,bid_px_01,bid_sz_01,bid_ct_01,bid_px_02,bid_sz_02,bid_ct_02,bid_px_03,bid_sz_03,bid_ct_03,bid_px_04,bid_sz_04,bid_ct_04,bid_px_05,bid_sz_05,bid_ct_05,bid_px_06,bid_sz_06,bid_ct_06,bid_px_07,bid_sz_07,bid_ct_07,bid_px_08,bid_sz_08,bid_ct_08,bid_px_09,bid_sz_09,bid_ct_09,ask_px_00,ask_sz_00,ask_ct_00,ask_px_01,ask_sz_01,ask_ct_01,ask_px_02,ask_sz_02,ask_ct_02,ask_px_03,ask_sz_03,ask_ct_03,ask_px_04,ask_sz_04,ask_ct_04,ask_px_05,ask_sz_05,ask_ct_05,ask_px_06,ask_sz_06,ask_ct_06,ask_px_07,ask_sz_07,ask_ct_07,ask_px_08,ask_sz_08,ask_ct_08,ask_px_09,ask_sz_09,ask_ct_09,symbol,order_id
588,2025-07-17T15:36:30.044094509Z,2025-07-17T15:36:30.043928872Z,10,2,1108,A,A,1,13.8,100,130,165637,245013624,13.3,100,1,13.14,2,1,13.03,100,1,12.73,100,1,12.71,100,1,12.5,700,1,12.46,200,2,12.43,700,1,12.42,700,1,12.37,700,1,13.78,100,1,13.8,100,1,13.82,100,1,13.95,2,1,14.12,100,1,14.4,100,1,14.56,800,2,14.6,700,1,14.65,100,1,14.68,1400,2,ARL,291778909
589,2025-07-17T15:36:30.051045453Z,2025-07-17T15:36:30.050880126Z,10,2,1108,C,A,-1,13.82,100,130,165327,245013914,13.3,100,1,13.14,2,1,13.03,100,1,12.73,100,1,12.71,100,1,12.5,700,1,12.46,200,2,12.43,700,1,12.42,700,1,12.37,700,1,13.78,100,1,13.8,100,1,13.95,2,1,14.12,100,1,14.4,100,1,14.56,800,2,14.6,700,1,14.65,100,1,14.68,1400,2,14.72,200,2,ARL,290630573
590,2025-07-17T15:36:34.298010005Z,2025-07-17T15:36:34.297844579Z,10,2,1108,C,B,-1,13.3,100,130,165426,245144122,13.14,2,1,13.03,100,1,12.73,100,1,12.71,100,1,12.5,700,1,12.46,200,2,12.43,700,1,12.42,700,1,12.37,700,1,12.36,200,2,13.78,100,1,13.8,100,1,13.95,2,1,14.12,100,1,14.4,100,1,14.56,800,2,14.6,700,1,14.65,100,1,14.68,1400,2,14.72,200,2,ARL,288724429
591,2025-07-17T15:36:35.381330809Z,2025-07-17T15:36:35.381165559Z,10,2,1108,A,B,1,13.13,100,130,165250,245161447,13.14,2,1,13.13,100,1,13.03,100,1,12.73,100,1,12.71,100,1,12.5,700,1,12.46,200,2,12.43,700,1,12.42,700,1,12.37,700,1,13.78,100,1,13.8,100,1,13.95,2,1,14.12,100,1,14.4,100,1,14.56,800,2,14.6,700,1,14.65,100,1,14.68,1400,2,14.72,200,2,ARL,291951937
592,2025-07-17T15:36:35.532851032Z,2025-07-17T15:36:35.532685683Z,10,2,1108,A,B,0,13.27,10,130,165349,245174454,13.27,10,1,13.14,2,1,13.13,100,1,13.03,100,1,12.73,100,1,12.71,100,1,12.5,700,1,12.46,200,2,12.43,700,1,12.42,700,1,13.78,100,1,13.8,100,1,13.95,2,1,14.12,100,1,14.4,100,1,14.56,800,2,14.6,700,1,14.65,100,1,14.68,1400,2,14.72,200,2,ARL,291964737
593,2025-07-17T15:36:36.152132527Z,2025-07-17T15:36:36.151966883Z,10,2,1108,C,B,-1,13.13,100,0,165644,245183955,13.27,10,1,13.14,2,1,13.03,100,1,12.73,100,1,12.71,100,1,12.5,700,1,12.46,200,2,12.43,700,1,12.42,700,1,12.37,700,1,13.78,100,1,13.8,100,1,13.95,2,1,14.12,100,1,14.4,100,1,14.56,800,2,14.6,700,1,14.65,100,1,14.68,1400,2,14.72,200,2,ARL,291951937
594,2025-07-17T15:36:36.152132527Z,2025-07-17T15:36:36.151966883Z,10,2,1108,A,B,1,13.26,100,130,165644,245183955,13.27,10,1,13.26,100,1,13.14,2,1,13.03,100,1,12.73,100,1,12.71,100,1,12.5,700,1,12.46,200,2,12.43,700,1,12.42,700,1,13.78,100,1,13.8,100,1,13.95,2,1,14.12,100,1,14.4,100,1,14.56,800,2,14.6,700,1,14.65,100,1,14.68,1400,2,14.72,200,2,ARL,291975017
595,2025-07-17T15:36:46.889917278Z,2025-07-17T15:36:46.889749756Z,10,2,1108,C,B,-1,13.27,10,128,167522,245499598,13.26,100,1,13.14,2,1,13.03,100,1,12.73,100,1,12.71,100,1,12.5,700,1,12.46,200,2,12.43,700,1,12.42,700,1,12.37,700,1,13.78,100,1,13.8,100,1,13.95,2,1,14.12,100,1,14.4,100,1,14.56,800,2,14.6,700,1,14.65,100,1,14.68,1400,2,14.72,200,2,ARL,291964737
596,2025-07-17T15:36:46.986820391Z,2025-07-17T15:36:46.986655137Z,10,2,1108,C,A,-1,13.8,100,130,165254,245503745,13.26,100,1,13.14,2,1,13.03,100,1,12.73,100,1,12.71,100,1,12.5,700,1,12.46,200,2,12.43,700,1,12.42,700,1,12.37,700,1,13.78,100,1,13.95,2,1,14.12,100,1,14.4,100,1,14.56,800,2,14.6,700,1,14.65,100,1,14.68,1400,2,14.72,200,2,14.81,200,2,ARL,291778909
597,2025-07-17T15:36:50.997434689Z,2025-07-17T15:36:50.997269299Z,10,2,1108,A,A,1,13.82,100,130,165390,245564901,13.26,100,1,13.14,2,1,13.03,100,1,12.73,100,1,12.71,100,1,12.5,700,1,12.46,200,2,12.43,700,1,12.42,700,1,12.37,700,1,13.78,100,1,13.82,100,1,13.95,2,1,14.12,100,1,14.4,100,1,14.56,800,2,14.6,700,1,14.65,100,1,14.68,1400,2,14.72,200,2,ARL,292434813
598,2025-07-17T15:37:40.389737573Z,2025-07-17T15:37:40.389572053Z,10,2,1108,C,B,-1,13.14,2,0,165520,246491394,13.26,100,1,13.03,100,1,12.73,100,1,12.71,100,1,12.5,700,1,12.46,200,2,12.43,700,1,12.42,700,1,12.37,700,1,12.36,200,2,13.78,100,1,13.82,100,1,13.95,2,1,14.12,100,1,14.4,100,1,14.56,800,2,14.6,700,1,14.65,100,1,14.68,1400,2,14.72,200,2,ARL,289828293
599,2025-07-17T15:37:40.389737573Z,2025-07-17T15:37:40.389572053Z,10,2,1108,A,B,1,13.04,2,130,165520,246491394,13.26,100,1,13.04,2,1,13.03,100,1,12.73,100,1,12.71,100,1,12.5,700,1,12.46,200,2,12.43,700,1,12.42,700,1,12.37,700,1,13.78,100,1,13.82,100,1,13.95,2,1,14.12,100,1,14.4,100,1,14.56,800,2,14.6,700,1,14.65,100,1,14.68,1400,2,14.72,200,2,ARL,293594281
600,2025-07-17T15:39:27.070109669Z,2025-07-17T15:39:27.069942913Z,10,2,1108,A,A,1,13.8,100,128,166756,248436908,13.26,100,1,13.04,2,1,13.03,100,1,12.73,100,1,12.71,100,1,12.5,700,1,12.46,200,2,12.43,700,1,12.42,700,1,12.37,700,1,13.78,100,1,13.8,100,1,13.82,100,1,13.95,2,1,14.12,100,1,14.4,100,1,14.56,800,2,14.6,700,1,14.65,100,1,14.68,1400,2,ARL,296059685
601,2025-07-17T15:39:27.077565902Z,2025-07-17T15:39:27.077400388Z,10,2,1108,C,A,-1,13.82,100,130,165514,248437548,13.26,100,1,13.04,2,1,13.03,100,1,12.73,100,1,12.71,100,1,12.5,700,1,12.46,200,2,12.43,700,1,12.42,700,1,12.37,700,1,13.78,100,1,13.8,100,1,13.95,2,1,14.12,100,1,14.4,100,1,14.56,800,2,14.6,700,1,14.65,100,1,14.68,1400,2,14.72,200,2,ARL,292434813
602,2025-07-17T15:39:30.509853083Z,2025-07-17T15:39:30.509687817Z,10,2,1108,A,A,0,13.76,15,130,165266,248491930,13.26,100,1,13.04,2,1,13.03,100,1,12.73,100,1,12.71,100,1,12.5,700,1,12.46,200,2,12.43,700,1,12.42,700,1,12.37,700,1,13.76,15,1,13.78,100,1,13.8,100,1,13.95,2,1,14.12,100,1,14.4,100,1,14.56,800,2,14.6,700,1,14.65,100,1,14.68,1400,2,ARL,296136617
603,2025-07-17T15:39:30.573217843Z,2025-07-17T15:39:30.573052284Z,10,2,1108,C,A,-1,13.78,100,0,165559,248492793,13.26,100,1,13.04,2,1,13.03,100,1,12.73,100,1,12.71,100,1,12.5,700,1,12.46,200,2,12.43,700,1,12.42,700,1,12.37,700,1,13.76,15,1,13.8,100,1,13.95,2,1,14.12,100,1,14.4,100,1,14.56,800,2,14.6,700,1,14.65,100,1,14.68,1400,2,14.72,200,2,ARL,289726281
604,2025-07-17T15:39:30.573217843Z,2025-07-17T15:39:30.573052284Z,10,2,1108,A,A,1,13.77,100,130,165559,248492793,13.26,100,1,13.04,2,1,13.03,100,1,12.73,100,1,12.71,100,1,12.5,700,1,12.46,200,2,12.43,700,1,12.42,700,1,12.37,700,1,13.76,15,1,13.77,100,1,13.8,100,1,13.95,2,1,14.12,100,1,14.4,100,1,14.56,800,2,14.6,700,1,14.65,100,1,14.68,1400,2,ARL,296137537
605,2025-07-17T15:39:30.589169820Z,2025-07-17T15:39:30.589004378Z,10,2,1108,C,A,-1,14.12,100,130,165442,248493012,13.26,100,1,13.04,2,1,13.03,100,1,12.73,100,1,12.71,100,1,12.5,700,1,12.46,200,2,12.43,700,1,12.42,700,1,12.37,700,1,13.76,15,1,13.77,100,1,13.8,100,1,13.95,2,1,14.4,100,1,14.56,800,2,14.6,700,1,14.65,100,1,14.68,1400,2,14.72,200,2,ARL,286680917
606,2025-07-17T15:39:30.589224596Z,2025-07-17T15:39:30.589059301Z,10,2,1108,A,A,4,14.05,100,130,165295,248493014,13.26,100,1,13.04,2,1,13.03,100,1,12.73,100,1,12.71,100,1,12.5,700,1,12.46,200,2,12.43,700,1,12.42,700,1,12.37,700,1,13.76,15,1,13.77,100,1,13.8,100,1,13.95,2,1,14.05,100,1,14.4,100,1,14.56,800,2,14.6,700,1,14.65,100,1,14.68,1400,2,ARL,296137769
607,2025-07-17T15:39:31.092010369Z,2025-07-17T15:39:31.091844988Z,10,2,1108,A,A,2,13.78,100,130,165381,248502203,13.26,100,1,13.04,2,1,13.03,100,1,12.73,100,1,12.71,100,1,12.5,700,1,12.46,200,2,12.43,700,1,12.42,700,1,12.37,700,1,13.76,15,1,13.77,100,1,13.78,100,1,13.8,100,1,13.95,2,1,14.05,100,1,14.4,100,1,14.56,800,2,14.6,700,1,14.65,100,1,ARL,296149845
608,2025-07-17T15:39:31.098856641Z,2025-07-17T15:39:31.098691429Z,10,2,1108,C,A,-1,13.8,100,130,165212,248502510,13.26,100,1,13.04,2,1,13.03,100,1,12.73,100,1,12.71,100,1,12.5,700,1,12.46,200,2,12.43,700,1,12.42,700,1,12.37,700,1,13.76,15,1,13.77,100,1,13.78,100,1,13.95,2,1,14.05,100,1,14.4,100,1,14.56,800,2,14.6,700,1,14.65,100,1,14.68,1400,2,ARL,296059685
609,2025-07-17T15:39:40.691151435Z,2025-07-17T15:39:40.690971606Z,10,2,1108,A,A,0,13.73,15,128,179829,248666930,13.26,100,1,13.04,2,1,13.03,100,1,12.73,100,1,12.71,100,1,12.5,700,1,12.46,200,2,12.43,700,1,12.42,700,1,12.37,700,1,13.73,15,1,13.76,15,1,13.77,100,1,13.78,100,1,13.95,2,1,14.05,100,1,14.4,100,1,14.56,800,2,14.6,700,1,14.65,100,1,ARL,296365029
610,2025-07-17T15:39:40.696349429Z,2025-07-17T15:39:40.696182148Z,10,2,1108,C,A,-1,13.77,100,0,167281,248669978,13.26,100,1,13.04,2,1,13.03,100,1,12.73,100,1,12.71,100,1,12.5,700,1,12.46,200,2,12.43,700,1,12.42,700,1,12.37,700,1,13.73,15,1,13.76,15,1,13.78,100,1,13.95,2,1,14.05,100,1,14.4,100,1,14.56,800,2,14.6,700,1,14.65,100,1,14.68,1400,2,ARL,296137537
611,2025-07-17T15:39:40.696349429Z,2025-07-17T15:39:40.696182148Z,10,2,1108,A,A,1,13.74,100,130,167281,248669978,13.26,100,1,13.04,2,1,13.03,100,1,12.73,100,1,12.71,100,1,12.5,700,1,12.46,200,2,12.43,700,1,12.42,700,1,12.37,700,1,13.73,15,1,13.74,100,1,13.76,15,1,13.78,100,1,13.95,2,1,14.05,100,1,14.4,100,1,14.56,800,2,14.6,700,1,14.65,100,1,ARL,296368281
612,2025-07-17T15:39:40.708810377Z,2025-07-17T15:39:40.708645114Z,10,2,1108,A,A,2,13.76,100,130,165263,248674504,13.26,100,1,13.04,2,1,13.03,100,1,12.73,100,1,12.71,100,1,12.5,700,1,12.46,200,2,12.43,700,1,12.42,700,1,12.37,700,1,13.73,15,1,13.74,100,1,13.76,115,2,13.78,100,1,13.95,2,1,14.05,100,1,14.4,100,1,14.56,800,2,14.6,700,1,14.65,100,1,ARL,296372577
613,2025-07-17T15:39:40.731431547Z,2025-07-17T15:39:40.731266408Z,10,2,1108,C,A,-1,13.78,100,130,165139,248676672,13.26,100,1,13.04,2,1,13.03,100,1,12.73,100,1,12.71,100,1,12.5,700,1,12.46,200,2,12.43,700,1,12.42,700,1,12.37,700,1,13.73,15,1,13.74,100,1,13.76,115,2,13.95,2,1,14.05,100,1,14.4,100,1,14.56,800,2,14.6,700,1,14.65,100,1,14.68,1400,2,ARL,296149845
614,2025-07-17T15:39:41.085864728Z,2025-07-17T15:39:41.085699437Z,10,2,1108,A,A,6,14.56,100,130,165291,248688410,13.26,100,1,13.04,2,1,13.03,100,1,12.73,100,1,12.71,100,1,12.5,700,1,12.46,200,2,12.43,700,1,12.42,700,1,12.37,700,1,13.73,15,1,13.74,100,1,13.76,115,2,13.95,2,1,14.05,100,1,14.4,100,1,14.56,900,3,14.6,700,1,14.65,100,1,14.68,1400,2,ARL,296391881
615,2025-07-17T15:39:43.773811774Z,2025-07-17T15:39:43.773645905Z,10,2,1108,A,A,8,14.61,100,130,165869,248737506,13.26,100,1,13.04,2,1,13.03,100,1,12.73,100,1,12.71,100,1,12.5,700,1,12.46,200,2,12.43,700,1,12.42,700,1,12.37,700,1,13.73,15,1,13.74,100,1,13.76,115,2,13.95,2,1,14.05,100,1,14.4,100,1,14.56,900,3,14.6,700,1,14.61,100,1,14.65,100,1,ARL,296455037
616,2025-07-17T15:39:43.773904473Z,2025-07-17T15:39:43.773738855Z,10,2,1108,A,A,8,14.61,100,130,165618,248737508,13.26,100,1,13.04,2,1,13.03,100,1,12.73,100,1,12.71,100,1,12.5,700,1,12.46,200,2,12.43,700,1,12.42,700,1,12.37,700,1,13.73,15,1,13.74,100,1,13.76,115,2,13.95,2,1,14.05,100,1,14.4,100,1,14.56,900,3,14.6,700,1,14.61,200,2,14.65,100,1,ARL,296455041
617,2025-07-17T15:39:44.428670900Z,2025-07-17T15:39:44.428505546Z,10,2,1108,C,A,2,13.76,15,130,165354,248751670,13.26,100,1,13.04,2,1,13.03,100,1,12.73,100,1,12.71,100,1,12.5,700,1,12.46,200,2,12.43,700,1,12.42,700,1,12.37,700,1,13.73,15,1,13.74,100,1,13.76,100,1,13.95,2,1,14.05,100,1,14.4,100,1,14.56,900,3,14.6,700,1,14.61,200,2,14.65,100,1,ARL,296136617
618,2025-07-17T15:39:44.433539292Z,2025-07-17T15:39:44.433372235Z,10,2,1108,C,A,-1,13.73,15,128,167057,248752483,13.26,100,1,13.04,2,1,13.03,100,1,12.73,100,1,12.71,100,1,12.5,700,1,12.46,200,2,12.43,700,1,12.42,700,1,12.37,700,1,13.74,100,1,13.76,100,1,13.95,2,1,14.05,100,1,14.4,100,1,14.56,900,3,14.6,700,1,14.61,200,2,14.65,100,1,14.68,1400,2,ARL,296365029
619,2025-07-17T15:39:44.436054885Z,2025-07-17T15:39:44.435889060Z,10,2,1108,C,A,-1,13.74,100,130,165825,248752938,13.26,100,1,13.04,2,1,13.03,100,1,12.73,100,1,12.71,100,1,12.5,700,1,12.46,200,2,12.43,700,1,12.42,700,1,12.37,700,1,13.76,100,1,13.95,2,1,14.05,100,1,14.4,100,1,14.56,900,3,14.6,700,1,14.61,200,2,14.65,100,1,14.68,1400,2,14.81,300,3,ARL,296368281
620,2025-07-17T15:39:44.450239090Z,2025-07-17T15:39:44.450073949Z,10,2,1108,C,A,-1,13.76,100,130,165141,248753643,13.26,100,1,13.04,2,1,13.03,100,1,12.73,100,1,12.71,100,1,12.5,700,1,12.46,200,2,12.43,700,1,12.42,700,1,12.37,700,1,13.95,2,1,14.05,100,1,14.4,100,1,14.56,900,3,14.6,700,1,14.61,200,2,14.65,100,1,14.68,1400,2,14.81,300,3,15.12,100,1,ARL,296372577
621,2025-07-17T15:39:44.450972330Z,2025-07-17T15:39:44.450806746Z,10,2,1108,C,A,8,14.81,100,0,165584,248753673,13.26,100,1,13.04,2,1,13.03,100,1,12.73,100,1,12.71,100,1,12.5,700,1,12.46,200,2,12.43,700,1,12.42,700,1,12.37,700,1,13.95,2,1,14.05,100,1,14.4,100,1,14.56,900,3,14.6,700,1,14.61,200,2,14.65,100,1,14.68,1400,2,14.81,200,2,15.12,100,1,ARL,296368709
622,2025-07-17T15:39:44.450972330Z,2025-07-17T15:39:44.450806746Z,10,2,1108,A,A,9,15.06,100,130,165584,248753673,13.26,100,1,13.04,2,1,13.03,100,1,12.73,100,1,12.71,100,1,12.5,700,1,12.46,200,2,12.43,700,1,12.42,700,1,12.37,700,1,13.95,2,1,14.05,100,1,14.4,100,1,14.56,900,3,14.6,700,1,14.61,200,2,14.65,100,1,14.68,1400,2,14.81,200,2,15.06,100,1,ARL,296478965
623,2025-07-17T15:39:44.451075992Z,2025-07-17T15:39:44.450910591Z,10,2,1108,C,A,-1,13.95,2,0,165401,248753678,13.26,100,1,13.04,2,1,13.03,100,1,12.73,100,1,12.71,100,1,12.5,700,1,12.46,200,2,12.43,700,1,12.42,700,1,12.37,700,1,14.05,100,1,14.4,100,1,14.56,900,3,14.6,700,1,14.61,200,2,14.65,100,1,14.68,1400,2,14.81,200,2,15.06,100,1,15.12,100,1,ARL,287540393
624,2025-07-17T15:39:44.451075992Z,2025-07-17T15:39:44.450910591Z,10,2,1108,A,A,1,14.07,2,130,165401,248753678,13.26,100,1,13.04,2,1,13.03,100,1,12.73,100,1,12.71,100,1,12.5,700,1,12.46,200,2,12.43,700,1,12.42,700,1,12.37,700,1,14.05,100,1,14.07,2,1,14.4,100,1,14.56,900,3,14.6,700,1,14.61,200,2,14.65,100,1,14.68,1400,2,14.81,200,2,15.06,100,1,ARL,296478973
625,2025-07-17T15:39:44.455130297Z,2025-07-17T15:39:44.454964327Z,10,2,1108,C,A,8,14.81,100,0,165970,248753748,13.26,100,1,13.04,2,1,13.03,100,1,12.73,100,1,12.71,100,1,12.5,700,1,12.46,200,2,12.43,700,1,12.42,700,1,12.37,700,1,14.05,100,1,14.07,2,1,14.4,100,1,14.56,900,3,14.6,700,1,14.61,200,2,14.65,100,1,14.68,1400,2,14.81,100,1,15.06,100,1,ARL,286680741
626,2025-07-17T15:39:44.455130297Z,2025-07-17T15:39:44.454964327Z,10,2,1108,A,A,9,14.96,100,130,165970,248753748,13.26,100,1,13.04,2,1,13.03,100,1,12.73,100,1,12.71,100,1,12.5,700,1,12.46,200,2,12.43,700,1,12.42,700,1,12.37,700,1,14.05,100,1,14.07,2,1,14.4,100,1,14.56,900,3,14.6,700,1,14.61,200,2,14.65,100,1,14.68,1400,2,14.81,100,1,14.96,100,1,ARL,296479053
627,2025-07-17T15:39:44.456288062Z,2025-07-17T15:39:44.456122660Z,10,2,1108,C,A,-1,14.65,100,130,165402,248753812,13.26,100,1,13.04,2,1,13.03,100,1,12.73,100,1,12.71,100,1,12.5,700,1,12.46,200,2,12.43,700,1,12.42,700,1,12.37,700,1,14.05,100,1,14.07,2,1,14.4,100,1,14.56,900,3,14.6,700,1,14.61,200,2,14.68,1400,2,14.81,100,1,14.96,100,1,15.06,100,1,ARL,286680905
628,2025-07-17T15:39:44.456377500Z,2025-07-17T15:39:44.456211953Z,10,2,1108,A,A,7,14.78,100,130,165547,248753815,13.26,100,1,13.04,2,1,13.03,100,1,12.73,100,1,12.71,100,1,12.5,700,1,12.46,200,2,12.43,700,1,12.42,700,1,12.37,700,1,14.05,100,1,14.07,2,1,14.4,100,1,14.56,900,3,14.6,700,1,14.61,200,2,14.68,1400,2,14.78,100,1,14.81,100,1,14.96,100,1,ARL,296479285
629,2025-07-17T15:39:44.462055094Z,2025-07-17T15:39:44.461889886Z,10,2,1108,C,A,-1,14.05,100,130,165208,248753947,13.26,100,1,13.04,2,1,13.03,100,1,12.73,100,1,12.71,100,1,12.5,700,1,12.46,200,2,12.43,700,1,12.42,700,1,12.37,700,1,14.07,2,1,14.4,100,1,14.56,900,3,14.6,700,1,14.61,200,2,14.68,1400,2,14.78,100,1,14.81,100,1,14.96,100,1,15.06,100,1,ARL,296137769
630,2025-07-17T15:39:44.462108809Z,2025-07-17T15:39:44.461943584Z,10,2,1108,A,A,1,14.26,100,130,165225,248753952,13.26,100,1,13.04,2,1,13.03,100,1,12.73,100,1,12.71,100,1,12.5,700,1,12.46,200,2,12.43,700,1,12.42,700,1,12.37,700,1,14.07,2,1,14.26,100,1,14.4,100,1,14.56,900,3,14.6,700,1,14.61,200,2,14.68,1400,2,14.78,100,1,14.81,100,1,14.96,100,1,ARL,296479425
631,2025-07-17T15:39:44.593773213Z,2025-07-17T15:39:44.593607433Z,10,2,1108,C,A,-1,14.81,100,0,165780,248756227,13.26,100,1,13.04,2,1,13.03,100,1,12.73,100,1,12.71,100,1,12.5,700,1,12.46,200,2,12.43,700,1,12.42,700,1,12.37,700,1,14.07,2,1,14.26,100,1,14.4,100,1,14.56,900,3,14.6,700,1,14.61,200,2,14.68,1400,2,14.78,100,1,14.96,100,1,15.06,100,1,ARL,286684005
632,2025-07-17T15:39:44.593773213Z,2025-07-17T15:39:44.593607433Z,10,2,1108,A,A,8,14.96,100,130,165780,248756227,13.26,100,1,13.04,2,1,13.03,100,1,12.73,100,1,12.71,100,1,12.5,700,1,12.46,200,2,12.43,700,1,12.42,700,1,12.37,700,1,14.07,2,1,14.26,100,1,14.4,100,1,14.56,900,3,14.6,700,1,14.61,200,2,14.68,1400,2,14.78,100,1,14.96,200,2,15.06,100,1,ARL,296482509
633,2025-07-17T15:39:44.859886562Z,2025-07-17T15:39:44.859720946Z,10,2,1108,C,A,5,14.61,100,0,165616,248760319,13.26,100,1,13.04,2,1,13.03,100,1,12.73,100,1,12.71,100,1,12.5,700,1,12.46,200,2,12.43,700,1,12.42,700,1,12.37,700,1,14.07,2,1,14.26,100,1,14.4,100,1,14.56,900,3,14.6,700,1,14.61,100,1,14.68,1400,2,14.78,100,1,14.96,200,2,15.06,100,1,ARL,296455041
634,2025-07-17T15:39:44.860160096Z,2025-07-17T15:39:44.859994671Z,10,2,1108,A,A,1,14.08,100,130,165425,248760324,13.26,100,1,13.04,2,1,13.03,100,1,12.73,100,1,12.71,100,1,12.5,700,1,12.46,200,2,12.43,700,1,12.42,700,1,12.37,700,1,14.07,2,1,14.08,100,1,14.26,100,1,14.4,100,1,14.56,900,3,14.6,700,1,14.61,100,1,14.68,1400,2,14.78,100,1,14.96,200,2,ARL,296485629
635,2025-07-17T15:39:44.863678795Z,2025-07-17T15:39:44.863513587Z,10,2,1108,C,A,-1,14.61,100,0,165208,248760417,13.26,100,1,13.04,2,1,13.03,100,1,12.73,100,1,12.71,100,1,12.5,700,1,12.46,200,2,12.43,700,1,12.42,700,1,12.37,700,1,14.07,2,1,14.08,100,1,14.26,100,1,14.4,100,1,14.56,900,3,14.6,700,1,14.68,1400,2,14.78,100,1,14.96,200,2,15.06,100,1,ARL,296455037
636,2025-07-17T15:39:54.187008224Z,2025-07-17T15:39:54.186842327Z,10,2,1108,A,A,8,14.88,100,130,165897,248915116,13.26,100,1,13.04,2,1,13.03,100,1,12.73,100,1,12.71,100,1,12.5,700,1,12.46,200,2,12.43,700,1,12.42,700,1,12.37,700,1,14.07,2,1,14.08,100,1,14.26,100,1,14.4,100,1,14.56,900,3,14.6,700,1,14.68,1400,2,14.78,100,1,14.88,100,1,14.96,200,2,ARL,296679277
637,2025-07-17T15:39:54.187557412Z,2025-07-17T15:39:54.187391707Z,10,2,1108,A,A,8,14.88,100,130,165705,248915126,13.26,100,1,13.04,2,1,13.03,100,1,12.73,100,1,12.71,100,1,12.5,700,1,12.46,200,2,12.43,700,1,12.42,700,1,12.37,700,1,14.07,2,1,14.08,100,1,14.26,100,1,14.4,100,1,14.56,900,3,14.6,700,1,14.68,1400,2,14.78,100,1,14.88,200,2,14.96,200,2,ARL,296679285
638,2025-07-17T15:42:06.780503054Z,2025-07-17T15:42:06.780337543Z,10,2,1108,A,A,0,13.9,15,130,165511,251407709,13.26,100,1,13.04,2,1,13.03,100,1,12.73,100,1,12.71,100,1,12.5,700,1,12.46,200,2,12.43,700,1,12.42,700,1,12.37,700,1,13.9,15,1,14.07,2,1,14.08,100,1,14.26,100,1,14.4,100,1,14.56,900,3,14.6,700,1,14.68,1400,2,14.78,100,1,14.88,200,2,ARL,299689753
639,2025-07-17T15:42:06.780767761Z,2025-07-17T15:42:06.780602350Z,10,2,1108,C,A,-1,14.08,100,0,165411,251407713,13.26,100,1,13.04,2,1,13.03,100,1,12.73,100,1,12.71,100,1,12.5,700,1,12.46,200,2,12.43,700,1,12.42,700,1,12.37,700,1,13.9,15,1,14.07,2,1,14.26,100,1,14.4,100,1,14.56,900,3,14.6,700,1,14.68,1400,2,14.78,100,1,14.88,200,2,14.96,200,2,ARL,296485629
640,2025-07-17T15:42:06.780767761Z,2025-07-17T15:42:06.780602350Z,10,2,1108,A,A,1,13.91,100,130,165411,251407713,13.26,100,1,13.04,2,1,13.03,100,1,12.73,100,1,12.71,100,1,12.5,700,1,12.46,200,2,12.43,700,1,12.42,700,1,12.37,700,1,13.9,15,1,13.91,100,1,14.07,2,1,14.26,100,1,14.4,100,1,14.56,900,3,14.6,700,1,14.68,1400,2,14.78,100,1,14.88,200,2,ARL,299689769
641,2025-07-17T15:42:06.795521307Z,2025-07-17T15:42:06.795355762Z,10,2,1108,C,A,-1,14.26,100,130,165545,251408268,13.26,100,1,13.04,2,1,13.03,100,1,12.73,100,1,12.71,100,1,12.5,700,1,12.46,200,2,12.43,700,1,12.42,700,1,12.37,700,1,13.9,15,1,13.91,100,1,14.07,2,1,14.4,100,1,14.56,900,3,14.6,700,1,14.68,1400,2,14.78,100,1,14.88,200,2,14.96,200,2,ARL,296479425
642,2025-07-17T15:42:06.795573392Z,2025-07-17T15:42:06.795408057Z,10,2,1108,A,A,3,14.19,100,130,165335,251408269,13.26,100,1,13.04,2,1,13.03,100,1,12.73,100,1,12.71,100,1,12.5,700,1,12.46,200,2,12.43,700,1,12.42,700,1,12.37,700,1,13.9,15,1,13.91,100,1,14.07,2,1,14.19,100,1,14.4,100,1,14.56,900,3,14.6,700,1,14.68,1400,2,14.78,100,1,14.88,200,2,ARL,299690593
643,2025-07-17T15:42:16.264132159Z,2025-07-17T15:42:16.263966448Z,10,2,1108,C,A,9,14.88,100,0,165711,251574391,13.26,100,1,13.04,2,1,13.03,100,1,12.73,100,1,12.71,100,1,12.5,700,1,12.46,200,2,12.43,700,1,12.42,700,1,12.37,700,1,13.9,15,1,13.91,100,1,14.07,2,1,14.19,100,1,14.4,100,1,14.56,900,3,14.6,700,1,14.68,1400,2,14.78,100,1,14.88,100,1,ARL,296679285
644,2025-07-17T15:42:16.264132159Z,2025-07-17T15:42:16.263966448Z,10,2,1108,A,A,8,14.76,100,130,165711,251574391,13.26,100,1,13.04,2,1,13.03,100,1,12.73,100,1,12.71,100,1,12.5,700,1,12.46,200,2,12.43,700,1,12.42,700,1,12.37,700,1,13.9,15,1,13.91,100,1,14.07,2,1,14.19,100,1,14.4,100,1,14.56,900,3,14.6,700,1,14.68,1400,2,14.76,100,1,14.78,100,1,ARL,299903169
645,2025-07-17T15:42:17.356766715Z,2025-07-17T15:42:17.356601231Z,10,2,1108,A,A,0,13.83,15,130,165484,251593608,13.26,100,1,13.04,2,1,13.03,100,1,12.73,100,1,12.71,100,1,12.5,700,1,12.46,200,2,12.43,700,1,12.42,700,1,12.37,700,1,13.83,15,1,13.9,15,1,13.91,100,1,14.07,2,1,14.19,100,1,14.4,100,1,14.56,900,3,14.6,700,1,14.68,1400,2,14.76,100,1,ARL,299923773
646,2025-07-17T15:42:17.577474246Z,2025-07-17T15:42:17.577308779Z,10,2,1108,C,A,-1,13.91,100,0,165467,251595553,13.26,100,1,13.04,2,1,13.03,100,1,12.73,100,1,12.71,100,1,12.5,700,1,12.46,200,2,12.43,700,1,12.42,700,1,12.37,700,1,13.83,15,1,13.9,15,1,14.07,2,1,14.19,100,1,14.4,100,1,14.56,900,3,14.6,700,1,14.68,1400,2,14.76,100,1,14.78,100,1,ARL,299689769
647,2025-07-17T15:42:17.577474246Z,2025-07-17T15:42:17.577308779Z,10,2,1108,A,A,1,13.84,100,130,165467,251595553,13.26,100,1,13.04,2,1,13.03,100,1,12.73,100,1,12.71,100,1,12.5,700,1,12.46,200,2,12.43,700,1,12.42,700,1,12.37,700,1,13.83,15,1,13.84,100,1,13.9,15,1,14.07,2,1,14.19,100,1,14.4,100,1,14.56,900,3,14.6,700,1,14.68,1400,2,14.76,100,1,ARL,299926781
648,2025-07-17T15:42:17.579343189Z,2025-07-17T15:42:17.579177582Z,10,2,1108,A,A,8,14.64,100,130,165607,251595571,13.26,100,1,13.04,2,1,13.03,100,1,12.73,100,1,12.71,100,1,12.5,700,1,12.46,200,2,12.43,700,1,12.42,700,1,12.37,700,1,13.83,15,1,13.84,100,1,13.9,15,1,14.07,2,1,14.19,100,1,14.4,100,1,14.56,900,3,14.6,700,1,14.64,100,1,14.68,1400,2,ARL,299926813
649,2025-07-17T15:42:17.589263550Z,2025-07-17T15:42:17.589098227Z,10,2,1108,C,A,-1,14.19,100,130,165323,251595691,13.26,100,1,13.04,2,1,13.03,100,1,12.73,100,1,12.71,100,1,12.5,700,1,12.46,200,2,12.43,700,1,12.42,700,1,12.37,700,1,13.83,15,1,13.84,100,1,13.9,15,1,14.07,2,1,14.4,100,1,14.56,900,3,14.6,700,1,14.64,100,1,14.68,1400,2,14.76,100,1,ARL,299690593
650,2025-07-17T15:42:17.589316911Z,2025-07-17T15:42:17.589151325Z,10,2,1108,A,A,4,14.12,100,130,165586,251595692,13.26,100,1,13.04,2,1,13.03,100,1,12.73,100,1,12.71,100,1,12.5,700,1,12.46,200,2,12.43,700,1,12.42,700,1,12.37,700,1,13.83,15,1,13.84,100,1,13.9,15,1,14.07,2,1,14.12,100,1,14.4,100,1,14.56,900,3,14.6,700,1,14.64,100,1,14.68,1400,2,ARL,299926965
651,2025-07-17T15:42:21.517871714Z,2025-07-17T15:42:21.517706139Z,10,2,1108,C,A,-1,13.9,15,130,165575,251668179,13.26,100,1,13.04,2,1,13.03,100,1,12.73,100,1,12.71,100,1,12.5,700,1,12.46,200,2,12.43,700,1,12.42,700,1,12.37,700,1,13.83,15,1,13.84,100,1,14.07,2,1,14.12,100,1,14.4,100,1,14.56,900,3,14.6,700,1,14.64,100,1,14.68,1400,2,14.73,100,1,ARL,299689753
652,2025-07-17T15:42:22.522744242Z,2025-07-17T15:42:22.522578675Z,10,2,1108,A,A,0,13.79,15,130,165567,251690950,13.26,100,1,13.04,2,1,13.03,100,1,12.73,100,1,12.71,100,1,12.5,700,1,12.46,200,2,12.43,700,1,12.42,700,1,12.37,700,1,13.79,15,1,13.83,15,1,13.84,100,1,14.07,2,1,14.12,100,1,14.4,100,1,14.56,900,3,14.6,700,1,14.64,100,1,14.68,1400,2,ARL,300042293
653,2025-07-17T15:42:22.533681479Z,2025-07-17T15:42:22.533515955Z,10,2,1108,A,A,1,13.82,100,130,165524,251691033,13.26,100,1,13.04,2,1,13.03,100,1,12.73,100,1,12.71,100,1,12.5,700,1,12.46,200,2,12.43,700,1,12.42,700,1,12.37,700,1,13.79,15,1,13.82,100,1,13.83,15,1,13.84,100,1,14.07,2,1,14.12,100,1,14.4,100,1,14.56,900,3,14.6,700,1,14.64,100,1,ARL,300042385
654,2025-07-17T15:42:23.490247121Z,2025-07-17T15:42:23.490079821Z,10,2,1108,C,A,-1,13.84,100,0,167300,251710173,13.26,100,1,13.04,2,1,13.03,100,1,12.73,100,1,12.71,100,1,12.5,700,1,12.46,200,2,12.43,700,1,12.42,700,1,12.37,700,1,13.79,15,1,13.82,100,1,13.83,15,1,14.07,2,1,14.12,100,1,14.4,100,1,14.56,900,3,14.6,700,1,14.64,100,1,14.68,1400,2,ARL,299926781
655,2025-07-17T15:42:23.490247121Z,2025-07-17T15:42:23.490079821Z,10,2,1108,A,A,1,13.8,100,128,167300,251710173,13.26,100,1,13.04,2,1,13.03,100,1,12.73,100,1,12.71,100,1,12.5,700,1,12.46,200,2,12.43,700,1,12.42,700,1,12.37,700,1,13.79,15,1,13.8,100,1,13.82,100,1,13.83,15,1,14.07,2,1,14.12,100,1,14.4,100,1,14.56,900,3,14.6,700,1,14.64,100,1,ARL,300061581
656,2025-07-17T15:42:23.589065154Z,2025-07-17T15:42:23.588899941Z,10,2,1108,C,A,-1,13.79,15,130,165213,251718746,13.26,100,1,13.04,2,1,13.03,100,1,12.73,100,1,12.71,100,1,12.5,700,1,12.46,200,2,12.43,700,1,12.42,700,1,12.37,700,1,13.8,100,1,13.82,100,1,13.83,15,1,14.07,2,1,14.12,100,1,14.4,100,1,14.56,900,3,14.6,700,1,14.64,100,1,14.68,1400,2,ARL,300042293
657,2025-07-17T15:42:23.589220778Z,2025-07-17T15:42:23.589055082Z,10,2,1108,C,A,-1,13.83,15,130,165696,251718767,13.26,100,1,13.04,2,1,13.03,100,1,12.73,100,1,12.71,100,1,12.5,700,1,12.46,200,2,12.43,700,1,12.42,700,1,12.37,700,1,13.8,100,1,13.82,100,1,14.07,2,1,14.12,100,1,14.4,100,1,14.56,900,3,14.6,700,1,14.64,100,1,14.68,1400,2,14.73,100,1,ARL,299923773
658,2025-07-17T15:42:34.003710081Z,2025-07-17T15:42:34.003544527Z,10,2,1108,C,A,-1,13.8,100,130,165554,251901273,13.26,100,1,13.04,2,1,13.03,100,1,12.73,100,1,12.71,100,1,12.5,700,1,12.46,200,2,12.43,700,1,12.42,700,1,12.37,700,1,13.82,100,1,14.07,2,1,14.12,100,1,14.4,100,1,14.56,900,3,14.6,700,1,14.64,100,1,14.68,1400,2,14.73,100,1,14.76,100,1,ARL,300061581
659,2025-07-17T15:42:34.003949340Z,2025-07-17T15:42:34.003783950Z,10,2,1108,C,A,-1,13.82,100,130,165390,251901275,13.26,100,1,13.04,2,1,13.03,100,1,12.73,100,1,12.71,100,1,12.5,700,1,12.46,200,2,12.43,700,1,12.42,700,1,12.37,700,1,14.07,2,1,14.12,100,1,14.4,100,1,14.56,900,3,14.6,700,1,14.64,100,1,14.68,1400,2,14.73,100,1,14.76,100,1,14.81,200,2,ARL,300042385
660,2025-07-17T15:42:34.004225180Z,2025-07-17T15:42:34.004059450Z,10,2,1108,C,A,-1,14.73,100,0,165730,251901280,13.26,100,1,13.04,2,1,13.03,100,1,12.73,100,1,12.71,100,1,12.5,700,1,12.46,200,2,12.43,700,1,12.42,700,1,12.37,700,1,14.07,2,1,14.12,100,1,14.4,100,1,14.56,900,3,14.6,700,1,14.64,100,1,14.68,1400,2,14.76,100,1,14.81,200,2,14.87,100,1,ARL,299945073
661,2025-07-17T15:42:34.004671652Z,2025-07-17T15:42:34.004506043Z,10,2,1108,C,A,-1,14.87,100,0,165609,251901285,13.26,100,1,13.04,2,1,13.03,100,1,12.73,100,1,12.71,100,1,12.5,700,1,12.46,200,2,12.43,700,1,12.42,700,1,12.37,700,1,14.07,2,1,14.12,100,1,14.4,100,1,14.56,900,3,14.6,700,1,14.64,100,1,14.68,1400,2,14.76,100,1,14.81,200,2,14.88,100,1,ARL,300061989
662,2025-07-17T15:42:34.004677786Z,2025-07-17T15:42:34.004512153Z,10,2,1108,C,A,-1,14.76,100,0,165633,251901286,13.26,100,1,13.04,2,1,13.03,100,1,12.73,100,1,12.71,100,1,12.5,700,1,12.46,200,2,12.43,700,1,12.42,700,1,12.37,700,1,14.07,2,1,14.12,100,1,14.4,100,1,14.56,900,3,14.6,700,1,14.64,100,1,14.68,1400,2,14.81,200,2,14.88,100,1,15.06,100,1,ARL,299903169
663,2025-07-17T15:42:34.004677786Z,2025-07-17T15:42:34.004512153Z,10,2,1108,A,A,8,14.88,100,130,165633,251901286,13.26,100,1,13.04,2,1,13.03,100,1,12.73,100,1,12.71,100,1,12.5,700,1,12.46,200,2,12.43,700,1,12.42,700,1,12.37,700,1,14.07,2,1,14.12,100,1,14.4,100,1,14.56,900,3,14.6,700,1,14.64,100,1,14.68,1400,2,14.81,200,2,14.88,200,2,15.06,100,1,ARL,300280761
664,2025-07-17T15:42:34.005832926Z,2025-07-17T15:42:34.005667449Z,10,2,1108,C,A,7,14.81,100,0,165477,251901305,13.26,100,1,13.04,2,1,13.03,100,1,12.73,100,1,12.71,100,1,12.5,700,1,12.46,200,2,12.43,700,1,12.42,700,1,12.37,700,1,14.07,2,1,14.12,100,1,14.4,100,1,14.56,900,3,14.6,700,1,14.64,100,1,14.68,1400,2,14.81,100,1,14.88,200,2,15.06,100,1,ARL,299926849
665,2025-07-17T15:42:34.005832926Z,2025-07-17T15:42:34.005667449Z,10,2,1108,A,A,9,14.96,100,130,165477,251901305,13.26,100,1,13.04,2,1,13.03,100,1,12.73,100,1,12.71,100,1,12.5,700,1,12.46,200,2,12.43,700,1,12.42,700,1,12.37,700,1,14.07,2,1,14.12,100,1,14.4,100,1,14.56,900,3,14.6,700,1,14.64,100,1,14.68,1400,2,14.81,100,1,14.88,200,2,14.96,100,1,ARL,300280777
666,2025-07-17T15:42:34.007908678Z,2025-07-17T15:42:34.007743383Z,10,2,1108,C,A,-1,14.64,100,130,165295,251901330,13.26,100,1,13.04,2,1,13.03,100,1,12.73,100,1,12.71,100,1,12.5,700,1,12.46,200,2,12.43,700,1,12.42,700,1,12.37,700,1,14.07,2,1,14.12,100,1,14.4,100,1,14.56,900,3,14.6,700,1,14.68,1400,2,14.81,100,1,14.88,200,2,14.96,100,1,15.06,100,1,ARL,299926813
667,2025-07-17T15:42:34.008072663Z,2025-07-17T15:42:34.007907269Z,10,2,1108,A,A,6,14.78,100,130,165394,251901331,13.26,100,1,13.04,2,1,13.03,100,1,12.73,100,1,12.71,100,1,12.5,700,1,12.46,200,2,12.43,700,1,12.42,700,1,12.37,700,1,14.07,2,1,14.12,100,1,14.4,100,1,14.56,900,3,14.6,700,1,14.68,1400,2,14.78,100,1,14.81,100,1,14.88,200,2,14.96,100,1,ARL,300280825
668,2025-07-17T15:42:34.010196831Z,2025-07-17T15:42:34.010031518Z,10,2,1108,C,A,-1,14.12,100,130,165313,251901352,13.26,100,1,13.04,2,1,13.03,100,1,12.73,100,1,12.71,100,1,12.5,700,1,12.46,200,2,12.43,700,1,12.42,700,1,12.37,700,1,14.07,2,1,14.4,100,1,14.56,900,3,14.6,700,1,14.68,1400,2,14.78,100,1,14.81,100,1,14.88,200,2,14.96,100,1,15.06,100,1,ARL,299926965
669,2025-07-17T15:42:34.010248842Z,2025-07-17T15:42:34.010083409Z,10,2,1108,A,A,1,14.26,100,130,165433,251901353,13.26,100,1,13.04,2,1,13.03,100,1,12.73,100,1,12.71,100,1,12.5,700,1,12.46,200,2,12.43,700,1,12.42,700,1,12.37,700,1,14.07,2,1,14.26,100,1,14.4,100,1,14.56,900,3,14.6,700,1,14.68,1400,2,14.78,100,1,14.81,100,1,14.88,200,2,14.96,100,1,ARL,300280857
670,2025-07-17T15:42:34.010572370Z,2025-07-17T15:42:34.010406771Z,10,2,1108,C,A,-1,14.81,100,0,165599,251901355,13.26,100,1,13.04,2,1,13.03,100,1,12.73,100,1,12.71,100,1,12.5,700,1,12.46,200,2,12.43,700,1,12.42,700,1,12.37,700,1,14.07,2,1,14.26,100,1,14.4,100,1,14.56,900,3,14.6,700,1,14.68,1400,2,14.78,100,1,14.88,200,2,14.96,100,1,15.06,100,1,ARL,299926857
671,2025-07-17T15:42:34.010572370Z,2025-07-17T15:42:34.010406771Z,10,2,1108,A,A,8,14.96,100,130,165599,251901355,13.26,100,1,13.04,2,1,13.03,100,1,12.73,100,1,12.71,100,1,12.5,700,1,12.46,200,2,12.43,700,1,12.42,700,1,12.37,700,1,14.07,2,1,14.26,100,1,14.4,100,1,14.56,900,3,14.6,700,1,14.68,1400,2,14.78,100,1,14.88,200,2,14.96,200,2,15.06,100,1,ARL,300280873
672,2025-07-17T15:42:34.952098027Z,2025-07-17T15:42:34.951932909Z,10,2,1108,A,A,1,14.08,100,130,165118,251912292,13.26,100,1,13.04,2,1,13.03,100,1,12.73,100,1,12.71,100,1,12.5,700,1,12.46,200,2,12.43,700,1,12.42,700,1,12.37,700,1,14.07,2,1,14.08,100,1,14.26,100,1,14.4,100,1,14.56,900,3,14.6,700,1,14.68,1400,2,14.78,100,1,14.88,200,2,14.96,200,2,ARL,300294885
673,2025-07-17T15:43:21.513838949Z,2025-07-17T15:43:21.513673603Z,10,2,1108,A,A,0,13.92,15,130,165346,252622568,13.26,100,1,13.04,2,1,13.03,100,1,12.73,100,1,12.71,100,1,12.5,700,1,12.46,200,2,12.43,700,1,12.42,700,1,12.37,700,1,13.92,15,1,14.07,2,1,14.08,100,1,14.26,100,1,14.4,100,1,14.56,900,3,14.6,700,1,14.68,1400,2,14.78,100,1,14.88,200,2,ARL,301218889
674,2025-07-17T15:43:24.878236760Z,2025-07-17T15:43:24.878071152Z,10,2,1108,C,A,-1,14.08,100,0,165608,252681819,13.26,100,1,13.04,2,1,13.03,100,1,12.73,100,1,12.71,100,1,12.5,700,1,12.46,200,2,12.43,700,1,12.42,700,1,12.37,700,1,13.92,15,1,14.07,2,1,14.26,100,1,14.4,100,1,14.56,900,3,14.6,700,1,14.68,1400,2,14.78,100,1,14.88,200,2,14.96,200,2,ARL,300294885
675,2025-07-17T15:43:24.878236760Z,2025-07-17T15:43:24.878071152Z,10,2,1108,A,A,1,13.93,100,130,165608,252681819,13.26,100,1,13.04,2,1,13.03,100,1,12.73,100,1,12.71,100,1,12.5,700,1,12.46,200,2,12.43,700,1,12.42,700,1,12.37,700,1,13.92,15,1,13.93,100,1,14.07,2,1,14.26,100,1,14.4,100,1,14.56,900,3,14.6,700,1,14.68,1400,2,14.78,100,1,14.88,200,2,ARL,301295841
676,2025-07-17T15:43:32.780372412Z,2025-07-17T15:43:32.780206927Z,10,2,1108,A,A,0,13.88,15,130,165485,252800884,13.26,100,1,13.04,2,1,13.03,100,1,12.73,100,1,12.71,100,1,12.5,700,1,12.46,200,2,12.43,700,1,12.42,700,1,12.37,700,1,13.88,15,1,13.92,15,1,13.93,100,1,14.07,2,1,14.26,100,1,14.4,100,1,14.56,900,3,14.6,700,1,14.68,1400,2,14.78,100,1,ARL,301451057
677,2025-07-17T15:43:32.780639619Z,2025-07-17T15:43:32.780474141Z,10,2,1108,C,A,-1,13.93,100,0,165478,252800887,13.26,100,1,13.04,2,1,13.03,100,1,12.73,100,1,12.71,100,1,12.5,700,1,12.46,200,2,12.43,700,1,12.42,700,1,12.37,700,1,13.88,15,1,13.92,15,1,14.07,2,1,14.26,100,1,14.4,100,1,14.56,900,3,14.6,700,1,14.68,1400,2,14.78,100,1,14.88,200,2,ARL,301295841
678,2025-07-17T15:43:32.780639619Z,2025-07-17T15:43:32.780474141Z,10,2,1108,A,A,1,13.89,100,130,165478,252800887,13.26,100,1,13.04,2,1,13.03,100,1,12.73,100,1,12.71,100,1,12.5,700,1,12.46,200,2,12.43,700,1,12.42,700,1,12.37,700,1,13.88,15,1,13.89,100,1,13.92,15,1,14.07,2,1,14.26,100,1,14.4,100,1,14.56,900,3,14.6,700,1,14.68,1400,2,14.78,100,1,ARL,301451061
679,2025-07-17T15:43:32.792119698Z,2025-07-17T15:43:32.791954053Z,10,2,1108,C,A,-1,14.26,100,130,165645,252801681,13.26,100,1,13.04,2,1,13.03,100,1,12.73,100,1,12.71,100,1,12.5,700,1,12.46,200,2,12.43,700,1,12.42,700,1,12.37,700,1,13.88,15,1,13.89,100,1,13.92,15,1,14.07,2,1,14.4,100,1,14.56,900,3,14.6,700,1,14.68,1400,2,14.78,100,1,14.88,200,2,ARL,300280857
680,2025-07-17T15:43:32.792174617Z,2025-07-17T15:43:32.792008881Z,10,2,1108,A,A,4,14.17,100,130,165736,252801689,13.26,100,1,13.04,2,1,13.03,100,1,12.73,100,1,12.71,100,1,12.5,700,1,12.46,200,2,12.43,700,1,12.42,700,1,12.37,700,1,13.88,15,1,13.89,100,1,13.92,15,1,14.07,2,1,14.17,100,1,14.4,100,1,14.56,900,3,14.6,700,1,14.68,1400,2,14.78,100,1,ARL,301452785
681,2025-07-17T15:43:44.004832641Z,2025-07-17T15:43:44.004667259Z,10,2,1108,C,A,-1,13.92,15,130,165382,252977583,13.26,100,1,13.04,2,1,13.03,100,1,12.73,100,1,12.71,100,1,12.5,700,1,12.46,200,2,12.43,700,1,12.42,700,1,12.37,700,1,13.88,15,1,13.89,100,1,14.07,2,1,14.17,100,1,14.4,100,1,14.56,900,3,14.6,700,1,14.68,1400,2,14.78,100,1,14.88,200,2,ARL,301218889
682,2025-07-17T15:43:44.005191111Z,2025-07-17T15:43:44.005025587Z,10,2,1108,C,A,9,14.88,100,0,165524,252977592,13.26,100,1,13.04,2,1,13.03,100,1,12.73,100,1,12.71,100,1,12.5,700,1,12.46,200,2,12.43,700,1,12.42,700,1,12.37,700,1,13.88,15,1,13.89,100,1,14.07,2,1,14.17,100,1,14.4,100,1,14.56,900,3,14.6,700,1,14.68,1400,2,14.78,100,1,14.88,100,1,ARL,300280761
683,2025-07-17T15:43:44.005191111Z,2025-07-17T15:43:44.005025587Z,10,2,1108,A,A,8,14.77,100,130,165524,252977592,13.26,100,1,13.04,2,1,13.03,100,1,12.73,100,1,12.71,100,1,12.5,700,1,12.46,200,2,12.43,700,1,12.42,700,1,12.37,700,1,13.88,15,1,13.89,100,1,14.07,2,1,14.17,100,1,14.4,100,1,14.56,900,3,14.6,700,1,14.68,1400,2,14.77,100,1,14.78,100,1,ARL,301671709
684,2025-07-17T15:43:44.005313071Z,2025-07-17T15:43:44.005147707Z,10,2,1108,A,A,8,14.77,100,130,165364,252977595,13.26,100,1,13.04,2,1,13.03,100,1,12.73,100,1,12.71,100,1,12.5,700,1,12.46,200,2,12.43,700,1,12.42,700,1,12.37,700,1,13.88,15,1,13.89,100,1,14.07,2,1,14.17,100,1,14.4,100,1,14.56,900,3,14.6,700,1,14.68,1400,2,14.77,200,2,14.78,100,1,ARL,301671713
685,2025-07-17T15:43:48.787497664Z,2025-07-17T15:43:48.787332399Z,10,2,1108,A,A,0,13.83,15,130,165265,253027890,13.26,100,1,13.04,2,1,13.03,100,1,12.73,100,1,12.71,100,1,12.5,700,1,12.46,200,2,12.43,700,1,12.42,700,1,12.37,700,1,13.83,15,1,13.88,15,1,13.89,100,1,14.07,2,1,14.17,100,1,14.4,100,1,14.56,900,3,14.6,700,1,14.68,1400,2,14.77,200,2,ARL,301746941
686,2025-07-17T15:43:48.787766907Z,2025-07-17T15:43:48.787601640Z,10,2,1108,C,A,-1,13.89,100,0,165267,253027924,13.26,100,1,13.04,2,1,13.03,100,1,12.73,100,1,12.71,100,1,12.5,700,1,12.46,200,2,12.43,700,1,12.42,700,1,12.37,700,1,13.83,15,1,13.88,15,1,14.07,2,1,14.17,100,1,14.4,100,1,14.56,900,3,14.6,700,1,14.68,1400,2,14.77,200,2,14.78,100,1,ARL,301451061
687,2025-07-17T15:43:48.787766907Z,2025-07-17T15:43:48.787601640Z,10,2,1108,A,A,1,13.84,100,130,165267,253027924,13.26,100,1,13.04,2,1,13.03,100,1,12.73,100,1,12.71,100,1,12.5,700,1,12.46,200,2,12.43,700,1,12.42,700,1,12.37,700,1,13.83,15,1,13.84,100,1,13.88,15,1,14.07,2,1,14.17,100,1,14.4,100,1,14.56,900,3,14.6,700,1,14.68,1400,2,14.77,200,2,ARL,301746949
688,2025-07-17T15:43:48.790600546Z,2025-07-17T15:43:48.790434947Z,10,2,1108,A,A,8,14.64,100,130,165599,253028027,13.26,100,1,13.04,2,1,13.03,100,1,12.73,100,1,12.71,100,1,12.5,700,1,12.46,200,2,12.43,700,1,12.42,700,1,12.37,700,1,13.83,15,1,13.84,100,1,13.88,15,1,14.07,2,1,14.17,100,1,14.4,100,1,14.56,900,3,14.6,700,1,14.64,100,1,14.68,1400,2,ARL,301747005
689,2025-07-17T15:43:53.123817759Z,2025-07-17T15:43:53.123652480Z,10,2,1108,C,A,-1,13.88,15,130,165279,253100941,13.26,100,1,13.04,2,1,13.03,100,1,12.73,100,1,12.71,100,1,12.5,700,1,12.46,200,2,12.43,700,1,12.42,700,1,12.37,700,1,13.83,15,1,13.84,100,1,14.07,2,1,14.17,100,1,14.4,100,1,14.56,900,3,14.6,700,1,14.64,100,1,14.68,1400,2,14.77,200,2,ARL,301451057
690,2025-07-17T15:43:54.126276976Z,2025-07-17T15:43:54.126111293Z,10,2,1108,A,A,0,13.81,15,130,165683,253121467,13.26,100,1,13.04,2,1,13.03,100,1,12.73,100,1,12.71,100,1,12.5,700,1,12.46,200,2,12.43,700,1,12.42,700,1,12.37,700,1,13.81,15,1,13.83,15,1,13.84,100,1,14.07,2,1,14.17,100,1,14.4,100,1,14.56,900,3,14.6,700,1,14.64,100,1,14.68,1400,2,ARL,301867541
691,2025-07-17T15:43:54.998238933Z,2025-07-17T15:43:54.998073317Z,10,2,1108,C,A,-1,13.84,100,0,165616,253137948,13.26,100,1,13.04,2,1,13.03,100,1,12.73,100,1,12.71,100,1,12.5,700,1,12.46,200,2,12.43,700,1,12.42,700,1,12.37,700,1,13.81,15,1,13.83,15,1,14.07,2,1,14.17,100,1,14.4,100,1,14.56,900,3,14.6,700,1,14.64,100,1,14.68,1400,2,14.77,200,2,ARL,301746949
692,2025-07-17T15:43:54.998238933Z,2025-07-17T15:43:54.998073317Z,10,2,1108,A,A,1,13.82,100,130,165616,253137948,13.26,100,1,13.04,2,1,13.03,100,1,12.73,100,1,12.71,100,1,12.5,700,1,12.46,200,2,12.43,700,1,12.42,700,1,12.37,700,1,13.81,15,1,13.82,100,1,13.83,15,1,14.07,2,1,14.17,100,1,14.4,100,1,14.56,900,3,14.6,700,1,14.64,100,1,14.68,1400,2,ARL,301885353
693,2025-07-17T15:43:55.019172741Z,2025-07-17T15:43:55.019007300Z,10,2,1108,C,A,-1,14.17,100,130,165441,253138492,13.26,100,1,13.04,2,1,13.03,100,1,12.73,100,1,12.71,100,1,12.5,700,1,12.46,200,2,12.43,700,1,12.42,700,1,12.37,700,1,13.81,15,1,13.82,100,1,13.83,15,1,14.07,2,1,14.4,100,1,14.56,900,3,14.6,700,1,14.64,100,1,14.68,1400,2,14.77,200,2,ARL,301452785
694,2025-07-17T15:43:55.019225935Z,2025-07-17T15:43:55.019060515Z,10,2,1108,A,A,4,14.1,100,130,165420,253138493,13.26,100,1,13.04,2,1,13.03,100,1,12.73,100,1,12.71,100,1,12.5,700,1,12.46,200,2,12.43,700,1,12.42,700,1,12.37,700,1,13.81,15,1,13.82,100,1,13.83,15,1,14.07,2,1,14.1,100,1,14.4,100,1,14.56,900,3,14.6,700,1,14.64,100,1,14.68,1400,2,ARL,301886057
695,2025-07-17T15:44:01.698791467Z,2025-07-17T15:44:01.698626200Z,10,2,1108,C,A,-1,13.83,15,130,165267,253246317,13.26,100,1,13.04,2,1,13.03,100,1,12.73,100,1,12.71,100,1,12.5,700,1,12.46,200,2,12.43,700,1,12.42,700,1,12.37,700,1,13.81,15,1,13.82,100,1,14.07,2,1,14.1,100,1,14.4,100,1,14.56,900,3,14.6,700,1,14.64,100,1,14.68,1400,2,14.77,200,2,ARL,301746941
696,2025-07-17T15:44:04.014878156Z,2025-07-17T15:44:04.014712730Z,10,2,1108,A,A,2,13.83,100,130,165426,253292355,13.26,100,1,13.04,2,1,13.03,100,1,12.73,100,1,12.71,100,1,12.5,700,1,12.46,200,2,12.43,700,1,12.42,700,1,12.37,700,1,13.81,15,1,13.82,100,1,13.83,100,1,14.07,2,1,14.1,100,1,14.4,100,1,14.56,900,3,14.6,700,1,14.64,100,1,14.68,1400,2,ARL,302078553
697,2025-07-17T15:44:05.055626948Z,2025-07-17T15:44:05.055461574Z,10,2,1108,A,A,0,13.81,100,130,165374,253307083,13.26,100,1,13.04,2,1,13.03,100,1,12.73,100,1,12.71,100,1,12.5,700,1,12.46,200,2,12.43,700,1,12.42,700,1,12.37,700,1,13.81,115,2,13.82,100,1,13.83,100,1,14.07,2,1,14.1,100,1,14.4,100,1,14.56,900,3,14.6,700,1,14.64,100,1,14.68,1400,2,ARL,302100649
698,2025-07-17T15:44:05.062431949Z,2025-07-17T15:44:05.062266845Z,10,2,1108,C,A,-1,13.83,100,130,165104,253307147,13.26,100,1,13.04,2,1,13.03,100,1,12.73,100,1,12.71,100,1,12.5,700,1,12.46,200,2,12.43,700,1,12.42,700,1,12.37,700,1,13.81,115,2,13.82,100,1,14.07,2,1,14.1,100,1,14.4,100,1,14.56,900,3,14.6,700,1,14.64,100,1,14.68,1400,2,14.77,200,2,ARL,302078553
699,2025-07-17T15:44:09.389713730Z,2025-07-17T15:44:09.389548394Z,10,2,1108,A,A,0,13.76,15,130,165336,253384422,13.26,100,1,13.04,2,1,13.03,100,1,12.73,100,1,12.71,100,1,12.5,700,1,12.46,200,2,12.43,700,1,12.42,700,1,12.37,700,1,13.76,15,1,13.81,115,2,13.82,100,1,14.07,2,1,14.1,100,1,14.4,100,1,14.56,900,3,14.6,700,1,14.64,100,1,14.68,1400,2,ARL,302205249
700,2025-07-17T15:44:09.390496140Z,2025-07-17T15:44:09.390329935Z,10,2,1108,A,A,9,14.66,100,128,166205,253384438,13.26,100,1,13.04,2,1,13.03,100,1,12.73,100,1,12.71,100,1,12.5,700,1,12.46,200,2,12.43,700,1,12.42,700,1,12.37,700,1,13.76,15,1,13.81,115,2,13.82,100,1,14.07,2,1,14.1,100,1,14.4,100,1,14.56,900,3,14.6,700,1,14.64,100,1,14.66,100,1,ARL,302205289
701,2025-07-17T15:44:09.391058486Z,2025-07-17T15:44:09.390893172Z,10,2,1108,A,A,9,14.66,100,130,165314,253384456,13.26,100,1,13.04,2,1,13.03,100,1,12.73,100,1,12.71,100,1,12.5,700,1,12.46,200,2,12.43,700,1,12.42,700,1,12.37,700,1,13.76,15,1,13.81,115,2,13.82,100,1,14.07,2,1,14.1,100,1,14.4,100,1,14.56,900,3,14.6,700,1,14.64,100,1,14.66,200,2,ARL,302205309
702,2025-07-17T15:44:09.395447612Z,2025-07-17T15:44:09.395281780Z,10,2,1108,C,A,-1,13.82,100,0,165832,253384698,13.26,100,1,13.04,2,1,13.03,100,1,12.73,100,1,12.71,100,1,12.5,700,1,12.46,200,2,12.43,700,1,12.42,700,1,12.37,700,1,13.76,15,1,13.81,115,2,14.07,2,1,14.1,100,1,14.4,100,1,14.56,900,3,14.6,700,1,14.64,100,1,14.66,200,2,14.68,1400,2,ARL,301885353
703,2025-07-17T15:44:09.395447612Z,2025-07-17T15:44:09.395281780Z,10,2,1108,A,A,1,13.77,100,130,165832,253384698,13.26,100,1,13.04,2,1,13.03,100,1,12.73,100,1,12.71,100,1,12.5,700,1,12.46,200,2,12.43,700,1,12.42,700,1,12.37,700,1,13.76,15,1,13.77,100,1,13.81,115,2,14.07,2,1,14.1,100,1,14.4,100,1,14.56,900,3,14.6,700,1,14.64,100,1,14.66,200,2,ARL,302205493
704,2025-07-17T15:44:09.398011186Z,2025-07-17T15:44:09.397845986Z,10,2,1108,A,A,2,13.79,100,130,165200,253384788,13.26,100,1,13.04,2,1,13.03,100,1,12.73,100,1,12.71,100,1,12.5,700,1,12.46,200,2,12.43,700,1,12.42,700,1,12.37,700,1,13.76,15,1,13.77,100,1,13.79,100,1,13.81,115,2,14.07,2,1,14.1,100,1,14.4,100,1,14.56,900,3,14.6,700,1,14.64,100,1,ARL,302205561
705,2025-07-17T15:44:09.404828956Z,2025-07-17T15:44:09.404663816Z,10,2,1108,C,A,3,13.81,100,130,165140,253385013,13.26,100,1,13.04,2,1,13.03,100,1,12.73,100,1,12.71,100,1,12.5,700,1,12.46,200,2,12.43,700,1,12.42,700,1,12.37,700,1,13.76,15,1,13.77,100,1,13.79,100,1,13.81,15,1,14.07,2,1,14.1,100,1,14.4,100,1,14.56,900,3,14.6,700,1,14.64,100,1,ARL,302100649
706,2025-07-17T15:44:20.402535831Z,2025-07-17T15:44:20.402370565Z,10,2,1108,C,A,-1,13.81,15,130,165266,253562230,13.26,100,1,13.04,2,1,13.03,100,1,12.73,100,1,12.71,100,1,12.5,700,1,12.46,200,2,12.43,700,1,12.42,700,1,12.37,700,1,13.76,15,1,13.77,100,1,13.79,100,1,14.07,2,1,14.1,100,1,14.4,100,1,14.56,900,3,14.6,700,1,14.64,100,1,14.66,200,2,ARL,301867541
707,2025-07-17T15:44:21.405486122Z,2025-07-17T15:44:21.405320730Z,10,2,1108,A,A,0,13.74,15,130,165392,253582427,13.26,100,1,13.04,2,1,13.03,100,1,12.73,100,1,12.71,100,1,12.5,700,1,12.46,200,2,12.43,700,1,12.42,700,1,12.37,700,1,13.74,15,1,13.76,15,1,13.77,100,1,13.79,100,1,14.07,2,1,14.1,100,1,14.4,100,1,14.56,900,3,14.6,700,1,14.64,100,1,ARL,302458113
708,2025-07-17T15:44:21.843235911Z,2025-07-17T15:44:21.843070079Z,10,2,1108,C,A,-1,13.77,100,0,165832,253590641,13.26,100,1,13.04,2,1,13.03,100,1,12.73,100,1,12.71,100,1,12.5,700,1,12.46,200,2,12.43,700,1,12.42,700,1,12.37,700,1,13.74,15,1,13.76,15,1,13.79,100,1,14.07,2,1,14.1,100,1,14.4,100,1,14.56,900,3,14.6,700,1,14.64,100,1,14.66,200,2,ARL,302205493
709,2025-07-17T15:44:21.843235911Z,2025-07-17T15:44:21.843070079Z,10,2,1108,A,A,1,13.75,100,130,165832,253590641,13.26,100,1,13.04,2,1,13.03,100,1,12.73,100,1,12.71,100,1,12.5,700,1,12.46,200,2,12.43,700,1,12.42,700,1,12.37,700,1,13.74,15,1,13.75,100,1,13.76,15,1,13.79,100,1,14.07,2,1,14.1,100,1,14.4,100,1,14.56,900,3,14.6,700,1,14.64,100,1,ARL,302466045
710,2025-07-17T15:44:21.855416093Z,2025-07-17T15:44:21.855250804Z,10,2,1108,C,A,-1,14.1,100,130,165289,253590837,13.26,100,1,13.04,2,1,13.03,100,1,12.73,100,1,12.71,100,1,12.5,700,1,12.46,200,2,12.43,700,1,12.42,700,1,12.37,700,1,13.74,15,1,13.75,100,1,13.76,15,1,13.79,100,1,14.07,2,1,14.4,100,1,14.56,900,3,14.6,700,1,14.64,100,1,14.66,200,2,ARL,301886057
711,2025-07-17T15:44:21.855471158Z,2025-07-17T15:44:21.855305995Z,10,2,1108,A,A,4,14.03,100,130,165163,253590838,13.26,100,1,13.04,2,1,13.03,100,1,12.73,100,1,12.71,100,1,12.5,700,1,12.46,200,2,12.43,700,1,12.42,700,1,12.37,700,1,13.74,15,1,13.75,100,1,13.76,15,1,13.79,100,1,14.03,100,1,14.07,2,1,14.4,100,1,14.56,900,3,14.6,700,1,14.64,100,1,ARL,302466157
712,2025-07-17T15:44:24.447075532Z,2025-07-17T15:44:24.446910206Z,10,2,1108,A,A,3,13.77,100,130,165326,253614407,13.26,100,1,13.04,2,1,13.03,100,1,12.73,100,1,12.71,100,1,12.5,700,1,12.46,200,2,12.43,700,1,12.42,700,1,12.37,700,1,13.74,15,1,13.75,100,1,13.76,15,1,13.77,100,1,13.79,100,1,14.03,100,1,14.07,2,1,14.4,100,1,14.56,900,3,14.6,700,1,ARL,302500469
713,2025-07-17T15:44:24.465555818Z,2025-07-17T15:44:24.465390625Z,10,2,1108,C,A,-1,13.79,100,130,165193,253614591,13.26,100,1,13.04,2,1,13.03,100,1,12.73,100,1,12.71,100,1,12.5,700,1,12.46,200,2,12.43,700,1,12.42,700,1,12.37,700,1,13.74,15,1,13.75,100,1,13.76,15,1,13.77,100,1,14.03,100,1,14.07,2,1,14.4,100,1,14.56,900,3,14.6,700,1,14.64,100,1,ARL,302205561
714,2025-07-17T15:44:30.846822983Z,2025-07-17T15:44:30.846657613Z,10,2,1108,C,A,-1,13.76,15,130,165370,253704439,13.26,100,1,13.04,2,1,13.03,100,1,12.73,100,1,12.71,100,1,12.5,700,1,12.46,200,2,12.43,700,1,12.42,700,1,12.37,700,1,13.74,15,1,13.75,100,1,13.77,100,1,14.03,100,1,14.07,2,1,14.4,100,1,14.56,900,3,14.6,700,1,14.64,100,1,14.66,200,2,ARL,302205249
715,2025-07-17T15:44:31.849784693Z,2025-07-17T15:44:31.849618640Z,10,2,1108,A,A,0,13.72,15,130,166053,253721156,13.26,100,1,13.04,2,1,13.03,100,1,12.73,100,1,12.71,100,1,12.5,700,1,12.46,200,2,12.43,700,1,12.42,700,1,12.37,700,1,13.72,15,1,13.74,15,1,13.75,100,1,13.77,100,1,14.03,100,1,14.07,2,1,14.4,100,1,14.56,900,3,14.6,700,1,14.64,100,1,ARL,302649021
716,2025-07-17T15:44:31.849921857Z,2025-07-17T15:44:31.849756452Z,10,2,1108,A,A,2,13.75,100,130,165405,253721157,13.26,100,1,13.04,2,1,13.03,100,1,12.73,100,1,12.71,100,1,12.5,700,1,12.46,200,2,12.43,700,1,12.42,700,1,12.37,700,1,13.72,15,1,13.74,15,1,13.75,200,2,13.77,100,1,14.03,100,1,14.07,2,1,14.4,100,1,14.56,900,3,14.6,700,1,14.64,100,1,ARL,302649029
717,2025-07-17T15:44:31.910124978Z,2025-07-17T15:44:31.909959614Z,10,2,1108,C,A,-1,13.77,100,130,165364,253722140,13.26,100,1,13.04,2,1,13.03,100,1,12.73,100,1,12.71,100,1,12.5,700,1,12.46,200,2,12.43,700,1,12.42,700,1,12.37,700,1,13.72,15,1,13.74,15,1,13.75,200,2,14.03,100,1,14.07,2,1,14.4,100,1,14.56,900,3,14.6,700,1,14.64,100,1,14.66,200,2,ARL,302500469
718,2025-07-17T15:44:32.484497230Z,2025-07-17T15:44:32.484331764Z,10,2,1108,C,A,2,13.75,100,0,165466,253730877,13.26,100,1,13.04,2,1,13.03,100,1,12.73,100,1,12.71,100,1,12.5,700,1,12.46,200,2,12.43,700,1,12.42,700,1,12.37,700,1,13.72,15,1,13.74,15,1,13.75,100,1,14.03,100,1,14.07,2,1,14.4,100,1,14.56,900,3,14.6,700,1,14.64,100,1,14.66,200,2,ARL,302466045
719,2025-07-17T15:44:32.484497230Z,2025-07-17T15:44:32.484331764Z,10,2,1108,A,A,1,13.73,100,130,165466,253730877,13.26,100,1,13.04,2,1,13.03,100,1,12.73,100,1,12.71,100,1,12.5,700,1,12.46,200,2,12.43,700,1,12.42,700,1,12.37,700,1,13.72,15,1,13.73,100,1,13.74,15,1,13.75,100,1,14.03,100,1,14.07,2,1,14.4,100,1,14.56,900,3,14.6,700,1,14.64,100,1,ARL,302662769
720,2025-07-17T15:44:33.389387814Z,2025-07-17T15:44:33.389222513Z,10,2,1108,A,A,6,14.28,100,130,165301,253745665,13.26,100,1,13.04,2,1,13.03,100,1,12.73,100,1,12.71,100,1,12.5,700,1,12.46,200,2,12.43,700,1,12.42,700,1,12.37,700,1,13.72,15,1,13.73,100,1,13.74,15,1,13.75,100,1,14.03,100,1,14.07,2,1,14.28,100,1,14.4,100,1,14.56,900,3,14.6,700,1,ARL,302681357
721,2025-07-17T15:44:33.389389030Z,2025-07-17T15:44:33.389223581Z,10,2,1108,C,A,8,14.56,100,130,165449,253745666,13.26,100,1,13.04,2,1,13.03,100,1,12.73,100,1,12.71,100,1,12.5,700,1,12.46,200,2,12.43,700,1,12.42,700,1,12.37,700,1,13.72,15,1,13.73,100,1,13.74,15,1,13.75,100,1,14.03,100,1,14.07,2,1,14.28,100,1,14.4,100,1,14.56,800,2,14.6,700,1,ARL,146960005
722,2025-07-17T15:44:36.362187673Z,2025-07-17T15:44:36.362022168Z,10,2,1108,C,A,-1,13.74,15,130,165505,253783635,13.26,100,1,13.04,2,1,13.03,100,1,12.73,100,1,12.71,100,1,12.5,700,1,12.46,200,2,12.43,700,1,12.42,700,1,12.37,700,1,13.72,15,1,13.73,100,1,13.75,100,1,14.03,100,1,14.07,2,1,14.28,100,1,14.4,100,1,14.56,800,2,14.6,700,1,14.64,100,1,ARL,302458113
723,2025-07-17T15:44:37.364377419Z,2025-07-17T15:44:37.364212109Z,10,2,1108,A,A,0,13.7,15,130,165310,253797506,13.26,100,1,13.04,2,1,13.03,100,1,12.73,100,1,12.71,100,1,12.5,700,1,12.46,200,2,12.43,700,1,12.42,700,1,12.37,700,1,13.7,15,1,13.72,15,1,13.73,100,1,13.75,100,1,14.03,100,1,14.07,2,1,14.28,100,1,14.4,100,1,14.56,800,2,14.6,700,1,ARL,302750929
724,2025-07-17T15:44:37.364519067Z,2025-07-17T15:44:37.364353897Z,10,2,1108,A,A,2,13.73,100,130,165170,253797510,13.26,100,1,13.04,2,1,13.03,100,1,12.73,100,1,12.71,100,1,12.5,700,1,12.46,200,2,12.43,700,1,12.42,700,1,12.37,700,1,13.7,15,1,13.72,15,1,13.73,200,2,13.75,100,1,14.03,100,1,14.07,2,1,14.28,100,1,14.4,100,1,14.56,800,2,14.6,700,1,ARL,302750937
725,2025-07-17T15:44:37.458119494Z,2025-07-17T15:44:37.457954350Z,10,2,1108,C,A,-1,13.75,100,130,165144,253798432,13.26,100,1,13.04,2,1,13.03,100,1,12.73,100,1,12.71,100,1,12.5,700,1,12.46,200,2,12.43,700,1,12.42,700,1,12.37,700,1,13.7,15,1,13.72,15,1,13.73,200,2,14.03,100,1,14.07,2,1,14.28,100,1,14.4,100,1,14.56,800,2,14.6,700,1,14.64,100,1,ARL,302649029
726,2025-07-17T15:44:38.432460509Z,2025-07-17T15:44:38.432294362Z,10,2,1108,C,A,2,13.73,100,0,166147,253807786,13.26,100,1,13.04,2,1,13.03,100,1,12.73,100,1,12.71,100,1,12.5,700,1,12.46,200,2,12.43,700,1,12.42,700,1,12.37,700,1,13.7,15,1,13.72,15,1,13.73,100,1,14.03,100,1,14.07,2,1,14.28,100,1,14.4,100,1,14.56,800,2,14.6,700,1,14.64,100,1,ARL,302662769
727,2025-07-17T15:44:38.432460509Z,2025-07-17T15:44:38.432294362Z,10,2,1108,A,A,1,13.71,100,130,166147,253807786,13.26,100,1,13.04,2,1,13.03,100,1,12.73,100,1,12.71,100,1,12.5,700,1,12.46,200,2,12.43,700,1,12.42,700,1,12.37,700,1,13.7,15,1,13.71,100,1,13.72,15,1,13.73,100,1,14.03,100,1,14.07,2,1,14.28,100,1,14.4,100,1,14.56,800,2,14.6,700,1,ARL,302763889
728,2025-07-17T15:44:43.019262217Z,2025-07-17T15:44:43.019083502Z,10,2,1108,C,A,-1,13.7,15,128,178715,253875920,13.26,100,1,13.04,2,1,13.03,100,1,12.73,100,1,12.71,100,1,12.5,700,1,12.46,200,2,12.43,700,1,12.42,700,1,12.37,700,1,13.71,100,1,13.72,15,1,13.73,100,1,14.03,100,1,14.07,2,1,14.28,100,1,14.4,100,1,14.56,800,2,14.6,700,1,14.64,100,1,ARL,302750929
729,2025-07-17T15:44:43.019352658Z,2025-07-17T15:44:43.019184132Z,10,2,1108,C,A,-1,13.72,15,128,168526,253876010,13.26,100,1,13.04,2,1,13.03,100,1,12.73,100,1,12.71,100,1,12.5,700,1,12.46,200,2,12.43,700,1,12.42,700,1,12.37,700,1,13.71,100,1,13.73,100,1,14.03,100,1,14.07,2,1,14.28,100,1,14.4,100,1,14.56,800,2,14.6,700,1,14.64,100,1,14.66,200,2,ARL,302649021
730,2025-07-17T15:44:44.076009999Z,2025-07-17T15:44:44.075843113Z,10,2,1108,A,A,0,13.7,15,128,166886,253892869,13.26,100,1,13.04,2,1,13.03,100,1,12.73,100,1,12.71,100,1,12.5,700,1,12.46,200,2,12.43,700,1,12.42,700,1,12.37,700,1,13.7,15,1,13.71,100,1,13.73,100,1,14.03,100,1,14.07,2,1,14.28,100,1,14.4,100,1,14.56,800,2,14.6,700,1,14.64,100,1,ARL,302867209
731,2025-07-17T15:44:44.781630732Z,2025-07-17T15:44:44.781464821Z,10,2,1108,C,A,-1,13.7,15,130,165911,253901222,13.26,100,1,13.04,2,1,13.03,100,1,12.73,100,1,12.71,100,1,12.5,700,1,12.46,200,2,12.43,700,1,12.42,700,1,12.37,700,1,13.71,100,1,13.73,100,1,14.03,100,1,14.07,2,1,14.28,100,1,14.4,100,1,14.56,800,2,14.6,700,1,14.64,100,1,14.66,200,2,ARL,302867209
732,2025-07-17T15:44:53.143249270Z,2025-07-17T15:44:53.143083969Z,10,2,1108,C,A,-1,13.73,100,130,165301,254011871,13.26,100,1,13.04,2,1,13.03,100,1,12.73,100,1,12.71,100,1,12.5,700,1,12.46,200,2,12.43,700,1,12.42,700,1,12.37,700,1,13.71,100,1,14.03,100,1,14.07,2,1,14.28,100,1,14.4,100,1,14.56,800,2,14.6,700,1,14.64,100,1,14.66,200,2,14.68,1400,2,ARL,302750937
733,2025-07-17T15:44:57.191188470Z,2025-07-17T15:44:57.191023026Z,10,2,1108,A,A,1,13.75,100,130,165444,254079162,13.26,100,1,13.04,2,1,13.03,100,1,12.73,100,1,12.71,100,1,12.5,700,1,12.46,200,2,12.43,700,1,12.42,700,1,12.37,700,1,13.71,100,1,13.75,100,1,14.03,100,1,14.07,2,1,14.28,100,1,14.4,100,1,14.56,800,2,14.6,700,1,14.64,100,1,14.66,200,2,ARL,303118785
734,2025-07-17T15:45:07.065756574Z,2025-07-17T15:45:07.065587919Z,10,2,1108,C,A,-1,13.71,100,128,168655,254244597,13.26,100,1,13.04,2,1,13.03,100,1,12.73,100,1,12.71,100,1,12.5,700,1,12.46,200,2,12.43,700,1,12.42,700,1,12.37,700,1,13.75,100,1,14.03,100,1,14.07,2,1,14.28,100,1,14.4,100,1,14.56,800,2,14.6,700,1,14.64,100,1,14.66,200,2,14.68,1400,2,ARL,302763889
735,2025-07-17T15:45:07.080131505Z,2025-07-17T15:45:07.079966224Z,10,2,1108,C,A,-1,13.75,100,130,165281,254245492,13.26,100,1,13.04,2,1,13.03,100,1,12.73,100,1,12.71,100,1,12.5,700,1,12.46,200,2,12.43,700,1,12.42,700,1,12.37,700,1,14.03,100,1,14.07,2,1,14.28,100,1,14.4,100,1,14.56,800,2,14.6,700,1,14.64,100,1,14.66,200,2,14.68,1400,2,14.79,100,1,ARL,303118785
736,2025-07-17T15:45:07.080687215Z,2025-07-17T15:45:07.080521807Z,10,2,1108,C,A,7,14.66,100,0,165408,254245505,13.26,100,1,13.04,2,1,13.03,100,1,12.73,100,1,12.71,100,1,12.5,700,1,12.46,200,2,12.43,700,1,12.42,700,1,12.37,700,1,14.03,100,1,14.07,2,1,14.28,100,1,14.4,100,1,14.56,800,2,14.6,700,1,14.64,100,1,14.66,100,1,14.68,1400,2,14.79,100,1,ARL,302205289
737,2025-07-17T15:45:07.080872245Z,2025-07-17T15:45:07.080706110Z,10,2,1108,C,A,-1,14.79,100,0,166135,254245511,13.26,100,1,13.04,2,1,13.03,100,1,12.73,100,1,12.71,100,1,12.5,700,1,12.46,200,2,12.43,700,1,12.42,700,1,12.37,700,1,14.03,100,1,14.07,2,1,14.28,100,1,14.4,100,1,14.56,800,2,14.6,700,1,14.64,100,1,14.66,100,1,14.68,1400,2,14.81,200,2,ARL,302662821
738,2025-07-17T15:45:07.081578064Z,2025-07-17T15:45:07.081407507Z,10,2,1108,C,A,9,14.81,100,0,170557,254245568,13.26,100,1,13.04,2,1,13.03,100,1,12.73,100,1,12.71,100,1,12.5,700,1,12.46,200,2,12.43,700,1,12.42,700,1,12.37,700,1,14.03,100,1,14.07,2,1,14.28,100,1,14.4,100,1,14.56,800,2,14.6,700,1,14.64,100,1,14.66,100,1,14.68,1400,2,14.81,100,1,ARL,301747001
739,2025-07-17T15:45:07.081607970Z,2025-07-17T15:45:07.081441134Z,10,2,1108,C,A,-1,14.66,100,0,166836,254245576,13.26,100,1,13.04,2,1,13.03,100,1,12.73,100,1,12.71,100,1,12.5,700,1,12.46,200,2,12.43,700,1,12.42,700,1,12.37,700,1,14.03,100,1,14.07,2,1,14.28,100,1,14.4,100,1,14.56,800,2,14.6,700,1,14.64,100,1,14.68,1400,2,14.81,100,1,14.89,100,1,ARL,302205309
740,2025-07-17T15:45:07.081607970Z,2025-07-17T15:45:07.081441134Z,10,2,1108,A,A,9,14.89,100,130,166836,254245576,13.26,100,1,13.04,2,1,13.03,100,1,12.73,100,1,12.71,100,1,12.5,700,1,12.46,200,2,12.43,700,1,12.42,700,1,12.37,700,1,14.03,100,1,14.07,2,1,14.28,100,1,14.4,100,1,14.56,800,2,14.6,700,1,14.64,100,1,14.68,1400,2,14.81,100,1,14.89,200,2,ARL,303330521
741,2025-07-17T15:45:07.085222525Z,2025-07-17T15:45:07.085057258Z,10,2,1108,C,A,-1,14.03,100,130,165267,254246434,13.26,100,1,13.04,2,1,13.03,100,1,12.73,100,1,12.71,100,1,12.5,700,1,12.46,200,2,12.43,700,1,12.42,700,1,12.37,700,1,14.07,2,1,14.28,100,1,14.4,100,1,14.56,800,2,14.6,700,1,14.64,100,1,14.68,1400,2,14.81,100,1,14.89,200,2,14.96,100,1,ARL,302466157
742,2025-07-17T15:45:07.085274852Z,2025-07-17T15:45:07.085109545Z,10,2,1108,A,A,1,14.26,100,130,165307,254246437,13.26,100,1,13.04,2,1,13.03,100,1,12.73,100,1,12.71,100,1,12.5,700,1,12.46,200,2,12.43,700,1,12.42,700,1,12.37,700,1,14.07,2,1,14.26,100,1,14.28,100,1,14.4,100,1,14.56,800,2,14.6,700,1,14.64,100,1,14.68,1400,2,14.81,100,1,14.89,200,2,ARL,303331401
743,2025-07-17T15:45:07.086534700Z,2025-07-17T15:45:07.086368957Z,10,2,1108,C,A,-1,14.64,100,130,165743,254246501,13.26,100,1,13.04,2,1,13.03,100,1,12.73,100,1,12.71,100,1,12.5,700,1,12.46,200,2,12.43,700,1,12.42,700,1,12.37,700,1,14.07,2,1,14.26,100,1,14.28,100,1,14.4,100,1,14.56,800,2,14.6,700,1,14.68,1400,2,14.81,100,1,14.89,200,2,14.96,100,1,ARL,301747005
744,2025-07-17T15:45:07.086660325Z,2025-07-17T15:45:07.086494745Z,10,2,1108,A,A,7,14.78,100,130,165580,254246502,13.26,100,1,13.04,2,1,13.03,100,1,12.73,100,1,12.71,100,1,12.5,700,1,12.46,200,2,12.43,700,1,12.42,700,1,12.37,700,1,14.07,2,1,14.26,100,1,14.28,100,1,14.4,100,1,14.56,800,2,14.6,700,1,14.68,1400,2,14.78,100,1,14.81,100,1,14.89,200,2,ARL,303331425
745,2025-07-17T15:45:07.133978488Z,2025-07-17T15:45:07.133812895Z,10,2,1108,C,A,-1,14.81,100,0,165593,254250625,13.26,100,1,13.04,2,1,13.03,100,1,12.73,100,1,12.71,100,1,12.5,700,1,12.46,200,2,12.43,700,1,12.42,700,1,12.37,700,1,14.07,2,1,14.26,100,1,14.28,100,1,14.4,100,1,14.56,800,2,14.6,700,1,14.68,1400,2,14.78,100,1,14.89,200,2,14.96,100,1,ARL,301747957
746,2025-07-17T15:45:07.133978488Z,2025-07-17T15:45:07.133812895Z,10,2,1108,A,A,9,14.96,100,130,165593,254250625,13.26,100,1,13.04,2,1,13.03,100,1,12.73,100,1,12.71,100,1,12.5,700,1,12.46,200,2,12.43,700,1,12.42,700,1,12.37,700,1,14.07,2,1,14.26,100,1,14.28,100,1,14.4,100,1,14.56,800,2,14.6,700,1,14.68,1400,2,14.78,100,1,14.89,200,2,14.96,200,2,ARL,303334253
747,2025-07-17T15:45:07.469961302Z,2025-07-17T15:45:07.469796155Z,10,2,1108,A,A,1,14.08,100,130,165147,254258029,13.26,100,1,13.04,2,1,13.03,100,1,12.73,100,1,12.71,100,1,12.5,700,1,12.46,200,2,12.43,700,1,12.42,700,1,12.37,700,1,14.07,2,1,14.08,100,1,14.26,100,1,14.28,100,1,14.4,100,1,14.56,800,2,14.6,700,1,14.68,1400,2,14.78,100,1,14.89,200,2,ARL,303340405
748,2025-07-17T15:45:08.094768552Z,2025-07-17T15:45:08.094603115Z,10,2,1108,C,A,9,14.89,100,0,165437,254266885,13.26,100,1,13.04,2,1,13.03,100,1,12.73,100,1,12.71,100,1,12.5,700,1,12.46,200,2,12.43,700,1,12.42,700,1,12.37,700,1,14.07,2,1,14.08,100,1,14.26,100,1,14.28,100,1,14.4,100,1,14.56,800,2,14.6,700,1,14.68,1400,2,14.78,100,1,14.89,100,1,ARL,303330521
749,2025-07-17T15:45:08.103306644Z,2025-07-17T15:45:08.103141155Z,10,2,1108,C,A,-1,14.89,100,0,165489,254266971,13.26,100,1,13.04,2,1,13.03,100,1,12.73,100,1,12.71,100,1,12.5,700,1,12.46,200,2,12.43,700,1,12.42,700,1,12.37,700,1,14.07,2,1,14.08,100,1,14.26,100,1,14.28,100,1,14.4,100,1,14.56,800,2,14.6,700,1,14.68,1400,2,14.78,100,1,14.96,200,2,ARL,303330477
750,2025-07-17T15:45:24.187008278Z,2025-07-17T15:45:24.186842413Z,10,2,1108,A,A,9,14.88,100,130,165865,254547413,13.26,100,1,13.04,2,1,13.03,100,1,12.73,100,1,12.71,100,1,12.5,700,1,12.46,200,2,12.43,700,1,12.42,700,1,12.37,700,1,14.07,2,1,14.08,100,1,14.26,100,1,14.28,100,1,14.4,100,1,14.56,800,2,14.6,700,1,14.68,1400,2,14.78,100,1,14.88,100,1,ARL,303682385
751,2025-07-17T15:45:24.187441892Z,2025-07-17T15:45:24.187276389Z,10,2,1108,A,A,9,14.88,100,130,165503,254547415,13.26,100,1,13.04,2,1,13.03,100,1,12.73,100,1,12.71,100,1,12.5,700,1,12.46,200,2,12.43,700,1,12.42,700,1,12.37,700,1,14.07,2,1,14.08,100,1,14.26,100,1,14.28,100,1,14.4,100,1,14.56,800,2,14.6,700,1,14.68,1400,2,14.78,100,1,14.88,200,2,ARL,303682389
752,2025-07-17T15:45:37.509454888Z,2025-07-17T15:45:37.509289536Z,10,2,1108,A,A,0,13.94,15,130,165352,254851462,13.26,100,1,13.04,2,1,13.03,100,1,12.73,100,1,12.71,100,1,12.5,700,1,12.46,200,2,12.43,700,1,12.42,700,1,12.37,700,1,13.94,15,1,14.07,2,1,14.08,100,1,14.26,100,1,14.28,100,1,14.4,100,1,14.56,800,2,14.6,700,1,14.68,1400,2,14.78,100,1,ARL,304056997
753,2025-07-17T15:45:37.998133497Z,2025-07-17T15:45:37.997967775Z,10,2,1108,C,A,-1,14.08,100,0,165722,254864588,13.26,100,1,13.04,2,1,13.03,100,1,12.73,100,1,12.71,100,1,12.5,700,1,12.46,200,2,12.43,700,1,12.42,700,1,12.37,700,1,13.94,15,1,14.07,2,1,14.26,100,1,14.28,100,1,14.4,100,1,14.56,800,2,14.6,700,1,14.68,1400,2,14.78,100,1,14.88,200,2,ARL,303340405
754,2025-07-17T15:45:37.998133497Z,2025-07-17T15:45:37.997967775Z,10,2,1108,A,A,1,13.95,100,130,165722,254864588,13.26,100,1,13.04,2,1,13.03,100,1,12.73,100,1,12.71,100,1,12.5,700,1,12.46,200,2,12.43,700,1,12.42,700,1,12.37,700,1,13.94,15,1,13.95,100,1,14.07,2,1,14.26,100,1,14.28,100,1,14.4,100,1,14.56,800,2,14.6,700,1,14.68,1400,2,14.78,100,1,ARL,304072245
755,2025-07-17T15:45:44.700593408Z,2025-07-17T15:45:44.700428155Z,10,2,1108,A,A,0,13.89,15,130,165253,254999429,13.26,100,1,13.04,2,1,13.03,100,1,12.73,100,1,12.71,100,1,12.5,700,1,12.46,200,2,12.43,700,1,12.42,700,1,12.37,700,1,13.89,15,1,13.94,15,1,13.95,100,1,14.07,2,1,14.26,100,1,14.28,100,1,14.4,100,1,14.56,800,2,14.6,700,1,14.68,1400,2,ARL,304238913
756,2025-07-17T15:45:45.262537122Z,2025-07-17T15:45:45.262371701Z,10,2,1108,C,A,-1,13.95,100,0,165421,255010979,13.26,100,1,13.04,2,1,13.03,100,1,12.73,100,1,12.71,100,1,12.5,700,1,12.46,200,2,12.43,700,1,12.42,700,1,12.37,700,1,13.89,15,1,13.94,15,1,14.07,2,1,14.26,100,1,14.28,100,1,14.4,100,1,14.56,800,2,14.6,700,1,14.68,1400,2,14.78,100,1,ARL,304072245
757,2025-07-17T15:45:45.262537122Z,2025-07-17T15:45:45.262371701Z,10,2,1108,A,A,1,13.9,100,130,165421,255010979,13.26,100,1,13.04,2,1,13.03,100,1,12.73,100,1,12.71,100,1,12.5,700,1,12.46,200,2,12.43,700,1,12.42,700,1,12.37,700,1,13.89,15,1,13.9,100,1,13.94,15,1,14.07,2,1,14.26,100,1,14.28,100,1,14.4,100,1,14.56,800,2,14.6,700,1,14.68,1400,2,ARL,304252313
758,2025-07-17T15:45:45.274360382Z,2025-07-17T15:45:45.274194870Z,10,2,1108,C,A,-1,14.26,100,130,165512,255011158,13.26,100,1,13.04,2,1,13.03,100,1,12.73,100,1,12.71,100,1,12.5,700,1,12.46,200,2,12.43,700,1,12.42,700,1,12.37,700,1,13.89,15,1,13.9,100,1,13.94,15,1,14.07,2,1,14.28,100,1,14.4,100,1,14.56,800,2,14.6,700,1,14.68,1400,2,14.78,100,1,ARL,303331401
759,2025-07-17T15:45:45.274410721Z,2025-07-17T15:45:45.274245387Z,10,2,1108,A,A,4,14.18,100,130,165334,255011161,13.26,100,1,13.04,2,1,13.03,100,1,12.73,100,1,12.71,100,1,12.5,700,1,12.46,200,2,12.43,700,1,12.42,700,1,12.37,700,1,13.89,15,1,13.9,100,1,13.94,15,1,14.07,2,1,14.18,100,1,14.28,100,1,14.4,100,1,14.56,800,2,14.6,700,1,14.68,1400,2,ARL,304252469
760,2025-07-17T15:45:58.419783333Z,2025-07-17T15:45:58.419617935Z,10,2,1108,C,A,-1,13.94,15,130,165398,255183198,13.26,100,1,13.04,2,1,13.03,100,1,12.73,100,1,12.71,100,1,12.5,700,1,12.46,200,2,12.43,700,1,12.42,700,1,12.37,700,1,13.89,15,1,13.9,100,1,14.07,2,1,14.18,100,1,14.28,100,1,14.4,100,1,14.56,800,2,14.6,700,1,14.68,1400,2,14.78,100,1,ARL,304056997
761,2025-07-17T15:45:58.420278691Z,2025-07-17T15:45:58.420113307Z,10,2,1108,A,A,9,14.77,100,130,165384,255183203,13.26,100,1,13.04,2,1,13.03,100,1,12.73,100,1,12.71,100,1,12.5,700,1,12.46,200,2,12.43,700,1,12.42,700,1,12.37,700,1,13.89,15,1,13.9,100,1,14.07,2,1,14.18,100,1,14.28,100,1,14.4,100,1,14.56,800,2,14.6,700,1,14.68,1400,2,14.77,100,1,ARL,304503585
762,2025-07-17T15:45:58.420755889Z,2025-07-17T15:45:58.420590199Z,10,2,1108,A,A,9,14.77,100,130,165690,255183204,13.26,100,1,13.04,2,1,13.03,100,1,12.73,100,1,12.71,100,1,12.5,700,1,12.46,200,2,12.43,700,1,12.42,700,1,12.37,700,1,13.89,15,1,13.9,100,1,14.07,2,1,14.18,100,1,14.28,100,1,14.4,100,1,14.56,800,2,14.6,700,1,14.68,1400,2,14.77,200,2,ARL,304503593
763,2025-07-17T15:45:58.782892109Z,2025-07-17T15:45:58.782726994Z,10,2,1108,C,A,-1,13.89,15,130,165115,255189425,13.26,100,1,13.04,2,1,13.03,100,1,12.73,100,1,12.71,100,1,12.5,700,1,12.46,200,2,12.43,700,1,12.42,700,1,12.37,700,1,13.9,100,1,14.07,2,1,14.18,100,1,14.28,100,1,14.4,100,1,14.56,800,2,14.6,700,1,14.68,1400,2,14.77,200,2,14.78,100,1,ARL,304238913
764,2025-07-17T15:46:16.783057616Z,2025-07-17T15:46:16.782892334Z,10,2,1108,A,A,0,13.88,15,130,165282,255552962,13.26,100,1,13.04,2,1,13.03,100,1,12.73,100,1,12.71,100,1,12.5,700,1,12.46,200,2,12.43,700,1,12.42,700,1,12.37,700,1,13.88,15,1,13.9,100,1,14.07,2,1,14.18,100,1,14.28,100,1,14.4,100,1,14.56,800,2,14.6,700,1,14.68,1400,2,14.77,200,2,ARL,304949689
765,2025-07-17T15:46:16.783326241Z,2025-07-17T15:46:16.783160795Z,10,2,1108,C,A,-1,13.9,100,0,165446,255552970,13.26,100,1,13.04,2,1,13.03,100,1,12.73,100,1,12.71,100,1,12.5,700,1,12.46,200,2,12.43,700,1,12.42,700,1,12.37,700,1,13.88,15,1,14.07,2,1,14.18,100,1,14.28,100,1,14.4,100,1,14.56,800,2,14.6,700,1,14.68,1400,2,14.77,200,2,14.78,100,1,ARL,304252313
766,2025-07-17T15:46:16.783326241Z,2025-07-17T15:46:16.783160795Z,10,2,1108,A,A,1,13.89,100,130,165446,255552970,13.26,100,1,13.04,2,1,13.03,100,1,12.73,100,1,12.71,100,1,12.5,700,1,12.46,200,2,12.43,700,1,12.42,700,1,12.37,700,1,13.88,15,1,13.89,100,1,14.07,2,1,14.18,100,1,14.28,100,1,14.4,100,1,14.56,800,2,14.6,700,1,14.68,1400,2,14.77,200,2,ARL,304949697
767,2025-07-17T15:46:18.782897570Z,2025-07-17T15:46:18.782732218Z,10,2,1108,C,A,-1,13.88,15,130,165352,255587336,13.26,100,1,13.04,2,1,13.03,100,1,12.73,100,1,12.71,100,1,12.5,700,1,12.46,200,2,12.43,700,1,12.42,700,1,12.37,700,1,13.89,100,1,14.07,2,1,14.18,100,1,14.28,100,1,14.4,100,1,14.56,800,2,14.6,700,1,14.68,1400,2,14.77,200,2,14.78,100,1,ARL,304949689
768,2025-07-17T15:46:28.474166897Z,2025-07-17T15:46:28.474001551Z,10,2,1108,C,A,-1,13.89,100,130,165346,255746167,13.26,100,1,13.04,2,1,13.03,100,1,12.73,100,1,12.71,100,1,12.5,700,1,12.46,200,2,12.43,700,1,12.42,700,1,12.37,700,1,14.07,2,1,14.18,100,1,14.28,100,1,14.4,100,1,14.56,800,2,14.6,700,1,14.68,1400,2,14.77,200,2,14.78,100,1,14.96,200,2,ARL,304949697
769,2025-07-17T15:46:28.474726594Z,2025-07-17T15:46:28.474561156Z,10,2,1108,C,A,7,14.77,100,0,165438,255746173,13.26,100,1,13.04,2,1,13.03,100,1,12.73,100,1,12.71,100,1,12.5,700,1,12.46,200,2,12.43,700,1,12.42,700,1,12.37,700,1,14.07,2,1,14.18,100,1,14.28,100,1,14.4,100,1,14.56,800,2,14.6,700,1,14.68,1400,2,14.77,100,1,14.78,100,1,14.96,200,2,ARL,304503593
770,2025-07-17T15:46:28.474726594Z,2025-07-17T15:46:28.474561156Z,10,2,1108,A,A,9,14.88,100,130,165438,255746173,13.26,100,1,13.04,2,1,13.03,100,1,12.73,100,1,12.71,100,1,12.5,700,1,12.46,200,2,12.43,700,1,12.42,700,1,12.37,700,1,14.07,2,1,14.18,100,1,14.28,100,1,14.4,100,1,14.56,800,2,14.6,700,1,14.68,1400,2,14.77,100,1,14.78,100,1,14.88,100,1,ARL,305184937
771,2025-07-17T15:46:28.474896460Z,2025-07-17T15:46:28.474730225Z,10,2,1108,C,A,-1,14.77,100,0,166235,255746176,13.26,100,1,13.04,2,1,13.03,100,1,12.73,100,1,12.71,100,1,12.5,700,1,12.46,200,2,12.43,700,1,12.42,700,1,12.37,700,1,14.07,2,1,14.18,100,1,14.28,100,1,14.4,100,1,14.56,800,2,14.6,700,1,14.68,1400,2,14.78,100,1,14.88,100,1,14.96,200,2,ARL,304503585
772,2025-07-17T15:46:28.474896460Z,2025-07-17T15:46:28.474730225Z,10,2,1108,A,A,8,14.88,100,130,166235,255746176,13.26,100,1,13.04,2,1,13.03,100,1,12.73,100,1,12.71,100,1,12.5,700,1,12.46,200,2,12.43,700,1,12.42,700,1,12.37,700,1,14.07,2,1,14.18,100,1,14.28,100,1,14.4,100,1,14.56,800,2,14.6,700,1,14.68,1400,2,14.78,100,1,14.88,200,2,14.96,200,2,ARL,305184953
773,2025-07-17T15:46:28.492881980Z,2025-07-17T15:46:28.492716775Z,10,2,1108,C,A,-1,14.18,100,130,165205,255746619,13.26,100,1,13.04,2,1,13.03,100,1,12.73,100,1,12.71,100,1,12.5,700,1,12.46,200,2,12.43,700,1,12.42,700,1,12.37,700,1,14.07,2,1,14.28,100,1,14.4,100,1,14.56,800,2,14.6,700,1,14.68,1400,2,14.78,100,1,14.88,200,2,14.96,200,2,15.03,100,1,ARL,304252469
774,2025-07-17T15:46:28.492931279Z,2025-07-17T15:46:28.492765859Z,10,2,1108,A,A,1,14.26,100,130,165420,255746621,13.26,100,1,13.04,2,1,13.03,100,1,12.73,100,1,12.71,100,1,12.5,700,1,12.46,200,2,12.43,700,1,12.42,700,1,12.37,700,1,14.07,2,1,14.26,100,1,14.28,100,1,14.4,100,1,14.56,800,2,14.6,700,1,14.68,1400,2,14.78,100,1,14.88,200,2,14.96,200,2,ARL,305185529
775,2025-07-17T15:46:28.646273467Z,2025-07-17T15:46:28.646108242Z,10,2,1108,A,A,1,14.08,100,130,165225,255748568,13.26,100,1,13.04,2,1,13.03,100,1,12.73,100,1,12.71,100,1,12.5,700,1,12.46,200,2,12.43,700,1,12.42,700,1,12.37,700,1,14.07,2,1,14.08,100,1,14.26,100,1,14.28,100,1,14.4,100,1,14.56,800,2,14.6,700,1,14.68,1400,2,14.78,100,1,14.88,200,2,ARL,305187077
776,2025-07-17T15:46:57.524024658Z,2025-07-17T15:46:57.523859388Z,10,2,1108,A,A,0,13.92,15,130,165270,256268482,13.26,100,1,13.04,2,1,13.03,100,1,12.73,100,1,12.71,100,1,12.5,700,1,12.46,200,2,12.43,700,1,12.42,700,1,12.37,700,1,13.92,15,1,14.07,2,1,14.08,100,1,14.26,100,1,14.28,100,1,14.4,100,1,14.56,800,2,14.6,700,1,14.68,1400,2,14.78,100,1,ARL,305862145
777,2025-07-17T15:46:57.932842994Z,2025-07-17T15:46:57.932677299Z,10,2,1108,C,A,-1,14.08,100,0,165695,256280751,13.26,100,1,13.04,2,1,13.03,100,1,12.73,100,1,12.71,100,1,12.5,700,1,12.46,200,2,12.43,700,1,12.42,700,1,12.37,700,1,13.92,15,1,14.07,2,1,14.26,100,1,14.28,100,1,14.4,100,1,14.56,800,2,14.6,700,1,14.68,1400,2,14.78,100,1,14.88,200,2,ARL,305187077
778,2025-07-17T15:46:57.932842994Z,2025-07-17T15:46:57.932677299Z,10,2,1108,A,A,1,13.93,100,130,165695,256280751,13.26,100,1,13.04,2,1,13.03,100,1,12.73,100,1,12.71,100,1,12.5,700,1,12.46,200,2,12.43,700,1,12.42,700,1,12.37,700,1,13.92,15,1,13.93,100,1,14.07,2,1,14.26,100,1,14.28,100,1,14.4,100,1,14.56,800,2,14.6,700,1,14.68,1400,2,14.78,100,1,ARL,305878881
779,2025-07-17T15:47:06.609456251Z,2025-07-17T15:47:06.609290857Z,10,2,1108,A,A,0,13.88,15,130,165394,256488374,13.26,100,1,13.04,2,1,13.03,100,1,12.73,100,1,12.71,100,1,12.5,700,1,12.46,200,2,12.43,700,1,12.42,700,1,12.37,700,1,13.88,15,1,13.92,15,1,13.93,100,1,14.07,2,1,14.26,100,1,14.28,100,1,14.4,100,1,14.56,800,2,14.6,700,1,14.68,1400,2,ARL,306121113
780,2025-07-17T15:47:08.787695144Z,2025-07-17T15:47:08.787529505Z,10,2,1108,C,A,-1,13.93,100,0,165639,256532991,13.26,100,1,13.04,2,1,13.03,100,1,12.73,100,1,12.71,100,1,12.5,700,1,12.46,200,2,12.43,700,1,12.42,700,1,12.37,700,1,13.88,15,1,13.92,15,1,14.07,2,1,14.26,100,1,14.28,100,1,14.4,100,1,14.56,800,2,14.6,700,1,14.68,1400,2,14.78,100,1,ARL,305878881
781,2025-07-17T15:47:08.787695144Z,2025-07-17T15:47:08.787529505Z,10,2,1108,A,A,1,13.89,100,130,165639,256532991,13.26,100,1,13.04,2,1,13.03,100,1,12.73,100,1,12.71,100,1,12.5,700,1,12.46,200,2,12.43,700,1,12.42,700,1,12.37,700,1,13.88,15,1,13.89,100,1,13.92,15,1,14.07,2,1,14.26,100,1,14.28,100,1,14.4,100,1,14.56,800,2,14.6,700,1,14.68,1400,2,ARL,306170837
782,2025-07-17T15:47:08.805983406Z,2025-07-17T15:47:08.805818249Z,10,2,1108,C,A,-1,14.26,100,130,165157,256533442,13.26,100,1,13.04,2,1,13.03,100,1,12.73,100,1,12.71,100,1,12.5,700,1,12.46,200,2,12.43,700,1,12.42,700,1,12.37,700,1,13.88,15,1,13.89,100,1,13.92,15,1,14.07,2,1,14.28,100,1,14.4,100,1,14.56,800,2,14.6,700,1,14.68,1400,2,14.78,100,1,ARL,305185529
783,2025-07-17T15:47:08.806033773Z,2025-07-17T15:47:08.805868059Z,10,2,1108,A,A,4,14.17,100,130,165714,256533443,13.26,100,1,13.04,2,1,13.03,100,1,12.73,100,1,12.71,100,1,12.5,700,1,12.46,200,2,12.43,700,1,12.42,700,1,12.37,700,1,13.88,15,1,13.89,100,1,13.92,15,1,14.07,2,1,14.17,100,1,14.28,100,1,14.4,100,1,14.56,800,2,14.6,700,1,14.68,1400,2,ARL,306171457
784,2025-07-17T15:47:13.121454355Z,2025-07-17T15:47:13.121288953Z,10,2,1108,C,A,-1,13.88,15,130,165402,256612694,13.26,100,1,13.04,2,1,13.03,100,1,12.73,100,1,12.71,100,1,12.5,700,1,12.46,200,2,12.43,700,1,12.42,700,1,12.37,700,1,13.89,100,1,13.92,15,1,14.07,2,1,14.17,100,1,14.28,100,1,14.4,100,1,14.56,800,2,14.6,700,1,14.68,1400,2,14.78,100,1,ARL,306121113
785,2025-07-17T15:47:13.122562533Z,2025-07-17T15:47:13.122396816Z,10,2,1108,C,A,-1,13.92,15,130,165717,256612757,13.26,100,1,13.04,2,1,13.03,100,1,12.73,100,1,12.71,100,1,12.5,700,1,12.46,200,2,12.43,700,1,12.42,700,1,12.37,700,1,13.89,100,1,14.07,2,1,14.17,100,1,14.28,100,1,14.4,100,1,14.56,800,2,14.6,700,1,14.68,1400,2,14.78,100,1,14.88,200,2,ARL,305862145
786,2025-07-17T15:47:24.786476266Z,2025-07-17T15:47:24.786310694Z,10,2,1108,A,A,0,13.87,15,130,165572,256812416,13.26,100,1,13.04,2,1,13.03,100,1,12.73,100,1,12.71,100,1,12.5,700,1,12.46,200,2,12.43,700,1,12.42,700,1,12.37,700,1,13.87,15,1,13.89,100,1,14.07,2,1,14.17,100,1,14.28,100,1,14.4,100,1,14.56,800,2,14.6,700,1,14.68,1400,2,14.78,100,1,ARL,306519385
787,2025-07-17T15:47:24.786745657Z,2025-07-17T15:47:24.786580061Z,10,2,1108,C,A,-1,13.89,100,0,165596,256812420,13.26,100,1,13.04,2,1,13.03,100,1,12.73,100,1,12.71,100,1,12.5,700,1,12.46,200,2,12.43,700,1,12.42,700,1,12.37,700,1,13.87,15,1,14.07,2,1,14.17,100,1,14.28,100,1,14.4,100,1,14.56,800,2,14.6,700,1,14.68,1400,2,14.78,100,1,14.88,200,2,ARL,306170837
788,2025-07-17T15:47:24.786745657Z,2025-07-17T15:47:24.786580061Z,10,2,1108,A,A,1,13.88,100,130,165596,256812420,13.26,100,1,13.04,2,1,13.03,100,1,12.73,100,1,12.71,100,1,12.5,700,1,12.46,200,2,12.43,700,1,12.42,700,1,12.37,700,1,13.87,15,1,13.88,100,1,14.07,2,1,14.17,100,1,14.28,100,1,14.4,100,1,14.56,800,2,14.6,700,1,14.68,1400,2,14.78,100,1,ARL,306519397
789,2025-07-17T15:47:24.786925729Z,2025-07-17T15:47:24.786759805Z,10,2,1108,A,A,9,14.77,100,130,165924,256812422,13.26,100,1,13.04,2,1,13.03,100,1,12.73,100,1,12.71,100,1,12.5,700,1,12.46,200,2,12.43,700,1,12.42,700,1,12.37,700,1,13.87,15,1,13.88,100,1,14.07,2,1,14.17,100,1,14.28,100,1,14.4,100,1,14.56,800,2,14.6,700,1,14.68,1400,2,14.77,100,1,ARL,306519409
790,2025-07-17T15:47:24.800616004Z,2025-07-17T15:47:24.800449950Z,10,2,1108,A,A,9,14.75,100,130,166054,256812578,13.26,100,1,13.04,2,1,13.03,100,1,12.73,100,1,12.71,100,1,12.5,700,1,12.46,200,2,12.43,700,1,12.42,700,1,12.37,700,1,13.87,15,1,13.88,100,1,14.07,2,1,14.17,100,1,14.28,100,1,14.4,100,1,14.56,800,2,14.6,700,1,14.68,1400,2,14.75,100,1,ARL,306519741
791,2025-07-17T15:47:27.860272892Z,2025-07-17T15:47:27.860107552Z,10,2,1108,A,A,0,13.83,15,130,165340,256866835,13.26,100,1,13.04,2,1,13.03,100,1,12.73,100,1,12.71,100,1,12.5,700,1,12.46,200,2,12.43,700,1,12.42,700,1,12.37,700,1,13.83,15,1,13.87,15,1,13.88,100,1,14.07,2,1,14.17,100,1,14.28,100,1,14.4,100,1,14.56,800,2,14.6,700,1,14.68,1400,2,ARL,306587393
792,2025-07-17T15:47:31.407029312Z,2025-07-17T15:47:31.406863918Z,10,2,1108,C,A,-1,13.88,100,0,165394,256910124,13.26,100,1,13.04,2,1,13.03,100,1,12.73,100,1,12.71,100,1,12.5,700,1,12.46,200,2,12.43,700,1,12.42,700,1,12.37,700,1,13.83,15,1,13.87,15,1,14.07,2,1,14.17,100,1,14.28,100,1,14.4,100,1,14.56,800,2,14.6,700,1,14.68,1400,2,14.75,100,1,ARL,306519397
793,2025-07-17T15:47:31.407029312Z,2025-07-17T15:47:31.406863918Z,10,2,1108,A,A,1,13.84,100,130,165394,256910124,13.26,100,1,13.04,2,1,13.03,100,1,12.73,100,1,12.71,100,1,12.5,700,1,12.46,200,2,12.43,700,1,12.42,700,1,12.37,700,1,13.83,15,1,13.84,100,1,13.87,15,1,14.07,2,1,14.17,100,1,14.28,100,1,14.4,100,1,14.56,800,2,14.6,700,1,14.68,1400,2,ARL,306647425
794,2025-07-17T15:47:31.413491477Z,2025-07-17T15:47:31.413325908Z,10,2,1108,A,A,9,14.64,100,130,165569,256910184,13.26,100,1,13.04,2,1,13.03,100,1,12.73,100,1,12.71,100,1,12.5,700,1,12.46,200,2,12.43,700,1,12.42,700,1,12.37,700,1,13.83,15,1,13.84,100,1,13.87,15,1,14.07,2,1,14.17,100,1,14.28,100,1,14.4,100,1,14.56,800,2,14.6,700,1,14.64,100,1,ARL,306647521
795,2025-07-17T15:47:37.159589804Z,2025-07-17T15:47:37.159424166Z,10,2,1108,C,A,-1,13.87,15,130,165638,256983942,13.26,100,1,13.04,2,1,13.03,100,1,12.73,100,1,12.71,100,1,12.5,700,1,12.46,200,2,12.43,700,1,12.42,700,1,12.37,700,1,13.83,15,1,13.84,100,1,14.07,2,1,14.17,100,1,14.28,100,1,14.4,100,1,14.56,800,2,14.6,700,1,14.64,100,1,14.68,1400,2,ARL,306519385
796,2025-07-17T15:47:37.172000440Z,2025-07-17T15:47:37.171834941Z,10,2,1108,A,A,2,13.85,100,130,165499,256984053,13.26,100,1,13.04,2,1,13.03,100,1,12.73,100,1,12.71,100,1,12.5,700,1,12.46,200,2,12.43,700,1,12.42,700,1,12.37,700,1,13.83,15,1,13.84,100,1,13.85,100,1,14.07,2,1,14.17,100,1,14.28,100,1,14.4,100,1,14.56,800,2,14.6,700,1,14.64,100,1,ARL,306749753
797,2025-07-17T15:47:38.161181283Z,2025-07-17T15:47:38.161015969Z,10,2,1108,A,A,0,13.79,15,130,165314,256998606,13.26,100,1,13.04,2,1,13.03,100,1,12.73,100,1,12.71,100,1,12.5,700,1,12.46,200,2,12.43,700,1,12.42,700,1,12.37,700,1,13.79,15,1,13.83,15,1,13.84,100,1,13.85,100,1,14.07,2,1,14.17,100,1,14.28,100,1,14.4,100,1,14.56,800,2,14.6,700,1,ARL,306770041
798,2025-07-17T15:47:38.794962245Z,2025-07-17T15:47:38.794795887Z,10,2,1108,C,A,-1,13.84,100,0,166358,257010989,13.26,100,1,13.04,2,1,13.03,100,1,12.73,100,1,12.71,100,1,12.5,700,1,12.46,200,2,12.43,700,1,12.42,700,1,12.37,700,1,13.79,15,1,13.83,15,1,13.85,100,1,14.07,2,1,14.17,100,1,14.28,100,1,14.4,100,1,14.56,800,2,14.6,700,1,14.64,100,1,ARL,306647425
799,2025-07-17T15:47:38.794962245Z,2025-07-17T15:47:38.794795887Z,10,2,1108,A,A,1,13.8,100,128,166358,257010989,13.26,100,1,13.04,2,1,13.03,100,1,12.73,100,1,12.71,100,1,12.5,700,1,12.46,200,2,12.43,700,1,12.42,700,1,12.37,700,1,13.79,15,1,13.8,100,1,13.83,15,1,13.85,100,1,14.07,2,1,14.17,100,1,14.28,100,1,14.4,100,1,14.56,800,2,14.6,700,1,ARL,306784133
800,2025-07-17T15:47:38.804624258Z,2025-07-17T15:47:38.804458744Z,10,2,1108,C,A,-1,14.17,100,130,165514,257011716,13.26,100,1,13.04,2,1,13.03,100,1,12.73,100,1,12.71,100,1,12.5,700,1,12.46,200,2,12.43,700,1,12.42,700,1,12.37,700,1,13.79,15,1,13.8,100,1,13.83,15,1,13.85,100,1,14.07,2,1,14.28,100,1,14.4,100,1,14.56,800,2,14.6,700,1,14.64,100,1,ARL,306171457
801,2025-07-17T15:47:38.804679592Z,2025-07-17T15:47:38.804513793Z,10,2,1108,A,A,5,14.08,100,130,165799,257011717,13.26,100,1,13.04,2,1,13.03,100,1,12.73,100,1,12.71,100,1,12.5,700,1,12.46,200,2,12.43,700,1,12.42,700,1,12.37,700,1,13.79,15,1,13.8,100,1,13.83,15,1,13.85,100,1,14.07,2,1,14.08,100,1,14.28,100,1,14.4,100,1,14.56,800,2,14.6,700,1,ARL,306784853
802,2025-07-17T15:47:39.092472059Z,2025-07-17T15:47:39.092305947Z,10,2,1108,C,A,-1,13.79,15,130,166112,257018687,13.26,100,1,13.04,2,1,13.03,100,1,12.73,100,1,12.71,100,1,12.5,700,1,12.46,200,2,12.43,700,1,12.42,700,1,12.37,700,1,13.8,100,1,13.83,15,1,13.85,100,1,14.07,2,1,14.08,100,1,14.28,100,1,14.4,100,1,14.56,800,2,14.6,700,1,14.64,100,1,ARL,306770041
803,2025-07-17T15:47:39.095920859Z,2025-07-17T15:47:39.095755335Z,10,2,1108,C,A,-1,13.83,15,130,165524,257018796,13.26,100,1,13.04,2,1,13.03,100,1,12.73,100,1,12.71,100,1,12.5,700,1,12.46,200,2,12.43,700,1,12.42,700,1,12.37,700,1,13.8,100,1,13.85,100,1,14.07,2,1,14.08,100,1,14.28,100,1,14.4,100,1,14.56,800,2,14.6,700,1,14.64,100,1,14.68,1400,2,ARL,306587393
804,2025-07-17T15:48:08.909366905Z,2025-07-17T15:48:08.909201576Z,10,2,1108,A,A,1,13.83,100,130,165329,257603755,13.26,100,1,13.04,2,1,13.03,100,1,12.73,100,1,12.71,100,1,12.5,700,1,12.46,200,2,12.43,700,1,12.42,700,1,12.37,700,1,13.8,100,1,13.83,100,1,13.85,100,1,14.07,2,1,14.08,100,1,14.28,100,1,14.4,100,1,14.56,800,2,14.6,700,1,14.64,100,1,ARL,307567929
805,2025-07-17T15:48:08.916721098Z,2025-07-17T15:48:08.916555821Z,10,2,1108,C,A,-1,13.85,100,130,165277,257604057,13.26,100,1,13.04,2,1,13.03,100,1,12.73,100,1,12.71,100,1,12.5,700,1,12.46,200,2,12.43,700,1,12.42,700,1,12.37,700,1,13.8,100,1,13.83,100,1,14.07,2,1,14.08,100,1,14.28,100,1,14.4,100,1,14.56,800,2,14.6,700,1,14.64,100,1,14.68,1400,2,ARL,306749753
806,2025-07-17T15:48:09.653473465Z,2025-07-17T15:48:09.653308042Z,10,2,1108,A,A,0,13.78,15,130,165423,257621095,13.26,100,1,13.04,2,1,13.03,100,1,12.73,100,1,12.71,100,1,12.5,700,1,12.46,200,2,12.43,700,1,12.42,700,1,12.37,700,1,13.78,15,1,13.8,100,1,13.83,100,1,14.07,2,1,14.08,100,1,14.28,100,1,14.4,100,1,14.56,800,2,14.6,700,1,14.64,100,1,ARL,307587873
807,2025-07-17T15:48:11.166689254Z,2025-07-17T15:48:11.166517494Z,10,2,1108,C,A,-1,13.78,15,128,171760,257644020,13.26,100,1,13.04,2,1,13.03,100,1,12.73,100,1,12.71,100,1,12.5,700,1,12.46,200,2,12.43,700,1,12.42,700,1,12.37,700,1,13.8,100,1,13.83,100,1,14.07,2,1,14.08,100,1,14.28,100,1,14.4,100,1,14.56,800,2,14.6,700,1,14.64,100,1,14.68,1400,2,ARL,307587873
808,2025-07-17T15:48:13.509078553Z,2025-07-17T15:48:13.508913083Z,10,2,1108,A,A,0,13.78,15,130,165470,257727039,13.26,100,1,13.04,2,1,13.03,100,1,12.73,100,1,12.71,100,1,12.5,700,1,12.46,200,2,12.43,700,1,12.42,700,1,12.37,700,1,13.78,15,1,13.8,100,1,13.83,100,1,14.07,2,1,14.08,100,1,14.28,100,1,14.4,100,1,14.56,800,2,14.6,700,1,14.64,100,1,ARL,307714769
809,2025-07-17T15:48:13.525953545Z,2025-07-17T15:48:13.525788139Z,10,2,1108,A,A,2,13.81,100,130,165406,257727301,13.26,100,1,13.04,2,1,13.03,100,1,12.73,100,1,12.71,100,1,12.5,700,1,12.46,200,2,12.43,700,1,12.42,700,1,12.37,700,1,13.78,15,1,13.8,100,1,13.81,100,1,13.83,100,1,14.07,2,1,14.08,100,1,14.28,100,1,14.4,100,1,14.56,800,2,14.6,700,1,ARL,307715101
810,2025-07-17T15:48:13.532608874Z,2025-07-17T15:48:13.532443045Z,10,2,1108,C,A,-1,13.83,100,130,165829,257727457,13.26,100,1,13.04,2,1,13.03,100,1,12.73,100,1,12.71,100,1,12.5,700,1,12.46,200,2,12.43,700,1,12.42,700,1,12.37,700,1,13.78,15,1,13.8,100,1,13.81,100,1,14.07,2,1,14.08,100,1,14.28,100,1,14.4,100,1,14.56,800,2,14.6,700,1,14.64,100,1,ARL,307567929
811,2025-07-17T15:48:15.568544154Z,2025-07-17T15:48:15.568378275Z,10,2,1108,C,A,-1,13.8,100,0,165879,257757458,13.26,100,1,13.04,2,1,13.03,100,1,12.73,100,1,12.71,100,1,12.5,700,1,12.46,200,2,12.43,700,1,12.42,700,1,12.37,700,1,13.78,15,1,13.81,100,1,14.07,2,1,14.08,100,1,14.28,100,1,14.4,100,1,14.56,800,2,14.6,700,1,14.64,100,1,14.68,1400,2,ARL,306784133
812,2025-07-17T15:48:15.568544154Z,2025-07-17T15:48:15.568378275Z,10,2,1108,A,A,1,13.79,100,130,165879,257757458,13.26,100,1,13.04,2,1,13.03,100,1,12.73,100,1,12.71,100,1,12.5,700,1,12.46,200,2,12.43,700,1,12.42,700,1,12.37,700,1,13.78,15,1,13.79,100,1,13.81,100,1,14.07,2,1,14.08,100,1,14.28,100,1,14.4,100,1,14.56,800,2,14.6,700,1,14.64,100,1,ARL,307753241
813,2025-07-17T15:48:24.009355346Z,2025-07-17T15:48:24.009190157Z,10,2,1108,A,A,0,13.75,15,130,165189,257928318,13.26,100,1,13.04,2,1,13.03,100,1,12.73,100,1,12.71,100,1,12.5,700,1,12.46,200,2,12.43,700,1,12.42,700,1,12.37,700,1,13.75,15,1,13.78,15,1,13.79,100,1,13.81,100,1,14.07,2,1,14.08,100,1,14.28,100,1,14.4,100,1,14.56,800,2,14.6,700,1,ARL,307964605
814,2025-07-17T15:48:24.009522633Z,2025-07-17T15:48:24.009357442Z,10,2,1108,A,A,2,13.79,100,130,165191,257928319,13.26,100,1,13.04,2,1,13.03,100,1,12.73,100,1,12.71,100,1,12.5,700,1,12.46,200,2,12.43,700,1,12.42,700,1,12.37,700,1,13.75,15,1,13.78,15,1,13.79,200,2,13.81,100,1,14.07,2,1,14.08,100,1,14.28,100,1,14.4,100,1,14.56,800,2,14.6,700,1,ARL,307964609
815,2025-07-17T15:48:24.009944381Z,2025-07-17T15:48:24.009778967Z,10,2,1108,C,A,2,13.79,100,0,165414,257928325,13.26,100,1,13.04,2,1,13.03,100,1,12.73,100,1,12.71,100,1,12.5,700,1,12.46,200,2,12.43,700,1,12.42,700,1,12.37,700,1,13.75,15,1,13.78,15,1,13.79,100,1,13.81,100,1,14.07,2,1,14.08,100,1,14.28,100,1,14.4,100,1,14.56,800,2,14.6,700,1,ARL,307753241
816,2025-07-17T15:48:24.009944381Z,2025-07-17T15:48:24.009778967Z,10,2,1108,A,A,1,13.76,100,130,165414,257928325,13.26,100,1,13.04,2,1,13.03,100,1,12.73,100,1,12.71,100,1,12.5,700,1,12.46,200,2,12.43,700,1,12.42,700,1,12.37,700,1,13.75,15,1,13.76,100,1,13.78,15,1,13.79,100,1,13.81,100,1,14.07,2,1,14.08,100,1,14.28,100,1,14.4,100,1,14.56,800,2,ARL,307964621
817,2025-07-17T15:48:24.009974166Z,2025-07-17T15:48:24.009808793Z,10,2,1108,C,A,-1,13.81,100,130,165373,257928326,13.26,100,1,13.04,2,1,13.03,100,1,12.73,100,1,12.71,100,1,12.5,700,1,12.46,200,2,12.43,700,1,12.42,700,1,12.37,700,1,13.75,15,1,13.76,100,1,13.78,15,1,13.79,100,1,14.07,2,1,14.08,100,1,14.28,100,1,14.4,100,1,14.56,800,2,14.6,700,1,ARL,307715101
818,2025-07-17T15:48:42.009954046Z,2025-07-17T15:48:42.009788565Z,10,2,1108,C,A,-1,13.78,15,130,165481,258199397,13.26,100,1,13.04,2,1,13.03,100,1,12.73,100,1,12.71,100,1,12.5,700,1,12.46,200,2,12.43,700,1,12.42,700,1,12.37,700,1,13.75,15,1,13.76,100,1,13.79,100,1,14.07,2,1,14.08,100,1,14.28,100,1,14.4,100,1,14.56,800,2,14.6,700,1,14.64,100,1,ARL,307714769
819,2025-07-17T15:48:42.011846392Z,2025-07-17T15:48:42.011680742Z,10,2,1108,A,A,9,14.64,100,130,165650,258199535,13.26,100,1,13.04,2,1,13.03,100,1,12.73,100,1,12.71,100,1,12.5,700,1,12.46,200,2,12.43,700,1,12.42,700,1,12.37,700,1,13.75,15,1,13.76,100,1,13.79,100,1,14.07,2,1,14.08,100,1,14.28,100,1,14.4,100,1,14.56,800,2,14.6,700,1,14.64,200,2,ARL,308296381
820,2025-07-17T15:48:42.016761374Z,2025-07-17T15:48:42.016595806Z,10,2,1108,A,A,2,13.77,100,130,165568,258199787,13.26,100,1,13.04,2,1,13.03,100,1,12.73,100,1,12.71,100,1,12.5,700,1,12.46,200,2,12.43,700,1,12.42,700,1,12.37,700,1,13.75,15,1,13.76,100,1,13.77,100,1,13.79,100,1,14.07,2,1,14.08,100,1,14.28,100,1,14.4,100,1,14.56,800,2,14.6,700,1,ARL,308296741
821,2025-07-17T15:48:42.023432407Z,2025-07-17T15:48:42.023266760Z,10,2,1108,C,A,-1,13.79,100,130,165647,258199990,13.26,100,1,13.04,2,1,13.03,100,1,12.73,100,1,12.71,100,1,12.5,700,1,12.46,200,2,12.43,700,1,12.42,700,1,12.37,700,1,13.75,15,1,13.76,100,1,13.77,100,1,14.07,2,1,14.08,100,1,14.28,100,1,14.4,100,1,14.56,800,2,14.6,700,1,14.64,200,2,ARL,307964609
822,2025-07-17T15:48:46.750088490Z,2025-07-17T15:48:46.749922127Z,10,2,1108,A,A,0,13.73,15,128,166363,258260871,13.26,100,1,13.04,2,1,13.03,100,1,12.73,100,1,12.71,100,1,12.5,700,1,12.46,200,2,12.43,700,1,12.42,700,1,12.37,700,1,13.73,15,1,13.75,15,1,13.76,100,1,13.77,100,1,14.07,2,1,14.08,100,1,14.28,100,1,14.4,100,1,14.56,800,2,14.6,700,1,ARL,308374537
823,2025-07-17T15:48:46.758551033Z,2025-07-17T15:48:46.758385367Z,10,2,1108,C,A,-1,13.76,100,0,165666,258261154,13.26,100,1,13.04,2,1,13.03,100,1,12.73,100,1,12.71,100,1,12.5,700,1,12.46,200,2,12.43,700,1,12.42,700,1,12.37,700,1,13.73,15,1,13.75,15,1,13.77,100,1,14.07,2,1,14.08,100,1,14.28,100,1,14.4,100,1,14.56,800,2,14.6,700,1,14.64,200,2,ARL,307964621
824,2025-07-17T15:48:46.758551033Z,2025-07-17T15:48:46.758385367Z,10,2,1108,A,A,1,13.74,100,130,165666,258261154,13.26,100,1,13.04,2,1,13.03,100,1,12.73,100,1,12.71,100,1,12.5,700,1,12.46,200,2,12.43,700,1,12.42,700,1,12.37,700,1,13.73,15,1,13.74,100,1,13.75,15,1,13.77,100,1,14.07,2,1,14.08,100,1,14.28,100,1,14.4,100,1,14.56,800,2,14.6,700,1,ARL,308374881
825,2025-07-17T15:48:46.773668988Z,2025-07-17T15:48:46.773503306Z,10,2,1108,C,A,-1,14.08,100,130,165682,258261538,13.26,100,1,13.04,2,1,13.03,100,1,12.73,100,1,12.71,100,1,12.5,700,1,12.46,200,2,12.43,700,1,12.42,700,1,12.37,700,1,13.73,15,1,13.74,100,1,13.75,15,1,13.77,100,1,14.07,2,1,14.28,100,1,14.4,100,1,14.56,800,2,14.6,700,1,14.64,200,2,ARL,306784853
826,2025-07-17T15:48:46.773720726Z,2025-07-17T15:48:46.773555566Z,10,2,1108,A,A,4,14.01,100,130,165160,258261539,13.26,100,1,13.04,2,1,13.03,100,1,12.73,100,1,12.71,100,1,12.5,700,1,12.46,200,2,12.43,700,1,12.42,700,1,12.37,700,1,13.73,15,1,13.74,100,1,13.75,15,1,13.77,100,1,14.01,100,1,14.07,2,1,14.28,100,1,14.4,100,1,14.56,800,2,14.6,700,1,ARL,308375185
827,2025-07-17T15:49:02.010494480Z,2025-07-17T15:49:02.010329052Z,10,2,1108,A,A,2,13.75,100,130,165428,258502869,13.26,100,1,13.04,2,1,13.03,100,1,12.73,100,1,12.71,100,1,12.5,700,1,12.46,200,2,12.43,700,1,12.42,700,1,12.37,700,1,13.73,15,1,13.74,100,1,13.75,115,2,13.77,100,1,14.01,100,1,14.07,2,1,14.28,100,1,14.4,100,1,14.56,800,2,14.6,700,1,ARL,308705489
828,2025-07-17T15:49:02.019989567Z,2025-07-17T15:49:02.019824230Z,10,2,1108,C,A,-1,13.77,100,130,165337,258502929,13.26,100,1,13.04,2,1,13.03,100,1,12.73,100,1,12.71,100,1,12.5,700,1,12.46,200,2,12.43,700,1,12.42,700,1,12.37,700,1,13.73,15,1,13.74,100,1,13.75,115,2,14.01,100,1,14.07,2,1,14.28,100,1,14.4,100,1,14.56,800,2,14.6,700,1,14.64,200,2,ARL,308296741
829,2025-07-17T15:49:03.406005590Z,2025-07-17T15:49:03.405840358Z,10,2,1108,C,A,2,13.75,15,130,165232,258527308,13.26,100,1,13.04,2,1,13.03,100,1,12.73,100,1,12.71,100,1,12.5,700,1,12.46,200,2,12.43,700,1,12.42,700,1,12.37,700,1,13.73,15,1,13.74,100,1,13.75,100,1,14.01,100,1,14.07,2,1,14.28,100,1,14.4,100,1,14.56,800,2,14.6,700,1,14.64,200,2,ARL,307964605
830,2025-07-17T15:49:04.713997925Z,2025-07-17T15:49:04.713831675Z,10,2,1108,A,A,0,13.71,15,128,166250,258547335,13.26,100,1,13.04,2,1,13.03,100,1,12.73,100,1,12.71,100,1,12.5,700,1,12.46,200,2,12.43,700,1,12.42,700,1,12.37,700,1,13.71,15,1,13.73,15,1,13.74,100,1,13.75,100,1,14.01,100,1,14.07,2,1,14.28,100,1,14.4,100,1,14.56,800,2,14.6,700,1,ARL,308763065
831,2025-07-17T15:49:06.013111941Z,2025-07-17T15:49:06.012946379Z,10,2,1108,A,A,1,13.73,100,130,165562,258567259,13.26,100,1,13.04,2,1,13.03,100,1,12.73,100,1,12.71,100,1,12.5,700,1,12.46,200,2,12.43,700,1,12.42,700,1,12.37,700,1,13.71,15,1,13.73,115,2,13.74,100,1,13.75,100,1,14.01,100,1,14.07,2,1,14.28,100,1,14.4,100,1,14.56,800,2,14.6,700,1,ARL,308786185
832,2025-07-17T15:49:06.023292147Z,2025-07-17T15:49:06.023126600Z,10,2,1108,C,A,-1,13.75,100,130,165547,258567405,13.26,100,1,13.04,2,1,13.03,100,1,12.73,100,1,12.71,100,1,12.5,700,1,12.46,200,2,12.43,700,1,12.42,700,1,12.37,700,1,13.71,15,1,13.73,115,2,13.74,100,1,14.01,100,1,14.07,2,1,14.28,100,1,14.4,100,1,14.56,800,2,14.6,700,1,14.64,200,2,ARL,308705489
833,2025-07-17T15:49:06.344356890Z,2025-07-17T15:49:06.344191321Z,10,2,1108,C,A,-1,13.74,100,0,165569,258574949,13.26,100,1,13.04,2,1,13.03,100,1,12.73,100,1,12.71,100,1,12.5,700,1,12.46,200,2,12.43,700,1,12.42,700,1,12.37,700,1,13.71,15,1,13.73,115,2,14.01,100,1,14.07,2,1,14.28,100,1,14.4,100,1,14.56,800,2,14.6,700,1,14.64,200,2,14.65,100,1,ARL,308374881
834,2025-07-17T15:49:06.344356890Z,2025-07-17T15:49:06.344191321Z,10,2,1108,A,A,1,13.72,100,130,165569,258574949,13.26,100,1,13.04,2,1,13.03,100,1,12.73,100,1,12.71,100,1,12.5,700,1,12.46,200,2,12.43,700,1,12.42,700,1,12.37,700,1,13.71,15,1,13.72,100,1,13.73,115,2,14.01,100,1,14.07,2,1,14.28,100,1,14.4,100,1,14.56,800,2,14.6,700,1,14.64,200,2,ARL,308797069
835,2025-07-17T15:49:10.459317885Z,2025-07-17T15:49:10.459152457Z,10,2,1108,C,A,2,13.73,15,130,165428,258636400,13.26,100,1,13.04,2,1,13.03,100,1,12.73,100,1,12.71,100,1,12.5,700,1,12.46,200,2,12.43,700,1,12.42,700,1,12.37,700,1,13.71,15,1,13.72,100,1,13.73,100,1,14.01,100,1,14.07,2,1,14.28,100,1,14.4,100,1,14.56,800,2,14.6,700,1,14.64,200,2,ARL,308374537
836,2025-07-17T15:49:11.460597600Z,2025-07-17T15:49:11.460432218Z,10,2,1108,A,A,0,13.69,15,130,165382,258650544,13.26,100,1,13.04,2,1,13.03,100,1,12.73,100,1,12.71,100,1,12.5,700,1,12.46,200,2,12.43,700,1,12.42,700,1,12.37,700,1,13.69,15,1,13.71,15,1,13.72,100,1,13.73,100,1,14.01,100,1,14.07,2,1,14.28,100,1,14.4,100,1,14.56,800,2,14.6,700,1,ARL,308893737
837,2025-07-17T15:49:11.891643099Z,2025-07-17T15:49:11.891477604Z,10,2,1108,C,A,-1,13.72,100,0,165495,258658721,13.26,100,1,13.04,2,1,13.03,100,1,12.73,100,1,12.71,100,1,12.5,700,1,12.46,200,2,12.43,700,1,12.42,700,1,12.37,700,1,13.69,15,1,13.71,15,1,13.73,100,1,14.01,100,1,14.07,2,1,14.28,100,1,14.4,100,1,14.56,800,2,14.6,700,1,14.64,200,2,ARL,308797069
838,2025-07-17T15:49:11.891643099Z,2025-07-17T15:49:11.891477604Z,10,2,1108,A,A,1,13.7,100,130,165495,258658721,13.26,100,1,13.04,2,1,13.03,100,1,12.73,100,1,12.71,100,1,12.5,700,1,12.46,200,2,12.43,700,1,12.42,700,1,12.37,700,1,13.69,15,1,13.7,100,1,13.71,15,1,13.73,100,1,14.01,100,1,14.07,2,1,14.28,100,1,14.4,100,1,14.56,800,2,14.6,700,1,ARL,308901793
839,2025-07-17T15:49:11.948829112Z,2025-07-17T15:49:11.948663655Z,10,2,1108,A,A,8,14.5,100,130,165457,258659499,13.26,100,1,13.04,2,1,13.03,100,1,12.73,100,1,12.71,100,1,12.5,700,1,12.46,200,2,12.43,700,1,12.42,700,1,12.37,700,1,13.69,15,1,13.7,100,1,13.71,15,1,13.73,100,1,14.01,100,1,14.07,2,1,14.28,100,1,14.4,100,1,14.5,100,1,14.56,800,2,ARL,308903349
840,2025-07-17T15:49:12.221221367Z,2025-07-17T15:49:12.221056085Z,10,2,1108,A,A,2,13.71,100,130,165282,258663292,13.26,100,1,13.04,2,1,13.03,100,1,12.73,100,1,12.71,100,1,12.5,700,1,12.46,200,2,12.43,700,1,12.42,700,1,12.37,700,1,13.69,15,1,13.7,100,1,13.71,115,2,13.73,100,1,14.01,100,1,14.07,2,1,14.28,100,1,14.4,100,1,14.5,100,1,14.56,800,2,ARL,308909249
841,2025-07-17T15:49:12.227986905Z,2025-07-17T15:49:12.227821500Z,10,2,1108,C,A,-1,13.73,100,130,165405,258663378,13.26,100,1,13.04,2,1,13.03,100,1,12.73,100,1,12.71,100,1,12.5,700,1,12.46,200,2,12.43,700,1,12.42,700,1,12.37,700,1,13.69,15,1,13.7,100,1,13.71,115,2,14.01,100,1,14.07,2,1,14.28,100,1,14.4,100,1,14.5,100,1,14.56,800,2,14.6,700,1,ARL,308786185
842,2025-07-17T15:49:14.463229121Z,2025-07-17T15:49:14.463063539Z,10,2,1108,C,A,2,13.71,15,130,165582,258702625,13.26,100,1,13.04,2,1,13.03,100,1,12.73,100,1,12.71,100,1,12.5,700,1,12.46,200,2,12.43,700,1,12.42,700,1,12.37,700,1,13.69,15,1,13.7,100,1,13.71,100,1,14.01,100,1,14.07,2,1,14.28,100,1,14.4,100,1,14.5,100,1,14.56,800,2,14.6,700,1,ARL,308763065
843,2025-07-17T15:49:15.466365122Z,2025-07-17T15:49:15.466199239Z,10,2,1108,A,A,0,13.67,15,130,165883,258716863,13.26,100,1,13.04,2,1,13.03,100,1,12.73,100,1,12.71,100,1,12.5,700,1,12.46,200,2,12.43,700,1,12.42,700,1,12.37,700,1,13.67,15,1,13.69,15,1,13.7,100,1,13.71,100,1,14.01,100,1,14.07,2,1,14.28,100,1,14.4,100,1,14.5,100,1,14.56,800,2,ARL,308980305
844,2025-07-17T15:49:16.351024588Z,2025-07-17T15:49:16.350859152Z,10,2,1108,C,A,-1,13.7,100,0,165436,258727929,13.26,100,1,13.04,2,1,13.03,100,1,12.73,100,1,12.71,100,1,12.5,700,1,12.46,200,2,12.43,700,1,12.42,700,1,12.37,700,1,13.67,15,1,13.69,15,1,13.71,100,1,14.01,100,1,14.07,2,1,14.28,100,1,14.4,100,1,14.5,100,1,14.56,800,2,14.6,700,1,ARL,308901793
845,2025-07-17T15:49:16.351024588Z,2025-07-17T15:49:16.350859152Z,10,2,1108,A,A,1,13.68,100,130,165436,258727929,13.26,100,1,13.04,2,1,13.03,100,1,12.73,100,1,12.71,100,1,12.5,700,1,12.46,200,2,12.43,700,1,12.42,700,1,12.37,700,1,13.67,15,1,13.68,100,1,13.69,15,1,13.71,100,1,14.01,100,1,14.07,2,1,14.28,100,1,14.4,100,1,14.5,100,1,14.56,800,2,ARL,308998225
846,2025-07-17T15:49:16.494111490Z,2025-07-17T15:49:16.493946243Z,10,2,1108,A,A,2,13.69,100,130,165247,258729266,13.26,100,1,13.04,2,1,13.03,100,1,12.73,100,1,12.71,100,1,12.5,700,1,12.46,200,2,12.43,700,1,12.42,700,1,12.37,700,1,13.67,15,1,13.68,100,1,13.69,115,2,13.71,100,1,14.01,100,1,14.07,2,1,14.28,100,1,14.4,100,1,14.5,100,1,14.56,800,2,ARL,309001525
847,2025-07-17T15:49:16.557924863Z,2025-07-17T15:49:16.557759633Z,10,2,1108,C,A,-1,13.71,100,130,165230,258730034,13.26,100,1,13.04,2,1,13.03,100,1,12.73,100,1,12.71,100,1,12.5,700,1,12.46,200,2,12.43,700,1,12.42,700,1,12.37,700,1,13.67,15,1,13.68,100,1,13.69,115,2,14.01,100,1,14.07,2,1,14.28,100,1,14.4,100,1,14.5,100,1,14.56,800,2,14.6,700,1,ARL,308909249
848,2025-07-17T15:49:21.186150487Z,2025-07-17T15:49:21.185984774Z,10,2,1108,C,A,-1,14.07,2,0,165713,258786552,13.26,100,1,13.04,2,1,13.03,100,1,12.73,100,1,12.71,100,1,12.5,700,1,12.46,200,2,12.43,700,1,12.42,700,1,12.37,700,1,13.67,15,1,13.68,100,1,13.69,115,2,14.01,100,1,14.28,100,1,14.4,100,1,14.5,100,1,14.56,800,2,14.6,700,1,14.64,100,1,ARL,296478973
849,2025-07-17T15:49:21.186150487Z,2025-07-17T15:49:21.185984774Z,10,2,1108,A,A,3,13.98,2,130,165713,258786552,13.26,100,1,13.04,2,1,13.03,100,1,12.73,100,1,12.71,100,1,12.5,700,1,12.46,200,2,12.43,700,1,12.42,700,1,12.37,700,1,13.67,15,1,13.68,100,1,13.69,115,2,13.98,2,1,14.01,100,1,14.28,100,1,14.4,100,1,14.5,100,1,14.56,800,2,14.6,700,1,ARL,309091513
850,2025-07-17T15:49:24.283152112Z,2025-07-17T15:49:24.282985894Z,10,2,1108,C,A,2,13.69,15,130,166218,258838460,13.26,100,1,13.04,2,1,13.03,100,1,12.73,100,1,12.71,100,1,12.5,700,1,12.46,200,2,12.43,700,1,12.42,700,1,12.37,700,1,13.67,15,1,13.68,100,1,13.69,100,1,13.98,2,1,14.01,100,1,14.28,100,1,14.4,100,1,14.5,100,1,14.56,800,2,14.6,700,1,ARL,308893737
851,2025-07-17T15:49:34.570197134Z,2025-07-17T15:49:34.570031718Z,10,2,1108,C,A,-1,13.67,15,130,165416,258980876,13.26,100,1,13.04,2,1,13.03,100,1,12.73,100,1,12.71,100,1,12.5,700,1,12.46,200,2,12.43,700,1,12.42,700,1,12.37,700,1,13.68,100,1,13.69,100,1,13.98,2,1,14.01,100,1,14.28,100,1,14.4,100,1,14.5,100,1,14.56,800,2,14.6,700,1,14.64,100,1,ARL,308980305
852,2025-07-17T15:49:34.591512915Z,2025-07-17T15:49:34.591347169Z,10,2,1108,C,A,-1,13.69,100,130,165746,258983321,13.26,100,1,13.04,2,1,13.03,100,1,12.73,100,1,12.71,100,1,12.5,700,1,12.46,200,2,12.43,700,1,12.42,700,1,12.37,700,1,13.68,100,1,13.98,2,1,14.01,100,1,14.28,100,1,14.4,100,1,14.5,100,1,14.56,800,2,14.6,700,1,14.64,100,1,14.65,100,1,ARL,309001525
853,2025-07-17T15:49:38.610017394Z,2025-07-17T15:49:38.609851985Z,10,2,1108,A,A,1,13.72,100,130,165409,259031220,13.26,100,1,13.04,2,1,13.03,100,1,12.73,100,1,12.71,100,1,12.5,700,1,12.46,200,2,12.43,700,1,12.42,700,1,12.37,700,1,13.68,100,1,13.72,100,1,13.98,2,1,14.01,100,1,14.28,100,1,14.4,100,1,14.5,100,1,14.56,800,2,14.6,700,1,14.64,100,1,ARL,309410565
854,2025-07-17T15:49:38.610073334Z,2025-07-17T15:49:38.609907720Z,10,2,1108,C,B,-1,13.26,100,130,165614,259031221,13.04,2,1,13.03,100,1,12.73,100,1,12.71,100,1,12.5,700,1,12.46,200,2,12.43,700,1,12.42,700,1,12.37,700,1,12.36,200,2,13.68,100,1,13.72,100,1,13.98,2,1,14.01,100,1,14.28,100,1,14.4,100,1,14.5,100,1,14.56,800,2,14.6,700,1,14.64,100,1,ARL,291975017
855,2025-07-17T15:49:39.068515005Z,2025-07-17T15:49:39.068349660Z,10,2,1108,A,B,2,13.02,100,130,165345,259035032,13.04,2,1,13.03,100,1,13.02,100,1,12.73,100,1,12.71,100,1,12.5,700,1,12.46,200,2,12.43,700,1,12.42,700,1,12.37,700,1,13.68,100,1,13.72,100,1,13.98,2,1,14.01,100,1,14.28,100,1,14.4,100,1,14.5,100,1,14.56,800,2,14.6,700,1,14.64,100,1,ARL,309415429
856,2025-07-17T15:49:44.788414401Z,2025-07-17T15:49:44.788249210Z,10,2,1108,A,A,0,13.67,15,130,165191,259105347,13.04,2,1,13.03,100,1,13.02,100,1,12.73,100,1,12.71,100,1,12.5,700,1,12.46,200,2,12.43,700,1,12.42,700,1,12.37,700,1,13.67,15,1,13.68,100,1,13.72,100,1,13.98,2,1,14.01,100,1,14.28,100,1,14.4,100,1,14.5,100,1,14.56,800,2,14.6,700,1,ARL,309524921
857,2025-07-17T15:49:44.789020757Z,2025-07-17T15:49:44.788855587Z,10,2,1108,A,A,2,13.7,100,130,165170,259105361,13.04,2,1,13.03,100,1,13.02,100,1,12.73,100,1,12.71,100,1,12.5,700,1,12.46,200,2,12.43,700,1,12.42,700,1,12.37,700,1,13.67,15,1,13.68,100,1,13.7,100,1,13.72,100,1,13.98,2,1,14.01,100,1,14.28,100,1,14.4,100,1,14.5,100,1,14.56,800,2,ARL,309524933
858,2025-07-17T15:49:44.789702916Z,2025-07-17T15:49:44.789537536Z,10,2,1108,C,A,-1,13.72,100,130,165380,259105380,13.04,2,1,13.03,100,1,13.02,100,1,12.73,100,1,12.71,100,1,12.5,700,1,12.46,200,2,12.43,700,1,12.42,700,1,12.37,700,1,13.67,15,1,13.68,100,1,13.7,100,1,13.98,2,1,14.01,100,1,14.28,100,1,14.4,100,1,14.5,100,1,14.56,800,2,14.6,700,1,ARL,309410565
859,2025-07-17T15:49:54.788658841Z,2025-07-17T15:49:54.788493605Z,10,2,1108,A,A,0,13.65,15,130,165236,259253294,13.04,2,1,13.03,100,1,13.02,100,1,12.73,100,1,12.71,100,1,12.5,700,1,12.46,200,2,12.43,700,1,12.42,700,1,12.37,700,1,13.65,15,1,13.67,15,1,13.68,100,1,13.7,100,1,13.98,2,1,14.01,100,1,14.28,100,1,14.4,100,1,14.5,100,1,14.56,800,2,ARL,309707269
860,2025-07-17T15:49:54.799535744Z,2025-07-17T15:49:54.799370442Z,10,2,1108,A,A,2,13.68,100,130,165302,259253527,13.04,2,1,13.03,100,1,13.02,100,1,12.73,100,1,12.71,100,1,12.5,700,1,12.46,200,2,12.43,700,1,12.42,700,1,12.37,700,1,13.65,15,1,13.67,15,1,13.68,200,2,13.7,100,1,13.98,2,1,14.01,100,1,14.28,100,1,14.4,100,1,14.5,100,1,14.56,800,2,ARL,309707413
861,2025-07-17T15:49:54.820634917Z,2025-07-17T15:49:54.820469390Z,10,2,1108,C,A,-1,13.7,100,130,165527,259253732,13.04,2,1,13.03,100,1,13.02,100,1,12.73,100,1,12.71,100,1,12.5,700,1,12.46,200,2,12.43,700,1,12.42,700,1,12.37,700,1,13.65,15,1,13.67,15,1,13.68,200,2,13.98,2,1,14.01,100,1,14.28,100,1,14.4,100,1,14.5,100,1,14.56,800,2,14.6,700,1,ARL,309524933
862,2025-07-17T15:49:59.512104064Z,2025-07-17T15:49:59.511938438Z,10,2,1108,C,A,2,13.68,100,0,165626,259313537,13.04,2,1,13.03,100,1,13.02,100,1,12.73,100,1,12.71,100,1,12.5,700,1,12.46,200,2,12.43,700,1,12.42,700,1,12.37,700,1,13.65,15,1,13.67,15,1,13.68,100,1,13.98,2,1,14.01,100,1,14.28,100,1,14.4,100,1,14.5,100,1,14.56,800,2,14.6,700,1,ARL,308998225
863,2025-07-17T15:49:59.512104064Z,2025-07-17T15:49:59.511938438Z,10,2,1108,A,A,1,13.66,100,130,165626,259313537,13.04,2,1,13.03,100,1,13.02,100,1,12.73,100,1,12.71,100,1,12.5,700,1,12.46,200,2,12.43,700,1,12.42,700,1,12.37,700,1,13.65,15,1,13.66,100,1,13.67,15,1,13.68,100,1,13.98,2,1,14.01,100,1,14.28,100,1,14.4,100,1,14.5,100,1,14.56,800,2,ARL,309782481
864,2025-07-17T15:49:59.534062634Z,2025-07-17T15:49:59.533897369Z,10,2,1108,C,A,-1,14.01,100,130,165265,259314032,13.04,2,1,13.03,100,1,13.02,100,1,12.73,100,1,12.71,100,1,12.5,700,1,12.46,200,2,12.43,700,1,12.42,700,1,12.37,700,1,13.65,15,1,13.66,100,1,13.67,15,1,13.68,100,1,13.98,2,1,14.28,100,1,14.4,100,1,14.5,100,1,14.56,800,2,14.6,700,1,ARL,308375185
865,2025-07-17T15:49:59.534115275Z,2025-07-17T15:49:59.533948952Z,10,2,1108,A,A,4,13.93,100,130,166323,259314033,13.04,2,1,13.03,100,1,13.02,100,1,12.73,100,1,12.71,100,1,12.5,700,1,12.46,200,2,12.43,700,1,12.42,700,1,12.37,700,1,13.65,15,1,13.66,100,1,13.67,15,1,13.68,100,1,13.93,100,1,13.98,2,1,14.28,100,1,14.4,100,1,14.5,100,1,14.56,800,2,ARL,309782973
866,2025-07-17T15:50:00.547404972Z,2025-07-17T15:50:00.547239401Z,10,2,1108,C,A,-1,13.67,15,130,165571,259349868,13.04,2,1,13.03,100,1,13.02,100,1,12.73,100,1,12.71,100,1,12.5,700,1,12.46,200,2,12.43,700,1,12.42,700,1,12.37,700,1,13.65,15,1,13.66,100,1,13.68,100,1,13.93,100,1,13.98,2,1,14.28,100,1,14.4,100,1,14.5,100,1,14.56,800,2,14.6,700,1,ARL,309524921
867,2025-07-17T15:50:00.555536688Z,2025-07-17T15:50:00.555363249Z,10,2,1108,A,A,8,14.54,100,128,173439,259353226,13.04,2,1,13.03,100,1,13.02,100,1,12.73,100,1,12.71,100,1,12.5,700,1,12.46,200,2,12.43,700,1,12.42,700,1,12.37,700,1,13.65,15,1,13.66,100,1,13.68,100,1,13.93,100,1,13.98,2,1,14.28,100,1,14.4,100,1,14.5,100,1,14.54,100,1,14.56,800,2,ARL,309823025
868,2025-07-17T15:50:03.412422880Z,2025-07-17T15:50:03.412257475Z,10,2,1108,A,A,0,13.63,15,130,165405,259413272,13.04,2,1,13.03,100,1,13.02,100,1,12.73,100,1,12.71,100,1,12.5,700,1,12.46,200,2,12.43,700,1,12.42,700,1,12.37,700,1,13.63,15,1,13.65,15,1,13.66,100,1,13.68,100,1,13.93,100,1,13.98,2,1,14.28,100,1,14.4,100,1,14.5,100,1,14.54,100,1,ARL,309899025
869,2025-07-17T15:50:03.415527372Z,2025-07-17T15:50:03.415361851Z,10,2,1108,A,A,9,14.53,100,130,165521,259413427,13.04,2,1,13.03,100,1,13.02,100,1,12.73,100,1,12.71,100,1,12.5,700,1,12.46,200,2,12.43,700,1,12.42,700,1,12.37,700,1,13.63,15,1,13.65,15,1,13.66,100,1,13.68,100,1,13.93,100,1,13.98,2,1,14.28,100,1,14.4,100,1,14.5,100,1,14.53,100,1,ARL,309899141
870,2025-07-17T15:50:03.824292152Z,2025-07-17T15:50:03.824126753Z,10,2,1108,C,A,-1,13.66,100,0,165399,259418661,13.04,2,1,13.03,100,1,13.02,100,1,12.73,100,1,12.71,100,1,12.5,700,1,12.46,200,2,12.43,700,1,12.42,700,1,12.37,700,1,13.63,15,1,13.65,15,1,13.68,100,1,13.93,100,1,13.98,2,1,14.28,100,1,14.4,100,1,14.5,100,1,14.53,100,1,14.54,100,1,ARL,309782481
871,2025-07-17T15:50:03.824292152Z,2025-07-17T15:50:03.824126753Z,10,2,1108,A,A,1,13.64,100,130,165399,259418661,13.04,2,1,13.03,100,1,13.02,100,1,12.73,100,1,12.71,100,1,12.5,700,1,12.46,200,2,12.43,700,1,12.42,700,1,12.37,700,1,13.63,15,1,13.64,100,1,13.65,15,1,13.68,100,1,13.93,100,1,13.98,2,1,14.28,100,1,14.4,100,1,14.5,100,1,14.53,100,1,ARL,309903973
872,2025-07-17T15:50:04.484898759Z,2025-07-17T15:50:04.484733438Z,10,2,1108,A,A,3,13.66,100,130,165321,259433904,13.04,2,1,13.03,100,1,13.02,100,1,12.73,100,1,12.71,100,1,12.5,700,1,12.46,200,2,12.43,700,1,12.42,700,1,12.37,700,1,13.63,15,1,13.64,100,1,13.65,15,1,13.66,100,1,13.68,100,1,13.93,100,1,13.98,2,1,14.28,100,1,14.4,100,1,14.5,100,1,ARL,309922345
873,2025-07-17T15:50:04.524729039Z,2025-07-17T15:50:04.524563568Z,10,2,1108,C,A,-1,13.68,100,130,165471,259434652,13.04,2,1,13.03,100,1,13.02,100,1,12.73,100,1,12.71,100,1,12.5,700,1,12.46,200,2,12.43,700,1,12.42,700,1,12.37,700,1,13.63,15,1,13.64,100,1,13.65,15,1,13.66,100,1,13.93,100,1,13.98,2,1,14.28,100,1,14.4,100,1,14.5,100,1,14.53,100,1,ARL,309707413
874,2025-07-17T15:50:06.787826975Z,2025-07-17T15:50:06.787661846Z,10,2,1108,C,A,-1,13.63,15,130,165129,259472951,13.04,2,1,13.03,100,1,13.02,100,1,12.73,100,1,12.71,100,1,12.5,700,1,12.46,200,2,12.43,700,1,12.42,700,1,12.37,700,1,13.64,100,1,13.65,15,1,13.66,100,1,13.93,100,1,13.98,2,1,14.28,100,1,14.4,100,1,14.5,100,1,14.53,100,1,14.54,100,1,ARL,309899025
875,2025-07-17T15:50:09.185499367Z,2025-07-17T15:50:09.185334126Z,10,2,1108,A,A,0,13.61,15,130,165241,259516855,13.04,2,1,13.03,100,1,13.02,100,1,12.73,100,1,12.71,100,1,12.5,700,1,12.46,200,2,12.43,700,1,12.42,700,1,12.37,700,1,13.61,15,1,13.64,100,1,13.65,15,1,13.66,100,1,13.93,100,1,13.98,2,1,14.28,100,1,14.4,100,1,14.5,100,1,14.53,100,1,ARL,310030465
876,2025-07-17T15:50:09.198476437Z,2025-07-17T15:50:09.198311198Z,10,2,1108,A,A,1,13.64,100,130,165239,259517754,13.04,2,1,13.03,100,1,13.02,100,1,12.73,100,1,12.71,100,1,12.5,700,1,12.46,200,2,12.43,700,1,12.42,700,1,12.37,700,1,13.61,15,1,13.64,200,2,13.65,15,1,13.66,100,1,13.93,100,1,13.98,2,1,14.28,100,1,14.4,100,1,14.5,100,1,14.53,100,1,ARL,310031625
877,2025-07-17T15:50:09.205487416Z,2025-07-17T15:50:09.205322092Z,10,2,1108,C,A,-1,13.66,100,130,165324,259517973,13.04,2,1,13.03,100,1,13.02,100,1,12.73,100,1,12.71,100,1,12.5,700,1,12.46,200,2,12.43,700,1,12.42,700,1,12.37,700,1,13.61,15,1,13.64,200,2,13.65,15,1,13.93,100,1,13.98,2,1,14.28,100,1,14.4,100,1,14.5,100,1,14.53,100,1,14.54,100,1,ARL,309922345
878,2025-07-17T15:50:09.330738153Z,2025-07-17T15:50:09.330572653Z,10,2,1108,C,A,1,13.64,100,0,165500,259522708,13.04,2,1,13.03,100,1,13.02,100,1,12.73,100,1,12.71,100,1,12.5,700,1,12.46,200,2,12.43,700,1,12.42,700,1,12.37,700,1,13.61,15,1,13.64,100,1,13.65,15,1,13.93,100,1,13.98,2,1,14.28,100,1,14.4,100,1,14.5,100,1,14.53,100,1,14.54,100,1,ARL,309903973
879,2025-07-17T15:50:09.330738153Z,2025-07-17T15:50:09.330572653Z,10,2,1108,A,A,1,13.62,100,130,165500,259522708,13.04,2,1,13.03,100,1,13.02,100,1,12.73,100,1,12.71,100,1,12.5,700,1,12.46,200,2,12.43,700,1,12.42,700,1,12.37,700,1,13.61,15,1,13.62,100,1,13.64,100,1,13.65,15,1,13.93,100,1,13.98,2,1,14.28,100,1,14.4,100,1,14.5,100,1,14.53,100,1,ARL,310037965
880,2025-07-17T15:50:20.204539185Z,2025-07-17T15:50:20.204373858Z,10,2,1108,C,A,-1,13.65,15,130,165327,259737768,13.04,2,1,13.03,100,1,13.02,100,1,12.73,100,1,12.71,100,1,12.5,700,1,12.46,200,2,12.43,700,1,12.42,700,1,12.37,700,1,13.61,15,1,13.62,100,1,13.64,100,1,13.93,100,1,13.98,2,1,14.28,100,1,14.4,100,1,14.5,100,1,14.53,100,1,14.54,100,1,ARL,309707269
881,2025-07-17T15:50:25.935579034Z,2025-07-17T15:50:25.935412900Z,10,2,1108,A,A,0,13.59,15,128,166134,259828644,13.04,2,1,13.03,100,1,13.02,100,1,12.73,100,1,12.71,100,1,12.5,700,1,12.46,200,2,12.43,700,1,12.42,700,1,12.37,700,1,13.59,15,1,13.61,15,1,13.62,100,1,13.64,100,1,13.93,100,1,13.98,2,1,14.28,100,1,14.4,100,1,14.5,100,1,14.53,100,1,ARL,310424077
882,2025-07-17T15:50:26.954828150Z,2025-07-17T15:50:26.954662143Z,10,2,1108,C,A,-1,13.62,100,0,166007,259847181,13.04,2,1,13.03,100,1,13.02,100,1,12.73,100,1,12.71,100,1,12.5,700,1,12.46,200,2,12.43,700,1,12.42,700,1,12.37,700,1,13.59,15,1,13.61,15,1,13.64,100,1,13.93,100,1,13.98,2,1,14.28,100,1,14.4,100,1,14.5,100,1,14.53,100,1,14.54,100,1,ARL,310037965
883,2025-07-17T15:50:26.954828150Z,2025-07-17T15:50:26.954662143Z,10,2,1108,A,A,1,13.6,100,130,166007,259847181,13.04,2,1,13.03,100,1,13.02,100,1,12.73,100,1,12.71,100,1,12.5,700,1,12.46,200,2,12.43,700,1,12.42,700,1,12.37,700,1,13.59,15,1,13.6,100,1,13.61,15,1,13.64,100,1,13.93,100,1,13.98,2,1,14.28,100,1,14.4,100,1,14.5,100,1,14.53,100,1,ARL,310446249
884,2025-07-17T15:50:30.046879569Z,2025-07-17T15:50:30.046714265Z,10,2,1108,C,A,-1,13.59,15,130,165304,259916670,13.04,2,1,13.03,100,1,13.02,100,1,12.73,100,1,12.71,100,1,12.5,700,1,12.46,200,2,12.43,700,1,12.42,700,1,12.37,700,1,13.6,100,1,13.61,15,1,13.64,100,1,13.93,100,1,13.98,2,1,14.28,100,1,14.4,100,1,14.5,100,1,14.53,100,1,14.54,100,1,ARL,310424077
885,2025-07-17T15:50:30.047015114Z,2025-07-17T15:50:30.046849726Z,10,2,1108,C,A,-1,13.61,15,130,165388,259916674,13.04,2,1,13.03,100,1,13.02,100,1,12.73,100,1,12.71,100,1,12.5,700,1,12.46,200,2,12.43,700,1,12.42,700,1,12.37,700,1,13.6,100,1,13.64,100,1,13.93,100,1,13.98,2,1,14.28,100,1,14.4,100,1,14.5,100,1,14.53,100,1,14.54,100,1,14.56,800,2,ARL,310030465
886,2025-07-17T15:51:37.986158330Z,2025-07-17T15:51:37.985992174Z,10,2,1108,C,A,-1,13.98,2,0,166156,261130345,13.04,2,1,13.03,100,1,13.02,100,1,12.73,100,1,12.71,100,1,12.5,700,1,12.46,200,2,12.43,700,1,12.42,700,1,12.37,700,1,13.6,100,1,13.64,100,1,13.93,100,1,14.28,100,1,14.4,100,1,14.5,100,1,14.53,100,1,14.54,100,1,14.56,800,2,14.6,700,1,ARL,309091513
887,2025-07-17T15:51:37.986158330Z,2025-07-17T15:51:37.985992174Z,10,2,1108,A,A,2,13.89,2,130,166156,261130345,13.04,2,1,13.03,100,1,13.02,100,1,12.73,100,1,12.71,100,1,12.5,700,1,12.46,200,2,12.43,700,1,12.42,700,1,12.37,700,1,13.6,100,1,13.64,100,1,13.89,2,1,13.93,100,1,14.28,100,1,14.4,100,1,14.5,100,1,14.53,100,1,14.54,100,1,14.56,800,2,ARL,311979125
888,2025-07-17T15:52:16.372434625Z,2025-07-17T15:52:16.372269170Z,10,2,1108,C,A,-1,13.6,100,130,165455,261713790,13.04,2,1,13.03,100,1,13.02,100,1,12.73,100,1,12.71,100,1,12.5,700,1,12.46,200,2,12.43,700,1,12.42,700,1,12.37,700,1,13.64,100,1,13.89,2,1,13.93,100,1,14.28,100,1,14.4,100,1,14.5,100,1,14.53,100,1,14.54,100,1,14.56,800,2,14.6,700,1,ARL,310446249
889,2025-07-17T15:52:16.374353159Z,2025-07-17T15:52:16.374186508Z,10,2,1108,C,A,-1,13.64,100,130,166651,261713870,13.04,2,1,13.03,100,1,13.02,100,1,12.73,100,1,12.71,100,1,12.5,700,1,12.46,200,2,12.43,700,1,12.42,700,1,12.37,700,1,13.89,2,1,13.93,100,1,14.28,100,1,14.4,100,1,14.5,100,1,14.53,100,1,14.54,100,1,14.56,800,2,14.6,700,1,14.66,200,2,ARL,310031625
890,2025-07-17T15:52:16.375388285Z,2025-07-17T15:52:16.375222836Z,10,2,1108,C,A,-1,14.54,100,0,165449,261713944,13.04,2,1,13.03,100,1,13.02,100,1,12.73,100,1,12.71,100,1,12.5,700,1,12.46,200,2,12.43,700,1,12.42,700,1,12.37,700,1,13.89,2,1,13.93,100,1,14.28,100,1,14.4,100,1,14.5,100,1,14.53,100,1,14.56,800,2,14.6,700,1,14.66,200,2,14.68,1400,2,ARL,309823025
891,2025-07-17T15:52:16.375414247Z,2025-07-17T15:52:16.375248654Z,10,2,1108,C,A,8,14.66,100,0,165593,261713945,13.04,2,1,13.03,100,1,13.02,100,1,12.73,100,1,12.71,100,1,12.5,700,1,12.46,200,2,12.43,700,1,12.42,700,1,12.37,700,1,13.89,2,1,13.93,100,1,14.28,100,1,14.4,100,1,14.5,100,1,14.53,100,1,14.56,800,2,14.6,700,1,14.66,100,1,14.68,1400,2,ARL,308901981
892,2025-07-17T15:52:16.375828154Z,2025-07-17T15:52:16.375662552Z,10,2,1108,C,A,-1,14.53,100,0,165602,261713959,13.04,2,1,13.03,100,1,13.02,100,1,12.73,100,1,12.71,100,1,12.5,700,1,12.46,200,2,12.43,700,1,12.42,700,1,12.37,700,1,13.89,2,1,13.93,100,1,14.28,100,1,14.4,100,1,14.5,100,1,14.56,800,2,14.6,700,1,14.66,100,1,14.68,1400,2,14.7,100,1,ARL,309899141
893,2025-07-17T15:52:16.378385943Z,2025-07-17T15:52:16.378220434Z,10,2,1108,C,A,-1,14.5,100,0,165509,261714145,13.04,2,1,13.03,100,1,13.02,100,1,12.73,100,1,12.71,100,1,12.5,700,1,12.46,200,2,12.43,700,1,12.42,700,1,12.37,700,1,13.89,2,1,13.93,100,1,14.28,100,1,14.4,100,1,14.56,800,2,14.6,700,1,14.66,100,1,14.68,1400,2,14.7,100,1,14.76,100,1,ARL,308903349
894,2025-07-17T15:52:16.378385943Z,2025-07-17T15:52:16.378220434Z,10,2,1108,A,A,9,14.72,100,130,165509,261714145,13.04,2,1,13.03,100,1,13.02,100,1,12.73,100,1,12.71,100,1,12.5,700,1,12.46,200,2,12.43,700,1,12.42,700,1,12.37,700,1,13.89,2,1,13.93,100,1,14.28,100,1,14.4,100,1,14.56,800,2,14.6,700,1,14.66,100,1,14.68,1400,2,14.7,100,1,14.72,100,1,ARL,312772061
895,2025-07-17T15:52:16.378870638Z,2025-07-17T15:52:16.378705201Z,10,2,1108,A,B,0,13.27,10,130,165437,261714171,13.27,10,1,13.04,2,1,13.03,100,1,13.02,100,1,12.73,100,1,12.71,100,1,12.5,700,1,12.46,200,2,12.43,700,1,12.42,700,1,13.89,2,1,13.93,100,1,14.28,100,1,14.4,100,1,14.56,800,2,14.6,700,1,14.66,100,1,14.68,1400,2,14.7,100,1,14.72,100,1,ARL,312772069
896,2025-07-17T15:52:16.378872385Z,2025-07-17T15:52:16.378707041Z,10,2,1108,A,A,0,13.86,15,130,165344,261714172,13.27,10,1,13.04,2,1,13.03,100,1,13.02,100,1,12.73,100,1,12.71,100,1,12.5,700,1,12.46,200,2,12.43,700,1,12.42,700,1,13.86,15,1,13.89,2,1,13.93,100,1,14.28,100,1,14.4,100,1,14.56,800,2,14.6,700,1,14.66,100,1,14.68,1400,2,14.7,100,1,ARL,312772073
897,2025-07-17T15:52:16.379127782Z,2025-07-17T15:52:16.378962330Z,10,2,1108,C,B,-1,13.02,100,0,165452,261714185,13.27,10,1,13.04,2,1,13.03,100,1,12.73,100,1,12.71,100,1,12.5,700,1,12.46,200,2,12.43,700,1,12.42,700,1,12.37,700,1,13.86,15,1,13.89,2,1,13.93,100,1,14.28,100,1,14.4,100,1,14.56,800,2,14.6,700,1,14.66,100,1,14.68,1400,2,14.7,100,1,ARL,309415429
898,2025-07-17T15:52:16.379127782Z,2025-07-17T15:52:16.378962330Z,10,2,1108,A,B,1,13.26,100,130,165452,261714185,13.27,10,1,13.26,100,1,13.04,2,1,13.03,100,1,12.73,100,1,12.71,100,1,12.5,700,1,12.46,200,2,12.43,700,1,12.42,700,1,13.86,15,1,13.89,2,1,13.93,100,1,14.28,100,1,14.4,100,1,14.56,800,2,14.6,700,1,14.66,100,1,14.68,1400,2,14.7,100,1,ARL,312772077
899,2025-07-17T15:52:16.389025469Z,2025-07-17T15:52:16.388859982Z,10,2,1108,C,A,-1,13.93,100,130,165487,261714477,13.27,10,1,13.26,100,1,13.04,2,1,13.03,100,1,12.73,100,1,12.71,100,1,12.5,700,1,12.46,200,2,12.43,700,1,12.42,700,1,13.86,15,1,13.89,2,1,14.28,100,1,14.4,100,1,14.56,800,2,14.6,700,1,14.66,100,1,14.68,1400,2,14.7,100,1,14.72,100,1,ARL,309782973
900,2025-07-17T15:52:16.389082451Z,2025-07-17T15:52:16.388917108Z,10,2,1108,A,A,2,14.19,100,130,165343,261714481,13.27,10,1,13.26,100,1,13.04,2,1,13.03,100,1,12.73,100,1,12.71,100,1,12.5,700,1,12.46,200,2,12.43,700,1,12.42,700,1,13.86,15,1,13.89,2,1,14.19,100,1,14.28,100,1,14.4,100,1,14.56,800,2,14.6,700,1,14.66,100,1,14.68,1400,2,14.7,100,1,ARL,312772501
901,2025-07-17T15:52:16.396174502Z,2025-07-17T15:52:16.396008715Z,10,2,1108,C,A,-1,14.66,100,0,165787,261714603,13.27,10,1,13.26,100,1,13.04,2,1,13.03,100,1,12.73,100,1,12.71,100,1,12.5,700,1,12.46,200,2,12.43,700,1,12.42,700,1,13.86,15,1,13.89,2,1,14.19,100,1,14.28,100,1,14.4,100,1,14.56,800,2,14.6,700,1,14.68,1400,2,14.7,100,1,14.72,100,1,ARL,308903001
902,2025-07-17T15:52:16.397677681Z,2025-07-17T15:52:16.397512710Z,10,2,1108,C,A,-1,14.19,100,130,164971,261714619,13.27,10,1,13.26,100,1,13.04,2,1,13.03,100,1,12.73,100,1,12.71,100,1,12.5,700,1,12.46,200,2,12.43,700,1,12.42,700,1,13.86,15,1,13.89,2,1,14.28,100,1,14.4,100,1,14.56,800,2,14.6,700,1,14.68,1400,2,14.7,100,1,14.72,100,1,14.76,100,1,ARL,312772501
903,2025-07-17T15:52:16.397727042Z,2025-07-17T15:52:16.397561691Z,10,2,1108,A,A,2,14.26,100,130,165351,261714620,13.27,10,1,13.26,100,1,13.04,2,1,13.03,100,1,12.73,100,1,12.71,100,1,12.5,700,1,12.46,200,2,12.43,700,1,12.42,700,1,13.86,15,1,13.89,2,1,14.26,100,1,14.28,100,1,14.4,100,1,14.56,800,2,14.6,700,1,14.68,1400,2,14.7,100,1,14.72,100,1,ARL,312772901
904,2025-07-17T15:52:16.424137423Z,2025-07-17T15:52:16.423972000Z,10,2,1108,C,A,-1,14.7,100,0,165423,261714976,13.27,10,1,13.26,100,1,13.04,2,1,13.03,100,1,12.73,100,1,12.71,100,1,12.5,700,1,12.46,200,2,12.43,700,1,12.42,700,1,13.86,15,1,13.89,2,1,14.26,100,1,14.28,100,1,14.4,100,1,14.56,800,2,14.6,700,1,14.68,1400,2,14.72,100,1,14.76,100,1,ARL,312771573
905,2025-07-17T15:52:16.464781343Z,2025-07-17T15:52:16.464616142Z,10,2,1108,A,A,1,13.87,100,130,165201,261715303,13.27,10,1,13.26,100,1,13.04,2,1,13.03,100,1,12.73,100,1,12.71,100,1,12.5,700,1,12.46,200,2,12.43,700,1,12.42,700,1,13.86,15,1,13.87,100,1,13.89,2,1,14.26,100,1,14.28,100,1,14.4,100,1,14.56,800,2,14.6,700,1,14.68,1400,2,14.72,100,1,ARL,312773881
906,2025-07-17T15:52:16.480090894Z,2025-07-17T15:52:16.479925781Z,10,2,1108,C,A,-1,14.26,100,130,165113,261715467,13.27,10,1,13.26,100,1,13.04,2,1,13.03,100,1,12.73,100,1,12.71,100,1,12.5,700,1,12.46,200,2,12.43,700,1,12.42,700,1,13.86,15,1,13.87,100,1,13.89,2,1,14.28,100,1,14.4,100,1,14.56,800,2,14.6,700,1,14.68,1400,2,14.72,100,1,14.76,100,1,ARL,312772901
907,2025-07-17T15:52:16.480140131Z,2025-07-17T15:52:16.479974840Z,10,2,1108,A,A,3,14.15,100,130,165291,261715468,13.27,10,1,13.26,100,1,13.04,2,1,13.03,100,1,12.73,100,1,12.71,100,1,12.5,700,1,12.46,200,2,12.43,700,1,12.42,700,1,13.86,15,1,13.87,100,1,13.89,2,1,14.15,100,1,14.28,100,1,14.4,100,1,14.56,800,2,14.6,700,1,14.68,1400,2,14.72,100,1,ARL,312774033
908,2025-07-17T15:52:28.787316865Z,2025-07-17T15:52:28.787151494Z,10,2,1108,C,B,-1,13.27,10,130,165371,261883294,13.26,100,1,13.04,2,1,13.03,100,1,12.73,100,1,12.71,100,1,12.5,700,1,12.46,200,2,12.43,700,1,12.42,700,1,12.37,700,1,13.86,15,1,13.87,100,1,13.89,2,1,14.15,100,1,14.28,100,1,14.4,100,1,14.56,800,2,14.6,700,1,14.68,1400,2,14.72,100,1,ARL,312772069
909,2025-07-17T15:52:28.787317827Z,2025-07-17T15:52:28.787152437Z,10,2,1108,C,A,-1,13.86,15,130,165390,261883295,13.26,100,1,13.04,2,1,13.03,100,1,12.73,100,1,12.71,100,1,12.5,700,1,12.46,200,2,12.43,700,1,12.42,700,1,12.37,700,1,13.87,100,1,13.89,2,1,14.15,100,1,14.28,100,1,14.4,100,1,14.56,800,2,14.6,700,1,14.68,1400,2,14.72,100,1,14.76,100,1,ARL,312772073
910,2025-07-17T15:52:43.128371033Z,2025-07-17T15:52:43.128203357Z,10,2,1108,C,A,-1,13.89,2,0,167676,262115170,13.26,100,1,13.04,2,1,13.03,100,1,12.73,100,1,12.71,100,1,12.5,700,1,12.46,200,2,12.43,700,1,12.42,700,1,12.37,700,1,13.87,100,1,14.15,100,1,14.28,100,1,14.4,100,1,14.56,800,2,14.6,700,1,14.68,1400,2,14.72,100,1,14.76,100,1,14.81,100,1,ARL,311979125
911,2025-07-17T15:52:43.128371033Z,2025-07-17T15:52:43.128203357Z,10,2,1108,A,A,1,13.99,2,128,167676,262115170,13.26,100,1,13.04,2,1,13.03,100,1,12.73,100,1,12.71,100,1,12.5,700,1,12.46,200,2,12.43,700,1,12.42,700,1,12.37,700,1,13.87,100,1,13.99,2,1,14.15,100,1,14.28,100,1,14.4,100,1,14.56,800,2,14.6,700,1,14.68,1400,2,14.72,100,1,14.76,100,1,ARL,313336713
912,2025-07-17T15:54:24.908483782Z,2025-07-17T15:54:24.908318259Z,10,2,1108,A,B,0,13.29,10,130,165523,263863872,13.29,10,1,13.26,100,1,13.04,2,1,13.03,100,1,12.73,100,1,12.71,100,1,12.5,700,1,12.46,200,2,12.43,700,1,12.42,700,1,13.87,100,1,13.99,2,1,14.15,100,1,14.28,100,1,14.4,100,1,14.56,800,2,14.6,700,1,14.68,1400,2,14.72,100,1,14.76,100,1,ARL,315581981
913,2025-07-17T15:54:26.792478456Z,2025-07-17T15:54:26.792313320Z,10,2,1108,C,B,-1,13.29,10,130,165136,263895481,13.26,100,1,13.04,2,1,13.03,100,1,12.73,100,1,12.71,100,1,12.5,700,1,12.46,200,2,12.43,700,1,12.42,700,1,12.37,700,1,13.87,100,1,13.99,2,1,14.15,100,1,14.28,100,1,14.4,100,1,14.56,800,2,14.6,700,1,14.68,1400,2,14.72,100,1,14.76,100,1,ARL,315581981
914,2025-07-17T15:54:52.986116083Z,2025-07-17T15:54:52.985950259Z,10,2,1108,C,A,-1,13.99,2,0,165824,264262615,13.26,100,1,13.04,2,1,13.03,100,1,12.73,100,1,12.71,100,1,12.5,700,1,12.46,200,2,12.43,700,1,12.42,700,1,12.37,700,1,13.87,100,1,14.15,100,1,14.28,100,1,14.4,100,1,14.56,800,2,14.6,700,1,14.68,1400,2,14.72,100,1,14.76,100,1,14.81,100,1,ARL,313336713
915,2025-07-17T15:54:52.986116083Z,2025-07-17T15:54:52.985950259Z,10,2,1108,A,A,1,14.1,2,130,165824,264262615,13.26,100,1,13.04,2,1,13.03,100,1,12.73,100,1,12.71,100,1,12.5,700,1,12.46,200,2,12.43,700,1,12.42,700,1,12.37,700,1,13.87,100,1,14.1,2,1,14.15,100,1,14.28,100,1,14.4,100,1,14.56,800,2,14.6,700,1,14.68,1400,2,14.72,100,1,14.76,100,1,ARL,316098525
916,2025-07-17T15:55:33.673598252Z,2025-07-17T15:55:33.673432762Z,10,2,1108,A,B,0,13.29,10,130,165490,264905534,13.29,10,1,13.26,100,1,13.04,2,1,13.03,100,1,12.73,100,1,12.71,100,1,12.5,700,1,12.46,200,2,12.43,700,1,12.42,700,1,13.87,100,1,14.1,2,1,14.15,100,1,14.28,100,1,14.4,100,1,14.56,800,2,14.6,700,1,14.68,1400,2,14.72,100,1,14.76,100,1,ARL,316911465
917,2025-07-17T15:55:34.257417204Z,2025-07-17T15:55:34.257251787Z,10,2,1108,C,B,-1,13.26,100,0,165417,264919835,13.29,10,1,13.04,2,1,13.03,100,1,12.73,100,1,12.71,100,1,12.5,700,1,12.46,200,2,12.43,700,1,12.42,700,1,12.37,700,1,13.87,100,1,14.1,2,1,14.15,100,1,14.28,100,1,14.4,100,1,14.56,800,2,14.6,700,1,14.68,1400,2,14.72,100,1,14.76,100,1,ARL,312772077
918,2025-07-17T15:55:34.257417204Z,2025-07-17T15:55:34.257251787Z,10,2,1108,A,B,1,13.28,100,130,165417,264919835,13.29,10,1,13.28,100,1,13.04,2,1,13.03,100,1,12.73,100,1,12.71,100,1,12.5,700,1,12.46,200,2,12.43,700,1,12.42,700,1,13.87,100,1,14.1,2,1,14.15,100,1,14.28,100,1,14.4,100,1,14.56,800,2,14.6,700,1,14.68,1400,2,14.72,100,1,14.76,100,1,ARL,316924721
919,2025-07-17T15:55:40.197750400Z,2025-07-17T15:55:40.197584524Z,10,2,1108,C,B,-1,13.29,10,130,165876,265015966,13.28,100,1,13.04,2,1,13.03,100,1,12.73,100,1,12.71,100,1,12.5,700,1,12.46,200,2,12.43,700,1,12.42,700,1,12.37,700,1,13.87,100,1,14.1,2,1,14.15,100,1,14.28,100,1,14.4,100,1,14.56,800,2,14.6,700,1,14.68,1400,2,14.72,100,1,14.76,100,1,ARL,316911465
920,2025-07-17T15:57:51.328863560Z,2025-07-17T15:57:51.328698198Z,10,2,1108,C,A,-1,13.87,100,130,165362,267272430,13.28,100,1,13.04,2,1,13.03,100,1,12.73,100,1,12.71,100,1,12.5,700,1,12.46,200,2,12.43,700,1,12.42,700,1,12.37,700,1,14.1,2,1,14.15,100,1,14.28,100,1,14.4,100,1,14.56,800,2,14.6,700,1,14.68,1400,2,14.72,100,1,14.76,100,1,14.81,100,1,ARL,312773881
921,2025-07-17T15:57:51.329857672Z,2025-07-17T15:57:51.329692071Z,10,2,1108,C,A,-1,14.76,100,0,165601,267272442,13.28,100,1,13.04,2,1,13.03,100,1,12.73,100,1,12.71,100,1,12.5,700,1,12.46,200,2,12.43,700,1,12.42,700,1,12.37,700,1,14.1,2,1,14.15,100,1,14.28,100,1,14.4,100,1,14.56,800,2,14.6,700,1,14.68,1400,2,14.72,100,1,14.81,100,1,14.89,100,1,ARL,312771829
922,2025-07-17T15:57:51.329857672Z,2025-07-17T15:57:51.329692071Z,10,2,1108,A,A,9,14.89,100,130,165601,267272442,13.28,100,1,13.04,2,1,13.03,100,1,12.73,100,1,12.71,100,1,12.5,700,1,12.46,200,2,12.43,700,1,12.42,700,1,12.37,700,1,14.1,2,1,14.15,100,1,14.28,100,1,14.4,100,1,14.56,800,2,14.6,700,1,14.68,1400,2,14.72,100,1,14.81,100,1,14.89,200,2,ARL,319985025
923,2025-07-17T15:57:51.339328219Z,2025-07-17T15:57:51.339162512Z,10,2,1108,C,A,-1,14.15,100,130,165707,267272660,13.28,100,1,13.04,2,1,13.03,100,1,12.73,100,1,12.71,100,1,12.5,700,1,12.46,200,2,12.43,700,1,12.42,700,1,12.37,700,1,14.1,2,1,14.28,100,1,14.4,100,1,14.56,800,2,14.6,700,1,14.68,1400,2,14.72,100,1,14.81,100,1,14.89,200,2,14.96,100,1,ARL,312774033
924,2025-07-17T15:57:51.339382098Z,2025-07-17T15:57:51.339216923Z,10,2,1108,A,A,1,14.26,100,130,165175,267272665,13.28,100,1,13.04,2,1,13.03,100,1,12.73,100,1,12.71,100,1,12.5,700,1,12.46,200,2,12.43,700,1,12.42,700,1,12.37,700,1,14.1,2,1,14.26,100,1,14.28,100,1,14.4,100,1,14.56,800,2,14.6,700,1,14.68,1400,2,14.72,100,1,14.81,100,1,14.89,200,2,ARL,319985165
925,2025-07-17T15:57:52.378369524Z,2025-07-17T15:57:52.378204338Z,10,2,1108,A,A,1,14.11,100,130,165186,267283873,13.28,100,1,13.04,2,1,13.03,100,1,12.73,100,1,12.71,100,1,12.5,700,1,12.46,200,2,12.43,700,1,12.42,700,1,12.37,700,1,14.1,2,1,14.11,100,1,14.26,100,1,14.28,100,1,14.4,100,1,14.56,800,2,14.6,700,1,14.68,1400,2,14.72,100,1,14.81,100,1,ARL,320000233
926,2025-07-17T15:58:14.483909354Z,2025-07-17T15:58:14.483743947Z,10,2,1108,A,A,0,13.76,4,130,165407,267657011,13.28,100,1,13.04,2,1,13.03,100,1,12.73,100,1,12.71,100,1,12.5,700,1,12.46,200,2,12.43,700,1,12.42,700,1,12.37,700,1,13.76,4,1,14.1,2,1,14.11,100,1,14.26,100,1,14.28,100,1,14.4,100,1,14.56,800,2,14.6,700,1,14.68,1400,2,14.72,100,1,ARL,320484625
927,2025-07-17T15:58:14.484164551Z,2025-07-17T15:58:14.483999049Z,10,2,1108,C,A,-1,14.11,100,0,165502,267657013,13.28,100,1,13.04,2,1,13.03,100,1,12.73,100,1,12.71,100,1,12.5,700,1,12.46,200,2,12.43,700,1,12.42,700,1,12.37,700,1,13.76,4,1,14.1,2,1,14.26,100,1,14.28,100,1,14.4,100,1,14.56,800,2,14.6,700,1,14.68,1400,2,14.72,100,1,14.81,100,1,ARL,320000233
928,2025-07-17T15:58:14.484164551Z,2025-07-17T15:58:14.483999049Z,10,2,1108,A,A,1,13.77,100,130,165502,267657013,13.28,100,1,13.04,2,1,13.03,100,1,12.73,100,1,12.71,100,1,12.5,700,1,12.46,200,2,12.43,700,1,12.42,700,1,12.37,700,1,13.76,4,1,13.77,100,1,14.1,2,1,14.26,100,1,14.28,100,1,14.4,100,1,14.56,800,2,14.6,700,1,14.68,1400,2,14.72,100,1,ARL,320484637
929,2025-07-17T15:58:14.484183413Z,2025-07-17T15:58:14.484017806Z,10,2,1108,C,B,-1,13.28,100,130,165607,267657014,13.04,2,1,13.03,100,1,12.73,100,1,12.71,100,1,12.5,700,1,12.46,200,2,12.43,700,1,12.42,700,1,12.37,700,1,12.36,200,2,13.76,4,1,13.77,100,1,14.1,2,1,14.26,100,1,14.28,100,1,14.4,100,1,14.56,800,2,14.6,700,1,14.68,1400,2,14.72,100,1,ARL,316924721
930,2025-07-17T15:58:14.484312532Z,2025-07-17T15:58:14.484147359Z,10,2,1108,A,A,2,13.79,100,130,165173,267657020,13.04,2,1,13.03,100,1,12.73,100,1,12.71,100,1,12.5,700,1,12.46,200,2,12.43,700,1,12.42,700,1,12.37,700,1,12.36,200,2,13.76,4,1,13.77,100,1,13.79,100,1,14.1,2,1,14.26,100,1,14.28,100,1,14.4,100,1,14.56,800,2,14.6,700,1,14.68,1400,2,ARL,320484661
931,2025-07-17T15:58:14.484927848Z,2025-07-17T15:58:14.484761664Z,10,2,1108,C,A,-1,13.76,4,128,166184,267657070,13.04,2,1,13.03,100,1,12.73,100,1,12.71,100,1,12.5,700,1,12.46,200,2,12.43,700,1,12.42,700,1,12.37,700,1,12.36,200,2,13.77,100,1,13.79,100,1,14.1,2,1,14.26,100,1,14.28,100,1,14.4,100,1,14.56,800,2,14.6,700,1,14.68,1400,2,14.72,100,1,ARL,320484625
932,2025-07-17T15:58:14.484963870Z,2025-07-17T15:58:14.484798779Z,10,2,1108,C,A,-1,13.77,100,130,165091,267657073,13.04,2,1,13.03,100,1,12.73,100,1,12.71,100,1,12.5,700,1,12.46,200,2,12.43,700,1,12.42,700,1,12.37,700,1,12.36,200,2,13.79,100,1,14.1,2,1,14.26,100,1,14.28,100,1,14.4,100,1,14.56,800,2,14.6,700,1,14.68,1400,2,14.72,100,1,14.81,100,1,ARL,320484637
933,2025-07-17T15:58:14.485392903Z,2025-07-17T15:58:14.485227487Z,10,2,1108,C,A,-1,14.81,100,0,165416,267657092,13.04,2,1,13.03,100,1,12.73,100,1,12.71,100,1,12.5,700,1,12.46,200,2,12.43,700,1,12.42,700,1,12.37,700,1,12.36,200,2,13.79,100,1,14.1,2,1,14.26,100,1,14.28,100,1,14.4,100,1,14.56,800,2,14.6,700,1,14.68,1400,2,14.72,100,1,14.84,100,1,ARL,312771781
934,2025-07-17T15:58:14.485392903Z,2025-07-17T15:58:14.485227487Z,10,2,1108,A,A,7,14.68,100,130,165416,267657092,13.04,2,1,13.03,100,1,12.73,100,1,12.71,100,1,12.5,700,1,12.46,200,2,12.43,700,1,12.42,700,1,12.37,700,1,12.36,200,2,13.79,100,1,14.1,2,1,14.26,100,1,14.28,100,1,14.4,100,1,14.56,800,2,14.6,700,1,14.68,1500,3,14.72,100,1,14.84,100,1,ARL,320484781
935,2025-07-17T15:58:14.485850874Z,2025-07-17T15:58:14.485685308Z,10,2,1108,A,A,9,14.76,100,130,165566,267657098,13.04,2,1,13.03,100,1,12.73,100,1,12.71,100,1,12.5,700,1,12.46,200,2,12.43,700,1,12.42,700,1,12.37,700,1,12.36,200,2,13.79,100,1,14.1,2,1,14.26,100,1,14.28,100,1,14.4,100,1,14.56,800,2,14.6,700,1,14.68,1500,3,14.72,100,1,14.76,100,1,ARL,320484821
936,2025-07-17T15:58:14.485989643Z,2025-07-17T15:58:14.485824228Z,10,2,1108,A,A,8,14.69,100,130,165415,267657101,13.04,2,1,13.03,100,1,12.73,100,1,12.71,100,1,12.5,700,1,12.46,200,2,12.43,700,1,12.42,700,1,12.37,700,1,12.36,200,2,13.79,100,1,14.1,2,1,14.26,100,1,14.28,100,1,14.4,100,1,14.56,800,2,14.6,700,1,14.68,1500,3,14.69,100,1,14.72,100,1,ARL,320484825
937,2025-07-17T15:58:14.508177256Z,2025-07-17T15:58:14.508012098Z,10,2,1108,C,A,-1,14.26,100,130,165158,267657330,13.04,2,1,13.03,100,1,12.73,100,1,12.71,100,1,12.5,700,1,12.46,200,2,12.43,700,1,12.42,700,1,12.37,700,1,12.36,200,2,13.79,100,1,14.1,2,1,14.28,100,1,14.4,100,1,14.56,800,2,14.6,700,1,14.68,1500,3,14.69,100,1,14.72,100,1,14.76,100,1,ARL,319985165
938,2025-07-17T15:58:14.508227890Z,2025-07-17T15:58:14.508062605Z,10,2,1108,A,A,1,14.05,100,130,165285,267657333,13.04,2,1,13.03,100,1,12.73,100,1,12.71,100,1,12.5,700,1,12.46,200,2,12.43,700,1,12.42,700,1,12.37,700,1,12.36,200,2,13.79,100,1,14.05,100,1,14.1,2,1,14.28,100,1,14.4,100,1,14.56,800,2,14.6,700,1,14.68,1500,3,14.69,100,1,14.72,100,1,ARL,320484985
939,2025-07-17T15:58:14.529557108Z,2025-07-17T15:58:14.529391743Z,10,2,1108,A,B,2,13.02,100,130,165365,267657561,13.04,2,1,13.03,100,1,13.02,100,1,12.73,100,1,12.71,100,1,12.5,700,1,12.46,200,2,12.43,700,1,12.42,700,1,12.37,700,1,13.79,100,1,14.05,100,1,14.1,2,1,14.28,100,1,14.4,100,1,14.56,800,2,14.6,700,1,14.68,1500,3,14.69,100,1,14.72,100,1,ARL,320485385
940,2025-07-17T15:58:14.529578291Z,2025-07-17T15:58:14.529413184Z,10,2,1108,A,A,1,13.8,100,130,165107,267657562,13.04,2,1,13.03,100,1,13.02,100,1,12.73,100,1,12.71,100,1,12.5,700,1,12.46,200,2,12.43,700,1,12.42,700,1,12.37,700,1,13.79,100,1,13.8,100,1,14.05,100,1,14.1,2,1,14.28,100,1,14.4,100,1,14.56,800,2,14.6,700,1,14.68,1500,3,14.69,100,1,ARL,320485389
941,2025-07-17T15:58:14.659899426Z,2025-07-17T15:58:14.659734381Z,10,2,1108,C,A,-1,13.79,100,130,165045,267658873,13.04,2,1,13.03,100,1,13.02,100,1,12.73,100,1,12.71,100,1,12.5,700,1,12.46,200,2,12.43,700,1,12.42,700,1,12.37,700,1,13.8,100,1,14.05,100,1,14.1,2,1,14.28,100,1,14.4,100,1,14.56,800,2,14.6,700,1,14.68,1500,3,14.69,100,1,14.72,100,1,ARL,320484661
942,2025-07-17T15:58:14.659939230Z,2025-07-17T15:58:14.659773896Z,10,2,1108,C,A,-1,13.8,100,130,165334,267658879,13.04,2,1,13.03,100,1,13.02,100,1,12.73,100,1,12.71,100,1,12.5,700,1,12.46,200,2,12.43,700,1,12.42,700,1,12.37,700,1,14.05,100,1,14.1,2,1,14.28,100,1,14.4,100,1,14.56,800,2,14.6,700,1,14.68,1500,3,14.69,100,1,14.72,100,1,14.76,100,1,ARL,320485389
943,2025-07-17T15:58:14.672315806Z,2025-07-17T15:58:14.672150755Z,10,2,1108,C,A,-1,14.05,100,130,165051,267658982,13.04,2,1,13.03,100,1,13.02,100,1,12.73,100,1,12.71,100,1,12.5,700,1,12.46,200,2,12.43,700,1,12.42,700,1,12.37,700,1,14.1,2,1,14.28,100,1,14.4,100,1,14.56,800,2,14.6,700,1,14.68,1500,3,14.69,100,1,14.72,100,1,14.76,100,1,14.89,100,1,ARL,320484985
944,2025-07-17T15:58:14.672365974Z,2025-07-17T15:58:14.672200872Z,10,2,1108,A,A,1,14.12,100,130,165102,267658983,13.04,2,1,13.03,100,1,13.02,100,1,12.73,100,1,12.71,100,1,12.5,700,1,12.46,200,2,12.43,700,1,12.42,700,1,12.37,700,1,14.1,2,1,14.12,100,1,14.28,100,1,14.4,100,1,14.56,800,2,14.6,700,1,14.68,1500,3,14.69,100,1,14.72,100,1,14.76,100,1,ARL,320487017
945,2025-07-17T15:58:14.673184116Z,2025-07-17T15:58:14.673019194Z,10,2,1108,C,A,-1,14.12,100,130,164922,267658989,13.04,2,1,13.03,100,1,13.02,100,1,12.73,100,1,12.71,100,1,12.5,700,1,12.46,200,2,12.43,700,1,12.42,700,1,12.37,700,1,14.1,2,1,14.28,100,1,14.4,100,1,14.56,800,2,14.6,700,1,14.68,1500,3,14.69,100,1,14.72,100,1,14.76,100,1,14.89,100,1,ARL,320487017
946,2025-07-17T15:58:14.673230480Z,2025-07-17T15:58:14.673065320Z,10,2,1108,A,A,1,14.26,100,130,165160,267658990,13.04,2,1,13.03,100,1,13.02,100,1,12.73,100,1,12.71,100,1,12.5,700,1,12.46,200,2,12.43,700,1,12.42,700,1,12.37,700,1,14.1,2,1,14.26,100,1,14.28,100,1,14.4,100,1,14.56,800,2,14.6,700,1,14.68,1500,3,14.69,100,1,14.72,100,1,14.76,100,1,ARL,320487025
947,2025-07-17T15:58:14.682945541Z,2025-07-17T15:58:14.682780396Z,10,2,1108,C,A,-1,14.76,100,0,165145,267659018,13.04,2,1,13.03,100,1,13.02,100,1,12.73,100,1,12.71,100,1,12.5,700,1,12.46,200,2,12.43,700,1,12.42,700,1,12.37,700,1,14.1,2,1,14.26,100,1,14.28,100,1,14.4,100,1,14.56,800,2,14.6,700,1,14.68,1500,3,14.69,100,1,14.72,100,1,14.89,100,1,ARL,320484821
948,2025-07-17T15:58:15.564070256Z,2025-07-17T15:58:15.563904700Z,10,2,1108,C,A,6,14.68,100,0,165556,267672469,13.04,2,1,13.03,100,1,13.02,100,1,12.73,100,1,12.71,100,1,12.5,700,1,12.46,200,2,12.43,700,1,12.42,700,1,12.37,700,1,14.1,2,1,14.26,100,1,14.28,100,1,14.4,100,1,14.56,800,2,14.6,700,1,14.68,1400,2,14.69,100,1,14.72,100,1,14.89,100,1,ARL,320484781
949,2025-07-17T15:58:15.564070256Z,2025-07-17T15:58:15.563904700Z,10,2,1108,A,A,9,14.87,100,130,165556,267672469,13.04,2,1,13.03,100,1,13.02,100,1,12.73,100,1,12.71,100,1,12.5,700,1,12.46,200,2,12.43,700,1,12.42,700,1,12.37,700,1,14.1,2,1,14.26,100,1,14.28,100,1,14.4,100,1,14.56,800,2,14.6,700,1,14.68,1400,2,14.69,100,1,14.72,100,1,14.87,100,1,ARL,320504473
950,2025-07-17T15:58:15.577719796Z,2025-07-17T15:58:15.577554368Z,10,2,1108,C,A,-1,14.69,100,0,165428,267672549,13.04,2,1,13.03,100,1,13.02,100,1,12.73,100,1,12.71,100,1,12.5,700,1,12.46,200,2,12.43,700,1,12.42,700,1,12.37,700,1,14.1,2,1,14.26,100,1,14.28,100,1,14.4,100,1,14.56,800,2,14.6,700,1,14.68,1400,2,14.72,100,1,14.87,100,1,14.89,100,1,ARL,320484825
951,2025-07-17T15:58:15.577719796Z,2025-07-17T15:58:15.577554368Z,10,2,1108,A,A,9,14.88,100,130,165428,267672549,13.04,2,1,13.03,100,1,13.02,100,1,12.73,100,1,12.71,100,1,12.5,700,1,12.46,200,2,12.43,700,1,12.42,700,1,12.37,700,1,14.1,2,1,14.26,100,1,14.28,100,1,14.4,100,1,14.56,800,2,14.6,700,1,14.68,1400,2,14.72,100,1,14.87,100,1,14.88,100,1,ARL,320504609
952,2025-07-17T15:58:16.502080515Z,2025-07-17T15:58:16.501915292Z,10,2,1108,A,A,1,14.11,100,130,165223,267685252,13.04,2,1,13.03,100,1,13.02,100,1,12.73,100,1,12.71,100,1,12.5,700,1,12.46,200,2,12.43,700,1,12.42,700,1,12.37,700,1,14.1,2,1,14.11,100,1,14.26,100,1,14.28,100,1,14.4,100,1,14.56,800,2,14.6,700,1,14.68,1400,2,14.72,100,1,14.87,100,1,ARL,320519893
953,2025-07-17T15:58:19.965200980Z,2025-07-17T15:58:19.965034325Z,10,2,1108,A,A,0,13.94,15,130,166655,267738403,13.04,2,1,13.03,100,1,13.02,100,1,12.73,100,1,12.71,100,1,12.5,700,1,12.46,200,2,12.43,700,1,12.42,700,1,12.37,700,1,13.94,15,1,14.1,2,1,14.11,100,1,14.26,100,1,14.28,100,1,14.4,100,1,14.56,800,2,14.6,700,1,14.68,1400,2,14.72,100,1,ARL,320588689
954,2025-07-17T15:58:20.237833402Z,2025-07-17T15:58:20.237668047Z,10,2,1108,C,A,-1,14.11,100,0,165355,267745213,13.04,2,1,13.03,100,1,13.02,100,1,12.73,100,1,12.71,100,1,12.5,700,1,12.46,200,2,12.43,700,1,12.42,700,1,12.37,700,1,13.94,15,1,14.1,2,1,14.26,100,1,14.28,100,1,14.4,100,1,14.56,800,2,14.6,700,1,14.68,1400,2,14.72,100,1,14.87,100,1,ARL,320519893
955,2025-07-17T15:58:20.237833402Z,2025-07-17T15:58:20.237668047Z,10,2,1108,A,A,1,13.95,100,130,165355,267745213,13.04,2,1,13.03,100,1,13.02,100,1,12.73,100,1,12.71,100,1,12.5,700,1,12.46,200,2,12.43,700,1,12.42,700,1,12.37,700,1,13.94,15,1,13.95,100,1,14.1,2,1,14.26,100,1,14.28,100,1,14.4,100,1,14.56,800,2,14.6,700,1,14.68,1400,2,14.72,100,1,ARL,320595817
956,2025-07-17T15:58:20.705512171Z,2025-07-17T15:58:20.705344578Z,10,2,1108,C,A,-1,13.94,15,128,167593,267754327,13.04,2,1,13.03,100,1,13.02,100,1,12.73,100,1,12.71,100,1,12.5,700,1,12.46,200,2,12.43,700,1,12.42,700,1,12.37,700,1,13.95,100,1,14.1,2,1,14.26,100,1,14.28,100,1,14.4,100,1,14.56,800,2,14.6,700,1,14.68,1400,2,14.72,100,1,14.87,100,1,ARL,320588689
957,2025-07-17T15:58:30.800053062Z,2025-07-17T15:58:30.799887713Z,10,2,1108,A,A,0,13.89,15,130,165349,267913947,13.04,2,1,13.03,100,1,13.02,100,1,12.73,100,1,12.71,100,1,12.5,700,1,12.46,200,2,12.43,700,1,12.42,700,1,12.37,700,1,13.89,15,1,13.95,100,1,14.1,2,1,14.26,100,1,14.28,100,1,14.4,100,1,14.56,800,2,14.6,700,1,14.68,1400,2,14.72,100,1,ARL,320833897
958,2025-07-17T15:58:30.905657319Z,2025-07-17T15:58:30.905491759Z,10,2,1108,C,A,-1,13.95,100,0,165560,267919515,13.04,2,1,13.03,100,1,13.02,100,1,12.73,100,1,12.71,100,1,12.5,700,1,12.46,200,2,12.43,700,1,12.42,700,1,12.37,700,1,13.89,15,1,14.1,2,1,14.26,100,1,14.28,100,1,14.4,100,1,14.56,800,2,14.6,700,1,14.68,1400,2,14.72,100,1,14.87,100,1,ARL,320595817
959,2025-07-17T15:58:30.905657319Z,2025-07-17T15:58:30.905491759Z,10,2,1108,A,A,1,13.9,100,130,165560,267919515,13.04,2,1,13.03,100,1,13.02,100,1,12.73,100,1,12.71,100,1,12.5,700,1,12.46,200,2,12.43,700,1,12.42,700,1,12.37,700,1,13.89,15,1,13.9,100,1,14.1,2,1,14.26,100,1,14.28,100,1,14.4,100,1,14.56,800,2,14.6,700,1,14.68,1400,2,14.72,100,1,ARL,320839125
960,2025-07-17T15:58:30.916726353Z,2025-07-17T15:58:30.916561264Z,10,2,1108,C,A,-1,14.26,100,130,165089,267919917,13.04,2,1,13.03,100,1,13.02,100,1,12.73,100,1,12.71,100,1,12.5,700,1,12.46,200,2,12.43,700,1,12.42,700,1,12.37,700,1,13.89,15,1,13.9,100,1,14.1,2,1,14.28,100,1,14.4,100,1,14.56,800,2,14.6,700,1,14.68,1400,2,14.72,100,1,14.87,100,1,ARL,320487025
961,2025-07-17T15:58:30.916784278Z,2025-07-17T15:58:30.916619122Z,10,2,1108,A,A,3,14.18,100,130,165156,267919919,13.04,2,1,13.03,100,1,13.02,100,1,12.73,100,1,12.71,100,1,12.5,700,1,12.46,200,2,12.43,700,1,12.42,700,1,12.37,700,1,13.89,15,1,13.9,100,1,14.1,2,1,14.18,100,1,14.28,100,1,14.4,100,1,14.56,800,2,14.6,700,1,14.68,1400,2,14.72,100,1,ARL,320839577
962,2025-07-17T15:58:40.799952243Z,2025-07-17T15:58:40.799787018Z,10,2,1108,A,A,0,13.83,15,130,165225,268074431,13.04,2,1,13.03,100,1,13.02,100,1,12.73,100,1,12.71,100,1,12.5,700,1,12.46,200,2,12.43,700,1,12.42,700,1,12.37,700,1,13.83,15,1,13.89,15,1,13.9,100,1,14.1,2,1,14.18,100,1,14.28,100,1,14.4,100,1,14.56,800,2,14.6,700,1,14.68,1400,2,ARL,321038033
963,2025-07-17T15:58:43.690244473Z,2025-07-17T15:58:43.690078924Z,10,2,1108,C,A,-1,13.9,100,0,165549,268115228,13.04,2,1,13.03,100,1,13.02,100,1,12.73,100,1,12.71,100,1,12.5,700,1,12.46,200,2,12.43,700,1,12.42,700,1,12.37,700,1,13.83,15,1,13.89,15,1,14.1,2,1,14.18,100,1,14.28,100,1,14.4,100,1,14.56,800,2,14.6,700,1,14.68,1400,2,14.72,100,1,ARL,320839125
964,2025-07-17T15:58:43.690244473Z,2025-07-17T15:58:43.690078924Z,10,2,1108,A,A,1,13.84,100,130,165549,268115228,13.04,2,1,13.03,100,1,13.02,100,1,12.73,100,1,12.71,100,1,12.5,700,1,12.46,200,2,12.43,700,1,12.42,700,1,12.37,700,1,13.83,15,1,13.84,100,1,13.89,15,1,14.1,2,1,14.18,100,1,14.28,100,1,14.4,100,1,14.56,800,2,14.6,700,1,14.68,1400,2,ARL,321096769
965,2025-07-17T15:58:44.903740109Z,2025-07-17T15:58:44.903574654Z,10,2,1108,A,A,0,13.83,100,130,165455,268129040,13.04,2,1,13.03,100,1,13.02,100,1,12.73,100,1,12.71,100,1,12.5,700,1,12.46,200,2,12.43,700,1,12.42,700,1,12.37,700,1,13.83,115,2,13.84,100,1,13.89,15,1,14.1,2,1,14.18,100,1,14.28,100,1,14.4,100,1,14.56,800,2,14.6,700,1,14.68,1400,2,ARL,321114473
966,2025-07-17T15:58:44.924114268Z,2025-07-17T15:58:44.923948853Z,10,2,1108,C,A,-1,14.18,100,130,165415,268129217,13.04,2,1,13.03,100,1,13.02,100,1,12.73,100,1,12.71,100,1,12.5,700,1,12.46,200,2,12.43,700,1,12.42,700,1,12.37,700,1,13.83,115,2,13.84,100,1,13.89,15,1,14.1,2,1,14.28,100,1,14.4,100,1,14.56,800,2,14.6,700,1,14.68,1400,2,14.72,100,1,ARL,320839577
967,2025-07-17T15:58:44.924165875Z,2025-07-17T15:58:44.924000519Z,10,2,1108,A,A,4,14.11,100,130,165356,268129218,13.04,2,1,13.03,100,1,13.02,100,1,12.73,100,1,12.71,100,1,12.5,700,1,12.46,200,2,12.43,700,1,12.42,700,1,12.37,700,1,13.83,115,2,13.84,100,1,13.89,15,1,14.1,2,1,14.11,100,1,14.28,100,1,14.4,100,1,14.56,800,2,14.6,700,1,14.68,1400,2,ARL,321114729
968,2025-07-17T15:58:51.241342265Z,2025-07-17T15:58:51.241176997Z,10,2,1108,C,A,-1,13.89,15,130,165268,268212338,13.04,2,1,13.03,100,1,13.02,100,1,12.73,100,1,12.71,100,1,12.5,700,1,12.46,200,2,12.43,700,1,12.42,700,1,12.37,700,1,13.83,115,2,13.84,100,1,14.1,2,1,14.11,100,1,14.28,100,1,14.4,100,1,14.56,800,2,14.6,700,1,14.68,1400,2,14.72,100,1,ARL,320833897
969,2025-07-17T15:58:51.254127339Z,2025-07-17T15:58:51.253961905Z,10,2,1108,A,A,0,13.8,100,130,165434,268212497,13.04,2,1,13.03,100,1,13.02,100,1,12.73,100,1,12.71,100,1,12.5,700,1,12.46,200,2,12.43,700,1,12.42,700,1,12.37,700,1,13.8,100,1,13.83,115,2,13.84,100,1,14.1,2,1,14.11,100,1,14.28,100,1,14.4,100,1,14.56,800,2,14.6,700,1,14.68,1400,2,ARL,321225725
970,2025-07-17T15:58:51.260753179Z,2025-07-17T15:58:51.260587778Z,10,2,1108,C,A,1,13.83,100,130,165401,268212534,13.04,2,1,13.03,100,1,13.02,100,1,12.73,100,1,12.71,100,1,12.5,700,1,12.46,200,2,12.43,700,1,12.42,700,1,12.37,700,1,13.8,100,1,13.83,15,1,13.84,100,1,14.1,2,1,14.11,100,1,14.28,100,1,14.4,100,1,14.56,800,2,14.6,700,1,14.68,1400,2,ARL,321114473
971,2025-07-17T15:58:53.579628288Z,2025-07-17T15:58:53.579462029Z,10,2,1108,C,A,-1,13.83,15,130,166259,268250290,13.04,2,1,13.03,100,1,13.02,100,1,12.73,100,1,12.71,100,1,12.5,700,1,12.46,200,2,12.43,700,1,12.42,700,1,12.37,700,1,13.8,100,1,13.84,100,1,14.1,2,1,14.11,100,1,14.28,100,1,14.4,100,1,14.56,800,2,14.6,700,1,14.68,1400,2,14.72,100,1,ARL,321038033
972,2025-07-17T15:58:53.580217445Z,2025-07-17T15:58:53.580052014Z,10,2,1108,C,A,-1,13.84,100,0,165431,268250346,13.04,2,1,13.03,100,1,13.02,100,1,12.73,100,1,12.71,100,1,12.5,700,1,12.46,200,2,12.43,700,1,12.42,700,1,12.37,700,1,13.8,100,1,14.1,2,1,14.11,100,1,14.28,100,1,14.4,100,1,14.56,800,2,14.6,700,1,14.68,1400,2,14.72,100,1,14.76,100,1,ARL,321096769
973,2025-07-17T15:58:53.580217445Z,2025-07-17T15:58:53.580052014Z,10,2,1108,A,A,1,13.81,100,130,165431,268250346,13.04,2,1,13.03,100,1,13.02,100,1,12.73,100,1,12.71,100,1,12.5,700,1,12.46,200,2,12.43,700,1,12.42,700,1,12.37,700,1,13.8,100,1,13.81,100,1,14.1,2,1,14.11,100,1,14.28,100,1,14.4,100,1,14.56,800,2,14.6,700,1,14.68,1400,2,14.72,100,1,ARL,321272581
974,2025-07-17T15:58:54.584124215Z,2025-07-17T15:58:54.583958582Z,10,2,1108,A,A,8,14.65,100,130,165633,268265585,13.04,2,1,13.03,100,1,13.02,100,1,12.73,100,1,12.71,100,1,12.5,700,1,12.46,200,2,12.43,700,1,12.42,700,1,12.37,700,1,13.8,100,1,13.81,100,1,14.1,2,1,14.11,100,1,14.28,100,1,14.4,100,1,14.56,800,2,14.6,700,1,14.65,100,1,14.68,1400,2,ARL,321293737
975,2025-07-17T15:58:54.584260712Z,2025-07-17T15:58:54.584094980Z,10,2,1108,A,A,8,14.64,100,130,165732,268265586,13.04,2,1,13.03,100,1,13.02,100,1,12.73,100,1,12.71,100,1,12.5,700,1,12.46,200,2,12.43,700,1,12.42,700,1,12.37,700,1,13.8,100,1,13.81,100,1,14.1,2,1,14.11,100,1,14.28,100,1,14.4,100,1,14.56,800,2,14.6,700,1,14.64,100,1,14.65,100,1,ARL,321293741
976,2025-07-17T15:58:55.305104029Z,2025-07-17T15:58:55.304938318Z,10,2,1108,A,A,0,13.78,100,130,165711,268277940,13.04,2,1,13.03,100,1,13.02,100,1,12.73,100,1,12.71,100,1,12.5,700,1,12.46,200,2,12.43,700,1,12.42,700,1,12.37,700,1,13.78,100,1,13.8,100,1,13.81,100,1,14.1,2,1,14.11,100,1,14.28,100,1,14.4,100,1,14.56,800,2,14.6,700,1,14.64,100,1,ARL,321309865
977,2025-07-17T15:58:55.307637209Z,2025-07-17T15:58:55.307472032Z,10,2,1108,A,A,8,14.58,100,130,165177,268278004,13.04,2,1,13.03,100,1,13.02,100,1,12.73,100,1,12.71,100,1,12.5,700,1,12.46,200,2,12.43,700,1,12.42,700,1,12.37,700,1,13.78,100,1,13.8,100,1,13.81,100,1,14.1,2,1,14.11,100,1,14.28,100,1,14.4,100,1,14.56,800,2,14.58,100,1,14.6,700,1,ARL,321309941
978,2025-07-17T15:58:55.311899965Z,2025-07-17T15:58:55.311734700Z,10,2,1108,C,A,-1,13.8,100,130,165265,268278030,13.04,2,1,13.03,100,1,13.02,100,1,12.73,100,1,12.71,100,1,12.5,700,1,12.46,200,2,12.43,700,1,12.42,700,1,12.37,700,1,13.78,100,1,13.81,100,1,14.1,2,1,14.11,100,1,14.28,100,1,14.4,100,1,14.56,800,2,14.58,100,1,14.6,700,1,14.64,100,1,ARL,321225725
979,2025-07-17T15:58:58.668252306Z,2025-07-17T15:58:58.668086788Z,10,2,1108,C,A,-1,13.81,100,0,165518,268321684,13.04,2,1,13.03,100,1,13.02,100,1,12.73,100,1,12.71,100,1,12.5,700,1,12.46,200,2,12.43,700,1,12.42,700,1,12.37,700,1,13.78,100,1,14.1,2,1,14.11,100,1,14.28,100,1,14.4,100,1,14.56,800,2,14.58,100,1,14.6,700,1,14.64,100,1,14.65,100,1,ARL,321272581
980,2025-07-17T15:58:58.668252306Z,2025-07-17T15:58:58.668086788Z,10,2,1108,A,A,1,13.79,100,130,165518,268321684,13.04,2,1,13.03,100,1,13.02,100,1,12.73,100,1,12.71,100,1,12.5,700,1,12.46,200,2,12.43,700,1,12.42,700,1,12.37,700,1,13.78,100,1,13.79,100,1,14.1,2,1,14.11,100,1,14.28,100,1,14.4,100,1,14.56,800,2,14.58,100,1,14.6,700,1,14.64,100,1,ARL,321364281
981,2025-07-17T15:59:03.613692913Z,2025-07-17T15:59:03.613527621Z,10,2,1108,A,A,0,13.72,15,130,165292,268437919,13.04,2,1,13.03,100,1,13.02,100,1,12.73,100,1,12.71,100,1,12.5,700,1,12.46,200,2,12.43,700,1,12.42,700,1,12.37,700,1,13.72,15,1,13.78,100,1,13.79,100,1,14.1,2,1,14.11,100,1,14.28,100,1,14.4,100,1,14.56,800,2,14.58,100,1,14.6,700,1,ARL,321500117
982,2025-07-17T15:59:03.626346616Z,2025-07-17T15:59:03.626181384Z,10,2,1108,A,A,1,13.76,100,130,165232,268438110,13.04,2,1,13.03,100,1,13.02,100,1,12.73,100,1,12.71,100,1,12.5,700,1,12.46,200,2,12.43,700,1,12.42,700,1,12.37,700,1,13.72,15,1,13.76,100,1,13.78,100,1,13.79,100,1,14.1,2,1,14.11,100,1,14.28,100,1,14.4,100,1,14.56,800,2,14.58,100,1,ARL,321500317
983,2025-07-17T15:59:03.633093258Z,2025-07-17T15:59:03.632928023Z,10,2,1108,C,A,-1,13.78,100,130,165235,268438149,13.04,2,1,13.03,100,1,13.02,100,1,12.73,100,1,12.71,100,1,12.5,700,1,12.46,200,2,12.43,700,1,12.42,700,1,12.37,700,1,13.72,15,1,13.76,100,1,13.79,100,1,14.1,2,1,14.11,100,1,14.28,100,1,14.4,100,1,14.56,800,2,14.58,100,1,14.6,700,1,ARL,321309865
984,2025-07-17T15:59:03.649282063Z,2025-07-17T15:59:03.649116452Z,10,2,1108,C,A,-1,14.11,100,130,165611,268438330,13.04,2,1,13.03,100,1,13.02,100,1,12.73,100,1,12.71,100,1,12.5,700,1,12.46,200,2,12.43,700,1,12.42,700,1,12.37,700,1,13.72,15,1,13.76,100,1,13.79,100,1,14.1,2,1,14.28,100,1,14.4,100,1,14.56,800,2,14.58,100,1,14.6,700,1,14.64,100,1,ARL,321114729
985,2025-07-17T15:59:03.649332873Z,2025-07-17T15:59:03.649167617Z,10,2,1108,A,A,3,14.04,100,130,165256,268438331,13.04,2,1,13.03,100,1,13.02,100,1,12.73,100,1,12.71,100,1,12.5,700,1,12.46,200,2,12.43,700,1,12.42,700,1,12.37,700,1,13.72,15,1,13.76,100,1,13.79,100,1,14.04,100,1,14.1,2,1,14.28,100,1,14.4,100,1,14.56,800,2,14.58,100,1,14.6,700,1,ARL,321500957
986,2025-07-17T15:59:04.224000805Z,2025-07-17T15:59:04.223835151Z,10,2,1108,C,A,-1,13.79,100,0,165654,268447989,13.04,2,1,13.03,100,1,13.02,100,1,12.73,100,1,12.71,100,1,12.5,700,1,12.46,200,2,12.43,700,1,12.42,700,1,12.37,700,1,13.72,15,1,13.76,100,1,14.04,100,1,14.1,2,1,14.28,100,1,14.4,100,1,14.56,800,2,14.58,100,1,14.6,700,1,14.64,100,1,ARL,321364281
987,2025-07-17T15:59:04.224000805Z,2025-07-17T15:59:04.223835151Z,10,2,1108,A,A,1,13.73,100,130,165654,268447989,13.04,2,1,13.03,100,1,13.02,100,1,12.73,100,1,12.71,100,1,12.5,700,1,12.46,200,2,12.43,700,1,12.42,700,1,12.37,700,1,13.72,15,1,13.73,100,1,13.76,100,1,14.04,100,1,14.1,2,1,14.28,100,1,14.4,100,1,14.56,800,2,14.58,100,1,14.6,700,1,ARL,321511377
988,2025-07-17T15:59:04.799998642Z,2025-07-17T15:59:04.799833206Z,10,2,1108,C,A,-1,13.72,15,130,165436,268457531,13.04,2,1,13.03,100,1,13.02,100,1,12.73,100,1,12.71,100,1,12.5,700,1,12.46,200,2,12.43,700,1,12.42,700,1,12.37,700,1,13.73,100,1,13.76,100,1,14.04,100,1,14.1,2,1,14.28,100,1,14.4,100,1,14.56,800,2,14.58,100,1,14.6,700,1,14.64,100,1,ARL,321500117
989,2025-07-17T16:00:13.989937414Z,2025-07-17T16:00:13.989771852Z,10,2,1108,C,A,-1,14.1,2,0,165562,269514876,13.04,2,1,13.03,100,1,13.02,100,1,12.73,100,1,12.71,100,1,12.5,700,1,12.46,200,2,12.43,700,1,12.42,700,1,12.37,700,1,13.73,100,1,13.76,100,1,14.04,100,1,14.28,100,1,14.4,100,1,14.56,800,2,14.58,100,1,14.6,700,1,14.64,100,1,14.65,100,1,ARL,316098525
990,2025-07-17T16:00:13.989937414Z,2025-07-17T16:00:13.989771852Z,10,2,1108,A,A,2,14.01,2,130,165562,269514876,13.04,2,1,13.03,100,1,13.02,100,1,12.73,100,1,12.71,100,1,12.5,700,1,12.46,200,2,12.43,700,1,12.42,700,1,12.37,700,1,13.73,100,1,13.76,100,1,14.01,2,1,14.04,100,1,14.28,100,1,14.4,100,1,14.56,800,2,14.58,100,1,14.6,700,1,14.64,100,1,ARL,322898193
991,2025-07-17T16:00:28.803015930Z,2025-07-17T16:00:28.802849928Z,10,2,1108,A,A,0,13.72,15,130,166002,269765653,13.04,2,1,13.03,100,1,13.02,100,1,12.73,100,1,12.71,100,1,12.5,700,1,12.46,200,2,12.43,700,1,12.42,700,1,12.37,700,1,13.72,15,1,13.73,100,1,13.76,100,1,14.01,2,1,14.04,100,1,14.28,100,1,14.4,100,1,14.56,800,2,14.58,100,1,14.6,700,1,ARL,323238809
992,2025-07-17T16:00:32.549412616Z,2025-07-17T16:00:32.549247168Z,10,2,1108,A,A,2,13.74,100,130,165448,269878282,13.04,2,1,13.03,100,1,13.02,100,1,12.73,100,1,12.71,100,1,12.5,700,1,12.46,200,2,12.43,700,1,12.42,700,1,12.37,700,1,13.72,15,1,13.73,100,1,13.74,100,1,13.76,100,1,14.01,2,1,14.04,100,1,14.28,100,1,14.4,100,1,14.56,800,2,14.58,100,1,ARL,323370569
993,2025-07-17T16:00:32.560989093Z,2025-07-17T16:00:32.560823786Z,10,2,1108,C,A,-1,13.76,100,130,165307,269878639,13.04,2,1,13.03,100,1,13.02,100,1,12.73,100,1,12.71,100,1,12.5,700,1,12.46,200,2,12.43,700,1,12.42,700,1,12.37,700,1,13.72,15,1,13.73,100,1,13.74,100,1,14.01,2,1,14.04,100,1,14.28,100,1,14.4,100,1,14.56,800,2,14.58,100,1,14.6,700,1,ARL,321500317
994,2025-07-17T16:00:35.513164458Z,2025-07-17T16:00:35.512999155Z,10,2,1108,A,A,0,13.69,15,130,165303,269940539,13.04,2,1,13.03,100,1,13.02,100,1,12.73,100,1,12.71,100,1,12.5,700,1,12.46,200,2,12.43,700,1,12.42,700,1,12.37,700,1,13.69,15,1,13.72,15,1,13.73,100,1,13.74,100,1,14.01,2,1,14.04,100,1,14.28,100,1,14.4,100,1,14.56,800,2,14.58,100,1,ARL,323455221
995,2025-07-17T16:00:42.614229184Z,2025-07-17T16:00:42.614063415Z,10,2,1108,C,A,-1,13.73,100,0,165769,270051089,13.04,2,1,13.03,100,1,13.02,100,1,12.73,100,1,12.71,100,1,12.5,700,1,12.46,200,2,12.43,700,1,12.42,700,1,12.37,700,1,13.69,15,1,13.72,15,1,13.74,100,1,14.01,2,1,14.04,100,1,14.28,100,1,14.4,100,1,14.56,800,2,14.58,100,1,14.6,700,1,ARL,321511377
996,2025-07-17T16:00:42.614229184Z,2025-07-17T16:00:42.614063415Z,10,2,1108,A,A,1,13.7,100,130,165769,270051089,13.04,2,1,13.03,100,1,13.02,100,1,12.73,100,1,12.71,100,1,12.5,700,1,12.46,200,2,12.43,700,1,12.42,700,1,12.37,700,1,13.69,15,1,13.7,100,1,13.72,15,1,13.74,100,1,14.01,2,1,14.04,100,1,14.28,100,1,14.4,100,1,14.56,800,2,14.58,100,1,ARL,323599605
997,2025-07-17T16:00:42.614254199Z,2025-07-17T16:00:42.614088947Z,10,2,1108,A,A,2,13.72,100,130,165252,270051090,13.04,2,1,13.03,100,1,13.02,100,1,12.73,100,1,12.71,100,1,12.5,700,1,12.46,200,2,12.43,700,1,12.42,700,1,12.37,700,1,13.69,15,1,13.7,100,1,13.72,115,2,13.74,100,1,14.01,2,1,14.04,100,1,14.28,100,1,14.4,100,1,14.56,800,2,14.58,100,1,ARL,323599609
998,2025-07-17T16:00:42.614396214Z,2025-07-17T16:00:42.614231125Z,10,2,1108,C,A,-1,13.74,100,130,165089,270051092,13.04,2,1,13.03,100,1,13.02,100,1,12.73,100,1,12.71,100,1,12.5,700,1,12.46,200,2,12.43,700,1,12.42,700,1,12.37,700,1,13.69,15,1,13.7,100,1,13.72,115,2,14.01,2,1,14.04,100,1,14.28,100,1,14.4,100,1,14.56,800,2,14.58,100,1,14.6,700,1,ARL,323370569
999,2025-07-17T16:00:42.636761176Z,2025-07-17T16:00:42.636595817Z,10,2,1108,C,A,-1,14.04,100,130,165359,270051179,13.04,2,1,13.03,100,1,13.02,100,1,12.73,100,1,12.71,100,1,12.5,700,1,12.46,200,2,12.43,700,1,12.42,700,1,12.37,700,1,13.69,15,1,13.7,100,1,13.72,115,2,14.01,2,1,14.28,100,1,14.4,100,1,14.56,800,2,14.58,100,1,14.6,700,1,14.64,100,1,ARL,321500957
1000,2025-07-17T16:00:42.636814704Z,2025-07-17T16:00:42.636649389Z,10,2,1108,A,A,3,13.97,100,130,165315,270051181,13.04,2,1,13.03,100,1,13.02,100,1,12.73,100,1,12.71,100,1,12.5,700,1,12.46,200,2,12.43,700,1,12.42,700,1,12.37,700,1,13.69,15,1,13.7,100,1,13.72,115,2,13.97,100,1,14.01,2,1,14.28,100,1,14.4,100,1,14.56,800,2,14.58,100,1,14.6,700,1,ARL,323599765
1001,2025-07-17T16:00:46.803262460Z,2025-07-17T16:00:46.803097192Z,10,2,1108,C,A,2,13.72,15,130,165268,270102799,13.04,2,1,13.03,100,1,13.02,100,1,12.73,100,1,12.71,100,1,12.5,700,1,12.46,200,2,12.43,700,1,12.42,700,1,12.37,700,1,13.69,15,1,13.7,100,1,13.72,100,1,13.97,100,1,14.01,2,1,14.28,100,1,14.4,100,1,14.56,800,2,14.58,100,1,14.6,700,1,ARL,323238809
1002,2025-07-17T16:00:49.255631264Z,2025-07-17T16:00:49.255465939Z,10,2,1108,A,A,0,13.66,15,130,165325,270140405,13.04,2,1,13.03,100,1,13.02,100,1,12.73,100,1,12.71,100,1,12.5,700,1,12.46,200,2,12.43,700,1,12.42,700,1,12.37,700,1,13.66,15,1,13.69,15,1,13.7,100,1,13.72,100,1,13.97,100,1,14.01,2,1,14.28,100,1,14.4,100,1,14.56,800,2,14.58,100,1,ARL,323720189
1003,2025-07-17T16:00:49.739644604Z,2025-07-17T16:00:49.739479408Z,10,2,1108,A,A,2,13.7,100,130,165196,270146528,13.04,2,1,13.03,100,1,13.02,100,1,12.73,100,1,12.71,100,1,12.5,700,1,12.46,200,2,12.43,700,1,12.42,700,1,12.37,700,1,13.66,15,1,13.69,15,1,13.7,200,2,13.72,100,1,13.97,100,1,14.01,2,1,14.28,100,1,14.4,100,1,14.56,800,2,14.58,100,1,ARL,323730309
1004,2025-07-17T16:00:49.745038261Z,2025-07-17T16:00:49.744872763Z,10,2,1108,C,A,2,13.7,100,0,165498,270146577,13.04,2,1,13.03,100,1,13.02,100,1,12.73,100,1,12.71,100,1,12.5,700,1,12.46,200,2,12.43,700,1,12.42,700,1,12.37,700,1,13.66,15,1,13.69,15,1,13.7,100,1,13.72,100,1,13.97,100,1,14.01,2,1,14.28,100,1,14.4,100,1,14.56,800,2,14.58,100,1,ARL,323599605
1005,2025-07-17T16:00:49.745038261Z,2025-07-17T16:00:49.744872763Z,10,2,1108,A,A,1,13.67,100,130,165498,270146577,13.04,2,1,13.03,100,1,13.02,100,1,12.73,100,1,12.71,100,1,12.5,700,1,12.46,200,2,12.43,700,1,12.42,700,1,12.37,700,1,13.66,15,1,13.67,100,1,13.69,15,1,13.7,100,1,13.72,100,1,13.97,100,1,14.01,2,1,14.28,100,1,14.4,100,1,14.56,800,2,ARL,323730353
1006,2025-07-17T16:00:49.746422142Z,2025-07-17T16:00:49.746256906Z,10,2,1108,C,A,-1,13.72,100,130,165236,270146586,13.04,2,1,13.03,100,1,13.02,100,1,12.73,100,1,12.71,100,1,12.5,700,1,12.46,200,2,12.43,700,1,12.42,700,1,12.37,700,1,13.66,15,1,13.67,100,1,13.69,15,1,13.7,100,1,13.97,100,1,14.01,2,1,14.28,100,1,14.4,100,1,14.56,800,2,14.58,100,1,ARL,323599609
1007,2025-07-17T16:00:51.624811889Z,2025-07-17T16:00:51.624646272Z,10,2,1108,A,A,8,14.54,100,130,165617,270181394,13.04,2,1,13.03,100,1,13.02,100,1,12.73,100,1,12.71,100,1,12.5,700,1,12.46,200,2,12.43,700,1,12.42,700,1,12.37,700,1,13.66,15,1,13.67,100,1,13.69,15,1,13.7,100,1,13.97,100,1,14.01,2,1,14.28,100,1,14.4,100,1,14.54,100,1,14.56,800,2,ARL,323775433
1008,2025-07-17T16:00:51.625372516Z,2025-07-17T16:00:51.625206675Z,10,2,1108,A,A,8,14.53,100,130,165841,270181399,13.04,2,1,13.03,100,1,13.02,100,1,12.73,100,1,12.71,100,1,12.5,700,1,12.46,200,2,12.43,700,1,12.42,700,1,12.37,700,1,13.66,15,1,13.67,100,1,13.69,15,1,13.7,100,1,13.97,100,1,14.01,2,1,14.28,100,1,14.4,100,1,14.53,100,1,14.54,100,1,ARL,323775457
1009,2025-07-17T16:00:53.749335010Z,2025-07-17T16:00:53.749169565Z,10,2,1108,A,A,1,13.67,100,130,165445,270204567,13.04,2,1,13.03,100,1,13.02,100,1,12.73,100,1,12.71,100,1,12.5,700,1,12.46,200,2,12.43,700,1,12.42,700,1,12.37,700,1,13.66,15,1,13.67,200,2,13.69,15,1,13.7,100,1,13.97,100,1,14.01,2,1,14.28,100,1,14.4,100,1,14.53,100,1,14.54,100,1,ARL,323803301
1010,2025-07-17T16:00:53.755966680Z,2025-07-17T16:00:53.755801462Z,10,2,1108,C,A,-1,13.7,100,130,165218,270204616,13.04,2,1,13.03,100,1,13.02,100,1,12.73,100,1,12.71,100,1,12.5,700,1,12.46,200,2,12.43,700,1,12.42,700,1,12.37,700,1,13.66,15,1,13.67,200,2,13.69,15,1,13.97,100,1,14.01,2,1,14.28,100,1,14.4,100,1,14.53,100,1,14.54,100,1,14.56,800,2,ARL,323730309
1011,2025-07-17T16:01:00.801342739Z,2025-07-17T16:01:00.801177403Z,10,2,1108,C,A,-1,13.69,15,130,165336,270319932,13.04,2,1,13.03,100,1,13.02,100,1,12.73,100,1,12.71,100,1,12.5,700,1,12.46,200,2,12.43,700,1,12.42,700,1,12.37,700,1,13.66,15,1,13.67,200,2,13.97,100,1,14.01,2,1,14.28,100,1,14.4,100,1,14.53,100,1,14.54,100,1,14.56,800,2,14.58,100,1,ARL,323455221
1012,2025-07-17T16:01:10.802877570Z,2025-07-17T16:01:10.802712247Z,10,2,1108,A,A,0,13.62,15,130,165323,270493149,13.04,2,1,13.03,100,1,13.02,100,1,12.73,100,1,12.71,100,1,12.5,700,1,12.46,200,2,12.43,700,1,12.42,700,1,12.37,700,1,13.62,15,1,13.66,15,1,13.67,200,2,13.97,100,1,14.01,2,1,14.28,100,1,14.4,100,1,14.53,100,1,14.54,100,1,14.56,800,2,ARL,324161541
1013,2025-07-17T16:01:11.418837472Z,2025-07-17T16:01:11.418671671Z,10,2,1108,A,A,1,13.65,100,130,165801,270503944,13.04,2,1,13.03,100,1,13.02,100,1,12.73,100,1,12.71,100,1,12.5,700,1,12.46,200,2,12.43,700,1,12.42,700,1,12.37,700,1,13.62,15,1,13.65,100,1,13.66,15,1,13.67,200,2,13.97,100,1,14.01,2,1,14.28,100,1,14.4,100,1,14.53,100,1,14.54,100,1,ARL,324175569
1014,2025-07-17T16:01:11.425922184Z,2025-07-17T16:01:11.425757014Z,10,2,1108,C,A,3,13.67,100,130,165170,270504009,13.04,2,1,13.03,100,1,13.02,100,1,12.73,100,1,12.71,100,1,12.5,700,1,12.46,200,2,12.43,700,1,12.42,700,1,12.37,700,1,13.62,15,1,13.65,100,1,13.66,15,1,13.67,100,1,13.97,100,1,14.01,2,1,14.28,100,1,14.4,100,1,14.53,100,1,14.54,100,1,ARL,323803301
1015,2025-07-17T16:01:11.820753616Z,2025-07-17T16:01:11.820588141Z,10,2,1108,C,A,-1,13.67,100,0,165475,270509970,13.04,2,1,13.03,100,1,13.02,100,1,12.73,100,1,12.71,100,1,12.5,700,1,12.46,200,2,12.43,700,1,12.42,700,1,12.37,700,1,13.62,15,1,13.65,100,1,13.66,15,1,13.97,100,1,14.01,2,1,14.28,100,1,14.4,100,1,14.53,100,1,14.54,100,1,14.56,800,2,ARL,323730353
1016,2025-07-17T16:01:11.820753616Z,2025-07-17T16:01:11.820588141Z,10,2,1108,A,A,1,13.63,100,130,165475,270509970,13.04,2,1,13.03,100,1,13.02,100,1,12.73,100,1,12.71,100,1,12.5,700,1,12.46,200,2,12.43,700,1,12.42,700,1,12.37,700,1,13.62,15,1,13.63,100,1,13.65,100,1,13.66,15,1,13.97,100,1,14.01,2,1,14.28,100,1,14.4,100,1,14.53,100,1,14.54,100,1,ARL,324186213
1017,2025-07-17T16:01:11.826399871Z,2025-07-17T16:01:11.826234488Z,10,2,1108,C,A,-1,13.97,100,130,165383,270510142,13.04,2,1,13.03,100,1,13.02,100,1,12.73,100,1,12.71,100,1,12.5,700,1,12.46,200,2,12.43,700,1,12.42,700,1,12.37,700,1,13.62,15,1,13.63,100,1,13.65,100,1,13.66,15,1,14.01,2,1,14.28,100,1,14.4,100,1,14.53,100,1,14.54,100,1,14.56,800,2,ARL,323599765
1018,2025-07-17T16:01:11.826451447Z,2025-07-17T16:01:11.826286284Z,10,2,1108,A,A,4,13.9,100,130,165163,270510143,13.04,2,1,13.03,100,1,13.02,100,1,12.73,100,1,12.71,100,1,12.5,700,1,12.46,200,2,12.43,700,1,12.42,700,1,12.37,700,1,13.62,15,1,13.63,100,1,13.65,100,1,13.66,15,1,13.9,100,1,14.01,2,1,14.28,100,1,14.4,100,1,14.53,100,1,14.54,100,1,ARL,324186721
1019,2025-07-17T16:01:11.828630414Z,2025-07-17T16:01:11.828464891Z,10,2,1108,A,A,8,14.43,100,130,165523,270510182,13.04,2,1,13.03,100,1,13.02,100,1,12.73,100,1,12.71,100,1,12.5,700,1,12.46,200,2,12.43,700,1,12.42,700,1,12.37,700,1,13.62,15,1,13.63,100,1,13.65,100,1,13.66,15,1,13.9,100,1,14.01,2,1,14.28,100,1,14.4,100,1,14.43,100,1,14.53,100,1,ARL,324186781
1020,2025-07-17T16:01:22.802518536Z,2025-07-17T16:01:22.802353061Z,10,2,1108,C,A,-1,13.66,15,130,165475,270674903,13.04,2,1,13.03,100,1,13.02,100,1,12.73,100,1,12.71,100,1,12.5,700,1,12.46,200,2,12.43,700,1,12.42,700,1,12.37,700,1,13.62,15,1,13.63,100,1,13.65,100,1,13.9,100,1,14.01,2,1,14.28,100,1,14.4,100,1,14.43,100,1,14.53,100,1,14.54,100,1,ARL,323720189
1021,2025-07-17T16:01:32.804004639Z,2025-07-17T16:01:32.803839043Z,10,2,1108,A,A,0,13.6,15,130,165596,270824320,13.04,2,1,13.03,100,1,13.02,100,1,12.73,100,1,12.71,100,1,12.5,700,1,12.46,200,2,12.43,700,1,12.42,700,1,12.37,700,1,13.6,15,1,13.62,15,1,13.63,100,1,13.65,100,1,13.9,100,1,14.01,2,1,14.28,100,1,14.4,100,1,14.43,100,1,14.53,100,1,ARL,324619361
1022,2025-07-17T16:01:32.804274168Z,2025-07-17T16:01:32.804108576Z,10,2,1108,C,A,-1,13.63,100,0,165592,270824323,13.04,2,1,13.03,100,1,13.02,100,1,12.73,100,1,12.71,100,1,12.5,700,1,12.46,200,2,12.43,700,1,12.42,700,1,12.37,700,1,13.6,15,1,13.62,15,1,13.65,100,1,13.9,100,1,14.01,2,1,14.28,100,1,14.4,100,1,14.43,100,1,14.53,100,1,14.54,100,1,ARL,324186213
1023,2025-07-17T16:01:32.804274168Z,2025-07-17T16:01:32.804108576Z,10,2,1108,A,A,1,13.61,100,130,165592,270824323,13.04,2,1,13.03,100,1,13.02,100,1,12.73,100,1,12.71,100,1,12.5,700,1,12.46,200,2,12.43,700,1,12.42,700,1,12.37,700,1,13.6,15,1,13.61,100,1,13.62,15,1,13.65,100,1,13.9,100,1,14.01,2,1,14.28,100,1,14.4,100,1,14.43,100,1,14.53,100,1,ARL,324619369
1024,2025-07-17T16:01:32.815913520Z,2025-07-17T16:01:32.815748258Z,10,2,1108,A,A,3,13.63,100,130,165262,270824657,13.04,2,1,13.03,100,1,13.02,100,1,12.73,100,1,12.71,100,1,12.5,700,1,12.46,200,2,12.43,700,1,12.42,700,1,12.37,700,1,13.6,15,1,13.61,100,1,13.62,15,1,13.63,100,1,13.65,100,1,13.9,100,1,14.01,2,1,14.28,100,1,14.4,100,1,14.43,100,1,ARL,324619837
1025,2025-07-17T16:01:32.822608966Z,2025-07-17T16:01:32.822443626Z,10,2,1108,C,A,-1,13.65,100,130,165340,270824747,13.04,2,1,13.03,100,1,13.02,100,1,12.73,100,1,12.71,100,1,12.5,700,1,12.46,200,2,12.43,700,1,12.42,700,1,12.37,700,1,13.6,15,1,13.61,100,1,13.62,15,1,13.63,100,1,13.9,100,1,14.01,2,1,14.28,100,1,14.4,100,1,14.43,100,1,14.53,100,1,ARL,324175569
1026,2025-07-17T16:01:37.242690420Z,2025-07-17T16:01:37.242525208Z,10,2,1108,C,A,-1,13.62,15,130,165212,270889017,13.04,2,1,13.03,100,1,13.02,100,1,12.73,100,1,12.71,100,1,12.5,700,1,12.46,200,2,12.43,700,1,12.42,700,1,12.37,700,1,13.6,15,1,13.61,100,1,13.63,100,1,13.9,100,1,14.01,2,1,14.28,100,1,14.4,100,1,14.43,100,1,14.53,100,1,14.54,100,1,ARL,324161541
1027,2025-07-17T16:01:40.605797765Z,2025-07-17T16:01:40.605632399Z,10,2,1108,A,A,1,13.61,100,130,165366,270946497,13.04,2,1,13.03,100,1,13.02,100,1,12.73,100,1,12.71,100,1,12.5,700,1,12.46,200,2,12.43,700,1,12.42,700,1,12.37,700,1,13.6,15,1,13.61,200,2,13.63,100,1,13.9,100,1,14.01,2,1,14.28,100,1,14.4,100,1,14.43,100,1,14.53,100,1,14.54,100,1,ARL,324782841
1028,2025-07-17T16:01:40.653738176Z,2025-07-17T16:01:40.653572805Z,10,2,1108,C,A,-1,13.63,100,130,165371,270946779,13.04,2,1,13.03,100,1,13.02,100,1,12.73,100,1,12.71,100,1,12.5,700,1,12.46,200,2,12.43,700,1,12.42,700,1,12.37,700,1,13.6,15,1,13.61,200,2,13.9,100,1,14.01,2,1,14.28,100,1,14.4,100,1,14.43,100,1,14.53,100,1,14.54,100,1,14.56,800,2,ARL,324619837
1029,2025-07-17T16:01:47.565991684Z,2025-07-17T16:01:47.565825466Z,10,2,1108,A,A,0,13.57,15,128,166218,271062350,13.04,2,1,13.03,100,1,13.02,100,1,12.73,100,1,12.71,100,1,12.5,700,1,12.46,200,2,12.43,700,1,12.42,700,1,12.37,700,1,13.57,15,1,13.6,15,1,13.61,200,2,13.9,100,1,14.01,2,1,14.28,100,1,14.4,100,1,14.43,100,1,14.53,100,1,14.54,100,1,ARL,324934601
1030,2025-07-17T16:01:47.902969773Z,2025-07-17T16:01:47.902804446Z,10,2,1108,C,A,2,13.61,100,0,165327,271068098,13.04,2,1,13.03,100,1,13.02,100,1,12.73,100,1,12.71,100,1,12.5,700,1,12.46,200,2,12.43,700,1,12.42,700,1,12.37,700,1,13.57,15,1,13.6,15,1,13.61,100,1,13.9,100,1,14.01,2,1,14.28,100,1,14.4,100,1,14.43,100,1,14.53,100,1,14.54,100,1,ARL,324619369
1031,2025-07-17T16:01:47.902969773Z,2025-07-17T16:01:47.902804446Z,10,2,1108,A,A,1,13.58,100,130,165327,271068098,13.04,2,1,13.03,100,1,13.02,100,1,12.73,100,1,12.71,100,1,12.5,700,1,12.46,200,2,12.43,700,1,12.42,700,1,12.37,700,1,13.57,15,1,13.58,100,1,13.6,15,1,13.61,100,1,13.9,100,1,14.01,2,1,14.28,100,1,14.4,100,1,14.43,100,1,14.53,100,1,ARL,324942229
1032,2025-07-17T16:01:47.903711757Z,2025-07-17T16:01:47.903546622Z,10,2,1108,C,A,-1,14.4,100,130,165135,271068105,13.04,2,1,13.03,100,1,13.02,100,1,12.73,100,1,12.71,100,1,12.5,700,1,12.46,200,2,12.43,700,1,12.42,700,1,12.37,700,1,13.57,15,1,13.58,100,1,13.6,15,1,13.61,100,1,13.9,100,1,14.01,2,1,14.28,100,1,14.43,100,1,14.53,100,1,14.54,100,1,ARL,289726421
1033,2025-07-17T16:01:47.904067686Z,2025-07-17T16:01:47.903902473Z,10,2,1108,A,A,6,14.19,100,130,165213,271068115,13.04,2,1,13.03,100,1,13.02,100,1,12.73,100,1,12.71,100,1,12.5,700,1,12.46,200,2,12.43,700,1,12.42,700,1,12.37,700,1,13.57,15,1,13.58,100,1,13.6,15,1,13.61,100,1,13.9,100,1,14.01,2,1,14.19,100,1,14.28,100,1,14.43,100,1,14.53,100,1,ARL,324942273
1034,2025-07-17T16:01:50.799100504Z,2025-07-17T16:01:50.798934838Z,10,2,1108,A,A,2,13.59,100,130,165666,271131418,13.04,2,1,13.03,100,1,13.02,100,1,12.73,100,1,12.71,100,1,12.5,700,1,12.46,200,2,12.43,700,1,12.42,700,1,12.37,700,1,13.57,15,1,13.58,100,1,13.59,100,1,13.6,15,1,13.61,100,1,13.9,100,1,14.01,2,1,14.19,100,1,14.28,100,1,14.43,100,1,ARL,325022101
1035,2025-07-17T16:01:50.805653961Z,2025-07-17T16:01:50.805488726Z,10,2,1108,C,A,-1,13.61,100,130,165235,271131583,13.04,2,1,13.03,100,1,13.02,100,1,12.73,100,1,12.71,100,1,12.5,700,1,12.46,200,2,12.43,700,1,12.42,700,1,12.37,700,1,13.57,15,1,13.58,100,1,13.59,100,1,13.6,15,1,13.9,100,1,14.01,2,1,14.19,100,1,14.28,100,1,14.43,100,1,14.53,100,1,ARL,324782841
1036,2025-07-17T16:01:52.133063761Z,2025-07-17T16:01:52.132898568Z,10,2,1108,C,A,-1,13.6,15,130,165193,271153294,13.04,2,1,13.03,100,1,13.02,100,1,12.73,100,1,12.71,100,1,12.5,700,1,12.46,200,2,12.43,700,1,12.42,700,1,12.37,700,1,13.57,15,1,13.58,100,1,13.59,100,1,13.9,100,1,14.01,2,1,14.19,100,1,14.28,100,1,14.43,100,1,14.53,100,1,14.54,100,1,ARL,324619361
1037,2025-07-17T16:01:53.137501962Z,2025-07-17T16:01:53.137336077Z,10,2,1108,A,A,0,13.55,15,130,165885,271200452,13.04,2,1,13.03,100,1,13.02,100,1,12.73,100,1,12.71,100,1,12.5,700,1,12.46,200,2,12.43,700,1,12.42,700,1,12.37,700,1,13.55,15,1,13.57,15,1,13.58,100,1,13.59,100,1,13.9,100,1,14.01,2,1,14.19,100,1,14.28,100,1,14.43,100,1,14.53,100,1,ARL,325109165
1038,2025-07-17T16:01:56.264154095Z,2025-07-17T16:01:56.263988198Z,10,2,1108,C,A,-1,13.58,100,0,165897,271251019,13.04,2,1,13.03,100,1,13.02,100,1,12.73,100,1,12.71,100,1,12.5,700,1,12.46,200,2,12.43,700,1,12.42,700,1,12.37,700,1,13.55,15,1,13.57,15,1,13.59,100,1,13.9,100,1,14.01,2,1,14.19,100,1,14.28,100,1,14.43,100,1,14.53,100,1,14.54,100,1,ARL,324942229
1039,2025-07-17T16:01:56.264154095Z,2025-07-17T16:01:56.263988198Z,10,2,1108,A,A,1,13.56,100,130,165897,271251019,13.04,2,1,13.03,100,1,13.02,100,1,12.73,100,1,12.71,100,1,12.5,700,1,12.46,200,2,12.43,700,1,12.42,700,1,12.37,700,1,13.55,15,1,13.56,100,1,13.57,15,1,13.59,100,1,13.9,100,1,14.01,2,1,14.19,100,1,14.28,100,1,14.43,100,1,14.53,100,1,ARL,325176181
1040,2025-07-17T16:01:56.269623788Z,2025-07-17T16:01:56.269458197Z,10,2,1108,C,A,-1,13.9,100,130,165591,271251357,13.04,2,1,13.03,100,1,13.02,100,1,12.73,100,1,12.71,100,1,12.5,700,1,12.46,200,2,12.43,700,1,12.42,700,1,12.37,700,1,13.55,15,1,13.56,100,1,13.57,15,1,13.59,100,1,14.01,2,1,14.19,100,1,14.28,100,1,14.43,100,1,14.53,100,1,14.54,100,1,ARL,324186721
1041,2025-07-17T16:01:56.269674232Z,2025-07-17T16:01:56.269508928Z,10,2,1108,A,A,4,13.83,100,130,165304,271251358,13.04,2,1,13.03,100,1,13.02,100,1,12.73,100,1,12.71,100,1,12.5,700,1,12.46,200,2,12.43,700,1,12.42,700,1,12.37,700,1,13.55,15,1,13.56,100,1,13.57,15,1,13.59,100,1,13.83,100,1,14.01,2,1,14.19,100,1,14.28,100,1,14.43,100,1,14.53,100,1,ARL,325176373
1042,2025-07-17T16:01:56.300889378Z,2025-07-17T16:01:56.300723805Z,10,2,1108,A,A,9,14.51,100,130,165573,271252044,13.04,2,1,13.03,100,1,13.02,100,1,12.73,100,1,12.71,100,1,12.5,700,1,12.46,200,2,12.43,700,1,12.42,700,1,12.37,700,1,13.55,15,1,13.56,100,1,13.57,15,1,13.59,100,1,13.83,100,1,14.01,2,1,14.19,100,1,14.28,100,1,14.43,100,1,14.51,100,1,ARL,325177757
1043,2025-07-17T16:02:01.992544607Z,2025-07-17T16:02:01.992379223Z,10,2,1108,C,A,-1,14.01,2,0,165384,271343251,13.04,2,1,13.03,100,1,13.02,100,1,12.73,100,1,12.71,100,1,12.5,700,1,12.46,200,2,12.43,700,1,12.42,700,1,12.37,700,1,13.55,15,1,13.56,100,1,13.57,15,1,13.59,100,1,13.83,100,1,14.19,100,1,14.28,100,1,14.43,100,1,14.51,100,1,14.53,100,1,ARL,322898193
1044,2025-07-17T16:02:01.992544607Z,2025-07-17T16:02:01.992379223Z,10,2,1108,A,A,5,13.92,2,130,165384,271343251,13.04,2,1,13.03,100,1,13.02,100,1,12.73,100,1,12.71,100,1,12.5,700,1,12.46,200,2,12.43,700,1,12.42,700,1,12.37,700,1,13.55,15,1,13.56,100,1,13.57,15,1,13.59,100,1,13.83,100,1,13.92,2,1,14.19,100,1,14.28,100,1,14.43,100,1,14.51,100,1,ARL,325297093
1045,2025-07-17T16:02:03.207720826Z,2025-07-17T16:02:03.207555626Z,10,2,1108,C,A,-1,13.57,15,130,165200,271367066,13.04,2,1,13.03,100,1,13.02,100,1,12.73,100,1,12.71,100,1,12.5,700,1,12.46,200,2,12.43,700,1,12.42,700,1,12.37,700,1,13.55,15,1,13.56,100,1,13.59,100,1,13.83,100,1,13.92,2,1,14.19,100,1,14.28,100,1,14.43,100,1,14.51,100,1,14.53,100,1,ARL,324934601
1046,2025-07-17T16:02:04.212956339Z,2025-07-17T16:02:04.212791108Z,10,2,1108,A,A,0,13.53,15,130,165231,271415821,13.04,2,1,13.03,100,1,13.02,100,1,12.73,100,1,12.71,100,1,12.5,700,1,12.46,200,2,12.43,700,1,12.42,700,1,12.37,700,1,13.53,15,1,13.55,15,1,13.56,100,1,13.59,100,1,13.83,100,1,13.92,2,1,14.19,100,1,14.28,100,1,14.43,100,1,14.51,100,1,ARL,325382429
1047,2025-07-17T16:02:04.214348814Z,2025-07-17T16:02:04.214183279Z,10,2,1108,A,A,8,14.43,100,130,165535,271415834,13.04,2,1,13.03,100,1,13.02,100,1,12.73,100,1,12.71,100,1,12.5,700,1,12.46,200,2,12.43,700,1,12.42,700,1,12.37,700,1,13.53,15,1,13.55,15,1,13.56,100,1,13.59,100,1,13.83,100,1,13.92,2,1,14.19,100,1,14.28,100,1,14.43,200,2,14.51,100,1,ARL,325382437
1048,2025-07-17T16:02:04.840132668Z,2025-07-17T16:02:04.839967173Z,10,2,1108,C,A,-1,13.56,100,0,165495,271432190,13.04,2,1,13.03,100,1,13.02,100,1,12.73,100,1,12.71,100,1,12.5,700,1,12.46,200,2,12.43,700,1,12.42,700,1,12.37,700,1,13.53,15,1,13.55,15,1,13.59,100,1,13.83,100,1,13.92,2,1,14.19,100,1,14.28,100,1,14.43,200,2,14.51,100,1,14.53,100,1,ARL,325176181
1049,2025-07-17T16:02:04.840132668Z,2025-07-17T16:02:04.839967173Z,10,2,1108,A,A,1,13.54,100,130,165495,271432190,13.04,2,1,13.03,100,1,13.02,100,1,12.73,100,1,12.71,100,1,12.5,700,1,12.46,200,2,12.43,700,1,12.42,700,1,12.37,700,1,13.53,15,1,13.54,100,1,13.55,15,1,13.59,100,1,13.83,100,1,13.92,2,1,14.19,100,1,14.28,100,1,14.43,200,2,14.51,100,1,ARL,325400045
1050,2025-07-17T16:02:04.840171240Z,2025-07-17T16:02:04.840006082Z,10,2,1108,A,A,7,14.27,700,130,165158,271432192,13.04,2,1,13.03,100,1,13.02,100,1,12.73,100,1,12.71,100,1,12.5,700,1,12.46,200,2,12.43,700,1,12.42,700,1,12.37,700,1,13.53,15,1,13.54,100,1,13.55,15,1,13.59,100,1,13.83,100,1,13.92,2,1,14.19,100,1,14.27,700,1,14.28,100,1,14.43,200,2,ARL,325400053
1051,2025-07-17T16:02:11.249291142Z,2025-07-17T16:02:11.249125653Z,10,2,1108,A,A,9,14.42,100,130,165489,271526467,13.04,2,1,13.03,100,1,13.02,100,1,12.73,100,1,12.71,100,1,12.5,700,1,12.46,200,2,12.43,700,1,12.42,700,1,12.37,700,1,13.53,15,1,13.54,100,1,13.55,15,1,13.59,100,1,13.83,100,1,13.92,2,1,14.19,100,1,14.27,700,1,14.28,100,1,14.42,100,1,ARL,325520705
1052,2025-07-17T16:02:15.062774661Z,2025-07-17T16:02:15.062605521Z,10,2,1108,C,A,-1,13.53,15,128,169140,271576282,13.04,2,1,13.03,100,1,13.02,100,1,12.73,100,1,12.71,100,1,12.5,700,1,12.46,200,2,12.43,700,1,12.42,700,1,12.37,700,1,13.54,100,1,13.55,15,1,13.59,100,1,13.83,100,1,13.92,2,1,14.19,100,1,14.27,700,1,14.28,100,1,14.42,100,1,14.43,200,2,ARL,325382429
1053,2025-07-17T16:02:15.068449048Z,2025-07-17T16:02:15.068283706Z,10,2,1108,C,A,-1,13.55,15,130,165342,271577104,13.04,2,1,13.03,100,1,13.02,100,1,12.73,100,1,12.71,100,1,12.5,700,1,12.46,200,2,12.43,700,1,12.42,700,1,12.37,700,1,13.54,100,1,13.59,100,1,13.83,100,1,13.92,2,1,14.19,100,1,14.27,700,1,14.28,100,1,14.42,100,1,14.43,200,2,14.51,100,1,ARL,325109165
1054,2025-07-17T16:02:20.635028489Z,2025-07-17T16:02:20.634863301Z,10,2,1108,C,A,-1,13.54,100,130,165188,271675842,13.04,2,1,13.03,100,1,13.02,100,1,12.73,100,1,12.71,100,1,12.5,700,1,12.46,200,2,12.43,700,1,12.42,700,1,12.37,700,1,13.59,100,1,13.83,100,1,13.92,2,1,14.19,100,1,14.27,700,1,14.28,100,1,14.42,100,1,14.43,200,2,14.51,100,1,14.56,800,2,ARL,325400045
1055,2025-07-17T16:02:20.650466751Z,2025-07-17T16:02:20.650301212Z,10,2,1108,C,A,-1,13.59,100,130,165539,271676032,13.04,2,1,13.03,100,1,13.02,100,1,12.73,100,1,12.71,100,1,12.5,700,1,12.46,200,2,12.43,700,1,12.42,700,1,12.37,700,1,13.83,100,1,13.92,2,1,14.19,100,1,14.27,700,1,14.28,100,1,14.42,100,1,14.43,200,2,14.51,100,1,14.56,800,2,14.57,100,1,ARL,325022101
1056,2025-07-17T16:02:20.650501448Z,2025-07-17T16:02:20.650335946Z,10,2,1108,C,A,-1,14.27,700,130,165502,271676033,13.04,2,1,13.03,100,1,13.02,100,1,12.73,100,1,12.71,100,1,12.5,700,1,12.46,200,2,12.43,700,1,12.42,700,1,12.37,700,1,13.83,100,1,13.92,2,1,14.19,100,1,14.28,100,1,14.42,100,1,14.43,200,2,14.51,100,1,14.56,800,2,14.57,100,1,14.6,700,1,ARL,325400053
1057,2025-07-17T16:02:20.650546483Z,2025-07-17T16:02:20.650381040Z,10,2,1108,A,A,7,14.53,700,130,165443,271676035,13.04,2,1,13.03,100,1,13.02,100,1,12.73,100,1,12.71,100,1,12.5,700,1,12.46,200,2,12.43,700,1,12.42,700,1,12.37,700,1,13.83,100,1,13.92,2,1,14.19,100,1,14.28,100,1,14.42,100,1,14.43,200,2,14.51,100,1,14.53,700,1,14.56,800,2,14.57,100,1,ARL,325714545
1058,2025-07-17T16:02:20.651186537Z,2025-07-17T16:02:20.651020858Z,10,2,1108,C,A,-1,14.42,100,0,165679,271676048,13.04,2,1,13.03,100,1,13.02,100,1,12.73,100,1,12.71,100,1,12.5,700,1,12.46,200,2,12.43,700,1,12.42,700,1,12.37,700,1,13.83,100,1,13.92,2,1,14.19,100,1,14.28,100,1,14.43,200,2,14.51,100,1,14.53,700,1,14.56,800,2,14.57,100,1,14.6,700,1,ARL,325520705
1059,2025-07-17T16:02:20.651201182Z,2025-07-17T16:02:20.651035000Z,10,2,1108,C,A,-1,14.19,100,130,166182,271676049,13.04,2,1,13.03,100,1,13.02,100,1,12.73,100,1,12.71,100,1,12.5,700,1,12.46,200,2,12.43,700,1,12.42,700,1,12.37,700,1,13.83,100,1,13.92,2,1,14.28,100,1,14.43,200,2,14.51,100,1,14.53,700,1,14.56,800,2,14.57,100,1,14.6,700,1,14.64,100,1,ARL,324942273
1060,2025-07-17T16:02:20.651558948Z,2025-07-17T16:02:20.651393708Z,10,2,1108,A,A,4,14.45,100,130,165240,271676057,13.04,2,1,13.03,100,1,13.02,100,1,12.73,100,1,12.71,100,1,12.5,700,1,12.46,200,2,12.43,700,1,12.42,700,1,12.37,700,1,13.83,100,1,13.92,2,1,14.28,100,1,14.43,200,2,14.45,100,1,14.51,100,1,14.53,700,1,14.56,800,2,14.57,100,1,14.6,700,1,ARL,325714601
1061,2025-07-17T16:02:20.651787813Z,2025-07-17T16:02:20.651618897Z,10,2,1108,C,A,3,14.43,100,0,168916,271676089,13.04,2,1,13.03,100,1,13.02,100,1,12.73,100,1,12.71,100,1,12.5,700,1,12.46,200,2,12.43,700,1,12.42,700,1,12.37,700,1,13.83,100,1,13.92,2,1,14.28,100,1,14.43,100,1,14.45,100,1,14.51,100,1,14.53,700,1,14.56,800,2,14.57,100,1,14.6,700,1,ARL,325382437
1062,2025-07-17T16:02:20.652021618Z,2025-07-17T16:02:20.651854531Z,10,2,1108,C,A,-1,14.57,100,0,167087,271676104,13.04,2,1,13.03,100,1,13.02,100,1,12.73,100,1,12.71,100,1,12.5,700,1,12.46,200,2,12.43,700,1,12.42,700,1,12.37,700,1,13.83,100,1,13.92,2,1,14.28,100,1,14.43,100,1,14.45,100,1,14.51,100,1,14.53,700,1,14.56,800,2,14.6,700,1,14.64,100,1,ARL,324619409
1063,2025-07-17T16:02:20.652097288Z,2025-07-17T16:02:20.651932129Z,10,2,1108,C,A,-1,14.43,100,130,165159,271676110,13.04,2,1,13.03,100,1,13.02,100,1,12.73,100,1,12.71,100,1,12.5,700,1,12.46,200,2,12.43,700,1,12.42,700,1,12.37,700,1,13.83,100,1,13.92,2,1,14.28,100,1,14.45,100,1,14.51,100,1,14.53,700,1,14.56,800,2,14.6,700,1,14.64,100,1,14.68,700,1,ARL,324186781
1064,2025-07-17T16:02:20.652259931Z,2025-07-17T16:02:20.652094426Z,10,2,1108,A,A,8,14.63,100,130,165505,271676118,13.04,2,1,13.03,100,1,13.02,100,1,12.73,100,1,12.71,100,1,12.5,700,1,12.46,200,2,12.43,700,1,12.42,700,1,12.37,700,1,13.83,100,1,13.92,2,1,14.28,100,1,14.45,100,1,14.51,100,1,14.53,700,1,14.56,800,2,14.6,700,1,14.63,100,1,14.64,100,1,ARL,325714653
1065,2025-07-17T16:02:20.653626391Z,2025-07-17T16:02:20.653460814Z,10,2,1108,A,B,0,13.27,10,130,165577,271676147,13.27,10,1,13.04,2,1,13.03,100,1,13.02,100,1,12.73,100,1,12.71,100,1,12.5,700,1,12.46,200,2,12.43,700,1,12.42,700,1,13.83,100,1,13.92,2,1,14.28,100,1,14.45,100,1,14.51,100,1,14.53,700,1,14.56,800,2,14.6,700,1,14.63,100,1,14.64,100,1,ARL,325714717
1066,2025-07-17T16:02:20.653627232Z,2025-07-17T16:02:20.653461966Z,10,2,1108,A,A,0,13.83,15,130,165266,271676148,13.27,10,1,13.04,2,1,13.03,100,1,13.02,100,1,12.73,100,1,12.71,100,1,12.5,700,1,12.46,200,2,12.43,700,1,12.42,700,1,13.83,115,2,13.92,2,1,14.28,100,1,14.45,100,1,14.51,100,1,14.53,700,1,14.56,800,2,14.6,700,1,14.63,100,1,14.64,100,1,ARL,325714721
1067,2025-07-17T16:02:20.653886896Z,2025-07-17T16:02:20.653721185Z,10,2,1108,C,B,-1,13.02,100,0,165711,271676153,13.27,10,1,13.04,2,1,13.03,100,1,12.73,100,1,12.71,100,1,12.5,700,1,12.46,200,2,12.43,700,1,12.42,700,1,12.37,700,1,13.83,115,2,13.92,2,1,14.28,100,1,14.45,100,1,14.51,100,1,14.53,700,1,14.56,800,2,14.6,700,1,14.63,100,1,14.64,100,1,ARL,320485385
1068,2025-07-17T16:02:20.653886896Z,2025-07-17T16:02:20.653721185Z,10,2,1108,A,B,1,13.26,100,130,165711,271676153,13.27,10,1,13.26,100,1,13.04,2,1,13.03,100,1,12.73,100,1,12.71,100,1,12.5,700,1,12.46,200,2,12.43,700,1,12.42,700,1,13.83,115,2,13.92,2,1,14.28,100,1,14.45,100,1,14.51,100,1,14.53,700,1,14.56,800,2,14.6,700,1,14.63,100,1,14.64,100,1,ARL,325714729
1069,2025-07-17T16:02:20.655277066Z,2025-07-17T16:02:20.655111649Z,10,2,1108,C,B,-1,13.04,2,0,165417,271676165,13.27,10,1,13.26,100,1,13.03,100,1,12.73,100,1,12.71,100,1,12.5,700,1,12.46,200,2,12.43,700,1,12.42,700,1,12.37,700,1,13.83,115,2,13.92,2,1,14.28,100,1,14.45,100,1,14.51,100,1,14.53,700,1,14.56,800,2,14.6,700,1,14.63,100,1,14.64,100,1,ARL,293594281
1070,2025-07-17T16:02:20.655277066Z,2025-07-17T16:02:20.655111649Z,10,2,1108,A,B,3,12.91,2,130,165417,271676165,13.27,10,1,13.26,100,1,13.03,100,1,12.91,2,1,12.73,100,1,12.71,100,1,12.5,700,1,12.46,200,2,12.43,700,1,12.42,700,1,13.83,115,2,13.92,2,1,14.28,100,1,14.45,100,1,14.51,100,1,14.53,700,1,14.56,800,2,14.6,700,1,14.63,100,1,14.64,100,1,ARL,325714741
1071,2025-07-17T16:02:20.663374576Z,2025-07-17T16:02:20.663209235Z,10,2,1108,C,A,0,13.83,100,130,165341,271676274,13.27,10,1,13.26,100,1,13.03,100,1,12.91,2,1,12.73,100,1,12.71,100,1,12.5,700,1,12.46,200,2,12.43,700,1,12.42,700,1,13.83,15,1,13.92,2,1,14.28,100,1,14.45,100,1,14.51,100,1,14.53,700,1,14.56,800,2,14.6,700,1,14.63,100,1,14.64,100,1,ARL,325176373
1072,2025-07-17T16:02:20.663406861Z,2025-07-17T16:02:20.663241882Z,10,2,1108,C,A,-1,14.53,700,130,164979,271676275,13.27,10,1,13.26,100,1,13.03,100,1,12.91,2,1,12.73,100,1,12.71,100,1,12.5,700,1,12.46,200,2,12.43,700,1,12.42,700,1,13.83,15,1,13.92,2,1,14.28,100,1,14.45,100,1,14.51,100,1,14.56,800,2,14.6,700,1,14.63,100,1,14.64,100,1,14.68,700,1,ARL,325714545
1073,2025-07-17T16:02:20.663426974Z,2025-07-17T16:02:20.663261632Z,10,2,1108,A,A,2,14.11,100,130,165342,271676276,13.27,10,1,13.26,100,1,13.03,100,1,12.91,2,1,12.73,100,1,12.71,100,1,12.5,700,1,12.46,200,2,12.43,700,1,12.42,700,1,13.83,15,1,13.92,2,1,14.11,100,1,14.28,100,1,14.45,100,1,14.51,100,1,14.56,800,2,14.6,700,1,14.63,100,1,14.64,100,1,ARL,325714905
1074,2025-07-17T16:02:20.669701452Z,2025-07-17T16:02:20.669536385Z,10,2,1108,C,A,-1,14.11,100,130,165067,271676398,13.27,10,1,13.26,100,1,13.03,100,1,12.91,2,1,12.73,100,1,12.71,100,1,12.5,700,1,12.46,200,2,12.43,700,1,12.42,700,1,13.83,15,1,13.92,2,1,14.28,100,1,14.45,100,1,14.51,100,1,14.56,800,2,14.6,700,1,14.63,100,1,14.64,100,1,14.68,700,1,ARL,325714905
1075,2025-07-17T16:02:20.669748954Z,2025-07-17T16:02:20.669583810Z,10,2,1108,A,A,2,14.26,100,130,165144,271676399,13.27,10,1,13.26,100,1,13.03,100,1,12.91,2,1,12.73,100,1,12.71,100,1,12.5,700,1,12.46,200,2,12.43,700,1,12.42,700,1,13.83,15,1,13.92,2,1,14.26,100,1,14.28,100,1,14.45,100,1,14.51,100,1,14.56,800,2,14.6,700,1,14.63,100,1,14.64,100,1,ARL,325715045
1076,2025-07-17T16:02:20.669752979Z,2025-07-17T16:02:20.669587514Z,10,2,1108,C,A,-1,14.51,100,0,165465,271676400,13.27,10,1,13.26,100,1,13.03,100,1,12.91,2,1,12.73,100,1,12.71,100,1,12.5,700,1,12.46,200,2,12.43,700,1,12.42,700,1,13.83,15,1,13.92,2,1,14.26,100,1,14.28,100,1,14.45,100,1,14.56,800,2,14.6,700,1,14.63,100,1,14.64,100,1,14.68,700,1,ARL,325177757
1077,2025-07-17T16:02:20.685252049Z,2025-07-17T16:02:20.685086585Z,10,2,1108,C,A,-1,14.64,100,0,165464,271676621,13.27,10,1,13.26,100,1,13.03,100,1,12.91,2,1,12.73,100,1,12.71,100,1,12.5,700,1,12.46,200,2,12.43,700,1,12.42,700,1,13.83,15,1,13.92,2,1,14.26,100,1,14.28,100,1,14.45,100,1,14.56,800,2,14.6,700,1,14.63,100,1,14.68,700,1,14.73,200,2,ARL,325714169
1078,2025-07-17T16:02:20.832112637Z,2025-07-17T16:02:20.831947250Z,10,2,1108,A,A,8,14.68,700,130,165387,271678584,13.27,10,1,13.26,100,1,13.03,100,1,12.91,2,1,12.73,100,1,12.71,100,1,12.5,700,1,12.46,200,2,12.43,700,1,12.42,700,1,13.83,15,1,13.92,2,1,14.26,100,1,14.28,100,1,14.45,100,1,14.56,800,2,14.6,700,1,14.63,100,1,14.68,1400,2,14.73,200,2,ARL,325716945
1079,2025-07-17T16:02:20.936787418Z,2025-07-17T16:02:20.936622241Z,10,2,1108,C,B,-1,13.26,100,130,165177,271679553,13.27,10,1,13.03,100,1,12.91,2,1,12.73,100,1,12.71,100,1,12.5,700,1,12.46,200,2,12.43,700,1,12.42,700,1,12.37,700,1,13.83,15,1,13.92,2,1,14.26,100,1,14.28,100,1,14.45,100,1,14.56,800,2,14.6,700,1,14.63,100,1,14.68,1400,2,14.73,200,2,ARL,325714729
1080,2025-07-17T16:02:20.936837611Z,2025-07-17T16:02:20.936672130Z,10,2,1108,A,A,1,13.91,5,130,165481,271679555,13.27,10,1,13.03,100,1,12.91,2,1,12.73,100,1,12.71,100,1,12.5,700,1,12.46,200,2,12.43,700,1,12.42,700,1,12.37,700,1,13.83,15,1,13.91,5,1,13.92,2,1,14.26,100,1,14.28,100,1,14.45,100,1,14.56,800,2,14.6,700,1,14.63,100,1,14.68,1400,2,ARL,325718477
1081,2025-07-17T16:02:20.936999211Z,2025-07-17T16:02:20.936833988Z,10,2,1108,A,A,1,13.84,100,130,165223,271679558,13.27,10,1,13.03,100,1,12.91,2,1,12.73,100,1,12.71,100,1,12.5,700,1,12.46,200,2,12.43,700,1,12.42,700,1,12.37,700,1,13.83,15,1,13.84,100,1,13.91,5,1,13.92,2,1,14.26,100,1,14.28,100,1,14.45,100,1,14.56,800,2,14.6,700,1,14.63,100,1,ARL,325718485
1082,2025-07-17T16:02:20.937901293Z,2025-07-17T16:02:20.937736247Z,10,2,1108,C,A,-1,13.91,5,130,165046,271679567,13.27,10,1,13.03,100,1,12.91,2,1,12.73,100,1,12.71,100,1,12.5,700,1,12.46,200,2,12.43,700,1,12.42,700,1,12.37,700,1,13.83,15,1,13.84,100,1,13.92,2,1,14.26,100,1,14.28,100,1,14.45,100,1,14.56,800,2,14.6,700,1,14.63,100,1,14.68,1400,2,ARL,325718477
1083,2025-07-17T16:02:20.939554686Z,2025-07-17T16:02:20.939389367Z,10,2,1108,A,B,2,13.02,100,130,165319,271679578,13.27,10,1,13.03,100,1,13.02,100,1,12.91,2,1,12.73,100,1,12.71,100,1,12.5,700,1,12.46,200,2,12.43,700,1,12.42,700,1,13.83,15,1,13.84,100,1,13.92,2,1,14.26,100,1,14.28,100,1,14.45,100,1,14.56,800,2,14.6,700,1,14.63,100,1,14.68,1400,2,ARL,325718561
1084,2025-07-17T16:02:20.946406202Z,2025-07-17T16:02:20.946240970Z,10,2,1108,C,A,-1,14.26,100,130,165232,271679616,13.27,10,1,13.03,100,1,13.02,100,1,12.91,2,1,12.73,100,1,12.71,100,1,12.5,700,1,12.46,200,2,12.43,700,1,12.42,700,1,13.83,15,1,13.84,100,1,13.92,2,1,14.28,100,1,14.45,100,1,14.56,800,2,14.6,700,1,14.63,100,1,14.68,1400,2,14.73,200,2,ARL,325715045
1085,2025-07-17T16:02:20.946456786Z,2025-07-17T16:02:20.946291345Z,10,2,1108,A,A,3,14.12,100,130,165441,271679617,13.27,10,1,13.03,100,1,13.02,100,1,12.91,2,1,12.73,100,1,12.71,100,1,12.5,700,1,12.46,200,2,12.43,700,1,12.42,700,1,13.83,15,1,13.84,100,1,13.92,2,1,14.12,100,1,14.28,100,1,14.45,100,1,14.56,800,2,14.6,700,1,14.63,100,1,14.68,1400,2,ARL,325718637
1086,2025-07-17T16:02:20.957051613Z,2025-07-17T16:02:20.956886401Z,10,2,1108,C,B,-1,13.02,100,0,165212,271679685,13.27,10,1,13.03,100,1,12.91,2,1,12.73,100,1,12.71,100,1,12.5,700,1,12.46,200,2,12.43,700,1,12.42,700,1,12.37,700,1,13.83,15,1,13.84,100,1,13.92,2,1,14.12,100,1,14.28,100,1,14.45,100,1,14.56,800,2,14.6,700,1,14.63,100,1,14.68,1400,2,ARL,325718561
1087,2025-07-17T16:02:20.957051613Z,2025-07-17T16:02:20.956886401Z,10,2,1108,A,B,1,13.26,100,130,165212,271679685,13.27,10,1,13.26,100,1,13.03,100,1,12.91,2,1,12.73,100,1,12.71,100,1,12.5,700,1,12.46,200,2,12.43,700,1,12.42,700,1,13.83,15,1,13.84,100,1,13.92,2,1,14.12,100,1,14.28,100,1,14.45,100,1,14.56,800,2,14.6,700,1,14.63,100,1,14.68,1400,2,ARL,325718821
1088,2025-07-17T16:02:20.957089143Z,2025-07-17T16:02:20.956923753Z,10,2,1108,A,B,2,13.12,100,130,165390,271679686,13.27,10,1,13.26,100,1,13.12,100,1,13.03,100,1,12.91,2,1,12.73,100,1,12.71,100,1,12.5,700,1,12.46,200,2,12.43,700,1,13.83,15,1,13.84,100,1,13.92,2,1,14.12,100,1,14.28,100,1,14.45,100,1,14.56,800,2,14.6,700,1,14.63,100,1,14.68,1400,2,ARL,325718833
1089,2025-07-17T16:02:20.957090484Z,2025-07-17T16:02:20.956925447Z,10,2,1108,A,B,2,13.12,100,130,165037,271679687,13.27,10,1,13.26,100,1,13.12,200,2,13.03,100,1,12.91,2,1,12.73,100,1,12.71,100,1,12.5,700,1,12.46,200,2,12.43,700,1,13.83,15,1,13.84,100,1,13.92,2,1,14.12,100,1,14.28,100,1,14.45,100,1,14.56,800,2,14.6,700,1,14.63,100,1,14.68,1400,2,ARL,325718837
1090,2025-07-17T16:02:20.988655870Z,2025-07-17T16:02:20.988490644Z,10,2,1108,A,A,3,13.98,100,130,165226,271679923,13.27,10,1,13.26,100,1,13.12,200,2,13.03,100,1,12.91,2,1,12.73,100,1,12.71,100,1,12.5,700,1,12.46,200,2,12.43,700,1,13.83,15,1,13.84,100,1,13.92,2,1,13.98,100,1,14.12,100,1,14.28,100,1,14.45,100,1,14.56,800,2,14.6,700,1,14.63,100,1,ARL,325719353
1091,2025-07-17T16:02:20.988656944Z,2025-07-17T16:02:20.988491826Z,10,2,1108,A,A,3,13.98,100,130,165118,271679924,13.27,10,1,13.26,100,1,13.12,200,2,13.03,100,1,12.91,2,1,12.73,100,1,12.71,100,1,12.5,700,1,12.46,200,2,12.43,700,1,13.83,15,1,13.84,100,1,13.92,2,1,13.98,200,2,14.12,100,1,14.28,100,1,14.45,100,1,14.56,800,2,14.6,700,1,14.63,100,1,ARL,325719357
1092,2025-07-17T16:02:30.805193695Z,2025-07-17T16:02:30.805028316Z,10,2,1108,C,B,-1,13.27,10,130,165379,271818376,13.26,100,1,13.12,200,2,13.03,100,1,12.91,2,1,12.73,100,1,12.71,100,1,12.5,700,1,12.46,200,2,12.43,700,1,12.42,700,1,13.83,15,1,13.84,100,1,13.92,2,1,13.98,200,2,14.12,100,1,14.28,100,1,14.45,100,1,14.56,800,2,14.6,700,1,14.63,100,1,ARL,325714717
1093,2025-07-17T16:02:34.987171397Z,2025-07-17T16:02:34.987005787Z,10,2,1108,C,B,-1,12.91,2,0,165610,271871706,13.26,100,1,13.12,200,2,13.03,100,1,12.73,100,1,12.71,100,1,12.5,700,1,12.46,200,2,12.43,700,1,12.42,700,1,12.37,700,1,13.83,15,1,13.84,100,1,13.92,2,1,13.98,200,2,14.12,100,1,14.28,100,1,14.45,100,1,14.56,800,2,14.6,700,1,14.63,100,1,ARL,325714741
1094,2025-07-17T16:02:34.987171397Z,2025-07-17T16:02:34.987005787Z,10,2,1108,A,B,3,13,2,130,165610,271871706,13.26,100,1,13.12,200,2,13.03,100,1,13,2,1,12.73,100,1,12.71,100,1,12.5,700,1,12.46,200,2,12.43,700,1,12.42,700,1,13.83,15,1,13.84,100,1,13.92,2,1,13.98,200,2,14.12,100,1,14.28,100,1,14.45,100,1,14.56,800,2,14.6,700,1,14.63,100,1,ARL,325967705
1095,2025-07-17T16:02:39.809464961Z,2025-07-17T16:02:39.809299504Z,10,2,1108,A,A,0,13.79,15,130,165457,271952021,13.26,100,1,13.12,200,2,13.03,100,1,13,2,1,12.73,100,1,12.71,100,1,12.5,700,1,12.46,200,2,12.43,700,1,12.42,700,1,13.79,15,1,13.83,15,1,13.84,100,1,13.92,2,1,13.98,200,2,14.12,100,1,14.28,100,1,14.45,100,1,14.56,800,2,14.6,700,1,ARL,326077141
1096,2025-07-17T16:02:40.007472020Z,2025-07-17T16:02:40.007306432Z,10,2,1108,C,A,-1,13.84,100,0,165588,271957331,13.26,100,1,13.12,200,2,13.03,100,1,13,2,1,12.73,100,1,12.71,100,1,12.5,700,1,12.46,200,2,12.43,700,1,12.42,700,1,13.79,15,1,13.83,15,1,13.92,2,1,13.98,200,2,14.12,100,1,14.28,100,1,14.45,100,1,14.56,800,2,14.6,700,1,14.63,100,1,ARL,325718485
1097,2025-07-17T16:02:40.007472020Z,2025-07-17T16:02:40.007306432Z,10,2,1108,A,A,1,13.8,100,130,165588,271957331,13.26,100,1,13.12,200,2,13.03,100,1,13,2,1,12.73,100,1,12.71,100,1,12.5,700,1,12.46,200,2,12.43,700,1,12.42,700,1,13.79,15,1,13.8,100,1,13.83,15,1,13.92,2,1,13.98,200,2,14.12,100,1,14.28,100,1,14.45,100,1,14.56,800,2,14.6,700,1,ARL,326082329
1098,2025-07-17T16:02:40.795014471Z,2025-07-17T16:02:40.794847674Z,10,2,1108,C,A,-1,13.79,15,130,166797,271972417,13.26,100,1,13.12,200,2,13.03,100,1,13,2,1,12.73,100,1,12.71,100,1,12.5,700,1,12.46,200,2,12.43,700,1,12.42,700,1,13.8,100,1,13.83,15,1,13.92,2,1,13.98,200,2,14.12,100,1,14.28,100,1,14.45,100,1,14.56,800,2,14.6,700,1,14.63,100,1,ARL,326077141
1099,2025-07-17T16:02:40.806305895Z,2025-07-17T16:02:40.806140621Z,10,2,1108,C,A,-1,13.83,15,130,165274,271973288,13.26,100,1,13.12,200,2,13.03,100,1,13,2,1,12.73,100,1,12.71,100,1,12.5,700,1,12.46,200,2,12.43,700,1,12.42,700,1,13.8,100,1,13.92,2,1,13.98,200,2,14.12,100,1,14.28,100,1,14.45,100,1,14.56,800,2,14.6,700,1,14.63,100,1,14.68,1400,2,ARL,325714721
1100,2025-07-17T16:02:43.841852430Z,2025-07-17T16:02:43.841686908Z,10,2,1108,C,B,-1,13.26,100,130,165522,272014658,13.12,200,2,13.03,100,1,13,2,1,12.73,100,1,12.71,100,1,12.5,700,1,12.46,200,2,12.43,700,1,12.42,700,1,12.37,700,1,13.8,100,1,13.92,2,1,13.98,200,2,14.12,100,1,14.28,100,1,14.45,100,1,14.56,800,2,14.6,700,1,14.63,100,1,14.68,1400,2,ARL,325718821
1101,2025-07-17T16:02:43.841912053Z,2025-07-17T16:02:43.841746626Z,10,2,1108,A,A,1,13.9,4,130,165427,272014659,13.12,200,2,13.03,100,1,13,2,1,12.73,100,1,12.71,100,1,12.5,700,1,12.46,200,2,12.43,700,1,12.42,700,1,12.37,700,1,13.8,100,1,13.9,4,1,13.92,2,1,13.98,200,2,14.12,100,1,14.28,100,1,14.45,100,1,14.56,800,2,14.6,700,1,14.63,100,1,ARL,326158809
1102,2025-07-17T16:02:43.842295427Z,2025-07-17T16:02:43.842130114Z,10,2,1108,C,A,-1,13.8,100,130,165313,272014661,13.12,200,2,13.03,100,1,13,2,1,12.73,100,1,12.71,100,1,12.5,700,1,12.46,200,2,12.43,700,1,12.42,700,1,12.37,700,1,13.9,4,1,13.92,2,1,13.98,200,2,14.12,100,1,14.28,100,1,14.45,100,1,14.56,800,2,14.6,700,1,14.63,100,1,14.68,1400,2,ARL,326082329
1103,2025-07-17T16:02:43.843106749Z,2025-07-17T16:02:43.842941514Z,10,2,1108,A,B,1,13.11,100,130,165235,272014674,13.12,200,2,13.11,100,1,13.03,100,1,13,2,1,12.73,100,1,12.71,100,1,12.5,700,1,12.46,200,2,12.43,700,1,12.42,700,1,13.9,4,1,13.92,2,1,13.98,200,2,14.12,100,1,14.28,100,1,14.45,100,1,14.56,800,2,14.6,700,1,14.63,100,1,14.68,1400,2,ARL,326158877
1104,2025-07-17T16:02:43.843204692Z,2025-07-17T16:02:43.843039530Z,10,2,1108,C,A,-1,13.9,4,130,165162,272014681,13.12,200,2,13.11,100,1,13.03,100,1,13,2,1,12.73,100,1,12.71,100,1,12.5,700,1,12.46,200,2,12.43,700,1,12.42,700,1,13.92,2,1,13.98,200,2,14.12,100,1,14.28,100,1,14.45,100,1,14.56,800,2,14.6,700,1,14.63,100,1,14.68,1400,2,14.73,200,2,ARL,326158809
1105,2025-07-17T16:02:43.847026795Z,2025-07-17T16:02:43.846861336Z,10,2,1108,C,A,-1,13.92,2,0,165459,272014713,13.12,200,2,13.11,100,1,13.03,100,1,13,2,1,12.73,100,1,12.71,100,1,12.5,700,1,12.46,200,2,12.43,700,1,12.42,700,1,13.98,200,2,14.12,100,1,14.28,100,1,14.45,100,1,14.56,800,2,14.6,700,1,14.63,100,1,14.68,1400,2,14.73,200,2,14.92,100,1,ARL,325297093
1106,2025-07-17T16:02:43.847026795Z,2025-07-17T16:02:43.846861336Z,10,2,1108,A,A,1,14.03,2,130,165459,272014713,13.12,200,2,13.11,100,1,13.03,100,1,13,2,1,12.73,100,1,12.71,100,1,12.5,700,1,12.46,200,2,12.43,700,1,12.42,700,1,13.98,200,2,14.03,2,1,14.12,100,1,14.28,100,1,14.45,100,1,14.56,800,2,14.6,700,1,14.63,100,1,14.68,1400,2,14.73,200,2,ARL,326159041
1107,2025-07-17T16:02:43.847832258Z,2025-07-17T16:02:43.847666979Z,10,2,1108,C,A,9,14.73,100,0,165279,272014721,13.12,200,2,13.11,100,1,13.03,100,1,13,2,1,12.73,100,1,12.71,100,1,12.5,700,1,12.46,200,2,12.43,700,1,12.42,700,1,13.98,200,2,14.03,2,1,14.12,100,1,14.28,100,1,14.45,100,1,14.56,800,2,14.6,700,1,14.63,100,1,14.68,1400,2,14.73,100,1,ARL,325714613
1108,2025-07-17T16:02:43.848147198Z,2025-07-17T16:02:43.847981726Z,10,2,1108,C,A,-1,14.73,100,0,165472,272014724,13.12,200,2,13.11,100,1,13.03,100,1,13,2,1,12.73,100,1,12.71,100,1,12.5,700,1,12.46,200,2,12.43,700,1,12.42,700,1,13.98,200,2,14.03,2,1,14.12,100,1,14.28,100,1,14.45,100,1,14.56,800,2,14.6,700,1,14.63,100,1,14.68,1400,2,14.87,100,1,ARL,325714577
1109,2025-07-17T16:02:43.848147198Z,2025-07-17T16:02:43.847981726Z,10,2,1108,A,A,9,14.87,100,130,165472,272014724,13.12,200,2,13.11,100,1,13.03,100,1,13,2,1,12.73,100,1,12.71,100,1,12.5,700,1,12.46,200,2,12.43,700,1,12.42,700,1,13.98,200,2,14.03,2,1,14.12,100,1,14.28,100,1,14.45,100,1,14.56,800,2,14.6,700,1,14.63,100,1,14.68,1400,2,14.87,200,2,ARL,326159061
1110,2025-07-17T16:02:43.860199647Z,2025-07-17T16:02:43.860034354Z,10,2,1108,C,A,-1,14.12,100,130,165293,272014788,13.12,200,2,13.11,100,1,13.03,100,1,13,2,1,12.73,100,1,12.71,100,1,12.5,700,1,12.46,200,2,12.43,700,1,12.42,700,1,13.98,200,2,14.03,2,1,14.28,100,1,14.45,100,1,14.56,800,2,14.6,700,1,14.63,100,1,14.68,1400,2,14.87,200,2,14.92,100,1,ARL,325718637
1111,2025-07-17T16:02:43.860252446Z,2025-07-17T16:02:43.860087215Z,10,2,1108,A,A,2,14.26,100,130,165231,272014789,13.12,200,2,13.11,100,1,13.03,100,1,13,2,1,12.73,100,1,12.71,100,1,12.5,700,1,12.46,200,2,12.43,700,1,12.42,700,1,13.98,200,2,14.03,2,1,14.26,100,1,14.28,100,1,14.45,100,1,14.56,800,2,14.6,700,1,14.63,100,1,14.68,1400,2,14.87,200,2,ARL,326159201
1112,2025-07-17T16:02:43.946967137Z,2025-07-17T16:02:43.946801538Z,10,2,1108,C,A,-1,14.63,100,0,165599,272015584,13.12,200,2,13.11,100,1,13.03,100,1,13,2,1,12.73,100,1,12.71,100,1,12.5,700,1,12.46,200,2,12.43,700,1,12.42,700,1,13.98,200,2,14.03,2,1,14.26,100,1,14.28,100,1,14.45,100,1,14.56,800,2,14.6,700,1,14.68,1400,2,14.87,200,2,14.96,200,2,ARL,325714653
1113,2025-07-17T16:02:43.946967137Z,2025-07-17T16:02:43.946801538Z,10,2,1108,A,A,8,14.77,100,130,165599,272015584,13.12,200,2,13.11,100,1,13.03,100,1,13,2,1,12.73,100,1,12.71,100,1,12.5,700,1,12.46,200,2,12.43,700,1,12.42,700,1,13.98,200,2,14.03,2,1,14.26,100,1,14.28,100,1,14.45,100,1,14.56,800,2,14.6,700,1,14.68,1400,2,14.77,100,1,14.87,200,2,ARL,326160141
1114,2025-07-17T16:02:44.664219784Z,2025-07-17T16:02:44.664054457Z,10,2,1108,A,A,1,13.99,100,130,165327,272021808,13.12,200,2,13.11,100,1,13.03,100,1,13,2,1,12.73,100,1,12.71,100,1,12.5,700,1,12.46,200,2,12.43,700,1,12.42,700,1,13.98,200,2,13.99,100,1,14.03,2,1,14.26,100,1,14.28,100,1,14.45,100,1,14.56,800,2,14.6,700,1,14.68,1400,2,14.77,100,1,ARL,326167529
1115,2025-07-17T16:03:02.985987598Z,2025-07-17T16:03:02.985818199Z,10,2,1108,A,A,9,14.7,100,128,169399,272331833,13.12,200,2,13.11,100,1,13.03,100,1,13,2,1,12.73,100,1,12.71,100,1,12.5,700,1,12.46,200,2,12.43,700,1,12.42,700,1,13.98,200,2,13.99,100,1,14.03,2,1,14.26,100,1,14.28,100,1,14.45,100,1,14.56,800,2,14.6,700,1,14.68,1400,2,14.7,100,1,ARL,326551237
1116,2025-07-17T16:03:02.987969729Z,2025-07-17T16:03:02.987797728Z,10,2,1108,A,A,9,14.7,100,128,172001,272332718,13.12,200,2,13.11,100,1,13.03,100,1,13,2,1,12.73,100,1,12.71,100,1,12.5,700,1,12.46,200,2,12.43,700,1,12.42,700,1,13.98,200,2,13.99,100,1,14.03,2,1,14.26,100,1,14.28,100,1,14.45,100,1,14.56,800,2,14.6,700,1,14.68,1400,2,14.7,200,2,ARL,326551829
1117,2025-07-17T16:03:10.807446975Z,2025-07-17T16:03:10.807281669Z,10,2,1108,A,A,0,13.72,15,130,165306,272474575,13.12,200,2,13.11,100,1,13.03,100,1,13,2,1,12.73,100,1,12.71,100,1,12.5,700,1,12.46,200,2,12.43,700,1,12.42,700,1,13.72,15,1,13.98,200,2,13.99,100,1,14.03,2,1,14.26,100,1,14.28,100,1,14.45,100,1,14.56,800,2,14.6,700,1,14.68,1400,2,ARL,326729677
1118,2025-07-17T16:03:10.807714421Z,2025-07-17T16:03:10.807548848Z,10,2,1108,C,A,-1,13.99,100,0,165573,272474576,13.12,200,2,13.11,100,1,13.03,100,1,13,2,1,12.73,100,1,12.71,100,1,12.5,700,1,12.46,200,2,12.43,700,1,12.42,700,1,13.72,15,1,13.98,200,2,14.03,2,1,14.26,100,1,14.28,100,1,14.45,100,1,14.56,800,2,14.6,700,1,14.68,1400,2,14.7,200,2,ARL,326167529
1119,2025-07-17T16:03:10.807714421Z,2025-07-17T16:03:10.807548848Z,10,2,1108,A,A,1,13.73,100,130,165573,272474576,13.12,200,2,13.11,100,1,13.03,100,1,13,2,1,12.73,100,1,12.71,100,1,12.5,700,1,12.46,200,2,12.43,700,1,12.42,700,1,13.72,15,1,13.73,100,1,13.98,200,2,14.03,2,1,14.26,100,1,14.28,100,1,14.45,100,1,14.56,800,2,14.6,700,1,14.68,1400,2,ARL,326729685
1120,2025-07-17T16:03:10.810059442Z,2025-07-17T16:03:10.809894317Z,10,2,1108,A,A,7,14.52,100,130,165125,272474597,13.12,200,2,13.11,100,1,13.03,100,1,13,2,1,12.73,100,1,12.71,100,1,12.5,700,1,12.46,200,2,12.43,700,1,12.42,700,1,13.72,15,1,13.73,100,1,13.98,200,2,14.03,2,1,14.26,100,1,14.28,100,1,14.45,100,1,14.52,100,1,14.56,800,2,14.6,700,1,ARL,326729729
1121,2025-07-17T16:03:10.817866066Z,2025-07-17T16:03:10.817700664Z,10,2,1108,C,A,-1,14.26,100,130,165402,272474675,13.12,200,2,13.11,100,1,13.03,100,1,13,2,1,12.73,100,1,12.71,100,1,12.5,700,1,12.46,200,2,12.43,700,1,12.42,700,1,13.72,15,1,13.73,100,1,13.98,200,2,14.03,2,1,14.28,100,1,14.45,100,1,14.52,100,1,14.56,800,2,14.6,700,1,14.68,1400,2,ARL,326159201
1122,2025-07-17T16:03:10.817919970Z,2025-07-17T16:03:10.817754737Z,10,2,1108,A,A,3,14,100,130,165233,272474676,13.12,200,2,13.11,100,1,13.03,100,1,13,2,1,12.73,100,1,12.71,100,1,12.5,700,1,12.46,200,2,12.43,700,1,12.42,700,1,13.72,15,1,13.73,100,1,13.98,200,2,14,100,1,14.03,2,1,14.28,100,1,14.45,100,1,14.52,100,1,14.56,800,2,14.6,700,1,ARL,326729929
1123,2025-07-17T16:03:10.843615537Z,2025-07-17T16:03:10.843448998Z,10,2,1108,C,A,2,13.98,100,0,166539,272474828,13.12,200,2,13.11,100,1,13.03,100,1,13,2,1,12.73,100,1,12.71,100,1,12.5,700,1,12.46,200,2,12.43,700,1,12.42,700,1,13.72,15,1,13.73,100,1,13.98,100,1,14,100,1,14.03,2,1,14.28,100,1,14.45,100,1,14.52,100,1,14.56,800,2,14.6,700,1,ARL,325719357
1124,2025-07-17T16:03:10.843615537Z,2025-07-17T16:03:10.843449402Z,10,2,1108,C,A,-1,13.98,100,130,166135,272474829,13.12,200,2,13.11,100,1,13.03,100,1,13,2,1,12.73,100,1,12.71,100,1,12.5,700,1,12.46,200,2,12.43,700,1,12.42,700,1,13.72,15,1,13.73,100,1,14,100,1,14.03,2,1,14.28,100,1,14.45,100,1,14.52,100,1,14.56,800,2,14.6,700,1,14.68,1400,2,ARL,325719353
1125,2025-07-17T16:03:10.843628246Z,2025-07-17T16:03:10.843462898Z,10,2,1108,A,A,2,13.87,100,130,165348,272474830,13.12,200,2,13.11,100,1,13.03,100,1,13,2,1,12.73,100,1,12.71,100,1,12.5,700,1,12.46,200,2,12.43,700,1,12.42,700,1,13.72,15,1,13.73,100,1,13.87,100,1,14,100,1,14.03,2,1,14.28,100,1,14.45,100,1,14.52,100,1,14.56,800,2,14.6,700,1,ARL,326730517
1126,2025-07-17T16:03:10.843629633Z,2025-07-17T16:03:10.843464369Z,10,2,1108,A,A,2,13.87,100,130,165264,272474831,13.12,200,2,13.11,100,1,13.03,100,1,13,2,1,12.73,100,1,12.71,100,1,12.5,700,1,12.46,200,2,12.43,700,1,12.42,700,1,13.72,15,1,13.73,100,1,13.87,200,2,14,100,1,14.03,2,1,14.28,100,1,14.45,100,1,14.52,100,1,14.56,800,2,14.6,700,1,ARL,326730521
1127,2025-07-17T16:03:16.348189077Z,2025-07-17T16:03:16.348023740Z,10,2,1108,A,A,0,13.69,15,130,165337,272557172,13.12,200,2,13.11,100,1,13.03,100,1,13,2,1,12.73,100,1,12.71,100,1,12.5,700,1,12.46,200,2,12.43,700,1,12.42,700,1,13.69,15,1,13.72,15,1,13.73,100,1,13.87,200,2,14,100,1,14.03,2,1,14.28,100,1,14.45,100,1,14.52,100,1,14.56,800,2,ARL,326835877
1128,2025-07-17T16:03:16.352011831Z,2025-07-17T16:03:16.351845457Z,10,2,1108,C,A,-1,13.73,100,0,166374,272557789,13.12,200,2,13.11,100,1,13.03,100,1,13,2,1,12.73,100,1,12.71,100,1,12.5,700,1,12.46,200,2,12.43,700,1,12.42,700,1,13.69,15,1,13.72,15,1,13.87,200,2,14,100,1,14.03,2,1,14.28,100,1,14.45,100,1,14.52,100,1,14.56,800,2,14.58,200,2,ARL,326729685
1129,2025-07-17T16:03:16.352011831Z,2025-07-17T16:03:16.351845457Z,10,2,1108,A,A,1,13.7,100,130,166374,272557789,13.12,200,2,13.11,100,1,13.03,100,1,13,2,1,12.73,100,1,12.71,100,1,12.5,700,1,12.46,200,2,12.43,700,1,12.42,700,1,13.69,15,1,13.7,100,1,13.72,15,1,13.87,200,2,14,100,1,14.03,2,1,14.28,100,1,14.45,100,1,14.52,100,1,14.56,800,2,ARL,326836533
1130,2025-07-17T16:03:18.804325078Z,2025-07-17T16:03:18.804159952Z,10,2,1108,C,A,-1,13.69,15,130,165126,272609485,13.12,200,2,13.11,100,1,13.03,100,1,13,2,1,12.73,100,1,12.71,100,1,12.5,700,1,12.46,200,2,12.43,700,1,12.42,700,1,13.7,100,1,13.72,15,1,13.87,200,2,14,100,1,14.03,2,1,14.28,100,1,14.45,100,1,14.52,100,1,14.56,800,2,14.58,200,2,ARL,326835877
1131,2025-07-17T16:03:18.804367560Z,2025-07-17T16:03:18.804202246Z,10,2,1108,C,A,-1,13.7,100,130,165314,272609486,13.12,200,2,13.11,100,1,13.03,100,1,13,2,1,12.73,100,1,12.71,100,1,12.5,700,1,12.46,200,2,12.43,700,1,12.42,700,1,13.72,15,1,13.87,200,2,14,100,1,14.03,2,1,14.28,100,1,14.45,100,1,14.52,100,1,14.56,800,2,14.58,200,2,14.6,700,1,ARL,326836533
1132,2025-07-17T16:03:18.805449089Z,2025-07-17T16:03:18.805283236Z,10,2,1108,C,A,-1,13.72,15,130,165853,272609541,13.12,200,2,13.11,100,1,13.03,100,1,13,2,1,12.73,100,1,12.71,100,1,12.5,700,1,12.46,200,2,12.43,700,1,12.42,700,1,13.87,200,2,14,100,1,14.03,2,1,14.28,100,1,14.45,100,1,14.52,100,1,14.56,800,2,14.58,200,2,14.6,700,1,14.68,1400,2,ARL,326729677
1133,2025-07-17T16:03:18.806535903Z,2025-07-17T16:03:18.806370373Z,10,2,1108,C,A,7,14.58,100,0,165530,272609577,13.12,200,2,13.11,100,1,13.03,100,1,13,2,1,12.73,100,1,12.71,100,1,12.5,700,1,12.46,200,2,12.43,700,1,12.42,700,1,13.87,200,2,14,100,1,14.03,2,1,14.28,100,1,14.45,100,1,14.52,100,1,14.56,800,2,14.58,100,1,14.6,700,1,14.68,1400,2,ARL,326835885
1134,2025-07-17T16:03:18.806802589Z,2025-07-17T16:03:18.806637004Z,10,2,1108,C,A,-1,14.58,100,0,165585,272609583,13.12,200,2,13.11,100,1,13.03,100,1,13,2,1,12.73,100,1,12.71,100,1,12.5,700,1,12.46,200,2,12.43,700,1,12.42,700,1,13.87,200,2,14,100,1,14.03,2,1,14.28,100,1,14.45,100,1,14.52,100,1,14.56,800,2,14.6,700,1,14.68,1400,2,14.7,100,1,ARL,326836085
1135,2025-07-17T16:03:18.809706334Z,2025-07-17T16:03:18.809540733Z,10,2,1108,C,A,-1,14.52,100,0,165601,272609656,13.12,200,2,13.11,100,1,13.03,100,1,13,2,1,12.73,100,1,12.71,100,1,12.5,700,1,12.46,200,2,12.43,700,1,12.42,700,1,13.87,200,2,14,100,1,14.03,2,1,14.28,100,1,14.45,100,1,14.56,800,2,14.6,700,1,14.68,1400,2,14.7,100,1,14.76,200,2,ARL,326729729
1136,2025-07-17T16:03:18.809706334Z,2025-07-17T16:03:18.809540733Z,10,2,1108,A,A,7,14.66,100,130,165601,272609656,13.12,200,2,13.11,100,1,13.03,100,1,13,2,1,12.73,100,1,12.71,100,1,12.5,700,1,12.46,200,2,12.43,700,1,12.42,700,1,13.87,200,2,14,100,1,14.03,2,1,14.28,100,1,14.45,100,1,14.56,800,2,14.6,700,1,14.66,100,1,14.68,1400,2,14.7,100,1,ARL,326892885
1137,2025-07-17T16:03:18.818245629Z,2025-07-17T16:03:18.818080239Z,10,2,1108,C,A,-1,14,100,130,165390,272609768,13.12,200,2,13.11,100,1,13.03,100,1,13,2,1,12.73,100,1,12.71,100,1,12.5,700,1,12.46,200,2,12.43,700,1,12.42,700,1,13.87,200,2,14.03,2,1,14.28,100,1,14.45,100,1,14.56,800,2,14.6,700,1,14.66,100,1,14.68,1400,2,14.7,100,1,14.76,200,2,ARL,326729929
1138,2025-07-17T16:03:18.818301143Z,2025-07-17T16:03:18.818135688Z,10,2,1108,A,A,2,14.15,100,130,165455,272609769,13.12,200,2,13.11,100,1,13.03,100,1,13,2,1,12.73,100,1,12.71,100,1,12.5,700,1,12.46,200,2,12.43,700,1,12.42,700,1,13.87,200,2,14.03,2,1,14.15,100,1,14.28,100,1,14.45,100,1,14.56,800,2,14.6,700,1,14.66,100,1,14.68,1400,2,14.7,100,1,ARL,326893213
1139,2025-07-17T16:03:18.868420503Z,2025-07-17T16:03:18.868254768Z,10,2,1108,C,A,-1,14.7,100,0,165735,272610397,13.12,200,2,13.11,100,1,13.03,100,1,13,2,1,12.73,100,1,12.71,100,1,12.5,700,1,12.46,200,2,12.43,700,1,12.42,700,1,13.87,200,2,14.03,2,1,14.15,100,1,14.28,100,1,14.45,100,1,14.56,800,2,14.6,700,1,14.66,100,1,14.68,1400,2,14.76,200,2,ARL,326729821
1140,2025-07-17T16:03:19.191219507Z,2025-07-17T16:03:19.191054306Z,10,2,1108,A,A,1,13.88,100,130,165201,272614303,13.12,200,2,13.11,100,1,13.03,100,1,13,2,1,12.73,100,1,12.71,100,1,12.5,700,1,12.46,200,2,12.43,700,1,12.42,700,1,13.87,200,2,13.88,100,1,14.03,2,1,14.15,100,1,14.28,100,1,14.45,100,1,14.56,800,2,14.6,700,1,14.66,100,1,14.68,1400,2,ARL,326899125
1141,2025-07-17T16:03:27.436323951Z,2025-07-17T16:03:27.436158395Z,10,2,1108,A,A,4,14.25,53,130,165556,272788767,13.12,200,2,13.11,100,1,13.03,100,1,13,2,1,12.73,100,1,12.71,100,1,12.5,700,1,12.46,200,2,12.43,700,1,12.42,700,1,13.87,200,2,13.88,100,1,14.03,2,1,14.15,100,1,14.25,53,1,14.28,100,1,14.45,100,1,14.56,800,2,14.6,700,1,14.66,100,1,ARL,327112281
1142,2025-07-17T16:03:27.454010355Z,2025-07-17T16:03:27.453845141Z,10,2,1108,C,B,-1,13.03,100,130,165214,272788897,13.12,200,2,13.11,100,1,13,2,1,12.73,100,1,12.71,100,1,12.5,700,1,12.46,200,2,12.43,700,1,12.42,700,1,12.37,700,1,13.87,200,2,13.88,100,1,14.03,2,1,14.15,100,1,14.25,53,1,14.28,100,1,14.45,100,1,14.56,800,2,14.6,700,1,14.66,100,1,ARL,285586293
1143,2025-07-17T16:03:27.454059719Z,2025-07-17T16:03:27.453894425Z,10,2,1108,A,B,3,12.95,100,130,165294,272788898,13.12,200,2,13.11,100,1,13,2,1,12.95,100,1,12.73,100,1,12.71,100,1,12.5,700,1,12.46,200,2,12.43,700,1,12.42,700,1,13.87,200,2,13.88,100,1,14.03,2,1,14.15,100,1,14.25,53,1,14.28,100,1,14.45,100,1,14.56,800,2,14.6,700,1,14.66,100,1,ARL,327112565
1144,2025-07-17T16:03:27.454892321Z,2025-07-17T16:03:27.454726901Z,10,2,1108,C,B,-1,12.95,100,130,165420,272788942,13.12,200,2,13.11,100,1,13,2,1,12.73,100,1,12.71,100,1,12.5,700,1,12.46,200,2,12.43,700,1,12.42,700,1,12.37,700,1,13.87,200,2,13.88,100,1,14.03,2,1,14.15,100,1,14.25,53,1,14.28,100,1,14.45,100,1,14.56,800,2,14.6,700,1,14.66,100,1,ARL,327112565
